File: data/180125_GEVarnish/180125_GEVarnish.dat
[Header]
; MPMS3 Data File (default extension .dat)
; Copyright (c) 2007, Quantum Design, Inc. All rights reserved.
TITLE,
FILEOPENTIME,3726065299.88445,01/25/2018,6:08 pm
BYAPP,MPMS3,1.0,1.1
INFO,MPMS3 Measurement Release 1.1.16 Build 388, MultiVu Release 2.3.4.15,APPNAME
INFO,0,MOMENT_UNITS
INFO,GE,SAMPLE_MATERIAL
INFO,drop,SAMPLE_COMMENT
INFO,1,SAMPLE_MASS
INFO,,SAMPLE_VOLUME
INFO,,SAMPLE_MOLECULAR_WEIGHT
INFO,,SAMPLE_SIZE
INFO,,SAMPLE_SHAPE
INFO,Quartz,SAMPLE_HOLDER
INFO,Standard,SAMPLE_HOLDER_DETAIL
INFO,66.44,SAMPLE_OFFSET
DATATYPE,COMMENT,1
DATATYPE,TIME,2
STARTUPAXIS,X,2
STARTUPAXIS,Y1,5
FIELDGROUP, VSM,2,3,4,5,6,8,9,10,11,14,15
FIELDGROUP, DC, 2,3,4,14,34,35,36,37,38,39,40,41,42,43,44,45,46,47
STARTUPGROUP, All
[Data]
Comment,Time Stamp (sec),Temperature (K),Magnetic Field (Oe),Moment (emu),M. Std. Err. (emu),Transport Action,Averaging Time (sec),Frequency (Hz),Peak Amplitude (mm),Center Position (mm),Lockin Signal' (V),Lockin Signal (V),Range,M. Quad. Signal (emu),Min. Temperature (K),Max. Temperature (K),Min. Field (Oe),Max. Field (Oe),Mass (grams),Motor Lag (deg),Pressure (Torr),Measure Count,Measurement Number,SQUID Status (code),Motor Status (code),Measure Status (code),Motor Current (amps),Motor Temp. (C),Temp. Status (code),Field Status (code),Chamber Status (code),Chamber Temp (K),Redirection State,Average Temp (K),Rotation Angle (deg),Rotator state,DC Moment Fixed Ctr (emu),DC Moment Err Fixed Ctr (emu),DC Moment Free Ctr (emu),DC Moment Err Free Ctr (emu),DC Fixed Fit,DC Free Fit,DC Calculated Center (mm),DC Calculated Center Err (mm),DC Scan Length (mm),DC Scan Time (s),DC Number of Points,DC Squid Drift,DC Min V (V),DC Max V (V),DC Scans per Measure,Map 01,Map 02,Map 03,Map 04,Map 05,Map 06,Map 07,Map 08,Map 09,Map 10,Map 11,Map 12,Map 13,Map 14,Map 15,Map 16
,3726065992.04683,299.833526611328,9999.6572265625,-4.48433784269798E-6,1.77314508617304E-7,1,2,13.2042255401611,7.99548557227747,33.6299985647202,-0.00909668685160884,-0.00115274256231861,1000,9.34754878252852E-8,299.833526611328,299.833526611328,9999.6572265625,9999.6572265625,50.4588106874669,5.51136712978055,6.21169328689575,26,1,0,0,1,0.458984375,30.3030319213867,1,1,1,299.833526611328,0,299.833526611328,,,,,,,,,,,,,,,,,,,,,,,,,,,,,,,,,
,3726066120.00409,294.997467041016,9999.6572265625,-4.53064684213864E-6,1.76558308452162E-7,1,2,13.2042255401611,7.99499928542298,33.6299985647202,-0.00917922515309026,-0.00123958070382994,1000,5.73665303437991E-8,294.997467041016,294.997467041016,9999.6572265625,9999.6572265625,50.361107122563,5.51275091691013,6.37595176696777,26,1,0,0,1,0.461959838867188,31.7693061828613,2,1,1,294.997467041016,0,294.997467041016,,,,,,,,,,,,,,,,,,,,,,,,,,,,,,,,,
,3726066238.05423,288.992706298828,9999.6572265625,-4.64006186910084E-6,1.8691509143167E-7,1,2,13.2042255401611,7.99465516783201,33.6299985647202,-0.0093775790233741,-0.00142561695666556,1000,-1.84566220205505E-8,288.992706298828,288.992706298828,9999.6572265625,9999.6572265625,50.3290603532746,5.51423306810419,6.43500137329102,26,1,0,0,1,0.463180541992188,31.7693061828613,2,1,1,288.992706298828,0,288.992706298828,,,,,,,,,,,,,,,,,,,,,,,,,,,,,,,,,
,3726066357.22046,282.993225097656,9999.6572265625,-4.53072818600053E-6,1.71033457804401E-7,1,2,13.2042255401611,7.99454172773884,33.6299985647202,-0.00916059880017797,-0.00136460559809847,1000,-4.46769609627661E-9,282.993225097656,282.993225097656,9999.6572265625,9999.6572265625,50.3939355203707,5.51541365095101,6.46190547943115,26,1,0,0,1,0.45989990234375,33.2355842590332,2,1,1,282.993225097656,0,282.993225097656,,,,,,,,,,,,,,,,,,,,,,,,,,,,,,,,,
,3726066476.53881,276.999664306641,9999.6572265625,-4.5640239961357E-6,1.86175564538411E-7,1,2,13.2042255401611,7.99442946017264,33.6299985647202,-0.00926284506371754,-0.00113808340143709,1000,1.12473239564357E-7,276.999664306641,276.999664306641,9999.6572265625,9999.6572265625,50.4345802033707,5.51604111388514,6.48141717910767,26,1,0,0,1,0.4595947265625,33.2355842590332,2,1,1,276.999664306641,0,276.999664306641,,,,,,,,,,,,,,,,,,,,,,,,,,,,,,,,,
,3726066597.10356,270.982482910156,9999.6572265625,-4.41942636335979E-6,2.0142274068504E-7,1,2,13.2042255401611,7.99424129508258,33.6299985647202,-0.00897894621030042,-0.00103656226997171,1000,1.41276622224998E-7,270.982482910156,270.982482910156,9999.6572265625,9999.6572265625,50.5178236406688,5.51615547104415,6.48206472396851,26,1,0,0,1,0.459518432617188,32.2580642700195,2,1,1,270.982482910156,0,270.982482910156,,,,,,,,,,,,,,,,,,,,,,,,,,,,,,,,,
,3726066716.45383,264.979949951172,9999.6572265625,-4.40646847588756E-6,1.75001151089904E-7,1,2,13.2042255401611,7.99400621980164,33.6299985647202,-0.00891999213699242,-0.00125304308379277,1000,3.22937826356621E-8,264.979949951172,264.979949951172,9999.6572265625,9999.6572265625,50.4502127737553,5.51531258261593,6.49004030227661,26,1,0,0,1,0.4620361328125,32.2580642700195,2,1,1,264.979949951172,0,264.979949951172,,,,,,,,,,,,,,,,,,,,,,,,,,,,,,,,,
,3726066836.79393,258.989593505859,9999.6572265625,-4.54931857840424E-6,1.77215457697666E-7,1,2,13.2042255401611,7.99375149266166,33.6299985647202,-0.00920837816400503,-0.00129784872465518,1000,3.12601750792762E-8,258.989593505859,258.989593505859,9999.6572265625,9999.6572265625,50.3345317529092,5.51550003664272,6.49888372421265,26,1,0,0,1,0.4608154296875,33.7243423461914,2,1,1,258.989593505859,0,258.989593505859,,,,,,,,,,,,,,,,,,,,,,,,,,,,,,,,,
,3726066957.24226,252.997756958008,9999.6572265625,-4.40386647227165E-6,1.77735691339676E-7,1,2,13.2042255401611,7.99341782966343,33.6299985647202,-0.00891578076959102,-0.00124266324289563,1000,3.70169736467333E-8,252.997756958008,252.997756958008,9999.6572265625,9999.6572265625,50.4123037905726,5.51601555642171,6.47820901870728,26,1,0,0,1,0.459518432617188,31.7693061828613,2,1,1,252.997756958008,0,252.997756958008,,,,,,,,,,,,,,,,,,,,,,,,,,,,,,,,,
,3726067076.70502,246.999069213867,9999.6572265625,-4.36389271626602E-6,1.69108824637572E-7,1,2,13.2042255401611,7.99342138606043,33.6299985647202,-0.00880831707814071,-0.00141074437938981,1000,-5.2022601384875E-8,246.999069213867,246.999069213867,9999.6572265625,9999.6572265625,50.4283271752169,5.51599506716998,6.46056652069092,26,1,0,0,1,0.461807250976562,31.7693061828613,2,1,1,246.999069213867,0,246.999069213867,,,,,,,,,,,,,,,,,,,,,,,,,,,,,,,,,
,3726067197.11684,240.996856689453,9999.6572265625,-4.44964929882137E-6,1.54680995946707E-7,1,2,13.2042255401611,7.99333689819312,33.6299985647202,-0.0089946400079556,-0.00134870507678606,1000,-8.65639157944855E-9,240.996856689453,240.996856689453,9999.6572265625,9999.6572265625,50.2931054413899,5.51612437386347,6.45118761062622,26,1,0,0,1,0.462570190429687,32.2580642700195,2,1,1,240.996856689453,0,240.996856689453,,,,,,,,,,,,,,,,,,,,,,,,,,,,,,,,,
,3726067317.15756,234.999740600586,9999.6572265625,-4.45235570285055E-6,1.73971034640295E-7,1,2,13.2042255401611,7.9932966969107,33.6299985647202,-0.00902273018708796,-0.0011964741757329,1000,6.70293583368186E-8,234.999740600586,234.999740600586,9999.6572265625,9999.6572265625,50.4740524435919,5.51634063566386,6.43431043624878,26,1,0,0,1,0.459136962890625,32.7468223571777,2,1,1,234.999740600586,0,234.999740600586,,,,,,,,,,,,,,,,,,,,,,,,,,,,,,,,,
,3726067437.14944,228.994583129883,9999.6572265625,-4.23130485937146E-6,1.64871602496582E-7,1,2,13.2042255401611,7.99333161217799,33.6299985647202,-0.00854145024813003,-0.0013624073392929,1000,-4.7738753198249E-8,228.994583129883,228.994583129883,9999.6572265625,9999.6572265625,50.5123522410342,5.51647871454322,6.43865537643433,26,1,0,0,1,0.461349487304687,33.7243423461914,2,1,1,228.994583129883,0,228.994583129883,,,,,,,,,,,,,,,,,,,,,,,,,,,,,,,,,
,3726067556.21315,222.996704101562,9999.6572265625,-4.28099588243814E-6,1.76050734549716E-7,1,2,13.2042255401611,7.9933132239048,33.6299985647202,-0.00867683900924235,-0.00114122909446764,1000,6.89981011798822E-8,222.996704101562,222.996704101562,9999.6572265625,9999.6572265625,50.5178236406688,5.51657171069366,6.41287803649902,26,1,0,0,1,0.45989990234375,32.2580642700195,2,1,1,222.996704101562,0,222.996704101562,,,,,,,,,,,,,,,,,,,,,,,,,,,,,,,,,
,3726067677.36562,216.989318847656,9999.6572265625,-4.21481150261069E-6,1.72173204454957E-7,1,2,13.2042255401611,7.99329806060906,33.6299985647202,-0.00854202066638012,-0.0011280795270018,1000,6.57083138911047E-8,216.989318847656,216.989318847656,9999.6572265625,9999.6572265625,50.4255914753996,5.5164418489952,6.30591487884521,26,1,0,0,1,0.461196899414063,33.7243423461914,2,1,1,216.989318847656,0,216.989318847656,,,,,,,,,,,,,,,,,,,,,,,,,,,,,,,,,
,3726067797.56761,210.994277954102,9999.6572265625,-4.32472114245713E-6,1.49048625865302E-7,1,2,13.2042255401611,7.99319851940786,33.6400009691715,-0.00874440514835841,-0.00129472721132831,1000,-4.51331142059866E-10,210.994277954102,210.994277954102,9999.6572265625,9999.6572265625,50.4697534867361,5.51648500533966,6.30795431137085,26,1,0,0,1,0.457687377929687,32.7468223571777,2,1,1,210.994277954102,0,210.994277954102,,,,,,,,,,,,,,,,,,,,,,,,,,,,,,,,,
,3726067917.65507,204.995269775391,9999.6572265625,-4.21612476140218E-6,1.69209240238481E-7,1,2,13.2042255401611,7.9931274435656,33.6299985647202,-0.00856321502397988,-0.00100247747093269,1000,1.28014396660363E-7,204.995269775391,204.995269775391,9999.6572265625,9999.6572265625,50.3747856216496,5.51668530389029,6.30066585540771,26,1,0,0,1,0.463180541992188,32.2580642700195,2,1,1,204.995269775391,0,204.995269775391,,,,,,,,,,,,,,,,,,,,,,,,,,,,,,,,,
,3726068037.92778,198.988403320313,9999.6572265625,-4.16956692748277E-6,1.80635644546636E-7,1,2,13.2042255401611,7.99307341731024,33.6299985647202,-0.00842383238075498,-0.00129412078376218,1000,-2.31130857716385E-8,198.988403320313,198.988403320313,9999.6572265625,9999.6572265625,50.4345802033707,5.51697767911156,6.29604864120483,26,1,0,0,1,0.461044311523438,32.7468223571777,2,1,1,198.988403320313,0,198.988403320313,,,,,,,,,,,,,,,,,,,,,,,,,,,,,,,,,
,3726068157.86154,192.997756958008,9999.6572265625,-4.20751235935714E-6,1.76000360416519E-7,1,2,13.2042255401611,7.99305155876499,33.6299985647202,-0.00851531797830834,-0.00120561822430047,1000,2.62707196225745E-8,192.997756958008,192.997756958008,9999.6572265625,9999.6572265625,50.5670662373803,5.51709754926341,6.2913384437561,26,1,0,0,1,0.457305908203125,32.2580642700195,2,1,1,192.997756958008,0,192.997756958008,,,,,,,,,,,,,,,,,,,,,,,,,,,,,,,,,
,3726068277.98627,186.998977661133,9999.6572265625,-4.27309080589378E-6,1.74237785995051E-7,1,2,13.2042255401611,7.99293898580167,33.6299985647202,-0.00862531213685935,-0.00137754224928626,1000,-4.90598394337389E-8,186.998977661133,186.998977661133,9999.6572265625,9999.6572265625,50.5205593404861,5.51756010375344,6.26979112625122,26,1,0,0,1,0.462722778320313,32.7468223571777,2,1,1,186.989562988281,0,186.998977661133,,,,,,,,,,,,,,,,,,,,,,,,,,,,,,,,,
,3726068398.44567,180.993743896484,9999.6572265625,-4.14356725043326E-6,1.89660288090718E-7,1,2,13.2042255401611,7.99283068319815,33.6299985647202,-0.0083686738519314,-0.00130286130077937,1000,-3.12935120801648E-8,180.993743896484,180.993743896484,9999.6572265625,9999.6572265625,50.2446444731976,5.51777074423421,6.2624397277832,26,1,0,0,1,0.46417236328125,31.7693061828613,2,1,1,180.993743896484,0,180.993743896484,,,,,,,,,,,,,,,,,,,,,,,,,,,,,,,,,
,3726068518.77413,174.976547241211,9999.6572265625,-4.04890731925111E-6,1.81008637036582E-7,1,2,13.2042255401611,7.99282049074931,33.6299985647202,-0.00820132887229119,-0.00111194530575051,1000,4.91227994360307E-8,174.976547241211,174.976547241211,9999.6572265625,9999.6572265625,50.3810386498034,5.51808085946274,6.24751138687134,26,1,0,0,1,0.463790893554687,33.7243423461914,2,1,1,174.976547241211,0,174.976547241211,,,,,,,,,,,,,,,,,,,,,,,,,,,,,,,,,
,3726068638.84277,168.980163574219,9999.6572265625,-4.09066077118094E-6,1.74867797943123E-7,1,2,13.2042255401611,7.99281274618528,33.6299985647202,-0.00831043544975052,-0.000957574874057906,1000,1.31648070255477E-7,168.980163574219,168.980163574219,9999.6572265625,9999.6572265625,50.3622795653419,5.51839486071429,6.23386573791504,26,1,0,0,1,0.463104248046875,32.7468223571777,2,1,1,168.980163574219,0,168.980163574219,,,,,,,,,,,,,,,,,,,,,,,,,,,,,,,,,
,3726068758.49107,162.990921020508,9999.6572265625,-4.31367182590887E-6,1.96862240195219E-7,1,2,13.2042255401611,7.9927679689559,33.6299985647202,-0.00874213032320704,-0.00115400036947269,1000,6.74950474281849E-8,162.990921020508,162.990921020508,9999.6572265625,9999.6572265625,50.4420056743034,5.51798716572989,6.20856094360352,26,1,0,0,1,0.462493896484375,33.2355842590332,2,1,1,162.990921020508,0,162.990921020508,,,,,,,,,,,,,,,,,,,,,,,,,,,,,,,,,
,3726068878.78083,156.985580444336,9999.6572265625,-4.01777907404491E-6,1.5985490050819E-7,1,2,13.2042255401611,7.9927535292589,33.6299985647202,-0.00818554515234533,-0.000783660958741033,1000,2.06876722422896E-7,156.985580444336,156.985580444336,9999.6572265625,9999.6572265625,50.5432265675438,5.51815985616643,6.13398885726929,26,1,0,0,1,0.45867919921875,33.7243423461914,2,1,1,156.985580444336,0,156.985580444336,,,,,,,,,,,,,,,,,,,,,,,,,,,,,,,,,
,3726068999.01094,150.994735717773,9999.6572265625,-4.10743592941386E-6,1.65902348513046E-7,1,2,13.2042255401611,7.9927158867262,33.6299985647202,-0.00830565691680557,-0.00122374991429624,1000,2.48231793681769E-9,150.994735717773,150.994735717773,9999.6572265625,9999.6572265625,50.5029726988034,5.51842373813727,6.11971855163574,26,1,0,0,1,0.463714599609375,30.7917900085449,2,1,1,150.994735717773,0,150.994735717773,,,,,,,,,,,,,,,,,,,,,,,,,,,,,,,,,
,3726069118.7501,144.99201965332,9999.6572265625,-3.9293102486003E-6,1.86306816735116E-7,1,2,13.2042255401611,7.99267970035678,33.6299985647202,-0.00798649891117158,-0.000893229246390349,1000,1.39594866347653E-7,144.99201965332,144.99201965332,9999.6572265625,9999.6572265625,50.5721468227553,5.51879564811201,6.11598587036133,26,1,0,0,1,0.45989990234375,33.2355842590332,2,1,1,144.99201965332,0,144.99201965332,,,,,,,,,,,,,,,,,,,,,,,,,,,,,,,,,
,3726069239.07011,138.990570068359,9999.6572265625,-3.98745248769419E-6,1.57430891509301E-7,1,2,13.2042255401611,7.99265632557922,33.6299985647202,-0.00807436850115801,-0.00111119380254533,1000,4.03955647176748E-8,138.990570068359,138.990570068359,9999.6572265625,9999.6572265625,50.7491856823611,5.51887408209181,6.10377073287964,26,1,0,0,1,0.461273193359375,32.7468223571777,2,1,1,138.990570068359,0,138.990570068359,,,,,,,,,,,,,,,,,,,,,,,,,,,,,,,,,
,3726069359.25196,132.995758056641,9999.6572265625,-3.89186760315766E-6,1.78339467664672E-7,1,2,13.2042255401611,7.99258599018889,33.6299985647202,-0.00790936574478899,-0.000891321821595555,1000,1.34995484674052E-7,132.995758056641,132.995758056641,9999.6572265625,9999.6572265625,50.53697353939,5.51877384177302,6.09673118591309,26,1,0,0,1,0.457077026367188,33.2355842590332,2,1,1,132.995758056641,0,132.995758056641,,,,,,,,,,,,,,,,,,,,,,,,,,,,,,,,,
,3726069479.6777,126.982719421387,9999.6572265625,-3.89962690667046E-6,2.01010744275619E-7,1,2,13.2042255401611,7.99256283744733,33.6299985647202,-0.00788433537498966,-0.00116876391676489,1000,-1.0756584426664E-9,126.982719421387,126.982719421387,9999.6572265625,9999.6572265625,50.559249952188,5.51950848296833,6.07934141159058,26,1,0,0,1,0.463485717773438,31.7693061828613,2,1,1,126.982719421387,0,126.982719421387,,,,,,,,,,,,,,,,,,,,,,,,,,,,,,,,,
,3726069599.92456,120.980743408203,9999.6572265625,-3.8742043740154E-6,1.85424398941668E-7,1,2,13.2042255401611,7.99258735718941,33.6400009691715,-0.00787707280228315,-0.000862925326128145,1000,1.46426564978493E-7,120.980743408203,120.980743408203,9999.6572265625,9999.6572265625,50.4537301020919,5.51930175893326,6.01731395721436,26,1,0,0,1,0.459671020507812,32.2580642700195,2,1,1,120.980743408203,0,120.980743408203,,,,,,,,,,,,,,,,,,,,,,,,,,,,,,,,,
,3726069719.63902,114.981834411621,9999.6572265625,-3.93195416764301E-6,1.55358091819454E-7,1,2,13.2042255401611,7.99255730697357,33.6400009691715,-0.00796829811008474,-0.00105269981420237,1000,6.11106539758868E-8,114.981834411621,114.981834411621,9999.6572265625,9999.6572265625,50.5189960834477,5.51948913323512,5.97536134719849,26,1,0,0,1,0.45867919921875,32.7468223571777,2,1,1,114.981834411621,0,114.981834411621,,,,,,,,,,,,,,,,,,,,,,,,,,,,,,,,,
,3726069839.88332,108.990867614746,9999.6572265625,-3.79294399978409E-6,1.84128145557276E-7,1,2,13.2042255401611,7.99257418834744,33.6299985647202,-0.00765403370592932,-0.00123556468247395,1000,-4.98982487752281E-8,108.990867614746,108.990867614746,9999.6572265625,9999.6572265625,50.54713471014,5.51949761501382,5.96805477142334,26,1,0,0,1,0.46234130859375,33.7243423461914,2,1,1,108.990867614746,0,108.990867614746,,,,,,,,,,,,,,,,,,,,,,,,,,,,,,,,,
,3726069960.16755,102.998405456543,9999.6572265625,-3.70785748731412E-6,1.73015855280384E-7,1,2,13.2042255401611,7.99251969476541,33.6299985647202,-0.00750813381068382,-0.00103326453377264,1000,3.75650703733376E-8,102.998405456543,102.998405456543,9999.6572265625,9999.6572265625,50.4584198732073,5.51961306328654,5.95550346374512,26,1,0,0,1,0.461959838867188,32.7468223571777,2,1,1,102.998405456543,0,102.998405456543,,,,,,,,,,,,,,,,,,,,,,,,,,,,,,,,,
,3726070079.89991,96.9976043701172,9999.6572265625,-3.72283082630579E-6,1.83774493997835E-7,1,2,13.2042255401611,7.99258012801491,33.6299985647202,-0.00754155422236709,-0.00101669911003267,1000,4.7975604101217E-8,96.9976043701172,96.9976043701172,9999.6572265625,9999.6572265625,50.5463530816207,5.51993822792077,5.94692373275757,26,1,0,0,1,0.461654663085937,33.7243423461914,2,1,1,96.9976043701172,0,96.9976043701172,,,,,,,,,,,,,,,,,,,,,,,,,,,,,,,,,
,3726070200.25968,90.979133605957,9999.6572265625,-3.52949445791298E-6,1.46778885592222E-7,1,2,13.2042255401611,7.99251005161277,33.6299985647202,-0.00713159377723532,-0.00108739722255541,1000,-1.55985737694678E-8,90.979133605957,90.979133605957,9999.6572265625,9999.6572265625,50.5436173818034,5.51939523152875,5.93091917037964,26,1,0,0,1,0.461349487304687,32.7468223571777,2,1,1,90.979133605957,0,90.979133605957,,,,,,,,,,,,,,,,,,,,,,,,,,,,,,,,,
,3726070320.60182,84.9779891967773,9999.6572265625,-3.69417377982916E-6,1.74681155756698E-7,1,2,13.2042255401611,7.99257324153339,33.6400009691715,-0.00743278052417922,-0.00135166081759884,1000,-1.21931293033954E-7,84.9779891967773,84.9779891967773,9999.6572265625,9999.6572265625,50.4447413741207,5.51956953034951,5.91772747039795,26,1,0,0,1,0.458831787109375,31.7693061828613,2,1,1,84.9779891967773,0,84.9779891967773,,,,,,,,,,,,,,,,,,,,,,,,,,,,,,,,,
,3726070439.82535,78.9891510009766,9999.6572265625,-3.63252238140225E-6,1.80642257083176E-7,1,2,13.2042255401611,7.99268339205881,33.6299985647202,-0.0073235677563095,-0.00122924759297225,1000,-7.05047990056533E-8,78.9891510009766,78.9891510009766,9999.6572265625,9999.6572265625,50.5182144549284,5.5190695394073,5.90014505386353,26,1,0,0,1,0.461273193359375,31.7693061828613,2,1,1,78.9891510009766,0,78.9891510009766,,,,,,,,,,,,,,,,,,,,,,,,,,,,,,,,,
,3726070558.89986,72.9999160766602,9999.6572265625,-3.28528930481385E-6,1.77858788583866E-7,1,2,13.2042255401611,7.99278846902203,33.6299985647202,-0.00668775387743019,-0.000677852976628348,1000,1.50830919916484E-7,72.9999160766602,72.9999160766602,9999.6572265625,9999.6572265625,50.4259822896592,5.5186906942331,5.87948560714722,26,1,0,0,1,0.463409423828125,32.2580642700195,2,1,1,72.9999160766602,0,72.9999160766602,,,,,,,,,,,,,,,,,,,,,,,,,,,,,,,,,
,3726070678.11985,66.9873886108398,9999.6572265625,-3.16149936555891E-6,1.69221573010449E-7,1,2,13.2042255401611,7.99284553662182,33.6299985647202,-0.0063983772580363,-0.000905137680184615,1000,2.01074503012348E-8,66.9873886108398,66.9873886108398,9999.6572265625,9999.6572265625,50.5752733368323,5.51858849763943,5.83882713317871,26,1,0,0,1,0.460205078125,32.7468223571777,2,1,1,66.9873886108398,0,66.9873886108398,,,,,,,,,,,,,,,,,,,,,,,,,,,,,,,,,
,3726070796.8501,60.989990234375,9999.6572265625,-3.08567160496087E-6,1.89595999262558E-7,1,2,13.2042255401611,7.99288903148404,33.6299985647202,-0.00621308402552212,-0.00109868671033003,1000,-8.68345700703572E-8,60.989990234375,60.989990234375,9999.6572265625,9999.6572265625,50.4697534867361,5.51858112453264,4.97574377059937,26,1,0,0,1,0.46142578125,32.2580642700195,2,1,1,60.989990234375,0,60.989990234375,,,,,,,,,,,,,,,,,,,,,,,,,,,,,,,,,
,3726070916.47907,54.9967575073242,9999.6572265625,-2.98859522187795E-6,1.68322774627539E-7,1,2,13.2042255401611,7.99280519800541,33.6299985647202,-0.00607001922770266,-0.00070971431425259,1000,9.11755360995593E-8,54.9967575073242,54.9967575073242,9999.6572265625,9999.6572265625,50.4611555730246,5.51840352238971,4.93602323532105,26,1,0,0,1,0.46173095703125,32.7468223571777,2,1,1,54.9967575073242,0,54.9967575073242,,,,,,,,,,,,,,,,,,,,,,,,,,,,,,,,,
,3726071035.58126,48.9938850402832,9999.6572265625,-2.71021218564909E-6,1.54936974671048E-7,1,2,13.2042255401611,7.99279428858081,33.6299985647202,-0.00549607111007535,-0.000701263936623816,1000,5.41659500062504E-8,48.9938850402832,48.9938850402832,9999.6572265625,9999.6572265625,50.4795238432265,5.518269421715,4.88646554946899,26,1,0,0,1,0.46295166015625,32.2580642700195,2,1,1,48.9938850402832,0,48.9938850402832,,,,,,,,,,,,,,,,,,,,,,,,,,,,,,,,,
,3726071154.92891,42.9688110351562,9999.6572265625,-2.47325953554923E-6,1.90497511029237E-7,1,2,13.2042255401611,7.99280748735014,33.6299985647202,-0.0049580101423609,-0.00102889435502653,1000,-1.42930586713709E-7,42.9688110351562,42.9688110351562,9999.6572265625,9999.6572265625,50.4521668450534,5.51864446906621,4.81823635101318,26,1,0,0,1,0.46142578125,31.7693061828613,2,1,1,42.9688110351562,0,42.9688110351562,,,,,,,,,,,,,,,,,,,,,,,,,,,,,,,,,
,3726071273.89244,36.9889793395996,9999.6572265625,-2.22326784080404E-6,1.76735396606499E-7,1,2,13.2042255401611,7.99287216159326,33.6299985647202,-0.00449736983244351,-0.000651275607521709,1000,6.84397668022729E-9,36.9889793395996,36.9889793395996,9999.6572265625,9999.6572265625,50.3927630775919,5.51857349172668,4.73148107528687,26,1,0,0,1,0.46295166015625,33.7243423461914,2,1,1,36.9889793395996,0,36.9889793395996,,,,,,,,,,,,,,,,,,,,,,,,,,,,,,,,,
,3726071393.11776,30.9976100921631,9999.6572265625,-1.78703058809402E-6,1.52909990412941E-7,1,2,13.2042255401611,7.9929157336631,33.6299985647202,-0.00362722927625928,-0.000440372467010297,1000,4.66074720888925E-8,30.9976100921631,30.9976100921631,9999.6572265625,9999.6572265625,50.4009701770438,5.51810976764277,4.62952947616577,26,1,0,0,1,0.460586547851562,32.2580642700195,2,1,1,30.9976100921631,0,30.9976100921631,,,,,,,,,,,,,,,,,,,,,,,,,,,,,,,,,
,3726071512.78391,24.9989929199219,9999.6572265625,-1.02872407778899E-6,1.36119330235292E-7,1,2,13.2042255401611,7.9929676428127,33.6299985647202,-0.00210482167825758,-0.000140235300517574,1000,8.28505537395344E-8,24.9989929199219,24.9989929199219,9999.6572265625,9999.6572265625,50.4666269726592,5.51780253293534,4.45945358276367,26,1,0,0,1,0.462417602539063,33.7243423461914,2,1,1,24.9989929199219,0,24.9989929199219,,,,,,,,,,,,,,,,,,,,,,,,,,,,,,,,,
,3726071633.46568,18.9884948730469,9999.6572265625,4.09897021212007E-7,4.85849198456629E-8,1,2,13.2042255401611,7.99301772730537,33.6299985647202,0.000797789794838807,0.000332195766241921,1000,1.0364653294874E-7,18.9884948730469,18.9884948730469,9999.6572265625,9999.6572265625,50.4924207137938,5.5178575639142,4.17590188980103,26,1,0,0,1,0.462799072265625,31.7693061828613,2,1,1,18.9884948730469,0,18.9884948730469,,,,,,,,,,,,,,,,,,,,,,,,,,,,,,,,,
,3726071756.14846,12.968282699585,9999.6572265625,2.2688976313739E-6,1.62255403455202E-7,1,2,13.2042255401611,7.99314735903791,33.6299985647202,0.00462743449799309,0.000410024257705291,1000,-1.32915631820848E-7,12.968282699585,12.968282699585,9999.6572265625,9999.6572265625,50.5713651942361,5.51780771788431,3.75001621246338,26,1,0,0,1,0.461578369140625,31.7693061828613,2,1,1,12.968282699585,0,12.968282699585,,,,,,,,,,,,,,,,,,,,,,,,,,,,,,,,,
,3726071870.42012,6.97703123092651,9999.6572265625,8.17950289082083E-6,1.61643955081271E-7,1,2,13.2042255401611,7.99316615967844,33.6299985647202,0.0165192620968141,0.00257929314462395,1000,6.54108855665115E-8,6.97703123092651,6.97703123092651,9999.6572265625,9999.6572265625,50.3904181920342,5.51774533655411,3.24006772041321,26,1,0,0,1,0.46173095703125,31.2805480957031,6,1,1,6.97703123092651,0,6.97703123092651,,,,,,,,,,,,,,,,,,,,,,,,,,,,,,,,,
,3726072643.81405,2.00020051002502,9999.6572265625,2.86173725069926E-5,1.85235568193408E-7,1,2,13.2042255401611,7.99326501939989,33.6299985647202,0.0578586648582634,0.00859943194436547,1000,1.88001780064772E-8,2.00020051002502,2.00020051002502,9999.6572265625,9999.6572265625,50.6120098772361,5.51786488711597,1.93048501014709,26,1,0,0,1,0.461349487304687,32.7468223571777,1,1,1,2.00020051002502,0,2.00020051002502,,,,,,,,,,,,,,,,,,,,,,,,,,,,,,,,,
,3726072762.03848,7.00875282287598,9999.6572265625,8.18728424797918E-6,1.6377319448816E-7,1,2,13.2042255401611,7.99331016473183,33.6299985647202,0.0165614653631666,0.002403860615772,1000,-2.25148024776135E-8,7.00875282287598,7.00875282287598,9999.6572265625,9999.6572265625,50.4126946048323,5.51719793234956,3.22655916213989,26,1,0,0,1,0.463714599609375,34.2131004333496,6,1,1,7.00875282287598,0,7.00875282287598,,,,,,,,,,,,,,,,,,,,,,,,,,,,,,,,,
,3726072889.91492,13.0048217773437,9999.6572265625,2.59803759935339E-6,1.52463275592735E-7,1,2,13.2042255401611,7.99333147512995,33.6299985647202,0.00525175238143695,0.000787395266376282,1000,5.01508142931787E-9,13.0048217773437,13.0048217773437,9999.6572265625,9999.6572265625,50.55729588089,5.51710849148566,3.83304476737976,26,1,0,0,1,0.461196899414063,32.7468223571777,6,1,1,13.0048217773437,0,13.0048217773437,,,,,,,,,,,,,,,,,,,,,,,,,,,,,,,,,
,3726073009.74104,19.0071201324463,9999.6572265625,3.72451147010231E-7,4.32562286160223E-8,1,2,13.2042255401611,7.99334089725339,33.6299985647202,0.000752518592705975,0.000115353669465361,1000,1.94233158461521E-9,19.0071201324463,19.0071201324463,9999.6572265625,9999.6572265625,50.3380490812457,5.51723889269429,4.13978958129883,26,1,0,0,1,0.466156005859375,32.7468223571777,2,1,1,19.0071201324463,0,19.0071201324463,,,,,,,,,,,,,,,,,,,,,,,,,,,,,,,,,
,3726073133.3905,25.0028839111328,9999.6572265625,-1.09796117492108E-6,1.12797375694874E-7,1,2,13.2042255401611,7.99339218270742,33.6299985647202,-0.00223386478372567,-0.000235416043438305,1000,4.6024504713289E-8,25.0028839111328,25.0028839111328,9999.6572265625,9999.6572265625,50.4650637156207,5.51709865271237,4.32479858398438,26,1,0,0,1,0.461273193359375,32.2580642700195,2,1,1,25.0028839111328,0,25.0028839111328,,,,,,,,,,,,,,,,,,,,,,,,,,,,,,,,,
,3726073256.94585,31.0092124938965,9999.6572265625,-1.71484800040753E-6,1.54430726714759E-7,1,2,13.2042255401611,7.99340105637524,33.6299985647202,-0.0034921050454605,-0.000346417166128218,1000,8.24009913010748E-8,31.0092124938965,31.0092124938965,9999.6572265625,9999.6572265625,50.46584534414,5.51704615246784,4.47106838226318,26,1,0,0,1,0.460281372070313,32.7468223571777,2,1,1,31.0092124938965,0,31.0092124938965,,,,,,,,,,,,,,,,,,,,,,,,,,,,,,,,,
,3726073380.3076,37.0044441223145,9999.6572265625,-2.07221632052011E-6,1.40750635570227E-7,1,2,13.2042255401611,7.99346026657675,33.6299985647202,-0.00418354296840003,-0.000664100374648208,1000,-2.18345530104834E-8,37.0044441223145,37.0044441223145,9999.6572265625,9999.6572265625,50.3267154677169,5.51706739664827,4.56812191009521,26,1,0,0,1,0.461959838867188,33.7243423461914,2,1,1,37.0044441223145,0,37.0044441223145,,,,,,,,,,,,,,,,,,,,,,,,,,,,,,,,,
,3726073502.9664,43.0064544677734,9999.6572265625,-2.38061800578538E-6,1.2226151123482E-7,1,2,13.2042255401611,7.99347085797703,33.6299985647202,-0.00482861732323758,-0.000611225250712081,1000,4.99453873720708E-8,43.0064544677734,43.0064544677734,9999.6572265625,9999.6572265625,50.5002369989861,5.51668020084628,4.634192943573,26,1,0,0,1,0.461273193359375,31.7693061828613,2,1,1,43.0064544677734,0,43.0064544677734,,,,,,,,,,,,,,,,,,,,,,,,,,,,,,,,,
,3726073625.92617,49.0180244445801,9999.6572265625,-2.77921434368539E-6,1.57095860484844E-7,1,2,13.2042255401611,7.99349538202482,33.6299985647202,-0.00559055298668634,-0.00102817494721918,1000,-9.72824646438661E-8,49.0180244445801,49.0180244445801,9999.6572265625,9999.6572265625,50.4904666424957,5.51636705990421,4.70295095443726,26,1,0,0,1,0.461807250976562,33.2355842590332,2,1,1,49.0180244445801,0,49.0180244445801,,,,,,,,,,,,,,,,,,,,,,,,,,,,,,,,,
,3726073748.19356,55.0088996887207,9999.6572265625,-2.88350349816725E-6,1.63569274854198E-7,1,2,13.2042255401611,7.99346405861594,33.6299985647202,-0.00581436112597864,-0.000971882676160418,1000,-5.40137404812612E-8,55.0088996887207,55.0088996887207,9999.6572265625,9999.6572265625,50.4248098468803,5.51688664325492,4.76659345626831,26,1,0,0,1,0.464630126953125,32.7468223571777,2,1,1,55.0088996887207,0,55.0088996887207,,,,,,,,,,,,,,,,,,,,,,,,,,,,,,,,,
,3726073870.23476,61.0000343322754,9999.6572265625,-2.96289534067992E-6,1.69048676880813E-7,1,2,13.2042255401611,7.99338465341144,33.6299985647202,-0.00602206170584624,-0.000676610394222191,1000,1.03758885143517E-7,61.0000343322754,61.0000343322754,9999.6572265625,9999.6572265625,50.366187707938,5.51696651251103,4.80008983612061,26,1,0,0,1,0.46234130859375,31.2805480957031,2,1,1,61.0000343322754,0,61.0000343322754,,,,,,,,,,,,,,,,,,,,,,,,,,,,,,,,,
,3726073992.57962,67.0118103027344,9999.6572265625,-3.32063245613158E-6,1.76619369023095E-7,1,2,13.2042255401611,7.99331355528913,33.6299985647202,-0.00677213122427958,-0.000602816610979896,1000,1.93182238785262E-7,67.0118103027344,67.0118103027344,9999.6572265625,9999.6572265625,50.5612040234861,5.51737843785973,4.84416389465332,26,1,0,0,1,0.461273193359375,33.7243423461914,2,1,1,67.0118103027344,0,67.0118103027344,,,,,,,,,,,,,,,,,,,,,,,,,,,,,,,,,
,3726074114.06196,73.0006942749023,9999.6572265625,-3.34255251370874E-6,1.58433301923055E-7,1,2,13.2042255401611,7.99313472006806,33.6299985647202,-0.00670913394639544,-0.00133414160962781,1000,-1.65265702959461E-7,73.0006942749023,73.0006942749023,9999.6572265625,9999.6572265625,50.55729588089,5.51758081582037,4.87561893463135,26,1,0,0,1,0.4608154296875,33.2355842590332,2,1,1,73.0006942749023,0,73.0006942749023,,,,,,,,,,,,,,,,,,,,,,,,,,,,,,,,,
,3726074236.30941,79.0164337158203,9999.6572265625,-3.58304373014551E-6,1.76753448565212E-7,1,2,13.2042255401611,7.99317942678344,33.6299985647202,-0.00726897601031041,-0.000908979792047309,1000,8.05880063712389E-8,79.0164337158203,79.0164337158203,9999.6572265625,9999.6572265625,50.5193868977073,5.5175567274818,4.89477872848511,26,1,0,0,1,0.459213256835937,32.2580642700195,2,1,1,79.0164337158203,0,79.0164337158203,,,,,,,,,,,,,,,,,,,,,,,,,,,,,,,,,
,3726074357.18987,85.0102844238281,9999.6572265625,-3.65525559183782E-6,1.54975361303621E-7,1,2,13.2042255401611,7.99310561046541,33.6299985647202,-0.00741259217880693,-0.000946511256413082,1000,7.27081771688231E-8,85.0102844238281,85.0102844238281,9999.6572265625,9999.6572265625,50.4189476329861,5.51769583520467,4.91519021987915,26,1,0,0,1,0.463409423828125,33.2355842590332,2,1,1,85.0102844238281,0,85.0102844238281,,,,,,,,,,,,,,,,,,,,,,,,,,,,,,,,,
,3726074478.19229,91.0051040649414,9999.6572265625,-3.61603799258666E-6,1.68544364965049E-7,1,2,13.2042255401611,7.99311309354687,33.6299985647202,-0.00731551250888062,-0.00105499268736016,1000,1.32547485191136E-8,91.0051040649414,91.0051040649414,9999.6572265625,9999.6572265625,50.6694595733996,5.5181799913574,4.93603754043579,26,1,0,0,1,0.460357666015625,33.2355842590332,2,1,1,91.0051040649414,0,91.0051040649414,,,,,,,,,,,,,,,,,,,,,,,,,,,,,,,,,
,3726074599.27564,97.0103073120117,9999.6572265625,-3.96454324766567E-6,1.8359373283685E-7,1,2,13.2042255401611,7.99310318967662,33.6299985647202,-0.00796878813982378,-0.00150657431338248,1000,-1.58518654536178E-7,97.0103073120117,97.0103073120117,9999.6572265625,9999.6572265625,50.3869008636976,5.51801386442146,4.96809196472168,26,1,0,0,1,0.4620361328125,33.2355842590332,2,1,1,97.0103073120117,0,97.0103073120117,,,,,,,,,,,,,,,,,,,,,,,,,,,,,,,,,
,3726074719.9301,103.021453857422,9999.6572265625,-3.95087486777228E-6,1.76194101555336E-7,1,2,13.2042255401611,7.99298161699773,33.6299985647202,-0.00800595447239152,-0.00106403193625674,1000,5.83208695306916E-8,103.000915527344,103.0419921875,9999.6572265625,9999.6572265625,50.5103981697361,5.51883937017432,4.96866893768311,26,1,0,0,1,0.462112426757812,31.7693061828613,2,1,1,103.0419921875,0,103.021453857422,,,,,,,,,,,,,,,,,,,,,,,,,,,,,,,,,
,3726074840.01619,109.000007629395,9999.6572265625,-3.95367989814363E-6,1.74169039559003E-7,1,2,13.2042255401611,7.99304021050506,33.6299985647202,-0.00796052273203668,-0.00141048895679612,1000,-1.12608480316167E-7,109.000007629395,109.000007629395,9999.6572265625,9999.6572265625,50.5103981697361,5.5185305082999,4.98395013809204,26,1,0,0,1,0.462265014648438,33.7243423461914,2,1,1,109.000007629395,0,109.000007629395,,,,,,,,,,,,,,,,,,,,,,,,,,,,,,,,,
,3726074960.50128,115.001525878906,9999.6572265625,-3.79280737556505E-6,1.63282211513653E-7,1,2,13.2042255401611,7.99299467270198,33.6400009691715,-0.00767376123891141,-0.00110186565167715,1000,1.62227780699471E-8,115.001525878906,115.001525878906,9999.6572265625,9999.6572265625,50.5248582973419,5.51849293681001,5.85623598098755,26,1,0,0,1,0.458145141601562,32.7468223571777,2,1,1,115.001525878906,0,115.001525878906,,,,,,,,,,,,,,,,,,,,,,,,,,,,,,,,,
,3726075080.74999,121.001625061035,9999.6572265625,-4.006231227544E-6,1.73857949920609E-7,1,2,13.2042255401611,7.99292864906571,33.6299985647202,-0.00813046791659566,-0.000995327735363969,1000,1.00488444763717E-7,121.001625061035,121.001625061035,9999.6572265625,9999.6572265625,50.4435689313419,5.51874813845959,5.88924503326416,26,1,0,0,1,0.462646484375,32.2580642700195,2,1,1,121.001625061035,0,121.001625061035,,,,,,,,,,,,,,,,,,,,,,,,,,,,,,,,,
,3726075201.36741,127.0078125,9999.6572265625,-4.04539681052924E-6,1.73567014492671E-7,1,2,13.2042255401611,7.99283603426007,33.6299985647202,-0.00820270085307627,-0.00105370943262805,1000,7.74059857007267E-8,127.0078125,127.0078125,9999.6572265625,9999.6572265625,50.43536183189,5.51934070225242,5.90729141235352,26,1,0,0,1,0.4632568359375,30.7917900085449,2,1,1,127.0078125,0,127.0078125,,,,,,,,,,,,,,,,,,,,,,,,,,,,,,,,,
,3726075322.26985,133.00700378418,9999.6572265625,-4.02114187909976E-6,1.7985856373209E-7,1,2,13.2042255401611,7.99279232350199,33.6299985647202,-0.00810907921397015,-0.00134758514164973,1000,-7.15282495767516E-8,133.00700378418,133.00700378418,9999.6572265625,9999.6572265625,50.452557659313,5.51972297488417,5.85570430755615,26,1,0,0,1,0.462265014648438,33.2355842590332,2,1,1,133.00700378418,0,133.00700378418,,,,,,,,,,,,,,,,,,,,,,,,,,,,,,,,,
,3726075442.40667,139.008331298828,9999.6572265625,-4.19228175898506E-6,1.83746392149931E-7,1,2,13.2042255401611,7.99274190500625,33.6299985647202,-0.00846467738004608,-0.00133393237795738,1000,-3.94569007880804E-8,139.003051757812,139.013610839844,9999.6572265625,9999.6572265625,50.483041171563,5.51960765889928,5.91506052017212,26,1,0,0,1,0.461883544921875,32.2580642700195,2,1,1,139.013610839844,0,139.008331298828,,,,,,,,,,,,,,,,,,,,,,,,,,,,,,,,,
,3726075562.62356,145.008743286133,9999.6572265625,-3.92126779904342E-6,1.83881703355593E-7,1,2,13.2042255401611,7.99273166352391,33.6299985647202,-0.00790970222639528,-0.00130016338363752,1000,-6.28543245551818E-8,145.008743286133,145.008743286133,9999.6572265625,9999.6572265625,50.4341893891111,5.51945206184809,5.91470766067505,26,1,0,0,1,0.463104248046875,32.2580642700195,2,1,1,145.008743286133,0,145.008743286133,,,,,,,,,,,,,,,,,,,,,,,,,,,,,,,,,
,3726075682.95473,151.007614135742,9999.6572265625,-4.06879384191821E-6,1.663178274298E-7,1,2,13.2042255401611,7.99281038512678,33.6299985647202,-0.008204038298761,-0.00137130611014244,1000,-7.62087971413629E-8,151.007614135742,151.007614135742,9999.6572265625,9999.6572265625,50.4212925185438,5.51946363789529,5.94645977020264,26,1,0,0,1,0.461883544921875,33.2355842590332,2,1,1,151.007614135742,0,151.007614135742,,,,,,,,,,,,,,,,,,,,,,,,,,,,,,,,,
,3726075803.65146,157.00163269043,9999.6572265625,-4.20478288842554E-6,1.78839124413543E-7,1,2,13.2042255401611,7.99274974066923,33.6299985647202,-0.00849006591540849,-0.00133694582447156,1000,-3.90972989105144E-8,157.00163269043,157.00163269043,9999.6572265625,9999.6572265625,50.4533392878323,5.51947817357086,5.94619607925415,26,1,0,0,1,0.461578369140625,32.2580642700195,2,1,1,157.00163269043,0,157.00163269043,,,,,,,,,,,,,,,,,,,,,,,,,,,,,,,,,
,3726075924.33085,163.018051147461,9999.6572265625,-4.29339219701901E-6,1.66337962625598E-7,1,2,13.2042255401611,7.99276741565199,33.6299985647202,-0.00864825438172162,-0.00150527847609342,1000,-1.09239627210355E-7,163.018051147461,163.018051147461,9999.6572265625,9999.6572265625,50.4267639181784,5.51961660151092,5.98144817352295,26,1,0,0,1,0.462570190429687,32.7468223571777,2,1,1,163.018051147461,0,163.018051147461,,,,,,,,,,,,,,,,,,,,,,,,,,,,,,,,,
,3726076044.16285,169.008071899414,9999.6572265625,-4.23588709861075E-6,1.84052064611426E-7,1,2,13.2042255401611,7.99274212532684,33.6299985647202,-0.00858276000097914,-0.00114478491704029,1000,6.05430035967305E-8,169.008071899414,169.008071899414,9999.6572265625,9999.6572265625,50.3845559781399,5.51969507630737,6.01037216186523,26,1,0,0,1,0.46234130859375,32.7468223571777,2,1,1,169.008071899414,0,169.008071899414,,,,,,,,,,,,,,,,,,,,,,,,,,,,,,,,,
,3726076164.50107,175.008377075195,9999.6572265625,-4.30610674653514E-6,1.86555340752508E-7,1,2,13.2042255401611,7.99275608488946,33.6299985647202,-0.00873095551820651,-0.00112383333772417,1000,8.12952103473811E-8,175.008377075195,175.008377075195,9999.6572265625,9999.6572265625,50.4013609913034,5.51987771643602,6.02581357955933,26,1,0,0,1,0.460968017578125,33.2355842590332,2,1,1,175.008377075195,0,175.008377075195,,,,,,,,,,,,,,,,,,,,,,,,,,,,,,,,,
,3726076285.41487,181.019012451172,9999.6572265625,-4.13265646098347E-6,1.91744324139953E-7,1,2,13.2042255401611,7.99272805831521,33.6299985647202,-0.00832578185763329,-0.00143997861764376,1000,-1.00727699885121E-7,181.019012451172,181.019012451172,9999.6572265625,9999.6572265625,50.503363513063,5.52003750197051,6.05160284042358,26,1,0,0,1,0.46173095703125,33.2355842590332,2,1,1,181.019012451172,0,181.019012451172,,,,,,,,,,,,,,,,,,,,,,,,,,,,,,,,,
,3726076405.1567,187.007553100586,9999.6572265625,-4.42094170998873E-6,1.73179076658572E-7,1,2,13.2042255401611,7.99273546312096,33.6299985647202,-0.00897555811913502,-0.0010741918485092,1000,1.22836639428183E-7,187.007553100586,187.007553100586,9999.6572265625,9999.6572265625,50.4889033854573,5.52001820633372,6.07051753997803,26,1,0,0,1,0.463333129882812,33.2355842590332,2,1,1,187.007553100586,0,187.007553100586,,,,,,,,,,,,,,,,,,,,,,,,,,,,,,,,,
,3726076525.67694,193.010864257813,9999.6572265625,-4.18670169987895E-6,1.79182965644312E-7,1,2,13.2042255401611,7.99269188251997,33.6400009691715,-0.00839673410910314,-0.00171501551533162,1000,-2.28760810713716E-7,193.010864257813,193.010864257813,9999.6572265625,9999.6572265625,50.4255914753996,5.51969940336706,6.09036493301392,26,1,0,0,1,0.46173095703125,32.2580642700195,2,1,1,193.010864257813,0,193.010864257813,,,,,,,,,,,,,,,,,,,,,,,,,,,,,,,,,
,3726076646.48298,199.017318725586,9999.6572265625,-4.53375264741517E-6,1.88333439415862E-7,1,2,13.2042255401611,7.9926353569542,33.6299985647202,-0.00915130716558212,-0.00146129467913984,1000,-5.19298768159359E-8,199.017318725586,199.017318725586,9999.6572265625,9999.6572265625,50.5924691642553,5.51959303830334,6.09702920913696,26,1,0,0,1,0.461502075195313,31.7693061828613,2,1,1,199.017318725586,0,199.017318725586,,,,,,,,,,,,,,,,,,,,,,,,,,,,,,,,,
,3726076766.58227,205.008834838867,9999.6572265625,-4.38225154066445E-6,1.74211626876818E-7,1,2,13.2042255401611,7.99267061607566,33.6400009691715,-0.00886010378294934,-0.00131394120505298,1000,-1.46558185522655E-9,205.008834838867,205.008834838867,9999.6572265625,9999.6572265625,50.4439597456015,5.51972100377338,6.12160778045654,26,1,0,0,1,0.460052490234375,33.2355842590332,2,1,1,205.008834838867,0,205.008834838867,,,,,,,,,,,,,,,,,,,,,,,,,,,,,,,,,
,3726076886.47054,211.033950805664,9999.6572265625,-4.45012092429759E-6,1.71673255811117E-7,1,2,13.2042255401611,7.9926103525098,33.6299985647202,-0.0089812365034836,-0.00144275659985389,1000,-5.51364033878899E-8,211.033950805664,211.033950805664,9999.6572265625,9999.6572265625,50.3994069200053,5.51983486890886,6.15320444107056,26,1,0,0,1,0.463333129882812,32.2580642700195,2,1,1,211.033950805664,0,211.033950805664,,,,,,,,,,,,,,,,,,,,,,,,,,,,,,,,,
,3726077007.14023,217.001373291016,9999.6572265625,-4.39242717403542E-6,1.50529385347251E-7,1,2,13.2042255401611,7.99258755450795,33.6299985647202,-0.00887951870456469,-0.00132446826268053,1000,-5.17027212781771E-9,217.001373291016,217.001373291016,9999.6572265625,9999.6572265625,50.4896850139765,5.5198850044045,6.15600347518921,26,1,0,0,1,0.461273193359375,32.2580642700195,2,1,1,217.038650512695,0,217.001373291016,,,,,,,,,,,,,,,,,,,,,,,,,,,,,,,,,
,3726077127.39215,223.006805419922,9999.6572265625,-4.55180937284649E-6,1.63852478682359E-7,1,2,13.2042255401611,7.99257465189328,33.6299985647202,-0.00922516013516994,-0.00121403212782289,1000,7.30307542802295E-8,223.006805419922,223.006805419922,9999.6572265625,9999.6572265625,50.422074147063,5.5196741547088,6.18083810806274,26,1,0,0,1,0.46234130859375,32.2580642700195,2,1,1,223.006805419922,0,223.006805419922,,,,,,,,,,,,,,,,,,,,,,,,,,,,,,,,,
,3726077247.44084,229.032135009766,9999.6572265625,-4.3798243016033E-6,1.72184279142062E-7,1,2,13.2042255401611,7.99252841871951,33.6299985647202,-0.00886541331436025,-0.00124355758408269,1000,3.29796033853461E-8,229.032135009766,229.032135009766,9999.6572265625,9999.6572265625,50.4259822896592,5.51937177648421,6.21228742599487,26,1,0,0,1,0.462188720703125,34.2131004333496,2,1,1,229.032135009766,0,229.032135009766,,,,,,,,,,,,,,,,,,,,,,,,,,,,,,,,,
,3726077367.94352,235.007095336914,9999.6572265625,-4.54879871092991E-6,1.66228601919362E-7,1,2,13.2042255401611,7.99248620764203,33.6400009691715,-0.00921508532160071,-0.00123969321019585,1000,5.98899955240561E-8,235.007095336914,235.007095336914,9999.6572265625,9999.6572265625,50.3732223646111,5.51979423584996,6.18679809570312,26,1,0,0,1,0.460433959960937,33.7243423461914,2,1,1,235.007095336914,0,235.007095336914,,,,,,,,,,,,,,,,,,,,,,,,,,,,,,,,,
,3726077488.15258,241.004638671875,9999.6572265625,-4.49034542394132E-6,1.79542781701194E-7,1,2,13.2042255401611,7.99248375300483,33.6299985647202,-0.00913774093216702,-0.000946158149374253,1000,1.96419927228662E-7,241.004638671875,241.004638671875,9999.6572265625,9999.6572265625,50.4240282183611,5.51975429629832,6.23950338363647,26,1,0,0,1,0.462570190429687,31.7693061828613,2,1,1,241.004638671875,0,241.004638671875,,,,,,,,,,,,,,,,,,,,,,,,,,,,,,,,,
,3726077608.48732,247.000030517578,9999.6572265625,-4.37845479601173E-6,1.93070724128886E-7,1,2,13.2042255401611,7.99235411951726,33.6299985647202,-0.00880324671298288,-0.00164386209685939,1000,-1.65217599438662E-7,247.000030517578,247.000030517578,9999.6572265625,9999.6572265625,50.4846044286015,5.51991064230643,6.26627922058105,26,1,0,0,1,0.463409423828125,32.2580642700195,2,1,1,247.000030517578,0,247.000030517578,,,,,,,,,,,,,,,,,,,,,,,,,,,,,,,,,
,3726077728.64887,253.005157470703,9999.6572265625,-4.62469160342046E-6,1.87629280528898E-7,1,2,13.2042255401611,7.99235422920063,33.6299985647202,-0.0093550477287626,-0.00135294556275979,1000,1.50996309895108E-8,253.005157470703,253.005157470703,9999.6572265625,9999.6572265625,50.4330169463323,5.51977662914242,6.37072563171387,26,1,0,0,1,0.463714599609375,31.2805480957031,2,1,1,253.005157470703,0,253.005157470703,,,,,,,,,,,,,,,,,,,,,,,,,,,,,,,,,
,3726077848.58033,259.003814697266,9999.6572265625,-4.42609218844354E-6,1.85947303671893E-7,1,2,13.2042255401611,7.99230516700126,33.6299985647202,-0.00894681955359347,-0.00133851170058347,1000,-7.14789900041507E-9,259.003814697266,259.003814697266,9999.6572265625,9999.6572265625,50.4517760307938,5.5196908470398,6.39560794830322,26,1,0,0,1,0.4632568359375,32.7468223571777,2,1,1,259.003814697266,0,259.003814697266,,,,,,,,,,,,,,,,,,,,,,,,,,,,,,,,,
,3726077969.54174,265.003997802734,9999.6572265625,-4.52930094489729E-6,1.79998385355331E-7,1,2,13.2042255401611,7.99242846264818,33.6299985647202,-0.00913425079921245,-0.0015135011901196,1000,-7.84196469118482E-8,265.003997802734,265.003997802734,9999.6572265625,9999.6572265625,50.4005793627842,5.51931309208535,6.37326955795288,26,1,0,0,1,0.463104248046875,32.7468223571777,2,1,1,265.003997802734,0,265.003997802734,,,,,,,,,,,,,,,,,,,,,,,,,,,,,,,,,
,3726078089.44198,271.010559082031,9999.6572265625,-4.43020704279712E-6,1.7493744312481E-7,1,2,13.2042255401611,7.99242819738289,33.6299985647202,-0.00897653573991449,-0.00119565659047609,1000,6.41211024287991E-8,271.010559082031,271.010559082031,9999.6572265625,9999.6572265625,50.4216833328034,5.52007525092564,6.38220500946045,26,1,0,0,1,0.463027954101562,33.2355842590332,2,1,1,271.010559082031,0,271.010559082031,,,,,,,,,,,,,,,,,,,,,,,,,,,,,,,,,
,3726078209.42287,277.004455566406,9999.6572265625,-4.48741303612288E-6,1.97848823549975E-7,1,2,13.2042255401611,7.99236541236593,33.6299985647202,-0.00905063054539756,-0.00149345047501135,1000,-7.47036158430757E-8,277.004455566406,277.004455566406,9999.6572265625,9999.6572265625,50.4541209163515,5.52003761429184,6.4394645690918,26,1,0,0,1,0.464019775390625,33.2355842590332,2,1,1,277.004455566406,0,277.004455566406,,,,,,,,,,,,,,,,,,,,,,,,,,,,,,,,,
,3726078329.86047,283.005249023438,9999.6572265625,-4.43354460686437E-6,2.05547222720168E-7,1,2,13.2042255401611,7.9923075610443,33.6400009691715,-0.00895276281597612,-0.00140242146489983,1000,-3.7654471729793E-8,283.005249023438,283.005249023438,9999.6572265625,9999.6572265625,50.4388791602265,5.51979736915902,6.60095596313477,26,1,0,0,1,0.460357666015625,33.2355842590332,2,1,1,283.005249023438,0,283.005249023438,,,,,,,,,,,,,,,,,,,,,,,,,,,,,,,,,
,3726078450.29685,289.002319335937,9999.6572265625,-4.57758247828522E-6,1.88644561398304E-7,1,2,13.2042255401611,7.99222239264252,33.6299985647202,-0.00930397706289517,-0.00103968273802345,1000,1.6306190184554E-7,289.002319335937,289.002319335937,9999.6572265625,9999.6572265625,50.3489918805149,5.52005384781412,6.83538341522217,26,1,0,0,1,0.463104248046875,31.7693061828613,2,1,1,289.002319335937,0,289.002319335937,,,,,,,,,,,,,,,,,,,,,,,,,,,,,,,,,
,3726078571.00329,295.001586914063,9999.6572265625,-4.57262029333954E-6,1.77467499466415E-7,1,2,13.2042255401611,7.99206088940523,33.6299985647202,-0.00922364129313018,-0.00151264257956094,1000,-7.16046394971426E-8,295.001586914063,295.001586914063,9999.6572265625,9999.6572265625,50.5174328264092,5.52051133132239,7.20757389068604,26,1,0,0,1,0.463790893554687,31.2805480957031,2,1,1,295.001586914063,0,295.001586914063,,,,,,,,,,,,,,,,,,,,,,,,,,,,,,,,,
,3726078730.16315,299.905822753906,9999.6572265625,-4.540188308795E-6,2.00171916372078E-7,1,2,13.2042255401611,7.99189879068451,33.6299985647202,-0.00922987984607366,-0.00101688115903941,1000,1.6879547120381E-7,299.905822753906,299.905822753906,9999.6572265625,9999.6572265625,50.4924207137938,5.52078249602492,7.65848445892334,26,1,0,0,1,0.4644775390625,33.2355842590332,1,1,1,299.905822753906,0,299.905822753906,,,,,,,,,,,,,,,,,,,,,,,,,,,,,,,,,