File: data/161117-cernox calibration/161117_RT_sensor-calibration.dat
[Header]
TITLE, sensor calibration
FILEOPENTIME, 27913873.48, 11/18/2016, 5:44 PM
BYAPP, Resistivity, 2.0, 1.0
INFO, APPNAME, PPMS MultiVu Application, Release 1.5.0.19
INFO, , Sample1 Name
INFO, 1, Sample1 Cross Section
INFO, 1, Sample1 Length
INFO, Ohm-m, Sample1 Units
INFO, cernox r07 c12, Sample2 Name
INFO, 1, Sample2 Cross Section
INFO, 1, Sample2 Length
INFO, Ohm-m, Sample2 Units
INFO, , Sample3 Name
INFO, 1, Sample3 Cross Section
INFO, 1, Sample3 Length
INFO, Ohm-m, Sample3 Units
INFO, , Sample4 Name
INFO, 1, Sample4 Cross Section
INFO, 1, Sample4 Length
INFO, Ohm-m, Sample4 Units
FIELDGROUP, Resistivity,2,3,4,5,6,7,8,9,10,11,12,13,14,15,16,17,18,19,20,21,22,23,24,25,26,27,28,29,30,31,32,33,34,35,36,37,38,39,40,41
STARTUPGROUP, Resistivity
STARTUPAXIS, X, 2, LINEAR, AUTO
STARTUPAXIS, Y1, 7, LINEAR, AUTO
STARTUPAXIS, Y2, 9, LINEAR, AUTO
STARTUPAXIS, Y3, 11, LINEAR, AUTO
PLOT_APPEARANCE, ALL, HORZ_GRID_ON, VERT_GRID_ON, MARKERS_AND_LINES, ALL_LINES
DATATYPE, TIME, 2
DATATYPE, COMMENT, 1
[Data]
Comment,Time Stamp (sec),Status (code),Temperature (K),Magnetic Field (Oe),Sample Position (deg),Bridge 1 Resistivity (Ohm-m),Bridge 1 Excitation (uA),Bridge 2 Resistivity (Ohm-m),Bridge 2 Excitation (uA),Bridge 3 Resistivity (Ohm-m),Bridge 3 Excitation (uA),Bridge 4 Resistivity (Ohm-m),Bridge 4 Excitation (uA),Bridge 1 Std. Dev. (Ohm-m),Bridge 2 Std. Dev. (Ohm-m),Bridge 3 Std. Dev. (Ohm-m),Bridge 4 Std. Dev. (Ohm-m),Number of Readings,Bridge 1 Resistance (Ohms),Bridge 2 Resistance (Ohms),Bridge 3 Resistance (Ohms),Bridge 4 Resistance (Ohms),Signal 1 Vin (V),Signal 2 Vin (V),Digital Inputs (code),Drive 1 Iout (mA),Drive 1 Ipower (watts),Drive 2 Iout (mA),Drive 2 Ipower (watts),Pressure (),Map 20 (),Map 21 (),Map 22 (),Map 23 (),Map 24 (),Map 25 (),Map 26 (),Map 27 (),Map 28 (),Map 29 ()
,27915314.30,4369,300.000411987305,-0.112000003457069,284.35400390625,,,0.0368143841552734,99.9020004272461,,,,,,2.73945016918054e-007,,,25,,36.8143841552734,,
,27916037.33,4369,292.863662719727,-0.112000003457069,284.35400390625,,,0.0374010470581055,99.9020004272461,,,,,,1.90772853638978e-007,,,25,,37.4010470581055,,
,27916758.98,4369,285.719497680664,-0.112000003457069,284.35400390625,,,0.0380136909484863,99.9020004272461,,,,,,3.51158940437769e-007,,,25,,38.0136909484863,,
,27917479.91,4369,278.576553344727,-0.112000003457069,284.35400390625,,,0.0386569635009766,99.9020004272461,,,,,,3.36322232763562e-007,,,25,,38.6569635009766,,
,27918201.78,4369,271.430999755859,-0.112000003457069,284.35400390625,,,0.039332847442627,99.9020004272461,,,,,,3.62932714998432e-007,,,25,,39.332847442627,,
,27918923.84,4369,264.283538818359,-0.112000003457069,284.35400390625,,,0.0400455390930176,99.9020004272461,,,,,,4.46227445533543e-007,,,25,,40.0455390930176,,
,27919645.78,4369,257.14045715332,-0.112000003457069,284.35400390625,,,0.0407950674438477,99.9020004272461,,,,,,4.83697018521197e-007,,,25,,40.7950674438477,,
,27920365.17,4369,249.994750976563,-0.112000003457069,284.35400390625,,,0.041579620513916,99.9020004272461,,,,,,3.38824509261409e-007,,,25,,41.579620513916,,
,27921083.88,4369,242.854301452637,-0.112000003457069,284.35400390625,,,0.0424084704589844,99.9020004272461,,,,,,5.31948065061468e-007,,,25,,42.4084704589844,,
,27921807.02,4369,235.713050842285,-0.112000003457069,284.35400390625,,,0.0432822532653809,99.9020004272461,,,,,,2.96860075024467e-007,,,25,,43.2822532653809,,
,27922524.20,4369,228.568901062012,-0.112000003457069,284.35400390625,,,0.0442026597595215,99.9020004272461,,,,,,4.35460283981338e-007,,,25,,44.2026597595215,,
,27923244.83,4369,221.426200866699,-0.112000003457069,284.35400390625,,,0.0451761097717285,99.9020004272461,,,,,,3.31944975545198e-007,,,25,,45.1761097717285,,
,27923966.50,4369,214.283950805664,-0.112000003457069,284.35400390625,,,0.0462050132751465,99.9020004272461,,,,,,4.35209739606093e-007,,,25,,46.2050132751465,,
,27924688.28,4369,207.143600463867,-0.112000003457069,284.35400390625,,,0.0472941398620606,99.9020004272461,,,,,,3.44294727354229e-007,,,25,,47.2941398620605,,
,27925411.03,4369,200.000801086426,-0.112000003457069,284.35400390625,,,0.0484452737426758,99.9020004272461,,,,,,3.05522070428367e-007,,,25,,48.4452737426758,,
,27926132.36,4369,192.858749389648,-0.112000003457069,284.35400390625,,,0.0496725845336914,99.9020004272461,,,,,,4.42405671598248e-007,,,25,,49.6725845336914,,
,27926850.78,4369,185.717102050781,-0.112000003457069,284.35400390625,,,0.050977540435791,99.9020004272461,,,,,,5.4224172487826e-007,,,25,,50.977540435791,,
,27927569.22,4369,178.57349395752,-0.112000003457069,284.35400390625,,,0.0523658734130859,99.9020004272461,,,,,,4.1359688466994e-007,,,25,,52.3658734130859,,
,27928290.70,4369,171.43244934082,-0.112000003457069,284.35400390625,,,0.0538468243408203,99.9020004272461,,,,,,4.04325412673316e-007,,,25,,53.8468243408203,,
,27929008.52,4369,164.287498474121,-0.112000003457069,284.35400390625,,,0.0554284367370605,99.9020004272461,,,,,,3.84592247944706e-007,,,25,,55.4284367370605,,
,27929730.53,4369,157.144248962402,-0.112000003457069,284.35400390625,,,0.0571281997680664,99.9020004272461,,,,,,4.42703576031012e-007,,,25,,57.1281997680664,,
,27930451.03,4369,150.002349853516,-0.112000003457069,284.35400390625,,,0.0589477449035644,99.9020004272461,,,,,,3.94210265148474e-007,,,25,,58.9477449035645,,
,27931173.27,4369,142.859855651855,-0.112000003457069,284.35400390625,,,0.0609061622619629,99.9020004272461,,,,,,4.02010003846207e-007,,,25,,60.9061622619629,,
,27931895.69,4369,135.716354370117,-0.112000003457069,284.35400390625,,,0.0630216983032227,99.9020004272461,,,,,,3.58071426998751e-007,,,25,,63.0216983032227,,
,27932613.61,4369,128.572799682617,-0.112000003457069,284.35400390625,,,0.0653066500854492,99.9020004272461,,,,,,3.83566985963429e-007,,,25,,65.3066500854492,,
,27933332.58,4369,121.429401397705,-0.112000003457069,284.35400390625,,,0.0677918035888672,99.9020004272461,,,,,,3.67046266774434e-007,,,25,,67.7918035888672,,
,27934050.55,4369,114.287300109863,-0.112000003457069,284.35400390625,,,0.0705022415161133,99.9020004272461,,,,,,3.59245535922868e-007,,,25,,70.5022415161133,,
,27934774.05,4369,107.144302368164,-0.112000003457069,284.35400390625,,,0.0734642578125,99.9020004272461,,,,,,3.21091607407807e-007,,,25,,73.4642578125,,
,27935496.55,4369,100.002250671387,-0.112000003457069,284.35400390625,,,0.0767204211425781,99.9020004272461,,,,,,3.46236625056988e-007,,,25,,76.7204211425781,,
,27935901.73,4369,100.000297546387,-0.112000003457069,284.35400390625,,,0.0767028823852539,99.9020004272461,,,,,,3.23695895359325e-007,,,25,,76.7028823852539,,
,27936275.11,4369,98.9765472412109,-0.112000003457069,284.35400390625,,,0.0772188024902344,99.9020004272461,,,,,,4.8660067148712e-007,,,25,,77.2188024902344,,
,27936643.53,4369,97.9507522583008,-0.112000003457069,284.35400390625,,,0.0777180456542969,99.9020004272461,,,,,,4.09069062659215e-007,,,25,,77.7180456542969,,
,27937011.31,4369,96.9263000488281,-0.112000003457069,284.35400390625,,,0.0782297872924805,99.9020004272461,,,,,,4.43942041477194e-007,,,25,,78.2297872924805,,
,27937378.48,4369,95.9000511169434,-0.112000003457069,284.35400390625,,,0.0787503381347656,99.9020004272461,,,,,,3.73427836002633e-007,,,25,,78.7503381347656,,
,27937747.34,4369,94.873950958252,-0.112000003457069,284.35400390625,,,0.0792811911010742,99.9020004272461,,,,,,4.12736695805447e-007,,,25,,79.2811911010742,,
,27938114.91,4369,93.8498001098633,-0.112000003457069,284.35400390625,,,0.0798120703125,99.9020004272461,,,,,,4.20890833833446e-007,,,25,,79.8120703125,,
,27938488.50,4369,92.8217468261719,-0.112000003457069,284.35400390625,,,0.0803600598144532,99.9020004272461,,,,,,4.13542880339117e-007,,,25,,80.3600598144531,,
,27938860.84,4369,91.7975006103516,-0.112000003457069,284.35400390625,,,0.0809086898803711,99.9020004272461,,,,,,4.5604100193913e-007,,,25,,80.9086898803711,,
,27939234.31,4369,90.7700004577637,-0.112000003457069,284.35400390625,,,0.0814672036743164,99.9020004272461,,,,,,3.54282256265117e-007,,,25,,81.4672036743164,,
,27939617.48,4369,89.7462501525879,-0.112000003457069,284.35400390625,,,0.0820403457641602,99.9020004272461,,,,,,3.85250225741852e-007,,,25,,82.0403457641602,,
,27940016.45,4369,88.7199020385742,-0.112000003457069,284.35400390625,,,0.082619333190918,99.9020004272461,,,,,,4.72175952987328e-007,,,25,,82.619333190918,,
,27940414.41,4369,87.6939010620117,-0.112000003457069,284.35400390625,,,0.0832070983886719,99.9020004272461,,,,,,3.86818527762541e-007,,,25,,83.2070983886719,,
,27940832.14,4369,86.6698989868164,-0.112000003457069,284.35400390625,,,0.0838083200073242,99.9020004272461,,,,,,3.16811246007054e-007,,,25,,83.8083200073242,,
,27941251.02,4369,85.6442985534668,-0.112000003457069,284.35400390625,,,0.0844162814331055,99.9020004272461,,,,,,3.34579498218673e-007,,,25,,84.4162814331055,,
,27941665.75,4369,84.6161499023438,-0.112000003457069,284.35400390625,,,0.0850337097167969,99.9020004272461,,,,,,4.12802887409829e-007,,,25,,85.0337097167969,,
,27942084.80,4369,83.5879020690918,-0.112000003457069,284.35400390625,,,0.0856658532714844,99.9020004272461,,,,,,3.42398816170854e-007,,,25,,85.6658532714844,,
,27942503.83,4369,82.5635528564453,-0.112000003457069,284.35400390625,,,0.0863132901000977,99.9020004272461,,,,,,4.95256119397354e-007,,,25,,86.3132901000977,,
,27942928.11,4369,81.5386505126953,-0.112000003457069,284.35400390625,,,0.0869692572021484,99.9020004272461,,,,,,5.07005714087322e-007,,,25,,86.9692572021484,,
,27943351.34,4369,80.5151977539063,-0.112000003457069,284.35400390625,,,0.087637445678711,99.9020004272461,,,,,,3.46622197711217e-007,,,25,,87.6374456787109,,
,27943777.22,4369,79.486198425293,-0.112000003457069,284.35400390625,,,0.0883199844360352,99.9020004272461,,,,,,3.86063257732089e-007,,,25,,88.3199844360352,,
,27944202.89,4369,78.4612007141113,-0.112000003457069,284.35400390625,,,0.0890123526000976,99.9020004272461,,,,,,4.27445610700657e-007,,,25,,89.0123526000977,,
,27944627.61,4369,77.4345016479492,-0.112000003457069,284.35400390625,,,0.0897200375366211,99.9020004272461,,,,,,3.8503628102288e-007,,,25,,89.7200375366211,,
,27945037.81,4369,76.4127006530762,-0.112000003457069,284.35400390625,,,0.0904430981445313,99.9020004272461,,,,,,4.00050476469148e-007,,,25,,90.4430981445312,,
,27945448.31,4369,75.3870964050293,-0.112000003457069,284.35400390625,,,0.0911805056762695,99.9020004272461,,,,,,3.89542297238176e-007,,,25,,91.1805056762695,,
,27945858.13,4369,74.361198425293,-0.112000003457069,284.35400390625,,,0.0919287158203125,99.9020004272461,,,,,,3.48048093014365e-007,,,25,,91.9287158203125,,
,27946267.73,4369,73.3327522277832,-0.112000003457069,284.35400390625,,,0.0926964010620117,99.9020004272461,,,,,,4.90311042293328e-007,,,25,,92.6964010620117,,
,27946678.48,4369,72.3105506896973,-0.112000003457069,284.35400390625,,,0.0934713229370117,99.9020004272461,,,,,,3.1867839031555e-007,,,25,,93.4713229370117,,
,27947088.86,4369,71.2808532714844,-0.112000003457069,284.35400390625,,,0.0942690371704101,99.9020004272461,,,,,,4.36701912126551e-007,,,25,,94.2690371704102,,
,27947493.64,4369,70.2565498352051,-0.112000003457069,284.35400390625,,,0.0951021380615235,99.9020004272461,,,,,,4.43595854318854e-006,,,25,,95.1021380615234,,
,27947899.09,4369,69.2356491088867,-0.112000003457069,284.35400390625,,,0.0959328216552734,99.9020004272461,,,,,,4.49475861575655e-006,,,25,,95.9328216552734,,
,27948305.48,4369,68.2036018371582,-0.112000003457069,284.35400390625,,,0.0967817669677734,99.9020004272461,,,,,,3.72077856811967e-006,,,25,,96.7817669677734,,
,27948717.23,4369,67.1802024841309,-0.112000003457069,284.35400390625,,,0.0976485650634766,99.9020004272461,,,,,,3.07716955676936e-006,,,25,,97.6485650634766,,
,27949128.00,4369,66.1566505432129,-0.112000003457069,284.35400390625,,,0.0985320748901367,99.9020004272461,,,,,,3.86115759142704e-006,,,25,,98.5320748901367,,
,27949533.59,4369,65.1286010742188,-0.112000003457069,284.35400390625,,,0.0994363250732422,99.9020004272461,,,,,,2.90709205167301e-006,,,25,,99.4363250732422,,
,27949940.58,4369,64.1030502319336,-0.112000003457069,284.35400390625,,,0.10036118560791,99.9020004272461,,,,,,3.36943626608026e-006,,,25,,100.36118560791,,
,27950345.34,4369,63.0792999267578,-0.112000003457069,284.35400390625,,,0.101309729309082,99.9020004272461,,,,,,3.0778225802346e-006,,,25,,101.309729309082,,
,27950750.31,4369,62.0516014099121,-0.112000003457069,284.35400390625,,,0.102280592041016,99.9020004272461,,,,,,3.02545065861575e-006,,,25,,102.280592041016,,
,27951156.20,4369,61.0291996002197,-0.112000003457069,284.35400390625,,,0.103270569763184,99.9020004272461,,,,,,2.92653237537916e-006,,,25,,103.270569763184,,
,27951560.81,4369,60.0002994537354,-0.112000003457069,284.35400390625,,,0.10428489074707,99.9020004272461,,,,,,3.16971803912655e-006,,,25,,104.28489074707,,
,27951965.66,4369,60.002950668335,-0.112000003457069,284.35400390625,,,0.104290883483887,99.9020004272461,,,,,,3.7216447150978e-006,,,25,,104.290883483887,,
,27952364.86,4369,59.4992008209229,-0.112000003457069,284.35400390625,,,0.104801284179688,99.9020004272461,,,,,,3.40940467999852e-006,,,25,,104.801284179688,,
,27952763.86,4369,58.9867992401123,-0.112000003457069,284.35400390625,,,0.105321336364746,99.9020004272461,,,,,,4.31247950246765e-006,,,25,,105.321336364746,,
,27953163.88,4369,58.4804992675781,-0.112000003457069,284.35400390625,,,0.105840989990234,99.9020004272461,,,,,,3.78149422557065e-006,,,25,,105.840989990234,,
,27953563.05,4369,57.9767990112305,-0.112000003457069,284.35400390625,,,0.106370938110352,99.9020004272461,,,,,,3.68942236016866e-006,,,25,,106.370938110352,,
,27953964.67,4369,57.4702491760254,-0.112000003457069,284.35400390625,,,0.106909354553223,99.9020004272461,,,,,,2.56102667375491e-006,,,25,,106.909354553223,,
,27954365.94,4369,56.9591503143311,-0.112000003457069,284.35400390625,,,0.107449495849609,99.9020004272461,,,,,,4.11333415492642e-006,,,25,,107.449495849609,,
,27954766.11,4369,56.4572010040283,-0.112000003457069,284.35400390625,,,0.108001357421875,99.9020004272461,,,,,,3.9064829129156e-006,,,25,,108.001357421875,,
,27955162.77,4369,55.9520492553711,-0.112000003457069,284.35400390625,,,0.108557749023438,99.9020004272461,,,,,,4.07552100526373e-006,,,25,,108.557749023437,,
,27955557.02,4369,55.4460506439209,-0.112000003457069,284.35400390625,,,0.109123116760254,99.9020004272461,,,,,,3.96880708456218e-006,,,25,,109.123116760254,,
,27955951.73,4369,54.9393997192383,-0.112000003457069,284.35400390625,,,0.109698285217285,99.9020004272461,,,,,,3.97043381644243e-006,,,25,,109.698285217285,,
,27956325.06,4369,54.4305000305176,-0.112000003457069,284.35400390625,,,0.110275239562988,99.9020004272461,,,,,,3.82314348736632e-006,,,25,,110.275239562988,,
,27956699.52,4369,53.9244995117188,-0.112000003457069,284.35400390625,,,0.110858283996582,99.9020004272461,,,,,,4.02279824375113e-006,,,25,,110.858283996582,,
,27957072.86,4369,53.4184989929199,-0.112000003457069,284.35400390625,,,0.111453676757813,99.9020004272461,,,,,,3.20781078962491e-006,,,25,,111.453676757813,,
,27957448.20,4369,52.9113006591797,-0.112000003457069,284.35400390625,,,0.112055901794434,99.9020004272461,,,,,,4.15768120543353e-006,,,25,,112.055901794434,,
,27957823.23,4369,52.4097003936768,-0.112000003457069,284.35400390625,,,0.112668591308594,99.9020004272461,,,,,,3.85818561345419e-006,,,25,,112.668591308594,,
,27958197.42,4369,51.9017505645752,-0.112000003457069,284.35400390625,,,0.113286641845703,99.9020004272461,,,,,,2.80705289833166e-006,,,25,,113.286641845703,,
,27958575.08,4369,51.3905010223389,-0.112000003457069,284.35400390625,,,0.11390903717041,99.9020004272461,,,,,,3.49433396629201e-006,,,25,,113.90903717041,,
,27958951.06,4369,50.885799407959,-0.112000003457069,284.35400390625,,,0.114550686340332,99.9020004272461,,,,,,2.91524912421317e-006,,,25,,114.550686340332,,
,27959325.02,4369,50.38210105896,-0.112000003457069,284.35400390625,,,0.115192436218262,99.9020004272461,,,,,,4.69279500254022e-006,,,25,,115.192436218262,,
,27959699.56,4369,49.8739986419678,-0.112000003457069,284.35400390625,,,0.115844347839355,99.9020004272461,,,,,,4.76258131546139e-006,,,25,,115.844347839355,,
,27960074.42,4369,49.3676509857178,-0.112000003457069,284.35400390625,,,0.116501672668457,99.9020004272461,,,,,,3.32478637311018e-006,,,25,,116.501672668457,,
,27960448.53,4369,48.8631496429443,-0.112000003457069,284.35400390625,,,0.117185913696289,99.9020004272461,,,,,,3.76253582462683e-006,,,25,,117.185913696289,,
,27960824.09,4369,48.3561496734619,-0.112000003457069,284.35400390625,,,0.117864876098633,99.9020004272461,,,,,,3.39306007023896e-006,,,25,,117.864876098633,,
,27961198.08,4369,47.8488502502441,-0.112000003457069,284.35400390625,,,0.118554968261719,99.9020004272461,,,,,,3.13411674990422e-006,,,25,,118.554968261719,,
,27961572.05,4369,47.3437995910645,-0.112000003457069,284.35400390625,,,0.119253805847168,99.9020004272461,,,,,,3.68502841941615e-006,,,25,,119.253805847168,,
,27961950.70,4369,46.835599899292,-0.112000003457069,284.35400390625,,,0.119968344726562,99.9020004272461,,,,,,3.54100576065077e-006,,,25,,119.968344726563,,
,27962325.16,4369,46.3344993591309,-0.112000003457069,284.35400390625,,,0.120694929504395,99.9020004272461,,,,,,2.44085912876858e-006,,,25,,120.694929504395,,
,27962699.55,4369,45.8250484466553,-0.112000003457069,284.35400390625,,,0.121430686645508,99.9020004272461,,,,,,2.42126531851411e-006,,,25,,121.430686645508,,
,27963079.19,4369,45.3177509307861,-0.112000003457069,284.35400390625,,,0.122169250793457,99.9020004272461,,,,,,4.51906676944714e-006,,,25,,122.169250793457,,
,27963457.97,4369,44.8088512420654,-0.112000003457069,284.35400390625,,,0.122927719421387,99.9020004272461,,,,,,3.63318449999815e-006,,,25,,122.927719421387,,
,27963837.05,4369,44.3050003051758,-0.112000003457069,284.35400390625,,,0.123700343933105,99.9020004272461,,,,,,3.12749741071335e-006,,,25,,123.700343933105,,
,27964217.38,4369,43.798900604248,-0.112000003457069,284.35400390625,,,0.12448407623291,99.9020004272461,,,,,,3.77913395867714e-006,,,25,,124.48407623291,,
,27964597.16,4369,43.293098449707,-0.112000003457069,284.35400390625,,,0.125278979187012,99.9020004272461,,,,,,4.20789390212641e-006,,,25,,125.278979187012,,
,27964976.38,4369,42.7858486175537,-0.112000003457069,284.35400390625,,,0.12607338104248,99.9020004272461,,,,,,4.07807003205089e-006,,,25,,126.07338104248,,
,27965356.22,4369,42.2779998779297,-0.112000003457069,284.35400390625,,,0.126899493408203,99.9020004272461,,,,,,2.84573411688594e-006,,,25,,126.899493408203,,
,27965736.23,4369,41.7715492248535,-0.112000003457069,284.35400390625,,,0.127732065734863,99.9020004272461,,,,,,3.4123343946868e-006,,,25,,127.732065734863,,
,27966115.41,4369,41.2679996490479,-0.112000003457069,284.35400390625,,,0.128580595092773,99.9020004272461,,,,,,3.45562996306414e-006,,,25,,128.580595092773,,
,27966494.61,4369,40.7613010406494,-0.112000003457069,284.35400390625,,,0.129434077148438,99.9020004272461,,,,,,2.5443712284843e-006,,,25,,129.434077148438,,
,27966876.11,4369,40.2570991516113,-0.112000003457069,284.35400390625,,,0.130311813964844,99.9020004272461,,,,,,3.48934789948621e-006,,,25,,130.311813964844,,
,27967256.11,4369,39.7472991943359,-0.112000003457069,284.35400390625,,,0.131203253173828,99.9020004272461,,,,,,3.19470685601071e-006,,,25,,131.203253173828,,
,27967640.73,4369,39.2409496307373,-0.112000003457069,284.35400390625,,,0.132109649047852,99.9020004272461,,,,,,2.71174651147533e-006,,,25,,132.109649047852,,
,27968021.67,4369,38.7349510192871,-0.112000003457069,284.35400390625,,,0.1330304296875,99.9020004272461,,,,,,2.86426982191359e-006,,,25,,133.0304296875,,
,27968406.25,4369,38.2290992736816,-0.112000003457069,284.35400390625,,,0.133974259033203,99.9020004272461,,,,,,3.13506363982695e-006,,,25,,133.974259033203,,
,27968791.56,4369,37.7242984771729,-0.112000003457069,284.35400390625,,,0.134930209350586,99.9020004272461,,,,,,3.16996375834894e-006,,,25,,134.930209350586,,
,27969177.23,4369,37.21875,-0.112000003457069,284.35400390625,,,0.135901663818359,99.9020004272461,,,,,,3.82867152185059e-006,,,25,,135.901663818359,,
,27969562.92,4369,36.7145500183105,-0.112000003457069,284.35400390625,,,0.136896759643555,99.9020004272461,,,,,,3.36616260466926e-006,,,25,,136.896759643555,,
,27969948.58,4369,36.2034015655518,-0.112000003457069,284.35400390625,,,0.137914030151367,99.9020004272461,,,,,,3.55112503889775e-006,,,25,,137.914030151367,,
,27970333.23,4369,35.6949996948242,-0.112000003457069,284.35400390625,,,0.138942271728516,99.9020004272461,,,,,,3.27416143684746e-006,,,25,,138.942271728516,,
,27970720.05,4369,35.1914005279541,-0.112000003457069,284.35400390625,,,0.139990322875977,99.9020004272461,,,,,,4.069525008441e-006,,,25,,139.990322875977,,
,27971104.64,4369,34.6821994781494,-0.112000003457069,284.35400390625,,,0.141046810302734,99.9020004272461,,,,,,4.4928757813242e-006,,,25,,141.046810302734,,
,27971489.28,4369,34.1758995056152,-0.112000003457069,284.35400390625,,,0.142134723510742,99.9020004272461,,,,,,4.31356565971789e-006,,,25,,142.134723510742,,
,27971874.98,4369,33.6735496520996,-0.112000003457069,284.35400390625,,,0.143240424194336,99.9020004272461,,,,,,3.45570727007617e-006,,,25,,143.240424194336,,
,27972259.95,4369,33.1671009063721,-0.112000003457069,284.35400390625,,,0.144371802978516,99.9020004272461,,,,,,3.65991524081919e-006,,,25,,144.371802978516,,
,27972648.78,4369,32.6699504852295,-0.112000003457069,284.35400390625,,,0.145497875366211,99.9020004272461,,,,,,3.52197532896992e-006,,,25,,145.497875366211,,
,27973038.39,4369,32.170051574707,-0.112000003457069,284.35400390625,,,0.146680455322266,99.9020004272461,,,,,,4.29570919712407e-006,,,25,,146.680455322266,,
,27973428.34,4369,31.658299446106,-0.112000003457069,284.35400390625,,,0.147913436889648,99.9020004272461,,,,,,3.44237435024257e-006,,,25,,147.913436889648,,
,27973818.30,4369,31.1585998535156,-0.112000003457069,284.35400390625,,,0.14911119140625,99.9020004272461,,,,,,4.09719952859485e-006,,,25,,149.11119140625,,
,27974213.13,4369,30.6316499710083,-0.112000003457069,284.35400390625,,,0.150416389770508,99.9020004272461,,,,,,4.06764940686695e-006,,,25,,150.416389770508,,
,27974537.69,4369,30.1315994262695,-0.112000003457069,284.35400390625,,,0.151649613037109,99.9020004272461,,,,,,4.88053763874405e-006,,,25,,151.649613037109,,
,27974931.88,4369,29.6199493408203,-0.112000003457069,284.35400390625,,,0.153010802001953,99.9020004272461,,,,,,2.50656054613118e-006,,,25,,153.010802001953,,
,27975256.09,4369,29.1147003173828,-0.112000003457069,284.35400390625,,,0.154328116455078,99.9020004272461,,,,,,3.39544373253835e-006,,,25,,154.328116455078,,
,27975579.77,4369,28.6077499389648,-0.112000003457069,284.35400390625,,,0.155724736938477,99.9020004272461,,,,,,3.30944870815197e-006,,,25,,155.724736938477,,
,27975903.30,4369,28.1020498275757,-0.112000003457069,284.35400390625,,,0.157108460693359,99.9020004272461,,,,,,4.31537055744518e-006,,,25,,157.108460693359,,
,27976226.47,4369,27.5960006713867,-0.112000003457069,284.35400390625,,,0.1585575390625,99.9020004272461,,,,,,3.87020595568897e-006,,,25,,158.5575390625,,
,27976549.30,4369,27.0881500244141,-0.112000003457069,284.35400390625,,,0.160018094482422,99.9020004272461,,,,,,3.36348021379385e-006,,,25,,160.018094482422,,
,27976872.70,4369,26.586049079895,-0.112000003457069,284.35400390625,,,0.161527640991211,99.9020004272461,,,,,,3.48469347546758e-006,,,25,,161.527640991211,,
,27977196.13,4369,26.0889501571655,-0.112000003457069,284.35400390625,,,0.16303568359375,99.9020004272461,,,,,,4.92071753886226e-006,,,25,,163.03568359375,,
,27977519.77,4369,25.5743494033813,-0.112000003457069,284.35400390625,,,0.164692725830078,99.9020004272461,,,,,,3.33193950297889e-006,,,25,,164.692725830078,,
,27977842.73,4369,25.0566005706787,-0.112000003457069,284.35400390625,,,0.166332088012695,99.9020004272461,,,,,,3.417839652065e-006,,,25,,166.332088012695,,
,27978166.88,4369,24.5560503005981,-0.112000003457069,284.35400390625,,,0.167969221801758,99.9020004272461,,,,,,3.4550847489225e-006,,,25,,167.969221801758,,
,27978491.19,4369,24.0495500564575,-0.112000003457069,284.35400390625,,,0.169675211791992,99.9020004272461,,,,,,4.02505204669356e-006,,,25,,169.675211791992,,
,27978815.06,4369,23.5417499542236,-0.112000003457069,284.35400390625,,,0.171435124511719,99.9020004272461,,,,,,2.95790688824381e-006,,,25,,171.435124511719,,
,27979139.58,4369,23.0378494262695,-0.112000003457069,284.35400390625,,,0.173234276123047,99.9020004272461,,,,,,3.69896659365976e-006,,,25,,173.234276123047,,
,27979463.94,4369,22.5324506759644,-0.112000003457069,284.35400390625,,,0.175089459838867,99.9020004272461,,,,,,3.4742446587348e-006,,,25,,175.089459838867,,
,27979787.95,4369,22.0257997512817,-0.112000003457069,284.35400390625,,,0.17702741027832,99.9020004272461,,,,,,3.74170316192309e-006,,,25,,177.02741027832,,
,27980112.53,4369,21.5199003219604,-0.112000003457069,284.35400390625,,,0.178994411621094,99.9020004272461,,,,,,4.21786359916407e-006,,,25,,178.994411621094,,
,27980438.09,4369,21.0126495361328,-0.112000003457069,284.35400390625,,,0.181055997924805,99.9020004272461,,,,,,4.33622910624238e-006,,,25,,181.055997924805,,
,27980762.33,4369,20.5056495666504,-0.112000003457069,284.35400390625,,,0.183176737670898,99.9020004272461,,,,,,2.76070277938942e-006,,,25,,183.176737670898,,
,27981085.67,4369,19.99880027771,-0.112000003457069,284.35400390625,,,0.185362025146484,99.9020004272461,,,,,,3.43400848387094e-006,,,25,,185.362025146484,,
,27981490.34,4369,19.9982004165649,-0.112000003457069,284.35400390625,,,0.185368153686523,99.9020004272461,,,,,,3.16440003588481e-006,,,25,,185.368153686523,,
,27981798.88,4369,19.7436504364014,-0.112000003457069,284.35400390625,,,0.186487496948242,99.9020004272461,,,,,,3.32990319888268e-006,,,25,,186.487496948242,,
,27982107.34,4369,19.491250038147,-0.112000003457069,284.35400390625,,,0.187608673095703,99.9020004272461,,,,,,3.63619057842871e-006,,,25,,187.608673095703,,
,27982417.00,4369,19.2326507568359,-0.112000003457069,284.35400390625,,,0.188836107788086,99.9020004272461,,,,,,3.50296655338572e-006,,,25,,188.836107788086,,
,27982724.63,4369,18.9748506546021,-0.112000003457069,284.35400390625,,,0.190017151489258,99.9020004272461,,,,,,4.20377676287386e-006,,,25,,190.017151489258,,
,27983031.89,4369,18.7185001373291,-0.112000003457069,284.35400390625,,,0.191224923095703,99.9020004272461,,,,,,4.95858319240155e-006,,,25,,191.224923095703,,
,27983338.77,4369,18.4614496231079,-0.112000003457069,284.35400390625,,,0.192462083129883,99.9020004272461,,,,,,3.66649573909816e-006,,,25,,192.462083129883,,
,27983648.09,4369,18.2044496536255,-0.112000003457069,284.35400390625,,,0.193732383422852,99.9020004272461,,,,,,2.86129335953113e-006,,,25,,193.732383422852,,
,27983956.86,4369,17.9480504989624,-0.112000003457069,284.35400390625,,,0.19503292175293,99.9020004272461,,,,,,3.53971881574548e-006,,,25,,195.03292175293,,
,27984266.72,4369,17.690899848938,-0.112000003457069,284.35400390625,,,0.19635233215332,99.9020004272461,,,,,,4.00255702447695e-006,,,25,,196.35233215332,,
,27984574.72,4369,17.4343004226685,-0.112000003457069,284.35400390625,,,0.197721540527344,99.9020004272461,,,,,,3.02062356144532e-006,,,25,,197.721540527344,,
,27984883.55,4369,17.1785001754761,-0.112000003457069,284.35400390625,,,0.199114371337891,99.9020004272461,,,,,,4.52483626379511e-006,,,25,,199.114371337891,,
,27985191.88,4369,16.9229001998901,-0.112000003457069,284.35400390625,,,0.20052620300293,99.9020004272461,,,,,,3.20390234662357e-006,,,25,,200.52620300293,,
,27985501.81,4369,16.6673002243042,-0.112000003457069,284.35400390625,,,0.201972791748047,99.9020004272461,,,,,,4.16520275281922e-006,,,25,,201.972791748047,,
,27985812.17,4369,16.410400390625,-0.112000003457069,284.35400390625,,,0.203460220336914,99.9020004272461,,,,,,4.00285692867988e-006,,,25,,203.460220336914,,
,27986120.92,4369,16.154899597168,-0.112000003457069,284.35400390625,,,0.204972674560547,99.9020004272461,,,,,,4.05140520569759e-006,,,25,,204.972674560547,,
,27986429.89,4369,15.897500038147,-0.112000003457069,284.35400390625,,,0.20652046875,99.9020004272461,,,,,,4.32115288638242e-006,,,25,,206.52046875,,
,27986733.58,4369,15.6410999298096,-0.112000003457069,284.35400390625,,,0.208100101318359,99.9020004272461,,,,,,3.5207550891496e-006,,,25,,208.100101318359,,
,27987041.41,4369,15.3839001655579,-0.112000003457069,284.35400390625,,,0.209718062133789,99.9020004272461,,,,,,4.14740686368668e-006,,,25,,209.718062133789,,
,27987350.91,4369,15.1289000511169,-0.112000003457069,284.35400390625,,,0.211381868896484,99.9020004272461,,,,,,4.15879486085254e-006,,,25,,211.381868896484,,
,27987659.58,4369,14.8713998794556,-0.112000003457069,284.35400390625,,,0.213074024047852,99.9020004272461,,,,,,3.51076939293357e-006,,,25,,213.074024047852,,
,27987968.67,4369,14.6157002449036,-0.112000003457069,284.35400390625,,,0.214815627441406,99.9020004272461,,,,,,4.68762694266585e-006,,,25,,214.815627441406,,
,27988277.47,4369,14.3593997955322,-0.112000003457069,284.35400390625,,,0.216593770751953,99.9020004272461,,,,,,4.64273037431939e-006,,,25,,216.593770751953,,
,27988587.00,4369,14.1015996932983,-0.112000003457069,284.35400390625,,,0.218424078979492,99.9020004272461,,,,,,3.66048776283961e-006,,,25,,218.424078979492,,
,27988894.64,4369,13.8470497131348,-0.112000003457069,284.35400390625,,,0.220302221679687,99.9020004272461,,,,,,4.56877429984565e-006,,,25,,220.302221679688,,
,27989202.31,4369,13.5903000831604,-0.112000003457069,284.35400390625,,,0.222230057983398,99.9020004272461,,,,,,3.71855727092464e-006,,,25,,222.230057983398,,
,27989511.27,4369,13.3329000473022,-0.112000003457069,284.35400390625,,,0.224227105102539,99.9020004272461,,,,,,3.36608272578025e-006,,,25,,224.227105102539,,
,27989820.47,4369,13.0766997337341,-0.112000003457069,284.35400390625,,,0.226271005859375,99.9020004272461,,,,,,3.51501917360741e-006,,,25,,226.271005859375,,
,27990129.55,4369,12.8195996284485,-0.112000003457069,284.35400390625,,,0.228365221557617,99.9020004272461,,,,,,3.33656993473591e-006,,,25,,228.365221557617,,
,27990432.75,4369,12.5648498535156,-0.112000003457069,284.35400390625,,,0.230530120849609,99.9020004272461,,,,,,3.50853033842759e-006,,,25,,230.530120849609,,
,27990741.88,4369,12.3074502944946,-0.112000003457069,284.35400390625,,,0.232789715576172,99.9020004272461,,,,,,4.96598593278532e-006,,,25,,232.789715576172,,
,27991050.52,4369,12.0510997772217,-0.112000003457069,284.35400390625,,,0.235091162109375,99.9020004272461,,,,,,3.61585338927426e-006,,,25,,235.091162109375,,
,27991358.86,4369,11.7954001426697,-0.112000003457069,284.35400390625,,,0.237480349121094,99.9020004272461,,,,,,3.87064832858683e-006,,,25,,237.480349121094,,
,27991669.52,4369,11.5386500358582,-0.112000003457069,284.35400390625,,,0.23993875,99.9020004272461,,,,,,3.88988723020634e-006,,,25,,239.93875,,
,27991979.22,4369,11.2807998657227,-0.112000003457069,284.35400390625,,,0.242504985351563,99.9020004272461,,,,,,3.96361346836949e-006,,,25,,242.504985351563,,
,27992287.66,4369,11.0255498886108,-0.112000003457069,284.35400390625,,,0.245143273925781,99.9020004272461,,,,,,4.22845228714724e-006,,,25,,245.143273925781,,
,27992595.95,4369,10.7694001197815,-0.112000003457069,284.35400390625,,,0.247874447021484,99.9020004272461,,,,,,3.19352126862273e-006,,,25,,247.874447021484,,
,27992904.61,4369,10.5125999450684,-0.112000003457069,284.35400390625,,,0.250724348144531,99.9020004272461,,,,,,3.70731150417833e-006,,,25,,250.724348144531,,
,27993213.61,4369,10.2561502456665,-0.112000003457069,284.35400390625,,,0.253694124145508,99.9020004272461,,,,,,3.73025652545314e-006,,,25,,253.694124145508,,
,27993522.45,4369,10,-0.112000003457069,284.35400390625,,,0.256761153564453,99.9020004272461,,,,,,3.43972415821117e-006,,,25,,256.761153564453,,
,27993927.72,4369,9.99994993209839,-0.112000003457069,284.35400390625,,,0.256767147216797,99.9020004272461,,,,,,3.81402599947428e-006,,,25,,256.767147216797,,
,27994246.28,4369,9.68345022201538,-0.112000003457069,284.35400390625,,,0.260752680664063,99.9020004272461,,,,,,3.79541636423131e-006,,,25,,260.752680664063,,
,27994565.78,4369,9.36815023422241,-0.112000003457069,284.35400390625,,,0.264960610351563,99.9020004272461,,,,,,3.26703286599703e-006,,,25,,264.960610351562,,
,27994884.72,4369,9.05214977264404,-0.112000003457069,284.35400390625,,,0.269406717529297,99.9020004272461,,,,,,2.78063663361195e-006,,,25,,269.406717529297,,
,27995205.16,4369,8.73680019378662,-0.112000003457069,284.35400390625,,,0.274123591308594,99.9020004272461,,,,,,3.55818465814993e-006,,,25,,274.123591308594,,
,27995524.63,4369,8.42065000534058,-0.112000003457069,284.35400390625,,,0.279175916748047,99.9020004272461,,,,,,4.38925521796606e-006,,,25,,279.175916748047,,
,27995843.61,4369,8.10559988021851,-0.112000003457069,284.35400390625,,,0.284515090332031,99.9020004272461,,,,,,3.51961476550005e-006,,,25,,284.515090332031,,
,27996162.86,4369,7.78924989700317,-0.112000003457069,284.35400390625,,,0.290256833496094,99.9020004272461,,,,,,5.18772589930349e-006,,,25,,290.256833496094,,
,27996482.55,4369,7.47399997711182,-0.112000003457069,284.35400390625,,,0.296361685791016,99.9020004272461,,,,,,3.23657200237353e-006,,,25,,296.361685791016,,
,27996801.30,4369,7.15829992294312,-0.112000003457069,284.35400390625,,,0.303024005126953,99.9020004272461,,,,,,5.0980880158856e-006,,,25,,303.024005126953,,
,27997152.58,4369,6.83920001983643,-0.112000003457069,284.35400390625,,,0.310506307373047,99.9020004272461,,,,,,3.1754183081979e-006,,,25,,310.506307373047,,
,27997501.47,4369,6.5271999835968,-0.112000003457069,284.35400390625,,,0.317911376953125,99.9020004272461,,,,,,1.63504985817585e-005,,,25,,317.911376953125,,
,27997819.84,4369,6.2112500667572,-0.112000003457069,284.35400390625,,,0.326134739990234,99.9020004272461,,,,,,1.4064714007155e-005,,,25,,326.134739990234,,
,27998138.52,4369,5.89504981040955,-0.112000003457069,284.35400390625,,,0.335128637695313,99.9020004272461,,,,,,1.37117167441624e-005,,,25,,335.128637695312,,
,27998458.00,4369,5.57890009880066,-0.112000003457069,284.35400390625,,,0.345064951171875,99.9020004272461,,,,,,1.28266316300771e-005,,,25,,345.064951171875,,
,27998776.39,4369,5.26384997367859,-0.112000003457069,284.35400390625,,,0.356018690185547,99.9020004272461,,,,,,1.68853984337154e-005,,,25,,356.018690185547,,
,27999091.09,4369,4.94750022888184,-0.112000003457069,284.35400390625,,,0.368149721679687,99.9020004272461,,,,,,1.81284943614171e-005,,,25,,368.149721679688,,
,27999410.78,4369,4.63240003585815,-0.112000003457069,284.35400390625,,,0.3819109765625,99.9020004272461,,,,,,1.61337613460869e-005,,,25,,381.9109765625,,
,27999729.42,4369,4.31610012054443,-0.112000003457069,284.35400390625,,,0.397818856201172,99.9020004272461,,,,,,2.22076675146542e-005,,,25,,397.818856201172,,
,28000047.98,4369,3.99895000457764,-0.112000003457069,284.35400390625,,,0.416286463623047,99.9020004272461,,,,,,3.27503972190103e-005,,,25,,416.286463623047,,
,28000402.89,4369,3.99975001811981,-0.112000003457069,284.35400390625,,,0.416262954101562,99.9020004272461,,,,,,1.75208018702583e-005,,,25,,416.262954101563,,
,28000655.53,4369,3.89985001087189,-0.112000003457069,284.35400390625,,,0.422558828125,99.9020004272461,,,,,,1.43106676493205e-005,,,25,,422.558828125,,
,28000909.25,4369,3.80025005340576,-0.112000003457069,284.35400390625,,,0.429096102294922,99.9020004272461,,,,,,1.97782029710502e-005,,,25,,429.096102294922,,
,28001163.98,4369,3.70050001144409,-0.112000003457069,284.35400390625,,,0.435930479736328,99.9020004272461,,,,,,2.26355695384931e-005,,,25,,435.930479736328,,
,28001419.25,4369,3.59930002689362,-0.112000003457069,284.35400390625,,,0.443507947998047,99.9020004272461,,,,,,2.93196889719281e-005,,,25,,443.507947998047,,
,28001672.89,4369,3.49974989891052,-0.112000003457069,284.35400390625,,,0.451114714355469,99.9020004272461,,,,,,4.60930618746391e-005,,,25,,451.114714355469,,
,28001927.91,4369,3.40029990673065,-0.112000003457069,284.35400390625,,,0.459025373535156,99.9020004272461,,,,,,8.13749568172747e-006,,,25,,459.025373535156,,
,28002180.73,4369,3.29999995231628,-0.112000003457069,284.35400390625,,,0.467443101806641,99.9020004272461,,,,,,1.02709232906893e-005,,,25,,467.443101806641,,
,28002434.48,4369,3.20065009593964,-0.112000003457069,284.35400390625,,,0.476392839355469,99.9020004272461,,,,,,4.46894242982143e-005,,,25,,476.392839355469,,
,28002689.53,4369,3.10025000572205,-0.112000003457069,284.35400390625,,,0.485820450439453,99.9020004272461,,,,,,3.36377838806787e-005,,,25,,485.820450439453,,
,28002943.44,4369,2.99975001811981,-0.112000003457069,284.35400390625,,,0.49572916015625,99.9020004272461,,,,,,1.16098646750498e-005,,,25,,495.72916015625,,
,28003198.66,4369,2.90009999275208,-0.112000003457069,284.35400390625,,,0.50620564453125,99.9020004272461,,,,,,2.1447770651799e-005,,,25,,506.20564453125,,
,28003452.50,4369,2.79955005645752,-0.112000003457069,284.35400390625,,,0.517264328613281,99.9020004272461,,,,,,3.21973898783413e-005,,,25,,517.264328613281,,
,28003706.20,4369,2.7002500295639,-0.112000003457069,284.35400390625,,,0.528978403320313,99.9020004272461,,,,,,2.05592895667882e-005,,,25,,528.978403320313,,
,28003960.06,4369,2.6003999710083,-0.112000003457069,284.35400390625,,,0.541285776367188,99.9020004272461,,,,,,5.09713838519518e-005,,,25,,541.285776367188,,
,28004215.02,4369,2.50034999847412,-0.112000003457069,284.35400390625,,,0.554108317871094,99.9020004272461,,,,,,2.51852536975467e-005,,,25,,554.108317871094,,
,28004465.58,4369,2.40069997310638,-0.112000003457069,284.35400390625,,,0.568038518066406,99.9020004272461,,,,,,5.21787830723052e-005,,,25,,568.038518066406,,
,28004719.50,4369,2.30029988288879,-0.112000003457069,284.35400390625,,,0.583302744140625,99.9020004272461,,,,,,4.20892167565574e-005,,,25,,583.302744140625,,
,28004979.84,4369,2.19955003261566,-0.112000003457069,284.35400390625,,,0.59934220703125,99.9020004272461,,,,,,3.37792570723987e-005,,,25,,599.34220703125,,
,28006227.31,4369,2.11729991436005,-0.112000003457069,284.35400390625,,,0.613085063476563,99.9020004272461,,,,,,8.4289844448377e-006,,,25,,613.085063476562,,
,28149010.48,4369,2.00080001354218,-0.112000003457069,284.35400390625,,,0.635571779785156,99.9020004272461,,,,,,7.95170581852579e-005,,,25,,635.571779785156,,
,28149265.42,4369,1.89939999580383,-0.112000003457069,284.35400390625,,,0.652817292480469,99.9020004272461,,,,,,7.98580196132886e-005,,,25,,652.817292480469,,
,28149520.09,4369,1.79999995231628,-0.112000003457069,284.35400390625,,,0.670103442382813,99.9020004272461,,,,,,5.21323784804652e-005,,,25,,670.103442382813,,
,28149774.91,4369,1.70275002717972,-0.112000003457069,284.35400390625,,,0.686641286621094,99.9020004272461,,,,,,7.41690610418543e-006,,,25,,686.641286621094,,