File: data/161117-cernox calibration/161115-RT_cernox_c12_r07-7TPPMS.dat
[Header]
TITLE, sensor calib
FILEOPENTIME,27648821.08,11/15/2016,5:11 PM
BYAPP, Resistivity, 2.1, 1.0
INFO, APPNAME, PPMS MultiVu Application, 1.5.8.11
INFO, , Sample1 Name
INFO, 1, Sample1 Cross Section
INFO, 1, Sample1 Length
INFO, Ohm-m, Sample1 Units
INFO, cernox r07 c12, Sample2 Name
INFO, 1, Sample2 Cross Section
INFO, 1, Sample2 Length
INFO, Ohm-m, Sample2 Units
INFO, , Sample3 Name
INFO, 1, Sample3 Cross Section
INFO, 1, Sample3 Length
INFO, Ohm-m, Sample3 Units
INFO, , Sample4 Name
INFO, 1, Sample4 Cross Section
INFO, 1, Sample4 Length
INFO, Ohm-m, Sample4 Units
FIELDGROUP, Resistivity,2,3,4,5,6,7,8,9,10,11,12,13,14,15,16,17,18,19,20,21,22,23,24,25,26,27,28,29,30,31,32,33,34,35,36,37,38,39,40,41
STARTUPGROUP, Resistivity
STARTUPAXIS, X, 2, LINEAR, AUTO
STARTUPAXIS, Y1, 7, LINEAR, AUTO
STARTUPAXIS, Y2, 9, LINEAR, AUTO
STARTUPAXIS, Y3, 11, LINEAR, AUTO
PLOT_APPEARANCE, ALL, HORZ_GRID_ON, VERT_GRID_ON, MARKERS_AND_LINES, ALL_LINES
DATATYPE, TIME, 2
DATATYPE, COMMENT, 1
[Data]
Comment,Time Stamp (sec),Status (code),Temperature (K),Magnetic Field (Oe),Sample Position (deg),Bridge 1 Resistivity (Ohm-m),Bridge 1 Excitation (uA),Bridge 2 Resistivity (Ohm-m),Bridge 2 Excitation (uA),Bridge 3 Resistivity (Ohm-m),Bridge 3 Excitation (uA),Bridge 4 Resistivity (Ohm-m),Bridge 4 Excitation (uA),Bridge 1 Std. Dev. (Ohm-m),Bridge 2 Std. Dev. (Ohm-m),Bridge 3 Std. Dev. (Ohm-m),Bridge 4 Std. Dev. (Ohm-m),Number of Readings,Bridge 1 Resistance (Ohms),Bridge 2 Resistance (Ohms),Bridge 3 Resistance (Ohms),Bridge 4 Resistance (Ohms),Signal 1 Vin (V),Signal 2 Vin (V),Digital Inputs (code),Drive 1 Iout (mA),Drive 1 Ipower (watts),Drive 2 Iout (mA),Drive 2 Ipower (watts),Pressure (),Map 20 (),Map 21 (),Map 22 (),Map 23 (),Map 24 (),Map 25 (),Map 26 (),Map 27 (),Map 28 (),Map 29 ()
,27650013.58,4370,299.996994018555,0.0500000007450581,0,,,0.0367605061340332,99.9020004272461,,,,,,2.69052708834549e-007,,,25,,36.7605061340332,,
,27650190.16,4370,298.477249145508,0.0500000007450581,0,,,0.0368578793334961,99.9020004272461,,,,,,6.50528318374496e-007,,,25,,36.8578793334961,,
,27650377.56,4370,296.971557617188,0.0500000007450581,0,,,0.036994016418457,99.9020004272461,,,,,,3.67310837006422e-007,,,25,,36.994016418457,,
,27650557.45,4370,295.473251342773,0.0500000007450581,0,,,0.0371098913574219,99.9020004272461,,,,,,6.01698354164788e-007,,,25,,37.1098913574219,,
,27650735.86,4370,293.982940673828,0.0500000007450581,0,,,0.037229130859375,99.9020004272461,,,,,,6.55833792827863e-007,,,25,,37.229130859375,,
,27650917.28,4370,292.469451904297,0.0500000007450581,0,,,0.037352416229248,99.9020004272461,,,,,,6.07878674888257e-007,,,25,,37.3524162292481,,
,27651096.70,4370,290.973190307617,0.0500000007450581,0,,,0.0374787982177734,99.9020004272461,,,,,,7.3227632325216e-007,,,25,,37.4787982177734,,
,27651276.45,4370,289.483200073242,0.0500000007450581,0,,,0.0376044401550293,99.9020004272461,,,,,,6.89665746973189e-007,,,25,,37.6044401550293,,
,27651458.14,4370,287.970703125,0.0500000007450581,0,,,0.0377360629272461,99.9020004272461,,,,,,6.79328800326007e-007,,,25,,37.7360629272461,,
,27651637.94,4370,286.472198486328,0.0500000007450581,0,,,0.0378659400939941,99.9020004272461,,,,,,7.53593776556618e-007,,,25,,37.8659400939941,,
,27651817.33,4370,284.974594116211,0.0500000007450581,0,,,0.0379963136291504,99.9020004272461,,,,,,7.74396260861642e-007,,,25,,37.9963136291504,,
,27651997.89,4370,283.473052978516,0.0500000007450581,0,,,0.0381304730224609,99.9020004272461,,,,,,7.48281176722434e-007,,,25,,38.1304730224609,,
,27652178.48,4370,281.988693237305,0.0500000007450581,0,,,0.0382648420715332,99.9020004272461,,,,,,8.31113564887278e-007,,,25,,38.2648420715332,,
,27652359.42,4370,280.469299316406,0.0500000007450581,0,,,0.0384032438659668,99.9020004272461,,,,,,7.53046292768272e-007,,,25,,38.4032438659668,,
,27652539.08,4370,278.974258422852,0.0500000007450581,0,,,0.0385380514526367,99.9020004272461,,,,,,7.62678559752881e-007,,,25,,38.5380514526367,,
,27652718.50,4370,277.481063842773,0.0500000007450581,0,,,0.0386758728027344,99.9020004272461,,,,,,7.59555226524013e-007,,,25,,38.6758728027344,,
,27652899.95,4370,275.969192504883,0.0500000007450581,0,,,0.0388166241455078,99.9020004272461,,,,,,8.06345867227443e-007,,,25,,38.8166241455078,,
,27653080.28,4370,274.469696044922,0.0500000007450581,0,,,0.0389591589355469,99.9020004272461,,,,,,7.73637335812063e-007,,,25,,38.9591589355469,,
,27653259.94,4370,272.97428894043,0.0500000007450581,0,,,0.0391006311035156,99.9020004272461,,,,,,1.0327103397351e-006,,,25,,39.1006311035156,,
,27653439.70,4370,271.474243164063,0.0500000007450581,0,,,0.0392468984985352,99.9020004272461,,,,,,6.17741251176367e-007,,,25,,39.2468984985352,,
,27653620.61,4370,269.97624206543,0.0500000007450581,0,,,0.0393926493835449,99.9020004272461,,,,,,8.27880421771115e-007,,,25,,39.3926493835449,,
,27653800.88,4370,268.475601196289,0.0500000007450581,0,,,0.0395395469665527,99.9020004272461,,,,,,7.8684550220625e-007,,,25,,39.5395469665527,,
,27653980.50,4370,266.97966003418,0.0500000007450581,0,,,0.0396888697814941,99.9020004272461,,,,,,9.03719838895527e-007,,,25,,39.6888697814941,,
,27654161.06,4370,265.476547241211,0.0500000007450581,0,,,0.0398419953918457,99.9020004272461,,,,,,7.81860000505972e-007,,,25,,39.8419953918457,,
,27654341.97,4370,263.971405029297,0.0500000007450581,0,,,0.0399933015441895,99.9020004272461,,,,,,7.72043524152664e-007,,,25,,39.9933015441895,,
,27654522.42,4370,262.469757080078,0.0500000007450581,0,,,0.0401486663818359,99.9020004272461,,,,,,8.75769865177352e-007,,,25,,40.1486663818359,,
,27654702.61,4370,260.970153808594,0.0500000007450581,0,,,0.0403040873718262,99.9020004272461,,,,,,7.21059324695416e-007,,,25,,40.3040873718262,,
,27654881.67,4370,259.481307983398,0.0500000007450581,0,,,0.0404602047729492,99.9020004272461,,,,,,7.68781823689742e-007,,,25,,40.4602047729492,,
,27655062.53,4370,257.974548339844,0.0500000007450581,0,,,0.0406207229614258,99.9020004272461,,,,,,8.95033701346549e-007,,,25,,40.6207229614258,,
,27655242.38,4370,256.478256225586,0.0500000007450581,0,,,0.0407818713378906,99.9020004272461,,,,,,8.43029701560611e-007,,,25,,40.7818713378906,,
,27655423.83,4370,254.96834564209,0.0500000007450581,0,,,0.0409435307312012,99.9020004272461,,,,,,8.66829705822244e-007,,,25,,40.9435307312012,,
,27655603.31,4370,253.476501464844,0.0500000007450581,0,,,0.0411063525390625,99.9020004272461,,,,,,6.73151362630426e-007,,,25,,41.1063525390625,,
,27655784.02,4370,251.971801757813,0.0500000007450581,0,,,0.0412761549377441,99.9020004272461,,,,,,8.57182133626345e-007,,,25,,41.2761549377441,,
,27655963.41,4370,250.479148864746,0.0500000007450581,0,,,0.0414411785888672,99.9020004272461,,,,,,9.60478981025769e-007,,,25,,41.4411785888672,,
,27656143.50,4370,248.976348876953,0.0500000007450581,0,,,0.0416117094421387,99.9020004272461,,,,,,8.9744371504967e-007,,,25,,41.6117094421387,,
,27656324.14,4370,247.47395324707,0.0500000007450581,0,,,0.0417836985778809,99.9020004272461,,,,,,9.62565584899371e-007,,,25,,41.7836985778809,,
,27656504.38,4370,245.977600097656,0.0500000007450581,0,,,0.0419548075866699,99.9020004272461,,,,,,8.25823346736776e-007,,,25,,41.9548075866699,,
,27656685.09,4370,244.469749450684,0.0500000007450581,0,,,0.0421322521972656,99.9020004272461,,,,,,9.0590199710895e-007,,,25,,42.1322521972656,,
,27656864.38,4370,242.980796813965,0.0500000007450581,0,,,0.042309690246582,99.9020004272461,,,,,,9.25557891187501e-007,,,25,,42.309690246582,,
,27657044.78,4370,241.475395202637,0.0500000007450581,0,,,0.0424889697265625,99.9020004272461,,,,,,9.93447404279928e-007,,,25,,42.4889697265625,,
,27657225.42,4370,239.97550201416,0.0500000007450581,0,,,0.042669020690918,99.9020004272461,,,,,,8.92127063314016e-007,,,25,,42.669020690918,,
,27657405.16,4370,238.479499816895,0.0500000007450581,0,,,0.0428496946716309,99.9020004272461,,,,,,8.86069371817586e-007,,,25,,42.8496946716309,,
,27657585.48,4370,236.981048583984,0.0500000007450581,0,,,0.0430368078613281,99.9020004272461,,,,,,8.64314390792345e-007,,,25,,43.0368078613281,,
,27657765.97,4370,235.473350524902,0.0500000007450581,0,,,0.0432239337158203,99.9020004272461,,,,,,9.54648115431319e-007,,,25,,43.2239337158203,,
,27657946.63,4370,233.970100402832,0.0500000007450581,0,,,0.0434118476867676,99.9020004272461,,,,,,8.52489871783564e-007,,,25,,43.4118476867676,,
,27658126.17,4370,232.479751586914,0.0500000007450581,0,,,0.0436027418518066,99.9020004272461,,,,,,1.01719570041805e-006,,,25,,43.6027418518066,,
,27658306.08,4370,230.977851867676,0.0500000007450581,0,,,0.0437967224121094,99.9020004272461,,,,,,9.61651667345769e-007,,,25,,43.7967224121094,,
,27658486.42,4370,229.477394104004,0.0500000007450581,0,,,0.0439921873474121,99.9020004272461,,,,,,1.10680341389011e-006,,,25,,43.9921873474121,,
,27658667.20,4370,227.972099304199,0.0500000007450581,0,,,0.0441908224487305,99.9020004272461,,,,,,1.03294999516324e-006,,,25,,44.1908224487305,,
,27658847.52,4370,226.472900390625,0.0500000007450581,0,,,0.0443915184020996,99.9020004272461,,,,,,9.38553233844606e-007,,,25,,44.3915184020996,,
,27659027.06,4370,224.982353210449,0.0500000007450581,0,,,0.0445934407043457,99.9020004272461,,,,,,1.10006405651538e-006,,,25,,44.5934407043457,,
,27659207.31,4370,223.479804992676,0.0500000007450581,0,,,0.0447988983154297,99.9020004272461,,,,,,1.04806505003051e-006,,,25,,44.7988983154297,,
,27659387.75,4370,221.975700378418,0.0500000007450581,0,,,0.0450058999633789,99.9020004272461,,,,,,1.12462821459279e-006,,,25,,45.0058999633789,,
,27659567.67,4370,220.479553222656,0.0500000007450581,0,,,0.0452155961608887,99.9020004272461,,,,,,1.11913434226543e-006,,,25,,45.2155961608887,,
,27659748.45,4370,218.973503112793,0.0500000007450581,0,,,0.0454298973083496,99.9020004272461,,,,,,1.04358361945414e-006,,,25,,45.4298973083496,,
,27659927.81,4370,217.480201721191,0.0500000007450581,0,,,0.0456441372680664,99.9020004272461,,,,,,1.21597296586159e-006,,,25,,45.6441372680664,,
,27660109.73,4370,215.971755981445,0.0500000007450581,0,,,0.045861559753418,99.9020004272461,,,,,,1.06670184812288e-006,,,25,,45.861559753418,,
,27660289.20,4370,214.470146179199,0.0500000007450581,0,,,0.0460800859069824,99.9020004272461,,,,,,1.15837174022033e-006,,,25,,46.0800859069824,,
,27660468.67,4370,212.981796264648,0.0500000007450581,0,,,0.0463023304748535,99.9020004272461,,,,,,1.10435361461111e-006,,,25,,46.3023304748535,,
,27660650.08,4370,211.471199035645,0.0500000007450581,0,,,0.0465301298522949,99.9020004272461,,,,,,1.23912179810756e-006,,,25,,46.5301298522949,,
,27660830.25,4370,209.970649719238,0.0500000007450581,0,,,0.0467577352905273,99.9020004272461,,,,,,1.13532232803089e-006,,,25,,46.7577352905273,,
,27661010.30,4370,208.476898193359,0.0500000007450581,0,,,0.0469891159057617,99.9020004272461,,,,,,1.17507649058568e-006,,,25,,46.9891159057617,,
,27661189.91,4370,206.976898193359,0.0500000007450581,0,,,0.0472241358947754,99.9020004272461,,,,,,1.16370665657798e-006,,,25,,47.2241358947754,,
,27661370.61,4370,205.475646972656,0.0500000007450581,0,,,0.0474610211181641,99.9020004272461,,,,,,1.2337117341983e-006,,,25,,47.4610211181641,,
,27661550.27,4370,203.97989654541,0.0500000007450581,0,,,0.047701100769043,99.9020004272461,,,,,,1.29033255478712e-006,,,25,,47.701100769043,,
,27661731.45,4370,202.472152709961,0.0500000007450581,0,,,0.0479469761657715,99.9020004272461,,,,,,1.12785816985843e-006,,,25,,47.9469761657715,,
,27661910.77,4370,200.979949951172,0.0500000007450581,0,,,0.0481930844116211,99.9020004272461,,,,,,1.33432542217802e-006,,,25,,48.1930844116211,,
,27662091.36,4370,199.476600646973,0.0500000007450581,0,,,0.0484407077026367,99.9020004272461,,,,,,1.1836236089244e-006,,,25,,48.4407077026367,,
,27662271.91,4370,197.974151611328,0.0500000007450581,0,,,0.0486922964477539,99.9020004272461,,,,,,1.30873208017782e-006,,,25,,48.6922964477539,,
,27662451.41,4370,196.477096557617,0.0500000007450581,0,,,0.048946439819336,99.9020004272461,,,,,,1.30658267486702e-006,,,25,,48.9464398193359,,
,27662632.20,4370,194.972351074219,0.0500000007450581,0,,,0.0492045848083496,99.9020004272461,,,,,,1.37877078015656e-006,,,25,,49.2045848083496,,
,27662812.50,4370,193.474647521973,0.0500000007450581,0,,,0.0494645745849609,99.9020004272461,,,,,,1.46986706363228e-006,,,25,,49.4645745849609,,
,27662992.58,4370,191.974449157715,0.0500000007450581,0,,,0.0497301791381836,99.9020004272461,,,,,,1.27253583496515e-006,,,25,,49.7301791381836,,
,27663173.22,4370,190.472351074219,0.0500000007450581,0,,,0.0499985383605957,99.9020004272461,,,,,,1.49850106136212e-006,,,25,,49.9985383605957,,
,27663353.00,4370,188.972694396973,0.0500000007450581,0,,,0.0502680313110352,99.9020004272461,,,,,,1.25809908493117e-006,,,25,,50.2680313110352,,
,27663532.67,4370,187.477699279785,0.0500000007450581,0,,,0.0505428900146484,99.9020004272461,,,,,,2.15789902479809e-006,,,25,,50.5428900146484,,
,27663713.19,4370,185.977394104004,0.0500000007450581,0,,,0.0508219660949707,99.9020004272461,,,,,,1.47815929722558e-006,,,25,,50.8219660949707,,
,27663892.86,4370,184.483596801758,0.0500000007450581,0,,,0.0511037174987793,99.9020004272461,,,,,,1.5349646914187e-006,,,25,,51.1037174987793,,
,27664073.63,4370,182.978797912598,0.0500000007450581,0,,,0.0513907534790039,99.9020004272461,,,,,,1.48689608491046e-006,,,25,,51.3907534790039,,
,27664253.86,4370,181.478652954102,0.0500000007450581,0,,,0.0516804536437988,99.9020004272461,,,,,,1.32126760247404e-006,,,25,,51.6804536437988,,
,27664434.20,4370,179.977500915527,0.0500000007450581,0,,,0.0519739962768555,99.9020004272461,,,,,,1.52861075427897e-006,,,25,,51.9739962768555,,
,27664614.69,4370,178.473350524902,0.0500000007450581,0,,,0.0522735111999512,99.9020004272461,,,,,,1.36916170368001e-006,,,25,,52.2735111999512,,
,27664794.67,4370,176.975944519043,0.0500000007450581,0,,,0.052577663269043,99.9020004272461,,,,,,1.57890217431228e-006,,,25,,52.577663269043,,
,27664974.75,4370,175.478805541992,0.0500000007450581,0,,,0.0528863223266602,99.9020004272461,,,,,,1.526883692127e-006,,,25,,52.8863223266602,,
,27665154.81,4370,173.979347229004,0.0500000007450581,0,,,0.0531966407775879,99.9020004272461,,,,,,1.74700327473343e-006,,,25,,53.1966407775879,,
,27665335.56,4370,172.475051879883,0.0500000007450581,0,,,0.0535124333190918,99.9020004272461,,,,,,1.40008885559324e-006,,,25,,53.5124333190918,,
,27665515.27,4370,170.980804443359,0.0500000007450581,0,,,0.053830334777832,99.9020004272461,,,,,,1.6264285578706e-006,,,25,,53.830334777832,,
,27665696.08,4370,169.474098205566,0.0500000007450581,0,,,0.0541585845947266,99.9020004272461,,,,,,1.67255396367461e-006,,,25,,54.1585845947266,,
,27665875.70,4370,167.977806091309,0.0500000007450581,0,,,0.0544873100280762,99.9020004272461,,,,,,1.79409184042712e-006,,,25,,54.4873100280762,,
,27666056.88,4370,166.469451904297,0.0500000007450581,0,,,0.0548215335083008,99.9020004272461,,,,,,1.74866347800776e-006,,,25,,54.8215335083008,,
,27666236.67,4370,164.976249694824,0.0500000007450581,0,,,0.0551607766723633,99.9020004272461,,,,,,1.63827370828699e-006,,,25,,55.1607766723633,,
,27666417.13,4370,163.473052978516,0.0500000007450581,0,,,0.0555032641601563,99.9020004272461,,,,,,1.6441681731361e-006,,,25,,55.5032641601562,,
,27666596.88,4370,161.976249694824,0.0500000007450581,0,,,0.0558513171386719,99.9020004272461,,,,,,1.67272392133995e-006,,,25,,55.8513171386719,,
,27666777.47,4370,160.474151611328,0.0500000007450581,0,,,0.056204609375,99.9020004272461,,,,,,1.68216374425357e-006,,,25,,56.204609375,,
,27666958.17,4370,158.970603942871,0.0500000007450581,0,,,0.0565612065124512,99.9020004272461,,,,,,1.90799528761353e-006,,,25,,56.5612065124512,,
,27667138.05,4370,157.468803405762,0.0500000007450581,0,,,0.0569251701354981,99.9020004272461,,,,,,2.07945009137084e-006,,,25,,56.9251701354981,,
,27667317.25,4370,155.98184967041,0.0500000007450581,0,,,0.0572918455505371,99.9020004272461,,,,,,1.74815226075311e-006,,,25,,57.2918455505371,,
,27667498.33,4370,154.474647521973,0.0500000007450581,0,,,0.0576667385864258,99.9020004272461,,,,,,1.72981905508393e-006,,,25,,57.6667385864258,,
,27667678.59,4370,152.974502563477,0.0500000007450581,0,,,0.0580444004821777,99.9020004272461,,,,,,1.81957039271788e-006,,,25,,58.0444004821777,,
,27667859.16,4370,151.473350524902,0.0500000007450581,0,,,0.0584339350891113,99.9020004272461,,,,,,1.94209520707538e-006,,,25,,58.4339350891113,,
,27668038.45,4370,149.979347229004,0.0500000007450581,0,,,0.0588256407165527,99.9020004272461,,,,,,1.89828798523271e-006,,,25,,58.8256407165527,,
,27668218.94,4370,148.474853515625,0.0500000007450581,0,,,0.0592248658752442,99.9020004272461,,,,,,1.94772028131057e-006,,,25,,59.2248658752441,,
,27668398.86,4370,146.979393005371,0.0500000007450581,0,,,0.0596276414489746,99.9020004272461,,,,,,1.88362839919861e-006,,,25,,59.6276414489746,,
,27668579.69,4370,145.470802307129,0.0500000007450581,0,,,0.0600402690124512,99.9020004272461,,,,,,2.15656334241249e-006,,,25,,60.0402690124512,,
,27668759.66,4370,143.977096557617,0.0500000007450581,0,,,0.0604567140197754,99.9020004272461,,,,,,2.13825852427379e-006,,,25,,60.4567140197754,,
,27668940.28,4370,142.474151611328,0.0500000007450581,0,,,0.0608811660766601,99.9020004272461,,,,,,2.061408308396e-006,,,25,,60.8811660766602,,
,27669119.72,4370,140.975845336914,0.0500000007450581,0,,,0.0613114181518555,99.9020004272461,,,,,,2.0259357324755e-006,,,25,,61.3114181518555,,
,27669300.80,4370,139.471450805664,0.0500000007450581,0,,,0.0617523484802246,99.9020004272461,,,,,,2.2165276727538e-006,,,25,,61.7523484802246,,
,27669480.72,4370,137.974754333496,0.0500000007450581,0,,,0.0621959410095215,99.9020004272461,,,,,,2.11743084584683e-006,,,25,,62.1959410095215,,
,27669660.97,4370,136.473899841309,0.0500000007450581,0,,,0.0626495849609375,99.9020004272461,,,,,,2.26061687924644e-006,,,25,,62.6495849609375,,
,27669841.53,4370,134.971450805664,0.0500000007450581,0,,,0.0631121633911133,99.9020004272461,,,,,,2.27281923426816e-006,,,25,,63.1121633911133,,
,27670021.30,4370,133.473945617676,0.0500000007450581,0,,,0.063579049987793,99.9020004272461,,,,,,2.19815784297308e-006,,,25,,63.579049987793,,
,27670201.80,4370,131.971351623535,0.0500000007450581,0,,,0.0640536459350586,99.9020004272461,,,,,,2.41875625290058e-006,,,25,,64.0536459350586,,
,27670381.72,4370,130.474601745605,0.0500000007450581,0,,,0.064535832824707,99.9020004272461,,,,,,2.49382066741239e-006,,,25,,64.535832824707,,
,27670562.69,4370,128.97200012207,0.0500000007450581,0,,,0.0650298303222656,99.9020004272461,,,,,,2.33208974780932e-006,,,25,,65.0298303222656,,
,27670741.92,4370,127.476551055908,0.0500000007450581,0,,,0.0655288299560547,99.9020004272461,,,,,,2.39002813892453e-006,,,25,,65.5288299560547,,
,27670921.67,4370,125.97550201416,0.0500000007450581,0,,,0.0660380435180664,99.9020004272461,,,,,,2.5918099860144e-006,,,25,,66.0380435180664,,
,27671101.50,4370,124.477802276611,0.0500000007450581,0,,,0.0665567196655273,99.9020004272461,,,,,,2.57537165006616e-006,,,25,,66.5567196655273,,
,27671281.69,4370,122.970897674561,0.0500000007450581,0,,,0.0670840258789063,99.9020004272461,,,,,,2.78050655609644e-006,,,25,,67.0840258789062,,
,27671461.66,4370,121.470699310303,0.0500000007450581,0,,,0.0676214733886719,99.9020004272461,,,,,,2.67444889431036e-006,,,25,,67.6214733886719,,
,27671640.95,4370,119.976848602295,0.0500000007450581,0,,,0.0681659103393555,99.9020004272461,,,,,,2.93989153098857e-006,,,25,,68.1659103393555,,
,27671820.64,4370,118.473148345947,0.0500000007450581,0,,,0.0687270196533203,99.9020004272461,,,,,,2.9398896132807e-006,,,25,,68.7270196533203,,
,27672000.44,4370,116.978252410889,0.0500000007450581,0,,,0.0692923141479492,99.9020004272461,,,,,,2.70992241290449e-006,,,25,,69.2923141479492,,
,27672180.73,4370,115.470699310303,0.0500000007450581,0,,,0.0698742468261719,99.9020004272461,,,,,,3.19667177333648e-006,,,25,,69.8742468261719,,
,27672360.25,4370,113.974750518799,0.0500000007450581,0,,,0.0704633346557617,99.9020004272461,,,,,,3.072428656781e-006,,,25,,70.4633346557617,,
,27672539.53,4370,112.479301452637,0.0500000007450581,0,,,0.0710634817504883,99.9020004272461,,,,,,3.04842991333413e-006,,,25,,71.0634817504883,,
,27672719.39,4370,110.976047515869,0.0500000007450581,0,,,0.0716783624267578,99.9020004272461,,,,,,3.75533341267895e-006,,,25,,71.6783624267578,,
,27672899.41,4370,109.476196289063,0.0500000007450581,0,,,0.0723038302612305,99.9020004272461,,,,,,3.13776397027345e-006,,,25,,72.3038302612305,,
,27673078.91,4370,107.979446411133,0.0500000007450581,0,,,0.0729404272460938,99.9020004272461,,,,,,3.07151074635735e-006,,,25,,72.9404272460937,,
,27673259.75,4370,106.46875,0.0500000007450581,0,,,0.0735954217529297,99.9020004272461,,,,,,3.17865743022414e-006,,,25,,73.5954217529297,,
,27673439.25,4370,104.973449707031,0.0500000007450581,0,,,0.074257614440918,99.9020004272461,,,,,,3.13942706540933e-006,,,25,,74.257614440918,,
,27673618.56,4370,103.476902008057,0.0500000007450581,0,,,0.0749255212402344,99.9020004272461,,,,,,3.42866870683496e-006,,,25,,74.9255212402344,,
,27673798.03,4370,101.980052947998,0.0500000007450581,0,,,0.0756187008666992,99.9020004272461,,,,,,3.35608754461571e-006,,,25,,75.6187008666992,,
,27673978.50,4370,100.474449157715,0.0500000007450581,0,,,0.0763291430664063,99.9020004272461,,,,,,3.80552478414095e-006,,,25,,76.3291430664062,,
,27674157.95,4370,98.9757499694824,0.0500000007450581,0,,,0.0770500411987305,99.9020004272461,,,,,,3.72207981028686e-006,,,25,,77.0500411987305,,
,27674338.11,4370,97.4734992980957,0.0500000007450581,0,,,0.0777945120239258,99.9020004272461,,,,,,4.45546121349889e-006,,,25,,77.7945120239258,,
,27674517.69,4370,95.9754981994629,0.0500000007450581,0,,,0.0785561077880859,99.9020004272461,,,,,,4.20474949233214e-006,,,25,,78.5561077880859,,
,27674697.66,4370,94.4780464172363,0.0500000007450581,0,,,0.0793335723876953,99.9020004272461,,,,,,3.94116622322518e-006,,,25,,79.3335723876953,,
,27674878.08,4370,92.9724998474121,0.0500000007450581,0,,,0.0801363629150391,99.9020004272461,,,,,,4.08101715945594e-006,,,25,,80.1363629150391,,
,27675057.70,4370,91.4742965698242,0.0500000007450581,0,,,0.0809596844482422,99.9020004272461,,,,,,4.59317426353432e-006,,,25,,80.9596844482422,,
,27675237.16,4370,89.9770469665527,0.0500000007450581,0,,,0.0818046505737305,99.9020004272461,,,,,,4.7002614896702e-006,,,25,,81.8046505737305,,
,27675417.28,4370,88.4747505187988,0.0500000007450581,0,,,0.082666527709961,99.9020004272461,,,,,,4.63960688289559e-006,,,25,,82.6665277099609,,
,27675597.00,4370,86.9775009155273,0.0500000007450581,0,,,0.0835481811523437,99.9020004272461,,,,,,4.52223918562861e-006,,,25,,83.5481811523437,,
,27675777.70,4370,85.4699974060059,0.0500000007450581,0,,,0.0844475357055664,99.9020004272461,,,,,,5.10022216435792e-006,,,25,,84.4475357055664,,
,27675957.30,4370,83.9714508056641,0.0500000007450581,0,,,0.0853704037475586,99.9020004272461,,,,,,4.96464837697154e-006,,,25,,85.3704037475586,,
,27676137.67,4370,82.4665031433105,0.0500000007450581,0,,,0.0863175042724609,99.9020004272461,,,,,,5.30630956871449e-006,,,25,,86.3175042724609,,
,27676316.67,4370,80.9755973815918,0.0500000007450581,0,,,0.087272553100586,99.9020004272461,,,,,,5.33609459483925e-006,,,25,,87.2725531005859,,
,27676497.27,4370,79.4700469970703,0.0500000007450581,0,,,0.0882641372680664,99.9020004272461,,,,,,4.83445081128001e-006,,,25,,88.2641372680664,,
,27676677.00,4370,77.9680023193359,0.0500000007450581,0,,,0.0892744705200195,99.9020004272461,,,,,,5.13876149927396e-006,,,25,,89.2744705200195,,
,27676855.83,4370,76.4796028137207,0.0500000007450581,0,,,0.0903114041137695,99.9020004272461,,,,,,5.07626303538839e-006,,,25,,90.3114041137695,,
,27677036.25,4370,74.9754486083984,0.0500000007450581,0,,,0.0913941748046875,99.9020004272461,,,,,,5.49231062667263e-006,,,25,,91.3941748046875,,
,27677216.20,4370,73.4719009399414,0.0500000007450581,0,,,0.0924991372680664,99.9020004272461,,,,,,5.64642651159435e-006,,,25,,92.4991372680664,,
,27677396.16,4370,71.9712982177734,0.0500000007450581,0,,,0.0936498916625976,99.9020004272461,,,,,,5.65650892997319e-006,,,25,,93.6498916625977,,
,27677575.25,4370,70.4764976501465,0.0500000007450581,0,,,0.0948898181152344,99.9020004272461,,,,,,7.23820346016823e-006,,,25,,94.8898181152344,,
,27677754.61,4370,68.9814491271973,0.0500000007450581,0,,,0.0961095404052734,99.9020004272461,,,,,,5.96304513759722e-006,,,25,,96.1095404052734,,
,27677934.97,4370,67.4757499694824,0.0500000007450581,0,,,0.0973663436889648,99.9020004272461,,,,,,7.54811431158546e-006,,,25,,97.3663436889648,,
,27678114.81,4370,65.9708518981934,0.0500000007450581,0,,,0.0986689385986328,99.9020004272461,,,,,,7.86898544436238e-006,,,25,,98.6689385986328,,
,27678294.80,4370,64.4716491699219,0.0500000007450581,0,,,0.0999987768554687,99.9020004272461,,,,,,9.98043380061341e-006,,,25,,99.9987768554687,,
,27678474.97,4370,62.9700508117676,0.0500000007450581,0,,,0.101385102844238,99.9020004272461,,,,,,7.37431235816227e-006,,,25,,101.385102844238,,
,27678654.78,4370,61.4704990386963,0.0500000007450581,0,,,0.102813577575684,99.9020004272461,,,,,,8.05946528190953e-006,,,25,,102.813577575684,,
,27678834.23,4370,59.9766006469727,0.0500000007450581,0,,,0.10429354888916,99.9020004272461,,,,,,7.5547832159831e-006,,,25,,104.29354888916,,
,27679014.09,4370,58.4783496856689,0.0500000007450581,0,,,0.105834886169434,99.9020004272461,,,,,,8.14886199304551e-006,,,25,,105.834886169434,,
,27679194.06,4370,56.975549697876,0.0500000007450581,0,,,0.10742551574707,99.9020004272461,,,,,,8.11458649625524e-006,,,25,,107.42551574707,,
,27679374.77,4370,55.4744510650635,0.0500000007450581,0,,,0.109083637695313,99.9020004272461,,,,,,9.51310894403408e-006,,,25,,109.083637695313,,
,27679554.89,4370,53.9716491699219,0.0500000007450581,0,,,0.110791455688477,99.9020004272461,,,,,,8.84685123307529e-006,,,25,,110.791455688477,,
,27679734.34,4370,52.4786014556885,0.0500000007450581,0,,,0.112549636230469,99.9020004272461,,,,,,9.23677287652244e-006,,,25,,112.549636230469,,
,27679914.59,4370,50.9758491516113,0.0500000007450581,0,,,0.11433703125,99.9020004272461,,,,,,1.02233166332608e-005,,,25,,114.33703125,,
,27680095.05,4370,49.4700508117676,0.0500000007450581,0,,,0.116218895874023,99.9020004272461,,,,,,9.90491204980748e-006,,,25,,116.218895874023,,
,27680275.41,4370,47.96755027771,0.0500000007450581,0,,,0.11824096496582,99.9020004272461,,,,,,1.05255456924138e-005,,,25,,118.24096496582,,
,27680454.78,4370,46.4760513305664,0.0500000007450581,0,,,0.120342972412109,99.9020004272461,,,,,,1.09036392098776e-005,,,25,,120.342972412109,,
,27680634.97,4370,44.9710502624512,0.0500000007450581,0,,,0.122551347045898,99.9020004272461,,,,,,1.24915549733976e-005,,,25,,122.551347045898,,
,27680814.55,4370,43.4761505126953,0.0500000007450581,0,,,0.124835902099609,99.9020004272461,,,,,,1.15208765123013e-005,,,25,,124.835902099609,,
,27680994.88,4370,41.9745006561279,0.0500000007450581,0,,,0.127251264343262,99.9020004272461,,,,,,1.24523478725201e-005,,,25,,127.251264343262,,
,27681175.45,4370,40.4682998657227,0.0500000007450581,0,,,0.129786540527344,99.9020004272461,,,,,,1.40556126134832e-005,,,25,,129.786540527344,,
,27681354.92,4370,38.9740505218506,0.0500000007450581,0,,,0.132438746337891,99.9020004272461,,,,,,1.48844873610817e-005,,,25,,132.438746337891,,
,27681534.63,4370,37.4766502380371,0.0500000007450581,0,,,0.135241970214844,99.9020004272461,,,,,,1.58589347909607e-005,,,25,,135.241970214844,,
,27681714.11,4370,35.9786491394043,0.0500000007450581,0,,,0.138201729125977,99.9020004272461,,,,,,1.69902092883515e-005,,,25,,138.201729125977,,
,27681894.91,4370,34.4728507995605,0.0500000007450581,0,,,0.14133962097168,99.9020004272461,,,,,,1.62065131216387e-005,,,25,,141.33962097168,,
,27682075.25,4370,32.9733009338379,0.0500000007450581,0,,,0.144644979248047,99.9020004272461,,,,,,1.63421905287681e-005,,,25,,144.644979248047,,
,27682255.64,4370,31.4686002731323,0.0500000007450581,0,,,0.148163673706055,99.9020004272461,,,,,,1.82838572340773e-005,,,25,,148.163673706055,,
,27682434.83,4370,29.9747495651245,0.0500000007450581,0,,,0.151876940307617,99.9020004272461,,,,,,2.00530425183489e-005,,,25,,151.876940307617,,
,27682615.02,4370,28.4724493026733,0.0500000007450581,0,,,0.155870279541016,99.9020004272461,,,,,,2.0332630353779e-005,,,25,,155.870279541016,,
,27682794.73,4370,26.974250793457,0.0500000007450581,0,,,0.160102015380859,99.9020004272461,,,,,,2.41413078981749e-005,,,25,,160.102015380859,,
,27682975.14,4370,25.4715003967285,0.0500000007450581,0,,,0.164623489379883,99.9020004272461,,,,,,2.38083711001766e-005,,,25,,164.623489379883,,
,27683155.25,4370,23.9728498458862,0.0500000007450581,0,,,0.16956962097168,99.9020004272461,,,,,,2.67015806400797e-005,,,25,,169.56962097168,,
,27683335.25,4370,22.4724493026733,0.0500000007450581,0,,,0.174927210693359,99.9020004272461,,,,,,2.81162297126815e-005,,,25,,174.927210693359,,
,27683515.72,4370,20.9685497283936,0.0500000007450581,0,,,0.180801558837891,99.9020004272461,,,,,,3.08835309266003e-005,,,25,,180.801558837891,,
,27683695.63,4370,19.4681005477905,0.0500000007450581,0,,,0.187311329956055,99.9020004272461,,,,,,3.61009972597864e-005,,,25,,187.311329956055,,
,27683875.61,4370,17.9713001251221,0.0500000007450581,0,,,0.194533451538086,99.9020004272461,,,,,,3.88022903274274e-005,,,25,,194.533451538086,,
,27684054.69,4370,16.4751501083374,0.0500000007450581,0,,,0.202626796264649,99.9020004272461,,,,,,4.3382636209178e-005,,,25,,202.626796264648,,
,27684234.94,4370,14.9749999046326,0.0500000007450581,0,,,0.211861753540039,99.9020004272461,,,,,,4.8884160872516e-005,,,25,,211.861753540039,,
,27684415.39,4370,13.4697999954224,0.0500000007450581,0,,,0.222590596313477,99.9020004272461,,,,,,6.226476059389e-005,,,25,,222.590596313477,,
,27684595.20,4370,11.9742498397827,0.0500000007450581,0,,,0.235228111572266,99.9020004272461,,,,,,7.06704590965679e-005,,,25,,235.228111572266,,
,27684775.06,4370,10.4754004478455,0.0500000007450581,0,,,0.250688046875,99.9020004272461,,,,,,9.3588167098899e-005,,,25,,250.688046875,,
,27684955.08,4370,8.974449634552,0.0500000007450581,0,,,0.270297888183594,99.9020004272461,,,,,,0.000117060347192381,,,25,,270.297888183594,,
,27685135.05,4370,7.47800016403198,0.0500000007450581,0,,,0.296641821289062,99.9020004272461,,,,,,0.000149239247716785,,,25,,296.641821289062,,
,27685315.16,4370,5.97730016708374,0.0500000007450581,0,,,0.335055728759766,99.9020004272461,,,,,,0.000239154035816141,,,25,,335.055728759766,,
,27685508.69,4370,5.01209998130798,0.0500000007450581,0,,,0.378555572509766,99.9020004272461,,,,,,0.000116920679300226,,,25,,378.555572509766,,
,27685687.80,4370,6.53119993209839,0.0500000007450581,0,,,0.323079375,99.9020004272461,,,,,,0.000187299156026071,,,25,,323.079375,,
,27685868.02,4370,8.02239990234375,0.0500000007450581,0,,,0.28878310546875,99.9020004272461,,,,,,0.000148177867645274,,,25,,288.78310546875,,
,27686047.77,4370,9.52664995193481,0.0500000007450581,0,,,0.264248327636719,99.9020004272461,,,,,,0.000120649984865586,,,25,,264.248327636719,,
,27686228.63,4370,11.0276002883911,0.0500000007450581,0,,,0.24587430480957,99.9020004272461,,,,,,8.44806437849279e-005,,,25,,245.87430480957,,
,27686408.80,4370,12.5277500152588,0.0500000007450581,0,,,0.231315448608398,99.9020004272461,,,,,,7.19425859996593e-005,,,25,,231.315448608398,,
,27686588.52,4370,14.0262498855591,0.0500000007450581,0,,,0.219230037231445,99.9020004272461,,,,,,5.68051756917429e-005,,,25,,219.230037231445,,
,27686768.08,4370,15.5223999023438,0.0500000007450581,0,,,0.209016611938477,99.9020004272461,,,,,,4.85565579836765e-005,,,25,,209.016611938477,,
,27686948.92,4370,17.0308494567871,0.0500000007450581,0,,,0.200127445068359,99.9020004272461,,,,,,4.35432838921419e-005,,,25,,200.127445068359,,
,27687127.70,4370,18.518500328064,0.0500000007450581,0,,,0.192259411621094,99.9020004272461,,,,,,3.10617630394386e-005,,,25,,192.259411621094,,
,27687309.53,4370,20.0221996307373,0.0500000007450581,0,,,0.185364829711914,99.9020004272461,,,,,,3.2245556779521e-005,,,25,,185.364829711914,,
,27687488.67,4370,21.5264005661011,0.0500000007450581,0,,,0.179180354003906,99.9020004272461,,,,,,3.20745686131096e-005,,,25,,179.180354003906,,
,27687667.72,4370,23.0257997512817,0.0500000007450581,0,,,0.173388524169922,99.9020004272461,,,,,,2.93563626897373e-005,,,25,,173.388524169922,,
,27687849.00,4370,24.5292997360229,0.0500000007450581,0,,,0.168276743774414,99.9020004272461,,,,,,2.73909678701486e-005,,,25,,168.276743774414,,
,27688028.03,4370,26.0303497314453,0.0500000007450581,0,,,0.163484260253906,99.9020004272461,,,,,,2.51645120275118e-005,,,25,,163.484260253906,,
,27688209.39,4370,27.5312004089355,0.0500000007450581,0,,,0.158994587402344,99.9020004272461,,,,,,2.03096783293172e-005,,,25,,158.994587402344,,
,27688388.72,4370,29.0275497436523,0.0500000007450581,0,,,0.154852906494141,99.9020004272461,,,,,,1.94648483035266e-005,,,25,,154.852906494141,,
,27688569.11,4370,30.529200553894,0.0500000007450581,0,,,0.150923971557617,99.9020004272461,,,,,,1.90430667576897e-005,,,25,,150.923971557617,,
,27688748.42,4370,32.0254993438721,0.0500000007450581,0,,,0.147278914794922,99.9020004272461,,,,,,1.83509152840452e-005,,,25,,147.278914794922,,
,27688928.55,4370,33.5270500183105,0.0500000007450581,0,,,0.143849245605469,99.9020004272461,,,,,,2.14956992003376e-005,,,25,,143.849245605469,,
,27689108.22,4370,35.0223999023438,0.0500000007450581,0,,,0.140604775390625,99.9020004272461,,,,,,1.52212860041251e-005,,,25,,140.604775390625,,
,27689288.53,4370,36.5228500366211,0.0500000007450581,0,,,0.137532162475586,99.9020004272461,,,,,,1.41034848769977e-005,,,25,,137.532162475586,,
,27689468.48,4370,38.0247001647949,0.0500000007450581,0,,,0.134626973266602,99.9020004272461,,,,,,1.41152552123651e-005,,,25,,134.626973266602,,
,27689648.50,4370,39.5240001678467,0.0500000007450581,0,,,0.13187471862793,99.9020004272461,,,,,,1.31421710694307e-005,,,25,,131.87471862793,,
,27689828.75,4370,41.0237007141113,0.0500000007450581,0,,,0.129262465820313,99.9020004272461,,,,,,1.21003996432422e-005,,,25,,129.262465820313,,
,27690008.83,4370,42.5249500274658,0.0500000007450581,0,,,0.126785989074707,99.9020004272461,,,,,,1.24049195340921e-005,,,25,,126.785989074707,,
,27690189.11,4370,44.0282001495361,0.0500000007450581,0,,,0.12441019317627,99.9020004272461,,,,,,1.20286175573519e-005,,,25,,124.41019317627,,
,27690368.95,4370,45.5261497497559,0.0500000007450581,0,,,0.12216993347168,99.9020004272461,,,,,,1.05889818784292e-005,,,25,,122.16993347168,,
,27690548.80,4370,47.0233497619629,0.0500000007450581,0,,,0.120007612915039,99.9020004272461,,,,,,1.06977801723061e-005,,,25,,120.007612915039,,
,27690729.17,4370,48.5275993347168,0.0500000007450581,0,,,0.117928530578613,99.9020004272461,,,,,,1.06032972514249e-005,,,25,,117.928530578613,,
,27690907.95,4370,50.0162010192871,0.0500000007450581,0,,,0.115948532409668,99.9020004272461,,,,,,9.47925554073993e-006,,,25,,115.948532409668,,
,27691089.30,4370,51.529899597168,0.0500000007450581,0,,,0.114039432373047,99.9020004272461,,,,,,9.75564802344499e-006,,,25,,114.039432373047,,
,27691269.16,4370,53.0306491851807,0.0500000007450581,0,,,0.112227242126465,99.9020004272461,,,,,,9.62670498021309e-006,,,25,,112.227242126465,,
,27691448.48,4370,54.5226001739502,0.0500000007450581,0,,,0.110499432983398,99.9020004272461,,,,,,9.62933264512171e-006,,,25,,110.499432983398,,
,27691628.42,4370,56.0236015319824,0.0500000007450581,0,,,0.108813751220703,99.9020004272461,,,,,,8.19786432119318e-006,,,25,,108.813751220703,,
,27691808.70,4370,57.5251502990723,0.0500000007450581,0,,,0.107248359069824,99.9020004272461,,,,,,8.83610058785004e-006,,,25,,107.248359069824,,
,27691988.89,4370,59.0234508514404,0.0500000007450581,0,,,0.105676772155762,99.9020004272461,,,,,,8.80016453517221e-006,,,25,,105.676772155762,,
,27692168.33,4370,60.5194492340088,0.0500000007450581,0,,,0.104159089050293,99.9020004272461,,,,,,7.04157669430422e-006,,,25,,104.159089050293,,
,27692348.59,4370,62.0228004455566,0.0500000007450581,0,,,0.102695080566406,99.9020004272461,,,,,,7.04889946687562e-006,,,25,,102.695080566406,,
,27692529.52,4370,63.5286502838135,0.0500000007450581,0,,,0.101278687438965,99.9020004272461,,,,,,7.1136063103317e-006,,,25,,101.278687438965,,
,27692708.63,4370,65.0240478515625,0.0500000007450581,0,,,0.0999170388793945,99.9020004272461,,,,,,6.64376385992661e-006,,,25,,99.9170388793945,,
,27692888.33,4370,66.5236511230469,0.0500000007450581,0,,,0.0985936599731446,99.9020004272461,,,,,,6.40965195837681e-006,,,25,,98.5936599731445,,
,27693069.13,4370,68.0296478271484,0.0500000007450581,0,,,0.0973136361694336,99.9020004272461,,,,,,6.42235644725716e-006,,,25,,97.3136361694336,,
,27693248.05,4370,69.5234489440918,0.0500000007450581,0,,,0.0960698352050781,99.9020004272461,,,,,,6.69744659975638e-006,,,25,,96.0698352050781,,
,27693427.98,4370,71.0230484008789,0.0500000007450581,0,,,0.0948655191040039,99.9020004272461,,,,,,5.65938376011129e-006,,,25,,94.8655191040039,,
,27693608.11,4370,72.5275993347168,0.0500000007450581,0,,,0.0936283041381836,99.9020004272461,,,,,,5.69764670536126e-006,,,25,,93.6283041381836,,
,27693788.06,4370,74.0288505554199,0.0500000007450581,0,,,0.0924892568969727,99.9020004272461,,,,,,5.61805782589993e-006,,,25,,92.4892568969727,,
,27693967.98,4370,75.5283470153809,0.0500000007450581,0,,,0.0913853381347657,99.9020004272461,,,,,,5.46262157302459e-006,,,25,,91.3853381347656,,
,27694146.89,4370,77.0225486755371,0.0500000007450581,0,,,0.0903293099975586,99.9020004272461,,,,,,5.20095288598957e-006,,,25,,90.3293099975586,,
,27694327.05,4370,78.5263023376465,0.0500000007450581,0,,,0.0892916271972656,99.9020004272461,,,,,,5.19282234128523e-006,,,25,,89.2916271972656,,
,27694506.92,4370,80.0239486694336,0.0500000007450581,0,,,0.0882823236083984,99.9020004272461,,,,,,5.26781611201354e-006,,,25,,88.2823236083984,,
,27694686.38,4370,81.5258483886719,0.0500000007450581,0,,,0.0873014657592774,99.9020004272461,,,,,,5.34684002463233e-006,,,25,,87.3014657592773,,
,27694866.28,4370,83.021598815918,0.0500000007450581,0,,,0.0863456008911133,99.9020004272461,,,,,,4.66815404894834e-006,,,25,,86.3456008911133,,
,27695046.31,4370,84.5251998901367,0.0500000007450581,0,,,0.0854070391845703,99.9020004272461,,,,,,5.59414407535367e-006,,,25,,85.4070391845703,,
,27695226.78,4370,86.0299491882324,0.0500000007450581,0,,,0.0844951226806641,99.9020004272461,,,,,,5.11043827721527e-006,,,25,,84.4951226806641,,
,27695405.84,4370,87.521900177002,0.0500000007450581,0,,,0.0836015179443359,99.9020004272461,,,,,,4.94672728513026e-006,,,25,,83.6015179443359,,
,27695586.14,4370,89.0269012451172,0.0500000007450581,0,,,0.082722709350586,99.9020004272461,,,,,,4.83788462681336e-006,,,25,,82.7227093505859,,
,27695765.72,4370,90.5242004394531,0.0500000007450581,0,,,0.0818669519042969,99.9020004272461,,,,,,4.64887059205433e-006,,,25,,81.8669519042969,,
,27695945.27,4370,92.019702911377,0.0500000007450581,0,,,0.0810286856079102,99.9020004272461,,,,,,4.31694043367048e-006,,,25,,81.0286856079102,,
,27696125.92,4370,93.528751373291,0.0500000007450581,0,,,0.0802092352294922,99.9020004272461,,,,,,4.70881298739533e-006,,,25,,80.2092352294922,,
,27696306.14,4370,95.0304985046387,0.0500000007450581,0,,,0.0794093905639648,99.9020004272461,,,,,,4.42525494446101e-006,,,25,,79.4093905639648,,
,27696485.39,4370,96.5251998901367,0.0500000007450581,0,,,0.0786367086791992,99.9020004272461,,,,,,4.1667050374767e-006,,,25,,78.6367086791992,,
,27696665.97,4370,98.030200958252,0.0500000007450581,0,,,0.0778732342529297,99.9020004272461,,,,,,4.2538714989619e-006,,,25,,77.8732342529297,,
,27696844.84,4370,99.521598815918,0.0500000007450581,0,,,0.0771403063964844,99.9020004272461,,,,,,4.00938338101264e-006,,,25,,77.1403063964844,,
,27697025.00,4370,101.02294921875,0.0500000007450581,0,,,0.0764154153442383,99.9020004272461,,,,,,3.36865863793257e-006,,,25,,76.4154153442383,,
,27697204.95,4370,102.52405166626,0.0500000007450581,0,,,0.075708955078125,99.9020004272461,,,,,,3.32814556012206e-006,,,25,,75.708955078125,,
,27697384.20,4370,104.022850036621,0.0500000007450581,0,,,0.0750166687011719,99.9020004272461,,,,,,3.7205794843183e-006,,,25,,75.0166687011719,,
,27697563.86,4370,105.518852233887,0.0500000007450581,0,,,0.0743428091430664,99.9020004272461,,,,,,3.30410700618193e-006,,,25,,74.3428091430664,,
,27697744.08,4370,107.027000427246,0.0500000007450581,0,,,0.0736746746826172,99.9020004272461,,,,,,3.22764857156491e-006,,,25,,73.6746746826172,,
,27697923.98,4370,108.524551391602,0.0500000007450581,0,,,0.0730266372680664,99.9020004272461,,,,,,3.1767254659407e-006,,,25,,73.0266372680664,,
,27698103.77,4370,110.023651123047,0.0500000007450581,0,,,0.0723852056884766,99.9020004272461,,,,,,3.16915812217258e-006,,,25,,72.3852056884766,,
,27698283.38,4370,111.523300170898,0.0500000007450581,0,,,0.0717599298095703,99.9020004272461,,,,,,3.05983335422094e-006,,,25,,71.7599298095703,,
,27698463.23,4370,113.023197174072,0.0500000007450581,0,,,0.0711492239379883,99.9020004272461,,,,,,3.00871408142346e-006,,,25,,71.1492239379883,,
,27698643.23,4370,114.523399353027,0.0500000007450581,0,,,0.0705487512207031,99.9020004272461,,,,,,2.88458717088731e-006,,,25,,70.5487512207031,,
,27698822.69,4370,116.022048950195,0.0500000007450581,0,,,0.0699596374511719,99.9020004272461,,,,,,2.7779808479189e-006,,,25,,69.9596374511719,,
,27699003.50,4370,117.531650543213,0.0500000007450581,0,,,0.069376646118164,99.9020004272461,,,,,,2.85797072430411e-006,,,25,,69.3766461181641,,
,27699182.25,4370,119.021499633789,0.0500000007450581,0,,,0.0688112194824219,99.9020004272461,,,,,,2.90860270644591e-006,,,25,,68.8112194824219,,
,27699362.11,4370,120.522399902344,0.0500000007450581,0,,,0.0682506991577148,99.9020004272461,,,,,,2.71583052473358e-006,,,25,,68.2506991577148,,
,27699541.89,4370,122.02184677124,0.0500000007450581,0,,,0.0677023669433594,99.9020004272461,,,,,,2.7158862546729e-006,,,25,,67.7023669433594,,
,27699721.33,4370,123.522998809814,0.0500000007450581,0,,,0.0671674896240234,99.9020004272461,,,,,,2.61606571637662e-006,,,25,,67.1674896240234,,
,27699901.08,4370,125.02054977417,0.0500000007450581,0,,,0.06664015625,99.9020004272461,,,,,,3.48383738195864e-006,,,25,,66.64015625,,
,27700081.08,4370,126.52184677124,0.0500000007450581,0,,,0.066120514831543,99.9020004272461,,,,,,2.54278250577279e-006,,,25,,66.120514831543,,
,27700260.89,4370,128.022300720215,0.0500000007450581,0,,,0.0656096090698242,99.9020004272461,,,,,,2.45417777097113e-006,,,25,,65.6096090698242,,
,27700441.89,4370,129.527198791504,0.0500000007450581,0,,,0.0651084997558594,99.9020004272461,,,,,,2.54933219985416e-006,,,25,,65.1084997558594,,
,27700621.50,4370,131.023246765137,0.0500000007450581,0,,,0.0646153536987304,99.9020004272461,,,,,,2.49320358610499e-006,,,25,,64.6153536987305,,
,27700802.02,4370,132.525749206543,0.0500000007450581,0,,,0.0641311242675781,99.9020004272461,,,,,,2.35893915235941e-006,,,25,,64.1311242675781,,
,27700982.67,4370,134.029853820801,0.0500000007450581,0,,,0.0636546025085449,99.9020004272461,,,,,,2.30623659442722e-006,,,25,,63.6546025085449,,
,27701162.25,4370,135.526145935059,0.0500000007450581,0,,,0.0631871839904785,99.9020004272461,,,,,,2.55761493631302e-006,,,25,,63.1871839904785,,
,27701342.09,4370,137.018943786621,0.0500000007450581,0,,,0.0627292967224121,99.9020004272461,,,,,,2.21594169809563e-006,,,25,,62.7292967224121,,
,27701522.89,4370,138.525299072266,0.0500000007450581,0,,,0.0622718893432617,99.9020004272461,,,,,,2.16366258796825e-006,,,25,,62.2718893432617,,
,27701703.42,4370,140.028953552246,0.0500000007450581,0,,,0.0618237936401367,99.9020004272461,,,,,,2.3323651417759e-006,,,25,,61.8237936401367,,
,27701882.97,4370,141.522750854492,0.0500000007450581,0,,,0.0613880029296875,99.9020004272461,,,,,,2.18225255267542e-006,,,25,,61.3880029296875,,
,27702064.03,4370,143.031547546387,0.0500000007450581,0,,,0.0609532037353516,99.9020004272461,,,,,,2.1612171615137e-006,,,25,,60.9532037353516,,
,27702244.09,4370,144.525802612305,0.0500000007450581,0,,,0.0605284394836426,99.9020004272461,,,,,,1.96221146475116e-006,,,25,,60.5284394836426,,
,27702423.59,4370,146.023147583008,0.0500000007450581,0,,,0.0601083535766602,99.9020004272461,,,,,,2.24813022873758e-006,,,25,,60.1083535766602,,
,27702604.61,4370,147.528945922852,0.0500000007450581,0,,,0.0596971597290039,99.9020004272461,,,,,,2.11779825146344e-006,,,25,,59.6971597290039,,
,27702784.64,4370,149.028953552246,0.0500000007450581,0,,,0.059291467590332,99.9020004272461,,,,,,2.01693079154751e-006,,,25,,59.291467590332,,
,27702964.16,4370,150.519844055176,0.0500000007450581,0,,,0.0588964646911621,99.9020004272461,,,,,,1.98308812286299e-006,,,25,,58.8964646911621,,
,27703144.67,4370,152.024200439453,0.0500000007450581,0,,,0.0585029748535156,99.9020004272461,,,,,,1.93513704265274e-006,,,25,,58.5029748535156,,
,27703324.63,4370,153.519302368164,0.0500000007450581,0,,,0.0581164846801758,99.9020004272461,,,,,,2.0149959718126e-006,,,25,,58.1164846801758,,
,27703505.02,4370,155.020149230957,0.0500000007450581,0,,,0.0577354020690918,99.9020004272461,,,,,,1.86016676442349e-006,,,25,,57.7354020690918,,
,27703685.59,4370,156.523750305176,0.0500000007450581,0,,,0.0573595317077637,99.9020004272461,,,,,,1.85137499592084e-006,,,25,,57.3595317077637,,
,27703866.09,4370,158.026252746582,0.0500000007450581,0,,,0.0569878327941895,99.9020004272461,,,,,,1.8051850953442e-006,,,25,,56.9878327941895,,
,27704045.48,4370,159.521606445313,0.0500000007450581,0,,,0.0566276603698731,99.9020004272461,,,,,,1.93582493381566e-006,,,25,,56.627660369873,,
,27704226.64,4370,161.028053283691,0.0500000007450581,0,,,0.0562628280639648,99.9020004272461,,,,,,1.69776848501958e-006,,,25,,56.2628280639648,,
,27704406.16,4370,162.523506164551,0.0500000007450581,0,,,0.0559096318054199,99.9020004272461,,,,,,1.65873831958586e-006,,,25,,55.9096318054199,,
,27704586.70,4370,164.024551391602,0.0500000007450581,0,,,0.0555630226135254,99.9020004272461,,,,,,1.68220886063097e-006,,,25,,55.5630226135254,,
,27704766.45,4370,165.522598266602,0.0500000007450581,0,,,0.0552184100341797,99.9020004272461,,,,,,1.69143128257956e-006,,,25,,55.2184100341797,,
,27704946.64,4370,167.020149230957,0.0500000007450581,0,,,0.0548808258056641,99.9020004272461,,,,,,1.69977341258621e-006,,,25,,54.8808258056641,,
,27705127.45,4370,168.528701782227,0.0500000007450581,0,,,0.054544944152832,99.9020004272461,,,,,,1.60107596588601e-006,,,25,,54.544944152832,,
,27705307.36,4370,170.024398803711,0.0500000007450581,0,,,0.0542153079223633,99.9020004272461,,,,,,1.66392435369828e-006,,,25,,54.2153079223633,,
,27705487.95,4370,171.52774810791,0.0500000007450581,0,,,0.0538870837402344,99.9020004272461,,,,,,1.69921494607697e-006,,,25,,53.8870837402344,,
,27705668.72,4370,173.030197143555,0.0500000007450581,0,,,0.0535647203063965,99.9020004272461,,,,,,1.63612689301865e-006,,,25,,53.5647203063965,,
,27705848.30,4370,174.526947021484,0.0500000007450581,0,,,0.0532489663696289,99.9020004272461,,,,,,1.56947391035623e-006,,,25,,53.2489663696289,,
,27706027.98,4370,176.022254943848,0.0500000007450581,0,,,0.0529373143005371,99.9020004272461,,,,,,1.64199803085873e-006,,,25,,52.9373143005371,,
,27706208.42,4370,177.524353027344,0.0500000007450581,0,,,0.0526276322937012,99.9020004272461,,,,,,1.64194322550548e-006,,,25,,52.6276322937012,,
,27706389.38,4370,179.030250549316,0.0500000007450581,0,,,0.0523216818237305,99.9020004272461,,,,,,1.61894350962042e-006,,,25,,52.3216818237305,,
,27706569.11,4370,180.522750854492,0.0500000007450581,0,,,0.0520235781860351,99.9020004272461,,,,,,1.44562249819078e-006,,,25,,52.0235781860352,,
,27706749.94,4370,182.029251098633,0.0500000007450581,0,,,0.0517288890075684,99.9020004272461,,,,,,1.48605292365356e-006,,,25,,51.7288890075684,,
,27706929.53,4370,183.52490234375,0.0500000007450581,0,,,0.0514355104064941,99.9020004272461,,,,,,1.55087147738888e-006,,,25,,51.4355104064941,,
,27707109.91,4370,185.025848388672,0.0500000007450581,0,,,0.0511467919921875,99.9020004272461,,,,,,1.35740592730305e-006,,,25,,51.1467919921875,,
,27707290.73,4370,186.530448913574,0.0500000007450581,0,,,0.0508638339233399,99.9020004272461,,,,,,1.44745775833163e-006,,,25,,50.8638339233398,,
,27707470.23,4370,188.023696899414,0.0500000007450581,0,,,0.0505838029479981,99.9020004272461,,,,,,1.40580373939161e-006,,,25,,50.583802947998,,
,27707650.95,4370,189.528099060059,0.0500000007450581,0,,,0.0503091947937012,99.9020004272461,,,,,,1.27383532542511e-006,,,25,,50.3091947937012,,
,27707830.28,4370,191.019546508789,0.0500000007450581,0,,,0.0500362898254395,99.9020004272461,,,,,,1.39904723546925e-006,,,25,,50.0362898254395,,
,27708010.81,4370,192.525451660156,0.0500000007450581,0,,,0.0497673529052734,99.9020004272461,,,,,,1.46172850822006e-006,,,25,,49.7673529052734,,
,27708191.27,4370,194.02424621582,0.0500000007450581,0,,,0.0495023336791992,99.9020004272461,,,,,,1.58316318593061e-006,,,25,,49.5023336791992,,
,27708372.11,4370,195.528450012207,0.0500000007450581,0,,,0.0492400271606445,99.9020004272461,,,,,,1.17439204274591e-006,,,25,,49.2400271606445,,
,27708551.95,4370,197.026954650879,0.0500000007450581,0,,,0.0489802076721192,99.9020004272461,,,,,,1.34416290475109e-006,,,25,,48.9802076721191,,
,27708731.86,4370,198.525901794434,0.0500000007450581,0,,,0.0487255509948731,99.9020004272461,,,,,,1.28887591511959e-006,,,25,,48.725550994873,,
,27708912.22,4370,200.022804260254,0.0500000007450581,0,,,0.0484730577087402,99.9020004272461,,,,,,1.18878739259405e-006,,,25,,48.4730577087402,,
,27709092.80,4370,201.52645111084,0.0500000007450581,0,,,0.0482238819885254,99.9020004272461,,,,,,1.20997477639365e-006,,,25,,48.2238819885254,,
,27709272.17,4370,203.019950866699,0.0500000007450581,0,,,0.0479803407287598,99.9020004272461,,,,,,1.17610407483705e-006,,,25,,47.9803407287598,,
,27709452.69,4370,204.522354125977,0.0500000007450581,0,,,0.0477348374938965,99.9020004272461,,,,,,1.19205069420667e-006,,,25,,47.7348374938965,,
,27709632.44,4370,206.022552490234,0.0500000007450581,0,,,0.0474954342651367,99.9020004272461,,,,,,1.32752576668141e-006,,,25,,47.4954342651367,,
,27709692.95,4370,206.523300170898,0.0500000007450581,0,,,0.0474161198425293,99.9020004272461,,,,,,1.26696278942663e-006,,,25,,47.4161198425293,,