File: data/161117-cernox calibration/161121_time-dep-50K-.dat
[Header]
TITLE, default name
FILEOPENTIME, 28171872.56, 11/21/2016, 5:25 PM
BYAPP, Resistivity, 2.0, 1.0
INFO, APPNAME, PPMS MultiVu Application, Release 1.5.0.19
INFO, , Sample1 Name
INFO, 1, Sample1 Cross Section
INFO, 1, Sample1 Length
INFO, Ohm-m, Sample1 Units
INFO, cernox r07 c12, Sample2 Name
INFO, 1, Sample2 Cross Section
INFO, 1, Sample2 Length
INFO, Ohm-m, Sample2 Units
INFO, , Sample3 Name
INFO, 1, Sample3 Cross Section
INFO, 1, Sample3 Length
INFO, Ohm-m, Sample3 Units
INFO, , Sample4 Name
INFO, 1, Sample4 Cross Section
INFO, 1, Sample4 Length
INFO, Ohm-m, Sample4 Units
FIELDGROUP, Resistivity,2,3,4,5,6,7,8,9,10,11,12,13,14,15,16,17,18,19,20,21,22,23,24,25,26,27,28,29,30,31,32,33,34,35,36,37,38,39,40,41
STARTUPGROUP, Resistivity
STARTUPAXIS, X, 2, LINEAR, AUTO
STARTUPAXIS, Y1, 7, LINEAR, AUTO
STARTUPAXIS, Y2, 9, LINEAR, AUTO
STARTUPAXIS, Y3, 11, LINEAR, AUTO
PLOT_APPEARANCE, ALL, HORZ_GRID_ON, VERT_GRID_ON, MARKERS_AND_LINES, ALL_LINES
DATATYPE, TIME, 2
DATATYPE, COMMENT, 1
[Data]
Comment,Time Stamp (sec),Status (code),Temperature (K),Magnetic Field (Oe),Sample Position (deg),Bridge 1 Resistivity (Ohm-m),Bridge 1 Excitation (uA),Bridge 2 Resistivity (Ohm-m),Bridge 2 Excitation (uA),Bridge 3 Resistivity (Ohm-m),Bridge 3 Excitation (uA),Bridge 4 Resistivity (Ohm-m),Bridge 4 Excitation (uA),Bridge 1 Std. Dev. (Ohm-m),Bridge 2 Std. Dev. (Ohm-m),Bridge 3 Std. Dev. (Ohm-m),Bridge 4 Std. Dev. (Ohm-m),Number of Readings,Bridge 1 Resistance (Ohms),Bridge 2 Resistance (Ohms),Bridge 3 Resistance (Ohms),Bridge 4 Resistance (Ohms),Signal 1 Vin (V),Signal 2 Vin (V),Digital Inputs (code),Drive 1 Iout (mA),Drive 1 Ipower (watts),Drive 2 Iout (mA),Drive 2 Ipower (watts),Pressure (),Map 20 (),Map 21 (),Map 22 (),Map 23 (),Map 24 (),Map 25 (),Map 26 (),Map 27 (),Map 28 (),Map 29 ()
,28181197.75,4369,50.0119495391846,-0.112000003457069,284.35400390625,,,0.115752956237793,99.9020004272461,,,,,,4.26995708860149e-006,,,25,,115.752956237793,,
,28181218.45,4369,49.9986000061035,-0.112000003457069,284.35400390625,,,0.115752803039551,99.9020004272461,,,,,,4.00211167728321e-006,,,25,,115.752803039551,,
,28181237.88,4369,50.0040988922119,-0.112000003457069,284.35400390625,,,0.11574974822998,99.9020004272461,,,,,,4.16854304040534e-006,,,25,,115.74974822998,,
,28181258.45,4369,50.0024013519287,-0.112000003457069,284.35400390625,,,0.115725431213379,99.9020004272461,,,,,,3.30716829434106e-006,,,25,,115.725431213379,,
,28181277.86,4369,50.0018005371094,-0.112000003457069,284.35400390625,,,0.115731884460449,99.9020004272461,,,,,,3.08900983942129e-006,,,25,,115.731884460449,,
,28181298.53,4369,50.0169506072998,-0.112000003457069,284.35400390625,,,0.115707560119629,99.9020004272461,,,,,,3.24397072789262e-006,,,25,,115.707560119629,,
,28181318.00,4369,50.0073490142822,-0.112000003457069,284.35400390625,,,0.115693356018066,99.9020004272461,,,,,,3.53102181840366e-006,,,25,,115.693356018066,,
,28181337.59,4369,50.0107517242432,-0.112000003457069,284.35400390625,,,0.115674409179688,99.9020004272461,,,,,,4.06671917316439e-006,,,25,,115.674409179688,,
,28181358.23,4369,50.0049495697021,-0.112000003457069,284.35400390625,,,0.115666924743652,99.9020004272461,,,,,,3.17961165145625e-006,,,25,,115.666924743652,,
,28181377.66,4369,50.0035018920898,-0.112000003457069,284.35400390625,,,0.115659525756836,99.9020004272461,,,,,,3.65737975911786e-006,,,25,,115.659525756836,,
,28181398.38,4369,49.9972496032715,-0.112000003457069,284.35400390625,,,0.115658723754883,99.9020004272461,,,,,,4.81714949918795e-006,,,25,,115.658723754883,,
,28181417.81,4369,49.9913997650146,-0.112000003457069,284.35400390625,,,0.1156711328125,99.9020004272461,,,,,,4.1330771674958e-006,,,25,,115.6711328125,,
,28181438.45,4369,49.9950981140137,-0.112000003457069,284.35400390625,,,0.115681677246094,99.9020004272461,,,,,,3.36656119776414e-006,,,25,,115.681677246094,,
,28181457.95,4369,49.9956493377686,-0.112000003457069,284.35400390625,,,0.115686488647461,99.9020004272461,,,,,,4.02251858585872e-006,,,25,,115.686488647461,,
,28181478.53,4369,49.9965000152588,-0.112000003457069,284.35400390625,,,0.115691148681641,99.9020004272461,,,,,,3.2486648704004e-006,,,25,,115.691148681641,,
,28181498.48,4369,49.998498916626,-0.112000003457069,284.35400390625,,,0.115695231628418,99.9020004272461,,,,,,3.03063069790069e-006,,,25,,115.695231628418,,
,28181517.86,4369,50.0007495880127,-0.112000003457069,284.35400390625,,,0.115694507446289,99.9020004272461,,,,,,4.02049334287963e-006,,,25,,115.694507446289,,
,28181538.61,4369,49.9992504119873,-0.112000003457069,284.35400390625,,,0.11569568939209,99.9020004272461,,,,,,2.50581334169902e-006,,,25,,115.69568939209,,
,28181558.13,4369,50.0012493133545,-0.112000003457069,284.35400390625,,,0.115691489868164,99.9020004272461,,,,,,3.9465567446635e-006,,,25,,115.691489868164,,
,28181577.48,4369,50.0004005432129,-0.112000003457069,284.35400390625,,,0.115687289428711,99.9020004272461,,,,,,3.11784098253525e-006,,,25,,115.687289428711,,
,28181598.17,4369,50.0049495697021,-0.112000003457069,284.35400390625,,,0.115684425964355,99.9020004272461,,,,,,2.91074288647078e-006,,,25,,115.684425964355,,
,28181617.69,4369,50.0035495758057,-0.112000003457069,284.35400390625,,,0.115682763977051,99.9020004272461,,,,,,3.53007720457748e-006,,,25,,115.682763977051,,
,28181638.31,4369,50.0007495880127,-0.112000003457069,284.35400390625,,,0.1156840625,99.9020004272461,,,,,,3.51405199300257e-006,,,25,,115.6840625,,
,28181657.94,4369,50.000150680542,-0.112000003457069,284.35400390625,,,0.115684139099121,99.9020004272461,,,,,,4.58779520466184e-006,,,25,,115.684139099121,,
,28181678.61,4369,49.9990005493164,-0.112000003457069,284.35400390625,,,0.115676039733887,99.9020004272461,,,,,,4.37878321624385e-006,,,25,,115.676039733887,,
,28181698.22,4369,49.9998989105225,-0.112000003457069,284.35400390625,,,0.115678598327637,99.9020004272461,,,,,,3.09009714605609e-006,,,25,,115.678598327637,,
,28181718.11,4369,49.9966506958008,-0.112000003457069,284.35400390625,,,0.11567768157959,99.9020004272461,,,,,,3.76445515429633e-006,,,25,,115.67768157959,,
,28181738.75,4369,50.0002994537354,-0.112000003457069,284.35400390625,,,0.115682304077148,99.9020004272461,,,,,,3.49296377437817e-006,,,25,,115.682304077148,,
,28181758.33,4369,50.00119972229,-0.112000003457069,284.35400390625,,,0.115681541442871,99.9020004272461,,,,,,3.39923809126897e-006,,,25,,115.681541442871,,
,28181777.66,4369,50.0004005432129,-0.112000003457069,284.35400390625,,,0.115679822692871,99.9020004272461,,,,,,3.76765209451168e-006,,,25,,115.679822692871,,
,28181798.48,4369,50.0027008056641,-0.112000003457069,284.35400390625,,,0.115673147888184,99.9020004272461,,,,,,3.43363136127744e-006,,,25,,115.673147888184,,
,28181817.94,4369,49.9993000030518,-0.112000003457069,284.35400390625,,,0.115673796386719,99.9020004272461,,,,,,4.1030603811082e-006,,,25,,115.673796386719,,
,28181838.55,4369,50.000150680542,-0.112000003457069,284.35400390625,,,0.115672956237793,99.9020004272461,,,,,,4.71681923449636e-006,,,25,,115.672956237793,,
,28181858.19,4369,49.9993000030518,-0.112000003457069,284.35400390625,,,0.115681198730469,99.9020004272461,,,,,,3.46574324908898e-006,,,25,,115.681198730469,,
,28181877.77,4369,50.000150680542,-0.112000003457069,284.35400390625,,,0.115679671020508,99.9020004272461,,,,,,3.60813957747027e-006,,,25,,115.679671020508,,
,28181898.31,4369,50,-0.112000003457069,284.35400390625,,,0.115678487243652,99.9020004272461,,,,,,3.73395409669006e-006,,,25,,115.678487243652,,
,28181917.81,4369,50.0012512207031,-0.112000003457069,284.35400390625,,,0.115675375976562,99.9020004272461,,,,,,3.31188390596621e-006,,,25,,115.675375976563,,
,28181938.47,4369,50.001501083374,-0.112000003457069,284.35400390625,,,0.115676215820312,99.9020004272461,,,,,,3.72867528229163e-006,,,25,,115.676215820313,,
,28181958.08,4369,50.0000514984131,-0.112000003457069,284.35400390625,,,0.115676063232422,99.9020004272461,,,,,,3.97695851686858e-006,,,25,,115.676063232422,,
,28181977.56,4369,50.0009002685547,-0.112000003457069,284.35400390625,,,0.115679276733398,99.9020004272461,,,,,,3.24715949776717e-006,,,25,,115.679276733398,,
,28181998.42,4369,49.9986000061035,-0.112000003457069,284.35400390625,,,0.115679104003906,99.9020004272461,,,,,,3.38058215524043e-006,,,25,,115.679104003906,,
,28182017.95,4369,49.9974002838135,-0.112000003457069,284.35400390625,,,0.115679371643066,99.9020004272461,,,,,,3.69447694908198e-006,,,25,,115.679371643066,,
,28182037.88,4369,49.9972496032715,-0.112000003457069,284.35400390625,,,0.115677240905762,99.9020004272461,,,,,,3.63710811000523e-006,,,25,,115.677240905762,,
,28182058.48,4369,49.998950958252,-0.112000003457069,284.35400390625,,,0.115676750488281,99.9020004272461,,,,,,4.61797967900976e-006,,,25,,115.676750488281,,
,28182078.02,4369,49.9997501373291,-0.112000003457069,284.35400390625,,,0.115675375671387,99.9020004272461,,,,,,3.2118902818046e-006,,,25,,115.675375671387,,
,28182097.91,4369,50.0005493164063,-0.112000003457069,284.35400390625,,,0.115674407348633,99.9020004272461,,,,,,3.16101830300388e-006,,,25,,115.674407348633,,
,28182118.63,4369,49.9988498687744,-0.112000003457069,284.35400390625,,,0.115674943847656,99.9020004272461,,,,,,3.14324638892755e-006,,,25,,115.674943847656,,
,28182138.33,4369,49.9995498657227,-0.112000003457069,284.35400390625,,,0.115674867248535,99.9020004272461,,,,,,3.7309096188369e-006,,,25,,115.674867248535,,
,28182158.14,4369,49.9993495941162,-0.112000003457069,284.35400390625,,,0.11568015625,99.9020004272461,,,,,,3.87853308789068e-006,,,25,,115.68015625,,
,28182177.94,4369,50.0013484954834,-0.112000003457069,284.35400390625,,,0.115681543884277,99.9020004272461,,,,,,2.92916214717428e-006,,,25,,115.681543884277,,
,28182198.56,4369,50.000301361084,-0.112000003457069,284.35400390625,,,0.115679176635742,99.9020004272461,,,,,,4.46796605991867e-006,,,25,,115.679176635742,,
,28182218.16,4369,49.9981002807617,-0.112000003457069,284.35400390625,,,0.115680577087402,99.9020004272461,,,,,,3.17908512590772e-006,,,25,,115.680577087402,,
,28182237.78,4369,50.0009498596191,-0.112000003457069,284.35400390625,,,0.115678488769531,99.9020004272461,,,,,,3.59011021322454e-006,,,25,,115.678488769531,,
,28182258.52,4369,49.9992008209229,-0.112000003457069,284.35400390625,,,0.115681008911133,99.9020004272461,,,,,,3.39920364401203e-006,,,25,,115.681008911133,,
,28182277.92,4369,50.0024490356445,-0.112000003457069,284.35400390625,,,0.115679275817871,99.9020004272461,,,,,,4.62840915742117e-006,,,25,,115.679275817871,,
,28182297.66,4369,50.0007495880127,-0.112000003457069,284.35400390625,,,0.115680520935059,99.9020004272461,,,,,,3.38248666370455e-006,,,25,,115.680520935059,,
,28182318.36,4369,49.9985504150391,-0.112000003457069,284.35400390625,,,0.115679756469727,99.9020004272461,,,,,,3.05437174042231e-006,,,25,,115.679756469727,,
,28182338.00,4369,49.9999504089355,-0.112000003457069,284.35400390625,,,0.11567713104248,99.9020004272461,,,,,,3.4713819363858e-006,,,25,,115.67713104248,,
,28182357.66,4369,50.0005493164063,-0.112000003457069,284.35400390625,,,0.115675548400879,99.9020004272461,,,,,,4.29350131119311e-006,,,25,,115.675548400879,,
,28182378.28,4369,49.9989986419678,-0.112000003457069,284.35400390625,,,0.11567684753418,99.9020004272461,,,,,,4.44784626840692e-006,,,25,,115.67684753418,,
,28182398.25,4369,49.9992008209229,-0.112000003457069,284.35400390625,,,0.115675687866211,99.9020004272461,,,,,,4.01228746446454e-006,,,25,,115.675687866211,,
,28182417.75,4369,49.9995002746582,-0.112000003457069,284.35400390625,,,0.115676656799316,99.9020004272461,,,,,,4.21155725058505e-006,,,25,,115.676656799316,,
,28182438.55,4369,50.0005989074707,-0.112000003457069,284.35400390625,,,0.115676618347168,99.9020004272461,,,,,,4.10332355801335e-006,,,25,,115.676618347168,,
,28182458.13,4369,49.9983501434326,-0.112000003457069,284.35400390625,,,0.115677197265625,99.9020004272461,,,,,,3.60764866709183e-006,,,25,,115.677197265625,,
,28182477.80,4369,49.9977989196777,-0.112000003457069,284.35400390625,,,0.115678116455078,99.9020004272461,,,,,,2.68604506699987e-006,,,25,,115.678116455078,,
,28182498.66,4369,49.9972496032715,-0.112000003457069,284.35400390625,,,0.11567956817627,99.9020004272461,,,,,,3.93468081725858e-006,,,25,,115.67956817627,,
,28182518.17,4369,50.0023498535156,-0.112000003457069,284.35400390625,,,0.115679454345703,99.9020004272461,,,,,,4.13212220059613e-006,,,25,,115.679454345703,,
,28182537.59,4369,50.002950668335,-0.112000003457069,284.35400390625,,,0.115678109130859,99.9020004272461,,,,,,3.97453450511528e-006,,,25,,115.678109130859,,
,28182558.34,4369,50.0038013458252,-0.112000003457069,284.35400390625,,,0.115679292602539,99.9020004272461,,,,,,3.73718014606785e-006,,,25,,115.679292602539,,
,28182577.89,4369,49.9998512268066,-0.112000003457069,284.35400390625,,,0.115678223266602,99.9020004272461,,,,,,2.91791789889625e-006,,,25,,115.678223266602,,
,28182598.56,4369,49.9981498718262,-0.112000003457069,284.35400390625,,,0.115678713073731,99.9020004272461,,,,,,3.4039940751135e-006,,,25,,115.67871307373,,
,28182617.95,4369,50.0009498596191,-0.112000003457069,284.35400390625,,,0.115681461791992,99.9020004272461,,,,,,4.05822804691201e-006,,,25,,115.681461791992,,
,28182637.59,4369,50.0000495910645,-0.112000003457069,284.35400390625,,,0.115681194458008,99.9020004272461,,,,,,3.11440117513146e-006,,,25,,115.681194458008,,
,28182658.25,4369,50.0011501312256,-0.112000003457069,284.35400390625,,,0.115682192077637,99.9020004272461,,,,,,4.47048786033829e-006,,,25,,115.682192077637,,
,28182677.70,4369,49.9997501373291,-0.112000003457069,284.35400390625,,,0.115682575073242,99.9020004272461,,,,,,3.67179308011741e-006,,,25,,115.682575073242,,
,28182697.63,4369,49.9989490509033,-0.112000003457069,284.35400390625,,,0.11568181060791,99.9020004272461,,,,,,3.33258815073411e-006,,,25,,115.68181060791,,
,28182718.25,4369,49.9978008270264,-0.112000003457069,284.35400390625,,,0.115680696716309,99.9020004272461,,,,,,5.50259977434516e-006,,,25,,115.680696716309,,
,28182737.67,4369,49.9987010955811,-0.112000003457069,284.35400390625,,,0.115682147827148,99.9020004272461,,,,,,4.27623228026237e-006,,,25,,115.682147827148,,
,28182758.44,4369,50.0008506774902,-0.112000003457069,284.35400390625,,,0.115681614379883,99.9020004272461,,,,,,3.18228331150669e-006,,,25,,115.681614379883,,
,28182777.86,4369,50.0031490325928,-0.112000003457069,284.35400390625,,,0.115684213562012,99.9020004272461,,,,,,2.88593439109507e-006,,,25,,115.684213562012,,
,28182798.50,4369,50.0008487701416,-0.112000003457069,284.35400390625,,,0.115686199951172,99.9020004272461,,,,,,4.20637921236003e-006,,,25,,115.686199951172,,
,28182818.22,4369,50.0007991790771,-0.112000003457069,284.35400390625,,,0.115685474243164,99.9020004272461,,,,,,4.12940342920046e-006,,,25,,115.685474243164,,
,28182837.61,4369,50.0011005401611,-0.112000003457069,284.35400390625,,,0.115681612243652,99.9020004272461,,,,,,3.79852582376767e-006,,,25,,115.681612243652,,
,28182858.30,4369,50.0011005401611,-0.112000003457069,284.35400390625,,,0.115680621337891,99.9020004272461,,,,,,3.6882946761236e-006,,,25,,115.680621337891,,
,28182878.03,4369,49.9992504119873,-0.112000003457069,284.35400390625,,,0.115681307983398,99.9020004272461,,,,,,3.43995613782784e-006,,,25,,115.681307983398,,
,28182897.58,4369,49.9987506866455,-0.112000003457069,284.35400390625,,,0.115678690490723,99.9020004272461,,,,,,4.51098200276114e-006,,,25,,115.678690490723,,
,28182918.16,4369,49.9993000030518,-0.112000003457069,284.35400390625,,,0.115680982055664,99.9020004272461,,,,,,4.34795761432792e-006,,,25,,115.680982055664,,
,28182937.72,4369,50.0011501312256,-0.112000003457069,284.35400390625,,,0.115679491882324,99.9020004272461,,,,,,3.39512874966297e-006,,,25,,115.679491882324,,
,28182958.30,4369,49.9997501373291,-0.112000003457069,284.35400390625,,,0.115683217773437,99.9020004272461,,,,,,3.40713414310959e-006,,,25,,115.683217773438,,
,28182977.91,4369,50.0009002685547,-0.112000003457069,284.35400390625,,,0.115683293457031,99.9020004272461,,,,,,3.53798401943531e-006,,,25,,115.683293457031,,
,28182998.66,4369,49.9998989105225,-0.112000003457069,284.35400390625,,,0.115682950134277,99.9020004272461,,,,,,4.7468312057824e-006,,,25,,115.682950134277,,
,28183017.92,4369,49.9973487854004,-0.112000003457069,284.35400390625,,,0.115683268127441,99.9020004272461,,,,,,3.47798372337117e-006,,,25,,115.683268127441,,
,28183037.45,4369,50.0002002716064,-0.112000003457069,284.35400390625,,,0.115685139465332,99.9020004272461,,,,,,3.49451615463621e-006,,,25,,115.685139465332,,
,28183058.17,4369,49.9990501403809,-0.112000003457069,284.35400390625,,,0.115685636901855,99.9020004272461,,,,,,2.71394525291925e-006,,,25,,115.685636901855,,
,28183077.95,4369,49.997350692749,-0.112000003457069,284.35400390625,,,0.115678456420898,99.9020004272461,,,,,,4.47037455152497e-006,,,25,,115.678456420898,,
,28183098.61,4369,50.0004482269287,-0.112000003457069,284.35400390625,,,0.115679105529785,99.9020004272461,,,,,,2.88180822372661e-006,,,25,,115.679105529785,,
,28183118.08,4369,49.9995498657227,-0.112000003457069,284.35400390625,,,0.115679221191406,99.9020004272461,,,,,,4.27910789336915e-006,,,25,,115.679221191406,,
,28183137.72,4369,50.0032501220703,-0.112000003457069,284.35400390625,,,0.115685254516602,99.9020004272461,,,,,,3.33731124720741e-006,,,25,,115.685254516602,,
,28183158.41,4369,49.9987010955811,-0.112000003457069,284.35400390625,,,0.11568491027832,99.9020004272461,,,,,,4.13051588924976e-006,,,25,,115.68491027832,,
,28183178.11,4369,50.0007019042969,-0.112000003457069,284.35400390625,,,0.11568536895752,99.9020004272461,,,,,,3.60744382087482e-006,,,25,,115.68536895752,,
,28183197.50,4369,49.9997997283936,-0.112000003457069,284.35400390625,,,0.115681538696289,99.9020004272461,,,,,,3.96504370896494e-006,,,25,,115.681538696289,,