File: data/161109-sensor-calibration/161109_RT_sensor-calib.dat
[Header]
TITLE, sensor calibration
FILEOPENTIME, 27142220.75, 11/9/2016, 7:27 PM
BYAPP, Resistivity, 2.0, 1.0
INFO, APPNAME, PPMS MultiVu Application, Release 1.5.0.19
INFO, , Sample1 Name
INFO, 1, Sample1 Cross Section
INFO, 1, Sample1 Length
INFO, Ohm-m, Sample1 Units
INFO, , Sample2 Name
INFO, 1, Sample2 Cross Section
INFO, 1, Sample2 Length
INFO, Ohm-m, Sample2 Units
INFO, cernoc R07 C12, Sample3 Name
INFO, 1, Sample3 Cross Section
INFO, 1, Sample3 Length
INFO, Ohm-m, Sample3 Units
INFO, , Sample4 Name
INFO, 1, Sample4 Cross Section
INFO, 1, Sample4 Length
INFO, Ohm-m, Sample4 Units
FIELDGROUP, Resistivity,2,3,4,5,6,7,8,9,10,11,12,13,14,15,16,17,18,19,20,21,22,23,24,25,26,27,28,29,30,31,32,33,34,35,36,37,38,39,40,41
STARTUPGROUP, Resistivity
STARTUPAXIS, X, 2, LINEAR, AUTO
STARTUPAXIS, Y1, 7, LINEAR, AUTO
STARTUPAXIS, Y2, 9, LINEAR, AUTO
STARTUPAXIS, Y3, 11, LINEAR, AUTO
PLOT_APPEARANCE, ALL, HORZ_GRID_ON, VERT_GRID_ON, MARKERS_AND_LINES, ALL_LINES
DATATYPE, TIME, 2
DATATYPE, COMMENT, 1
[Data]
Comment,Time Stamp (sec),Status (code),Temperature (K),Magnetic Field (Oe),Sample Position (deg),Bridge 1 Resistivity (Ohm-m),Bridge 1 Excitation (uA),Bridge 2 Resistivity (Ohm-m),Bridge 2 Excitation (uA),Bridge 3 Resistivity (Ohm-m),Bridge 3 Excitation (uA),Bridge 4 Resistivity (Ohm-m),Bridge 4 Excitation (uA),Bridge 1 Std. Dev. (Ohm-m),Bridge 2 Std. Dev. (Ohm-m),Bridge 3 Std. Dev. (Ohm-m),Bridge 4 Std. Dev. (Ohm-m),Number of Readings,Bridge 1 Resistance (Ohms),Bridge 2 Resistance (Ohms),Bridge 3 Resistance (Ohms),Bridge 4 Resistance (Ohms),Signal 1 Vin (V),Signal 2 Vin (V),Digital Inputs (code),Drive 1 Iout (mA),Drive 1 Ipower (watts),Drive 2 Iout (mA),Drive 2 Ipower (watts),Pressure (),Map 20 (),Map 21 (),Map 22 (),Map 23 (),Map 24 (),Map 25 (),Map 26 (),Map 27 (),Map 28 (),Map 29 ()
,27143493.92,4369,299.999694824219,0.0750000029802322,284.35400390625,,,,,0.0362773857116699,99.9020004272461,,,,,2.51190923704002e-007,,25,,,36.2773857116699,
,27145068.52,4369,294.998046875,0.0750000029802322,284.35400390625,,,,,0.0366908348083496,99.9020004272461,,,,,2.97823795912798e-007,,25,,,36.6908348083496,
,27146639.77,4369,289.997344970703,0.0750000029802322,284.35400390625,,,,,0.0371168075561523,99.9020004272461,,,,,2.08291183907878e-007,,25,,,37.1168075561523,
,27148214.64,4369,284.99755859375,0.0750000029802322,284.35400390625,,,,,0.0375563232421875,99.9020004272461,,,,,2.42399400527547e-007,,25,,,37.5563232421875,
,27149786.69,4369,279.998962402344,0.0750000029802322,284.35400390625,,,,,0.0380104388427734,99.9020004272461,,,,,5.51369314308106e-007,,25,,,38.0104388427734,
,27151359.63,4369,275.003555297852,0.0750000029802322,284.35400390625,,,,,0.0384797996520996,99.9020004272461,,,,,6.01579416800348e-007,,25,,,38.4797996520996,
,27152935.19,4369,269.997009277344,0.0750000029802322,284.35400390625,,,,,0.0389657287597656,99.9020004272461,,,,,4.34943097638176e-007,,25,,,38.9657287597656,
,27154506.72,4369,264.996612548828,0.0750000029802322,284.35400390625,,,,,0.0394691906738281,99.9020004272461,,,,,3.80871651494933e-007,,25,,,39.4691906738281,
,27156078.59,4369,259.997100830078,0.0750000029802322,284.35400390625,,,,,0.0399902239990234,99.9020004272461,,,,,5.0942685069429e-007,,25,,,39.9902239990234,
,27157652.25,4369,254.998100280762,0.0750000029802322,284.35400390625,,,,,0.0405287628173828,99.9020004272461,,,,,3.68549066595094e-007,,25,,,40.5287628173828,
,27159224.66,4369,249.996948242188,0.0750000029802322,284.35400390625,,,,,0.0410890007019043,99.9020004272461,,,,,3.37422615864161e-007,,25,,,41.0890007019043,
,27160800.39,4369,244.995796203613,0.0750000029802322,284.35400390625,,,,,0.0416683192443848,99.9020004272461,,,,,5.08857217739931e-007,,25,,,41.6683192443848,
,27162375.31,4369,239.997550964355,0.0750000029802322,284.35400390625,,,,,0.0422680754089356,99.9020004272461,,,,,4.36584464370263e-007,,25,,,42.2680754089355,
,27163951.23,4369,234.996948242188,0.0750000029802322,284.35400390625,,,,,0.0428917770385742,99.9020004272461,,,,,4.22484916534183e-007,,25,,,42.8917770385742,
,27165526.41,4369,229.994850158691,0.0750000029802322,284.35400390625,,,,,0.0435377615356445,99.9020004272461,,,,,3.8334644537567e-007,,25,,,43.5377615356445,
,27167102.28,4369,224.997543334961,0.0750000029802322,284.35400390625,,,,,0.0442128259277344,99.9020004272461,,,,,4.85186437174282e-007,,25,,,44.2128259277344,
,27168677.52,4369,220.000503540039,0.0750000029802322,284.35400390625,,,,,0.0449101676940918,99.9020004272461,,,,,4.86219068597538e-007,,25,,,44.9101676940918,
,27170251.70,4369,214.997650146484,0.0750000029802322,284.35400390625,,,,,0.0456347122192383,99.9020004272461,,,,,3.42262630049453e-007,,25,,,45.6347122192383,
,27171823.38,4369,209.997299194336,0.0750000029802322,284.35400390625,,,,,0.0463880303955078,99.9020004272461,,,,,5.34977741854452e-007,,25,,,46.3880303955078,
,27173396.77,4369,204.997802734375,0.0750000029802322,284.35400390625,,,,,0.0471715051269531,99.9020004272461,,,,,3.45848114628484e-007,,25,,,47.1715051269531,
,27174968.06,4369,199.998306274414,0.0750000029802322,284.35400390625,,,,,0.0479912109375,99.9020004272461,,,,,3.4661281386169e-007,,25,,,47.9912109375,
,27176543.44,4369,194.997352600098,0.0750000029802322,284.35400390625,,,,,0.0488422354125977,99.9020004272461,,,,,4.62933837845296e-007,,25,,,48.8422354125977,
,27178117.38,4369,189.999000549316,0.0750000029802322,284.35400390625,,,,,0.0497373542785644,99.9020004272461,,,,,4.40990827566579e-007,,25,,,49.7373542785645,
,27179690.95,4369,184.999351501465,0.0750000029802322,284.35400390625,,,,,0.0506656875610352,99.9020004272461,,,,,4.71140617292244e-007,,25,,,50.6656875610352,
,27181264.88,4369,179.998802185059,0.0750000029802322,284.35400390625,,,,,0.0516420243835449,99.9020004272461,,,,,4.15409019568516e-007,,25,,,51.6420243835449,
,27182838.78,4369,174.999702453613,0.0750000029802322,284.35400390625,,,,,0.0526567277526855,99.9020004272461,,,,,5.1234127873445e-007,,25,,,52.6567277526855,
,27184414.30,4369,169.997947692871,0.0750000029802322,284.35400390625,,,,,0.0537203102111816,99.9020004272461,,,,,5.12505890457164e-007,,25,,,53.7203102111816,
,27185989.84,4369,164.998100280762,0.0750000029802322,284.35400390625,,,,,0.0548361587524414,99.9020004272461,,,,,3.93674690147714e-007,,25,,,54.8361587524414,
,27187564.73,4369,159.998695373535,0.0750000029802322,284.35400390625,,,,,0.0560094757080078,99.9020004272461,,,,,4.7145118076964e-007,,25,,,56.0094757080078,
,27189137.98,4369,154.998603820801,0.0750000029802322,284.35400390625,,,,,0.0572347412109375,99.9020004272461,,,,,3.49126114744949e-007,,25,,,57.2347412109375,
,27190713.69,4369,149.99649810791,0.0750000029802322,284.35400390625,,,,,0.0585264096069336,99.9020004272461,,,,,4.24720876264238e-007,,25,,,58.5264096069336,
,27192283.80,4369,144.998153686523,0.0750000029802322,284.35400390625,,,,,0.0598876448059082,99.9020004272461,,,,,4.88018805397088e-007,,25,,,59.8876448059082,
,27193859.47,4369,139.997451782227,0.0750000029802322,284.35400390625,,,,,0.0613210510253906,99.9020004272461,,,,,4.13141034434397e-007,,25,,,61.3210510253906,
,27195435.36,4369,134.997955322266,0.0750000029802322,284.35400390625,,,,,0.0628302803039551,99.9020004272461,,,,,3.98562539812949e-007,,25,,,62.8302803039551,
,27197007.88,4369,130.000350952148,0.0750000029802322,284.35400390625,,,,,0.0644302651977539,99.9020004272461,,,,,4.15534800742734e-007,,25,,,64.4302651977539,
,27198583.81,4369,124.998149871826,0.0750000029802322,284.35400390625,,,,,0.0661209045410156,99.9020004272461,,,,,4.13408625426116e-007,,25,,,66.1209045410156,
,27200153.34,4369,119.998798370361,0.0750000029802322,284.35400390625,,,,,0.0679154568481445,99.9020004272461,,,,,5.23713083723538e-007,,25,,,67.9154568481445,
,27201725.61,4369,114.999450683594,0.0750000029802322,284.35400390625,,,,,0.0698208059692383,99.9020004272461,,,,,4.67209366120641e-007,,25,,,69.8208059692383,
,27203297.19,4369,109.997200012207,0.0750000029802322,284.35400390625,,,,,0.0718484844970703,99.9020004272461,,,,,4.53135091993252e-007,,25,,,71.8484844970703,
,27204867.56,4369,104.999500274658,0.0750000029802322,284.35400390625,,,,,0.0740118264770508,99.9020004272461,,,,,4.68856866176656e-007,,25,,,74.0118264770508,
,27206435.38,4369,99.9992980957031,0.0750000029802322,284.35400390625,,,,,0.0763258456420898,99.9020004272461,,,,,4.53258536885885e-007,,25,,,76.3258456420898,
,27206640.06,4369,99.9994010925293,0.0750000029802322,284.35400390625,,,,,0.0763306463623047,99.9020004272461,,,,,5.12499967044998e-007,,25,,,76.3306463623047,
,27207012.27,4369,98.9976501464844,0.0750000029802322,284.35400390625,,,,,0.0768165029907227,99.9020004272461,,,,,4.48724515337994e-007,,25,,,76.8165029907227,
,27207383.86,4369,97.9997482299805,0.0750000029802322,284.35400390625,,,,,0.0773018167114258,99.9020004272461,,,,,3.59992016573039e-007,,25,,,77.3018167114258,
,27207756.19,4369,96.9971008300781,0.0750000029802322,284.35400390625,,,,,0.0777984548950195,99.9020004272461,,,,,4.35751491372628e-007,,25,,,77.7984548950195,
,27208128.78,4369,95.9994010925293,0.0750000029802322,284.35400390625,,,,,0.0783062161254883,99.9020004272461,,,,,4.52120421475521e-007,,25,,,78.3062161254883,
,27208500.45,4369,94.9994506835938,0.0750000029802322,284.35400390625,,,,,0.0788230764770508,99.9020004272461,,,,,3.78843433076174e-007,,25,,,78.8230764770508,
,27208872.33,4369,93.9984474182129,0.0750000029802322,284.35400390625,,,,,0.0793453576660156,99.9020004272461,,,,,5.00706941152803e-007,,25,,,79.3453576660156,
,27209241.03,4369,92.9982490539551,0.0750000029802322,284.35400390625,,,,,0.0798693594360352,99.9020004272461,,,,,8.82062292197356e-007,,25,,,79.8693594360352,
,27209614.28,4369,91.9993515014648,0.0750000029802322,284.35400390625,,,,,0.0804124493408203,99.9020004272461,,,,,4.31327046759587e-007,,25,,,80.4124493408203,
,27209986.91,4369,90.9982528686523,0.0750000029802322,284.35400390625,,,,,0.0809624917602539,99.9020004272461,,,,,4.97721996687777e-007,,25,,,80.9624917602539,
,27210357.56,4369,90.0014495849609,0.0750000029802322,284.35400390625,,,,,0.0815112252807617,99.9020004272461,,,,,5.12955869639777e-007,,25,,,81.5112252807617,
,27210730.88,4369,88.9980964660645,0.0750000029802322,284.35400390625,,,,,0.0820713711547851,99.9020004272461,,,,,3.24568255572913e-007,,25,,,82.0713711547852,
,27211103.20,4369,87.9995002746582,0.0750000029802322,284.35400390625,,,,,0.0826391134643555,99.9020004272461,,,,,4.57968347311798e-007,,25,,,82.6391134643555,
,27211476.23,4369,86.9979515075684,0.0750000029802322,284.35400390625,,,,,0.0832258700561524,99.9020004272461,,,,,4.38884219315043e-007,,25,,,83.2258700561523,
,27211847.28,4369,86.0019493103027,0.0750000029802322,284.35400390625,,,,,0.0838197998046875,99.9020004272461,,,,,5.45476037428072e-007,,25,,,83.8197998046875,
,27212221.02,4369,84.9959487915039,0.0750000029802322,284.35400390625,,,,,0.0844171694946289,99.9020004272461,,,,,4.72546870396618e-007,,25,,,84.4171694946289,
,27212589.58,4369,83.995548248291,0.0750000029802322,284.35400390625,,,,,0.0850286807250976,99.9020004272461,,,,,3.1323744112849e-007,,25,,,85.0286807250977,
,27212958.48,4369,82.9974021911621,0.0750000029802322,284.35400390625,,,,,0.0856541839599609,99.9020004272461,,,,,4.39750954029356e-007,,25,,,85.6541839599609,
,27213331.81,4369,81.9983520507813,0.0750000029802322,284.35400390625,,,,,0.0862891613769531,99.9020004272461,,,,,5.29938094050508e-007,,25,,,86.2891613769531,
,27213703.98,4369,80.9925498962402,0.0750000029802322,284.35400390625,,,,,0.0869383215332031,99.9020004272461,,,,,3.64450692287163e-007,,25,,,86.9383215332031,
,27214073.19,4369,79.9984512329102,0.0750000029802322,284.35400390625,,,,,0.0876008129882813,99.9020004272461,,,,,3.5196601095341e-007,,25,,,87.6008129882812,
,27214449.64,4369,79.0039978027344,0.0750000029802322,284.35400390625,,,,,0.0882714324951172,99.9020004272461,,,,,4.38150402891732e-007,,25,,,88.2714324951172,
,27214826.08,4369,78.0043525695801,0.0750000029802322,284.35400390625,,,,,0.0889536614990234,99.9020004272461,,,,,4.73276837237021e-007,,25,,,88.9536614990234,
,27215203.44,4369,76.9950523376465,0.0750000029802322,284.35400390625,,,,,0.0896476641845703,99.9020004272461,,,,,5.26287082530807e-007,,25,,,89.6476641845703,
,27215573.91,4369,75.9977531433105,0.0750000029802322,284.35400390625,,,,,0.0903581246948242,99.9020004272461,,,,,5.05479134584307e-007,,25,,,90.3581246948242,
,27215943.25,4369,74.9988021850586,0.0750000029802322,284.35400390625,,,,,0.0910797448730469,99.9020004272461,,,,,9.06081622072848e-007,,25,,,91.0797448730469,
,27216315.95,4369,73.9974021911621,0.0750000029802322,284.35400390625,,,,,0.091816708984375,99.9020004272461,,,,,4.94712029529539e-007,,25,,,91.816708984375,
,27216686.23,4369,73.0029983520508,0.0750000029802322,284.35400390625,,,,,0.0925687622070313,99.9020004272461,,,,,4.94708522985287e-007,,25,,,92.5687622070313,
,27217063.36,4369,72.0059471130371,0.0750000029802322,284.35400390625,,,,,0.0933354321289062,99.9020004272461,,,,,4.50010981934948e-007,,25,,,93.3354321289062,
,27217439.75,4369,70.9961013793945,0.0750000029802322,284.35400390625,,,,,0.0941112783813477,99.9020004272461,,,,,4.00000606353596e-007,,25,,,94.1112783813477,
,27217809.77,4369,70.0009498596191,0.0750000029802322,284.35400390625,,,,,0.0949294790649414,99.9020004272461,,,,,3.41828093803779e-006,,25,,,94.9294790649414,
,27218183.84,4369,69.0010528564453,0.0750000029802322,284.35400390625,,,,,0.095747490234375,99.9020004272461,,,,,3.52942356565934e-006,,25,,,95.747490234375,
,27218556.31,4369,67.9988021850586,0.0750000029802322,284.35400390625,,,,,0.0965814862060547,99.9020004272461,,,,,4.50398689623274e-006,,25,,,96.5814862060547,
,27218927.73,4369,67.0018005371094,0.0750000029802322,284.35400390625,,,,,0.0974260699462891,99.9020004272461,,,,,3.36881325103738e-006,,25,,,97.4260699462891,
,27219300.36,4369,65.9978485107422,0.0750000029802322,284.35400390625,,,,,0.098289303894043,99.9020004272461,,,,,3.05479085708678e-006,,25,,,98.289303894043,
,27219672.17,4369,65.0022506713867,0.0750000029802322,284.35400390625,,,,,0.0991804949951172,99.9020004272461,,,,,3.10100714285668e-006,,25,,,99.1804949951172,
,27220049.20,4369,64.0002517700195,0.0750000029802322,284.35400390625,,,,,0.100088346862793,99.9020004272461,,,,,3.32358220568975e-006,,25,,,100.088346862793,
,27220425.94,4369,63.0014495849609,0.0750000029802322,284.35400390625,,,,,0.101006389465332,99.9020004272461,,,,,3.551139938107e-006,,25,,,101.006389465332,
,27220798.44,4369,62.0006999969482,0.0750000029802322,284.35400390625,,,,,0.101950711975098,99.9020004272461,,,,,4.80135221927557e-006,,25,,,101.950711975098,
,27221169.81,4369,61.0006008148193,0.0750000029802322,284.35400390625,,,,,0.102920525512695,99.9020004272461,,,,,4.60172789020707e-006,,25,,,102.920525512695,
,27221543.39,4369,59.9981498718262,0.0750000029802322,284.35400390625,,,,,0.103912390136719,99.9020004272461,,,,,3.6197943473662e-006,,25,,,103.912390136719,
,27221748.55,4369,60.0020999908447,0.0750000029802322,284.35400390625,,,,,0.103907963562012,99.9020004272461,,,,,3.01373855413986e-006,,25,,,103.907963562012,
,27221973.09,4369,59.5033988952637,0.0750000029802322,284.35400390625,,,,,0.104428896179199,99.9020004272461,,,,,2.68806736235001e-006,,25,,,104.428896179199,
,27222196.34,4369,58.999698638916,0.0750000029802322,284.35400390625,,,,,0.10493016204834,99.9020004272461,,,,,3.28115609586865e-006,,25,,,104.93016204834,
,27222418.28,4369,58.4997005462646,0.0750000029802322,284.35400390625,,,,,0.105443071289062,99.9020004272461,,,,,3.85027540543327e-006,,25,,,105.443071289063,
,27222641.30,4369,58.0012989044189,0.0750000029802322,284.35400390625,,,,,0.105976744995117,99.9020004272461,,,,,3.40350302648163e-006,,25,,,105.976744995117,
,27222865.64,4369,57.4993991851807,0.0750000029802322,284.35400390625,,,,,0.10649984954834,99.9020004272461,,,,,2.74198701178665e-006,,25,,,106.49984954834,
,27223087.83,4369,56.9995002746582,0.0750000029802322,284.35400390625,,,,,0.107039855957031,99.9020004272461,,,,,3.340160855789e-006,,25,,,107.039855957031,
,27223309.83,4369,56.4999504089355,0.0750000029802322,284.35400390625,,,,,0.10757972442627,99.9020004272461,,,,,3.41209443629587e-006,,25,,,107.57972442627,
,27223532.83,4369,55.9987010955811,0.0750000029802322,284.35400390625,,,,,0.108125968933106,99.9020004272461,,,,,2.44271690751759e-006,,25,,,108.125968933105,
,27223757.45,4369,55.4991512298584,0.0750000029802322,284.35400390625,,,,,0.108683962402344,99.9020004272461,,,,,3.51650582745059e-006,,25,,,108.683962402344,
,27223980.77,4369,55.0003490447998,0.0750000029802322,284.35400390625,,,,,0.109247844848633,99.9020004272461,,,,,3.0775957146779e-006,,25,,,109.247844848633,
,27224203.81,4369,54.4974498748779,0.0750000029802322,284.35400390625,,,,,0.109819976196289,99.9020004272461,,,,,3.47055105029562e-006,,25,,,109.819976196289,
,27224426.98,4369,53.9993000030518,0.0750000029802322,284.35400390625,,,,,0.110401850280762,99.9020004272461,,,,,3.43612344235948e-006,,25,,,110.401850280762,
,27224650.16,4369,53.5006008148193,0.0750000029802322,284.35400390625,,,,,0.110981991882324,99.9020004272461,,,,,4.02582407623662e-006,,25,,,110.981991882324,
,27224874.64,4369,53.0008010864258,0.0750000029802322,284.35400390625,,,,,0.111575166015625,99.9020004272461,,,,,3.93568148841894e-006,,25,,,111.575166015625,
,27225097.81,4369,52.5037002563477,0.0750000029802322,284.35400390625,,,,,0.112170662536621,99.9020004272461,,,,,3.57378847190546e-006,,25,,,112.170662536621,
,27225322.28,4369,52.0002498626709,0.0750000029802322,284.35400390625,,,,,0.112789384765625,99.9020004272461,,,,,3.27441521185524e-006,,25,,,112.789384765625,
,27225546.00,4369,51.4999504089355,0.0750000029802322,284.35400390625,,,,,0.113405591125488,99.9020004272461,,,,,4.15946136787958e-006,,25,,,113.405591125488,
,27225768.84,4369,51.0030498504639,0.0750000029802322,284.35400390625,,,,,0.114024072570801,99.9020004272461,,,,,2.7689452794767e-006,,25,,,114.024072570801,
,27225996.97,4369,50.50119972229,0.0750000029802322,284.35400390625,,,,,0.114663937072754,99.9020004272461,,,,,4.15085069925415e-006,,25,,,114.663937072754,
,27226221.45,4369,50.0020008087158,0.0750000029802322,284.35400390625,,,,,0.115311437988281,99.9020004272461,,,,,3.61799462114625e-006,,25,,,115.311437988281,
,27226448.23,4369,49.5000495910645,0.0750000029802322,284.35400390625,,,,,0.115952877502441,99.9020004272461,,,,,2.77635272937787e-006,,25,,,115.952877502441,
,27226671.42,4369,48.9981994628906,0.0750000029802322,284.35400390625,,,,,0.116623163146973,99.9020004272461,,,,,3.61333739873272e-006,,25,,,116.623163146973,
,27226896.83,4369,48.5005512237549,0.0750000029802322,284.35400390625,,,,,0.117291011352539,99.9020004272461,,,,,3.26238615646737e-006,,25,,,117.291011352539,
,27227120.03,4369,48.0004005432129,0.0750000029802322,284.35400390625,,,,,0.117961070861816,99.9020004272461,,,,,3.61186226426814e-006,,25,,,117.961070861816,
,27227343.27,4369,47.4980487823486,0.0750000029802322,284.35400390625,,,,,0.118667419128418,99.9020004272461,,,,,3.42613993831187e-006,,25,,,118.667419128418,
,27227566.70,4369,46.9981994628906,0.0750000029802322,284.35400390625,,,,,0.119361551513672,99.9020004272461,,,,,4.38367966103708e-006,,25,,,119.361551513672,
,27227790.13,4369,46.49880027771,0.0750000029802322,284.35400390625,,,,,0.120068125915527,99.9020004272461,,,,,3.84747131678363e-006,,25,,,120.068125915527,
,27228013.53,4369,46.0004501342773,0.0750000029802322,284.35400390625,,,,,0.120798919677734,99.9020004272461,,,,,2.84505891881158e-006,,25,,,120.798919677734,
,27228237.02,4369,45.5020008087158,0.0750000029802322,284.35400390625,,,,,0.121527955932617,99.9020004272461,,,,,3.50787045922586e-006,,25,,,121.527955932617,
,27228460.17,4369,44.9988498687744,0.0750000029802322,284.35400390625,,,,,0.122267493896484,99.9020004272461,,,,,2.95664336212294e-006,,25,,,122.267493896484,
,27228683.20,4369,44.4994010925293,0.0750000029802322,284.35400390625,,,,,0.123032270507812,99.9020004272461,,,,,2.97493791495308e-006,,25,,,123.032270507813,
,27228906.70,4369,44.0029983520508,0.0750000029802322,284.35400390625,,,,,0.123788717346191,99.9020004272461,,,,,3.47967315509776e-006,,25,,,123.788717346191,
,27229131.13,4369,43.4986000061035,0.0750000029802322,284.35400390625,,,,,0.124559980773926,99.9020004272461,,,,,4.06285606434363e-006,,25,,,124.559980773926,
,27229358.02,4369,42.9986991882324,0.0750000029802322,284.35400390625,,,,,0.125359755859375,99.9020004272461,,,,,3.8938787296444e-006,,25,,,125.359755859375,
,27229583.55,4369,42.4990501403809,0.0750000029802322,284.35400390625,,,,,0.126156809692383,99.9020004272461,,,,,3.73797473738727e-006,,25,,,126.156809692383,
,27229807.89,4369,42.0012016296387,0.0750000029802322,284.35400390625,,,,,0.126970141601563,99.9020004272461,,,,,3.58151402903993e-006,,25,,,126.970141601563,
,27230035.52,4369,41.498950958252,0.0750000029802322,284.35400390625,,,,,0.127803793334961,99.9020004272461,,,,,3.0099290939437e-006,,25,,,127.803793334961,
,27230257.66,4369,41.0035495758057,0.0750000029802322,284.35400390625,,,,,0.128644936523437,99.9020004272461,,,,,3.46832629498657e-006,,25,,,128.644936523438,
,27230481.94,4369,40.5026016235352,0.0750000029802322,284.35400390625,,,,,0.129493647460938,99.9020004272461,,,,,3.34067523559998e-006,,25,,,129.493647460938,
,27230709.67,4369,40.0004005432129,0.0750000029802322,284.35400390625,,,,,0.130367507324219,99.9020004272461,,,,,3.27181083152848e-006,,25,,,130.367507324219,
,27230935.14,4369,39.49880027771,0.0750000029802322,284.35400390625,,,,,0.131249177856445,99.9020004272461,,,,,3.52757011139717e-006,,25,,,131.249177856445,
,27231159.67,4369,38.9993000030518,0.0750000029802322,284.35400390625,,,,,0.132157459106445,99.9020004272461,,,,,2.99459818917206e-006,,25,,,132.157459106445,
,27231382.73,4369,38.5023002624512,0.0750000029802322,284.35400390625,,,,,0.133089305419922,99.9020004272461,,,,,3.43624763296864e-006,,25,,,133.089305419922,
,27231606.39,4369,37.9996490478516,0.0750000029802322,284.35400390625,,,,,0.134015836181641,99.9020004272461,,,,,3.98257533994228e-006,,25,,,134.015836181641,
,27231829.80,4369,37.5005512237549,0.0750000029802322,284.35400390625,,,,,0.134962154541016,99.9020004272461,,,,,4.21865030467949e-006,,25,,,134.962154541016,
,27232052.80,4369,37.0009498596191,0.0750000029802322,284.35400390625,,,,,0.135933775634766,99.9020004272461,,,,,3.82876123213843e-006,,25,,,135.933775634766,
,27232279.56,4369,36.5012493133545,0.0750000029802322,284.35400390625,,,,,0.136917543945313,99.9020004272461,,,,,3.72790453497627e-006,,25,,,136.917543945313,
,27232503.98,4369,36.001350402832,0.0750000029802322,284.35400390625,,,,,0.137923580932617,99.9020004272461,,,,,4.92227056149263e-006,,25,,,137.923580932617,
,27232727.47,4369,35.4999504089355,0.0750000029802322,284.35400390625,,,,,0.138942694702148,99.9020004272461,,,,,3.618438344341e-006,,25,,,138.942694702148,
,27232951.95,4369,35.0013999938965,0.0750000029802322,284.35400390625,,,,,0.139983009643555,99.9020004272461,,,,,3.17196054682594e-006,,25,,,139.983009643555,
,27233177.48,4369,34.5007991790771,0.0750000029802322,284.35400390625,,,,,0.141038464355469,99.9020004272461,,,,,4.25998062714616e-006,,25,,,141.038464355469,
,27233400.61,4369,34.0029983520508,0.0750000029802322,284.35400390625,,,,,0.14211486328125,99.9020004272461,,,,,2.52322907343258e-006,,25,,,142.11486328125,
,27233624.97,4369,33.4996013641357,0.0750000029802322,284.35400390625,,,,,0.143237210693359,99.9020004272461,,,,,3.71164050784114e-006,,25,,,143.237210693359,
,27233851.88,4369,32.9997997283936,0.0750000029802322,284.35400390625,,,,,0.144352153320313,99.9020004272461,,,,,4.29198591367063e-006,,25,,,144.352153320313,
,27234078.58,4369,32.500150680542,0.0750000029802322,284.35400390625,,,,,0.145493504638672,99.9020004272461,,,,,3.91226920560882e-006,,25,,,145.493504638672,
,27234306.31,4369,32.00119972229,0.0750000029802322,284.35400390625,,,,,0.146662235107422,99.9020004272461,,,,,4.34008190973462e-006,,25,,,146.662235107422,
,27234529.73,4369,31.4999494552612,0.0750000029802322,284.35400390625,,,,,0.147862485961914,99.9020004272461,,,,,2.98594334097558e-006,,25,,,147.862485961914,
,27234751.78,4369,31.0006494522095,0.0750000029802322,284.35400390625,,,,,0.149066786499023,99.9020004272461,,,,,3.23174999009053e-006,,25,,,149.066786499023,
,27234977.30,4369,30.5009498596191,0.0750000029802322,284.35400390625,,,,,0.150317836914062,99.9020004272461,,,,,3.66265571015768e-006,,25,,,150.317836914063,
,27235202.64,4369,30.00119972229,0.0750000029802322,284.35400390625,,,,,0.151583610229492,99.9020004272461,,,,,3.5306019939413e-006,,25,,,151.583610229492,
,27235430.28,4369,29.5004501342773,0.0750000029802322,284.35400390625,,,,,0.152894888305664,99.9020004272461,,,,,3.9142622511338e-006,,25,,,152.894888305664,
,27235653.81,4369,29.0024499893188,0.0750000029802322,284.35400390625,,,,,0.154225791625977,99.9020004272461,,,,,3.00641890410705e-006,,25,,,154.225791625977,
,27235877.58,4369,28.5006999969482,0.0750000029802322,284.35400390625,,,,,0.155578511352539,99.9020004272461,,,,,2.25969412357866e-006,,25,,,155.578511352539,
,27236105.31,4369,28.0005006790161,0.0750000029802322,284.35400390625,,,,,0.156966753540039,99.9020004272461,,,,,3.91279238965708e-006,,25,,,156.966753540039,
,27236332.06,4369,27.5006999969482,0.0750000029802322,284.35400390625,,,,,0.158401467895508,99.9020004272461,,,,,3.89290251649144e-006,,25,,,158.401467895508,
,27236556.16,4369,27.0013999938965,0.0750000029802322,284.35400390625,,,,,0.159852704467773,99.9020004272461,,,,,2.42118292498517e-006,,25,,,159.852704467773,
,27236782.02,4369,26.5006999969482,0.0750000029802322,284.35400390625,,,,,0.161344152832031,99.9020004272461,,,,,3.50150387652076e-006,,25,,,161.344152832031,
,27237009.50,4369,25.9993991851807,0.0750000029802322,284.35400390625,,,,,0.162871148681641,99.9020004272461,,,,,3.2875180324969e-006,,25,,,162.871148681641,
,27237236.25,4369,25.5014505386353,0.0750000029802322,284.35400390625,,,,,0.164434278564453,99.9020004272461,,,,,3.45053040641832e-006,,25,,,164.434278564453,
,27237462.81,4369,25.0005502700806,0.0750000029802322,284.35400390625,,,,,0.166043027954102,99.9020004272461,,,,,3.22714439718524e-006,,25,,,166.043027954102,
,27237690.47,4369,24.4995498657227,0.0750000029802322,284.35400390625,,,,,0.167700180664062,99.9020004272461,,,,,3.51811266059849e-006,,25,,,167.700180664062,
,27237913.61,4369,24.0001497268677,0.0750000029802322,284.35400390625,,,,,0.169400751953125,99.9020004272461,,,,,4.27615905686202e-006,,25,,,169.400751953125,
,27238137.72,4369,23.5006999969482,0.0750000029802322,284.35400390625,,,,,0.171129948730469,99.9020004272461,,,,,3.64416657910812e-006,,25,,,171.129948730469,
,27238363.00,4369,23.0005502700806,0.0750000029802322,284.35400390625,,,,,0.172916307373047,99.9020004272461,,,,,3.17033476375589e-006,,25,,,172.916307373047,
,27238588.50,4369,22.499249458313,0.0750000029802322,284.35400390625,,,,,0.174752225341797,99.9020004272461,,,,,4.12184054440382e-006,,25,,,174.752225341797,
,27238815.67,4369,22.0002498626709,0.0750000029802322,284.35400390625,,,,,0.17665265625,99.9020004272461,,,,,3.17632721736386e-006,,25,,,176.65265625,
,27239038.86,4369,21.49880027771,0.0750000029802322,284.35400390625,,,,,0.178601106567383,99.9020004272461,,,,,5.2124319897305e-006,,25,,,178.601106567383,
,27239261.00,4369,20.9989004135132,0.0750000029802322,284.35400390625,,,,,0.18064453918457,99.9020004272461,,,,,4.55938780331358e-006,,25,,,180.64453918457,
,27239484.08,4369,20.4986505508423,0.0750000029802322,284.35400390625,,,,,0.182721142578125,99.9020004272461,,,,,3.84761176136552e-006,,25,,,182.721142578125,
,27239706.94,4369,20.0012998580933,0.0750000029802322,284.35400390625,,,,,0.184886788330078,99.9020004272461,,,,,3.95847110391501e-006,,25,,,184.886788330078,
,27239912.08,4369,20,0.0750000029802322,284.35400390625,,,,,0.184884760742188,99.9020004272461,,,,,3.09051618895835e-006,,25,,,184.884760742188,
,27240060.53,4369,19.7515497207642,0.0750000029802322,284.35400390625,,,,,0.185985700683594,99.9020004272461,,,,,4.25356543499015e-006,,25,,,185.985700683594,
,27240209.17,4369,19.4993000030518,0.0750000029802322,284.35400390625,,,,,0.187111231079102,99.9020004272461,,,,,4.56344412283028e-006,,25,,,187.111231079102,
,27240357.69,4369,19.2495002746582,0.0750000029802322,284.35400390625,,,,,0.188278811645508,99.9020004272461,,,,,3.6119287831361e-006,,25,,,188.278811645508,
,27240507.45,4369,18.9996500015259,0.0750000029802322,284.35400390625,,,,,0.189442300415039,99.9020004272461,,,,,3.45229909907026e-006,,25,,,189.442300415039,
,27240655.95,4369,18.7488498687744,0.0750000029802322,284.35400390625,,,,,0.190612992553711,99.9020004272461,,,,,3.26785684037324e-006,,25,,,190.612992553711,
,27240803.28,4369,18.5000495910645,0.0750000029802322,284.35400390625,,,,,0.191836979980469,99.9020004272461,,,,,3.36763152294514e-006,,25,,,191.836979980469,
,27240952.95,4369,18.2494497299194,0.0750000029802322,284.35400390625,,,,,0.193076494140625,99.9020004272461,,,,,3.83561287433846e-006,,25,,,193.076494140625,
,27241100.83,4369,17.9997501373291,0.0750000029802322,284.35400390625,,,,,0.194337540893555,99.9020004272461,,,,,2.7030145244592e-006,,25,,,194.337540893555,
,27241249.38,4369,17.7490997314453,0.0750000029802322,284.35400390625,,,,,0.195627572021484,99.9020004272461,,,,,2.84122569519454e-006,,25,,,195.627572021484,
,27241397.58,4369,17.4993000030518,0.0750000029802322,284.35400390625,,,,,0.196947236328125,99.9020004272461,,,,,3.49016760079979e-006,,25,,,196.947236328125,
,27241546.33,4369,17.2500495910645,0.0750000029802322,284.35400390625,,,,,0.198302294311523,99.9020004272461,,,,,3.88490269392543e-006,,25,,,198.302294311523,
,27241693.83,4369,16.9998502731323,0.0750000029802322,284.35400390625,,,,,0.199676357421875,99.9020004272461,,,,,3.57093511165279e-006,,25,,,199.676357421875,
,27241843.63,4369,16.7496500015259,0.0750000029802322,284.35400390625,,,,,0.201079204101562,99.9020004272461,,,,,3.45819924382918e-006,,25,,,201.079204101563,
,27241991.20,4369,16.4989500045776,0.0750000029802322,284.35400390625,,,,,0.20252844543457,99.9020004272461,,,,,3.35317206018563e-006,,25,,,202.52844543457,
,27242138.55,4369,16.249249458313,0.0750000029802322,284.35400390625,,,,,0.203984815673828,99.9020004272461,,,,,3.26831864236374e-006,,25,,,203.984815673828,
,27242287.23,4369,15.9995002746582,0.0750000029802322,284.35400390625,,,,,0.205489931640625,99.9020004272461,,,,,4.42665290861984e-006,,25,,,205.489931640625,
,27242436.86,4369,15.7497997283936,0.0750000029802322,284.35400390625,,,,,0.207019921875,99.9020004272461,,,,,3.01937249184285e-006,,25,,,207.019921875,
,27242586.86,4369,15.5005502700806,0.0750000029802322,284.35400390625,,,,,0.208565768432617,99.9020004272461,,,,,3.00400720332142e-006,,25,,,208.565768432617,
,27242735.50,4369,15.2504000663757,0.0750000029802322,284.35400390625,,,,,0.210162555541992,99.9020004272461,,,,,4.99029159564053e-006,,25,,,210.162555541992,
,27242884.38,4369,14.9988503456116,0.0750000029802322,284.35400390625,,,,,0.21181177734375,99.9020004272461,,,,,3.43548323418952e-006,,25,,,211.81177734375,
,27243034.20,4369,14.7491002082825,0.0750000029802322,284.35400390625,,,,,0.213474368286133,99.9020004272461,,,,,3.30090676977489e-006,,25,,,213.474368286133,
,27243182.48,4369,14.500500202179,0.0750000029802322,284.35400390625,,,,,0.215204076538086,99.9020004272461,,,,,4.01554672886363e-006,,25,,,215.204076538086,
,27243330.08,4369,14.2499499320984,0.0750000029802322,284.35400390625,,,,,0.216955815429688,99.9020004272461,,,,,3.10399740694917e-006,,25,,,216.955815429688,
,27243479.44,4369,13.999400138855,0.0750000029802322,284.35400390625,,,,,0.218754197387695,99.9020004272461,,,,,4.79293452358728e-006,,25,,,218.754197387695,
,27243628.30,4369,13.75,0.0750000029802322,284.35400390625,,,,,0.220617170410156,99.9020004272461,,,,,3.43644754013146e-006,,25,,,220.617170410156,
,27243778.27,4369,13.4998998641968,0.0750000029802322,284.35400390625,,,,,0.222508779296875,99.9020004272461,,,,,3.45185688523201e-006,,25,,,222.508779296875,
,27243926.89,4369,13.2497496604919,0.0750000029802322,284.35400390625,,,,,0.22446344909668,99.9020004272461,,,,,4.5961168193787e-006,,25,,,224.46344909668,
,27244076.41,4369,13.0006999969482,0.0750000029802322,284.35400390625,,,,,0.226468745727539,99.9020004272461,,,,,3.73867450620524e-006,,25,,,226.468745727539,
,27244224.72,4369,12.75,0.0750000029802322,284.35400390625,,,,,0.22854625,99.9020004272461,,,,,3.550312082361e-006,,25,,,228.54625,
,27244374.56,4369,12.4997000694275,0.0750000029802322,284.35400390625,,,,,0.230669913330078,99.9020004272461,,,,,3.57301271557983e-006,,25,,,230.669913330078,
,27244524.19,4369,12.2497501373291,0.0750000029802322,284.35400390625,,,,,0.232870017700195,99.9020004272461,,,,,3.65380244082212e-006,,25,,,232.870017700195,
,27244672.16,4369,11.9993500709534,0.0750000029802322,284.35400390625,,,,,0.235140469360352,99.9020004272461,,,,,3.2718654419678e-006,,25,,,235.140469360352,
,27244819.52,4369,11.7495498657227,0.0750000029802322,284.35400390625,,,,,0.237484631347656,99.9020004272461,,,,,3.55181277986255e-006,,25,,,237.484631347656,
,27244967.88,4369,11.4993000030518,0.0750000029802322,284.35400390625,,,,,0.239898140869141,99.9020004272461,,,,,4.29784692932018e-006,,25,,,239.898140869141,
,27245115.22,4369,11.2494497299194,0.0750000029802322,284.35400390625,,,,,0.242406858520508,99.9020004272461,,,,,3.93753580441593e-006,,25,,,242.406858520508,
,27245262.92,4369,11.0001001358032,0.0750000029802322,284.35400390625,,,,,0.245004757080078,99.9020004272461,,,,,3.07057603677958e-006,,25,,,245.004757080078,
,27245412.53,4369,10.7495002746582,0.0750000029802322,284.35400390625,,,,,0.247700810546875,99.9020004272461,,,,,3.98101871439423e-006,,25,,,247.700810546875,
,27245561.05,4369,10.4995999336243,0.0750000029802322,284.35400390625,,,,,0.250485036621094,99.9020004272461,,,,,4.98644126535833e-006,,25,,,250.485036621094,
,27245710.61,4369,10.2500500679016,0.0750000029802322,284.35400390625,,,,,0.253402509155273,99.9020004272461,,,,,3.90258253905159e-006,,25,,,253.402509155273,
,27245860.11,4369,10.0003995895386,0.0750000029802322,284.35400390625,,,,,0.256436547851562,99.9020004272461,,,,,3.51258726512842e-006,,25,,,256.436547851563,
,27246065.44,4369,9.99955034255981,0.0750000029802322,284.35400390625,,,,,0.256458996582031,99.9020004272461,,,,,4.25603452529276e-006,,25,,,256.458996582031,
,27246230.73,4369,9.69990015029907,0.0750000029802322,284.35400390625,,,,,0.260293927001953,99.9020004272461,,,,,3.39945752485941e-006,,25,,,260.293927001953,
,27246395.16,4369,9.39970016479492,0.0750000029802322,284.35400390625,,,,,0.264361573486328,99.9020004272461,,,,,3.38383930339465e-006,,25,,,264.361573486328,
,27246559.63,4369,9.09980010986328,0.0750000029802322,284.35400390625,,,,,0.26868150390625,99.9020004272461,,,,,3.94893599079173e-006,,25,,,268.68150390625,
,27246723.91,4369,8.79979991912842,0.0750000029802322,284.35400390625,,,,,0.273283950195313,99.9020004272461,,,,,4.37130871826362e-006,,25,,,273.283950195313,
,27246889.64,4369,8.49979972839355,0.0750000029802322,284.35400390625,,,,,0.278176997070312,99.9020004272461,,,,,4.1747824370262e-006,,25,,,278.176997070313,
,27247055.17,4369,8.19974994659424,0.0750000029802322,284.35400390625,,,,,0.283337998046875,99.9020004272461,,,,,3.41729145442991e-006,,25,,,283.337998046875,
,27247219.61,4369,7.89980006217957,0.0750000029802322,284.35400390625,,,,,0.288805003662109,99.9020004272461,,,,,3.2492925037715e-006,,25,,,288.805003662109,
,27247384.11,4369,7.60004997253418,0.0750000029802322,284.35400390625,,,,,0.294551740722656,99.9020004272461,,,,,3.31368707743761e-006,,25,,,294.551740722656,
,27247548.31,4369,7.30010008811951,0.0750000029802322,284.35400390625,,,,,0.300632652587891,99.9020004272461,,,,,3.48551028981618e-006,,25,,,300.632652587891,
,27247712.66,4369,7.00040006637573,0.0750000029802322,284.35400390625,,,,,0.307173729248047,99.9020004272461,,,,,2.87170835415786e-006,,25,,,307.173729248047,
,27247889.41,4369,6.70010018348694,0.0750000029802322,284.35400390625,,,,,0.314213032226562,99.9020004272461,,,,,3.51274727185928e-006,,25,,,314.213032226563,
,27248067.52,4369,6.41044998168945,0.0750000029802322,284.35400390625,,,,,0.322250308837891,99.9020004272461,,,,,3.81113573163692e-005,,25,,,322.250308837891,
,27258917.81,4369,6.10365009307861,0.0750000029802322,284.35400390625,,,,,0.329130505371094,99.9020004272461,,,,,2.20044765459166e-005,,25,,,329.130505371094,
,27259097.98,4369,5.80310010910034,0.0750000029802322,284.35400390625,,,,,0.338653565673828,99.9020004272461,,,,,2.65388365712467e-005,,25,,,338.653565673828,
,27259276.19,4369,5.50524997711182,0.0750000029802322,284.35400390625,,,,,0.34764740234375,99.9020004272461,,,,,4.14592677089688e-006,,25,,,347.64740234375,
,27259441.59,4369,5.19939994812012,0.0750000029802322,284.35400390625,,,,,0.358424321289063,99.9020004272461,,,,,5.62468504390887e-006,,25,,,358.424321289063,
,27259609.05,4369,4.90100002288818,0.0750000029802322,284.35400390625,,,,,0.370109226074219,99.9020004272461,,,,,3.98060821801497e-006,,25,,,370.109226074219,
,27259780.03,4369,4.60009980201721,0.0750000029802322,284.35400390625,,,,,0.383346496582031,99.9020004272461,,,,,5.12823792636834e-006,,25,,,383.346496582031,
,27259946.36,4369,4.30034995079041,0.0750000029802322,284.35400390625,,,,,0.398022684326172,99.9020004272461,,,,,4.76870626433617e-006,,25,,,398.022684326172,
,27263329.58,4369,3.9849499464035,0.0750000029802322,284.35400390625,,,,,0.41392626953125,99.9020004272461,,,,,5.79901415848205e-005,,25,,,413.92626953125,
,27263871.77,4369,4.00239992141724,0.0750000029802322,284.35400390625,,,,,0.420622501220703,99.9020004272461,,,,,2.36220261267662e-005,,25,,,420.622501220703,
,27263977.28,4369,3.90059995651245,0.0750000029802322,284.35400390625,,,,,0.426900845947266,99.9020004272461,,,,,1.05820279110264e-005,,25,,,426.900845947266,
,27264085.31,4369,3.7997499704361,0.0750000029802322,284.35400390625,,,,,0.433287727050781,99.9020004272461,,,,,8.51356885515717e-006,,25,,,433.287727050781,
,27264192.94,4369,3.7019499540329,0.0750000029802322,284.35400390625,,,,,0.439937349853516,99.9020004272461,,,,,2.65297222755323e-005,,25,,,439.937349853516,
,27264299.77,4369,3.60004997253418,0.0750000029802322,284.35400390625,,,,,0.446763637695313,99.9020004272461,,,,,8.00497535853233e-006,,25,,,446.763637695313,
,27264406.48,4369,3.49974989891052,0.0750000029802322,284.35400390625,,,,,0.453972391357422,99.9020004272461,,,,,2.8298446309819e-005,,25,,,453.972391357422,
,27264514.09,4369,3.40104997158051,0.0750000029802322,284.35400390625,,,,,0.461406768798828,99.9020004272461,,,,,3.01644790705251e-005,,25,,,461.406768798828,
,27264621.75,4369,3.30030000209808,0.0750000029802322,284.35400390625,,,,,0.469262204589844,99.9020004272461,,,,,7.89581584220471e-006,,25,,,469.262204589844,
,27264729.44,4369,3.19969999790192,0.0750000029802322,284.35400390625,,,,,0.477638909912109,99.9020004272461,,,,,6.40161390054951e-005,,25,,,477.638909912109,
,27264895.77,4369,3.09990000724792,0.0750000029802322,284.35400390625,,,,,0.481290164794922,99.9020004272461,,,,,2.44773373375e-005,,25,,,481.290164794922,
,27265004.59,4369,3.00069999694824,0.0750000029802322,284.35400390625,,,,,0.490287153320312,99.9020004272461,,,,,1.7500192632898e-005,,25,,,490.287153320312,
,27265111.00,4369,2.90059995651245,0.0750000029802322,284.35400390625,,,,,0.499708133544922,99.9020004272461,,,,,2.30123083420118e-005,,25,,,499.708133544922,
,27265217.58,4369,2.79910004138947,0.0750000029802322,284.35400390625,,,,,0.509419177246094,99.9020004272461,,,,,2.77457510690338e-005,,25,,,509.419177246094,
,27265324.42,4369,2.70009994506836,0.0750000029802322,284.35400390625,,,,,0.519583247070313,99.9020004272461,,,,,4.90320099505381e-006,,25,,,519.583247070313,
,27265431.02,4369,2.59900009632111,0.0750000029802322,284.35400390625,,,,,0.530053815917969,99.9020004272461,,,,,3.81340294422303e-005,,25,,,530.053815917969,
,27265537.39,4369,2.50059998035431,0.0750000029802322,284.35400390625,,,,,0.540737243652344,99.9020004272461,,,,,2.99973652709113e-005,,25,,,540.737243652344,
,27265643.95,4369,2.40020000934601,0.0750000029802322,284.35400390625,,,,,0.55201638671875,99.9020004272461,,,,,6.58294108097504e-006,,25,,,552.01638671875,
,27265750.52,4369,2.30075001716614,0.0750000029802322,284.35400390625,,,,,0.564061381835937,99.9020004272461,,,,,1.59725261158024e-005,,25,,,564.061381835937,
,27269533.94,4369,2.19429993629456,0.0750000029802322,284.35400390625,,,,,0.578157116699219,99.9020004272461,,,,,8.53176716539911e-006,,25,,,578.157116699219,
,27269691.56,4369,2.08369994163513,0.0750000029802322,284.35400390625,,,,,0.590238679199219,99.9020004272461,,,,,2.49335591572532e-005,,25,,,590.238679199219,
,27269820.88,4369,2.03914999961853,0.0750000029802322,284.35400390625,,,,,0.59493416015625,99.9020004272461,,,,,0.000194113208672239,,25,,,594.93416015625,
,27269968.50,4369,1.89950001239777,0.0750000029802322,284.35400390625,,,,,0.61913728515625,99.9020004272461,,,,,4.59672027909836e-005,,25,,,619.13728515625,
,27270075.98,4369,1.80014997720718,0.0750000029802322,284.35400390625,,,,,0.629196403808594,99.9020004272461,,,,,5.1103325383483e-006,,25,,,629.196403808594,
,27271120.06,4369,1.70039999485016,0.0750000029802322,284.35400390625,,,,,0.641924089355469,99.9020004272461,,,,,2.47102849665103e-005,,25,,,641.924089355469,
,27271326.53,4369,1.7002500295639,0.0750000029802322,284.35400390625,,,,,0.641939482421875,99.9020004272461,,,,,2.08560023860748e-005,,25,,,641.939482421875,
,27271555.20,4369,2.20039999485016,0.0750000029802322,284.35400390625,,,,,0.578119265136719,99.9020004272461,,,,,0.000110339301596242,,25,,,578.119265136719,
,27271782.80,4369,2.69900000095367,0.0750000029802322,284.35400390625,,,,,0.51949185546875,99.9020004272461,,,,,2.22605319494788e-005,,25,,,519.49185546875,
,27272010.47,4369,3.19924998283386,0.0750000029802322,284.35400390625,,,,,0.4720348828125,99.9020004272461,,,,,9.87241008722785e-006,,25,,,472.0348828125,
,27272236.81,4369,3.69929993152618,0.0750000029802322,284.35400390625,,,,,0.434300047607422,99.9020004272461,,,,,5.23580771564384e-006,,25,,,434.300047607422,
,27275787.19,4369,4.18099999427795,0.0750000029802322,284.35400390625,,,,,0.402858369140625,99.9020004272461,,,,,0.000123996547408621,,25,,,402.858369140625,
,27276358.84,4369,4.70875000953674,0.0750000029802322,284.35400390625,,,,,0.383092745361328,99.9020004272461,,,,,1.14905877251973e-005,,25,,,383.092745361328,
,27276581.73,4369,5.19595003128052,0.0750000029802322,284.35400390625,,,,,0.362372943115234,99.9020004272461,,,,,1.04358580534413e-005,,25,,,362.372943115234,
,27276808.39,4369,5.69744992256165,0.0750000029802322,284.35400390625,,,,,0.344621903076172,99.9020004272461,,,,,5.89666150811098e-006,,25,,,344.621903076172,
,27277035.28,4369,6.23399996757507,0.0750000029802322,284.35400390625,,,,,0.328815263671875,99.9020004272461,,,,,0.000312968682378107,,25,,,328.815263671875,
,27277246.25,4369,6.6967499256134,0.0750000029802322,284.35400390625,,,,,0.313482393798828,99.9020004272461,,,,,4.56489144626542e-006,,25,,,313.482393798828,
,27277472.75,4369,7.19679999351501,0.0750000029802322,284.35400390625,,,,,0.301940886230469,99.9020004272461,,,,,4.28842403744632e-006,,25,,,301.940886230469,