File: data/160911_RT_sensor-calibr_Pt100_CePt3P.dat
[Header]
TITLE, sensor calibration
FILEOPENTIME, 22096290.48, 9/12/2016, 10:46 AM
BYAPP, Resistivity, 2.0, 1.0
INFO, APPNAME, PPMS MultiVu Application, Release 1.5.0.19
INFO, Pt100, Sample1 Name
INFO, 1, Sample1 Cross Section
INFO, 1, Sample1 Length
INFO, Ohm-m, Sample1 Units
INFO, CePt3P, Sample2 Name
INFO, 1, Sample2 Cross Section
INFO, 1, Sample2 Length
INFO, Ohm-m, Sample2 Units
INFO, Cernox R07 C12, Sample3 Name
INFO, 1, Sample3 Cross Section
INFO, 1, Sample3 Length
INFO, Ohm-m, Sample3 Units
INFO, , Sample4 Name
INFO, 1, Sample4 Cross Section
INFO, 1, Sample4 Length
INFO, Ohm-m, Sample4 Units
FIELDGROUP, Resistivity,2,3,4,5,6,7,8,9,10,11,12,13,14,15,16,17,18,19,20,21,22,23,24,25,26,27,28,29,30,31,32,33,34,35,36,37,38,39,40,41
STARTUPGROUP, Resistivity
STARTUPAXIS, X, 2, LINEAR, AUTO
STARTUPAXIS, Y1, 7, LINEAR, AUTO
STARTUPAXIS, Y2, 9, LINEAR, AUTO
STARTUPAXIS, Y3, 11, LINEAR, AUTO
PLOT_APPEARANCE, ALL, HORZ_GRID_ON, VERT_GRID_ON, MARKERS_AND_LINES, ALL_LINES
DATATYPE, TIME, 2
DATATYPE, COMMENT, 1
[Data]
Comment,Time Stamp (sec),Status (code),Temperature (K),Magnetic Field (Oe),Sample Position (deg),Bridge 1 Resistivity (Ohm-m),Bridge 1 Excitation (uA),Bridge 2 Resistivity (Ohm-m),Bridge 2 Excitation (uA),Bridge 3 Resistivity (Ohm-m),Bridge 3 Excitation (uA),Bridge 4 Resistivity (Ohm-m),Bridge 4 Excitation (uA),Bridge 1 Std. Dev. (Ohm-m),Bridge 2 Std. Dev. (Ohm-m),Bridge 3 Std. Dev. (Ohm-m),Bridge 4 Std. Dev. (Ohm-m),Number of Readings,Bridge 1 Resistance (Ohms),Bridge 2 Resistance (Ohms),Bridge 3 Resistance (Ohms),Bridge 4 Resistance (Ohms),Signal 1 Vin (V),Signal 2 Vin (V),Digital Inputs (code),Drive 1 Iout (mA),Drive 1 Ipower (watts),Drive 2 Iout (mA),Drive 2 Ipower (watts),Pressure (),Map 20 (),Map 21 (),Map 22 (),Map 23 (),Map 24 (),Map 25 (),Map 26 (),Map 27 (),Map 28 (),Map 29 ()
,22097382.72,4369,330,0.0979999974370003,284.35400390625,0.121848718261719,492.554959716797,9.8068155348301e-006,496.922319335938,0.0348651924133301,500,,,1.41594882707853e-005,6.97937403794546e-006,1.94263608973875e-006,,25,121.848718261719,0.00980681553483009,34.8651924133301,,,,,0.00,0.00,0.00,0.00
,22098761.22,4369,320.363800048828,0.0979999974370003,284.35400390625,0.118180931091309,500,8.3473363891244e-006,500,0.0359337692260742,500,,,7.17976620873736e-007,4.43030735497131e-008,2.54970217417513e-006,,25,118.180931091309,0.00834733638912439,35.9337692260742,,,,,0.00,0.00,0.00,0.00
,22100121.52,4369,311.006500244141,0.0979999974370003,284.35400390625,0.114624076843262,500,8.32688961178064e-006,500,0.0366531257629395,500,,,7.15704280714726e-007,3.32676596946283e-008,7.04800625735882e-007,,25,114.624076843262,0.00832688961178064,36.6531257629395,,,,,0.00,0.00,0.00,0.00
,22101464.14,4369,301.924850463867,0.0979999974370003,284.35400390625,0.111147010803223,500,8.28111324459314e-006,500,0.0373348463439941,500,,,7.46123662013592e-007,4.43251407604006e-008,5.3130055104725e-007,,25,111.147010803223,0.00828111324459314,37.3348463439941,,,,,0.00,0.00,0.00,0.00
,22102789.91,4369,293.108001708984,0.0979999974370003,284.35400390625,0.107737274169922,500,8.27043209224939e-006,500,0.0380391731262207,500,,,7.74070818250321e-007,4.93437247575134e-008,7.37569701944089e-007,,25,107.737274169922,0.00827043209224939,38.0391731262207,,,,,0.00,0.00,0.00,0.00
,22104102.11,4369,284.54914855957,0.0979999974370003,284.35400390625,0.104423377990723,500,8.24205074459314e-006,500,0.0387756576538086,500,,,5.48250860582501e-007,4.03565403912196e-008,6.36677002192681e-007,,25,104.423377990723,0.00824205074459314,38.7756576538086,,,,,0.00,0.00,0.00,0.00
,22105398.78,4369,276.236846923828,0.0979999974370003,284.35400390625,0.101181251525879,500,8.23106441646814e-006,500,0.0395378646850586,500,,,6.62923756181705e-007,4.53358113403646e-008,8.22914935243649e-007,,25,101.181251525879,0.00823106441646814,39.5378646850586,,,,,0.00,0.00,0.00,0.00
,22106683.34,4369,268.173355102539,0.0979999974370003,284.35400390625,0.0980254159545899,500,8.19596920162439e-006,500,0.0403177101135254,500,,,2.88637165527289e-006,3.87242694381046e-008,1.28606214279773e-006,,25,98.0254159545898,0.00819596920162439,40.3177101135254,,,,,0.00,0.00,0.00,0.00
,22107951.63,4369,260.340408325195,0.0979999974370003,284.35400390625,0.0949427264404297,500,8.18223629146814e-006,500,0.0411222538757324,500,,,2.76414720169892e-006,4.32381421462656e-008,1.49260002558481e-006,,25,94.9427264404297,0.00818223629146814,41.1222538757324,,,,,0.00,0.00,0.00,0.00
,22109206.53,4369,252.73690032959,0.0979999974370003,284.35400390625,0.0919507751464844,500,8.16056881099939e-006,500,0.0419495315551758,500,,,6.28022239788142e-007,3.61133987238597e-008,6.485433112446e-007,,25,91.9507751464844,0.00816056881099939,41.9495315551758,,,,,0.00,0.00,0.00,0.00
,22110451.25,4369,245.355995178223,0.0979999974370003,284.35400390625,0.0890372955322266,500,8.1477514281869e-006,500,0.0427906150817871,500,,,6.66542042716695e-007,3.70684950673022e-008,6.31445119029953e-007,,25,89.0372955322266,0.00814775142818689,42.7906150817871,,,,,0.00,0.00,0.00,0.00
,22111679.92,4369,238.191398620605,0.0979999974370003,284.35400390625,0.0861986236572266,500,8.10899402946234e-006,500,0.0436493110656738,500,,,1.00493891918163e-006,4.86912101176556e-008,6.50784098664144e-007,,25,86.1986236572266,0.00810899402946234,43.6493110656738,,,,,0.00,0.00,0.00,0.00
,22112895.69,4369,231.234252929688,0.0979999974370003,284.35400390625,0.0834429092407227,500,8.06977868080139e-006,500,0.0445329438781738,500,,,5.81034084363398e-007,3.56399917104973e-008,9.03862833073292e-007,,25,83.4429092407227,0.00806977868080139,44.5329438781738,,,,,0.00,0.00,0.00,0.00
,22114097.92,4369,224.479545593262,0.0979999974370003,284.35400390625,0.0807550430297852,500,8.06077595800161e-006,500,0.0454364356994629,500,,,7.66745494522321e-007,4.73631427917655e-008,8.58908930903649e-007,,25,80.7550430297852,0.00806077595800161,45.4364356994629,,,,,0.00,0.00,0.00,0.00
,22115289.11,4369,217.923698425293,0.0979999974370003,284.35400390625,0.0781315307617187,500,8.04399117827415e-006,500,0.0463588027954102,500,,,1.09300177655971e-006,3.82345355454307e-008,5.9362408854896e-007,,25,78.1315307617188,0.00804399117827415,46.3588027954102,,,,,0.00,0.00,0.00,0.00
,22116467.75,4369,211.561599731445,0.0979999974370003,284.35400390625,0.0755760726928711,500,7.99165327101946e-006,500,0.0472990608215332,500,,,4.57763756761164e-007,4.85592021983059e-008,7.92869537597798e-007,,25,75.5760726928711,0.00799165327101946,47.2990608215332,,,,,0.00,0.00,0.00,0.00
,22117637.25,4369,205.38289642334,0.0979999974370003,284.35400390625,0.0731024780273438,500,7.9968411847949e-006,500,0.0482607536315918,500,,,7.30034533366042e-007,5.26344104287097e-008,8.44281540948165e-007,,25,73.1024780273438,0.0079968411847949,48.2607536315918,,,,,0.00,0.00,0.00,0.00
,22118800.11,4369,199.383445739746,0.0979999974370003,284.35400390625,0.0706886596679688,500,7.96662867069244e-006,500,0.0492445869445801,500,,,7.69244258386682e-007,4.50457440770451e-008,6.90198001373323e-007,,25,70.6886596679688,0.00796662867069244,49.2445869445801,,,,,0.00,0.00,0.00,0.00
,22119947.55,4369,193.561248779297,0.0979999974370003,284.35400390625,0.068336784362793,500,7.93199121952057e-006,500,0.0502481803894043,500,,,6.19061961679128e-007,3.92853815628356e-008,7.74149530769675e-007,,25,68.336784362793,0.00793199121952057,50.2481803894043,,,,,0.00,0.00,0.00,0.00
,22121084.45,4369,187.908401489258,0.0979999974370003,284.35400390625,0.0660459899902344,500,7.91337549686432e-006,500,0.0512741084289551,500,,,7.87122964331039e-007,3.68757927534978e-008,9.1154026613146e-007,,25,66.0459899902344,0.00791337549686432,51.2741084289551,,,,,0.00,0.00,0.00,0.00
,22122216.31,4369,182.421699523926,0.0979999974370003,284.35400390625,0.063817693939209,500,7.89842188358307e-006,500,0.0523179092407227,500,,,6.84776099876243e-007,3.75335195863338e-008,7.82672321075548e-007,,25,63.817693939209,0.00789842188358307,52.3179092407227,,,,,0.00,0.00,0.00,0.00
,22123337.69,4369,177.093246459961,0.0979999974370003,284.35400390625,0.0616472778320313,500,7.88194239139557e-006,500,0.0533815841674805,500,,,6.60548701892291e-007,4.10855469293149e-008,7.04881997661693e-007,,25,61.6472778320313,0.00788194239139557,53.3815841674805,,,,,0.00,0.00,0.00,0.00
,22124448.86,4369,171.921051025391,0.0979999974370003,284.35400390625,0.059542724609375,500,7.85188257694245e-006,500,0.0544707450866699,500,,,8.08715178998359e-007,4.23513181190121e-008,5.14404623754772e-007,,25,59.542724609375,0.00785188257694244,54.4707450866699,,,,,0.00,0.00,0.00,0.00
,22125550.28,4369,166.901504516602,0.0979999974370003,284.35400390625,0.0574868545532227,500,7.83174097537994e-006,500,0.0555686721801758,500,,,6.78115722198506e-007,3.67397927800445e-008,8.09795287912484e-007,,25,57.4868545532227,0.00783174097537994,55.5686721801758,,,,,0.00,0.00,0.00,0.00
,22126640.75,4369,162.023643493652,0.0979999974370003,284.35400390625,0.055486255645752,500,7.79893457889557e-006,500,0.0566859970092774,500,,,7.75199759166226e-007,3.04044534163959e-008,7.69245104049082e-007,,25,55.486255645752,0.00779893457889557,56.6859970092773,,,,,0.00,0.00,0.00,0.00
,22127724.70,4369,157.29419708252,0.0979999974370003,284.35400390625,0.0535375480651855,500,7.76185566559434e-006,500,0.057805477142334,500,,,7.39933294576929e-007,4.96500422791222e-008,6.6292539166516e-007,,25,53.5375480651855,0.00776185566559434,57.805477142334,,,,,0.00,0.00,0.00,0.00
,22128797.86,4369,152.702545166016,0.0979999974370003,284.35400390625,0.0516417770385742,500,7.73957783356309e-006,500,0.0589494323730469,500,,,8.76550199664968e-007,4.32974344265495e-008,8.51284364297854e-007,,25,51.6417770385742,0.00773957783356309,58.9494323730469,,,,,0.00,0.00,0.00,0.00
,22129866.52,4369,148.241798400879,0.0979999974370003,284.35400390625,0.049799373626709,500,7.71028088405728e-006,500,0.0601139831542969,500,,,8.06517552710188e-007,5.15310465000788e-008,8.33526940458176e-007,,25,49.799373626709,0.00771028088405728,60.1139831542969,,,,,0.00,0.00,0.00,0.00
,22130925.53,4369,143.913047790527,0.0979999974370003,284.35400390625,0.0480024028015137,500,7.69547974690795e-006,500,0.0613046913146973,500,,,7.36932490546601e-007,4.67543763670828e-008,7.30033642282578e-007,,25,48.0024028015137,0.00769547974690795,61.3046913146973,,,,,0.00,0.00,0.00,0.00
,22131977.50,4369,139.707748413086,0.0979999974370003,284.35400390625,0.0462543449401856,500,7.64924544841051e-006,500,0.0625159301757812,500,,,8.28202130943575e-007,4.30774745468502e-008,7.20807574074289e-007,,25,46.2543449401855,0.00764924544841051,62.5159301757813,,,,,0.00,0.00,0.00,0.00
,22133023.70,4369,135.630149841309,0.0979999974370003,284.35400390625,0.044556572265625,500,7.61460795998573e-006,500,0.0637571411132812,500,,,8.44332649421269e-007,3.91310232211269e-008,7.9235685502307e-007,,25,44.556572265625,0.00761460795998573,63.7571411132813,,,,,0.00,0.00,0.00,0.00
,22134060.67,4369,131.668296813965,0.0979999974370003,284.35400390625,0.0429045372009277,500,7.58821023628116e-006,500,0.0650254898071289,500,,,6.01900854005865e-007,5.21261317521751e-008,6.70954412739209e-007,,25,42.9045372009277,0.00758821023628116,65.0254898071289,,,,,0.00,0.00,0.00,0.00
,22135093.45,4369,127.821601867676,0.0979999974370003,284.35400390625,0.0412874603271484,500,7.57600322365761e-006,500,0.0662967300415039,500,,,8.86981103018767e-007,5.59396853602061e-008,9.3614921949953e-007,,25,41.2874603271484,0.00757600322365761,66.2967300415039,,,,,0.00,0.00,0.00,0.00
,22136118.17,4369,124.090549468994,0.0979999974370003,284.35400390625,0.0397198982238769,500,7.54365457221866e-006,500,0.0675905456542969,500,,,8.10154558125456e-007,4.18730754194965e-008,9.07545058262348e-007,,25,39.719898223877,0.00754365457221866,67.5905456542969,,,,,0.00,0.00,0.00,0.00
,22137132.48,4369,120.466499328613,0.0979999974370003,284.35400390625,0.0381904718017578,500,7.51939307898283e-006,500,0.0688973922729492,500,,,8.62857548920352e-007,4.88600934163432e-008,8.21144531428423e-007,,25,38.1904718017578,0.00751939307898283,68.8973922729492,,,,,0.00,0.00,0.00,0.00
,22138146.02,4369,116.947700500488,0.0979999974370003,284.35400390625,0.0367067488098145,500,7.48368743807077e-006,500,0.0702308477783203,500,,,1.4362897991499e-006,4.15925823793121e-008,2.59406307432499e-006,,25,36.7067488098145,0.00748368743807077,70.2308477783203,,,,,0.00,0.00,0.00,0.00
,22139150.34,4369,113.532699584961,0.0979999974370003,284.35400390625,0.0352621383666992,500,7.44004711508751e-006,500,0.0715781021118164,500,,,6.39414162214084e-007,4.21608530322943e-008,8.83364248723098e-007,,25,35.2621383666992,0.00744004711508751,71.5781021118164,,,,,0.00,0.00,0.00,0.00
,22140150.14,4369,110.217948913574,0.0979999974370003,284.35400390625,0.0338535194396973,500,7.41105539724231e-006,500,0.0729362716674805,500,,,6.09684012311623e-007,5.36265170905457e-008,1.004767147808e-006,,25,33.8535194396973,0.00741105539724231,72.9362716674805,,,,,0.00,0.00,0.00,0.00
,22141144.55,4369,106.998649597168,0.0979999974370003,284.35400390625,0.0324893035888672,500,7.35963311046362e-006,500,0.074315673828125,500,,,8.01050572697793e-007,4.49489843419444e-008,8.65052294423729e-007,,25,32.4893035888672,0.00735963311046362,74.315673828125,,,,,0.00,0.00,0.00,0.00
,22142132.75,4369,103.873802185059,0.0979999974370003,284.35400390625,0.0311568773651123,500,7.36024346202612e-006,500,0.0757075415039063,500,,,9.20258575814161e-007,3.77493929942314e-008,1.0961654834196e-006,,25,31.1568773651123,0.00736024346202612,75.7075415039063,,,,,0.00,0.00,0.00,0.00
,22143117.05,4369,100.839099884033,0.0979999974370003,284.35400390625,0.0298653659820557,500,7.30653250589967e-006,500,0.0771148452758789,500,,,7.03395516813197e-007,5.6989936002335e-008,8.69348094503622e-007,,25,29.8653659820557,0.00730653250589967,77.1148452758789,,,,,0.00,0.00,0.00,0.00
,22144091.72,4369,97.8967018127441,0.0979999974370003,284.35400390625,0.0286067200469971,500,7.27616753429174e-006,500,0.0785505599975586,500,,,7.2356272326368e-007,3.45435529257098e-008,8.33178269102786e-007,,25,28.6067200469971,0.00727616753429174,78.5505599975586,,,,,0.00,0.00,0.00,0.00
,22145064.23,4369,95.0364990234375,0.0979999974370003,284.35400390625,0.0273751923370361,500,7.22794966772199e-006,500,0.0800015411376953,500,,,6.51333228391471e-007,4.51656476883886e-008,9.10619667686649e-007,,25,27.3751923370361,0.00722794966772199,80.0015411376953,,,,,0.00,0.00,0.00,0.00
,22146069.70,4369,92.2607002258301,0.0979999974370003,284.35400390625,0.0261869697570801,500,7.1985000371933e-006,500,0.0814673233032227,500,,,7.18298497790171e-007,4.46628460881957e-008,7.64842675280764e-007,,25,26.1869697570801,0.0071985000371933,81.4673233032227,,,,,0.00,0.00,0.00,0.00
,22147121.48,4369,89.5673980712891,0.0979999974370003,284.35400390625,0.0250290869903564,500,7.16935560107231e-006,500,0.0829488143920898,500,,,7.70541187116158e-007,4.50199903968405e-008,5.78528258056382e-007,,25,25.0290869903564,0.00716935560107231,82.9488143920898,,,,,0.00,0.00,0.00,0.00
,22148188.06,4369,86.9470481872559,0.0979999974370003,284.35400390625,0.0239058895111084,500,7.14036390185356e-006,500,0.0844507827758789,500,,,6.25238244717355e-007,4.49811854808618e-008,5.44526716382963e-007,,25,23.9058895111084,0.00714036390185356,84.4507827758789,,,,,0.00,0.00,0.00,0.00
,22149233.83,4369,84.4120483398438,0.0979999974370003,284.35400390625,0.0228163604736328,500,7.09611335769296e-006,500,0.0859817352294922,500,,,6.16708296709136e-007,3.81927215907968e-008,1.18179183532511e-006,,25,22.8163604736328,0.00709611335769296,85.9817352294922,,,,,0.00,0.00,0.00,0.00
,22150300.45,4369,81.9419021606445,0.0979999974370003,284.35400390625,0.0217486763000488,500,7.05552497878671e-006,500,0.0875259552001953,500,,,6.9061835244422e-007,4.3815314550987e-008,7.82375265640616e-007,,25,21.7486763000488,0.00705552497878671,87.5259552001953,,,,,0.00,0.00,0.00,0.00
,22151371.73,4369,79.5489501953125,0.0979999974370003,284.35400390625,0.0207160110473633,500,7.03858772292733e-006,500,0.0891202087402344,500,,,7.31944891848626e-007,4.08770399767868e-008,7.26839842620731e-007,,25,20.7160110473633,0.00703858772292733,89.1202087402344,,,,,0.00,0.00,0.00,0.00
,22152430.48,4369,77.228199005127,0.0979999974370003,284.35400390625,0.0197126921081543,500,6.9810620136559e-006,500,0.090772102355957,500,,,7.29672812600945e-007,3.39570027262566e-008,8.06914561445718e-007,,25,19.7126921081543,0.0069810620136559,90.772102355957,,,,,0.00,0.00,0.00,0.00
,22153477.91,4369,74.9748992919922,0.0979999974370003,284.35400390625,0.0187464046478271,500,6.94840803742409e-006,500,0.092384765625,500,,,1.54860035139905e-007,4.29980426282919e-008,9.34841912340505e-007,,25,18.7464046478271,0.00694840803742409,92.384765625,,,,,0.00,0.00,0.00,0.00
,22154518.61,4369,72.7811012268066,0.0979999974370003,284.35400390625,0.0178061058044434,500,6.91331267356872e-006,500,0.0940276260375977,500,,,1.25767562211008e-007,3.61012549627243e-008,9.99829330016028e-007,,25,17.8061058044434,0.00691331267356873,94.0276260375977,,,,,0.00,0.00,0.00,0.00
,22155553.41,4369,70.6608009338379,0.0979999974370003,284.35400390625,0.0168971309661865,500,6.87394497916102e-006,500,0.0956764935302734,500,,,6.12725148233217e-008,4.99301535156439e-008,1.33888560669577e-006,,25,16.8971309661865,0.00687394497916102,95.6764935302734,,,,,0.00,0.00,0.00,0.00
,22156588.69,4369,68.5954475402832,0.0979999974370003,284.35400390625,0.0160229423522949,500,6.85166709125042e-006,500,0.0973438339233399,500,,,8.53815716502493e-008,3.76604719678995e-008,9.03882025200633e-007,,25,16.0229423522949,0.00685166709125042,97.3438339233398,,,,,0.00,0.00,0.00,0.00
,22157619.11,4369,66.5890998840332,0.0979999974370003,284.35400390625,0.0151755069732666,500,6.81077353656292e-006,500,0.0990412979125977,500,,,1.1255874729062e-007,3.94078722233846e-008,7.35753086125294e-007,,25,15.1755069732666,0.00681077353656292,99.0412979125977,,,,,0.00,0.00,0.00,0.00
,22158650.42,4369,64.6472015380859,0.0979999974370003,284.35400390625,0.0143583040237427,500,6.77583085373044e-006,500,0.100748649597168,500,,,1.11868643110096e-007,5.64707924392881e-008,7.46899802047454e-007,,25,14.3583040237427,0.00677583085373044,100.748649597168,,,,,0.00,0.00,0.00,0.00
,22159674.27,4369,62.7627506256104,0.0979999974370003,284.35400390625,0.013572364616394,500,6.74760207533837e-006,500,0.102495132446289,500,,,1.85950583839892e-007,4.41542131246157e-008,8.81517356897051e-007,,25,13.572364616394,0.00674760207533836,102.495132446289,,,,,0.00,0.00,0.00,0.00
,22160699.19,4369,60.926399230957,0.0979999974370003,284.35400390625,0.0128160137176514,500,6.71662660315633e-006,500,0.104269416809082,500,,,9.82861131680509e-008,3.81398338857353e-008,1.01720209564031e-006,,25,12.8160137176514,0.00671662660315633,104.269416809082,,,,,0.00,0.00,0.00,0.00
,22161722.98,4369,59.1450004577637,0.0979999974370003,284.35400390625,0.0120899147033691,500,6.69312790036202e-006,500,0.106051457519531,500,,,1.01948188193754e-007,3.89635677969776e-008,2.10957741056014e-006,,25,12.0899147033691,0.00669312790036202,106.051457519531,,,,,0.00,0.00,0.00,0.00
,22162738.72,4369,57.4198513031006,0.0979999974370003,284.35400390625,0.011392368888855,500,6.65330244228244e-006,500,0.10786540222168,500,,,1.01059630612534e-007,4.88796929818308e-008,9.32352048398476e-007,,25,11.392368888855,0.00665330244228244,107.86540222168,,,,,0.00,0.00,0.00,0.00
,22163754.75,4369,55.7425498962402,0.0979999974370003,284.35400390625,0.0107245515823364,500,6.64033239707351e-006,500,0.109694313049316,500,,,9.58575381590998e-008,2.96374237451612e-008,1.14532685570757e-006,,25,10.7245515823364,0.00664033239707351,109.694313049316,,,,,0.00,0.00,0.00,0.00
,22164770.78,4369,54.1110000610352,0.0979999974370003,284.35400390625,0.0100859718322754,500,6.60249061882496e-006,500,0.111543266296387,500,,,1.14821630530319e-007,3.8024760968201e-008,8.38403459443398e-007,,25,10.0859718322754,0.00660249061882496,111.543266296387,,,,,0.00,0.00,0.00,0.00
,22165762.89,4369,52.5353984832764,0.0979999974370003,284.35400390625,0.00947748622894287,500,6.58143347129226e-006,500,0.113421478271484,500,,,6.96158757646778e-008,3.65657388032385e-008,8.32475278767382e-007,,25,9.47748622894287,0.00658143347129226,113.421478271484,,,,,0.00,0.00,0.00,0.00
,22166734.91,4369,50.9982490539551,0.0979999974370003,284.35400390625,0.00889732856750488,500,6.54313391074538e-006,500,0.115313271484375,500,,,7.81556151027758e-008,4.35782039771713e-008,3.9507467634807e-006,,25,8.89732856750488,0.00654313391074538,115.313271484375,,,,,0.00,0.00,0.00,0.00
,22167707.20,4369,49.5104503631592,0.0979999974370003,284.35400390625,0.00834501132965088,500,6.50620758533478e-006,500,0.117260025024414,500,,,8.61345944511495e-008,3.97766800243645e-008,7.89340798478777e-007,,25,8.34501132965088,0.00650620758533478,117.260025024414,,,,,0.00,0.00,0.00,0.00
,22168670.27,4369,48.0643005371094,0.0979999974370003,284.35400390625,0.00782083005905151,500,6.50101955980062e-006,500,0.119190711364746,500,,,1.22008422539776e-007,3.87225922512727e-008,9.6063293892358e-007,,25,7.82083005905151,0.00650101955980062,119.190711364746,,,,,0.00,0.00,0.00,0.00
,22169638.92,4369,46.6620998382568,0.0979999974370003,284.35400390625,0.00732278482437134,500,6.46378789097071e-006,500,0.121160018920898,500,,,6.46038959199618e-008,3.40529151836686e-008,8.68416227999139e-007,,25,7.32278482437134,0.00646378789097071,121.160018920898,,,,,0.00,0.00,0.00,0.00
,22170611.14,4369,45.2971000671387,0.0979999974370003,284.35400390625,0.00685270574569702,500,6.44974980503321e-006,500,0.123141792297363,500,,,4.51965901440892e-008,4.54739123498808e-008,8.63169738932362e-007,,25,6.85270574569702,0.00644974980503321,123.141792297363,,,,,0.00,0.00,0.00,0.00
,22171583.39,4369,43.9757995605469,0.0979999974370003,284.35400390625,0.00640868854522705,500,6.43342282623053e-006,500,0.125161582946777,500,,,1.3029979591305e-007,3.76420280618306e-008,9.93285980001684e-007,,25,6.40868854522705,0.00643342282623053,125.161582946777,,,,,0.00,0.00,0.00,0.00
,22172555.52,4369,42.6919498443604,0.0979999974370003,284.35400390625,0.00599048385620117,500,6.408856138587e-006,500,0.127233604431152,500,,,4.57254428847061e-008,4.38339804845558e-008,8.51285892625512e-007,,25,5.99048385620117,0.006408856138587,127.233604431152,,,,,0.00,0.00,0.00,0.00
,22173537.48,4369,41.4455986022949,0.0979999974370003,284.35400390625,0.00559742076873779,500,6.38566276058555e-006,500,0.129288317871094,500,,,4.66471851118641e-008,4.60107973325874e-008,1.02333832989126e-006,,25,5.59742076873779,0.00638566276058555,129.288317871094,,,,,0.00,0.00,0.00,0.00
,22174519.38,4369,40.2345504760742,0.0979999974370003,284.35400390625,0.0052257656288147,500,6.35621327906847e-006,500,0.131374622802734,500,,,5.93440448660418e-008,4.6486496275841e-008,8.73560717139427e-007,,25,5.2257656288147,0.00635621327906847,131.374622802734,,,,,0.00,0.00,0.00,0.00
,22175503.47,4369,39.0582008361816,0.0979999974370003,284.35400390625,0.00487946174621582,500,6.36262197047472e-006,500,0.133454861450195,500,,,6.61633451705295e-008,4.53537826914819e-008,8.27710547660459e-007,,25,4.87946174621582,0.00636262197047472,133.454861450195,,,,,0.00,0.00,0.00,0.00
,22176487.42,4369,37.918399810791,0.0979999974370003,284.35400390625,0.00455491733551025,500,6.34690541774035e-006,500,0.135560397949219,500,,,5.27698275098223e-008,4.14943684108919e-008,9.98532429261659e-007,,25,4.55491733551025,0.00634690541774034,135.560397949219,,,,,0.00,0.00,0.00,0.00
,22177470.41,4369,36.8101005554199,0.0979999974370003,284.35400390625,0.00425200731277466,500,6.32737416774035e-006,500,0.137704935302734,500,,,8.03510745923363e-008,4.86456321761929e-008,1.10878401723316e-006,,25,4.25200731277466,0.00632737416774035,137.704935302734,,,,,0.00,0.00,0.00,0.00
,22178464.67,4369,35.7359008789063,0.0979999974370003,284.35400390625,0.00397052062988281,500,6.31593007594347e-006,500,0.139872739868164,500,,,5.65572124609425e-008,3.46061800651228e-008,9.16642859717501e-007,,25,3.97052062988281,0.00631593007594347,139.872739868164,,,,,0.00,0.00,0.00,0.00
,22179467.77,4369,34.6920013427734,0.0979999974370003,284.35400390625,0.00370944089889526,500,6.29914538934827e-006,500,0.14205209777832,500,,,4.00379651305979e-008,3.94451130212174e-008,1.43502756632752e-006,,25,3.70944089889526,0.00629914538934827,142.05209777832,,,,,0.00,0.00,0.00,0.00
,22180472.86,4369,33.6794490814209,0.0979999974370003,284.35400390625,0.0034667728805542,500,6.27000104635954e-006,500,0.144252110595703,500,,,5.37802090823988e-008,4.73008769099153e-008,1.80698565031523e-006,,25,3.4667728805542,0.00627000104635954,144.252110595703,,,,,0.00,0.00,0.00,0.00
,22181486.52,4369,32.6983509063721,0.0979999974370003,284.35400390625,0.00324224969863892,500,6.26267680898309e-006,500,0.146476721191406,500,,,4.19231964673151e-008,4.91433850446988e-008,2.53473567253756e-006,,25,3.24224969863892,0.00626267680898309,146.476721191406,,,,,0.00,0.00,0.00,0.00
,22182500.81,4369,31.7402505874634,0.0979999974370003,284.35400390625,0.00303443458557129,500,6.24772312119603e-006,500,0.148716838378906,500,,,3.94775625198646e-008,4.47867495415088e-008,2.48978460966189e-006,,25,3.03443458557129,0.00624772312119603,148.716838378906,,,,,0.00,0.00,0.00,0.00
,22183516.30,4369,30.8171005249023,0.0979999974370003,284.35400390625,0.00284320311546326,500,6.24116189777851e-006,500,0.150969158935547,500,,,6.1159025043794e-008,3.64447132893982e-008,2.90839619170727e-006,,25,2.84320311546326,0.00624116189777851,150.969158935547,,,,,0.00,0.00,0.00,0.00
,22184530.27,4369,29.9167003631592,0.0979999974370003,284.35400390625,0.00266603970527649,500,6.22590301558375e-006,500,0.153260653686523,500,,,2.01762518223216e-007,4.44071940915116e-008,9.80015128696776e-007,,25,2.66603970527649,0.00622590301558375,153.260653686523,,,,,0.00,0.00,0.00,0.00
,22185387.42,4369,29.047550201416,0.0979999974370003,284.35400390625,0.00250426456451416,500,6.23215911909938e-006,500,0.155596164550781,500,,,2.22401006607381e-007,4.30980933179753e-008,9.87116630317169e-006,,25,2.50426456451416,0.00623215911909938,155.596164550781,,,,,0.00,0.00,0.00,0.00
,22186236.94,4369,28.1950492858887,0.0979999974370003,284.35400390625,0.0023528740978241,500,6.22529262676835e-006,500,0.157963741455078,500,,,1.61331956693936e-007,3.62204466456897e-008,1.73123923889815e-006,,25,2.3528740978241,0.00622529262676835,157.963741455078,,,,,0.00,0.00,0.00,0.00
,22187087.36,4369,27.3688993453979,0.0979999974370003,284.35400390625,0.00221618852615356,500,6.21567960828543e-006,500,0.160299594726562,500,,,4.8648983103899e-008,4.05007132322988e-008,6.02349029960581e-007,,25,2.21618852615356,0.00621567960828543,160.299594726563,,,,,0.00,0.00,0.00,0.00
,22187932.67,4369,26.5717000961304,0.0979999974370003,284.35400390625,0.00209193764686585,500,6.2182735465467e-006,500,0.162639064331055,500,,,7.82426210986754e-008,3.31493574249419e-008,2.28258176415462e-006,,25,2.09193764686584,0.0062182735465467,162.639064331055,,,,,0.00,0.00,0.00,0.00
,22188775.34,4369,25.7924995422363,0.0979999974370003,284.35400390625,0.00197613571166992,500,6.19523268193006e-006,500,0.165020001220703,500,,,4.0418797874664e-008,4.23481617135015e-008,1.0162568719392e-006,,25,1.97613571166992,0.00619523268193007,165.020001220703,,,,,0.00,0.00,0.00,0.00
,22189620.11,4369,25.0356502532959,0.0979999974370003,284.35400390625,0.00187393164634705,500,6.19111282750964e-006,500,0.167232235107422,500,,,2.28706293130065e-007,4.96262021251693e-008,1.15053285531291e-006,,25,1.87393164634705,0.00619111282750964,167.232235107422,,,,,0.00,0.00,0.00,0.00
,22190465.36,4369,24.3120002746582,0.0979999974370003,284.35400390625,0.00177884428024292,500,6.19065506383776e-006,500,0.169714290771484,500,,,8.66272005726666e-008,4.52094492462869e-008,2.23230153127617e-006,,25,1.77884428024292,0.00619065506383777,169.714290771484,,,,,0.00,0.00,0.00,0.00
,22191313.63,4369,23.594500541687,0.0979999974370003,284.35400390625,0.00169217347621918,500,6.20194658637047e-006,500,0.172096912841797,500,,,7.35872439953399e-008,4.28336169960997e-008,3.69467203991188e-006,,25,1.69217347621918,0.00620194658637047,172.096912841797,,,,,0.00,0.00,0.00,0.00
,22192159.84,4369,22.9100008010864,0.0979999974370003,284.35400390625,0.00161247700691223,500,6.18272045627236e-006,500,0.17464604675293,500,,,5.79520628636293e-008,3.77526009110823e-008,8.39185207063671e-007,,25,1.61247700691223,0.00618272045627236,174.64604675293,,,,,0.00,0.00,0.00,0.00
,22192995.92,4369,22.2411994934082,0.0979999974370003,284.35400390625,0.00154123177051544,500,6.19736893102527e-006,500,0.177076069335938,500,,,6.0251164253599e-008,3.15493333947068e-008,1.54714853736396e-006,,25,1.54123177051544,0.00619736893102527,177.076069335937,,,,,0.00,0.00,0.00,0.00
,22193830.17,4369,21.5906496047974,0.0979999974370003,284.35400390625,0.00147608684539795,500,6.18012648075819e-006,500,0.179564799804688,500,,,3.69231099143649e-008,4.44595376306655e-008,7.45644562069939e-007,,25,1.47608684539795,0.00618012648075819,179.564799804688,,,,,0.00,0.00,0.00,0.00
,22194666.08,4369,20.9598999023438,0.0979999974370003,284.35400390625,0.00141659682750702,500,6.17982124909759e-006,500,0.182074741210938,500,,,4.79121140411454e-008,3.60444165636491e-008,5.61671618678323e-006,,25,1.41659682750702,0.00617982124909759,182.074741210938,,,,,0.00,0.00,0.00,0.00
,22195501.44,4369,20.3481502532959,0.0979999974370003,284.35400390625,0.00136257433891296,500,6.16730902343989e-006,500,0.184632274780273,500,,,5.06766347576739e-008,3.42987274964133e-008,8.12147461320791e-007,,25,1.36257433891296,0.00616730902343988,184.632274780273,,,,,0.00,0.00,0.00,0.00
,22196336.00,4369,19.7545003890991,0.0979999974370003,284.35400390625,0.00131405447483063,500,6.17509104311466e-006,500,0.187151394042969,500,,,4.11659355974841e-008,3.86966895617304e-008,6.52457769518234e-007,,25,1.31405447483063,0.00617509104311466,187.151394042969,,,,,0.00,0.00,0.00,0.00
,22197172.05,4369,19.1774492263794,0.0979999974370003,284.35400390625,0.00126990335464478,500,6.16608833894134e-006,500,0.189687901000977,500,,,4.44070070477868e-008,4.32527481064979e-008,8.35802730841409e-007,,25,1.26990335464478,0.00616608833894134,189.687901000977,,,,,0.00,0.00,0.00,0.00
,22198008.52,4369,18.6185503005981,0.0979999974370003,284.35400390625,0.00122973337173462,500,6.17600660771132e-006,500,0.192389298095703,493.404998779297,,,4.16064348641587e-008,5.06767607364757e-008,7.89748364070924e-007,,25,1.22973337173462,0.00617600660771131,192.389298095703,,,,,0.00,0.00,0.00,0.00
,22198841.80,4369,18.0729503631592,0.0979999974370003,284.35400390625,0.00119334409236908,500,6.17493845522404e-006,500,0.195056754760742,486.809997558594,,,4.40263114900694e-008,4.65521627353044e-008,9.18376619435632e-007,,25,1.19334409236908,0.00617493845522404,195.056754760742,,,,,0.00,0.00,0.00,0.00
,22199677.20,4369,17.5443000793457,0.0979999974370003,284.35400390625,0.0011602578496933,500,6.15311833098531e-006,500,0.197773051147461,479.971008300781,,,4.53096215066209e-008,2.8587332145812e-008,8.03143559587709e-007,,25,1.1602578496933,0.00615311833098531,197.773051147461,,,,,0.00,0.00,0.00,0.00
,22200501.92,4369,17.034649848938,0.0979999974370003,284.35400390625,0.00113017518043518,500,6.16669867187738e-006,500,0.200535895385742,473.376007080078,,,4.69306395371086e-008,3.75639533349035e-008,9.15932906748139e-007,,25,1.13017518043518,0.00616669867187738,200.535895385742,,,,,0.00,0.00,0.00,0.00
,22201325.92,4369,16.5350503921509,0.0979999974370003,284.35400390625,0.00110309510231018,500,6.16883492097259e-006,500,0.203321791992188,467.024993896484,,,4.92081184442238e-008,4.54102862496593e-008,8.99806066544123e-007,,25,1.10309510231018,0.00616883492097259,203.321791992188,,,,,0.00,0.00,0.00,0.00
,22202149.94,4369,16.0519008636475,0.0979999974370003,284.35400390625,0.00107868534564972,500,6.16288401186466e-006,500,0.206139281616211,460.674011230469,,,3.8114616267529e-008,4.39745452067051e-008,8.62225662378835e-007,,25,1.07868534564972,0.00616288401186466,206.139281616211,,,,,0.00,0.00,0.00,0.00
,22202972.45,4369,15.5838499069214,0.0979999974370003,284.35400390625,0.00105662220478058,500,6.17570139467716e-006,500,0.209013161010742,454.322998046875,,,5.12804268962483e-008,3.8084755914156e-008,1.01758062117867e-006,,25,1.05662220478058,0.00617570139467716,209.013161010742,,,,,0.00,0.00,0.00,0.00
,22203794.41,4369,15.1286001205444,0.0979999974370003,284.35400390625,0.00103695759296417,500,6.16196844726801e-006,500,0.21185208984375,448.217010498047,,,4.52484193396977e-008,3.4774015726017e-008,1.45272470541467e-006,,25,1.03695759296417,0.00616196844726801,211.85208984375,,,,,0.00,0.00,0.00,0.00
,22204618.78,4369,14.6880502700806,0.0979999974370003,284.35400390625,0.00101914939880371,500,6.17173418402672e-006,500,0.21478166809082,442.109985351563,,,3.46613119329542e-008,5.15911159785806e-008,7.8856573352673e-007,,25,1.01914939880371,0.00617173418402672,214.78166809082,,,,,0.00,0.00,0.00,0.00
,22205442.50,4369,14.2578001022339,0.0979999974370003,284.35400390625,0.00100322807312012,500,6.17646437138319e-006,500,0.217693877563477,436.247985839844,,,4.40067263933194e-008,4.41890197906909e-008,1.03275569272867e-006,,25,1.00322807312012,0.00617646437138319,217.693877563477,,,,,0.00,0.00,0.00,0.00
,22206266.16,4369,13.8421001434326,0.0979999974370003,284.35400390625,0.000988844385147095,500,6.17142893373966e-006,500,0.22066532409668,430.385986328125,,,5.58322493239654e-008,5.009913690691e-008,1.00748270469698e-006,,25,0.988844385147095,0.00617142893373966,220.66532409668,,,,,0.00,0.00,0.00,0.00
,22207090.30,4369,13.436900138855,0.0979999974370003,284.35400390625,0.00097584564447403,500,6.17799021303654e-006,500,0.223700243530273,424.523986816406,,,3.68882583851211e-008,4.15522160360568e-008,8.44318781096224e-007,,25,0.97584564447403,0.00617799021303654,223.700243530273,,,,,0.00,0.00,0.00,0.00
,22207912.61,4369,13.0451498031616,0.0979999974370003,284.35400390625,0.000964243638515472,500,6.17066597566009e-006,500,0.226744860229492,418.661010742188,,,4.62149606445809e-008,3.8024763957895e-008,9.82280007950896e-007,,25,0.964243638515472,0.00617066597566009,226.744860229492,,,,,0.00,0.00,0.00,0.00
,22208725.44,4369,12.6638998985291,0.0979999974370003,284.35400390625,0.000953830428123474,500,6.18195747956634e-006,500,0.229828132324219,413.042999267578,,,4.05040268048248e-008,3.28876290503576e-008,1.87713419191309e-006,,25,0.953830428123474,0.00618195747956634,229.828132324219,,,,,0.00,0.00,0.00,0.00
,22209539.50,4369,12.2941498756409,0.0979999974370003,284.35400390625,0.000944458570480347,500,6.18867140263319e-006,500,0.232959133300781,407.670013427734,,,4.04192602228411e-008,3.70277824720801e-008,1.60131593729585e-006,,25,0.944458570480347,0.00618867140263319,232.959133300781,,,,,0.00,0.00,0.00,0.00
,22210352.63,4369,11.9348998069763,0.0979999974370003,284.35400390625,0.000936066856384277,500,6.20164135470986e-006,500,0.236134173583984,402.052001953125,,,3.80968445876863e-008,2.67034288975507e-008,1.0363775018205e-006,,25,0.936066856384277,0.00620164135470986,236.134173583984,,,,,0.00,0.00,0.00,0.00
,22211166.91,4369,11.5866503715515,0.0979999974370003,284.35400390625,0.000928537242412567,500,6.19599564000964e-006,500,0.239348336181641,396.678009033203,,,4.50451556631691e-008,3.97211118581486e-008,1.09849329887682e-006,,25,0.928537242412567,0.00619599564000964,239.348336181641,,,,,0.00,0.00,0.00,0.00
,22211979.50,4369,11.2479500770569,0.0979999974370003,284.35400390625,0.000921735441684723,500,6.19599564000964e-006,500,0.242636752319336,391.303985595703,,,3.56316994020328e-008,3.26247150425679e-008,1.06131879579849e-006,,25,0.921735441684723,0.00619599564000964,242.636752319336,,,,,0.00,0.00,0.00,0.00
,22212794.25,4369,10.919499874115,0.0979999974370003,284.35400390625,0.000915705754756927,500,6.20087847113609e-006,500,0.245954582519531,385.930999755859,,,4.45046436213161e-008,4.03872723341548e-008,7.00839884625566e-007,,25,0.915705754756928,0.00620087847113609,245.954582519531,,,,,0.00,0.00,0.00,0.00
,22213607.78,4369,10.6009998321533,0.0979999974370003,284.35400390625,0.000910291638374329,500,6.19187572970986e-006,500,0.249316602172852,380.800994873047,,,4.77252617179336e-008,5.16402560560827e-008,1.2666644401881e-006,,25,0.910291638374329,0.00619187572970986,249.316602172852,,,,,0.00,0.00,0.00,0.00
,22214422.73,4369,10.2915997505188,0.0979999974370003,284.35400390625,0.000905458271503449,500,6.21308555826545e-006,500,0.252719857788086,375.671997070313,,,3.91780422128436e-008,4.65147233701261e-008,1.45171652070737e-006,,25,0.905458271503448,0.00621308555826545,252.719857788086,,,,,0.00,0.00,0.00,0.00
,22215235.80,4369,9.99059963226318,0.0979999974370003,284.35400390625,0.000901111183166504,500,6.2042354606092e-006,500,0.256196363525391,370.5419921875,,,5.58803350173011e-008,3.52443509478194e-008,9.22323499127833e-007,,25,0.901111183166504,0.0062042354606092,256.196363525391,,,,,0.00,0.00,0.00,0.00
,22216049.16,4369,9.69964981079102,0.0979999974370003,284.35400390625,0.000897238974571228,500,6.19599567726254e-006,500,0.259730129394531,365.412994384766,,,4.4849275404349e-008,5.10120129988308e-008,9.74830958642524e-007,,25,0.897238974571228,0.00619599567726254,259.730129394531,,,,,0.00,0.00,0.00,0.00
,22216859.02,4369,9.41589975357056,0.0979999974370003,284.35400390625,0.000893770644664765,500,6.22117279097438e-006,500,0.263325231933594,360.528015136719,,,4.16767461857099e-008,4.38367631760205e-008,1.26869518140243e-006,,25,0.893770644664764,0.00622117279097438,263.325231933594,,,,,0.00,0.00,0.00,0.00
,22217671.97,4369,9.14019966125488,0.0979999974370003,284.35400390625,0.000890660743713379,500,6.2268185429275e-006,500,0.266991121826172,355.641998291016,,,5.29145086748532e-008,4.23652603500691e-008,1.13865373399689e-006,,25,0.890660743713379,0.0062268185429275,266.991121826172,,,,,0.00,0.00,0.00,0.00
,22218476.06,4369,8.87325000762939,0.0979999974370003,284.35400390625,0.000887867584228516,500,6.2292599491775e-006,500,0.270707813720703,350.756988525391,,,3.95659925222365e-008,4.36344671367855e-008,1.4278557101676e-006,,25,0.887867584228516,0.0062292599491775,270.707813720703,,,,,0.00,0.00,0.00,0.00
,22219279.19,4369,8.61464977264404,0.0979999974370003,284.35400390625,0.000885388019084931,500,6.22895477339625e-006,500,0.27449712890625,345.872009277344,,,2.77291679912179e-008,3.81977762248291e-008,9.69320249319218e-007,,25,0.88538801908493,0.00622895477339625,274.49712890625,,,,,0.00,0.00,0.00,0.00
,22220082.36,4369,8.36289978027344,0.0979999974370003,284.35400390625,0.000883199927806854,500,6.23505832627416e-006,500,0.2783534375,340.986999511719,,,4.7548237711991e-008,2.93930619366249e-008,1.13227990941353e-006,,25,0.883199927806854,0.00623505832627416,278.3534375,,,,,0.00,0.00,0.00,0.00
,22220885.20,4369,8.11845016479492,0.0979999974370003,284.35400390625,0.000881184988021851,500,6.22147792950272e-006,500,0.282324353027344,336.346008300781,,,3.34210767555538e-008,2.88292025228496e-008,1.19225586581858e-006,,25,0.881184988021851,0.00622147792950273,282.324353027344,,,,,0.00,0.00,0.00,0.00
,22221687.66,4369,7.88145017623901,0.0979999974370003,284.35400390625,0.000879400324821472,500,6.23261692002416e-006,500,0.286321303710938,331.460998535156,,,4.77086599153384e-008,4.07968328932135e-008,1.29966724319271e-006,,25,0.879400324821472,0.00623261692002416,286.321303710938,,,,,0.00,0.00,0.00,0.00
,22222490.91,4369,7.6515998840332,0.0979999974370003,284.35400390625,0.000877837355136871,500,6.25687850639224e-006,500,0.290387781982422,326.820007324219,,,3.64958291489863e-008,2.53957887081047e-008,1.28237132760468e-006,,25,0.877837355136871,0.00625687850639224,290.387781982422,,,,,0.00,0.00,0.00,0.00
,22223295.00,4369,7.42779994010925,0.0979999974370003,284.35400390625,0.000876412508487702,500,6.25108007341623e-006,500,0.294542606201172,322.178985595703,,,4.30470470675497e-008,3.69176132210825e-008,1.63245094308631e-006,,25,0.876412508487701,0.00625108007341623,294.542606201172,,,,,0.00,0.00,0.00,0.00
,22224099.38,4369,7.21165013313293,0.0979999974370003,284.35400390625,0.00087515059709549,500,6.25031718984246e-006,500,0.298749379882812,317.782012939453,,,3.86358720604211e-008,4.33082352164409e-008,1.45682191411616e-006,,25,0.875150597095489,0.00625031718984246,298.749379882812,,,,,0.00,0.00,0.00,0.00
,22224902.55,4369,7.00029993057251,0.0979999974370003,284.35400390625,0.000874034559726715,500,6.27610454335809e-006,500,0.303025207519531,313.140991210938,,,3.24636660924233e-008,4.17083014546625e-008,1.19603866552955e-006,,25,0.874034559726715,0.00627610454335809,303.025207519531,,,,,0.00,0.00,0.00,0.00
,22225732.44,4369,6.88260006904602,0.0979999974370003,284.35400390625,0.00087355010509491,500,6.26511821523309e-006,500,0.305303706054687,308.989013671875,,,5.24463258955998e-008,4.09704825521737e-008,0.000162646719784787,,25,0.87355010509491,0.00626511821523309,305.303706054688,,,,,0.00,0.00,0.00,0.00
,22247385.59,4369,6.59769988059998,0.0979999974370003,284.35400390625,0.000872084350585938,500,6.27442616969347e-006,500,0.312118481445313,294.821990966797,,,4.01839960802304e-008,3.34477389785235e-008,2.99638416912658e-006,,25,0.872084350585937,0.00627442616969347,312.118481445313,,,,,0.00,0.00,0.00,0.00
,22248189.34,4369,6.40520000457764,0.0979999974370003,284.35400390625,0.000871341228485107,500,6.26389751210809e-006,500,0.316045380859375,294.821990966797,,,4.57672158377549e-008,3.22334211696715e-008,3.02659604881928e-006,,25,0.871341228485107,0.00626389751210809,316.045380859375,,,,,0.00,0.00,0.00,0.00
,22270430.02,4369,6.21679997444153,0.0979999974370003,284.35400390625,0.00087046980381012,500,6.27549422904849e-006,500,0.32215990234375,283.341003417969,,,4.64565797004225e-008,4.23128967415846e-008,4.17238216076457e-005,,25,0.87046980381012,0.00627549422904849,322.15990234375,,,,,0.00,0.00,0.00,0.00
,22271238.70,4369,6.03704977035522,0.0979999974370003,284.35400390625,0.000869929029941559,500,6.29365220665932e-006,500,0.325694033203125,283.341003417969,,,4.00424485750995e-008,4.10243788282936e-008,4.73003176674939e-006,,25,0.869929029941559,0.00629365220665932,325.694033203125,,,,,0.00,0.00,0.00,0.00
,22272030.56,4369,5.89144992828369,0.0979999974370003,284.35400390625,0.000869468679428101,500,6.30326524376869e-006,500,0.329021060791016,283.341003417969,,,4.55071963925642e-008,4.11122486315595e-008,8.52146401808959e-005,,25,0.869468679428101,0.00630326524376869,329.021060791016,,,,,0.00,0.00,0.00,0.00
,22294445.00,4369,5.68915009498596,0.0979999974370003,284.35400390625,0.000868754422664642,500,6.29197373986244e-006,500,0.335790638427734,268.686004638672,,,4.71067298585284e-008,3.98924047652788e-008,4.88377317523468e-006,,25,0.868754422664642,0.00629197373986244,335.790638427734,,,,,0.00,0.00,0.00,0.00
,22295238.16,4369,5.5231499671936,0.0979999974370003,284.35400390625,0.00086832243680954,500,6.30357045680285e-006,500,0.339920596923828,268.686004638672,,,3.84128557613592e-008,3.45280469729451e-008,3.13236665801038e-006,,25,0.86832243680954,0.00630357045680285,339.920596923828,,,,,0.00,0.00,0.00,0.00
,22295634.63,4374,5.92904996871948,0.0979999974370003,284.35400390625,0.000869590129852295,500,6.29975574091077e-006,500,0.329056988525391,268.686004638672,,,6.02430406060691e-008,3.54267341211129e-008,0.000215237009019829,,25,0.869590129852295,0.00629975574091077,329.056988525391,,,,,0.00,0.00,0.00,0.00