File: data/quartz-holder/180619_empty-quartz_4mm_6T.dat
[Header]
; MPMS3 Data File (default extension .dat)
; Copyright (c) 2007, Quantum Design, Inc. All rights reserved.
TITLE,
FILEOPENTIME,3738622276.68344,06/20/2018,2:11 am
BYAPP,MPMS3,1.0,1.1
INFO,MPMS3 Measurement Release 1.1.16 Build 388, MultiVu Release 2.3.4.15,APPNAME
INFO,0,MOMENT_UNITS
INFO,empty quartz,SAMPLE_MATERIAL
INFO,,SAMPLE_COMMENT
INFO,1,SAMPLE_MASS
INFO,,SAMPLE_VOLUME
INFO,,SAMPLE_MOLECULAR_WEIGHT
INFO,,SAMPLE_SIZE
INFO,,SAMPLE_SHAPE
INFO,Standard,SAMPLE_HOLDER
INFO,Standard,SAMPLE_HOLDER_DETAIL
INFO,66,SAMPLE_OFFSET
DATATYPE,COMMENT,1
DATATYPE,TIME,2
STARTUPAXIS,X,2
STARTUPAXIS,Y1,5
FIELDGROUP, VSM,2,3,4,5,6,8,9,10,11,14,15
FIELDGROUP, DC, 2,3,4,14,34,35,36,37,38,39,40,41,42,43,44,45,46,47
STARTUPGROUP, All
[Data]
Comment,Time Stamp (sec),Temperature (K),Magnetic Field (Oe),Moment (emu),M. Std. Err. (emu),Transport Action,Averaging Time (sec),Frequency (Hz),Peak Amplitude (mm),Center Position (mm),Lockin Signal' (V),Lockin Signal (V),Range,M. Quad. Signal (emu),Min. Temperature (K),Max. Temperature (K),Min. Field (Oe),Max. Field (Oe),Mass (grams),Motor Lag (deg),Pressure (Torr),Measure Count,Measurement Number,SQUID Status (code),Motor Status (code),Measure Status (code),Motor Current (amps),Motor Temp. (C),Temp. Status (code),Field Status (code),Chamber Status (code),Chamber Temp (K),Redirection State,Average Temp (K),Rotation Angle (deg),Rotator state,DC Moment Fixed Ctr (emu),DC Moment Err Fixed Ctr (emu),DC Moment Free Ctr (emu),DC Moment Err Free Ctr (emu),DC Fixed Fit,DC Free Fit,DC Calculated Center (mm),DC Calculated Center Err (mm),DC Scan Length (mm),DC Scan Time (s),DC Number of Points,DC Squid Drift,DC Min V (V),DC Max V (V),DC Scans per Measure,Map 01,Map 02,Map 03,Map 04,Map 05,Map 06,Map 07,Map 08,Map 09,Map 10,Map 11,Map 12,Map 13,Map 14,Map 15,Map 16
,3738622355.69016,2.00074768066406,40000.328125,5.5124315942646E-7,4.33111785967813E-8,1,10,13.2042255401611,3.98052434871178,32.3400013148785,0.000488665227149279,6.0190114891807E-5,1,-1.34176802555586E-8,2.00074768066406,2.00074768066406,40000.328125,40000.328125,51.3025786739766,5.51570675232781,2.47544455528259,132,1,0,0,1,0.236129760742187,30.3030319213867,1,1,1,2.00074768066406,0,2.00074768066406,,,,,,,,,,,,,,,,,,,,,,,,,,,,,,,,,
,3738622412.14139,4.1858104467392,40000.328125,4.71314665763121E-7,4.05936465342812E-8,1,10,13.2042255401611,3.98043481128032,32.3400013148785,0.000415284536466062,6.84305365312025E-5,1,7.74023167767637E-9,3.98228478431702,4.38933610916138,40000.328125,40000.328125,51.0239281068708,5.51596352056004,3.50692081451416,132,1,0,0,1,0.23712158203125,30.3030319213867,6,1,1,4.38933610916138,0,4.1858104467392,,,,,,,,,,,,,,,,,,,,,,,,,,,,,,,,,
,3738622471.96317,6.85669374465942,40000.328125,3.76478829985218E-7,4.06589912035245E-8,1,10,13.2042255401611,3.98041866551035,32.3499999940395,0.000333309745832057,4.39208510969453E-5,1,-5.97677318796056E-9,6.63019275665283,7.08319473266602,40000.328125,40000.328125,50.8863614874862,5.51530630523805,4.18075561523438,132,1,0,0,1,0.238189697265625,30.3030319213867,6,1,1,7.08319473266602,0,6.85669374465942,,,,,,,,,,,,,,,,,,,,,,,,,,,,,,,,,
,3738622531.94697,9.63776159286499,40000.328125,3.6638925121E-7,3.66632056771726E-8,1,10,13.2042255401611,3.98045894803953,32.3400013148785,0.000323080477613237,5.15433986070433E-5,1,4.14512112309413E-9,9.40322494506836,9.87229824066162,40000.328125,40000.328125,50.7491856823611,5.51516972409246,4.62235116958618,132,1,0,0,1,0.24200439453125,31.2805480957031,6,1,1,9.87229824066162,0,9.63776159286499,,,,,,,,,,,,,,,,,,,,,,,,,,,,,,,,,
,3738622591.91604,12.4693202972412,40000.328125,2.15735480346204E-7,3.75001300831249E-8,1,10,13.2042255401611,3.98044363266262,32.3400013148785,0.000193815661591908,6.13818589635082E-6,1,-2.49701449550003E-8,12.2397165298462,12.6989240646362,40000.328125,40000.328125,50.6940808717554,5.51456479779323,4.93769693374634,132,1,0,0,1,0.234909057617187,31.7693061828613,6,1,1,12.6989240646362,0,12.4693202972412,,,,,,,,,,,,,,,,,,,,,,,,,,,,,,,,,
,3738622652.00912,15.4215731620789,40000.328125,2.22835564108756E-7,3.4861528866541E-8,1,10,13.2042255401611,3.98050533410737,32.3400013148785,0.000198977039132325,1.4601291495927E-5,1,-1.64394864263703E-8,15.0999126434326,15.7432336807251,40000.328125,40000.328125,50.6714136446977,5.51469324526932,5.1776385307312,132,1,0,0,1,0.237579345703125,30.7917900085449,6,1,1,15.7432336807251,0,15.4215731620789,,,,,,,,,,,,,,,,,,,,,,,,,,,,,,,,,
,3738622711.89462,18.4825754165649,40000.328125,1.76388985538573E-7,3.36614801252316E-8,1,10,13.2042255401611,3.98047531221521,32.3400013148785,0.000158715497012521,3.35264826070131E-6,1,-2.23022789690522E-8,18.2467365264893,18.7184143066406,40000.328125,40000.328125,50.599894635188,5.51446690088488,5.3337869644165,132,1,0,0,1,0.23162841796875,30.7917900085449,2,1,1,18.7184143066406,0,18.4825754165649,,,,,,,,,,,,,,,,,,,,,,,,,,,,,,,,,
,3738622772.02736,21.3887853622437,40000.328125,1.39064565656502E-7,3.24624027453837E-8,1,10,13.2042255401611,3.980464258955,32.3400013148785,0.000127824994925622,-1.55696160045629E-5,1,-3.82026771112414E-8,21.1437473297119,21.6338233947754,40000.328125,40000.328125,50.604975220563,5.51478308303352,5.47641563415527,132,1,0,0,1,0.236434936523438,30.3030319213867,2,1,1,21.6338233947754,0,21.3887853622437,,,,,,,,,,,,,,,,,,,,,,,,,,,,,,,,,
,3738622831.87381,24.2918605804443,40000.328125,1.27394754773924E-7,2.8615710495652E-8,1,10,13.2042255401611,3.98043992206208,32.3400013148785,0.000113070893878508,1.29499454074833E-5,1,-4.18751839716282E-9,24.0559978485107,24.5277233123779,40000.328125,40000.328125,50.549088781438,5.51436868718621,5.58389282226562,132,1,0,0,1,0.239944458007813,30.7917900085449,2,1,1,24.5277233123779,0,24.2918605804443,,,,,,,,,,,,,,,,,,,,,,,,,,,,,,,,,
,3738622891.91861,27.2109251022339,40000.328125,1.23041751332347E-7,3.1008481737976E-8,1,10,13.2042255401611,3.98042143420555,32.3400013148785,0.000109032303139218,1.36848282799368E-5,1,-2.71134180863189E-9,26.9736938476562,27.4481563568115,40000.328125,40000.328125,50.5057083986207,5.51411208658752,5.67082643508911,132,1,0,0,1,0.234909057617187,31.2805480957031,2,1,1,27.4481563568115,0,27.2109251022339,,,,,,,,,,,,,,,,,,,,,,,,,,,,,,,,,
,3738622951.80854,30.1193618774414,40000.328125,8.9968943773336E-8,3.02340120568216E-8,1,10,13.2042255401611,3.9804377176971,32.3400013148785,7.91547563448537E-5,1.38651099053594E-5,1,2.38601313317036E-9,29.876106262207,30.3626174926758,40000.328125,40000.328125,50.5436173818034,5.51411143905263,5.75375652313232,132,1,0,0,1,0.24261474609375,30.7917900085449,2,1,1,30.3626174926758,0,30.1193618774414,,,,,,,,,,,,,,,,,,,,,,,,,,,,,,,,,
,3738623011.9026,33.0362930297852,40000.328125,7.50088400715834E-8,2.90116528843874E-8,1,10,13.2042255401611,3.98041518230607,32.3400013148785,7.03817951314534E-5,-1.81082563315943E-5,1,-3.15997162824942E-8,32.773380279541,33.2992057800293,40000.328125,40000.328125,50.4920298995342,5.51367988025765,5.82267427444458,132,1,0,0,1,0.235061645507813,29.3255138397217,2,1,1,33.2992057800293,0,33.0362930297852,,,,,,,,,,,,,,,,,,,,,,,,,,,,,,,,,
,3738623071.94581,35.9583377838135,40000.328125,8.7292768184366E-8,2.87210505005248E-8,1,10,13.2042255401611,3.98036040793918,32.3499999940395,7.59816133818147E-5,1.89691262445155E-5,1,8.56120588362974E-9,35.7200241088867,36.1966514587402,40000.328125,40000.328125,50.4892941997169,5.51401285841916,5.88036680221558,132,1,0,0,1,0.23651123046875,30.7917900085449,2,1,1,36.1966514587402,0,35.9583377838135,,,,,,,,,,,,,,,,,,,,,,,,,,,,,,,,,
,3738623131.76469,38.8808250427246,40000.328125,6.20752828602574E-8,2.76342109674587E-8,1,10,13.2042255401611,3.980404938426,32.3400013148785,5.78200363755324E-5,-1.21080425367183E-5,1,-2.28928956128902E-8,38.6453857421875,39.1162643432617,40000.328125,40000.328125,50.5174328264092,5.51404536484728,5.93815231323242,132,1,0,0,1,0.236663818359375,32.2580642700195,2,1,1,39.1162643432617,0,38.8808250427246,,,,,,,,,,,,,,,,,,,,,,,,,,,,,,,,,
,3738623191.70355,41.8033237457275,40000.328125,4.28593781625957E-8,2.80909675272526E-8,1,10,13.2042255401611,3.98034592807001,32.3400013148785,4.20373399025809E-5,-2.26673081478619E-5,1,-3.20053235705345E-8,41.5610237121582,42.0456237792969,40000.328125,40000.328125,50.5248582973419,5.51367525890969,5.97963762283325,132,1,0,0,1,0.235137939453125,31.7693061828613,2,1,1,42.0456237792969,0,41.8033237457275,,,,,,,,,,,,,,,,,,,,,,,,,,,,,,,,,
,3738623251.75243,44.7338466644287,40000.328125,7.52754375070422E-8,3.16625760890064E-8,1,10,13.2042255401611,3.98036188691006,32.3499999940395,6.85898338072764E-5,-4.38035803609754E-6,1,-1.60969375913583E-8,44.4949035644531,44.9727897644043,40000.328125,40000.328125,50.518605269188,5.51380479136612,6.03086948394775,132,1,0,0,1,0.238876342773438,30.7917900085449,2,1,1,44.9727897644043,0,44.7338466644287,,,,,,,,,,,,,,,,,,,,,,,,,,,,,,,,,
,3738623311.82163,47.6747703552246,40000.328125,4.09917350618511E-8,3.00237738032123E-8,1,10,13.2042255401611,3.98037785276271,32.3400013148785,3.45602849168609E-5,1.64782404010362E-5,1,1.25914592342101E-8,47.4294548034668,47.9200859069824,40000.328125,40000.328125,50.4947655993515,5.51432823393257,6.06701040267944,132,1,0,0,1,0.238723754882813,30.7917900085449,2,1,1,47.9200859069824,0,47.6747703552246,,,,,,,,,,,,,,,,,,,,,,,,,,,,,,,,,
,3738623371.64991,50.6052989959717,40000.328125,3.23445109219859E-8,2.76842688985903E-8,1,10,13.2042255401611,3.98036913415624,32.3499999940395,3.03919886428306E-5,-8.10071281135618E-6,1,-1.39571545172246E-8,50.3630142211914,50.847583770752,40000.328125,40000.328125,50.4900758282361,5.51370679981036,6.0999116897583,132,1,0,0,1,0.2386474609375,28.8367557525635,2,1,1,50.847583770752,0,50.6052989959717,,,,,,,,,,,,,,,,,,,,,,,,,,,,,,,,,
,3738623431.61085,53.5471248626709,40000.328125,6.15395925411653E-8,3.30712675790099E-8,1,10,13.2042255401611,3.98037241742336,32.3400013148785,5.52683253417592E-5,1.86546794528922E-6,1,-6.99313913569139E-9,53.2946548461914,53.7995948791504,40000.328125,40000.328125,50.4892941997169,5.51433923516984,6.13858366012573,132,1,0,0,1,0.2349853515625,31.2805480957031,2,1,1,53.7995948791504,0,53.5471248626709,,,,,,,,,,,,,,,,,,,,,,,,,,,,,,,,,
,3738623491.59606,56.4979362487793,40000.328125,1.57151615995306E-9,3.21808186208029E-8,1,10,13.2042255401611,3.9803466153179,32.3400013148785,6.00712171678462E-6,-3.10139014028992E-5,1,-3.5346526333185E-8,56.2583084106445,56.7375640869141,40000.328125,40000.328125,50.4740524435919,5.51377774125931,6.17043399810791,132,1,0,0,1,0.23834228515625,31.2805480957031,2,1,1,56.7375640869141,0,56.4979362487793,,,,,,,,,,,,,,,,,,,,,,,,,,,,,,,,,
,3738623551.58067,59.4436569213867,40000.328125,2.93144353940583E-8,3.27130887419793E-8,1,10,13.2042255401611,3.98038272012057,32.3400013148785,2.83144909461829E-5,-1.25427944315034E-5,1,-1.85380460512633E-8,59.1894721984863,59.6978416442871,40000.328125,40000.328125,50.4994553704669,5.51441111484929,6.19232940673828,131,1,68,0,0,0.239944458007813,31.2805480957031,2,1,1,59.6978416442871,0,59.4436569213867,,,,,,,,,,,,,,,,,,,,,,,,,,,,,,,,,
,3738623611.5736,62.3862361907959,40000.328125,2.71449129567235E-8,3.30577755288885E-8,1,10,13.2042255401611,3.98036888671911,32.3400013148785,2.76210365502311E-5,-2.10916033977652E-5,1,-2.78960236337341E-8,62.1443595886231,62.6281127929688,40000.328125,40000.328125,50.4924207137938,5.5143842234792,6.21367835998535,132,1,0,0,1,0.238189697265625,30.7917900085449,2,1,1,62.6281127929688,0,62.3862361907959,,,,,,,,,,,,,,,,,,,,,,,,,,,,,,,,,
,3738623671.67939,65.3443298339844,40000.328125,-9.04366244436403E-10,3.38799314210012E-8,1,10,13.2042255401611,3.98038493237685,32.3400013148785,-3.79451533662086E-6,2.01291753908323E-5,1,2.29237547033342E-8,65.0962219238281,65.5924377441406,40000.328125,40000.328125,50.4181660044669,5.51459810494227,6.24138259887695,132,1,0,0,1,0.238189697265625,30.7917900085449,2,1,1,65.5924377441406,0,65.3443298339844,,,,,,,,,,,,,,,,,,,,,,,,,,,,,,,,,
,3738623731.68629,68.2963104248047,40000.328125,2.0419354421426E-8,3.09974221699599E-8,1,10,13.2042255401611,3.98044672192378,32.3400013148785,1.77215979574143E-5,4.79213501847942E-6,1,2.40426469965045E-9,68.0646362304687,68.5279846191406,40000.328125,40000.328125,50.5229042260438,5.51441828174151,6.26021289825439,132,1,0,0,1,0.23651123046875,30.3030319213867,2,1,1,68.5279846191406,0,68.2963104248047,,,,,,,,,,,,,,,,,,,,,,,,,,,,,,,,,
,3738623791.52825,71.2388381958008,40000.328125,4.15752765938167E-8,3.27188601955623E-8,1,10,13.2042255401611,3.9803946651377,32.3400013148785,3.62843057228648E-5,8.38754320743319E-6,1,3.34486528492681E-9,70.9915618896484,71.4861145019531,40000.328125,40000.328125,50.5080532841784,5.51404929693575,6.28436899185181,132,1,0,0,1,0.236282348632813,30.7917900085449,2,1,1,71.4861145019531,0,71.2388381958008,,,,,,,,,,,,,,,,,,,,,,,,,,,,,,,,,
,3738623851.55971,74.1959228515625,40000.328125,3.75624788829093E-9,3.42055703577545E-8,1,10,13.2042255401611,3.9803800004397,32.3400013148785,4.36233032910746E-6,-6.56955143197811E-6,1,-7.99372397437402E-9,73.9536056518555,74.4382400512695,40000.328125,40000.328125,50.4361434604092,5.5143627451117,6.29715490341187,132,1,0,0,1,0.241851806640625,30.3030319213867,2,1,1,74.4382400512695,0,74.1959228515625,,,,,,,,,,,,,,,,,,,,,,,,,,,,,,,,,
,3738623911.46853,77.1530647277832,40000.328125,-1.67501573861278E-9,3.38134158494421E-8,1,10,13.2042255401611,3.98034977262861,32.3400013148785,1.91317797553283E-6,-2.31486272908186E-5,1,-2.59610652183752E-8,76.9035720825195,77.4025573730469,40000.328125,40000.328125,50.4756157006303,5.51439139174568,6.31751394271851,132,1,0,0,1,0.235214233398438,30.7917900085449,2,1,1,77.4025573730469,0,77.1530647277832,,,,,,,,,,,,,,,,,,,,,,,,,,,,,,,,,
,3738623971.5387,80.1045112609863,40000.328125,-3.38071152879739E-8,3.82082050482184E-8,1,10,13.2042255401611,3.98037041714412,32.3400013148785,-3.43767001822976E-5,2.61098944989269E-5,1,3.45633937337087E-8,79.871452331543,80.3375701904297,40000.328125,40000.328125,50.4384883459669,5.51418384285517,6.32575416564941,132,1,0,0,1,0.237045288085938,30.7917900085449,2,1,1,80.3375701904297,0,80.1045112609863,,,,,,,,,,,,,,,,,,,,,,,,,,,,,,,,,
,3738624031.42029,83.0424613952637,40000.328125,-3.90664181282053E-8,3.63859739574944E-8,1,10,13.2042255401611,3.98035404661538,32.3400013148785,-2.93866582009605E-5,-3.96980879532401E-5,1,-3.9165987206789E-8,82.7981414794922,83.2867813110352,40000.328125,40000.328125,50.4408332315246,5.51406436593962,6.34976625442505,132,1,0,0,1,0.235748291015625,30.7917900085449,2,1,1,83.2867813110352,0,83.0424613952637,,,,,,,,,,,,,,,,,,,,,,,,,,,,,,,,,
,3738624091.40361,86.0330085754394,40000.328125,1.5978440245539E-8,3.6744283780384E-8,1,10,13.2042255401611,3.98037476871882,32.3400013148785,1.12656648255937E-5,2.13315629020156E-5,1,2.17872513242171E-8,85.7894287109375,86.2765884399414,40000.328125,40000.328125,50.4318445035534,5.51468980733569,6.35537481307983,132,1,0,0,1,0.237045288085938,30.7917900085449,2,1,1,86.2765884399414,0,86.0330085754394,,,,,,,,,,,,,,,,,,,,,,,,,,,,,,,,,
,3738624151.36826,89.0207557678223,40000.328125,-1.27192379560579E-8,3.44241635784689E-8,1,10,13.2042255401611,3.98033970686565,32.3400013148785,-1.38550534579961E-5,1.60525801349462E-5,1,2.00567165739413E-8,88.7697067260742,89.2718048095703,40000.328125,40000.328125,50.4420056743034,5.5142834099989,6.36777591705322,132,1,0,0,1,0.23193359375,30.3030319213867,2,1,1,89.2718048095703,0,89.0207557678223,,,,,,,,,,,,,,,,,,,,,,,,,,,,,,,,,
,3738624211.3542,92.0148582458496,40000.328125,-1.26587904279799E-8,3.73123171786073E-8,1,10,13.2042255401611,3.98032796024145,32.3400013148785,-1.38736643177452E-5,1.65474723757231E-5,1,2.06081809991915E-8,91.7620239257812,92.267692565918,40000.328125,40000.328125,50.4349710176303,5.51421051885652,6.38355875015259,132,1,0,0,1,0.234146118164062,31.2805480957031,2,1,1,92.267692565918,0,92.0148582458496,,,,,,,,,,,,,,,,,,,,,,,,,,,,,,,,,
,3738624271.35409,94.9968795776367,40000.328125,1.8900801811866E-9,3.59953913907644E-8,1,10,13.2042255401611,3.98031123670285,32.3400013148785,-4.67815310082573E-6,4.31481039140451E-5,1,4.85734251888715E-8,94.7461471557617,95.2476119995117,40000.328125,40000.328125,50.4541209163515,5.51450269861194,6.39800548553467,132,1,0,0,1,0.23895263671875,30.3030319213867,2,1,1,95.2476119995117,0,94.9968795776367,,,,,,,,,,,,,,,,,,,,,,,,,,,,,,,,,
,3738624331.40969,97.9632759094238,40000.328125,-1.04544265061958E-8,3.3391285687429E-8,1,10,13.2042255401611,3.98032153212074,32.3400013148785,-5.67286557783361E-6,-2.54323186233943E-5,1,-2.72480150422182E-8,97.7088012695313,98.2177505493164,40000.328125,40000.328125,50.4005793627842,5.51443063778237,6.41195964813232,132,1,0,0,1,0.23895263671875,30.3030319213867,2,1,1,98.2177505493164,0,97.9632759094238,,,,,,,,,,,,,,,,,,,,,,,,,,,,,,,,,
,3738624391.46498,100.960586547852,40000.328125,-1.02400206425559E-8,3.51893774319516E-8,1,10,13.2042255401611,3.98028850730344,32.3400013148785,-1.5160344956348E-5,3.99997052644757E-5,1,4.68038953193265E-8,100.724906921387,101.196266174316,40000.328125,40000.328125,50.4259822896592,5.51439938511881,6.42553377151489,132,1,0,0,1,0.233688354492187,30.7917900085449,2,1,1,101.196266174316,0,100.960586547852,,,,,,,,,,,,,,,,,,,,,,,,,,,,,,,,,
,3738624451.29358,103.952709197998,40000.328125,5.14530289501719E-9,3.28422853778227E-8,1,10,13.2042255401611,3.98028052519422,32.3499999940395,6.78989119014787E-6,-1.4504370866344E-5,1,-1.71836003583943E-8,103.71280670166,104.192611694336,40000.328125,40000.328125,50.4556841733899,5.51474493132125,6.43676090240478,132,1,0,0,1,0.242233276367187,30.7917900085449,2,1,1,104.192611694336,0,103.952709197998,,,,,,,,,,,,,,,,,,,,,,,,,,,,,,,,,
,3738624511.22502,106.926151275635,40000.328125,3.73239091071763E-9,3.24332611383948E-8,1,10,13.2042255401611,3.98034147547122,32.3400013148785,1.6930771886891E-6,1.1325315507989E-5,1,1.22703416538906E-8,106.679183959961,107.173118591309,40000.328125,40000.328125,50.3634520081207,5.51468996155991,6.44717502593994,132,1,0,0,1,0.23956298828125,30.7917900085449,2,1,1,107.173118591309,0,106.926151275635,,,,,,,,,,,,,,,,,,,,,,,,,,,,,,,,,
,3738624571.29424,109.913951873779,40000.328125,-3.26717293475257E-8,3.23634849842316E-8,1,10,13.2042255401611,3.98036180231091,32.3499999940395,-3.03092397018074E-5,5.54589932293008E-6,1,1.11130477225388E-8,109.666648864746,110.161254882813,40000.328125,40000.328125,50.4431781170823,5.51472075727818,6.46159601211548,132,1,0,0,1,0.238037109375,30.7917900085449,2,1,1,110.161254882813,0,109.913951873779,,,,,,,,,,,,,,,,,,,,,,,,,,,,,,,,,
,3738624631.34365,112.933437347412,40000.328125,8.8254472180525E-9,2.74763691464243E-8,1,10,13.2042255401611,3.98030698132805,32.3400013148785,3.28991437839307E-6,3.16006876914493E-5,1,3.4473154593219E-8,112.688377380371,113.178497314453,40000.328125,40000.328125,50.4416148600438,5.51468962980837,6.4695725440979,132,1,0,0,1,0.230484008789062,30.7917900085449,2,1,1,113.178497314453,0,112.933437347412,,,,,,,,,,,,,,,,,,,,,,,,,,,,,,,,,
,3738624691.21023,115.888786315918,40000.328125,-5.09457162951684E-8,3.28573780753036E-8,1,10,13.2042255401611,3.98054230745147,32.3400013148785,-5.125398494742E-5,3.56071539913333E-5,1,4.78491006994938E-8,115.644187927246,116.13338470459,40000.328125,40000.328125,50.5459622673611,5.51302745851293,6.47440195083618,132,1,0,0,1,0.238265991210938,31.2805480957031,2,1,1,116.13338470459,0,115.888786315918,,,,,,,,,,,,,,,,,,,,,,,,,,,,,,,,,
,3738624751.19971,118.881446838379,40000.328125,-2.25866810296769E-8,3.06500861535452E-8,1,10,13.2042255401611,3.98037801966559,32.3400013148785,-1.99421754996816E-5,-3.0017585764894E-6,1,-5.67008400767652E-11,118.634506225586,119.128387451172,40000.328125,40000.328125,50.5760549653515,5.51267431195867,6.48393106460571,132,1,0,0,1,0.23895263671875,30.7917900085449,2,1,1,119.128387451172,0,118.881446838379,,,,,,,,,,,,,,,,,,,,,,,,,,,,,,,,,
,3738624811.11911,121.875503540039,40000.328125,-2.74310575279503E-8,2.40231549561719E-8,1,10,13.2042255401611,3.9802178287247,32.3400013148785,-2.40029258176169E-5,-5.09763043907761E-6,1,-1.71323440028063E-9,121.634201049805,122.116806030273,40000.328125,40000.328125,50.4533392878323,5.51536091043801,6.49936151504517,132,1,0,0,1,0.242156982421875,30.7917900085449,2,1,1,122.116806030273,0,121.875503540039,,,,,,,,,,,,,,,,,,,,,,,,,,,,,,,,,
,3738624871.21427,124.865962982178,40000.328125,-3.09913342627063E-8,2.92213798131422E-8,1,10,13.2042255401611,3.98021105916122,32.3400013148785,-3.06869512956894E-5,1.8361036952733E-5,1,2.53749197139791E-8,124.632514953613,125.099411010742,40000.328125,40000.328125,50.4568566161688,5.51699391658511,6.50032901763916,132,1,0,0,1,0.239105224609375,30.7917900085449,2,1,1,125.099411010742,0,124.865962982178,,,,,,,,,,,,,,,,,,,,,,,,,,,,,,,,,
,3738624931.07474,127.838203430176,40000.328125,-2.72294897264471E-8,2.80044742498512E-8,1,10,13.2042255401611,3.98020105749329,32.3400013148785,-2.78952321148352E-5,2.24400694596028E-5,1,2.94369723929592E-8,127.596862792969,128.079544067383,40000.328125,40000.328125,50.5131338695534,5.51614580989764,6.51636075973511,132,1,0,0,1,0.237274169921875,30.7917900085449,2,1,1,128.079544067383,0,127.838203430176,,,,,,,,,,,,,,,,,,,,,,,,,,,,,,,,,
,3738624991.26963,130.855926513672,40000.328125,-7.97632340022065E-9,2.66044767747387E-8,1,10,13.2042255401611,3.9802851128146,32.3400013148785,-8.67052315686094E-6,9.94556733715344E-6,1,1.24408237729605E-8,130.600006103516,131.111846923828,40000.328125,40000.328125,50.4595923159861,5.51582164962067,6.51715087890625,132,1,0,0,1,0.238265991210938,30.7917900085449,2,1,1,131.111846923828,0,130.855926513672,,,,,,,,,,,,,,,,,,,,,,,,,,,,,,,,,
,3738625051.05214,133.824287414551,40000.328125,-1.9714403689739E-8,3.14010255034622E-8,1,10,13.2042255401611,3.98029581488988,32.3400013148785,-2.22131226994775E-5,2.98726716502517E-5,1,3.67394778843458E-8,133.584274291992,134.064300537109,40000.328125,40000.328125,50.4400516030053,5.5158102208587,6.52480030059814,132,1,0,0,1,0.229873657226562,30.3030319213867,2,1,1,134.064300537109,0,133.824287414551,,,,,,,,,,,,,,,,,,,,,,,,,,,,,,,,,
,3738625111.04348,136.807426452637,40000.328125,-5.76094661864428E-8,3.04583603609473E-8,1,10,13.2042255401611,3.98024087568831,32.3400013148785,-5.39510534077741E-5,1.32249016189247E-5,1,2.34976147113989E-8,136.56298828125,137.051864624023,40000.328125,40000.328125,50.4298904322553,5.5161542437165,6.53836393356323,132,1,0,0,1,0.23834228515625,31.2805480957031,2,1,1,137.051864624023,0,136.807426452637,,,,,,,,,,,,,,,,,,,,,,,,,,,,,,,,,
,3738625170.9987,139.81324005127,40000.328125,-1.48821764249134E-8,2.74690920943505E-8,1,10,13.2042255401611,3.98023598089264,32.3400013148785,-1.70235298397926E-5,2.42768631760104E-5,1,2.96894608837264E-8,139.570129394531,140.056350708008,40000.328125,40000.328125,50.467799415438,5.51617440945993,6.54831266403198,132,1,0,0,1,0.242767333984375,31.2805480957031,2,1,1,140.056350708008,0,139.81324005127,,,,,,,,,,,,,,,,,,,,,,,,,,,,,,,,,
,3738625231.11107,142.821411132812,40000.328125,-1.10603082725758E-8,3.00273869414481E-8,1,10,13.2042255401611,3.98027786340866,32.3400013148785,-1.28486485331056E-5,1.93720489447838E-5,1,2.35701318382988E-8,142.559204101562,143.083618164062,40000.328125,40000.328125,50.4412240457842,5.51595499226414,6.54897975921631,132,1,0,0,1,0.233535766601562,30.3030319213867,2,1,1,143.083618164062,0,142.821411132812,,,,,,,,,,,,,,,,,,,,,,,,,,,,,,,,,
,3738625291.14461,145.794097900391,40000.328125,-3.28917407396757E-8,2.89339620444996E-8,1,10,13.2042255401611,3.98029355424057,32.3400013148785,-3.16647989130193E-5,1.33711269764165E-5,1,2.00057013452267E-8,145.560241699219,146.027954101562,40000.328125,40000.328125,50.4420056743034,5.51611592258873,6.55983686447144,132,1,0,0,1,0.235366821289062,30.7917900085449,2,1,1,146.027954101562,0,145.794097900391,,,,,,,,,,,,,,,,,,,,,,,,,,,,,,,,,
,3738625350.94521,148.78296661377,40000.328125,-2.17101744389354E-8,3.17614390902914E-8,1,10,13.2042255401611,3.98026391115498,32.3400013148785,-1.91225250720047E-5,-3.18853236910414E-6,1,-3.98014465590304E-10,148.536560058594,149.029373168945,40000.328125,40000.328125,50.4455230026399,5.51580328092422,6.56358575820923,132,1,0,0,1,0.2337646484375,30.7917900085449,2,1,1,149.029373168945,0,148.78296661377,,,,,,,,,,,,,,,,,,,,,,,,,,,,,,,,,
,3738625410.94746,151.769905090332,40000.328125,-4.90219481907642E-8,3.29103738453262E-8,1,10,13.2042255401611,3.9802577542385,32.3400013148785,-4.5275239931345E-5,6.96895102155002E-6,1,1.51436768390811E-8,151.514175415039,152.025634765625,40000.328125,40000.328125,50.4670177869188,5.51595665554515,6.56990671157837,132,1,0,0,1,0.233154296875,31.2805480957031,2,1,1,152.025634765625,0,151.769905090332,,,,,,,,,,,,,,,,,,,,,,,,,,,,,,,,,
,3738625470.90838,154.748039245605,40000.328125,-2.68477980752252E-8,3.25053255154609E-8,1,10,13.2042255401611,3.98025892121364,32.3400013148785,-2.52534613742217E-5,6.90952333409922E-6,1,1.17955691910046E-8,154.495162963867,155.000915527344,40000.328125,40000.328125,50.4494311452361,5.51598778929087,6.57628631591797,132,1,0,0,1,0.230026245117187,30.7917900085449,2,1,1,155.000915527344,0,154.748039245605,,,,,,,,,,,,,,,,,,,,,,,,,,,,,,,,,
,3738625530.98527,157.762229919434,40000.328125,-2.4527874561283E-8,3.35893853251514E-8,1,10,13.2042255401611,3.980291205044,32.3400013148785,-2.258505935602E-5,3.02412991349896E-6,1,7.05307003197139E-9,157.523986816406,158.000473022461,40000.328125,40000.328125,50.4216833328034,5.5159799764975,6.58587265014648,132,1,0,0,1,0.233688354492187,30.7917900085449,2,1,1,158.000473022461,0,157.762229919434,,,,,,,,,,,,,,,,,,,,,,,,,,,,,,,,,
,3738625590.85122,160.719261169434,40000.328125,-3.39481145907155E-8,3.10120642914053E-8,1,10,13.2042255401611,3.98031885268692,32.3400013148785,-3.24281613884653E-5,1.20844052572788E-5,1,1.87049997924693E-8,160.468383789062,160.970138549805,40000.328125,40000.328125,50.4037058768611,5.51563812398045,6.59274625778198,132,1,0,0,1,0.239410400390625,31.2805480957031,2,1,1,160.970138549805,0,160.719261169434,,,,,,,,,,,,,,,,,,,,,,,,,,,,,,,,,
,3738625650.9884,163.719192504883,40000.328125,-1.42031316877399E-8,3.26847389574655E-8,1,10,13.2042255401611,3.98028256375143,32.3400013148785,-1.19234206078666E-5,-6.05286591117579E-6,1,-4.75179419772006E-9,163.463745117187,163.974639892578,40000.328125,40000.328125,50.3708774790534,5.51615576795818,6.59921073913574,132,1,0,0,1,0.233001708984375,31.2805480957031,2,1,1,163.974639892578,0,163.719192504883,,,,,,,,,,,,,,,,,,,,,,,,,,,,,,,,,
,3738625710.84505,166.714134216309,40000.328125,-4.74895208861704E-8,2.94659601816147E-8,1,10,13.2042255401611,3.9802575451169,32.3499999940395,-4.25991612905043E-5,-1.77009864600663E-6,1,5.02221855086286E-9,166.472534179687,166.95573425293,40000.328125,40000.328125,50.4298904322553,5.51592548325275,6.60110330581665,132,1,0,0,1,0.239791870117187,30.7917900085449,2,1,1,166.95573425293,0,166.714134216309,,,,,,,,,,,,,,,,,,,,,,,,,,,,,,,,,
,3738625770.85301,169.69522857666,40000.328125,-2.77862416594391E-8,3.04362513691407E-8,1,10,13.2042255401611,3.98029518049093,32.3400013148785,-2.83389620873207E-5,2.2036601405335E-5,1,2.90615704101859E-8,169.439025878906,169.951431274414,40000.328125,40000.328125,50.4173843759476,5.51560853472972,6.6054048538208,132,1,0,0,1,0.23406982421875,31.2805480957031,2,1,1,169.951431274414,0,169.69522857666,,,,,,,,,,,,,,,,,,,,,,,,,,,,,,,,,
,3738625830.81486,172.685348510742,40000.328125,-4.69858552940206E-8,3.21031292439346E-8,1,10,13.2042255401611,3.98030672896943,32.3400013148785,-4.46636723075051E-5,1.52500687876455E-5,1,2.42183183217466E-8,172.43669128418,172.934005737305,40000.328125,40000.328125,50.3927630775919,5.51536621009047,6.61125040054321,132,1,0,0,1,0.236358642578125,30.3030319213867,2,1,1,172.934005737305,0,172.685348510742,,,,,,,,,,,,,,,,,,,,,,,,,,,,,,,,,
,3738625890.73938,175.670715332031,40000.328125,-2.13362182624783E-8,3.11026827798643E-8,1,10,13.2042255401611,3.98036472544604,32.3400013148785,-1.98319858949966E-5,3.88239022057656E-6,1,7.55245873635591E-9,175.426391601562,175.9150390625,40000.328125,40000.328125,50.4388791602265,5.51529939012944,6.61438369750977,132,1,0,0,1,0.231475830078125,31.7693061828613,2,1,1,175.9150390625,0,175.670715332031,,,,,,,,,,,,,,,,,,,,,,,,,,,,,,,,,
,3738625950.88675,178.697738647461,40000.328125,-7.92948142262638E-9,3.20185294922688E-8,1,10,13.2042255401611,3.98033743796343,32.3400013148785,-9.0870052760633E-6,1.30451793626468E-5,1,1.59430572938055E-8,178.460723876953,178.934753417969,40000.328125,40000.328125,50.4228557755823,5.51540929335287,6.62145233154297,132,1,0,0,1,0.236282348632813,30.3030319213867,2,1,1,178.934753417969,0,178.697738647461,,,,,,,,,,,,,,,,,,,,,,,,,,,,,,,,,
,3738626010.73229,181.657386779785,40000.328125,-1.94425209559747E-8,3.50753912793852E-8,1,10,13.2042255401611,3.9803284508223,32.3400013148785,-1.86844628072637E-5,7.68037841720336E-6,1,1.15724595229792E-8,181.408050537109,181.906723022461,40000.328125,40000.328125,50.4509944022746,5.51560495673756,6.63106155395508,132,1,0,0,1,0.234146118164062,31.7693061828613,2,1,1,181.906723022461,0,181.657386779785,,,,,,,,,,,,,,,,,,,,,,,,,,,,,,,,,
,3738626070.70517,184.657379150391,40000.328125,-3.43771711687142E-8,3.50481079462235E-8,1,10,13.2042255401611,3.98030096996955,32.3400013148785,-3.93870578288364E-5,5.65018834903101E-5,1,6.90590716577043E-8,184.407135009766,184.907623291016,40000.328125,40000.328125,50.4236374041015,5.5153289604205,6.63384485244751,132,1,0,0,1,0.235824584960938,31.2805480957031,2,1,1,184.907623291016,0,184.657379150391,,,,,,,,,,,,,,,,,,,,,,,,,,,,,,,,,
,3738626130.64927,187.638549804687,40000.328125,-6.35473123362588E-9,3.9271291317804E-8,1,10,13.2042255401611,3.98033595105782,32.3400013148785,-8.21941959719297E-6,1.67877163166884E-5,1,1.9947398037034E-8,187.391326904297,187.885772705078,40000.328125,40000.328125,50.4642820871015,5.5154018782885,6.63715076446533,132,1,0,0,1,0.231170654296875,31.2805480957031,2,1,1,187.885772705078,0,187.638549804687,,,,,,,,,,,,,,,,,,,,,,,,,,,,,,,,,
,3738626190.72012,190.63761138916,40000.328125,2.91630012440257E-8,3.95017539914719E-8,1,10,13.2042255401611,3.98031833935602,32.3400013148785,2.17546252273755E-5,3.08651543371802E-5,1,3.06311289653686E-8,190.394332885742,190.880889892578,40000.328125,40000.328125,50.41503949039,5.51527594138643,6.65071868896484,132,1,0,0,1,0.2325439453125,31.2805480957031,2,1,1,190.880889892578,0,190.63761138916,,,,,,,,,,,,,,,,,,,,,,,,,,,,,,,,,
,3738626250.66258,193.622779846191,40000.328125,-1.27571636489329E-8,3.70384555432038E-8,1,10,13.2042255401611,3.9803067115192,32.3400013148785,-1.28451833357173E-5,8.99682006666486E-6,1,1.20738931391984E-8,193.371383666992,193.874176025391,40000.328125,40000.328125,50.4126946048323,5.5155778525498,6.64934015274048,132,1,0,0,1,0.232391357421875,32.2580642700195,2,1,1,193.874176025391,0,193.622779846191,,,,,,,,,,,,,,,,,,,,,,,,,,,,,,,,,
,3738626310.7535,196.619041442871,40000.328125,1.85443692078157E-8,3.97484622732683E-8,1,10,13.2042255401611,3.98030741255919,32.3400013148785,1.17079954646354E-5,3.39918216796475E-5,1,3.57424572705427E-8,196.365859985352,196.872222900391,40000.328125,40000.328125,50.4701443009957,5.51607510772229,6.66215801239014,132,1,0,0,1,0.2337646484375,31.2805480957031,2,1,1,196.872222900391,0,196.619041442871,,,,,,,,,,,,,,,,,,,,,,,,,,,,,,,,,
,3738626370.57666,199.593391418457,40000.328125,7.56849453475736E-9,3.7636106434692E-8,1,10,13.2042255401611,3.98032065492807,32.3400013148785,2.18405029520453E-6,3.14076077960752E-5,1,3.44403251185349E-8,199.349090576172,199.837692260742,40000.328125,40000.328125,50.3798662070246,5.51547830642964,6.66651201248169,132,1,0,0,1,0.2374267578125,31.7693061828613,2,1,1,199.837692260742,0,199.593391418457,,,,,,,,,,,,,,,,,,,,,,,,,,,,,,,,,
,3738626430.54288,202.604804992676,40000.328125,3.05569488773192E-9,3.67310416358924E-8,1,10,13.2042255401611,3.98031291433674,32.3400013148785,1.11000045317263E-6,1.1137971567601E-5,1,1.21584964268221E-8,202.352294921875,202.857315063477,40000.328125,40000.328125,50.4623280158034,5.51543131259567,6.66941547393799,132,1,0,0,1,0.2349853515625,30.7917900085449,2,1,1,202.857315063477,0,202.604804992676,,,,,,,,,,,,,,,,,,,,,,,,,,,,,,,,,
,3738626490.64894,205.616363525391,40000.328125,-4.46124837148197E-8,3.41862194867505E-8,1,10,13.2042255401611,3.98029132239755,32.3400013148785,-3.58285102469736E-5,-2.99848388965094E-5,1,-2.73489340590443E-8,205.372970581055,205.859756469727,40000.328125,40000.328125,50.4345802033707,5.51621168943878,6.67527198791504,132,1,0,0,1,0.234527587890625,31.7693061828613,2,1,1,205.859756469727,0,205.616363525391,,,,,,,,,,,,,,,,,,,,,,,,,,,,,,,,,
,3738626550.6458,208.590950012207,40000.328125,-5.43601050720826E-8,3.28722863461215E-8,1,10,13.2042255401611,3.98029135740314,32.3400013148785,-4.73744678461558E-5,-1.14101894951765E-5,1,-4.87597923236015E-9,208.340896606445,208.841003417969,40000.328125,40000.328125,50.4924207137938,5.51511001472868,6.68556547164917,132,1,0,0,1,0.236282348632813,31.7693061828613,2,1,1,208.841003417969,0,208.590950012207,,,,,,,,,,,,,,,,,,,,,,,,,,,,,,,,,
,3738626610.65993,211.588417053223,40000.328125,-2.66360934928719E-8,3.4352237109711E-8,1,10,13.2042255401611,3.98033356072346,32.3400013148785,-2.60680235674279E-5,1.37014561495008E-5,1,1.94538936660566E-8,211.346389770508,211.830444335938,40000.328125,40000.328125,50.4529484735726,5.51540261480759,6.68797063827515,132,1,0,0,1,0.233840942382813,30.7917900085449,2,1,1,211.830444335938,0,211.588417053223,,,,,,,,,,,,,,,,,,,,,,,,,,,,,,,,,
,3738626670.48993,214.571853637695,40000.328125,-1.26092390586122E-8,3.15664077104256E-8,1,10,13.2042255401611,3.98038306785906,32.3400013148785,-1.1970818323402E-5,3.98722514616335E-6,1,6.37990260476094E-9,214.321136474609,214.822570800781,40000.328125,40000.328125,50.386510049438,5.51532001121097,6.69267845153809,132,1,0,0,1,0.235671997070313,29.3255138397217,2,1,1,214.822570800781,0,214.571853637695,,,,,,,,,,,,,,,,,,,,,,,,,,,,,,,,,
,3738626730.45679,217.547180175781,40000.328125,-3.44821394914263E-8,3.30911448081489E-8,1,10,13.2042255401611,3.98034923282926,32.3400013148785,-2.98746055125262E-5,-8.43458223424148E-6,1,-4.44777439953997E-9,217.300994873047,217.793365478516,40000.328125,40000.328125,50.4650637156207,5.51520369458984,6.70706558227539,132,1,0,0,1,0.233001708984375,30.7917900085449,2,1,1,217.793365478516,0,217.547180175781,,,,,,,,,,,,,,,,,,,,,,,,,,,,,,,,,
,3738626790.42604,220.551773071289,40000.328125,-2.69744631931088E-8,3.14389276284435E-8,1,10,13.2042255401611,3.98036910921582,32.3400013148785,-2.50906447399021E-5,5.02915111809712E-6,1,9.68502153205284E-9,220.305374145508,220.79817199707,40000.328125,40000.328125,50.4775697719284,5.51581005117802,6.71867752075195,132,1,0,0,1,0.234222412109375,30.7917900085449,2,1,1,220.79817199707,0,220.551773071289,,,,,,,,,,,,,,,,,,,,,,,,,,,,,,,,,
,3738626850.55642,223.545227050781,40000.328125,-1.99690567444706E-8,3.41636092767327E-8,1,10,13.2042255401611,3.98035551026848,32.3400013148785,-2.31271705810798E-5,3.44941436323763E-5,1,4.20087671726298E-8,223.308395385742,223.78205871582,40000.328125,40000.328125,50.4052691338996,5.51531823238478,6.72844314575195,132,1,0,0,1,0.235748291015625,31.7693061828613,2,1,1,223.78205871582,0,223.545227050781,,,,,,,,,,,,,,,,,,,,,,,,,,,,,,,,,
,3738626910.38335,226.522933959961,40000.328125,-7.41848131927068E-9,3.09733418839503E-8,1,10,13.2042255401611,3.980372685018,32.3400013148785,-6.07792451732289E-6,-4.17581524296522E-6,1,-3.630202894376E-9,226.280075073242,226.76579284668,40000.328125,40000.328125,50.432235317813,5.5154861500443,6.73778772354126,132,1,0,0,1,0.235977172851562,32.2580642700195,2,1,1,226.76579284668,0,226.522933959961,,,,,,,,,,,,,,,,,,,,,,,,,,,,,,,,,
,3738626970.39476,229.521560668945,40000.328125,-1.21634707788023E-8,2.9001351500771E-8,1,10,13.2042255401611,3.98033121578953,32.3400013148785,-1.20214626815692E-5,7.05038637915405E-6,1,9.78218169741718E-9,229.28190612793,229.761215209961,40000.328125,40000.328125,50.4123037905726,5.51537441178609,6.74841690063477,132,1,0,0,1,0.234603881835938,30.3030319213867,2,1,1,229.761215209961,0,229.521560668945,,,,,,,,,,,,,,,,,,,,,,,,,,,,,,,,,
,3738627030.33917,232.526084899902,40000.328125,-3.10149722715572E-8,3.18768733488987E-8,1,10,13.2042255401611,3.9803549497082,32.3400013148785,-2.79957535598935E-5,1.68440620198574E-8,1,4.60794844307214E-9,232.286636352539,232.765533447266,40000.328125,40000.328125,50.4244190326207,5.5153060818556,6.75629186630249,132,1,0,0,1,0.23681640625,31.2805480957031,2,1,1,232.765533447266,0,232.526084899902,,,,,,,,,,,,,,,,,,,,,,,,,,,,,,,,,
,3738627090.43571,235.510070800781,40000.328125,-3.08233051453701E-8,3.03774776058438E-8,1,10,13.2042255401611,3.98034925805461,32.3400013148785,-3.01878563613115E-5,1.60023145207084E-5,1,2.26783568490701E-8,235.270523071289,235.749618530273,40000.328125,40000.328125,50.4212925185438,5.51563594215906,6.7758731842041,132,1,0,0,1,0.235977172851562,31.7693061828613,2,1,1,235.749618530273,0,235.510070800781,,,,,,,,,,,,,,,,,,,,,,,,,,,,,,,,,
,3738627150.31055,238.509696960449,40000.328125,-3.79789912992061E-8,2.81913588789485E-8,1,10,13.2042255401611,3.98031681953693,32.3400013148785,-3.57369982538601E-5,9.8591556814562E-6,1,1.67819440071742E-8,238.270263671875,238.749130249023,40000.328125,40000.328125,50.422074147063,5.51562069342327,6.79319953918457,132,1,0,0,1,0.237808227539062,32.7468223571777,2,1,1,238.749130249023,0,238.509696960449,,,,,,,,,,,,,,,,,,,,,,,,,,,,,,,,,
,3738627210.43449,241.495872497559,40000.328125,-5.00303548542106E-8,3.04574394100169E-8,1,10,13.2042255401611,3.98035413507362,32.3400013148785,-4.62656441923612E-5,7.49972718725672E-6,1,1.58935162920806E-8,241.244369506836,241.747375488281,40000.328125,40000.328125,50.4294996179957,5.51532747062451,6.8113865852356,132,1,0,0,1,0.233993530273438,31.2805480957031,2,1,1,241.747375488281,0,241.495872497559,,,,,,,,,,,,,,,,,,,,,,,,,,,,,,,,,
,3738627270.25527,244.478485107422,40000.328125,-3.02038258345852E-8,2.93333674214727E-8,1,10,13.2042255401611,3.98032692580218,32.3400013148785,-2.648785450236E-5,-5.22437185123102E-6,1,-1.44622951920782E-9,244.225982666016,244.730987548828,40000.328125,40000.328125,50.3826019068419,5.51552044710642,6.83563375473022,132,1,0,0,1,0.23956298828125,31.7693061828613,2,1,1,244.730987548828,0,244.478485107422,,,,,,,,,,,,,,,,,,,,,,,,,,,,,,,,,
,3738627330.28804,247.482780456543,40000.328125,-8.9777065249098E-8,3.50578232476348E-8,1,10,13.2042255401611,3.98057313009023,32.3400013148785,-7.75346774229566E-5,-2.36740177178735E-5,1,-1.35182070104432E-8,247.239318847656,247.72624206543,40000.328125,40000.328125,50.5686294944188,5.51469470368049,6.86747932434082,132,1,0,0,1,0.234222412109375,31.2805480957031,2,1,1,247.72624206543,0,247.482780456543,,,,,,,,,,,,,,,,,,,,,,,,,,,,,,,,,
,3738627390.24911,250.451560974121,40000.328125,-6.02312684229568E-8,3.30601106500867E-8,1,10,13.2042255401611,3.98043970132375,32.3400013148785,-5.79663289311751E-5,2.43408239596397E-5,1,3.64693349541782E-8,250.204254150391,250.698867797852,40000.328125,40000.328125,50.4904666424957,5.51376433056124,6.90385341644287,132,1,0,0,1,0.23284912109375,30.7917900085449,2,1,1,250.698867797852,0,250.451560974121,,,,,,,,,,,,,,,,,,,,,,,,,,,,,,,,,
,3738627450.29758,253.457679748535,40000.328125,-6.78136938238798E-8,3.50155129491737E-8,1,10,13.2042255401611,3.98043730937327,32.3499999940395,-6.3133257025315E-5,1.30068793251925E-5,1,2.47593826309719E-8,253.203521728516,253.711837768555,40000.328125,40000.328125,50.462718830063,5.51494336587303,6.94997406005859,132,1,0,0,1,0.238037109375,31.2805480957031,2,1,1,253.711837768555,0,253.457679748535,,,,,,,,,,,,,,,,,,,,,,,,,,,,,,,,,
,3738627510.32057,256.449737548828,40000.328125,-4.9979656983874E-8,3.34402276122663E-8,1,10,13.2042255401611,3.98031456825088,32.3400013148785,-4.91647285264551E-5,2.74079609191672E-5,1,3.84265877240461E-8,256.214599609375,256.684875488281,40000.328125,40000.328125,50.4341893891111,5.51428515825452,7.00364017486572,132,1,0,0,1,0.241622924804687,30.7917900085449,2,1,1,256.684875488281,0,256.449737548828,,,,,,,,,,,,,,,,,,,,,,,,,,,,,,,,,
,3738627570.14349,259.455780029297,40000.328125,-5.99710568388349E-8,3.00513568133104E-8,1,10,13.2042255401611,3.98027267113287,32.3400013148785,-5.87096232436673E-5,3.0976493095953E-5,1,4.39458261150712E-8,259.215881347656,259.695678710938,40000.328125,40000.328125,50.4037058768611,5.51425244217112,7.05379962921143,132,1,0,0,1,0.240097045898438,32.7468223571777,2,1,1,259.695678710938,0,259.455780029297,,,,,,,,,,,,,,,,,,,,,,,,,,,,,,,,,
,3738627630.1275,262.438659667969,40000.328125,-8.41354130977446E-8,3.29638043383999E-8,1,10,13.2042255401611,3.9803949996963,32.3400013148785,-7.72017650779594E-5,8.53108734510433E-6,1,2.21071395957144E-8,262.190124511719,262.687194824219,40000.328125,40000.328125,50.4431781170823,5.51688428065394,7.01072597503662,132,1,0,0,1,0.240325927734375,31.2805480957031,2,1,1,262.687194824219,0,262.438659667969,,,,,,,,,,,,,,,,,,,,,,,,,,,,,,,,,
,3738627690.1124,265.444854736328,40000.328125,-6.15600796131308E-8,3.37789363250133E-8,1,10,13.2042255401611,3.98033000124654,32.3400013148785,-5.85811921031E-5,2.04067143676823E-5,1,3.22129181042282E-8,265.198181152344,265.691528320313,40000.328125,40000.328125,50.477960586188,5.51737116394471,6.98468399047852,132,1,0,0,1,0.2398681640625,31.2805480957031,2,1,1,265.691528320313,0,265.444854736328,,,,,,,,,,,,,,,,,,,,,,,,,,,,,,,,,
,3738627750.19793,268.408874511719,40000.328125,-5.33507908295324E-8,3.69997325164537E-8,1,10,13.2042255401611,3.98040236642122,32.3400013148785,-5.07540911342998E-5,1.75741580227724E-5,1,2.77906712500616E-8,268.166534423828,268.651214599609,40000.328125,40000.328125,50.5322837682746,5.51676844730747,6.97130489349365,132,1,0,0,1,0.23162841796875,30.7917900085449,2,1,1,268.651214599609,0,268.408874511719,,,,,,,,,,,,,,,,,,,,,,,,,,,,,,,,,
,3738627810.07631,271.418334960938,40000.328125,-1.02901824686619E-7,3.83238763484332E-8,1,10,13.2042255401611,3.98034666123978,32.3400013148785,-8.94026094302123E-5,-2.34760310227991E-5,1,-1.13545853508774E-8,271.161376953125,271.67529296875,40000.328125,40000.328125,50.5018002560246,5.51460603840377,6.96182823181152,132,1,0,0,1,0.230484008789062,30.7917900085449,2,1,1,271.67529296875,0,271.418334960938,,,,,,,,,,,,,,,,,,,,,,,,,,,,,,,,,
,3738627870.21111,274.408142089844,40000.328125,-8.2118119297552E-8,3.69420544104682E-8,1,10,13.2042255401611,3.98046908503679,32.3400013148785,-6.79301047217565E-5,-4.18422622451855E-5,1,-3.5221636490651E-8,274.147674560547,274.668609619141,40000.328125,40000.328125,50.5447898245823,5.51500263852081,6.97050857543945,132,1,0,0,1,0.234527587890625,31.2805480957031,2,1,1,274.668609619141,0,274.408142089844,,,,,,,,,,,,,,,,,,,,,,,,,,,,,,,,,
,3738627930.03724,277.388793945313,40000.328125,-9.80623295793658E-8,3.69413226126036E-8,1,10,13.2042255401611,3.98047644027599,32.3400013148785,-8.54595659144908E-5,-2.06351718591184E-5,1,-8.85297714080983E-9,277.141204833984,277.636383056641,40000.328125,40000.328125,50.5096165412169,5.51534926403767,6.98402261734009,132,1,0,0,1,0.236358642578125,30.3030319213867,2,1,1,277.636383056641,0,277.388793945313,,,,,,,,,,,,,,,,,,,,,,,,,,,,,,,,,
,3738627990.00408,280.389862060547,40000.328125,-9.97621819721303E-8,3.40378523075664E-8,1,10,13.2042255401611,3.98050054851186,32.3400013148785,-8.67425649565531E-5,-2.23396388109568E-5,1,-1.05309282563411E-8,280.148498535156,280.631225585938,40000.328125,40000.328125,50.4928115280534,5.5147654037755,7.02536344528198,132,1,0,0,1,0.235748291015625,30.7917900085449,2,1,1,280.646942138672,0,280.389862060547,,,,,,,,,,,,,,,,,,,,,,,,,,,,,,,,,
,3738628049.97204,283.385696411133,40000.328125,-1.04617204790722E-7,3.81855047639436E-8,1,10,13.2042255401611,3.98051862789303,32.3400013148785,-9.14132144426754E-5,-2.03951691034748E-5,1,-7.61102979528767E-9,283.130493164062,283.640899658203,40000.328125,40000.328125,50.4775697719284,5.51528243981102,7.08002090454102,132,1,0,0,1,0.240554809570313,31.2805480957031,2,1,1,283.640899658203,0,283.385696411133,,,,,,,,,,,,,,,,,,,,,,,,,,,,,,,,,
,3738628110.13957,286.371948242187,40000.328125,-8.07343165247013E-8,3.63959951373913E-8,1,10,13.2042255401611,3.98053620853721,32.3400013148785,-6.84068987438935E-5,-3.01910987683642E-5,1,-2.22346332447012E-8,286.117340087891,286.626556396484,40000.328125,40000.328125,50.4869493141592,5.51590359757531,7.1567850112915,132,1,0,0,1,0.234832763671875,29.3255138397217,2,1,1,286.626556396484,0,286.371948242187,,,,,,,,,,,,,,,,,,,,,,,,,,,,,,,,,
,3738628169.93715,289.340545654297,40000.328125,-8.12612365464168E-8,3.5987197177893E-8,1,10,13.2042255401611,3.98053136378088,32.3400013148785,-6.79905588769683E-5,-3.62186352709698E-5,1,-2.89806225968609E-8,289.090972900391,289.590118408203,40000.328125,40000.328125,50.5025818845438,5.51689509982324,7.26242637634277,132,1,0,0,1,0.238571166992187,31.2805480957031,2,1,1,289.590118408203,0,289.340545654297,,,,,,,,,,,,,,,,,,,,,,,,,,,,,,,,,
,3738628229.905,292.347564697266,40000.328125,-7.57057399978362E-8,3.47744016441889E-8,1,10,13.2042255401611,3.98053423217501,32.3400013148785,-5.65132836925544E-5,-7.98986688592933E-5,1,-7.9253456890855E-8,292.105682373047,292.589447021484,40000.328125,40000.328125,50.4349710176303,5.51753670645015,7.39599847793579,132,1,0,0,1,0.237503051757813,31.2805480957031,2,1,1,292.589447021484,0,292.347564697266,,,,,,,,,,,,,,,,,,,,,,,,,,,,,,,,,
,3738628289.93513,295.331970214844,40000.328125,-7.67622690453715E-8,3.4282332723516E-8,1,10,13.2042255401611,3.98054184558039,32.3400013148785,-5.83811166713381E-5,-7.37214731053539E-5,1,-7.2103572824924E-8,295.087677001953,295.576263427734,40000.328125,40000.328125,50.5139154980726,5.51824282466671,7.54238176345825,132,1,0,0,1,0.235214233398438,33.7243423461914,2,1,1,295.576263427734,0,295.331970214844,,,,,,,,,,,,,,,,,,,,,,,,,,,,,,,,,
,3738628349.92275,298.334106445313,40000.328125,-9.22547031376322E-8,3.13632237335419E-8,1,10,13.2042255401611,3.98049165687498,32.3400013148785,-7.61529081664255E-5,-4.81101203104648E-5,1,-4.0817499970941E-8,298.079284667969,298.588928222656,40000.328125,40000.328125,50.4947655993515,5.51601077811743,7.73570203781128,132,1,0,0,1,0.233993530273438,32.2580642700195,2,1,1,298.588928222656,0,298.334106445313,,,,,,,,,,,,,,,,,,,,,,,,,,,,,,,,,
,3738628410.04179,299.782455444336,40000.328125,-1.0453488304178E-7,3.2445009149976E-8,1,10,13.2042255401611,3.98054342246401,32.3499999940395,-8.92431263567164E-5,-3.45663363590708E-5,1,-2.3666339862821E-8,299.755767822266,299.809143066406,40000.328125,40000.328125,50.4380975317073,5.51904870243188,7.91023969650269,132,1,0,0,1,0.240631103515625,30.3030319213867,5,1,1,299.809143066406,0,299.782455444336,,,,,,,,,,,,,,,,,,,,,,,,,,,,,,,,,
,3738628449.88101,299.920303344727,40000.328125,-9.7365920024179E-8,3.12695186796909E-8,1,10,13.2042255401611,3.98045700693376,32.3400013148785,-8.05505535433459E-5,-4.95607387899847E-5,1,-4.17043390013475E-8,299.910614013672,299.929992675781,40000.328125,40000.328125,50.4560749876496,5.5165584482232,8.01821613311768,132,1,0,0,1,0.233535766601562,30.7917900085449,1,1,1,299.929992675781,0,299.920303344727,,,,,,,,,,,,,,,,,,,,,,,,,,,,,,,,,