File: data/quartz-holder/180619_empty-quartz_4mm_5T.dat
[Header]
; MPMS3 Data File (default extension .dat)
; Copyright (c) 2007, Quantum Design, Inc. All rights reserved.
TITLE,
FILEOPENTIME,3738615509.68594,06/20/2018,12:18 am
BYAPP,MPMS3,1.0,1.1
INFO,MPMS3 Measurement Release 1.1.16 Build 388, MultiVu Release 2.3.4.15,APPNAME
INFO,0,MOMENT_UNITS
INFO,empty quartz,SAMPLE_MATERIAL
INFO,,SAMPLE_COMMENT
INFO,1,SAMPLE_MASS
INFO,,SAMPLE_VOLUME
INFO,,SAMPLE_MOLECULAR_WEIGHT
INFO,,SAMPLE_SIZE
INFO,,SAMPLE_SHAPE
INFO,Standard,SAMPLE_HOLDER
INFO,Standard,SAMPLE_HOLDER_DETAIL
INFO,66,SAMPLE_OFFSET
DATATYPE,COMMENT,1
DATATYPE,TIME,2
STARTUPAXIS,X,2
STARTUPAXIS,Y1,5
FIELDGROUP, VSM,2,3,4,5,6,8,9,10,11,14,15
FIELDGROUP, DC, 2,3,4,14,34,35,36,37,38,39,40,41,42,43,44,45,46,47
STARTUPGROUP, All
[Data]
Comment,Time Stamp (sec),Temperature (K),Magnetic Field (Oe),Moment (emu),M. Std. Err. (emu),Transport Action,Averaging Time (sec),Frequency (Hz),Peak Amplitude (mm),Center Position (mm),Lockin Signal' (V),Lockin Signal (V),Range,M. Quad. Signal (emu),Min. Temperature (K),Max. Temperature (K),Min. Field (Oe),Max. Field (Oe),Mass (grams),Motor Lag (deg),Pressure (Torr),Measure Count,Measurement Number,SQUID Status (code),Motor Status (code),Measure Status (code),Motor Current (amps),Motor Temp. (C),Temp. Status (code),Field Status (code),Chamber Status (code),Chamber Temp (K),Redirection State,Average Temp (K),Rotation Angle (deg),Rotator state,DC Moment Fixed Ctr (emu),DC Moment Err Fixed Ctr (emu),DC Moment Free Ctr (emu),DC Moment Err Free Ctr (emu),DC Fixed Fit,DC Free Fit,DC Calculated Center (mm),DC Calculated Center Err (mm),DC Scan Length (mm),DC Scan Time (s),DC Number of Points,DC Squid Drift,DC Min V (V),DC Max V (V),DC Scans per Measure,Map 01,Map 02,Map 03,Map 04,Map 05,Map 06,Map 07,Map 08,Map 09,Map 10,Map 11,Map 12,Map 13,Map 14,Map 15,Map 16
,3738615589.0877,299.999481201172,49999.71484375,-5.71643350601181E-8,1.36945046223342E-7,1,10,13.2042255401611,4.01156354945137,32.3400013148785,-4.67970528155019E-5,-3.68016292268034E-5,1,-3.2692747457613E-8,299.999481201172,299.999481201172,49999.71484375,49999.71484375,50.4298904322553,5.51492939190223,8.00349140167236,132,1,0,0,1,0.238494873046875,31.7693061828613,1,1,1,299.999481201172,0,299.999481201172,,,,,,,,,,,,,,,,,,,,,,,,,,,,,,,,,
,3738615644.40055,299.082290649414,49999.71484375,-1.16380596984357E-7,1.2488228639833E-7,1,10,13.2042255401611,4.01153869059485,32.3400013148785,-8.79695028248768E-5,-0.000124285567418478,1,-1.21754879804473E-7,298.849578857422,299.315002441406,49999.71484375,49999.71484375,50.457638244688,5.51561026260304,7.93543243408203,132,1,0,0,1,0.235137939453125,31.7693061828613,2,1,1,298.849578857422,0,299.082290649414,,,,,,,,,,,,,,,,,,,,,,,,,,,,,,,,,
,3738615704.36874,295.93505859375,49999.71484375,-7.98796907578387E-8,1.29387724515811E-7,1,10,13.2042255401611,4.01162638290407,32.3400013148785,-5.61544244110112E-5,-0.000113877230270407,1,-1.15512562683045E-7,295.664764404297,296.205352783203,49999.71484375,49999.71484375,50.3958895916688,5.51550770815144,7.86667013168335,132,1,0,0,1,0.239028930664062,30.7917900085449,2,1,1,295.664764404297,0,295.93505859375,,,,,,,,,,,,,,,,,,,,,,,,,,,,,,,,,
,3738615764.4018,292.675003051758,49999.71484375,-9.65804062366552E-8,1.50527004290767E-7,1,10,13.2042255401611,4.01162799350978,32.3400013148785,-7.54101669569993E-5,-8.68921181588063E-5,1,-8.28682341536147E-8,292.325866699219,293.024139404297,49999.71484375,49999.71484375,50.3724407360919,5.516029333006,7.80769157409668,132,1,0,0,1,0.23895263671875,31.2805480957031,2,1,1,292.325866699219,0,292.675003051758,,,,,,,,,,,,,,,,,,,,,,,,,,,,,,,,,
,3738615824.47021,289.308197021484,49999.71484375,-8.40572235923091E-8,1.19787492886574E-7,1,10,13.2042255401611,4.01159580754017,32.3400013148785,-6.31788097537118E-5,-9.21992641386023E-5,1,-9.06566004061182E-8,289.082672119141,289.533721923828,49999.71484375,49999.71484375,50.4197292615053,5.51608698326421,7.75122737884521,132,1,0,0,1,0.239410400390625,31.7693061828613,2,1,1,289.082672119141,0,289.308197021484,,,,,,,,,,,,,,,,,,,,,,,,,,,,,,,,,
,3738615884.32227,286.35612487793,49999.71484375,-5.56878578738736E-8,1.30675896866305E-7,1,10,13.2042255401611,4.01178130154924,32.3400013148785,-3.41291820859454E-5,-0.00011333022733034,1,-1.18472483384613E-7,286.125152587891,286.587097167969,49999.71484375,49999.71484375,50.4240282183611,5.51709345878493,7.70011138916016,132,1,0,0,1,0.237808227539062,31.7693061828613,2,1,1,286.125152587891,0,286.35612487793,,,,,,,,,,,,,,,,,,,,,,,,,,,,,,,,,
,3738615944.30145,283.441421508789,49999.71484375,-7.88617419765167E-8,1.37407172245988E-7,1,10,13.2042255401611,4.01145250370662,32.3400013148785,-6.05028610640727E-5,-7.81659086390729E-5,1,-7.57387596688818E-8,283.197937011719,283.684906005859,49999.71484375,49999.71484375,50.4642820871015,5.51788362939693,7.66800785064697,132,1,0,0,1,0.238113403320313,31.2805480957031,2,1,1,283.197937011719,0,283.441421508789,,,,,,,,,,,,,,,,,,,,,,,,,,,,,,,,,
,3738616004.31953,280.473434448242,49999.71484375,-1.10445428541545E-7,1.53300494443326E-7,1,10,13.2042255401611,4.01150428000625,32.3400013148785,-9.62583856935855E-5,-3.15942186857939E-5,1,-1.89874885763309E-8,280.233001708984,280.7138671875,49999.71484375,49999.71484375,50.4631096443226,5.51735803143263,7.62555599212647,132,1,0,0,1,0.237655639648438,31.2805480957031,2,1,1,280.220336914062,0,280.473434448242,,,,,,,,,,,,,,,,,,,,,,,,,,,,,,,,,
,3738616064.383,277.458587646484,49999.71484375,-6.84199335859423E-8,1.58532419975688E-7,1,10,13.2042255401611,4.01151206398463,32.3400013148785,-5.8205601436772E-5,-2.92088021600094E-5,1,-2.25379753813559E-8,277.215179443359,277.701995849609,49999.71484375,49999.71484375,50.4646729013611,5.51819017718223,7.59122800827026,132,1,0,0,1,0.237274169921875,31.2805480957031,2,1,1,277.215179443359,0,277.458587646484,,,,,,,,,,,,,,,,,,,,,,,,,,,,,,,,,
,3738616124.20883,274.491561889648,49999.71484375,-1.78298627392486E-7,1.30962624656087E-7,1,10,13.2042255401611,4.01146273249278,32.3400013148785,-0.000155608430380416,-4.95480579049696E-5,1,-2.90250353464279E-8,274.252197265625,274.730926513672,49999.71484375,49999.71484375,50.4459138168996,5.51698770496574,7.56029796600342,132,1,0,0,1,0.235977172851562,31.2805480957031,2,1,1,274.252197265625,0,274.491561889648,,,,,,,,,,,,,,,,,,,,,,,,,,,,,,,,,
,3738616184.23856,271.476654052734,49999.71484375,-5.66916159636483E-8,2.16371213263454E-7,1,10,13.2042255401611,4.01150744410975,32.3400013148785,-4.72847213710667E-5,-3.05779354909249E-5,1,-2.58042828400121E-8,271.221771240234,271.731536865234,49999.71484375,49999.71484375,50.4212925185438,5.51708211253553,7.52560043334961,130,1,32,0,0,0.238876342773438,32.2580642700195,2,1,1,271.221771240234,0,271.476654052734,,,,,,,,,,,,,,,,,,,,,,,,,,,,,,,,,
,3738616244.17233,268.471771240234,49999.71484375,-1.31878926479465E-7,1.65847423514838E-7,1,10,13.2042255401611,4.01127656411137,32.3400013148785,-0.000114881552104061,-3.80379982351033E-5,1,-2.30255362131823E-8,268.2119140625,268.731628417969,49999.71484375,49999.71484375,50.3978436629669,5.51765254505163,7.49856567382813,132,1,0,0,1,0.240097045898438,31.7693061828613,2,1,1,268.2119140625,0,268.471771240234,,,,,,,,,,,,,,,,,,,,,,,,,,,,,,,,,
,3738616304.22173,265.484436035156,49999.71484375,-9.26811524642716E-8,1.57914015190926E-7,1,10,13.2042255401611,4.01154965051167,32.3400013148785,-7.78910442213267E-5,-4.60213737524558E-5,1,-3.77473481109987E-8,265.236419677734,265.732452392578,49999.71484375,49999.71484375,50.5174328264092,5.51882467547051,7.47526693344116,132,1,0,0,1,0.236740112304687,31.7693061828613,2,1,1,265.236419677734,0,265.484436035156,,,,,,,,,,,,,,,,,,,,,,,,,,,,,,,,,
,3738616364.12792,262.463989257813,49999.71484375,-1.50968993228487E-7,1.26928987106181E-7,1,10,13.2042255401611,4.01132062409366,32.3400013148785,-0.000127495582724373,-7.070076708391E-5,1,-5.67264491917982E-8,262.199798583984,262.728179931641,49999.71484375,49999.71484375,50.442396488563,5.51885464344868,7.44363832473755,132,1,0,0,1,0.236358642578125,31.2805480957031,2,1,1,262.199798583984,0,262.463989257813,,,,,,,,,,,,,,,,,,,,,,,,,,,,,,,,,
,3738616424.23674,259.472198486328,49999.71484375,-1.49911373755968E-7,1.14707244559177E-7,1,10,13.2042255401611,4.01116314211014,32.3400013148785,-0.000133935666188712,-2.05840453702679E-5,1,-8.39778596262819E-10,259.226287841797,259.718109130859,49999.71484375,49999.71484375,50.3970620344476,5.51922766749284,7.42297887802124,130,1,32,0,0,0.233840942382813,31.2805480957031,2,1,1,259.226287841797,0,259.472198486328,,,,,,,,,,,,,,,,,,,,,,,,,,,,,,,,,
,3738616484.25876,256.491546630859,49999.71484375,-1.35733049693068E-7,9.29751527151044E-8,1,10,13.2042255401611,4.0111154379329,32.3400013148785,-0.000121383849502282,-1.78403459673091E-5,1,1.3048279232818E-10,256.2490234375,256.734069824219,49999.71484375,49999.71484375,50.4205108900246,5.51886796335358,7.4021110534668,131,1,68,0,0,0.233535766601562,32.2580642700195,2,1,1,256.2490234375,0,256.491546630859,,,,,,,,,,,,,,,,,,,,,,,,,,,,,,,,,
,3738616544.06953,253.496795654297,49999.71484375,-1.81420562289902E-7,8.30143095681383E-8,1,10,13.2042255401611,4.01136691683754,32.3400013148785,-0.000161436904047519,-2.93949993668436E-5,1,-6.0288586194328E-9,253.256149291992,253.737442016602,49999.71484375,49999.71484375,50.4154303046496,5.51858077523389,7.37905788421631,132,1,0,0,1,0.23773193359375,31.7693061828613,2,1,1,253.256149291992,0,253.496795654297,,,,,,,,,,,,,,,,,,,,,,,,,,,,,,,,,
,3738616604.08899,250.522621154785,49999.71484375,-1.59941667363443E-7,6.70542216779709E-8,1,10,13.2042255401611,4.01124195663051,32.3400013148785,-0.000144924532154796,-8.28904873260193E-6,1,1.43946874650651E-8,250.271179199219,250.774063110352,49999.71484375,49999.71484375,50.3954987774092,5.5193352893903,7.36369657516479,132,1,0,0,1,0.240402221679687,31.7693061828613,2,1,1,250.271179199219,0,250.522621154785,,,,,,,,,,,,,,,,,,,,,,,,,,,,,,,,,
,3738616664.05415,247.48356628418,49999.71484375,-1.24512982853761E-7,6.17927293108083E-8,1,10,13.2042255401611,4.01097875738955,32.3400013148785,-0.000115402227912026,1.10645403144406E-5,1,3.0797498104058E-8,247.232879638672,247.734252929687,49999.71484375,49999.71484375,50.4130854190919,5.51873968505464,7.33997344970703,132,1,0,0,1,0.237350463867187,31.2805480957031,2,1,1,247.232879638672,0,247.48356628418,,,,,,,,,,,,,,,,,,,,,,,,,,,,,,,,,
,3738616724.12775,244.475875854492,49999.71484375,-1.40150004243067E-7,5.11700227390119E-8,1,10,13.2042255401611,4.01091886413655,32.3400013148785,-0.000129551518967913,1.01527081906239E-5,1,3.20915494468174E-8,244.234375,244.717376708984,49999.71484375,49999.71484375,50.3392215240246,5.51941087524272,7.32665014266968,132,1,0,0,1,0.236587524414062,31.7693061828613,2,1,1,244.234375,0,244.475875854492,,,,,,,,,,,,,,,,,,,,,,,,,,,,,,,,,
,3738616783.98633,241.501998901367,49999.71484375,-1.33465319525681E-7,4.47113151133901E-8,1,10,13.2042255401611,4.01114398204527,32.3400013148785,-0.000125421206500205,2.34424235934521E-5,1,4.59641721915997E-8,241.258483886719,241.745513916016,49999.71484375,49999.71484375,50.4599831302457,5.51887390249145,7.3036060333252,132,1,0,0,1,0.238723754882813,30.7917900085449,2,1,1,241.258483886719,0,241.501998901367,,,,,,,,,,,,,,,,,,,,,,,,,,,,,,,,,
,3738616843.97576,238.509696960449,49999.71484375,-1.17269884223895E-7,5.03543742824983E-8,1,10,13.2042255401611,4.01095955546032,32.3400013148785,-0.000107190914359766,3.00496100868763E-7,1,1.76869701320888E-8,238.261947631836,238.757446289062,49999.71484375,49999.71484375,50.4603739445053,5.51788383685112,7.29575347900391,132,1,0,0,1,0.238494873046875,31.2805480957031,2,1,1,238.261947631836,0,238.509696960449,,,,,,,,,,,,,,,,,,,,,,,,,,,,,,,,,
,3738616903.94648,235.517364501953,49999.71484375,-8.78777492488456E-8,5.08912725750892E-8,1,10,13.2042255401611,4.01098692321593,32.3400013148785,-8.34980028673179E-5,2.16651531257811E-5,1,3.72330630639966E-8,235.262786865234,235.771942138672,49999.71484375,49999.71484375,50.4142578618707,5.51799918678946,7.27359008789063,132,1,0,0,1,0.240707397460938,31.2805480957031,2,1,1,235.262786865234,0,235.517364501953,,,,,,,,,,,,,,,,,,,,,,,,,,,,,,,,,
,3738616963.99436,232.507926940918,49999.71484375,-8.23827619673686E-8,3.69490059987917E-8,1,10,13.2042255401611,4.01100453852232,32.3400013148785,-7.92452386959496E-5,2.68517399608506E-5,1,4.22206639761559E-8,232.25520324707,232.760650634766,49999.71484375,49999.71484375,50.3931538918515,5.51777043855835,7.25635766983032,131,1,68,0,0,0.2362060546875,31.2805480957031,2,1,1,232.25520324707,0,232.507926940918,,,,,,,,,,,,,,,,,,,,,,,,,,,,,,,,,
,3738617023.90958,229.494384765625,49999.71484375,-1.09352276838658E-7,3.81880951734122E-8,1,10,13.2042255401611,4.01095946335203,32.3400013148785,-9.9383690452674E-5,-3.57298175795613E-6,1,1.21832464211108E-8,229.238388061523,229.750381469727,49999.71484375,49999.71484375,50.4259822896592,5.51857855286563,7.24349784851074,132,1,0,0,1,0.235443115234375,31.7693061828613,2,1,1,229.238388061523,0,229.494384765625,,,,,,,,,,,,,,,,,,,,,,,,,,,,,,,,,
,3738617084.05783,226.509674072266,49999.71484375,-9.64572235599836E-8,3.7154457492093E-8,1,10,13.2042255401611,4.01089376143267,32.3400013148785,-8.83098112341574E-5,1.22772207160389E-6,1,1.5644678530224E-8,226.257522583008,226.761825561523,49999.71484375,49999.71484375,50.3669693364573,5.51828472153145,7.23246574401855,130,1,32,0,0,0.235824584960938,31.2805480957031,2,1,1,226.257522583008,0,226.509674072266,,,,,,,,,,,,,,,,,,,,,,,,,,,,,,,,,
,3738617143.88722,223.525047302246,49999.71484375,-9.45462601020015E-8,3.34858909719879E-8,1,10,13.2042255401611,4.01086695184101,32.3400013148785,-8.49153398442801E-5,-9.90795057388785E-6,1,2.90689367163695E-9,223.251235961914,223.798858642578,49999.71484375,49999.71484375,50.3517275803322,5.51839357723729,7.21130037307739,128,1,32,0,0,0.240325927734375,31.2805480957031,2,1,1,223.251235961914,0,223.525047302246,,,,,,,,,,,,,,,,,,,,,,,,,,,,,,,,,
,3738617203.86434,220.515449523926,49999.71484375,-6.42639495460046E-8,3.89443975738537E-8,1,10,13.2042255401611,4.01095315994194,32.3400013148785,-6.19643401058558E-5,2.19535908081933E-5,1,3.40621662557933E-8,220.272674560547,220.758224487305,49999.71484375,49999.71484375,50.4275455466976,5.51715059832571,7.20162057876587,132,1,0,0,1,0.238113403320313,32.7468223571777,2,1,1,220.272674560547,0,220.515449523926,,,,,,,,,,,,,,,,,,,,,,,,,,,,,,,,,
,3738617263.82167,217.543334960938,49999.71484375,-4.74710505044488E-8,3.59771401977322E-8,1,10,13.2042255401611,4.01109539320668,32.3400013148785,-4.45171629332531E-5,7.71680003267849E-6,1,1.56539925720606E-8,217.294219970703,217.792449951172,49999.71484375,49999.71484375,50.391590634813,5.51689576039288,7.1832389831543,130,1,32,0,0,0.237350463867187,30.3030319213867,2,1,1,217.294219970703,0,217.543334960938,,,,,,,,,,,,,,,,,,,,,,,,,,,,,,,,,
,3738617323.85248,214.522193908691,49999.71484375,-4.47311743289697E-8,3.4102894371144E-8,1,10,13.2042255401611,4.01123850123642,32.3400013148785,-4.54423478083011E-5,3.08745645212346E-5,1,4.1145858436361E-8,214.277374267578,214.767013549805,49999.71484375,49999.71484375,50.4365342746688,5.51528230565136,7.17216396331787,132,1,0,0,1,0.240859985351562,31.2805480957031,2,1,1,214.277374267578,0,214.522193908691,,,,,,,,,,,,,,,,,,,,,,,,,,,,,,,,,
,3738617383.95836,211.511497497559,49999.71484375,-7.67673819707755E-8,3.86287751617639E-8,1,10,13.2042255401611,4.01117342742508,32.3400013148785,-7.3257739036693E-5,2.10291802390775E-5,1,3.48761744553931E-8,211.263702392578,211.759292602539,49999.71484375,49999.71484375,50.3423480381015,5.5152937932125,7.15359354019165,132,1,0,0,1,0.23895263671875,31.7693061828613,2,1,1,211.263702392578,0,211.511497497559,,,,,,,,,,,,,,,,,,,,,,,,,,,,,,,,,
,3738617443.77757,208.538726806641,49999.71484375,-4.31285336884748E-8,3.60855574381194E-8,1,10,13.2042255401611,4.0111516519128,32.3400013148785,-3.99549751033366E-5,3.69394156871123E-6,1,1.05123051336784E-8,208.292358398438,208.785095214844,49999.71484375,49999.71484375,50.361107122563,5.5155804351689,7.13534307479858,132,1,0,0,1,0.239715576171875,32.2580642700195,2,1,1,208.292358398438,0,208.538726806641,,,,,,,,,,,,,,,,,,,,,,,,,,,,,,,,,
,3738617503.74223,205.538131713867,49999.71484375,-8.37496403499695E-8,3.69363380138958E-8,1,10,13.2042255401611,4.01115625741138,32.3400013148785,-7.539700723896E-5,-7.62958332335625E-6,1,3.85875547242999E-9,205.295379638672,205.780883789062,49999.71484375,49999.71484375,50.3642336366399,5.51551762898887,7.12454843521118,132,1,0,0,1,0.238571166992187,31.7693061828613,2,1,1,205.295379638672,0,205.538131713867,,,,,,,,,,,,,,,,,,,,,,,,,,,,,,,,,
,3738617563.71166,202.536575317383,49999.71484375,-5.80607498320804E-8,3.43688970815737E-8,1,10,13.2042255401611,4.01114756010839,32.3400013148785,-5.44204624199325E-5,9.24524476169254E-6,1,1.8929980950481E-8,202.286178588867,202.786972045898,49999.71484375,49999.71484375,50.3146002256688,5.5153294708184,7.10555124282837,132,1,0,0,1,0.240020751953125,32.7468223571777,2,1,1,202.286178588867,0,202.536575317383,,,,,,,,,,,,,,,,,,,,,,,,,,,,,,,,,
,3738617623.70519,199.534149169922,49999.71484375,-5.44850989851482E-8,3.59779081519178E-8,1,10,13.2042255401611,4.01109312751742,32.3400013148785,-5.39438679643474E-5,2.81136226960429E-5,1,3.95032239999572E-8,199.272384643555,199.795913696289,49999.71484375,49999.71484375,50.3837743496207,5.515497784317,7.09456396102905,132,1,0,0,1,0.235519409179687,32.2580642700195,2,1,1,199.272384643555,0,199.534149169922,,,,,,,,,,,,,,,,,,,,,,,,,,,,,,,,,
,3738617683.66702,196.518516540527,49999.71484375,-3.78146126338491E-8,3.60187496712479E-8,1,10,13.2042255401611,4.01116637937845,32.3400013148785,-3.69981305810582E-5,1.65254922204774E-5,1,2.4076212484016E-8,196.267791748047,196.769241333008,49999.71484375,49999.71484375,50.3505551375534,5.51598737229954,7.0835542678833,132,1,0,0,1,0.239715576171875,31.2805480957031,2,1,1,196.267791748047,0,196.518516540527,,,,,,,,,,,,,,,,,,,,,,,,,,,,,,,,,
,3738617743.76641,193.524185180664,49999.71484375,-7.93541133567373E-8,5.13618073280085E-8,1,10,13.2042255401611,4.01117853594269,32.3400013148785,-7.71053136086455E-5,3.10577603871338E-5,1,4.64742581316214E-8,193.270004272461,193.778366088867,49999.71484375,49999.71484375,50.4025334340823,5.51590773472043,7.07154083251953,132,1,0,0,1,0.235366821289062,30.7917900085449,2,1,1,193.270004272461,0,193.524185180664,,,,,,,,,,,,,,,,,,,,,,,,,,,,,,,,,
,3738617803.62193,190.55086517334,49999.71484375,-5.24687593581756E-8,4.62023630594406E-8,1,10,13.2042255401611,4.01120178077818,32.3400013148785,-5.20091402198731E-5,2.74754478294956E-5,1,3.84898427496887E-8,190.303817749023,190.797912597656,49999.71484375,49999.71484375,50.4357526461496,5.51512980630719,7.05662727355957,132,1,0,0,1,0.23468017578125,31.2805480957031,2,1,1,190.303817749023,0,190.55086517334,,,,,,,,,,,,,,,,,,,,,,,,,,,,,,,,,
,3738617863.64237,187.539337158203,49999.71484375,-8.94008391721612E-8,3.75069345390134E-8,1,10,13.2042255401611,4.01125223064551,32.3400013148785,-8.15411935327802E-5,-1.02418485523794E-6,1,1.2082108716855E-8,187.292846679687,187.785827636719,49999.71484375,49999.71484375,50.3775213214669,5.51497469321879,7.04543304443359,132,1,0,0,1,0.239791870117187,31.2805480957031,2,1,1,187.292846679687,0,187.539337158203,,,,,,,,,,,,,,,,,,,,,,,,,,,,,,,,,
,3738617923.58877,184.539031982422,49999.71484375,-3.06596162907919E-8,5.00852060261291E-8,1,10,13.2042255401611,4.01121153809066,32.3400013148785,-2.46995782745055E-5,-2.24127723685078E-5,1,-2.05285702897584E-8,184.296768188477,184.781295776367,49999.71484375,49999.71484375,50.3888549349957,5.51476608469447,7.03027772903442,132,1,0,0,1,0.239486694335938,30.3030319213867,2,1,1,184.296768188477,0,184.539031982422,,,,,,,,,,,,,,,,,,,,,,,,,,,,,,,,,
,3738617983.65458,181.552658081055,49999.71484375,-7.07190417793571E-8,4.14510508868683E-8,1,10,13.2042255401611,4.0113605097024,32.3400013148785,-6.1681652746617E-5,-1.98895610436227E-5,1,-1.17784051068457E-8,181.296127319336,181.809188842773,49999.71484375,49999.71484375,50.335704195688,5.5140906507073,7.02236127853394,132,1,0,0,1,0.236968994140625,31.7693061828613,2,1,1,181.296127319336,0,181.552658081055,,,,,,,,,,,,,,,,,,,,,,,,,,,,,,,,,
,3738618043.70014,178.546646118164,49999.71484375,-9.40558158639018E-8,4.53065112402201E-8,1,10,13.2042255401611,4.0113950267551,32.3400013148785,-8.44268400359982E-5,-1.03029411219699E-5,1,2.39495643073053E-9,178.299255371094,178.794036865234,49999.71484375,49999.71484375,50.3380490812457,5.5140943746766,7.00483798980713,132,1,0,0,1,0.2398681640625,31.2805480957031,2,1,1,178.299255371094,0,178.546646118164,,,,,,,,,,,,,,,,,,,,,,,,,,,,,,,,,
,3738618103.55347,175.552886962891,49999.71484375,-7.66872073384437E-8,5.26774033014632E-8,1,10,13.2042255401611,4.01125066646216,32.3400013148785,-6.92450248528405E-5,-5.61105179099504E-6,1,5.0714889766443E-9,175.304153442383,175.801620483398,49999.71484375,49999.71484375,50.447477073938,5.51520394279753,6.99390316009522,132,1,0,0,1,0.234603881835938,30.7917900085449,2,1,1,175.304153442383,0,175.552886962891,,,,,,,,,,,,,,,,,,,,,,,,,,,,,,,,,
,3738618163.49136,172.530349731445,49999.71484375,-8.57588252963895E-8,3.62759321607149E-8,1,10,13.2042255401611,4.01133857587202,32.3400013148785,-7.3742395142926E-5,-3.12592565111704E-5,1,-2.22677871054228E-8,172.29167175293,172.769027709961,49999.71484375,49999.71484375,50.4091772764957,5.51431847351233,6.98362874984741,130,1,32,0,0,0.239944458007813,31.7693061828613,2,1,1,172.29167175293,0,172.530349731445,,,,,,,,,,,,,,,,,,,,,,,,,,,,,,,,,
,3738618223.52093,169.572059631348,49999.71484375,-6.18623490458844E-8,3.88663269315151E-8,1,10,13.2042255401611,4.01134339038242,32.3400013148785,-5.6628999390095E-5,6.64748544613561E-7,1,9.89632748667031E-9,169.303451538086,169.840667724609,49999.71484375,49999.71484375,50.3790845785053,5.51400306503386,6.96970844268799,132,1,0,0,1,0.2349853515625,31.2805480957031,2,1,1,169.303451538086,0,169.572059631348,,,,,,,,,,,,,,,,,,,,,,,,,,,,,,,,,
,3738618283.6073,166.558296203613,49999.71484375,-9.25744863097476E-8,4.58058006218573E-8,1,10,13.2042255401611,4.01130798126304,32.3400013148785,-7.6666785683308E-5,-5.35820611912203E-5,1,-4.62230887561641E-8,166.308959960938,166.807632446289,49999.71484375,49999.71484375,50.3771305072072,5.51478875245636,6.96158123016357,132,1,0,0,1,0.237884521484375,30.7917900085449,2,1,1,166.308959960938,0,166.558296203613,,,,,,,,,,,,,,,,,,,,,,,,,,,,,,,,,
,3738618343.47178,163.567192077637,49999.71484375,-1.07739236175227E-7,4.64250317988169E-8,1,10,13.2042255401611,4.0112690162288,32.3400013148785,-9.03234462152327E-5,-5.49295658111976E-5,1,-4.54872078321939E-8,163.337493896484,163.796890258789,49999.71484375,49999.71484375,50.3657968936784,5.51462309539482,6.94815111160278,132,1,0,0,1,0.236587524414062,31.2805480957031,2,1,1,163.337493896484,0,163.567192077637,,,,,,,,,,,,,,,,,,,,,,,,,,,,,,,,,
,3738618403.39865,160.586776733398,49999.71484375,-5.89859719973443E-8,4.0680402786439E-8,1,10,13.2042255401611,4.01129177265802,32.3400013148785,-5.38152100676728E-5,-5.80290107865087E-7,1,8.07844363513171E-9,160.328765869141,160.844787597656,49999.71484375,49999.71484375,50.3571989799669,5.51508395547724,6.94146299362183,132,1,0,0,1,0.236968994140625,32.2580642700195,2,1,1,160.328765869141,0,160.586776733398,,,,,,,,,,,,,,,,,,,,,,,,,,,,,,,,,
,3738618463.39301,157.561508178711,49999.71484375,-9.36822184392822E-9,5.44114838611281E-8,1,10,13.2042255401611,4.01131058738116,32.3400013148785,-9.10683076013559E-6,3.6911802156458E-6,1,5.51388688325472E-9,157.297470092773,157.825546264648,49999.71484375,49999.71484375,50.4744432578515,5.51439470260268,6.92692422866821,132,1,0,0,1,0.235061645507813,31.2805480957031,2,1,1,157.297470092773,0,157.561508178711,,,,,,,,,,,,,,,,,,,,,,,,,,,,,,,,,
,3738618523.47321,154.569877624512,49999.71484375,-5.371699487766E-8,4.09858243354908E-8,1,10,13.2042255401611,4.01131617026595,32.3400013148785,-5.12855498705452E-5,1.48608828915281E-5,1,2.45664742891082E-8,154.325973510742,154.813781738281,49999.71484375,49999.71484375,50.3802570212842,5.51479542105986,6.91679191589356,132,1,0,0,1,0.239410400390625,31.2805480957031,2,1,1,154.325973510742,0,154.569877624512,,,,,,,,,,,,,,,,,,,,,,,,,,,,,,,,,
,3738618583.34762,151.562515258789,49999.71484375,-6.82891498629967E-8,3.66175947591841E-8,1,10,13.2042255401611,4.01134226754322,32.3400013148785,-5.84834290111517E-5,-2.64947875865981E-5,1,-1.9524523290086E-8,151.309326171875,151.815704345703,49999.71484375,49999.71484375,50.356026537188,5.51486463547694,6.90546989440918,132,1,0,0,1,0.240554809570313,31.2805480957031,2,1,1,151.309326171875,0,151.562515258789,,,,,,,,,,,,,,,,,,,,,,,,,,,,,,,,,
,3738618643.55554,148.575752258301,49999.71484375,-4.08818484016915E-8,3.64787857039492E-8,1,10,13.2042255401611,4.01135286243156,32.3400013148785,-3.83177514581399E-5,6.48316595563296E-6,1,1.3298659961486E-8,148.322204589844,148.829299926758,49999.71484375,49999.71484375,50.3607163083034,5.51497917709931,6.89101076126099,132,1,0,0,1,0.239410400390625,30.7917900085449,2,1,1,148.322204589844,0,148.575752258301,,,,,,,,,,,,,,,,,,,,,,,,,,,,,,,,,
,3738618703.30396,145.595329284668,49999.71484375,-4.58147461103553E-8,4.78410388674913E-8,1,10,13.2042255401611,4.01135570203918,32.3400013148785,-4.33117540379816E-5,9.76919303871003E-6,1,1.77031592333138E-8,145.352172851562,145.838485717773,49999.71484375,49999.71484375,50.4064415766784,5.51476143205813,6.87977600097656,131,1,68,0,0,0.236663818359375,30.7917900085449,2,1,1,145.352172851562,0,145.595329284668,,,,,,,,,,,,,,,,,,,,,,,,,,,,,,,,,
,3738618763.42766,142.590217590332,49999.71484375,-3.72453881063554E-8,3.78178000868615E-8,1,10,13.2042255401611,4.01132918657652,32.3400013148785,-3.25758707180899E-5,-9.86282843046817E-6,1,-5.5186687887844E-9,142.348449707031,142.831985473633,49999.71484375,49999.71484375,50.4326261320726,5.51487839861892,6.87433481216431,130,1,32,0,0,0.240402221679687,31.7693061828613,2,1,1,142.348449707031,0,142.590217590332,,,,,,,,,,,,,,,,,,,,,,,,,,,,,,,,,
,3738618823.28394,139.56999206543,49999.71484375,-5.94859275721409E-8,3.57368971822035E-8,1,10,13.2042255401611,4.01136437548,32.3400013148785,-5.05065877274397E-5,-2.60407333411382E-5,1,-2.03190085636626E-8,139.33903503418,139.80094909668,49999.71484375,49999.71484375,50.4560749876496,5.51487520211334,6.85753202438354,132,1,0,0,1,0.238800048828125,31.2805480957031,2,1,1,139.33903503418,0,139.56999206543,,,,,,,,,,,,,,,,,,,,,,,,,,,,,,,,,
,3738618883.40967,136.609558105469,49999.71484375,-6.24357028319188E-8,4.01271509523785E-8,1,10,13.2042255401611,4.01132512257623,32.3400013148785,-5.95070296089048E-5,1.65782117437541E-5,1,2.77768610697621E-8,136.355834960938,136.86328125,49999.71484375,49999.71484375,50.3626703796015,5.51551736970473,6.84503889083862,130,1,68,0,0,0.236282348632813,31.7693061828613,2,1,1,136.355834960938,0,136.609558105469,,,,,,,,,,,,,,,,,,,,,,,,,,,,,,,,,
,3738618943.24571,133.615699768066,49999.71484375,-4.04814242919944E-8,3.45053080778116E-8,1,10,13.2042255401611,4.01132202186252,32.3400013148785,-3.51782654964043E-5,-1.22595850560146E-5,1,-7.72015309552713E-9,133.35612487793,133.875274658203,49999.71484375,49999.71484375,50.3614979368226,5.51541302024816,6.83375406265259,132,1,0,0,1,0.239791870117187,30.7917900085449,2,1,1,133.35612487793,0,133.615699768066,,,,,,,,,,,,,,,,,,,,,,,,,,,,,,,,,
,3738619003.22716,130.585250854492,49999.71484375,-2.00863225399935E-8,4.59942696456525E-8,1,10,13.2042255401611,4.01129074328643,32.3400013148785,-1.26743029182147E-5,-3.83927098817646E-5,1,-3.99624503097147E-8,130.347579956055,130.82292175293,49999.71484375,49999.71484375,50.3603254940438,5.51532144623053,6.82455158233643,132,1,0,0,1,0.238418579101562,31.7693061828613,2,1,1,130.347579956055,0,130.585250854492,,,,,,,,,,,,,,,,,,,,,,,,,,,,,,,,,
,3738619063.18191,127.567359924316,49999.71484375,-3.28383184826552E-8,3.5965087989542E-8,1,10,13.2042255401611,4.01125648817781,32.3400013148785,-3.11969830530879E-5,8.04236270772281E-6,1,1.38525072013253E-8,127.315711975098,127.819007873535,49999.71484375,49999.71484375,50.3786937642457,5.51546277883213,6.8160982131958,132,1,0,0,1,0.240097045898438,31.7693061828613,2,1,1,127.315711975098,0,127.567359924316,,,,,,,,,,,,,,,,,,,,,,,,,,,,,,,,,
,3738619123.22232,124.603412628174,49999.71484375,-4.30173607982121E-8,4.23326574506578E-8,1,10,13.2042255401611,4.01121016942743,32.3400013148785,-3.8749707398143E-5,-3.7717352097837E-6,1,2.14666716683517E-9,124.348045349121,124.858779907227,49999.71484375,49999.71484375,50.3552449086688,5.51484709178367,6.80357551574707,124,1,100,0,0,0.235443115234375,30.7917900085449,2,1,1,124.348045349121,0,124.603412628174,,,,,,,,,,,,,,,,,,,,,,,,,,,,,,,,,
,3738619183.30772,121.607349395752,49999.71484375,-4.27686845732349E-8,5.23537802272053E-8,1,10,13.2042255401611,4.01121118970348,32.3400013148785,-3.36897178761739E-5,-3.64351346679218E-5,1,-3.44185815216511E-8,121.380470275879,121.834228515625,49999.71484375,49999.71484375,50.399797734265,5.5155295346182,6.79266786575317,130,1,32,0,0,0.2398681640625,30.7917900085449,2,1,1,121.380470275879,0,121.607349395752,,,,,,,,,,,,,,,,,,,,,,,,,,,,,,,,,
,3738619243.13518,118.601253509521,49999.71484375,-1.87390370266981E-8,3.83664921929578E-8,1,10,13.2042255401611,4.01125172044033,32.3400013148785,-1.89609489330608E-5,1.24197621005183E-5,1,1.66617368602704E-8,118.354362487793,118.84814453125,49999.71484375,49999.71484375,50.3857284209188,5.51511182329527,6.7795991897583,132,1,0,0,1,0.2392578125,31.2805480957031,2,1,1,118.354362487793,0,118.601253509521,,,,,,,,,,,,,,,,,,,,,,,,,,,,,,,,,
,3738619303.10087,115.609672546387,49999.71484375,-4.0372087964074E-8,3.562108417892E-8,1,10,13.2042255401611,4.011195911295,32.3400013148785,-3.77679918719555E-5,5.93144070923211E-6,1,1.26066748959182E-8,115.368171691895,115.851173400879,49999.71484375,49999.71484375,50.3829927211015,5.51493475584489,6.7606372833252,132,1,0,0,1,0.237884521484375,30.7917900085449,2,1,1,115.368171691895,0,115.609672546387,,,,,,,,,,,,,,,,,,,,,,,,,,,,,,,,,
,3738619363.05751,112.615730285645,49999.71484375,-6.28727120242771E-8,5.03287982508442E-8,1,10,13.2042255401611,4.01112501386439,32.3400013148785,-5.61027685560997E-5,-9.09843314999179E-6,1,-8.72949970781915E-10,112.374198913574,112.857261657715,49999.71484375,49999.71484375,50.4009701770438,5.51475796342835,6.74907207489014,132,1,0,0,1,0.236663818359375,31.2805480957031,2,1,1,112.374198913574,0,112.615730285645,,,,,,,,,,,,,,,,,,,,,,,,,,,,,,,,,
,3738619423.10493,109.611164093018,49999.71484375,-1.55898789224727E-8,5.47791541584507E-8,1,10,13.2042255401611,4.01119402548343,32.3400013148785,-2.11526791808051E-5,4.66844475292287E-5,1,5.45156000936701E-8,109.354667663574,109.867660522461,49999.71484375,49999.71484375,50.3849467923996,5.51575421674534,6.73322343826294,132,1,0,0,1,0.239181518554687,31.2805480957031,2,1,1,109.354667663574,0,109.611164093018,,,,,,,,,,,,,,,,,,,,,,,,,,,,,,,,,
,3738619483.02161,106.630069732666,49999.71484375,-3.29836278148314E-8,3.98929051693963E-8,1,10,13.2042255401611,4.01115028183352,32.3400013148785,-2.78353554672465E-5,-1.55667967222561E-5,1,-1.25290821839618E-8,106.379707336426,106.880432128906,49999.71484375,49999.71484375,50.4193384472457,5.51456273605926,6.72105884552002,132,1,0,0,1,0.235977172851562,31.2805480957031,2,1,1,106.379707336426,0,106.630069732666,,,,,,,,,,,,,,,,,,,,,,,,,,,,,,,,,
,3738619543.08094,103.620464324951,49999.71484375,-2.30419267533815E-8,4.87007130162722E-8,1,10,13.2042255401611,4.01117561800199,32.3400013148785,-2.34153731084011E-5,1.59556954472123E-5,1,2.12531947807329E-8,103.36506652832,103.875862121582,49999.71484375,49999.71484375,50.2841167134188,5.5148382893954,6.70736122131348,131,1,68,0,0,0.239639282226562,31.2805480957031,2,1,1,103.36506652832,0,103.620464324951,,,,,,,,,,,,,,,,,,,,,,,,,,,,,,,,,
,3738619603.17241,100.617515563965,49999.71484375,-5.23227800645948E-8,3.59747417877154E-8,1,10,13.2042255401611,4.01117938805556,32.3400013148785,-4.38255987436576E-5,-2.69304533021135E-5,1,-2.23759985743786E-8,100.381507873535,100.853523254395,49999.71484375,49999.71484375,50.3654060794188,5.51472274944646,6.69827270507812,132,1,0,0,1,0.237808227539062,30.7917900085449,2,1,1,100.381507873535,0,100.617515563965,,,,,,,,,,,,,,,,,,,,,,,,,,,,,,,,,
,3738619662.97475,97.5881233215332,49999.71484375,-8.50547851539885E-9,3.88050000144192E-8,1,10,13.2042255401611,4.01114737383902,32.3400013148785,-6.56728038330901E-6,-8.14112245920388E-6,1,-7.84624788888777E-9,97.3594512939453,97.8167953491211,49999.71484375,49999.71484375,50.4279363609573,5.514805819473,6.67900705337524,132,1,0,0,1,0.2362060546875,30.7917900085449,2,1,1,97.3594512939453,0,97.5881233215332,,,,,,,,,,,,,,,,,,,,,,,,,,,,,,,,,
,3738619723.01092,94.6287689208984,49999.71484375,9.15711370003404E-9,4.05960337471342E-8,1,10,13.2042255401611,4.01111388075722,32.3400013148785,8.72454601711865E-6,-2.41567405617667E-6,1,-4.05648273545115E-9,94.3818283081055,94.8757095336914,49999.71484375,49999.71484375,50.4005793627842,5.51555597889229,6.66389417648315,132,1,0,0,1,0.2392578125,31.7693061828613,2,1,1,94.3818283081055,0,94.6287689208984,,,,,,,,,,,,,,,,,,,,,,,,,,,,,,,,,
,3738619782.9059,91.6085662841797,49999.71484375,1.54246313130282E-8,4.27740761654405E-8,1,10,13.2042255401611,4.01113213330411,32.3400013148785,1.36006896998426E-5,3.33450289269629E-6,1,1.44701162556443E-9,91.3389434814453,91.8781890869141,49999.71484375,49999.71484375,50.4697534867361,5.51499620021734,6.65672540664673,130,1,32,0,0,0.235977172851562,30.7917900085449,2,1,1,91.3389434814453,0,91.6085662841797,,,,,,,,,,,,,,,,,,,,,,,,,,,,,,,,,
,3738619843.0302,88.6130065917969,49999.71484375,-1.21711175809755E-8,3.94550402936005E-8,1,10,13.2042255401611,4.01121033841048,32.3400013148785,-1.36121637741977E-5,1.68334279578193E-5,1,2.06261328094406E-8,88.3650588989258,88.860954284668,49999.71484375,49999.71484375,50.3884641207361,5.5148720914633,6.63922023773193,132,1,0,0,1,0.240402221679687,30.7917900085449,2,1,1,88.3650588989258,0,88.6130065917969,,,,,,,,,,,,,,,,,,,,,,,,,,,,,,,,,
,3738619902.87744,85.6394882202148,49999.71484375,-1.16477248357162E-8,3.85499338217599E-8,1,10,13.2042255401611,4.01115965230391,32.3400013148785,-1.43007577695418E-5,2.47213111911673E-5,1,2.93705088543021E-8,85.3837356567383,85.8952407836914,49999.71484375,49999.71484375,50.4123037905726,5.51559463312945,6.62374877929688,132,1,0,0,1,0.236129760742187,31.2805480957031,2,1,1,85.3837356567383,0,85.6394882202148,,,,,,,,,,,,,,,,,,,,,,,,,,,,,,,,,
,3738619963.01538,82.6194000244141,49999.71484375,2.6923696616709E-8,4.56757262241316E-8,1,10,13.2042255401611,4.01120344610934,32.3400013148785,2.1602588950409E-5,2.02713067598757E-5,1,1.86865333410236E-8,82.3656158447266,82.8731842041016,49999.71484375,49999.71484375,50.411912976313,5.51523442807174,6.60421466827393,132,1,0,0,1,0.23895263671875,30.3030319213867,2,1,1,82.3656158447266,0,82.6194000244141,,,,,,,,,,,,,,,,,,,,,,,,,,,,,,,,,
,3738620023.03786,79.5940742492676,49999.71484375,4.44718404339908E-8,4.78849657166496E-8,1,10,13.2042255401611,4.01116092177541,32.3400013148785,3.73574095608678E-5,2.2159227265157E-5,1,1.82019084231869E-8,79.3377456665039,79.8504028320312,49999.71484375,49999.71484375,50.3376582669861,5.51535723095258,6.58827590942383,131,1,68,0,0,0.23651123046875,30.3030319213867,2,1,1,79.3377456665039,0,79.5940742492676,,,,,,,,,,,,,,,,,,,,,,,,,,,,,,,,,
,3738620082.84671,76.5686683654785,49999.71484375,5.41049989827454E-9,4.31747141443135E-8,1,10,13.2042255401611,4.01118014990027,32.3400013148785,-2.77646707778156E-7,3.5290785839922E-5,1,3.86667080467124E-8,76.31591796875,76.821418762207,49999.71484375,49999.71484375,50.3446929236592,5.51483546073837,6.57353353500366,130,1,32,0,0,0.241241455078125,31.7693061828613,2,1,1,76.31591796875,0,76.5686683654785,,,,,,,,,,,,,,,,,,,,,,,,,,,,,,,,,
,3738620142.80251,73.5513191223145,49999.71484375,-7.6750930118511E-9,5.15608241447503E-8,1,10,13.2042255401611,4.01118087235165,32.3400013148785,-1.13042699430976E-5,2.90025077868116E-5,1,3.35703456089471E-8,73.296630859375,73.8060073852539,49999.71484375,49999.71484375,50.3829927211015,5.51423357924647,6.55303430557251,130,1,32,0,0,0.240707397460938,30.7917900085449,2,1,1,73.296630859375,0,73.5513191223145,,,,,,,,,,,,,,,,,,,,,,,,,,,,,,,,,
,3738620202.83878,70.5267143249512,49999.71484375,1.88621638788059E-8,4.9532012846439E-8,1,10,13.2042255401611,4.01121621418773,32.3400013148785,1.57775604091458E-5,9.85467971615696E-6,1,8.2299748575752E-9,70.2755813598633,70.7778472900391,49999.71484375,49999.71484375,50.3947171488899,5.51435933443373,6.53287839889526,131,1,68,0,0,0.240249633789062,30.7917900085449,2,1,1,70.2755813598633,0,70.5267143249512,,,,,,,,,,,,,,,,,,,,,,,,,,,,,,,,,
,3738620262.96197,67.5029907226563,49999.71484375,-5.59126031536832E-8,4.97881952376573E-8,1,10,13.2042255401611,4.01117211188261,32.3400013148785,-4.86227745350727E-5,-1.66767295472567E-5,1,-1.03777225743642E-8,67.2547912597656,67.7511901855469,49999.71484375,49999.71484375,50.4380975317073,5.51502830914235,6.51500797271729,132,1,0,0,1,0.233230590820313,31.7693061828613,2,1,1,67.2547912597656,0,67.5029907226563,,,,,,,,,,,,,,,,,,,,,,,,,,,,,,,,,
,3738620322.74925,64.4964218139648,49999.71484375,3.68626136028418E-9,4.2016397558203E-8,1,10,13.2042255401611,4.01116680043268,32.3400013148785,1.65183621438409E-6,1.16012377157479E-5,1,1.24288324864805E-8,64.2535095214844,64.7393341064453,49999.71484375,49999.71484375,50.4439597456015,5.51381718088557,6.49677467346191,131,1,68,0,0,0.235595703125,30.7917900085449,2,1,1,64.2535095214844,0,64.4964218139648,,,,,,,,,,,,,,,,,,,,,,,,,,,,,,,,,
,3738620382.7405,61.4607563018799,49999.71484375,3.41847996821126E-8,5.08491784730412E-8,1,10,13.2042255401611,4.01118473763321,32.3400013148785,2.46409276223997E-5,4.45780807963985E-5,1,4.47956503530695E-8,61.2012405395508,61.720272064209,49999.71484375,49999.71484375,50.4470862596784,5.51391946740158,6.46669864654541,130,1,68,0,0,0.2386474609375,31.2805480957031,2,1,1,61.2012405395508,0,61.4607563018799,,,,,,,,,,,,,,,,,,,,,,,,,,,,,,,,,
,3738620442.6875,58.4534854888916,49999.71484375,1.43816132929906E-7,5.88594689147978E-8,1,10,13.2042255401611,4.0112756718686,32.3400013148785,0.000131060471407579,2.4135853694602E-6,1,-1.85794665106773E-8,58.2198791503906,58.6870918273926,49999.71484375,49999.71484375,50.4560749876496,5.51316241966401,6.44872093200684,132,1,0,0,1,0.235595703125,31.2805480957031,2,1,1,58.2198791503906,0,58.4534854888916,,,,,,,,,,,,,,,,,,,,,,,,,,,,,,,,,
,3738620502.72766,55.3916530609131,49999.71484375,4.12635944157149E-8,5.09943181374714E-8,1,10,13.2042255401611,4.01128875556502,32.3400013148785,3.43921897368653E-5,2.23998990005672E-5,1,1.89444739266557E-8,55.1377029418945,55.6456031799316,49999.71484375,49999.71484375,50.4310628750342,5.51399970969383,6.41890573501587,131,1,68,0,0,0.2362060546875,32.2580642700195,2,1,1,55.1377029418945,0,55.3916530609131,,,,,,,,,,,,,,,,,,,,,,,,,,,,,,,,,
,3738620562.69742,52.4018535614014,49999.71484375,2.09868673250926E-8,4.89573195274763E-8,1,10,13.2042255401611,4.01123072097292,32.3400013148785,1.41312711851141E-5,3.41042104325726E-5,1,3.50343123279772E-8,52.1528778076172,52.6508293151855,49999.71484375,49999.71484375,50.4803054717457,5.51370594959789,6.38832330703735,132,1,0,0,1,0.237579345703125,31.2805480957031,2,1,1,52.1528778076172,0,52.4018535614014,,,,,,,,,,,,,,,,,,,,,,,,,,,,,,,,,
,3738620622.73659,49.3621044158936,49999.71484375,7.62440270598096E-8,4.62808313109038E-8,1,10,13.2042255401611,4.0113302140385,32.3400013148785,6.39327915363857E-5,3.87927933508235E-5,1,3.21002641135142E-8,49.1044845581055,49.6197242736816,49999.71484375,49999.71484375,50.5451806388419,5.51272670815569,6.3592357635498,132,1,0,0,1,0.23468017578125,30.3030319213867,2,1,1,49.1044845581055,0,49.3621044158936,,,,,,,,,,,,,,,,,,,,,,,,,,,,,,,,,
,3738620682.78899,46.3382244110107,49999.71484375,7.00520235097753E-8,4.8617331562735E-8,1,10,13.2042255401611,4.01127994700311,32.3400013148785,5.1008010520476E-5,8.78962734341953E-5,1,8.79296709203807E-8,46.0986442565918,46.5778045654297,49999.71484375,49999.71484375,50.5584683236688,5.51407857146374,6.33129930496216,129,1,32,0,0,0.235977172851562,31.7693061828613,2,1,1,46.0986442565918,0,46.3382244110107,,,,,,,,,,,,,,,,,,,,,,,,,,,,,,,,,
,3738620742.62595,43.3214015960693,49999.71484375,5.22595045802413E-8,4.36520861801569E-8,1,10,13.2042255401611,4.01130327722515,32.3400013148785,4.56223041899122E-5,1.44121196616998E-5,1,8.38476331829526E-9,43.0672912597656,43.575511932373,49999.71484375,49999.71484375,50.5260307401207,5.51366749237351,6.28760385513306,130,1,32,0,0,0.23468017578125,30.3030319213867,2,1,1,43.0672912597656,0,43.3214015960693,,,,,,,,,,,,,,,,,,,,,,,,,,,,,,,,,
,3738620802.59417,40.2933197021484,49999.71484375,5.95638262792397E-8,4.71138090758814E-8,1,10,13.2042255401611,4.0112949360339,32.3400013148785,5.60199400732331E-5,-1.07515368334625E-5,1,-2.08362414807493E-8,40.0373382568359,40.5493011474609,49999.71484375,49999.71484375,50.477960586188,5.51441799611143,6.25065898895264,123,1,100,0,0,0.239410400390625,30.7917900085449,2,1,1,40.0373382568359,0,40.2933197021484,,,,,,,,,,,,,,,,,,,,,,,,,,,,,,,,,
,3738620862.60934,37.2844505310059,49999.71484375,5.76938469984032E-8,3.82216413409659E-8,1,10,13.2042255401611,4.01126052092203,32.3400013148785,4.12549110695016E-5,7.7487222186453E-5,1,7.81183810639938E-8,37.0402450561523,37.5286560058594,49999.71484375,49999.71484375,50.5791814794284,5.51432304104787,6.19361877441406,132,1,0,0,1,0.235977172851562,31.2805480957031,2,1,1,37.0402450561523,0,37.2844505310059,,,,,,,,,,,,,,,,,,,,,,,,,,,,,,,,,
,3738620922.64804,34.2556324005127,49999.71484375,6.86068227233304E-8,4.32304243780988E-8,1,10,13.2042255401611,4.01124728437678,32.3400013148785,5.93161255092416E-5,2.2812844941366E-5,1,1.5361071883222E-8,34.0066375732422,34.5046272277832,49999.71484375,49999.71484375,50.5037543273227,5.51367584127437,6.14217805862427,129,1,100,0,0,0.235595703125,31.2805480957031,2,1,1,34.0066375732422,0,34.2556324005127,,,,,,,,,,,,,,,,,,,,,,,,,,,,,,,,,
,3738620982.49114,31.2423286437988,49999.71484375,7.99305435091057E-8,4.41489954709693E-8,1,10,13.2042255401611,4.01124504152965,32.3400013148785,7.69838083029836E-5,-2.66635720787442E-5,1,-4.16445410052194E-8,30.9875450134277,31.4971122741699,49999.71484375,49999.71484375,50.5459622673611,5.51355662047879,6.07095384597778,131,1,68,0,0,0.240325927734375,31.2805480957031,2,1,1,30.9875450134277,0,31.2423286437988,,,,,,,,,,,,,,,,,,,,,,,,,,,,,,,,,
,3738621042.48037,28.2200155258179,49999.71484375,9.58265539523038E-8,4.9479008901805E-8,1,10,13.2042255401611,4.01124560920719,32.3400013148785,8.51777598924363E-5,1.61292312150508E-5,1,3.85936013031589E-9,27.9555244445801,28.4845066070557,49999.71484375,49999.71484375,50.5127430552938,5.513711509183,5.98956155776978,127,1,100,0,0,0.237884521484375,28.8367557525635,2,1,1,27.9555244445801,0,28.2200155258179,,,,,,,,,,,,,,,,,,,,,,,,,,,,,,,,,
,3738621102.44488,25.2064256668091,49999.71484375,1.05041338382725E-7,4.76534048755588E-8,1,10,13.2042255401611,4.01124704820212,32.3400013148785,9.56242035957335E-5,2.43522398623178E-6,1,-1.28182405611113E-8,24.9729747772217,25.4398765563965,49999.71484375,49999.71484375,50.5655029803419,5.51406620079,5.88756847381592,125,1,100,0,0,0.2362060546875,31.7693061828613,2,1,1,24.9729747772217,0,25.2064256668091,,,,,,,,,,,,,,,,,,,,,,,,,,,,,,,,,
,3738621162.4851,22.1872787475586,49999.71484375,1.35219111791891E-7,4.76955845010824E-8,1,10,13.2042255401611,4.01128243322289,32.3400013148785,0.000123155127732356,2.75026175726286E-6,1,-1.69309809657658E-8,21.9461765289307,22.4283809661865,49999.71484375,49999.71484375,50.518605269188,5.51395026501508,5.7610936164856,131,1,68,0,0,0.239028930664062,30.7917900085449,2,1,1,21.9461765289307,0,22.1872787475586,,,,,,,,,,,,,,,,,,,,,,,,,,,,,,,,,
,3738621222.41438,19.2109241485596,49999.71484375,2.04350373894429E-7,5.42393652161936E-8,1,10,13.2042255401611,4.01124843426285,32.3400013148785,0.000179644034754718,4.78993471824425E-5,1,2.33314429217557E-8,18.968505859375,19.4533424377441,49999.71484375,49999.71484375,50.5991130066688,5.51427128122978,5.57461738586426,129,1,68,0,0,0.2398681640625,30.7917900085449,2,1,1,18.968505859375,0,19.2109241485596,,,,,,,,,,,,,,,,,,,,,,,,,,,,,,,,,
,3738621282.55054,16.2244434356689,49999.71484375,2.61774508633336E-7,4.52123906807442E-8,1,10,13.2042255401611,4.01133375634677,32.3400013148785,0.000234556050187397,3.14692797712185E-5,1,-3.54000828237819E-9,15.9742183685303,16.4746685028076,49999.71484375,49999.71484375,50.660861659688,5.51388890653041,5.32128572463989,128,1,68,0,0,0.2392578125,30.3030319213867,2,1,1,15.9742183685303,0,16.2244434356689,,,,,,,,,,,,,,,,,,,,,,,,,,,,,,,,,
,3738621342.35486,13.2684664726257,49999.71484375,2.70203334057713E-7,4.6054965744102E-8,1,10,13.2042255401611,4.01133342405427,32.3400013148785,0.000238358310223431,5.78286658398687E-5,1,2.46899526173762E-8,13.0221519470215,13.51478099823,49999.71484375,49999.71484375,50.6557810743131,5.51437133718979,5.00504732131958,130,1,32,0,0,0.239181518554687,31.7693061828613,2,1,1,13.0221519470215,0,13.2684664726257,,,,,,,,,,,,,,,,,,,,,,,,,,,,,,,,,
,3738621402.36582,10.3484935760498,49999.71484375,3.71824079397623E-7,4.88419707050799E-8,1,10,13.2042255401611,4.01134435428239,32.3400013148785,0.00033638429813378,2.29368821438531E-5,1,-2.93642751479034E-8,10.1115503311157,10.5854368209839,49999.71484375,49999.71484375,50.8410270333708,5.51481899179509,4.60245513916016,128,1,100,0,0,0.23681640625,31.2805480957031,2,1,1,10.1115503311157,0,10.3484935760498,,,,,,,,,,,,,,,,,,,,,,,,,,,,,,,,,
,3738621462.32108,7.1188485622406,49999.71484375,4.46535200876519E-7,4.93558394792075E-8,1,10,13.2042255401611,4.01138873505917,32.3400013148785,0.000391919635933748,0.000109069487193154,1,5.58991259339128E-8,6.87608051300049,7.36161661148071,49999.71484375,49999.71484375,51.0137669361208,5.51475821606262,4.25995492935181,132,1,0,0,1,0.236740112304687,32.7468223571777,6,1,1,6.87608051300049,0,7.1188485622406,,,,,,,,,,,,,,,,,,,,,,,,,,,,,,,,,
,3738621522.4641,4.2526638507843,49999.71484375,5.62936592956691E-7,4.19739197345203E-8,1,10,13.2042255401611,4.01139526749218,32.3400013148785,0.000499958191206483,9.78084414731749E-5,1,2.60837825640868E-8,4.01807355880737,4.48725414276123,49999.71484375,49999.71484375,51.28890017489,5.51586623974575,3.5153865814209,132,1,0,0,1,0.236129760742187,31.2805480957031,6,1,1,4.01807355880737,0,4.2526638507843,,,,,,,,,,,,,,,,,,,,,,,,,,,,,,,,,
,3738621582.28006,2.84455800056458,49999.71484375,6.08726341073811E-7,4.18729372530775E-8,1,10,13.2042255401611,4.01147035982634,32.3400013148785,0.000538511721507111,0.00012016099634247,1,4.43005701857901E-8,2.84342336654663,2.84569263458252,49999.71484375,49999.71484375,51.4866521902554,5.51560058793986,2.93087959289551,132,1,0,0,1,0.237503051757813,30.3030319213867,6,1,1,2.84569263458252,0,2.84455800056458,,,,,,,,,,,,,,,,,,,,,,,,,,,,,,,,,
,3738621642.32439,2.8474543094635,49999.71484375,5.66835611564699E-7,4.37198949146034E-8,1,10,13.2042255401611,4.01143065621711,32.3400013148785,0.00050362412000324,9.71623249321779E-5,1,2.47828499223775E-8,2.84736132621765,2.84754729270935,49999.71484375,49999.71484375,51.4065352670343,5.51560916226681,2.93302583694458,132,1,0,0,1,0.239181518554687,30.3030319213867,6,1,1,2.84754729270935,0,2.8474543094635,,,,,,,,,,,,,,,,,,,,,,,,,,,,,,,,,
,3738621702.23989,2.84462106227875,49999.71484375,5.74251989365048E-7,4.02572640745193E-8,1,10,13.2042255401611,4.01147815752958,32.3400013148785,0.000507136223886334,0.00011929864107709,1,4.84365750477217E-8,2.84344816207886,2.84579396247864,49999.71484375,49999.71484375,51.4378004078035,5.51586823037959,2.93751287460327,132,1,0,0,1,0.237884521484375,30.3030319213867,6,1,1,2.84344816207886,0,2.84462106227875,,,,,,,,,,,,,,,,,,,,,,,,,,,,,,,,,
,3738621762.21874,2.83623218536377,49999.71484375,5.97578219997854E-7,4.30524476721123E-8,1,10,13.2042255401611,4.01146779475785,32.3400013148785,0.000532270673565166,9.34821022221445E-5,1,1.61173837706952E-8,2.83572936058044,2.83673501014709,49999.71484375,49999.71484375,51.4475707642939,5.51557547342629,2.94407391548157,130,1,68,0,0,0.23773193359375,30.7917900085449,6,1,1,2.83572936058044,0,2.83623218536377,,,,,,,,,,,,,,,,,,,,,,,,,,,,,,,,,
,3738621822.18576,2.85680782794952,49999.71484375,5.87520325441825E-7,4.29988070054492E-8,1,10,13.2042255401611,4.01147670056692,32.3400013148785,0.000528966595658041,5.37035054714619E-5,1,-2.68757545767028E-8,2.85668992996216,2.85692572593689,49999.71484375,49999.71484375,51.4467891357747,5.51551101768503,2.95112776756287,132,1,0,0,1,0.235595703125,30.7917900085449,6,1,1,2.85668992996216,0,2.85680782794952,,,,,,,,,,,,,,,,,,,,,,,,,,,,,,,,,
,3738621882.25814,2.82343077659607,49999.71484375,6.23343521563854E-7,4.02996659839374E-8,1,10,13.2042255401611,4.01148916541825,32.3400013148785,0.000554863172915141,9.995817300195E-5,1,1.95459274283537E-8,2.81649446487427,2.83036708831787,49999.71484375,49999.71484375,51.5226071021401,5.51561869835401,2.94580388069153,132,1,0,0,1,0.231857299804687,30.3030319213867,6,1,1,2.81649446487427,0,2.82343077659607,,,,,,,,,,,,,,,,,,,,,,,,,,,,,,,,,
,3738621942.15155,2.77692747116089,49999.71484375,6.16637737107715E-7,5.46971611268758E-8,1,10,13.2042255401611,4.01150858180337,32.3400013148785,0.000549261801739384,9.64269208542673E-5,1,1.65885936360127E-8,2.767662525177,2.78619241714478,49999.71484375,49999.71484375,51.5566079427266,5.51622311909331,2.91991281509399,132,1,0,0,1,0.23834228515625,31.2805480957031,6,1,1,2.767662525177,0,2.77692747116089,,,,,,,,,,,,,,,,,,,,,,,,,,,,,,,,,
,3738622002.29655,2.77145755290985,49999.71484375,6.17671112404955E-7,4.22982037735417E-8,1,10,13.2042255401611,4.01147283592083,32.3400013148785,0.000550212716342145,9.63285403835955E-5,1,1.63272194472139E-8,2.75700521469116,2.78590989112854,49999.71484375,49999.71484375,51.4463983215151,5.51536453354079,2.92449498176575,132,1,0,0,1,0.235671997070313,30.7917900085449,6,1,1,2.78590989112854,0,2.77145755290985,,,,,,,,,,,,,,,,,,,,,,,,,,,,,,,,,
,3738622062.17351,2.73584079742432,49999.71484375,5.99083645331503E-7,4.35466842199856E-8,1,10,13.2042255401611,4.0114422048862,32.3400013148785,0.000530063347310279,0.000117661493239493,1,4.29337633753786E-8,2.73033905029297,2.74134254455566,49999.71484375,49999.71484375,51.4077077098131,5.51650241677569,2.9128885269165,132,1,0,0,1,0.239410400390625,29.3255138397217,6,1,1,2.73017287254334,0,2.73584079742432,,,,,,,,,,,,,,,,,,,,,,,,,,,,,,,,,
,3738622122.20932,2.21412265300751,49999.71484375,5.68516237212976E-7,4.58640146948317E-8,1,10,13.2042255401611,4.01144044583592,32.3400013148785,0.000504783452441634,9.97206357605278E-5,1,2.73945422821863E-8,2.15053868293762,2.27770662307739,49999.71484375,49999.71484375,51.6511849935535,5.51624226626782,2.59251713752747,132,1,0,0,1,0.236587524414062,30.7917900085449,6,1,1,2.15053868293762,0,2.21412265300751,,,,,,,,,,,,,,,,,,,,,,,,,,,,,,,,,
,3738622182.07518,2.00016927719116,49999.71484375,5.9130217209503E-7,1.46262622570702E-7,1,10,13.2042255401611,4.01149188291605,32.3400013148785,0.00052630872706683,9.50480799084379E-5,1,1.87960521808034E-8,2.0001060962677,2.00023245811462,49999.71484375,49999.71484375,51.6042872823997,5.51616233474854,2.48152923583984,132,1,0,0,1,0.239715576171875,30.7917900085449,5,1,1,2.0001060962677,0,2.00016927719116,,,,,,,,,,,,,,,,,,,,,,,,,,,,,,,,,
,3738622212.04642,1.99991887807846,49999.71484375,6.14064418394275E-7,1.43284717399852E-7,1,10,13.2042255401611,4.01150043842659,32.3400013148785,0.000538399441795913,0.000153935964693165,1,8.12763771983939E-8,1.99977338314056,2.00006437301636,49999.71484375,49999.71484375,51.6074137964766,5.51576266130068,2.48245096206665,132,1,0,0,1,0.236740112304687,30.7917900085449,1,1,1,2.00006437301636,0,1.99991887807846,,,,,,,,,,,,,,,,,,,,,,,,,,,,,,,,,