File: data/quartz-holder/180619_empty-quartz_4mm_3T.dat
[Header]
; MPMS3 Data File (default extension .dat)
; Copyright (c) 2007, Quantum Design, Inc. All rights reserved.
TITLE,
FILEOPENTIME,3738602513.6835,06/19/2018,8:41 pm
BYAPP,MPMS3,1.0,1.1
INFO,MPMS3 Measurement Release 1.1.16 Build 388, MultiVu Release 2.3.4.15,APPNAME
INFO,0,MOMENT_UNITS
INFO,empty quartz,SAMPLE_MATERIAL
INFO,,SAMPLE_COMMENT
INFO,1,SAMPLE_MASS
INFO,,SAMPLE_VOLUME
INFO,,SAMPLE_MOLECULAR_WEIGHT
INFO,,SAMPLE_SIZE
INFO,,SAMPLE_SHAPE
INFO,Standard,SAMPLE_HOLDER
INFO,Standard,SAMPLE_HOLDER_DETAIL
INFO,66,SAMPLE_OFFSET
DATATYPE,COMMENT,1
DATATYPE,TIME,2
STARTUPAXIS,X,2
STARTUPAXIS,Y1,5
FIELDGROUP, VSM,2,3,4,5,6,8,9,10,11,14,15
FIELDGROUP, DC, 2,3,4,14,34,35,36,37,38,39,40,41,42,43,44,45,46,47
STARTUPGROUP, All
[Data]
Comment,Time Stamp (sec),Temperature (K),Magnetic Field (Oe),Moment (emu),M. Std. Err. (emu),Transport Action,Averaging Time (sec),Frequency (Hz),Peak Amplitude (mm),Center Position (mm),Lockin Signal' (V),Lockin Signal (V),Range,M. Quad. Signal (emu),Min. Temperature (K),Max. Temperature (K),Min. Field (Oe),Max. Field (Oe),Mass (grams),Motor Lag (deg),Pressure (Torr),Measure Count,Measurement Number,SQUID Status (code),Motor Status (code),Measure Status (code),Motor Current (amps),Motor Temp. (C),Temp. Status (code),Field Status (code),Chamber Status (code),Chamber Temp (K),Redirection State,Average Temp (K),Rotation Angle (deg),Rotator state,DC Moment Fixed Ctr (emu),DC Moment Err Fixed Ctr (emu),DC Moment Free Ctr (emu),DC Moment Err Free Ctr (emu),DC Fixed Fit,DC Free Fit,DC Calculated Center (mm),DC Calculated Center Err (mm),DC Scan Length (mm),DC Scan Time (s),DC Number of Points,DC Squid Drift,DC Min V (V),DC Max V (V),DC Scans per Measure,Map 01,Map 02,Map 03,Map 04,Map 05,Map 06,Map 07,Map 08,Map 09,Map 10,Map 11,Map 12,Map 13,Map 14,Map 15,Map 16
,3738602578.84382,299.998321533203,29999.72265625,-6.44427197601582E-8,2.38393014214991E-8,1,10,13.2042255401611,4.01137120965782,32.3400013148785,-5.91227208395179E-5,1.57780664677091E-6,1,1.12991380807775E-8,299.998321533203,299.998321533203,29999.72265625,29999.72265625,50.5811355507265,5.51733849060214,7.83205604553223,132,1,0,0,1,0.238876342773438,30.7917900085449,1,1,1,299.998321533203,0,299.998321533203,,,,,,,,,,,,,,,,,,,,,,,,,,,,,,,,,
,3738602639.22244,298.596038818359,29999.72265625,-6.4177641470604E-8,2.57738637375789E-8,1,10,13.2042255401611,4.01131823370916,32.3400013148785,-5.97198471259575E-5,7.25916135412436E-6,1,1.76133138481432E-8,298.355194091797,298.836883544922,29999.72265625,29999.72265625,50.4975012991688,5.5177575620741,7.76157093048096,132,1,0,0,1,0.240707397460938,31.7693061828613,2,1,1,298.355194091797,0,298.596038818359,,,,,,,,,,,,,,,,,,,,,,,,,,,,,,,,,
,3738602698.99931,295.475326538086,29999.72265625,-5.20009099903945E-8,2.46997335964208E-8,1,10,13.2042255401611,4.0112574682797,32.3400013148785,-4.33499976845079E-5,-2.81670641440606E-5,1,-2.38056006779628E-8,295.217956542969,295.732696533203,29999.72265625,29999.72265625,50.5139154980726,5.51734360020556,7.71681499481201,132,1,0,0,1,0.239486694335938,32.2580642700195,2,1,1,295.217956542969,0,295.475326538086,,,,,,,,,,,,,,,,,,,,,,,,,,,,,,,,,
,3738602758.98391,292.40673828125,29999.72265625,-6.18370039258886E-8,2.23442262953434E-8,1,10,13.2042255401611,4.01126993154838,32.3400013148785,-5.45193359076114E-5,-1.3426208846332E-5,1,-5.86537235651222E-9,292.145843505859,292.667633056641,29999.72265625,29999.72265625,50.5350194680919,5.51752184894802,7.67495536804199,130,1,32,0,0,0.23773193359375,30.3030319213867,2,1,1,292.145843505859,0,292.40673828125,,,,,,,,,,,,,,,,,,,,,,,,,,,,,,,,,
,3738602819.01344,289.346862792969,29999.72265625,-4.48079488108259E-8,2.18362990539382E-8,1,10,13.2042255401611,4.0112293618032,32.3400013148785,-4.16248069228663E-5,4.5996956960552E-6,1,1.17735831941454E-8,289.084228515625,289.609497070313,29999.72265625,29999.72265625,50.5615948377457,5.51754404035708,7.63033151626587,132,1,0,0,1,0.240478515625,31.2805480957031,2,1,1,289.084228515625,0,289.346862792969,,,,,,,,,,,,,,,,,,,,,,,,,,,,,,,,,
,3738602879.10731,286.328598022461,29999.72265625,-5.36785132008282E-8,2.26535577786932E-8,1,10,13.2042255401611,4.01125078360611,32.3400013148785,-4.70504054694639E-5,-1.35170223987114E-5,1,-7.17414908707068E-9,286.079925537109,286.577270507813,29999.72265625,29999.72265625,50.6163088340919,5.51812605265171,7.58712148666382,132,1,0,0,1,0.239410400390625,31.2805480957031,2,1,1,286.079925537109,0,286.328598022461,,,,,,,,,,,,,,,,,,,,,,,,,,,,,,,,,
,3738602938.9328,283.308929443359,29999.72265625,-7.33726664991598E-8,2.28017382355646E-8,1,10,13.2042255401611,4.01120109893219,32.3400013148785,-6.29628427882356E-5,-2.75911180395683E-5,1,-2.00001079931308E-8,283.054931640625,283.562927246094,29999.72265625,29999.72265625,50.503363513063,5.51889001772836,7.55252456665039,132,1,0,0,1,0.2386474609375,30.3030319213867,2,1,1,283.054931640625,0,283.308929443359,,,,,,,,,,,,,,,,,,,,,,,,,,,,,,,,,
,3738602998.90313,280.332443237305,29999.72265625,-5.92333100827772E-8,2.07683697221388E-8,1,10,13.2042255401611,4.01121573473614,32.3400013148785,-5.35946397947868E-5,-3.58759518558998E-6,1,4.75186620786077E-9,280.074371337891,280.590515136719,29999.72265625,29999.72265625,50.5967681211111,5.51793748611802,7.51685571670532,132,1,0,0,1,0.234909057617187,30.7917900085449,2,1,1,280.074371337891,0,280.332443237305,,,,,,,,,,,,,,,,,,,,,,,,,,,,,,,,,
,3738603058.94339,277.337829589844,29999.72265625,-5.81441564672518E-8,2.43975428438165E-8,1,10,13.2042255401611,4.01127803836727,32.3400013148785,-5.18539186370915E-5,-8.6350368344977E-6,1,-1.05373734615398E-9,277.088897705078,277.586761474609,29999.72265625,29999.72265625,50.6147455770534,5.51850798611491,7.48670768737793,130,1,32,0,0,0.235595703125,31.2805480957031,2,1,1,277.088897705078,0,277.337829589844,,,,,,,,,,,,,,,,,,,,,,,,,,,,,,,,,
,3738603119.05373,274.326293945313,29999.72265625,-6.520521591141E-8,2.22772392532524E-8,1,10,13.2042255401611,4.01120885923717,32.3400013148785,-5.85017243498206E-5,-7.30275718191621E-6,1,1.48065894590474E-9,274.069915771484,274.582672119141,29999.72265625,29999.72265625,50.5553418095919,5.51837293878982,7.45483922958374,132,1,0,0,1,0.2362060546875,30.7917900085449,2,1,1,274.069915771484,0,274.326293945313,,,,,,,,,,,,,,,,,,,,,,,,,,,,,,,,,
,3738603178.83873,271.337203979492,29999.72265625,-6.77068945484438E-8,2.16270348138334E-8,1,10,13.2042255401611,4.01115782487067,32.3400013148785,-6.0484422407466E-5,-9.3438445876903E-6,1,-4.32023676074751E-10,271.082336425781,271.592071533203,29999.72265625,29999.72265625,50.5037543273227,5.51822909911069,7.42546558380127,132,1,0,0,1,0.238189697265625,31.2805480957031,2,1,1,271.082336425781,0,271.337203979492,,,,,,,,,,,,,,,,,,,,,,,,,,,,,,,,,
,3738603238.84412,268.359619140625,29999.72265625,-5.36043185349666E-8,2.21838913780016E-8,1,10,13.2042255401611,4.0112214841758,32.3400013148785,-4.99620948982866E-5,6.62437139489161E-6,1,1.53393286158428E-8,268.110687255859,268.608551025391,29999.72265625,29999.72265625,50.6053660348227,5.51790218134156,7.40329599380493,132,1,0,0,1,0.232391357421875,31.7693061828613,2,1,1,268.110687255859,0,268.359619140625,,,,,,,,,,,,,,,,,,,,,,,,,,,,,,,,,
,3738603298.7837,265.364852905273,29999.72265625,-5.03037187411227E-8,2.18684278091765E-8,1,10,13.2042255401611,4.01120421170648,32.3400013148785,-4.33289192819899E-5,-1.78210924451978E-5,1,-1.24871364168629E-8,265.121459960938,265.608245849609,29999.72265625,29999.72265625,50.5850436933227,5.51811077162043,7.38103151321411,132,1,0,0,1,0.233840942382813,31.7693061828613,2,1,1,265.121459960938,0,265.364852905273,,,,,,,,,,,,,,,,,,,,,,,,,,,,,,,,,
,3738603358.80462,262.348083496094,29999.72265625,-6.42758571951705E-8,1.91869229887771E-8,1,10,13.2042255401611,4.01124050040125,32.3400013148785,-5.89395506359772E-5,1.39101423658208E-6,1,1.10656481370429E-8,262.090087890625,262.606079101562,29999.72265625,29999.72265625,50.5256399258611,5.51876592799964,7.35638093948364,132,1,0,0,1,0.23773193359375,31.7693061828613,2,1,1,262.090087890625,0,262.348083496094,,,,,,,,,,,,,,,,,,,,,,,,,,,,,,,,,
,3738603418.74842,259.354354858398,29999.72265625,-5.80755683856969E-8,1.94011098399914E-8,1,10,13.2042255401611,4.01121395523393,32.3400013148785,-4.99098738001575E-5,-2.13415701353599E-5,1,-1.52742120925163E-8,259.115539550781,259.593170166016,29999.72265625,29999.72265625,50.6241251192842,5.51824102505279,7.3358998298645,132,1,0,0,1,0.232391357421875,31.7693061828613,2,1,1,259.115539550781,0,259.354354858398,,,,,,,,,,,,,,,,,,,,,,,,,,,,,,,,,
,3738603478.73987,256.375762939453,29999.72265625,-6.51934724764155E-8,1.98397752766484E-8,1,10,13.2042255401611,4.01117668210649,32.3400013148785,-5.67636568877468E-5,-1.89722078540942E-5,1,-1.15716577893401E-8,256.123474121094,256.628051757813,29999.72265625,29999.72265625,50.5612040234861,5.51825482565386,7.32066631317139,132,1,0,0,1,0.23468017578125,31.7693061828613,2,1,1,256.123474121094,0,256.375762939453,,,,,,,,,,,,,,,,,,,,,,,,,,,,,,,,,
,3738603538.69875,253.38191986084,29999.72265625,-7.0200250245679E-8,2.42405486156106E-8,1,10,13.2042255401611,4.01119242939843,32.3400013148785,-6.18795604494094E-5,-1.53188150412105E-5,1,-6.74500901239314E-9,253.141067504883,253.622772216797,29999.72265625,29999.72265625,50.6061476633419,5.51739570231965,7.29901885986328,132,1,0,0,1,0.24017333984375,31.2805480957031,2,1,1,253.129791259766,0,253.38191986084,,,,,,,,,,,,,,,,,,,,,,,,,,,,,,,,,
,3738603598.69816,250.381446838379,29999.72265625,-6.02186539842242E-8,2.16083293919677E-8,1,10,13.2042255401611,4.01115039124376,32.3400013148785,-5.55503734337067E-5,3.5549421235159E-6,1,1.28854565857607E-8,250.136627197266,250.626266479492,29999.72265625,29999.72265625,50.4846044286015,5.51769662902097,7.28003931045532,132,1,0,0,1,0.23773193359375,30.7917900085449,2,1,1,250.136627197266,0,250.381446838379,,,,,,,,,,,,,,,,,,,,,,,,,,,,,,,,,
,3738603658.66634,247.343238830566,29999.72265625,-6.12986439011637E-8,2.17930098246658E-8,1,10,13.2042255401611,4.01117909779887,32.3400013148785,-5.57214677048125E-5,-1.96273528528332E-6,1,6.87454071345915E-9,247.10124206543,247.585235595703,29999.72265625,29999.72265625,50.5057083986207,5.51804535072396,7.27022790908813,132,1,0,0,1,0.239486694335938,31.2805480957031,2,1,1,247.10124206543,0,247.343238830566,,,,,,,,,,,,,,,,,,,,,,,,,,,,,,,,,
,3738603718.73369,244.380500793457,29999.72265625,-3.25842034858817E-8,2.62327968758762E-8,1,10,13.2042255401611,4.01101654510484,32.3400013148785,-3.16990303998294E-5,1.30241622387274E-5,1,1.93874929474182E-8,244.12419128418,244.636810302734,29999.72265625,29999.72265625,50.4502127737553,5.51742069523864,7.25205898284912,132,1,0,0,1,0.237808227539062,31.2805480957031,2,1,1,244.12419128418,0,244.380500793457,,,,,,,,,,,,,,,,,,,,,,,,,,,,,,,,,
,3738603778.79879,241.365158081055,29999.72265625,-3.36351860842002E-8,2.16554787831804E-8,1,10,13.2042255401611,4.01113718056364,32.3400013148785,-3.05209403845119E-5,-1.43843520282231E-6,1,3.36786377235975E-9,241.128936767578,241.601379394531,29999.72265625,29999.72265625,50.4197292615053,5.5168411017929,7.2391185760498,132,1,0,0,1,0.239105224609375,32.2580642700195,2,1,1,241.128936767578,0,241.365158081055,,,,,,,,,,,,,,,,,,,,,,,,,,,,,,,,,
,3738603838.59547,238.382637023926,29999.72265625,-5.39342572508897E-9,1.97486311215778E-8,1,10,13.2042255401611,4.01116011502664,32.3400013148785,-4.12213280015652E-6,-5.44816407080887E-6,1,-5.29497426632017E-9,238.12043762207,238.644836425781,29999.72265625,29999.72265625,50.4189476329861,5.51622995424435,7.22103214263916,132,1,0,0,1,0.238876342773438,31.7693061828613,2,1,1,238.12043762207,0,238.382637023926,,,,,,,,,,,,,,,,,,,,,,,,,,,,,,,,,
,3738603898.56925,235.393699645996,29999.72265625,-4.30051290770224E-8,1.95998253083065E-8,1,10,13.2042255401611,4.01125470367935,32.3400013148785,-3.94444933626694E-5,9.9497610632967E-7,1,7.47559577930152E-9,235.149200439453,235.638198852539,29999.72265625,29999.72265625,50.493202342313,5.51519880235772,7.21159076690674,132,1,0,0,1,0.241012573242187,30.7917900085449,2,1,1,235.149200439453,0,235.393699645996,,,,,,,,,,,,,,,,,,,,,,,,,,,,,,,,,
,3738603958.54545,232.404182434082,29999.72265625,-3.47391726937786E-8,1.94567338572475E-8,1,10,13.2042255401611,4.0112631718016,32.3400013148785,-3.16469321999919E-5,-6.56803791689095E-7,1,4.40539042199412E-9,232.158889770508,232.649475097656,29999.72265625,29999.72265625,50.3736131788707,5.51535305839231,7.19056224822998,132,1,0,0,1,0.236282348632813,31.7693061828613,2,1,1,232.158889770508,0,232.404182434082,,,,,,,,,,,,,,,,,,,,,,,,,,,,,,,,,
,3738604018.72668,229.36238861084,29999.72265625,-3.3753943506719E-8,1.97261395504639E-8,1,10,13.2042255401611,4.01118445858404,32.3400013148785,-3.03624056353453E-5,-3.24725531062273E-6,1,1.36258582581178E-9,229.118728637695,229.606048583984,29999.72265625,29999.72265625,50.4517760307938,5.51664201254221,7.17883586883545,132,1,0,0,1,0.239028930664062,31.2805480957031,2,1,1,229.118728637695,0,229.36238861084,,,,,,,,,,,,,,,,,,,,,,,,,,,,,,,,,
,3738604078.5155,226.400428771973,29999.72265625,-2.34246399724546E-8,1.85627855741128E-8,1,10,13.2042255401611,4.01125414161264,32.3400013148785,-2.12138895653984E-5,-1.29160648992732E-6,1,2.0214184191949E-9,226.164962768555,226.635894775391,29999.72265625,29999.72265625,50.5174328264092,5.51642656096688,7.17059850692749,132,1,0,0,1,0.236129760742187,30.3030319213867,2,1,1,226.164962768555,0,226.400428771973,,,,,,,,,,,,,,,,,,,,,,,,,,,,,,,,,
,3738604138.50601,223.420524597168,29999.72265625,-3.12268919414872E-8,1.94905257347037E-8,1,10,13.2042255401611,4.01128203945778,32.3400013148785,-2.80757673449669E-5,-3.10286638842437E-6,1,1.15030192818788E-9,223.178009033203,223.663040161133,29999.72265625,29999.72265625,50.5076624699188,5.5148134089972,7.15507698059082,132,1,0,0,1,0.235748291015625,30.7917900085449,2,1,1,223.178009033203,0,223.420524597168,,,,,,,,,,,,,,,,,,,,,,,,,,,,,,,,,
,3738604198.5256,220.402801513672,29999.72265625,-2.32836781022529E-8,1.92179864148385E-8,1,10,13.2042255401611,4.01121509494424,32.3400013148785,-2.19382181271013E-5,4.47674351088004E-6,1,8.45144814889351E-9,220.160232543945,220.645370483398,29999.72265625,29999.72265625,50.4646729013611,5.51500880203009,7.13908576965332,132,1,0,0,1,0.234756469726562,31.7693061828613,2,1,1,220.160232543945,0,220.402801513672,,,,,,,,,,,,,,,,,,,,,,,,,,,,,,,,,
,3738604258.63696,217.388847351074,29999.72265625,-2.89711376802799E-8,2.76230073482944E-8,1,10,13.2042255401611,4.01132929999938,32.3400013148785,-2.35007299133873E-5,-2.00959707640142E-5,1,-1.8186392632325E-8,217.148361206055,217.629333496094,29999.72265625,29999.72265625,50.4427873028226,5.51528494764396,7.1344895362854,132,1,0,0,1,0.237655639648438,31.2805480957031,2,1,1,217.148361206055,0,217.388847351074,,,,,,,,,,,,,,,,,,,,,,,,,,,,,,,,,
,3738604318.43291,214.40657043457,29999.72265625,-1.78085695125677E-8,2.05058221726234E-8,1,10,13.2042255401611,4.01128775752308,32.3400013148785,-1.77764934034453E-5,1.01593343421928E-5,1,1.39960418583353E-8,214.155426025391,214.65771484375,29999.72265625,29999.72265625,50.4380975317073,5.51502149419091,7.11400365829468,132,1,0,0,1,0.2398681640625,30.3030319213867,2,1,1,214.155426025391,0,214.40657043457,,,,,,,,,,,,,,,,,,,,,,,,,,,,,,,,,
,3738604378.40233,211.437217712402,29999.72265625,-3.7819308463008E-8,3.05469776430604E-8,1,10,13.2042255401611,4.01126576215684,32.3400013148785,-3.62127327028409E-5,1.11789794275635E-5,1,1.80971419416149E-8,211.193313598633,211.681121826172,29999.72265625,29999.72265625,50.4935931565727,5.51460235053725,7.10570430755615,132,1,0,0,1,0.236663818359375,31.2805480957031,2,1,1,211.193313598633,0,211.437217712402,,,,,,,,,,,,,,,,,,,,,,,,,,,,,,,,,
,3738604438.38053,208.425170898438,29999.72265625,-2.30060617657801E-8,2.50758896153654E-8,1,10,13.2042255401611,4.01120470177951,32.3400013148785,-2.49960384338643E-5,2.68588346513917E-5,1,3.34410203960514E-8,208.166091918945,208.68424987793,29999.72265625,29999.72265625,50.4978921134284,5.5147823554455,7.08698558807373,132,1,0,0,1,0.233917236328125,31.2805480957031,2,1,1,208.166091918945,0,208.425170898438,,,,,,,,,,,,,,,,,,,,,,,,,,,,,,,,,
,3738604498.40398,205.438919067383,29999.72265625,-2.4010235131296E-8,2.35201955745089E-8,1,10,13.2042255401611,4.01125021444222,32.3400013148785,-2.19940943378432E-5,3.6518234225383E-7,1,3.96086678373616E-9,205.191375732422,205.686462402344,29999.72265625,29999.72265625,50.4697534867361,5.51542053928071,7.07721900939941,132,1,0,0,1,0.238571166992187,29.3255138397217,2,1,1,205.191375732422,0,205.438919067383,,,,,,,,,,,,,,,,,,,,,,,,,,,,,,,,,
,3738604558.33298,202.430252075195,29999.72265625,2.83319393689076E-9,3.31317200110859E-8,1,10,13.2042255401611,4.01119111436151,32.3400013148785,2.87004063043217E-6,-1.90046346616148E-6,1,-2.54455256841179E-9,202.17643737793,202.684066772461,29999.72265625,29999.72265625,50.460764758765,5.51659904391856,7.06235456466675,132,1,0,0,1,0.236740112304687,31.2805480957031,2,1,1,202.17643737793,0,202.430252075195,,,,,,,,,,,,,,,,,,,,,,,,,,,,,,,,,
,3738604618.49019,199.456184387207,29999.72265625,4.42790991792946E-9,2.90550637442057E-8,1,10,13.2042255401611,4.01129833778825,32.3400013148785,1.71351907945071E-6,1.57660292955857E-5,1,1.69758722911517E-8,199.209243774414,199.703125,29999.72265625,29999.72265625,50.4568566161688,5.51534646796036,7.05217885971069,132,1,0,0,1,0.240478515625,31.7693061828613,2,1,1,199.209243774414,0,199.456184387207,,,,,,,,,,,,,,,,,,,,,,,,,,,,,,,,,
,3738604678.30454,196.424179077148,29999.72265625,-2.60305088418406E-8,2.75589108633257E-8,1,10,13.2042255401611,4.01129965968136,32.3400013148785,-2.62342982836868E-5,1.65432218610348E-5,1,2.23515219026288E-8,196.171096801758,196.677261352539,29999.72265625,29999.72265625,50.3724407360919,5.51493964694971,7.03842306137085,132,1,0,0,1,0.235595703125,31.7693061828613,2,1,1,196.171096801758,0,196.424179077148,,,,,,,,,,,,,,,,,,,,,,,,,,,,,,,,,
,3738604738.33772,193.446815490723,29999.72265625,-1.97382565403256E-9,4.42180952610005E-8,1,10,13.2042255401611,4.01128883567222,32.3400013148785,-8.30069761614261E-6,4.39116424133219E-5,1,4.93982299103633E-8,193.202590942383,193.691040039062,29999.72265625,29999.72265625,50.440442417265,5.51503925220504,7.0295205116272,132,1,0,0,1,0.23834228515625,31.7693061828613,2,1,1,193.202590942383,0,193.446815490723,,,,,,,,,,,,,,,,,,,,,,,,,,,,,,,,,
,3738604798.25328,190.426895141602,29999.72265625,-4.08498292874855E-8,2.90684851726321E-8,1,10,13.2042255401611,4.01136459617112,32.3400013148785,-3.71000220772415E-5,-1.55055320721042E-6,1,4.31008772123704E-9,190.189819335938,190.663970947266,29999.72265625,29999.72265625,50.5690203086784,5.51441174550729,7.01292610168457,132,1,0,0,1,0.235214233398438,32.2580642700195,2,1,1,190.189819335938,0,190.426895141602,,,,,,,,,,,,,,,,,,,,,,,,,,,,,,,,,
,3738604858.42251,187.439895629883,29999.72265625,-3.16394410520056E-8,2.76093462152981E-8,1,10,13.2042255401611,4.01131390268016,32.3400013148785,-2.75043593803333E-5,-9.51526081454628E-6,1,-5.95949462637409E-9,187.170196533203,187.709594726562,29999.72265625,29999.72265625,50.4623280158034,5.51502691991543,7.00434112548828,132,1,0,0,1,0.23468017578125,31.7693061828613,2,1,1,187.170196533203,0,187.439895629883,,,,,,,,,,,,,,,,,,,,,,,,,,,,,,,,,
,3738604918.21069,184.456558227539,29999.72265625,-4.08658962744649E-8,3.05512826150909E-8,1,10,13.2042255401611,4.01135446402164,32.3400013148785,-4.2501621831157E-5,3.48591682515725E-5,1,4.50282213566846E-8,184.219375610352,184.693740844727,29999.72265625,29999.72265625,50.4345802033707,5.51397582164916,6.99636030197144,132,1,0,0,1,0.239334106445313,31.7693061828613,2,1,1,184.219375610352,0,184.456558227539,,,,,,,,,,,,,,,,,,,,,,,,,,,,,,,,,
,3738604978.19396,181.473594665527,29999.72265625,-7.53807353563238E-9,2.77866794273659E-8,1,10,13.2042255401611,4.01133448500605,32.3400013148785,-1.12255060185598E-5,2.93135298942188E-5,1,3.38959015317245E-8,181.228637695313,181.718551635742,29999.72265625,29999.72265625,50.4896850139765,5.51438655291292,6.98170471191406,132,1,0,0,1,0.233917236328125,31.2805480957031,2,1,1,181.228637695313,0,181.473594665527,,,,,,,,,,,,,,,,,,,,,,,,,,,,,,,,,
,3738605038.19819,178.464828491211,29999.72265625,-2.84747515045089E-8,2.90282049645317E-8,1,10,13.2042255401611,4.01129310133809,32.3400013148785,-3.26130628970919E-5,4.45601026403978E-5,1,5.40443090970979E-8,178.225357055664,178.704299926758,29999.72265625,29999.72265625,50.4400516030053,5.51616625399364,6.96999311447144,132,1,0,0,1,0.23681640625,31.2805480957031,2,1,1,178.225357055664,0,178.464828491211,,,,,,,,,,,,,,,,,,,,,,,,,,,,,,,,,
,3738605098.22948,175.479461669922,29999.72265625,6.28284736903055E-9,3.05232224459683E-8,1,10,13.2042255401611,4.01134191260443,32.3400013148785,6.51793914623231E-6,-5.24877501122928E-6,1,-6.79914762998219E-9,175.232498168945,175.726425170898,29999.72265625,29999.72265625,50.4263731039188,5.51431601064668,6.95987939834595,132,1,0,0,1,0.235595703125,31.2805480957031,2,1,1,175.232498168945,0,175.479461669922,,,,,,,,,,,,,,,,,,,,,,,,,,,,,,,,,
,3738605158.28239,172.442504882813,29999.72265625,-2.85142010456332E-8,2.41691049911851E-8,1,10,13.2042255401611,4.01133495546633,32.3400013148785,-2.63295893312594E-5,1.84524624683726E-6,1,6.28236401637284E-9,172.213439941406,172.671569824219,29999.72265625,29999.72265625,50.4388791602265,5.5145270318911,6.95077848434448,132,1,0,0,1,0.237045288085938,31.7693061828613,2,1,1,172.213439941406,0,172.442504882813,,,,,,,,,,,,,,,,,,,,,,,,,,,,,,,,,
,3738605218.13116,169.498092651367,29999.72265625,-1.39729601079795E-8,2.93991937167643E-8,1,10,13.2042255401611,4.01130807831951,32.3400013148785,-1.4389124454215E-5,1.0953362346666E-5,1,1.43163965481175E-8,169.260772705078,169.735412597656,29999.72265625,29999.72265625,50.4060507624188,5.51451961871993,6.93436050415039,132,1,0,0,1,0.237884521484375,30.3030319213867,2,1,1,169.260772705078,0,169.498092651367,,,,,,,,,,,,,,,,,,,,,,,,,,,,,,,,,
,3738605278.10026,166.480621337891,29999.72265625,-2.54254536462302E-8,3.02209951806389E-8,1,10,13.2042255401611,4.0113635359956,32.3400013148785,-2.1028010097086E-5,-1.49117585163958E-5,1,-1.29133864218072E-8,166.231430053711,166.72981262207,29999.72265625,29999.72265625,50.4380975317073,5.51446751984739,6.93204593658447,132,1,0,0,1,0.238037109375,31.7693061828613,2,1,1,166.231430053711,0,166.480621337891,,,,,,,,,,,,,,,,,,,,,,,,,,,,,,,,,
,3738605338.06039,163.496147155762,29999.72265625,-3.073517564236E-8,3.21501533927184E-8,1,10,13.2042255401611,4.01147644438698,32.3400013148785,-2.95873786268564E-5,1.01359129705136E-5,1,1.58815801278095E-8,163.254821777344,163.73747253418,29999.72265625,29999.72265625,50.4537301020919,5.5143746904945,6.92059659957886,132,1,0,0,1,0.239028930664062,30.7917900085449,2,1,1,163.254821777344,0,163.496147155762,,,,,,,,,,,,,,,,,,,,,,,,,,,,,,,,,
,3738605398.14182,160.494827270508,29999.72265625,-3.46461434971196E-8,3.56087843111237E-8,1,10,13.2042255401611,4.01143125622258,32.3400013148785,-3.07463335104607E-5,-6.18344358716217E-6,1,-1.78839116591984E-9,160.241195678711,160.748458862305,29999.72265625,29999.72265625,50.3943263346303,5.51459950843378,6.90902471542358,132,1,0,0,1,0.23895263671875,31.2805480957031,2,1,1,160.241195678711,0,160.494827270508,,,,,,,,,,,,,,,,,,,,,,,,,,,,,,,,,
,3738605458.02431,157.499717712402,29999.72265625,-2.23370967029831E-8,3.42644801713622E-8,1,10,13.2042255401611,4.01144741077169,32.3400013148785,-2.46632282993106E-5,2.87276042063552E-5,1,3.5428851073922E-8,157.260025024414,157.739410400391,29999.72265625,29999.72265625,50.4330169463323,5.51482783339709,6.89263010025024,132,1,0,0,1,0.239028930664062,30.7917900085449,2,1,1,157.260025024414,0,157.499717712402,,,,,,,,,,,,,,,,,,,,,,,,,,,,,,,,,
,3738605518.02032,154.50560760498,29999.72265625,-4.99112425300097E-8,2.98438284347808E-8,1,10,13.2042255401611,4.01140805375783,32.3400013148785,-4.58645741103014E-5,1.71562694108029E-6,1,9.3031971536389E-9,154.265548706055,154.745666503906,29999.72265625,29999.72265625,50.481087100265,5.5146396297899,6.88571262359619,132,1,0,0,1,0.237655639648438,31.2805480957031,2,1,1,154.265548706055,0,154.50560760498,,,,,,,,,,,,,,,,,,,,,,,,,,,,,,,,,
,3738605577.97767,151.516754150391,29999.72265625,-1.97856503583809E-8,2.50594937495127E-8,1,10,13.2042255401611,4.01140479255364,32.3400013148785,-2.04011878657252E-5,1.56826386332123E-5,1,2.04644376759205E-8,151.278289794922,151.755218505859,29999.72265625,29999.72265625,50.4123037905726,5.5142280212947,6.87316942214966,132,1,0,0,1,0.237960815429687,31.2805480957031,2,1,1,151.278289794922,0,151.516754150391,,,,,,,,,,,,,,,,,,,,,,,,,,,,,,,,,
,3738605637.94986,148.51789855957,29999.72265625,-2.60777502582955E-8,2.2753574013263E-8,1,10,13.2042255401611,4.01139304969113,32.3400013148785,-2.16828244916865E-5,-1.45166919383173E-5,1,-1.23748962963253E-8,148.274307250977,148.761489868164,29999.72265625,29999.72265625,50.4556841733899,5.51475868084098,6.86240339279175,132,1,0,0,1,0.238265991210938,31.2805480957031,2,1,1,148.274307250977,0,148.51789855957,,,,,,,,,,,,,,,,,,,,,,,,,,,,,,,,,
,3738605697.9272,145.503936767578,29999.72265625,-3.11540960760394E-8,2.09429117465552E-8,1,10,13.2042255401611,4.0114453102738,32.3400013148785,-3.02386396311407E-5,1.1952508706998E-5,1,1.7975066884794E-8,145.247436523438,145.760437011719,29999.72265625,29999.72265625,50.4291088037361,5.51441077959704,6.85177898406982,132,1,0,0,1,0.2392578125,32.2580642700195,2,1,1,145.247436523438,0,145.503936767578,,,,,,,,,,,,,,,,,,,,,,,,,,,,,,,,,
,3738605758.01645,142.501266479492,29999.72265625,1.28974510595131E-9,3.5536868381786E-8,1,10,13.2042255401611,4.01144096071666,32.3400013148785,1.73424411677331E-6,-3.75523020081261E-6,1,-4.39002959407608E-9,142.242401123047,142.760131835938,29999.72265625,29999.72265625,50.4502127737553,5.51408620518304,6.84139680862427,132,1,0,0,1,0.2392578125,30.7917900085449,2,1,1,142.242401123047,0,142.501266479492,,,,,,,,,,,,,,,,,,,,,,,,,,,,,,,,,
,3738605818.0737,139.520408630371,29999.72265625,-1.9399992966944E-8,3.08503211323239E-8,1,10,13.2042255401611,4.01143198633667,32.3400013148785,-2.23410450183353E-5,3.11742709354488E-5,1,3.77304239128967E-8,139.28352355957,139.757293701172,29999.72265625,29999.72265625,50.4248098468803,5.5138924526659,6.82964706420898,132,1,0,0,1,0.23834228515625,30.7917900085449,2,1,1,139.28352355957,0,139.520408630371,,,,,,,,,,,,,,,,,,,,,,,,,,,,,,,,,
,3738605877.86599,136.512664794922,29999.72265625,7.57079558770465E-9,3.30274735624475E-8,1,10,13.2042255401611,4.01145973326102,32.3400013148785,9.08741129465078E-6,-1.46583064056304E-5,1,-1.75113551960565E-8,136.272201538086,136.753128051758,29999.72265625,29999.72265625,50.4736616293323,5.5136741564134,6.82045555114746,132,1,0,0,1,0.240478515625,31.7693061828613,2,1,1,136.272201538086,0,136.512664794922,,,,,,,,,,,,,,,,,,,,,,,,,,,,,,,,,
,3738605937.84039,133.524696350098,29999.72265625,-2.24096490595842E-8,2.22408025722978E-8,1,10,13.2042255401611,4.01142872398576,32.3400013148785,-2.07876156831105E-5,2.08630556398598E-6,1,5.64863741314789E-9,133.279418945312,133.769973754883,29999.72265625,29999.72265625,50.4502127737553,5.51443749986401,6.80838918685913,132,1,0,0,1,0.238418579101562,30.7917900085449,2,1,1,133.279418945312,0,133.524696350098,,,,,,,,,,,,,,,,,,,,,,,,,,,,,,,,,
,3738605997.82409,130.522659301758,29999.72265625,-2.34465004778051E-8,2.37967925317555E-8,1,10,13.2042255401611,4.01139824968831,32.3400013148785,-2.09699149352431E-5,-3.08386544995623E-6,1,2.0547644942145E-11,130.278244018555,130.767074584961,29999.72265625,29999.72265625,50.4908574567553,5.51414595319716,6.79342699050903,132,1,0,0,1,0.237884521484375,30.7917900085449,2,1,1,130.278244018555,0,130.522659301758,,,,,,,,,,,,,,,,,,,,,,,,,,,,,,,,,
,3738606057.89219,127.529582977295,29999.72265625,3.559870785888E-9,2.51870886664974E-8,1,10,13.2042255401611,4.01151853114588,32.3400013148785,2.38273254041351E-6,5.88382039696137E-6,1,6.05254177808334E-9,127.28271484375,127.77645111084,29999.72265625,29999.72265625,50.4806962860053,5.512769457392,6.78507041931152,132,1,0,0,1,0.238494873046875,34.2131004333496,2,1,1,127.28271484375,0,127.529582977295,,,,,,,,,,,,,,,,,,,,,,,,,,,,,,,,,
,3738606117.77182,124.523262023926,29999.72265625,6.97086653886846E-9,2.63584915290658E-8,1,10,13.2042255401611,4.01153558329696,32.3400013148785,3.76281004433739E-6,1.76250560901565E-5,1,1.86767001732095E-8,124.287475585938,124.759048461914,29999.72265625,29999.72265625,50.3650152651592,5.51362688443229,6.7700252532959,132,1,0,0,1,0.238571166992187,32.7468223571777,2,1,1,124.287475585938,0,124.523262023926,,,,,,,,,,,,,,,,,,,,,,,,,,,,,,,,,
,3738606177.78116,121.552127838135,29999.72265625,1.35260171724901E-8,2.49551700292911E-8,1,10,13.2042255401611,4.01154440530233,32.3499999940395,1.29603272236569E-5,-4.04904544649294E-6,1,-6.52883620125646E-9,121.303237915039,121.80101776123,29999.72265625,29999.72265625,50.3681417792361,5.51252211043607,6.75285482406616,130,1,68,0,0,0.239028930664062,31.2805480957031,2,1,1,121.303237915039,0,121.552127838135,,,,,,,,,,,,,,,,,,,,,,,,,,,,,,,,,
,3738606237.74319,118.531555175781,29999.72265625,-2.71849314928938E-8,2.06440477213591E-8,1,10,13.2042255401611,4.01151663171177,32.3400013148785,-2.42915548396165E-5,-3.7315634378394E-6,1,-1.50415851739969E-10,118.288597106934,118.774513244629,29999.72265625,29999.72265625,50.4060507624188,5.51387068184367,6.74490642547607,132,1,0,0,1,0.2386474609375,32.7468223571777,2,1,1,118.288597106934,0,118.531555175781,,,,,,,,,,,,,,,,,,,,,,,,,,,,,,,,,
,3738606297.78265,115.516983032227,29999.72265625,-1.93362603844883E-8,2.27911764046674E-8,1,10,13.2042255401611,4.01149581611061,32.3499999940395,-1.91009168045225E-5,9.66573966520239E-6,1,1.36691958785852E-8,115.276809692383,115.75715637207,29999.72265625,29999.72265625,50.5060992128803,5.51465374326179,6.73015546798706,132,1,0,0,1,0.240325927734375,31.2805480957031,2,1,1,115.276809692383,0,115.516983032227,,,,,,,,,,,,,,,,,,,,,,,,,,,,,,,,,
,3738606357.69759,112.544471740723,29999.72265625,-6.82065321385361E-10,2.05631651435637E-8,1,10,13.2042255401611,4.01153188893219,32.3400013148785,-2.20249509233813E-6,1.06731655854219E-5,1,1.20355160649731E-8,112.304374694824,112.784568786621,29999.72265625,29999.72265625,50.5100073554765,5.51300933699433,6.71169662475586,132,1,0,0,1,0.23895263671875,31.7693061828613,2,1,1,112.304374694824,0,112.544471740723,,,,,,,,,,,,,,,,,,,,,,,,,,,,,,,,,
,3738606417.84422,109.524700164795,29999.72265625,-2.93776059165102E-8,2.83345208496225E-8,1,10,13.2042255401611,4.01152422259518,32.3400013148785,-2.81699186984574E-5,8.93733058699423E-6,1,1.43402594020726E-8,109.260627746582,109.788772583008,29999.72265625,29999.72265625,50.4326261320726,5.51354076941676,6.70180606842041,132,1,0,0,1,0.238723754882813,31.7693061828613,2,1,1,109.260627746582,0,109.524700164795,,,,,,,,,,,,,,,,,,,,,,,,,,,,,,,,,
,3738606477.65094,106.546508789062,29999.72265625,-2.44609849596905E-8,2.26480044363278E-8,1,10,13.2042255401611,4.01157792497993,32.3400013148785,-2.09884604698113E-5,-9.23511689111978E-6,1,-6.7072326749447E-9,106.298439025879,106.794578552246,29999.72265625,29999.72265625,50.4674086011784,5.51351248856436,6.68518304824829,132,1,0,0,1,0.235824584960938,31.2805480957031,2,1,1,106.298439025879,0,106.546508789062,,,,,,,,,,,,,,,,,,,,,,,,,,,,,,,,,
,3738606537.62141,103.555004119873,29999.72265625,-3.87060969090191E-8,2.78226646103617E-8,1,10,13.2042255401611,4.01166140666238,32.3400013148785,-3.33371815087001E-5,-1.37704901587947E-5,1,-9.67036489199502E-9,103.311653137207,103.798355102539,29999.72265625,29999.72265625,50.481087100265,5.51377926681848,6.67189788818359,132,1,0,0,1,0.238418579101562,31.2805480957031,2,1,1,103.311653137207,0,103.555004119873,,,,,,,,,,,,,,,,,,,,,,,,,,,,,,,,,
,3738606597.62779,100.56600189209,29999.72265625,-3.31617360992612E-8,2.37251317377334E-8,1,10,13.2042255401611,4.01159458005388,32.3400013148785,-3.23867162532895E-5,1.4058506845035E-5,1,2.06261604952051E-8,100.316452026367,100.815551757813,29999.72265625,29999.72265625,50.46584534414,5.51406298099007,6.65998411178589,132,1,0,0,1,0.238418579101562,31.2805480957031,2,1,1,100.316452026367,0,100.56600189209,,,,,,,,,,,,,,,,,,,,,,,,,,,,,,,,,
,3738606657.59951,97.590934753418,29999.72265625,-9.11514476119903E-9,2.5215765620313E-8,1,10,13.2042255401611,4.01159191247368,32.3400013148785,-5.035575436232E-6,-2.22685778823966E-5,1,-2.3551202518806E-8,97.3240280151367,97.8578414916992,29999.72265625,29999.72265625,50.4545117306111,5.51434162653033,6.64619588851929,130,1,68,0,0,0.23834228515625,31.7693061828613,2,1,1,97.3240280151367,0,97.590934753418,,,,,,,,,,,,,,,,,,,,,,,,,,,,,,,,,
,3738606717.71735,94.5676116943359,29999.72265625,-9.97307551918568E-9,2.26907275882904E-8,1,10,13.2042255401611,4.01158781814925,32.3400013148785,-9.39889816882992E-6,1.92274199785721E-6,1,3.62552305305268E-9,94.3254013061523,94.8098220825195,29999.72265625,29999.72265625,50.4783514004476,5.51292069094879,6.62941741943359,132,1,0,0,1,0.239028930664062,31.7693061828613,2,1,1,94.3254013061523,0,94.5676116943359,,,,,,,,,,,,,,,,,,,,,,,,,,,,,,,,,
,3738606777.54647,91.5761985778809,29999.72265625,-2.97457895208795E-8,2.24105137169065E-8,1,10,13.2042255401611,4.01156759603526,32.3400013148785,-2.83772058955588E-5,8.06101777207367E-6,1,1.34146944042463E-8,91.3188095092773,91.8335876464844,29999.72265625,29999.72265625,50.528766439938,5.51276382958081,6.61678695678711,132,1,0,0,1,0.234603881835938,31.7693061828613,2,1,1,91.3188095092773,0,91.5761985778809,,,,,,,,,,,,,,,,,,,,,,,,,,,,,,,,,
,3738606837.57605,88.5879974365234,29999.72265625,3.52224326476096E-9,2.70614415718839E-8,1,10,13.2042255401611,4.01162532614211,32.3400013148785,3.13177092267757E-6,5.89785386708055E-7,1,1.38326119608488E-10,88.34619140625,88.8298034667969,29999.72265625,29999.72265625,50.447477073938,5.51294168315983,6.59429836273193,131,1,68,0,0,0.237503051757813,31.7693061828613,2,1,1,88.34619140625,0,88.5879974365234,,,,,,,,,,,,,,,,,,,,,,,,,,,,,,,,,
,3738606897.53164,85.6164703369141,29999.72265625,-3.30198210815269E-9,2.92950441358716E-8,1,10,13.2042255401611,4.01157791706275,32.3400013148785,6.48314511714687E-8,-2.08338320822866E-5,1,-2.28071527751462E-8,85.3740005493164,85.8589401245117,29999.72265625,29999.72265625,50.528766439938,5.51297966876302,6.58166217803955,132,1,0,0,1,0.237350463867187,30.7917900085449,2,1,1,85.3740005493164,0,85.6164703369141,,,,,,,,,,,,,,,,,,,,,,,,,,,,,,,,,
,3738606957.61318,82.5708961486816,29999.72265625,7.02136950411642E-9,2.973116783699E-8,1,10,13.2042255401611,4.01156204853931,32.3400013148785,1.16779343476574E-5,-3.55587133244369E-5,1,-4.07996903852052E-8,82.3127822875977,82.8290100097656,29999.72265625,29999.72265625,50.4623280158034,5.51332526340558,6.56374454498291,132,1,0,0,1,0.239028930664062,31.2805480957031,2,1,1,82.3127822875977,0,82.5708961486816,,,,,,,,,,,,,,,,,,,,,,,,,,,,,,,,,
,3738607017.46407,79.5756492614746,29999.72265625,-4.25167309728849E-10,3.44623237614117E-8,1,10,13.2042255401611,4.01155380113635,32.3400013148785,-1.40199613374875E-6,6.84956495372009E-6,1,7.72193732794052E-9,79.3209686279297,79.8303298950195,29999.72265625,29999.72265625,50.4908574567553,5.51348716119647,6.54356813430786,132,1,0,0,1,0.237274169921875,30.7917900085449,2,1,1,79.3209686279297,0,79.5756492614746,,,,,,,,,,,,,,,,,,,,,,,,,,,,,,,,,
,3738607077.61738,76.5194625854492,29999.72265625,1.73591206811314E-8,3.7123087856976E-8,1,10,13.2042255401611,4.0115251518133,32.3400013148785,1.42222246215414E-5,1.10972789106468E-5,1,9.84047041002247E-9,76.2664794921875,76.7724456787109,29999.72265625,29999.72265625,50.3919814490726,5.51353649484744,6.52458810806274,130,1,68,0,0,0.237350463867187,30.7917900085449,2,1,1,76.2664794921875,0,76.5194625854492,,,,,,,,,,,,,,,,,,,,,,,,,,,,,,,,,
,3738607137.42637,73.5166015625,29999.72265625,3.23029293388829E-8,2.91812729990524E-8,1,10,13.2042255401611,4.01158997852967,32.3400013148785,3.08194931244493E-5,-8.77114303014925E-6,1,-1.45869954451523E-8,73.2586441040039,73.7745590209961,29999.72265625,29999.72265625,50.508444098438,5.51309860099567,6.5115761756897,131,1,68,0,0,0.237884521484375,31.2805480957031,2,1,1,73.2586441040039,0,73.5166015625,,,,,,,,,,,,,,,,,,,,,,,,,,,,,,,,,
,3738607197.40134,70.5004577636719,29999.72265625,5.06983915141221E-8,3.46716042141752E-8,1,10,13.2042255401611,4.01157278705756,32.3400013148785,4.65696024916282E-5,-1.59850208391775E-6,1,-9.288570275693E-9,70.2419662475586,70.7589492797852,29999.72265625,29999.72265625,50.4763973291496,5.5138154946351,6.48769092559814,132,1,0,0,1,0.239028930664062,31.7693061828613,2,1,1,70.2419662475586,0,70.5004577636719,,,,,,,,,,,,,,,,,,,,,,,,,,,,,,,,,
,3738607257.40687,67.4739837646484,29999.72265625,-1.59307169003034E-8,3.33657850960706E-8,1,10,13.2042255401611,4.01160652649711,32.3400013148785,-1.58984773561573E-5,9.05164221407419E-6,1,1.24781913517451E-8,67.2276077270508,67.7203598022461,29999.72265625,29999.72265625,50.4720983722938,5.5122863847591,6.47232723236084,132,1,0,0,1,0.238113403320313,31.7693061828613,2,1,1,67.2276077270508,0,67.4739837646484,,,,,,,,,,,,,,,,,,,,,,,,,,,,,,,,,
,3738607317.43935,64.457878112793,29999.72265625,-2.23122014407382E-8,3.03610587399851E-8,1,10,13.2042255401611,4.0116327914302,32.3400013148785,-2.14284114553421E-5,7.007975164933E-6,1,1.1137158855115E-8,64.2071228027344,64.7086334228516,29999.72265625,29999.72265625,50.4763973291496,5.51259313949401,6.44521045684814,132,1,0,0,1,0.23895263671875,31.7693061828613,2,1,1,64.2071228027344,0,64.457878112793,,,,,,,,,,,,,,,,,,,,,,,,,,,,,,,,,
,3738607377.55705,61.4468612670898,29999.72265625,-1.09408735845546E-10,2.66322742123013E-8,1,10,13.2042255401611,4.01162343517761,32.3400013148785,-2.22018501923222E-7,8.24755366045058E-7,1,9.38385335477164E-10,61.2192878723145,61.6744346618652,29999.72265625,29999.72265625,50.4549025448707,5.51216557990382,6.42323446273804,130,1,32,0,0,0.234909057617187,30.3030319213867,2,1,1,61.2192878723145,0,61.4468612670898,,,,,,,,,,,,,,,,,,,,,,,,,,,,,,,,,
,3738607437.31108,58.4210681915283,29999.72265625,2.50998734184707E-8,2.70008553146398E-8,1,10,13.2042255401611,4.01163948392802,32.3400013148785,2.12713929754215E-5,1.12729251448023E-5,1,8.89100646154909E-9,58.1693801879883,58.6727561950684,29999.72265625,29999.72265625,50.440442417265,5.51213020354881,6.39977169036865,132,1,0,0,1,0.238265991210938,31.7693061828613,2,1,1,58.1693801879883,0,58.4210681915283,,,,,,,,,,,,,,,,,,,,,,,,,,,,,,,,,
,3738607497.28773,55.4039859771729,29999.72265625,-3.49449990142322E-9,2.82306716373669E-8,1,10,13.2042255401611,4.01159292678738,32.3400013148785,-5.3304125325456E-6,1.44418795931264E-5,1,1.66653721846133E-8,55.1459693908691,55.6620025634766,29999.72265625,29999.72265625,50.4455230026399,5.51179796002474,6.37788057327271,132,1,0,0,1,0.238723754882813,31.2805480957031,2,1,1,55.1459693908691,0,55.4039859771729,,,,,,,,,,,,,,,,,,,,,,,,,,,,,,,,,
,3738607557.27177,52.3818264007568,29999.72265625,5.83552053235428E-8,3.75324385536506E-8,1,10,13.2042255401611,4.01159075379052,32.3400013148785,4.98079062414729E-5,2.38117023603395E-5,1,1.79912717702197E-8,52.1492309570313,52.6144218444824,29999.72265625,29999.72265625,50.4885125711976,5.51250440763367,6.33769035339356,130,1,32,0,0,0.237655639648438,31.2805480957031,2,1,1,52.1492309570313,0,52.3818264007568,,,,,,,,,,,,,,,,,,,,,,,,,,,,,,,,,
,3738607617.35991,49.3793182373047,29999.72265625,3.17728748157595E-8,3.391040313595E-8,1,10,13.2042255401611,4.011669201697,32.3400013148785,2.79003590138597E-5,7.69061281407265E-6,1,3.89806318752539E-9,49.1526489257812,49.6059875488281,29999.72265625,29999.72265625,50.5150879408515,5.51195539836944,6.31127643585205,130,1,32,0,0,0.23651123046875,30.7917900085449,2,1,1,49.1526489257812,0,49.3793182373047,,,,,,,,,,,,,,,,,,,,,,,,,,,,,,,,,
,3738607677.22038,46.3500881195068,29999.72265625,3.69145125696509E-8,2.86236425411145E-8,1,10,13.2042255401611,4.01167364804023,32.3400013148785,3.55593072796486E-5,-1.23137524493092E-5,1,-1.92300631445561E-8,46.0930252075195,46.6071510314941,29999.72265625,29999.72265625,50.4799146574861,5.51232985384815,6.27458381652832,132,1,0,0,1,0.237579345703125,32.2580642700195,2,1,1,46.0930252075195,0,46.3500881195068,,,,,,,,,,,,,,,,,,,,,,,,,,,,,,,,,
,3738607737.36226,43.3138256072998,29999.72265625,2.66999678508886E-8,3.18876380314636E-8,1,10,13.2042255401611,4.01173083790692,32.3400013148785,2.38154621254968E-5,3.9679315168814E-6,1,4.86097440469178E-10,43.0654716491699,43.5621795654297,29999.72265625,29999.72265625,50.3978436629669,5.51061967587793,6.22702360153198,130,1,32,0,0,0.23773193359375,32.2580642700195,2,1,1,43.0654716491699,0,43.3138256072998,,,,,,,,,,,,,,,,,,,,,,,,,,,,,,,,,
,3738607797.37886,40.2865314483643,29999.72265625,2.9548226777978E-8,2.601888485593E-8,1,10,13.2042255401611,4.01171156903599,32.3400013148785,2.64774747308501E-5,3.568886678071E-6,1,-3.81463106610076E-10,40.0424346923828,40.5306282043457,29999.72265625,29999.72265625,50.5385367964284,5.51141935797475,6.17675876617432,132,1,0,0,1,0.2386474609375,30.3030319213867,2,1,1,40.0424346923828,0,40.2865314483643,,,,,,,,,,,,,,,,,,,,,,,,,,,,,,,,,
,3738607857.242,37.3016777038574,29999.72265625,4.95046838335449E-8,2.63612068045811E-8,1,10,13.2042255401611,4.01172403155004,32.3400013148785,4.42381495130825E-5,6.80425636512294E-6,1,2.83296268518776E-10,37.0456619262695,37.5576934814453,29999.72265625,29999.72265625,50.4357526461496,5.51127860257976,6.12263965606689,132,1,0,0,1,0.238800048828125,31.2805480957031,2,1,1,37.0456619262695,0,37.3016777038574,,,,,,,,,,,,,,,,,,,,,,,,,,,,,,,,,
,3738607917.14462,34.2900485992432,29999.72265625,7.82431620620933E-8,2.65205980302422E-8,1,10,13.2042255401611,4.0116767005568,32.3400013148785,6.72618109782763E-5,2.8706403547971E-5,1,2.05206819264324E-8,34.0458793640137,34.5342178344727,29999.72265625,29999.72265625,50.498282927688,5.51104449293591,6.06593751907349,129,1,100,0,0,0.238037109375,32.2580642700195,2,1,1,34.0458793640137,0,34.2900485992432,,,,,,,,,,,,,,,,,,,,,,,,,,,,,,,,,
,3738607977.1106,31.2652816772461,29999.72265625,5.49005028946481E-8,2.94060273735414E-8,1,10,13.2042255401611,4.0116689155848,32.3400013148785,4.50304882932618E-5,3.47724121144045E-5,1,3.07570529796537E-8,31.0123023986816,31.5182609558105,29999.72265625,29999.72265625,50.5170420121496,5.51155853165127,5.979079246521,132,1,0,0,1,0.238418579101562,30.7917900085449,2,1,1,31.0123023986816,0,31.2652816772461,,,,,,,,,,,,,,,,,,,,,,,,,,,,,,,,,
,3738608037.21495,28.2578039169312,29999.72265625,9.40152480244047E-8,2.76594996387932E-8,1,10,13.2042255401611,4.01170973710979,32.3400013148785,8.56912255424374E-5,1.57934256015326E-6,1,-1.21443237424795E-8,28.0180587768555,28.4975490570068,29999.72265625,29999.72265625,50.5971589353707,5.51260168074928,5.88741445541382,130,1,68,0,0,0.237884521484375,32.2580642700195,2,1,1,28.0180587768555,0,28.2578039169312,,,,,,,,,,,,,,,,,,,,,,,,,,,,,,,,,
,3738608097.07701,25.2510242462158,29999.72265625,9.61651523564598E-8,2.6785512220288E-8,1,10,13.2042255401611,4.0117078447187,32.3400013148785,8.40959250411657E-5,2.56413025272355E-5,1,1.44414856515868E-8,25.0079536437988,25.4940948486328,29999.72265625,29999.72265625,50.5545601810727,5.51196713769017,5.76864194869995,126,1,100,0,0,0.237808227539062,31.7693061828613,2,1,1,25.0079536437988,0,25.2510242462158,,,,,,,,,,,,,,,,,,,,,,,,,,,,,,,,,
,3738608157.20459,22.2654705047607,29999.72265625,1.2105058144925E-7,2.66766023492565E-8,1,10,13.2042255401611,4.01174711305699,32.3400013148785,0.000107351154420769,2.21972461484302E-5,1,6.90829734702157E-9,22.0133895874023,22.5175514221191,29999.72265625,29999.72265625,50.5475255243996,5.51288669551622,5.60791540145874,132,1,0,0,1,0.237808227539062,32.2580642700195,2,1,1,22.0133895874023,0,22.2654705047607,,,,,,,,,,,,,,,,,,,,,,,,,,,,,,,,,
,3738608217.04486,19.2910966873169,29999.72265625,1.06081093678419E-7,3.47095259667107E-8,1,10,13.2042255401611,4.01171528092416,32.3400013148785,9.52520319189053E-5,1.14940146769842E-5,1,-2.84389783104912E-9,19.0449714660645,19.5372219085693,29999.72265625,29999.72265625,50.5436173818034,5.51289037852652,5.39402484893799,128,1,100,0,0,0.239181518554687,30.7917900085449,2,1,1,19.0449714660645,0,19.2910966873169,,,,,,,,,,,,,,,,,,,,,,,,,,,,,,,,,
,3738608277.01734,16.3315134048462,29999.72265625,1.35659547196557E-7,3.07338379591397E-8,1,10,13.2042255401611,4.0118375104267,32.3400013148785,0.000113662741322972,6.98116383198082E-5,1,5.79812621973065E-8,16.0836143493652,16.5794124603271,29999.72265625,29999.72265625,50.5244674830823,5.50999378258238,5.15166568756103,131,1,68,0,0,0.23834228515625,30.7917900085449,2,1,1,16.0836143493652,0,16.3315134048462,,,,,,,,,,,,,,,,,,,,,,,,,,,,,,,,,
,3738608336.9945,13.3921971321106,29999.72265625,2.11648890416478E-7,2.91208107792941E-8,1,10,13.2042255401611,4.01179704032789,32.3499999940395,0.000184106243355612,6.31009119471955E-5,1,3.92363133120105E-8,13.1495866775513,13.6348075866699,29999.72265625,29999.72265625,50.521731783265,5.51091715406388,4.86996603012085,127,1,100,0,0,0.239944458007813,31.7693061828613,2,1,1,13.1495866775513,0,13.3921971321106,,,,,,,,,,,,,,,,,,,,,,,,,,,,,,,,,
,3738608397.07353,10.4884195327759,29999.72265625,2.3918233352387E-7,2.62673464455667E-8,1,10,13.2042255401611,4.01175820341025,32.3400013148785,0.000213291531585846,3.59058484419111E-5,1,4.75719507427621E-9,10.2417907714844,10.7350482940674,29999.72265625,29999.72265625,50.6342862900342,5.51098306988235,4.49918365478516,131,1,68,0,0,0.240936279296875,31.2805480957031,2,1,1,10.2417907714844,0,10.4884195327759,,,,,,,,,,,,,,,,,,,,,,,,,,,,,,,,,
,3738608456.95477,7.13030862808228,29999.72265625,3.19939676522137E-7,3.11081903147623E-8,1,10,13.2042255401611,4.01178207962956,32.3400013148785,0.000280830031511567,7.83072610510722E-5,1,4.02162278528063E-8,6.88800477981567,7.37261247634888,29999.72265625,29999.72265625,50.66906875914,5.51118449970828,4.18111133575439,132,1,0,0,1,0.237503051757813,31.7693061828613,6,1,1,6.88800477981567,0,7.13030862808228,,,,,,,,,,,,,,,,,,,,,,,,,,,,,,,,,
,3738608516.98151,4.2723593711853,29999.72265625,4.43461401719761E-7,2.83046299921722E-8,1,10,13.2042255401611,4.01177150729809,32.3400013148785,0.000389478352428447,0.00010700117134536,1,5.40228266379583E-8,4.04683208465576,4.49788665771484,29999.72265625,29999.72265625,50.8699472885823,5.51135685688167,3.4663565158844,130,1,68,0,0,0.23773193359375,31.2805480957031,6,1,1,4.04683208465576,0,4.2723593711853,,,,,,,,,,,,,,,,,,,,,,,,,,,,,,,,,
,3738608576.90186,2.84158217906952,29999.72265625,5.26655832153056E-7,2.3490074398695E-8,1,10,13.2042255401611,4.01182039767062,32.3400013148785,0.000469420599040796,8.06706528572415E-5,1,1.22722360938898E-8,2.84154415130615,2.84162020683289,29999.72265625,29999.72265625,50.9856283094285,5.51394834283053,2.86896800994873,130,1,68,0,0,0.240097045898438,31.7693061828613,6,1,1,2.84154415130615,0,2.84158217906952,,,,,,,,,,,,,,,,,,,,,,,,,,,,,,,,,
,3738608636.89424,2.86811482906342,29999.72265625,5.24737534550483E-7,2.61220862762737E-8,1,10,13.2042255401611,4.01182274465188,32.3400013148785,0.000462805849625802,0.000113530896859428,1,4.92956447452797E-8,2.86779260635376,2.86843705177307,29999.72265625,29999.72265625,51.0387790487362,5.5158898687521,2.88982200622559,132,1,0,0,1,0.238571166992187,30.7917900085449,6,1,1,2.86779260635376,0,2.86811482906342,,,,,,,,,,,,,,,,,,,,,,,,,,,,,,,,,
,3738608696.92721,2.85941064357758,29999.72265625,5.04887590071384E-7,2.59744392895572E-8,1,10,13.2042255401611,4.01171627329887,32.3400013148785,0.000450557379439264,7.35621769099293E-5,1,7.54870074461101E-9,2.85805583000183,2.86076545715332,29999.72265625,29999.72265625,50.9539723543996,5.51434847258894,2.90214776992798,132,1,0,0,1,0.237884521484375,31.2805480957031,6,1,1,2.85805583000183,0,2.85941064357758,,,,,,,,,,,,,,,,,,,,,,,,,,,,,,,,,
,3738608757.02788,2.84708595275879,29999.72265625,5.02347074519313E-7,2.25181892068724E-8,1,10,13.2042255401611,4.01173341932694,32.3400013148785,0.000446343502245696,8.63706615412539E-5,1,2.22451674917318E-8,2.84624266624451,2.84792923927307,29999.72265625,29999.72265625,51.0161118216785,5.51550291794545,2.90619897842407,132,1,0,0,1,0.237274169921875,30.7917900085449,6,1,1,2.84624266624451,0,2.84708595275879,,,,,,,,,,,,,,,,,,,,,,,,,,,,,,,,,
,3738608816.8507,2.84297716617584,29999.72265625,5.11448415313742E-7,2.43053805800811E-8,1,10,13.2042255401611,4.01175129400757,32.3400013148785,0.000453574992618983,9.37379765920023E-5,1,2.91351973794365E-8,2.84279942512512,2.84315490722656,29999.72265625,29999.72265625,51.0688717467266,5.51439126779105,2.91377067565918,132,1,0,0,1,0.235214233398438,30.7917900085449,6,1,1,2.84315490722656,0,2.84297716617584,,,,,,,,,,,,,,,,,,,,,,,,,,,,,,,,,
,3738608876.80641,2.80848717689514,29999.72265625,5.03217787845466E-7,2.31905824988765E-8,1,10,13.2042255401611,4.01170581869258,32.3400013148785,0.000447285340105562,8.53495029265117E-5,1,2.09756304087659E-8,2.79517912864685,2.82179522514343,29999.72265625,29999.72265625,50.9578804969958,5.51397118770952,2.89518523216248,132,1,0,0,1,0.239105224609375,30.7917900085449,6,1,1,2.79517912864685,0,2.80848717689514,,,,,,,,,,,,,,,,,,,,,,,,,,,,,,,,,
,3738608936.8695,2.76162672042847,29999.72265625,5.29188369615001E-7,2.352559205427E-8,1,10,13.2042255401611,4.01176221957263,32.3400013148785,0.000469216880248513,9.76164511985857E-5,1,3.08464596120537E-8,2.75279879570007,2.77045464515686,29999.72265625,29999.72265625,51.029790320765,5.51388145406428,2.87942123413086,132,1,0,0,1,0.238494873046875,30.7917900085449,6,1,1,2.75279879570007,0,2.76162672042847,,,,,,,,,,,,,,,,,,,,,,,,,,,,,,,,,
,3738608996.91486,2.78079509735107,29999.72265625,5.25111878836136E-7,2.32195959732177E-8,1,10,13.2042255401611,4.01174808232149,32.3400013148785,0.00046770370998617,8.26438649374164E-5,1,1.47094969365939E-8,2.78065752983093,2.78093266487122,29999.72265625,29999.72265625,51.0559748761592,5.51349086202375,2.9009325504303,132,1,0,0,1,0.237655639648438,30.7917900085449,6,1,1,2.78093266487122,0,2.78079509735107,,,,,,,,,,,,,,,,,,,,,,,,,,,,,,,,,
,3738609056.76113,2.7338627576828,29999.72265625,5.15732891994558E-7,2.51662541655985E-8,1,10,13.2042255401611,4.01175771414618,32.3400013148785,0.000459928319869011,7.72718354766278E-5,1,1.0090431661478E-8,2.72770810127258,2.74001741409302,29999.72265625,29999.72265625,51.0555840618996,5.51367556899391,2.87799406051636,132,1,0,0,1,0.237579345703125,29.8142719268799,6,1,1,2.72770810127258,0,2.7338627576828,,,,,,,,,,,,,,,,,,,,,,,,,,,,,,,,,
,3738609116.71384,2.23360824584961,29999.72265625,5.56800334597179E-7,2.56866543606115E-8,1,10,13.2042255401611,4.01172919800366,32.3400013148785,0.000494220659270264,9.91434419752615E-5,1,2.8469839967474E-8,2.17426896095276,2.29294753074646,29999.72265625,29999.72265625,51.0977920019381,5.51388635721811,2.59085702896118,132,1,0,0,1,0.237274169921875,31.2805480957031,6,1,1,2.17426896095276,0,2.23360824584961,,,,,,,,,,,,,,,,,,,,,,,,,,,,,,,,,
,3738609176.82719,2.00003236532211,29999.72265625,5.76280862951193E-7,2.66336668971814E-8,1,10,13.2042255401611,4.01174611510027,32.3400013148785,0.000512125136104291,9.84902746820276E-5,1,2.48565161118226E-8,1.99983632564545,2.00022840499878,29999.72265625,29999.72265625,51.1540692553227,5.51405032933859,2.46211075782776,132,1,0,0,1,0.23651123046875,30.7917900085449,5,1,1,2.00022840499878,0,2.00003236532211,,,,,,,,,,,,,,,,,,,,,,,,,,,,,,,,,
,3738609206.69796,2.00034195184708,29999.72265625,5.45603398113367E-7,2.64682572152426E-8,1,10,13.2042255401611,4.01176749444658,32.3400013148785,0.000483818991262115,0.000100331453897743,1,3.14531128371668E-8,1.99978768825531,2.00089621543884,29999.72265625,29999.72265625,51.0039965796304,5.51437833789889,2.45945644378662,132,1,0,0,1,0.238494873046875,30.7917900085449,1,1,1,2.00089621543884,0,2.00034195184708,,,,,,,,,,,,,,,,,,,,,,,,,,,,,,,,,