File: data/quartz-holder/180619_empty-quartz_4mm_2T.dat
[Header]
; MPMS3 Data File (default extension .dat)
; Copyright (c) 2007, Quantum Design, Inc. All rights reserved.
TITLE,
FILEOPENTIME,3738596285.68454,06/19/2018,6:58 pm
BYAPP,MPMS3,1.0,1.1
INFO,MPMS3 Measurement Release 1.1.16 Build 388, MultiVu Release 2.3.4.15,APPNAME
INFO,0,MOMENT_UNITS
INFO,empty quartz,SAMPLE_MATERIAL
INFO,,SAMPLE_COMMENT
INFO,1,SAMPLE_MASS
INFO,,SAMPLE_VOLUME
INFO,,SAMPLE_MOLECULAR_WEIGHT
INFO,,SAMPLE_SIZE
INFO,,SAMPLE_SHAPE
INFO,Standard,SAMPLE_HOLDER
INFO,Standard,SAMPLE_HOLDER_DETAIL
INFO,66,SAMPLE_OFFSET
DATATYPE,COMMENT,1
DATATYPE,TIME,2
STARTUPAXIS,X,2
STARTUPAXIS,Y1,5
FIELDGROUP, VSM,2,3,4,5,6,8,9,10,11,14,15
FIELDGROUP, DC, 2,3,4,14,34,35,36,37,38,39,40,41,42,43,44,45,46,47
STARTUPGROUP, All
[Data]
Comment,Time Stamp (sec),Temperature (K),Magnetic Field (Oe),Moment (emu),M. Std. Err. (emu),Transport Action,Averaging Time (sec),Frequency (Hz),Peak Amplitude (mm),Center Position (mm),Lockin Signal' (V),Lockin Signal (V),Range,M. Quad. Signal (emu),Min. Temperature (K),Max. Temperature (K),Min. Field (Oe),Max. Field (Oe),Mass (grams),Motor Lag (deg),Pressure (Torr),Measure Count,Measurement Number,SQUID Status (code),Motor Status (code),Measure Status (code),Motor Current (amps),Motor Temp. (C),Temp. Status (code),Field Status (code),Chamber Status (code),Chamber Temp (K),Redirection State,Average Temp (K),Rotation Angle (deg),Rotator state,DC Moment Fixed Ctr (emu),DC Moment Err Fixed Ctr (emu),DC Moment Free Ctr (emu),DC Moment Err Free Ctr (emu),DC Fixed Fit,DC Free Fit,DC Calculated Center (mm),DC Calculated Center Err (mm),DC Scan Length (mm),DC Scan Time (s),DC Number of Points,DC Squid Drift,DC Min V (V),DC Max V (V),DC Scans per Measure,Map 01,Map 02,Map 03,Map 04,Map 05,Map 06,Map 07,Map 08,Map 09,Map 10,Map 11,Map 12,Map 13,Map 14,Map 15,Map 16
,3738596350.70203,2.00036907196045,19999.732421875,4.87369791191617E-7,1.93642038527994E-8,1,10,13.2042255401611,4.01138370826646,32.3400013148785,0.000433237378780197,8.20159033897898E-5,1,1.9604853360427E-8,2.00036907196045,2.00036907196045,19999.732421875,19999.732421875,50.8855798589669,5.5190447051893,2.47670483589172,131,1,68,0,0,0.239028930664062,30.7917900085449,1,1,1,2.00036907196045,0,2.00036907196045,,,,,,,,,,,,,,,,,,,,,,,,,,,,,,,,,
,3738596411.32108,4.33817553520203,19999.732421875,3.48075366602956E-7,1.83924609134471E-8,1,10,13.2042255401611,4.01134662987607,32.3400013148785,0.000311199251952147,4.64804540981444E-5,1,4.77550741547411E-10,4.12629699707031,4.55005407333374,19999.732421875,19999.732421875,50.7073685565823,5.51958298524562,3.56081795692444,132,1,0,0,1,0.237960815429687,31.2805480957031,6,1,1,4.55005407333374,0,4.33817553520203,,,,,,,,,,,,,,,,,,,,,,,,,,,,,,,,,
,3738596471.20325,7.01167607307434,19999.732421875,2.43097203851339E-7,1.78979490962779E-8,1,10,13.2042255401611,4.01133263700176,32.3400013148785,0.000217767819237677,2.9581064169265E-5,1,-2.88810356556255E-9,6.78277444839478,7.24057769775391,19999.732421875,19999.732421875,50.6858737723034,5.51960358217888,4.20746898651123,132,1,0,0,1,0.238571166992187,31.7693061828613,6,1,1,7.24057769775391,0,7.01167607307434,,,,,,,,,,,,,,,,,,,,,,,,,,,,,,,,,
,3738596531.34489,9.7999415397644,19999.732421875,1.70058668436827E-7,1.78632280479085E-8,1,10,13.2042255401611,4.011387973079,32.3400013148785,0.000152826312034072,1.74262650471714E-5,1,-5.67440002461045E-9,9.56007766723633,10.0398054122925,19999.732421875,19999.732421875,50.6272516333611,5.51914402299167,4.65058946609497,132,1,0,0,1,0.2362060546875,30.7917900085449,6,1,1,10.0398054122925,0,9.7999415397644,,,,,,,,,,,,,,,,,,,,,,,,,,,,,,,,,
,3738596591.17501,12.622416973114,19999.732421875,1.35138653031499E-7,1.84626146651332E-8,1,10,13.2042255401611,4.01135278866602,32.3400013148785,0.000122421525227055,7.23489131999708E-6,1,-1.19041491965224E-8,12.3847789764404,12.8600549697876,19999.732421875,19999.732421875,50.6628157309861,5.51854595933539,4.95987272262573,132,1,0,0,1,0.238723754882813,31.7693061828613,6,1,1,12.8600549697876,0,12.622416973114,,,,,,,,,,,,,,,,,,,,,,,,,,,,,,,,,
,3738596651.17473,15.5743889808655,19999.732421875,1.01188932596329E-7,1.91690447997051E-8,1,10,13.2042255401611,4.0113115282114,32.3400013148785,8.97485498470586E-5,1.83707960094044E-5,1,5.57219615604834E-9,15.238317489624,15.9104604721069,19999.732421875,19999.732421875,50.6135731342746,5.5177223373164,5.19289684295654,132,1,0,0,1,0.239181518554687,31.2805480957031,2,1,1,15.9104604721069,0,15.5743889808655,,,,,,,,,,,,,,,,,,,,,,,,,,,,,,,,,
,3738596711.11392,18.6453838348389,19999.732421875,7.79553554253364E-8,1.79075399695708E-8,1,10,13.2042255401611,4.01131845355149,32.3400013148785,6.85974434330402E-5,1.78329117478391E-5,1,8.40820011014366E-9,18.4037227630615,18.8870449066162,19999.732421875,19999.732421875,50.5912967214765,5.51934817061389,5.34314441680908,132,1,0,0,1,0.239181518554687,31.2805480957031,2,1,1,18.8870449066162,0,18.6453838348389,,,,,,,,,,,,,,,,,,,,,,,,,,,,,,,,,
,3738596771.20052,21.5402946472168,19999.732421875,7.18768081211385E-8,1.91893889168927E-8,1,10,13.2042255401611,4.01133413630646,32.3400013148785,6.53620705222602E-5,2.16063313538541E-6,1,-8.21848349844777E-9,21.2932720184326,21.787317276001,19999.732421875,19999.732421875,50.6038027777842,5.51752349908757,5.47768354415894,132,1,0,0,1,0.233154296875,30.7917900085449,2,1,1,21.787317276001,0,21.5402946472168,,,,,,,,,,,,,,,,,,,,,,,,,,,,,,,,,
,3738596831.22741,24.448992729187,19999.732421875,6.20462967105499E-8,1.77367815834921E-8,1,10,13.2042255401611,4.01138020197478,32.3400013148785,5.54717980028773E-5,8.29816474507471E-6,1,9.92881924261236E-11,24.214038848877,24.6839466094971,19999.732421875,19999.732421875,50.5823079935053,5.51693263967959,5.59296083450317,132,1,0,0,1,0.235595703125,32.7468223571777,2,1,1,24.6839466094971,0,24.448992729187,,,,,,,,,,,,,,,,,,,,,,,,,,,,,,,,,
,3738596891.05657,27.3636255264282,19999.732421875,4.56956270681941E-8,1.78459112463122E-8,1,10,13.2042255401611,4.0113576018243,32.3400013148785,4.02598140024614E-5,1.01225417822422E-5,1,4.55870185585606E-9,27.1285629272461,27.5986881256104,19999.732421875,19999.732421875,50.5709743799765,5.51787644407978,5.67766094207764,132,1,0,0,1,0.239028930664062,31.2805480957031,2,1,1,27.5986881256104,0,27.3636255264282,,,,,,,,,,,,,,,,,,,,,,,,,,,,,,,,,
,3738596951.06999,30.2762823104858,19999.732421875,3.91777733809444E-8,1.9289997250067E-8,1,10,13.2042255401611,4.0114026893044,32.3400013148785,3.48292984224812E-5,6.57435196846049E-6,1,1.55511523382027E-9,30.0438289642334,30.5087356567383,19999.732421875,19999.732421875,50.6671146878419,5.51841594249293,5.7613787651062,132,1,0,0,1,0.2362060546875,30.7917900085449,2,1,1,30.5087356567383,0,30.2762823104858,,,,,,,,,,,,,,,,,,,,,,,,,,,,,,,,,
,3738597011.0239,33.1784362792969,19999.732421875,1.4133723878016E-8,2.38219419635485E-8,1,10,13.2042255401611,4.0114135767313,32.3400013148785,1.3114633526427E-5,-1.34286932362767E-6,1,-3.59283147763474E-9,32.9385108947754,33.4183616638184,19999.732421875,19999.732421875,50.5995038209284,5.51800704898859,5.82772636413574,132,1,0,0,1,0.23895263671875,31.2805480957031,2,1,1,33.4183616638184,0,33.1784362792969,,,,,,,,,,,,,,,,,,,,,,,,,,,,,,,,,
,3738597071.09928,36.1066989898682,19999.732421875,9.2460246211685E-9,1.74480198399028E-8,1,10,13.2042255401611,4.01139515553006,32.3400013148785,8.56757999946706E-6,-7.99319392491116E-7,1,-2.26185015001164E-9,35.8720817565918,36.3413162231445,19999.732421875,19999.732421875,50.5932507927746,5.51825826989086,5.88755702972412,132,1,0,0,1,0.235977172851562,30.3030319213867,2,1,1,36.3413162231445,0,36.1066989898682,,,,,,,,,,,,,,,,,,,,,,,,,,,,,,,,,
,3738597130.96584,39.026195526123,19999.732421875,1.8281000084246E-8,1.55460181560258E-8,1,10,13.2042255401611,4.01140534731094,32.3400013148785,1.54821785679388E-5,8.27035709665504E-6,1,6.54347522699931E-9,38.7846603393555,39.2677307128906,19999.732421875,19999.732421875,50.5256399258611,5.5170027249763,5.93718385696411,132,1,0,0,1,0.23956298828125,31.2805480957031,2,1,1,39.2677307128906,0,39.026195526123,,,,,,,,,,,,,,,,,,,,,,,,,,,,,,,,,
,3738597191.14079,41.9739151000977,19999.732421875,1.35519035739669E-8,1.58419563415041E-8,1,10,13.2042255401611,4.01141554236789,32.3400013148785,1.1972188129577E-5,2.78512497167317E-6,1,1.10933876683179E-9,41.7150573730469,42.2327728271484,19999.732421875,19999.732421875,50.5756641510919,5.51712893015956,5.98968505859375,132,1,0,0,1,0.235748291015625,31.2805480957031,2,1,1,42.2327728271484,0,41.9739151000977,,,,,,,,,,,,,,,,,,,,,,,,,,,,,,,,,
,3738597250.93761,44.9056968688965,19999.732421875,1.46619457048331E-8,1.55248433760723E-8,1,10,13.2042255401611,4.0114561331301,32.3400013148785,1.44008213161385E-5,-6.77182787114756E-6,1,-9.74173614720096E-9,44.6688995361328,45.1424942016602,19999.732421875,19999.732421875,50.5322837682746,5.51813692176502,6.02203321456909,132,1,0,0,1,0.240707397460938,30.7917900085449,2,1,1,45.1424942016602,0,44.9056968688965,,,,,,,,,,,,,,,,,,,,,,,,,,,,,,,,,
,3738597310.90254,47.8229598999023,19999.732421875,2.00974117712962E-8,1.71469379035342E-8,1,10,13.2042255401611,4.01145815089823,32.3400013148785,1.77025648062037E-5,4.48480256622216E-6,1,2.041447102548E-9,47.5794372558594,48.0664825439453,19999.732421875,19999.732421875,50.4869493141592,5.51691234476107,6.06300973892212,132,1,0,0,1,0.239715576171875,31.7693061828613,2,1,1,48.0664825439453,0,47.8229598999023,,,,,,,,,,,,,,,,,,,,,,,,,,,,,,,,,
,3738597370.90905,50.7698497772217,19999.732421875,-1.27306025179657E-8,1.72763635296655E-8,1,10,13.2042255401611,4.01143401461495,32.3400013148785,-9.77886825479739E-6,-1.25370749114796E-5,1,-1.21357650740765E-8,50.5333213806152,51.0063781738281,19999.732421875,19999.732421875,50.6127915057554,5.51702689598056,6.10138082504273,132,1,0,0,1,0.235519409179687,31.2805480957031,2,1,1,51.0063781738281,0,50.7698497772217,,,,,,,,,,,,,,,,,,,,,,,,,,,,,,,,,
,3738597430.89181,53.6951389312744,19999.732421875,1.14533183990762E-8,1.87762104821501E-8,1,10,13.2042255401611,4.01144144713052,32.3400013148785,1.03295462240119E-5,9.26335296062118E-7,1,-6.58743199796126E-10,53.4533920288086,53.9368858337402,19999.732421875,19999.732421875,50.6002854494477,5.51826752050425,6.13255596160889,132,1,0,0,1,0.239791870117187,31.2805480957031,2,1,1,53.9368858337402,0,53.6951389312744,,,,,,,,,,,,,,,,,,,,,,,,,,,,,,,,,
,3738597490.99455,56.6680030822754,19999.732421875,1.33154062974501E-9,1.78230716746121E-8,1,10,13.2042255401611,4.01138354672868,32.3400013148785,6.10361580190661E-7,4.0987459312485E-6,1,4.38642580795297E-9,56.4316596984863,56.9043464660645,19999.732421875,19999.732421875,50.533847025313,5.51625831580375,6.15565681457519,132,1,0,0,1,0.2362060546875,29.8142719268799,2,1,1,56.9043464660645,0,56.6680030822754,,,,,,,,,,,,,,,,,,,,,,,,,,,,,,,,,
,3738597550.8408,59.6158847808838,19999.732421875,4.52979612433944E-9,1.75637780156877E-8,1,10,13.2042255401611,4.01137820278488,32.3400013148785,7.54911741293691E-6,-2.30450406356134E-5,1,-2.64404629578421E-8,59.3892440795898,59.8425254821777,19999.732421875,19999.732421875,50.6014578922265,5.51511358193478,6.18807792663574,132,1,0,0,1,0.239791870117187,31.2805480957031,2,1,1,59.8425254821777,0,59.6158847808838,,,,,,,,,,,,,,,,,,,,,,,,,,,,,,,,,
,3738597610.79376,62.5258636474609,19999.732421875,-1.16744639354634E-8,2.05520454054423E-8,1,10,13.2042255401611,4.01135236536894,32.3400013148785,-8.58318858964371E-6,-1.40928342031287E-5,1,-1.40322373550246E-8,62.2846946716309,62.767032623291,19999.732421875,19999.732421875,50.6827472582265,5.51525997884877,6.20660352706909,132,1,0,0,1,0.238723754882813,31.7693061828613,2,1,1,62.767032623291,0,62.5258636474609,,,,,,,,,,,,,,,,,,,,,,,,,,,,,,,,,
,3738597670.77634,65.4933090209961,19999.732421875,1.91809198858486E-8,1.95146845372004E-8,1,10,13.2042255401611,4.01143856564453,32.3400013148785,1.69086248497089E-5,4.18919475930425E-6,1,1.84653018001603E-9,65.2554092407227,65.7312088012695,19999.732421875,19999.732421875,50.6194353481688,5.515893331582,6.22757816314697,132,1,0,0,1,0.237579345703125,31.7693061828613,2,1,1,65.7312088012695,0,65.4933090209961,,,,,,,,,,,,,,,,,,,,,,,,,,,,,,,,,
,3738597730.82144,68.4519920349121,19999.732421875,-1.87798575417853E-9,1.94927389957717E-8,1,10,13.2042255401611,4.01138326314776,32.3400013148785,3.0746236367983E-7,-1.36770831486868E-5,1,-1.50165849067314E-8,68.2212524414062,68.682731628418,19999.732421875,19999.732421875,50.6006762637073,5.51685400432019,6.25229024887085,132,1,0,0,1,0.239105224609375,31.2805480957031,2,1,1,68.682731628418,0,68.4519920349121,,,,,,,,,,,,,,,,,,,,,,,,,,,,,,,,,
,3738597790.73873,71.401496887207,19999.732421875,-2.22545629712225E-8,2.91720704054277E-8,1,10,13.2042255401611,4.01143203471119,32.3400013148785,-2.17090187531057E-5,9.27151443615879E-6,1,1.3660417410161E-8,71.16455078125,71.6384429931641,19999.732421875,19999.732421875,50.564330537563,5.51733625348572,6.26663589477539,132,1,0,0,1,0.2398681640625,31.7693061828613,2,1,1,71.6384429931641,0,71.401496887207,,,,,,,,,,,,,,,,,,,,,,,,,,,,,,,,,
,3738597850.89548,74.3508453369141,19999.732421875,-3.57836765763804E-8,2.15963948931475E-8,1,10,13.2042255401611,4.01146657781735,32.3400013148785,-3.19552944853824E-5,-5.04140234609343E-6,1,-3.42939011851358E-10,74.1008377075195,74.6008529663086,19999.732421875,19999.732421875,50.6186537196496,5.51755630337238,6.28837966918945,132,1,0,0,1,0.2374267578125,31.7693061828613,2,1,1,74.6008529663086,0,74.3508453369141,,,,,,,,,,,,,,,,,,,,,,,,,,,,,,,,,
,3738597910.70034,77.2989311218262,19999.732421875,-2.90265453915012E-8,2.4169697284119E-8,1,10,13.2042255401611,4.0114236206563,32.3400013148785,-2.61651948157385E-5,-2.43650496335298E-6,1,1.57008978264879E-9,77.0472030639648,77.5506591796875,19999.732421875,19999.732421875,50.5381459821688,5.51719005841579,6.30507516860962,132,1,0,0,1,0.2386474609375,30.7917900085449,2,1,1,77.5506591796875,0,77.2989311218262,,,,,,,,,,,,,,,,,,,,,,,,,,,,,,,,,
,3738597970.67342,80.2503395080566,19999.732421875,-1.37118659813677E-9,2.7111715111962E-8,1,10,13.2042255401611,4.01128293585983,32.3400013148785,-4.63761474587842E-7,-5.33410352062944E-6,1,-5.76224110279737E-9,80.0034790039063,80.497200012207,19999.732421875,19999.732421875,50.549088781438,5.51416639811498,6.32514905929565,132,1,0,0,1,0.237045288085938,30.7917900085449,2,1,1,80.497200012207,0,80.2503395080566,,,,,,,,,,,,,,,,,,,,,,,,,,,,,,,,,
,3738598030.64939,83.2159156799316,19999.732421875,1.18552448043177E-8,3.12784965824836E-8,1,10,13.2042255401611,4.01137792566795,32.3400013148785,1.47709008341958E-5,-2.66109360673021E-5,1,-3.15118995263872E-8,82.9747543334961,83.4570770263672,19999.732421875,19999.732421875,50.4799146574861,5.51627718866325,6.33105754852295,132,1,0,0,1,0.239410400390625,32.2580642700195,2,1,1,83.4570770263672,0,83.2159156799316,,,,,,,,,,,,,,,,,,,,,,,,,,,,,,,,,
,3738598090.64763,86.1940650939941,19999.732421875,5.62527652824754E-10,3.37035825014153E-8,1,10,13.2042255401611,4.01140743159164,32.3400013148785,3.16321305183444E-6,-1.79049137490542E-5,1,-2.0105269605494E-8,85.9461212158203,86.442008972168,19999.732421875,19999.732421875,50.4986737419476,5.5183379800086,6.3513822555542,132,1,0,0,1,0.2386474609375,31.7693061828613,2,1,1,86.442008972168,0,86.1940650939941,,,,,,,,,,,,,,,,,,,,,,,,,,,,,,,,,
,3738598150.73657,89.1757431030273,19999.732421875,-2.46432492844696E-8,3.2467233832113E-8,1,10,13.2042255401611,4.0113428511232,32.3400013148785,-1.86439921409302E-5,-2.61923333690221E-5,1,-2.56440005060162E-8,88.9283218383789,89.4231643676758,19999.732421875,19999.732421875,50.5557326238515,5.51583675620584,6.36638402938843,132,1,0,0,1,0.23956298828125,31.2805480957031,2,1,1,89.4231643676758,0,89.1757431030273,,,,,,,,,,,,,,,,,,,,,,,,,,,,,,,,,
,3738598210.6108,92.162166595459,19999.732421875,-2.1554859861989E-8,3.01649547421069E-8,1,10,13.2042255401611,4.01129379231312,32.3400013148785,-1.55565662048221E-5,-2.79822533011769E-5,1,-2.8103175087622E-8,91.922607421875,92.401725769043,19999.732421875,19999.732421875,50.5608132092265,5.5151701243134,6.37486696243286,132,1,0,0,1,0.236663818359375,31.2805480957031,2,1,1,92.401725769043,0,92.162166595459,,,,,,,,,,,,,,,,,,,,,,,,,,,,,,,,,
,3738598270.58067,95.1350784301758,19999.732421875,-5.34989707045763E-8,2.88442324550705E-8,1,10,13.2042255401611,4.01132004224043,32.3400013148785,-4.08178163499593E-5,-5.45416315055464E-5,1,-5.30773616602648E-8,94.8844909667969,95.3856658935547,19999.732421875,19999.732421875,50.5518244812554,5.51579337630546,6.39391708374023,132,1,0,0,1,0.236129760742187,31.2805480957031,2,1,1,95.3856658935547,0,95.1350784301758,,,,,,,,,,,,,,,,,,,,,,,,,,,,,,,,,
,3738598330.5488,98.1245193481445,19999.732421875,-1.65633593999922E-8,2.95812970467274E-8,1,10,13.2042255401611,4.01135752828946,32.3400013148785,-1.31119314260663E-5,-1.3679487106312E-5,1,-1.28466279008444E-8,97.8750381469727,98.3740005493164,19999.732421875,19999.732421875,50.5842620648034,5.51588194344812,6.40516090393066,132,1,0,0,1,0.235824584960938,31.2805480957031,2,1,1,98.3740005493164,0,98.1245193481445,,,,,,,,,,,,,,,,,,,,,,,,,,,,,,,,,
,3738598390.54269,101.10818862915,19999.732421875,7.35777669156747E-8,1.80777286203572E-7,1,10,13.2042255401611,4.01130640190467,32.3400013148785,8.0167562676331E-5,-8.74052075007676E-5,1,-1.08630496337364E-7,100.855621337891,101.36075592041,19999.732421875,19999.732421875,50.5811355507265,5.51675176886355,6.41201782226563,132,1,0,0,1,0.236053466796875,32.2580642700195,2,1,1,101.36075592041,0,101.10818862915,,,,,,,,,,,,,,,,,,,,,,,,,,,,,,,,,
,3738598450.4983,104.109519958496,19999.732421875,-4.50136736238498E-9,2.58894161255624E-8,1,10,13.2042255401611,4.0113129168397,32.3400013148785,-1.08022235690321E-6,-2.05001510455502E-5,1,-2.22589976922968E-8,103.862213134766,104.356826782227,19999.732421875,19999.732421875,50.5639397233034,5.51555430466741,6.4251823425293,132,1,0,0,1,0.240478515625,30.7917900085449,2,1,1,104.356826782227,0,104.109519958496,,,,,,,,,,,,,,,,,,,,,,,,,,,,,,,,,
,3738598510.55874,107.088520050049,19999.732421875,7.82912214797284E-10,5.14624439603961E-8,1,10,13.2042255401611,4.01135212881612,32.3400013148785,3.24235693431067E-6,-1.70787546737008E-5,1,-1.92144502229002E-8,106.842422485352,107.334617614746,19999.732421875,19999.732421875,50.5873885788804,5.51508325449553,6.43859767913818,132,1,0,0,1,0.239715576171875,31.7693061828613,2,1,1,107.334617614746,0,107.088520050049,,,,,,,,,,,,,,,,,,,,,,,,,,,,,,,,,
,3738598570.649,110.085525512695,19999.732421875,4.07364563841933E-9,2.07089549718886E-8,1,10,13.2042255401611,4.01133108365509,32.3400013148785,4.91780296694854E-6,-8.07849770757697E-6,1,-9.63671918737373E-9,109.841705322266,110.329345703125,19999.732421875,19999.732421875,50.5103981697361,5.51547792865458,6.45147657394409,132,1,0,0,1,0.2362060546875,30.7917900085449,2,1,1,110.329345703125,0,110.085525512695,,,,,,,,,,,,,,,,,,,,,,,,,,,,,,,,,
,3738598630.46738,113.067008972168,19999.732421875,-2.31674244588004E-8,2.57541232069189E-8,1,10,13.2042255401611,4.01131289344293,32.3400013148785,-1.38018468407668E-5,-4.9802359295135E-5,1,-5.22654391623706E-8,112.82706451416,113.306953430176,19999.732421875,19999.732421875,50.5705835657169,5.51618856138018,6.45601940155029,132,1,0,0,1,0.237579345703125,31.2805480957031,2,1,1,113.306953430176,0,113.067008972168,,,,,,,,,,,,,,,,,,,,,,,,,,,,,,,,,
,3738598690.42341,116.050132751465,19999.732421875,-3.69197556229119E-8,2.63562085143837E-8,1,10,13.2042255401611,4.01146490983595,32.3400013148785,-3.6471015621434E-5,1.84622636210839E-5,1,2.61073515907287E-8,115.807823181152,116.292442321777,19999.732421875,19999.732421875,50.5100073554765,5.51603446864857,6.47156763076782,132,1,0,0,1,0.235519409179687,30.7917900085449,2,1,1,116.292442321777,0,116.050132751465,,,,,,,,,,,,,,,,,,,,,,,,,,,,,,,,,
,3738598750.48951,119.048721313477,19999.732421875,-7.78547714746221E-9,2.57728996344785E-8,1,10,13.2042255401611,4.01139434839925,32.3400013148785,-8.57491743473967E-6,9.86976832943737E-6,1,1.21887688108456E-8,118.791130065918,119.306312561035,19999.732421875,19999.732421875,50.4306720607746,5.51576572571087,6.48227787017822,132,1,0,0,1,0.236282348632813,31.2805480957031,2,1,1,119.306312561035,0,119.048721313477,,,,,,,,,,,,,,,,,,,,,,,,,,,,,,,,,
,3738598810.371,122.014274597168,19999.732421875,-4.28578922883502E-8,2.44028835127237E-8,1,10,13.2042255401611,4.01136797076282,32.3400013148785,-3.54069931506694E-5,-2.53959636138196E-5,1,-2.20581783354825E-8,121.76774597168,122.260803222656,19999.732421875,19999.732421875,50.4732708150726,5.5156904897862,6.49009084701538,132,1,0,0,1,0.238494873046875,31.7693061828613,2,1,1,122.260803222656,0,122.014274597168,,,,,,,,,,,,,,,,,,,,,,,,,,,,,,,,,
,3738598870.36438,125.026393890381,19999.732421875,-1.37840709203708E-8,2.47788502911339E-8,1,10,13.2042255401611,4.01137702404824,32.3400013148785,-1.19275623184969E-5,-4.51939261842891E-6,1,-3.01439130584282E-9,124.774436950684,125.278350830078,19999.732421875,19999.732421875,50.4416148600438,5.51529354004524,6.49059391021729,132,1,0,0,1,0.2362060546875,31.2805480957031,2,1,1,125.278350830078,0,125.026393890381,,,,,,,,,,,,,,,,,,,,,,,,,,,,,,,,,
,3738598930.36869,128.016483306885,19999.732421875,-2.57863080901778E-8,2.41891451290125E-8,1,10,13.2042255401611,4.01144394641715,32.3400013148785,-2.29741829925359E-5,-3.99192713794502E-6,1,-6.48617844997436E-10,127.776206970215,128.256759643555,19999.732421875,19999.732421875,50.508444098438,5.51516574907889,6.50221538543701,132,1,0,0,1,0.240249633789062,31.7693061828613,2,1,1,128.256759643555,0,128.016483306885,,,,,,,,,,,,,,,,,,,,,,,,,,,,,,,,,
,3738598990.32367,131.008033752441,19999.732421875,-2.54850163382516E-8,2.19905777355625E-8,1,10,13.2042255401611,4.01139920982419,32.3400013148785,-2.10630535521169E-5,-1.50450151045445E-5,1,-1.30533510876268E-8,130.747467041016,131.268600463867,19999.732421875,19999.732421875,50.6120098772361,5.51435888332603,6.51095771789551,132,1,0,0,1,0.240020751953125,31.7693061828613,2,1,1,131.268600463867,0,131.008033752441,,,,,,,,,,,,,,,,,,,,,,,,,,,,,,,,,
,3738599050.4677,134.004875183105,19999.732421875,-1.72309360675948E-8,1.21867105176836E-8,1,10,13.2042255401611,4.01146507109588,32.3400013148785,-1.52937622228936E-5,-3.06075533752263E-6,1,-8.73154023812054E-10,133.762649536133,134.247100830078,19999.732421875,19999.732421875,50.4599831302457,5.51495999783174,6.51688385009766,132,1,0,0,1,0.239181518554687,31.2805480957031,2,1,1,134.247100830078,0,134.004875183105,,,,,,,,,,,,,,,,,,,,,,,,,,,,,,,,,
,3738599110.25922,136.955284118652,19999.732421875,-1.88887666938854E-8,1.401367328038E-8,1,10,13.2042255401611,4.0114818697121,32.3400013148785,-1.71451535362157E-5,-7.88099535448328E-7,1,1.91346191132896E-9,136.707244873047,137.203323364258,19999.732421875,19999.732421875,50.5717560084957,5.51308641693649,6.53017091751099,132,1,0,0,1,0.23834228515625,31.7693061828613,2,1,1,137.203323364258,0,136.955284118652,,,,,,,,,,,,,,,,,,,,,,,,,,,,,,,,,
,3738599170.25746,139.947196960449,19999.732421875,-2.95695140458523E-9,1.43887079711483E-8,1,10,13.2042255401611,4.01149951368409,32.3400013148785,-1.96338099707162E-6,-4.99394585731508E-6,1,-5.146738194563E-9,139.686859130859,140.207534790039,19999.732421875,19999.732421875,50.6190445339092,5.514952698212,6.53516626358032,132,1,0,0,1,0.24017333984375,31.7693061828613,2,1,1,140.207534790039,0,139.947196960449,,,,,,,,,,,,,,,,,,,,,,,,,,,,,,,,,
,3738599230.28806,142.952812194824,19999.732421875,-2.38489830966648E-8,1.34120091321633E-8,1,10,13.2042255401611,4.01148059446635,32.3400013148785,-2.07872526878404E-5,-6.80912207455479E-6,1,-4.08540957983094E-9,142.712387084961,143.193237304688,19999.732421875,19999.732421875,50.5213409690053,5.51449255709675,6.54039287567139,132,1,0,0,1,0.239181518554687,33.7243423461914,2,1,1,143.193237304688,0,142.952812194824,,,,,,,,,,,,,,,,,,,,,,,,,,,,,,,,,
,3738599290.24386,145.943977355957,19999.732421875,-1.658336570371E-8,1.3271189706555E-8,1,10,13.2042255401611,4.01144719065491,32.3400013148785,-1.39901836543352E-5,-7.87083216909109E-6,1,-6.34773933827687E-9,145.704513549805,146.183441162109,19999.732421875,19999.732421875,50.4650637156207,5.51348404056948,6.54679346084595,132,1,0,0,1,0.235443115234375,31.2805480957031,2,1,1,146.183441162109,0,145.943977355957,,,,,,,,,,,,,,,,,,,,,,,,,,,,,,,,,
,3738599350.18284,148.935844421387,19999.732421875,-1.41559089269382E-8,1.57578404782793E-8,1,10,13.2042255401611,4.01142626249679,32.3400013148785,-1.24306962805878E-5,-3.41714008230862E-6,1,-1.72669979445189E-9,148.693283081055,149.178405761719,19999.732421875,19999.732421875,50.5029726988034,5.5139315631537,6.55646991729736,132,1,0,0,1,0.235137939453125,31.2805480957031,2,1,1,149.178405761719,0,148.935844421387,,,,,,,,,,,,,,,,,,,,,,,,,,,,,,,,,
,3738599410.25194,151.912605285645,19999.732421875,-1.61812949227798E-8,1.50911439905795E-8,1,10,13.2042255401611,4.01139447978636,32.3400013148785,-1.57736953797128E-5,6.66890825914561E-6,1,9.85163004372414E-9,151.659744262695,152.165466308594,19999.732421875,19999.732421875,50.481087100265,5.51454502017487,6.56435441970825,132,1,0,0,1,0.23895263671875,31.2805480957031,2,1,1,152.165466308594,0,151.912605285645,,,,,,,,,,,,,,,,,,,,,,,,,,,,,,,,,
,3738599470.33173,154.911796569824,19999.732421875,-8.55407607655823E-9,1.66858154975246E-8,1,10,13.2042255401611,4.01136921841549,32.3400013148785,-8.30637170221593E-6,3.30813952193147E-6,1,4.96499331534626E-9,154.674987792969,155.14860534668,19999.732421875,19999.732421875,50.5178236406688,5.51456403206333,6.56707191467285,132,1,0,0,1,0.239715576171875,32.2580642700195,2,1,1,155.14860534668,0,154.911796569824,,,,,,,,,,,,,,,,,,,,,,,,,,,,,,,,,
,3738599530.12108,157.898635864258,19999.732421875,-1.79150553016306E-8,1.55892068942852E-8,1,10,13.2042255401611,4.01148078136575,32.3400013148785,-1.62164863102422E-5,-1.05047771843312E-6,1,1.47600031075022E-9,157.665374755859,158.131896972656,19999.732421875,19999.732421875,50.5256399258611,5.51508715282606,6.57076025009155,132,1,0,0,1,0.237960815429687,32.2580642700195,2,1,1,158.141540527344,0,157.898635864258,,,,,,,,,,,,,,,,,,,,,,,,,,,,,,,,,
,3738599590.11558,160.897796630859,19999.732421875,-2.27129539082025E-8,1.45858166351025E-8,1,10,13.2042255401611,4.01146089370314,32.3400013148785,-2.04782285216847E-5,-1.87989039859634E-6,1,1.25840798944084E-9,160.648376464844,161.147216796875,19999.732421875,19999.732421875,50.528766439938,5.51544044675841,6.57745933532715,132,1,0,0,1,0.237197875976562,31.7693061828613,2,1,1,161.147216796875,0,160.897796630859,,,,,,,,,,,,,,,,,,,,,,,,,,,,,,,,,
,3738599650.08402,163.881675720215,19999.732421875,-2.27557285935568E-8,1.43992109015213E-8,1,10,13.2042255401611,4.0114724614111,32.3400013148785,-2.07966126670551E-5,7.13729673356535E-9,1,3.37484696192542E-9,163.624557495117,164.138793945313,19999.732421875,19999.732421875,50.5412724962457,5.51488394875644,6.58419704437256,132,1,0,0,1,0.23834228515625,30.7917900085449,2,1,1,164.138793945313,0,163.881675720215,,,,,,,,,,,,,,,,,,,,,,,,,,,,,,,,,
,3738599710.0829,166.867401123047,19999.732421875,-1.90515294324511E-8,1.47179670946367E-8,1,10,13.2042255401611,4.01154120119769,32.3400013148785,-1.64694591915015E-5,-6.36301996430815E-6,1,-4.2962184629079E-9,166.625442504883,167.109359741211,19999.732421875,19999.732421875,50.5291572541977,5.51385562244418,6.59581470489502,132,1,0,0,1,0.239028930664062,31.2805480957031,2,1,1,167.109359741211,0,166.867401123047,,,,,,,,,,,,,,,,,,,,,,,,,,,,,,,,,
,3738599770.04377,169.853866577148,19999.732421875,-1.24164079059907E-8,1.58176973916473E-8,1,10,13.2042255401611,4.01155162100643,32.3400013148785,-1.05546903547261E-5,-5.35648437328653E-6,1,-4.15241405159165E-9,169.60888671875,170.098846435547,19999.732421875,19999.732421875,50.4763973291496,5.51419234554673,6.60417079925537,132,1,0,0,1,0.239181518554687,31.2805480957031,2,1,1,170.098846435547,0,169.853866577148,,,,,,,,,,,,,,,,,,,,,,,,,,,,,,,,,
,3738599830.15647,172.877731323242,19999.732421875,-2.87611887523584E-8,1.7638057015456E-8,1,10,13.2042255401611,4.01148654145224,32.3400013148785,-2.72087670310005E-5,6.25122671143778E-6,1,1.12455841002305E-8,172.623245239258,173.132217407227,19999.732421875,19999.732421875,50.4928115280534,5.51420296714066,6.60192060470581,132,1,0,0,1,0.239486694335938,31.2805480957031,2,1,1,173.132217407227,0,172.877731323242,,,,,,,,,,,,,,,,,,,,,,,,,,,,,,,,,
,3738599890.18456,175.858100891113,19999.732421875,-1.15973188235056E-8,1.95910899241893E-8,1,10,13.2042255401611,4.01143974841084,32.3400013148785,-1.20875140713302E-5,1.00659259210608E-5,1,1.2971906827977E-8,175.607925415039,176.108276367187,19999.732421875,19999.732421875,50.4177751902073,5.51461559505014,6.6115837097168,132,1,0,0,1,0.237503051757813,31.2805480957031,2,1,1,176.108276367187,0,175.858100891113,,,,,,,,,,,,,,,,,,,,,,,,,,,,,,,,,
,3738599949.96312,178.81714630127,19999.732421875,-2.3090295910841E-8,1.7932870519196E-8,1,10,13.2042255401611,4.01151160161859,32.3400013148785,-2.06943660221874E-5,-2.75260332466314E-6,1,3.38416161427635E-10,178.575790405273,179.058502197266,19999.732421875,19999.732421875,50.4920298995342,5.51408331231731,6.61113357543945,132,1,0,0,1,0.237808227539062,31.7693061828613,2,1,1,179.058502197266,0,178.81714630127,,,,,,,,,,,,,,,,,,,,,,,,,,,,,,,,,
,3738600009.94599,181.817008972168,19999.732421875,-9.81458294867688E-9,1.98328810599182E-8,1,10,13.2042255401611,4.01153987514299,32.3400013148785,-7.93336466499606E-6,-7.00226531392928E-6,1,-6.37768558349306E-9,181.575149536133,182.058868408203,19999.732421875,19999.732421875,50.5412724962457,5.5141910080914,6.62194633483887,132,1,0,0,1,0.237503051757813,31.2805480957031,2,1,1,182.058868408203,0,181.817008972168,,,,,,,,,,,,,,,,,,,,,,,,,,,,,,,,,
,3738600069.94926,184.831611633301,19999.732421875,-1.85752851253773E-8,2.06861454746126E-8,1,10,13.2042255401611,4.01142207460673,32.3400013148785,-1.60549509034809E-5,-6.21752013333548E-6,1,-4.20431560830178E-9,184.589431762695,185.073791503906,19999.732421875,19999.732421875,50.5232950403034,5.51455229866495,6.62922096252441,132,1,0,0,1,0.234603881835938,31.2805480957031,2,1,1,185.073791503906,0,184.831611633301,,,,,,,,,,,,,,,,,,,,,,,,,,,,,,,,,
,3738600130.09415,187.816711425781,19999.732421875,-2.53974180736705E-8,1.88297817935731E-8,1,10,13.2042255401611,4.01151639276622,32.3400013148785,-2.11782458666638E-5,-1.37327264344701E-5,1,-1.1598134912404E-8,187.57160949707,188.061813354492,19999.732421875,19999.732421875,50.5612040234861,5.51426059146918,6.63298416137695,132,1,0,0,1,0.23895263671875,31.2805480957031,2,1,1,188.061813354492,0,187.816711425781,,,,,,,,,,,,,,,,,,,,,,,,,,,,,,,,,
,3738600189.8858,190.790451049805,19999.732421875,1.11006995442725E-8,2.33740427647846E-8,1,10,13.2042255401611,4.01143681833562,32.3400013148785,2.93838708413156E-6,4.87031030186536E-5,1,5.28188309471804E-8,190.552154541016,191.028747558594,19999.732421875,19999.732421875,50.5651121660823,5.51492626001099,6.63505458831787,132,1,0,0,1,0.238265991210938,31.7693061828613,2,1,1,191.028747558594,0,190.790451049805,,,,,,,,,,,,,,,,,,,,,,,,,,,,,,,,,
,3738600249.90181,193.784370422363,19999.732421875,-3.91815030373483E-9,2.59559514006251E-8,1,10,13.2042255401611,4.01144905971283,32.3400013148785,-2.72089640124528E-6,-5.81056075940424E-6,1,-5.91779274371764E-9,193.541076660156,194.02766418457,19999.732421875,19999.732421875,50.5150879408515,5.51475285931836,6.63937711715698,132,1,0,0,1,0.238189697265625,31.2805480957031,2,1,1,194.02766418457,0,193.784370422363,,,,,,,,,,,,,,,,,,,,,,,,,,,,,,,,,
,3738600309.85564,196.796684265137,19999.732421875,-1.06983807401809E-8,2.31804786123038E-8,1,10,13.2042255401611,4.01149863080391,32.3400013148785,-1.51892568028132E-5,3.65804614463392E-5,1,4.24872521129764E-8,196.538558959961,197.054809570313,19999.732421875,19999.732421875,50.4767881434092,5.51368809475907,6.64778280258179,132,1,0,0,1,0.235443115234375,33.2355842590332,2,1,1,197.054809570313,0,196.796684265137,,,,,,,,,,,,,,,,,,,,,,,,,,,,,,,,,
,3738600369.92634,199.776390075684,19999.732421875,-1.1381865977222E-8,2.53994947832124E-8,1,10,13.2042255401611,4.01149408997836,32.3400013148785,-1.25332507082044E-5,1.44077548474372E-5,1,1.77948376385977E-8,199.541412353516,200.011367797852,19999.732421875,19999.732421875,50.4545117306111,5.51393768383079,6.65469789505005,132,1,0,0,1,0.238265991210938,30.7917900085449,2,1,1,200.011367797852,0,199.776390075684,,,,,,,,,,,,,,,,,,,,,,,,,,,,,,,,,
,3738600429.84646,202.750930786133,19999.732421875,3.56017693995021E-11,2.23919965229556E-8,1,10,13.2042255401611,4.01148022693949,32.3400013148785,2.90509637450178E-6,-1.94148578963641E-5,1,-2.1715163551372E-8,202.499252319336,203.00260925293,19999.732421875,19999.732421875,50.4939839708323,5.51408380842889,6.65863752365112,132,1,0,0,1,0.239410400390625,31.2805480957031,2,1,1,203.00260925293,0,202.750930786133,,,,,,,,,,,,,,,,,,,,,,,,,,,,,,,,,
,3738600489.79538,205.747520446777,19999.732421875,-1.75091862407408E-8,2.38347081962858E-8,1,10,13.2042255401611,4.01145651545399,32.3400013148785,-1.69105679958508E-5,6.14854530991908E-6,1,9.46603613229363E-9,205.501235961914,205.993804931641,19999.732421875,19999.732421875,50.5404908677265,5.51411949638377,6.66763019561768,132,1,0,0,1,0.238037109375,31.2805480957031,2,1,1,205.993804931641,0,205.747520446777,,,,,,,,,,,,,,,,,,,,,,,,,,,,,,,,,
,3738600549.7957,208.752326965332,19999.732421875,-1.56444313067325E-8,2.07745465431299E-8,1,10,13.2042255401611,4.0114359477151,32.3400013148785,-1.33976490405868E-5,-6.07587990394182E-6,1,-4.47953082716025E-9,208.516815185547,208.987838745117,19999.732421875,19999.732421875,50.5698019371977,5.51454941875088,6.6719856262207,132,1,0,0,1,0.235595703125,31.2805480957031,2,1,1,208.987838745117,0,208.752326965332,,,,,,,,,,,,,,,,,,,,,,,,,,,,,,,,,
,3738600609.79629,211.740684509277,19999.732421875,-1.42646926668027E-8,2.09171595977029E-8,1,10,13.2042255401611,4.01140940447341,32.3400013148785,-1.17384045909524E-5,-8.76745471266806E-6,1,-7.69357588144916E-9,211.491653442383,211.989715576172,19999.732421875,19999.732421875,50.5174328264092,5.51448509542162,6.68482208251953,132,1,0,0,1,0.236129760742187,31.7693061828613,2,1,1,211.989715576172,0,211.740684509277,,,,,,,,,,,,,,,,,,,,,,,,,,,,,,,,,
,3738600669.70377,214.737655639648,19999.732421875,-1.41736088343383E-8,2.12461013733489E-8,1,10,13.2042255401611,4.01140560241893,32.3400013148785,-1.42360618686648E-5,8.67622999407271E-6,1,1.17992207658475E-8,214.491302490234,214.984008789062,19999.732421875,19999.732421875,50.4838228000823,5.51480851168048,6.6878399848938,132,1,0,0,1,0.23773193359375,31.2805480957031,2,1,1,214.984008789062,0,214.737655639648,,,,,,,,,,,,,,,,,,,,,,,,,,,,,,,,,
,3738600729.81979,217.72989654541,19999.732421875,-1.67555957215554E-8,1.86374660978157E-8,1,10,13.2042255401611,4.0113852722955,32.3400013148785,-1.640713142844E-5,7.40343067586278E-6,1,1.07580106496133E-8,217.46614074707,217.99365234375,19999.732421875,19999.732421875,50.4877309426784,5.51499007599549,6.69387245178223,132,1,0,0,1,0.237960815429687,32.7468223571777,2,1,1,217.99365234375,0,217.72989654541,,,,,,,,,,,,,,,,,,,,,,,,,,,,,,,,,
,3738600789.86555,220.721046447754,19999.732421875,-2.06606712553728E-8,2.05933578692685E-8,1,10,13.2042255401611,4.01144107405572,32.3400013148785,-1.61541411041823E-5,-1.84282810334142E-5,1,-1.75501281829329E-8,220.487442016602,220.954650878906,19999.732421875,19999.732421875,50.5189960834477,5.5150243097801,6.70558500289917,132,1,0,0,1,0.239105224609375,30.7917900085449,2,1,1,220.954650878906,0,220.721046447754,,,,,,,,,,,,,,,,,,,,,,,,,,,,,,,,,
,3738600849.68876,223.698059082031,19999.732421875,-9.09656050795871E-9,2.08406489369806E-8,1,10,13.2042255401611,4.01140375549387,32.3400013148785,-6.10657843057516E-6,-1.49109693577644E-5,1,-1.5328209116206E-8,223.455062866211,223.941055297852,19999.732421875,19999.732421875,50.501409441765,5.51577541627711,6.71274042129517,132,1,0,0,1,0.238265991210938,31.2805480957031,2,1,1,223.941055297852,0,223.698059082031,,,,,,,,,,,,,,,,,,,,,,,,,,,,,,,,,
,3738600909.63702,226.687866210938,19999.732421875,-4.91651819990952E-9,2.05690224382062E-8,1,10,13.2042255401611,4.01144186139831,32.3400013148785,-4.71216510753515E-6,1.48157380300805E-6,1,2.38416903542598E-9,226.430786132813,226.944946289062,19999.732421875,19999.732421875,50.5311113254957,5.51535336892009,6.72477531433105,132,1,0,0,1,0.23834228515625,31.2805480957031,2,1,1,226.944946289062,0,226.687866210938,,,,,,,,,,,,,,,,,,,,,,,,,,,,,,,,,
,3738600969.63283,229.679061889648,19999.732421875,-2.2317034412571E-8,2.04205829224587E-8,1,10,13.2042255401611,4.01134927007653,32.3400013148785,-1.89280725919695E-5,-9.90546076865703E-6,1,-7.77500739098177E-9,229.427856445313,229.930267333984,19999.732421875,19999.732421875,50.5096165412169,5.51582961304284,6.73536348342895,132,1,0,0,1,0.2386474609375,31.2805480957031,2,1,1,229.930267333984,0,229.679061889648,,,,,,,,,,,,,,,,,,,,,,,,,,,,,,,,,
,3738601029.77068,232.660690307617,19999.732421875,-1.2303480627124E-8,1.88160960567639E-8,1,10,13.2042255401611,4.01137386662883,32.3400013148785,-1.16174121037451E-5,2.52904923706017E-6,1,4.64851290232337E-9,232.419128417969,232.902252197266,19999.732421875,19999.732421875,50.4431781170823,5.5154642529801,6.74870204925537,132,1,0,0,1,0.236587524414062,31.7693061828613,2,1,1,232.902252197266,0,232.660690307617,,,,,,,,,,,,,,,,,,,,,,,,,,,,,,,,,
,3738601089.5762,235.682357788086,19999.732421875,-2.26174026500883E-8,1.70918543162268E-8,1,10,13.2042255401611,4.0113368317189,32.3400013148785,-2.00028416572878E-5,-4.49584287824045E-6,1,-1.68118499522043E-9,235.441375732422,235.92333984375,19999.732421875,19999.732421875,50.5537785525534,5.51600928060778,6.76034641265869,132,1,0,0,1,0.23590087890625,31.7693061828613,2,1,1,235.92333984375,0,235.682357788086,,,,,,,,,,,,,,,,,,,,,,,,,,,,,,,,,
,3738601149.54982,238.660652160645,19999.732421875,-1.44097656577124E-8,1.75376978933581E-8,1,10,13.2042255401611,4.01133884421867,32.3400013148785,-1.17501300996837E-5,-9.58173598408914E-6,1,-8.5829751004557E-9,238.417251586914,238.904052734375,19999.732421875,19999.732421875,50.5240766688226,5.51641320987983,6.78433418273926,132,1,0,0,1,0.235519409179687,31.7693061828613,2,1,1,238.904052734375,0,238.660652160645,,,,,,,,,,,,,,,,,,,,,,,,,,,,,,,,,
,3738601209.51573,241.64087677002,19999.732421875,-2.39868369059399E-8,1.60419015447962E-8,1,10,13.2042255401611,4.0112683341602,32.3400013148785,-2.05716913800071E-5,-9.10501061630353E-6,1,-6.63315781778811E-9,241.395370483398,241.886383056641,19999.732421875,19999.732421875,50.5397092392073,5.51657719438078,6.79998779296875,132,1,0,0,1,0.234756469726562,31.2805480957031,2,1,1,241.886383056641,0,241.64087677002,,,,,,,,,,,,,,,,,,,,,,,,,,,,,,,,,
,3738601269.58563,244.623886108398,19999.732421875,-2.69201452968855E-8,1.75483103182643E-8,1,10,13.2042255401611,4.01132481983068,32.3400013148785,-2.29714971504528E-5,-1.10053142227788E-5,1,-8.32399670311095E-9,244.378952026367,244.86882019043,19999.732421875,19999.732421875,50.4091772764957,5.51685423132629,6.82754993438721,132,1,0,0,1,0.234298706054687,31.2805480957031,2,1,1,244.86882019043,0,244.623886108398,,,,,,,,,,,,,,,,,,,,,,,,,,,,,,,,,
,3738601329.47614,247.623497009277,19999.732421875,-1.71284794031337E-8,1.70389788940045E-8,1,10,13.2042255401611,4.01127536642382,32.3400013148785,-1.47499541247809E-5,-6.0954080165787E-6,1,-4.28222751440437E-9,247.386306762695,247.860687255859,19999.732421875,19999.732421875,50.5018002560246,5.5170858265541,6.86052179336548,132,1,0,0,1,0.240020751953125,31.7693061828613,2,1,1,247.860687255859,0,247.623497009277,,,,,,,,,,,,,,,,,,,,,,,,,,,,,,,,,
,3738601389.47866,250.617546081543,19999.732421875,-2.08669307626818E-8,1.8113476376754E-8,1,10,13.2042255401611,4.01125002337979,32.3400013148785,-1.83632230929055E-5,-4.76186908023968E-6,1,-2.23785316836438E-9,250.369201660156,250.86589050293,19999.732421875,19999.732421875,50.4334077605919,5.51698650298993,6.89810848236084,132,1,0,0,1,0.236663818359375,31.7693061828613,2,1,1,250.86589050293,0,250.617546081543,,,,,,,,,,,,,,,,,,,,,,,,,,,,,,,,,
,3738601449.43138,253.591079711914,19999.732421875,-1.78225376551851E-8,2.04746769872878E-8,1,10,13.2042255401611,4.0112091989771,32.3400013148785,-1.59064803938013E-5,-2.56240650022767E-6,1,-2.28651591403018E-10,253.348831176758,253.83332824707,19999.732421875,19999.732421875,50.5424449390246,5.51739608643553,6.93928670883179,132,1,0,0,1,0.236358642578125,31.7693061828613,2,1,1,253.83332824707,0,253.591079711914,,,,,,,,,,,,,,,,,,,,,,,,,,,,,,,,,
,3738601509.48519,256.600021362305,19999.732421875,-2.45917428333455E-8,1.72943483941858E-8,1,10,13.2042255401611,4.01120727894769,32.3400013148785,-2.27607744823008E-5,1.95817099203315E-6,1,5.82840144262055E-9,256.361846923828,256.838195800781,19999.732421875,19999.732421875,50.4294996179957,5.51647452957341,6.99991083145142,132,1,0,0,1,0.240249633789062,31.2805480957031,2,1,1,256.838195800781,0,256.600021362305,,,,,,,,,,,,,,,,,,,,,,,,,,,,,,,,,
,3738601569.40039,259.575271606445,19999.732421875,-3.26223490809488E-8,1.83731444648869E-8,1,10,13.2042255401611,4.01121277920736,32.3400013148785,-2.96509628334074E-5,-1.06944006734697E-6,1,3.63071395772454E-9,259.329681396484,259.820861816406,19999.732421875,19999.732421875,50.4427873028226,5.51661491711443,7.043776512146,132,1,0,0,1,0.2398681640625,31.7693061828613,2,1,1,259.820861816406,0,259.575271606445,,,,,,,,,,,,,,,,,,,,,,,,,,,,,,,,,
,3738601629.45587,262.60466003418,19999.732421875,-2.73677728077682E-8,1.67650027853811E-8,1,10,13.2042255401611,4.0112241974586,32.3400013148785,-2.53344829470462E-5,2.20759557103432E-6,1,6.51805690445683E-9,262.356201171875,262.853118896484,19999.732421875,19999.732421875,50.4873401284188,5.51844500502838,6.99069023132324,132,1,0,0,1,0.238800048828125,30.7917900085449,2,1,1,262.853118896484,0,262.60466003418,,,,,,,,,,,,,,,,,,,,,,,,,,,,,,,,,
,3738601689.54829,265.568801879883,19999.732421875,-3.48357976403592E-8,1.5840791589952E-8,1,10,13.2042255401611,4.01115803242034,32.3400013148785,-3.13856998041346E-5,-3.01017296332886E-6,1,1.78775731095541E-9,265.3310546875,265.806549072266,19999.732421875,19999.732421875,50.5170420121496,5.51758686332856,6.97113656997681,132,1,0,0,1,0.236129760742187,31.7693061828613,2,1,1,265.806549072266,0,265.568801879883,,,,,,,,,,,,,,,,,,,,,,,,,,,,,,,,,
,3738601749.37275,268.571151733398,19999.732421875,-5.46582370758545E-9,1.65554132244578E-8,1,10,13.2042255401611,4.01117949810039,32.3400013148785,-5.61090486867156E-6,4.16666733866536E-6,1,5.46847350323558E-9,268.319519042969,268.822784423828,19999.732421875,19999.732421875,50.5225134117842,5.51707738937576,6.94855785369873,132,1,0,0,1,0.2362060546875,30.3030319213867,2,1,1,268.822784423828,0,268.571151733398,,,,,,,,,,,,,,,,,,,,,,,,,,,,,,,,,
,3738601809.31901,271.556838989258,19999.732421875,-2.13350052296981E-8,1.66973175073931E-8,1,10,13.2042255401611,4.01118937798354,32.3400013148785,-1.84570147070044E-5,-7.01560406697017E-6,1,-4.68916777264584E-9,271.310729980469,271.802947998047,19999.732421875,19999.732421875,50.5311113254957,5.51715699184458,6.94208335876465,132,1,0,0,1,0.240478515625,31.2805480957031,2,1,1,271.802947998047,0,271.556838989258,,,,,,,,,,,,,,,,,,,,,,,,,,,,,,,,,
,3738601869.28999,274.541946411133,19999.732421875,-1.21157415932513E-8,1.52650194738985E-8,1,10,13.2042255401611,4.01113120448581,32.3400013148785,-1.27755419311334E-5,1.15232775594067E-5,1,1.46798426212442E-8,274.295532226562,274.788360595703,19999.732421875,19999.732421875,50.493202342313,5.51762217076645,6.94559049606323,132,1,0,0,1,0.240859985351562,31.7693061828613,2,1,1,274.788360595703,0,274.541946411133,,,,,,,,,,,,,,,,,,,,,,,,,,,,,,,,,
,3738601929.31932,277.563766479492,19999.732421875,-2.08687169357653E-8,1.68050122953909E-8,1,10,13.2042255401611,4.0110648120569,32.3400013148785,-1.89411461835146E-5,-8.57392207346852E-7,1,2.1287665079824E-9,277.319396972656,277.808135986328,19999.732421875,19999.732421875,50.4584198732073,5.51740328006896,6.97488212585449,132,1,0,0,1,0.23712158203125,32.2580642700195,2,1,1,277.808135986328,0,277.563766479492,,,,,,,,,,,,,,,,,,,,,,,,,,,,,,,,,
,3738601989.25852,280.541213989258,19999.732421875,-1.37013948725368E-8,1.74790034171709E-8,1,10,13.2042255401611,4.01109812668226,32.3400013148785,-1.54335006378308E-5,1.96962963713253E-5,1,2.40551623539306E-8,280.288665771484,280.793762207031,19999.732421875,19999.732421875,50.5260307401207,5.51730000241352,7.0088324546814,132,1,0,0,1,0.240478515625,29.3255138397217,2,1,1,280.793762207031,0,280.541213989258,,,,,,,,,,,,,,,,,,,,,,,,,,,,,,,,,
,3738602049.39311,283.535537719727,19999.732421875,-9.13728234148214E-9,1.76705524560161E-8,1,10,13.2042255401611,4.01113530498005,32.3400013148785,-9.9533055704402E-6,1.08425159991182E-5,1,1.34777991973467E-8,283.282470703125,283.788604736328,19999.732421875,19999.732421875,50.5862161361015,5.51744928856196,7.06790447235107,132,1,0,0,1,0.236663818359375,31.7693061828613,2,1,1,283.788604736328,0,283.535537719727,,,,,,,,,,,,,,,,,,,,,,,,,,,,,,,,,
,3738602109.41809,286.532623291016,19999.732421875,-1.56537610740361E-8,1.74116974082693E-8,1,10,13.2042255401611,4.01106893368198,32.3400013148785,-1.55836669931754E-5,8.65529116301532E-6,1,1.19960993958513E-8,286.291961669922,286.773284912109,19999.732421875,19999.732421875,50.452557659313,5.51769398242208,7.14629888534546,132,1,0,0,1,0.236740112304687,31.2805480957031,2,1,1,286.773284912109,0,286.532623291016,,,,,,,,,,,,,,,,,,,,,,,,,,,,,,,,,
,3738602169.18117,289.509506225586,19999.732421875,-1.50896727984094E-8,1.75334634816403E-8,1,10,13.2042255401611,4.01106572824911,32.3400013148785,-1.46856522178405E-5,6.06952391206308E-6,1,9.02074297775889E-9,289.265838623047,289.753173828125,19999.732421875,19999.732421875,50.472880000813,5.51729081634924,7.25695896148682,132,1,0,0,1,0.235595703125,32.2580642700195,2,1,1,289.753173828125,0,289.509506225586,,,,,,,,,,,,,,,,,,,,,,,,,,,,,,,,,
,3738602229.16001,292.486862182617,19999.732421875,-2.1664161561643E-8,1.74299608909299E-8,1,10,13.2042255401611,4.01105142248055,32.3400013148785,-2.07422775948435E-5,6.40438160704429E-6,1,1.03680273660091E-8,292.234191894531,292.739532470703,19999.732421875,19999.732421875,50.544008196063,5.51722972150885,7.37939357757568,132,1,0,0,1,0.232925415039062,31.2805480957031,2,1,1,292.739532470703,0,292.486862182617,,,,,,,,,,,,,,,,,,,,,,,,,,,,,,,,,
,3738602289.19363,295.520736694336,19999.732421875,-1.22607682553427E-8,1.76090757163868E-8,1,10,13.2042255401611,4.01106684268356,32.3400013148785,-1.19117428068859E-5,4.79139066799312E-6,1,7.17272753343137E-9,295.240631103516,295.800842285156,19999.732421875,19999.732421875,50.4849952428611,5.51819940453987,7.53393316268921,132,1,0,0,1,0.237884521484375,32.2580642700195,2,1,1,295.800842285156,0,295.520736694336,,,,,,,,,,,,,,,,,,,,,,,,,,,,,,,,,
,3738602349.11308,298.504165649414,19999.732421875,-1.86857934801535E-8,1.57237783448484E-8,1,10,13.2042255401611,4.01112962641242,32.3400013148785,-1.70727232368216E-5,-7.81087892115725E-9,1,2.75595573326838E-9,298.25927734375,298.749053955078,19999.732421875,19999.732421875,50.5025818845438,5.51724713114338,7.71587085723877,132,1,0,0,1,0.237274169921875,31.7693061828613,2,1,1,298.749053955078,0,298.504165649414,,,,,,,,,,,,,,,,,,,,,,,,,,,,,,,,,
,3738602409.10033,299.799758911133,19999.732421875,-2.14728704494065E-8,1.76401345109838E-8,1,10,13.2042255401611,4.01109964746838,32.3400013148785,-1.87627693210421E-5,-5.79579761673758E-6,1,-3.30484287163223E-9,299.772918701172,299.826599121094,19999.732421875,19999.732421875,50.4592015017265,5.51766657029989,7.90613412857056,132,1,0,0,1,0.236282348632813,30.7917900085449,5,1,1,299.826599121094,0,299.799758911133,,,,,,,,,,,,,,,,,,,,,,,,,,,,,,,,,
,3738602449.16375,299.927017211914,19999.732421875,-2.59186219752906E-8,1.51821253248072E-8,1,10,13.2042255401611,4.01110535522832,32.3400013148785,-2.39306691263939E-5,1.6770030221664E-6,1,5.71035920611498E-9,299.917694091797,299.936340332031,19999.732421875,19999.732421875,50.4853860571207,5.5175188408687,7.98569202423096,132,1,0,0,1,0.237350463867187,31.7693061828613,1,1,1,299.936340332031,0,299.927017211914,,,,,,,,,,,,,,,,,,,,,,,,,,,,,,,,,