File: data/quartz-holder/180619_empty-quartz_4mm_7T.dat
[Header]
; MPMS3 Data File (default extension .dat)
; Copyright (c) 2007, Quantum Design, Inc. All rights reserved.
TITLE,
FILEOPENTIME,3738628514.9239,06/20/2018,3:55 am
BYAPP,MPMS3,1.0,1.1
INFO,MPMS3 Measurement Release 1.1.16 Build 388, MultiVu Release 2.3.4.15,APPNAME
INFO,0,MOMENT_UNITS
INFO,empty quartz,SAMPLE_MATERIAL
INFO,,SAMPLE_COMMENT
INFO,1,SAMPLE_MASS
INFO,,SAMPLE_VOLUME
INFO,,SAMPLE_MOLECULAR_WEIGHT
INFO,,SAMPLE_SIZE
INFO,,SAMPLE_SHAPE
INFO,Standard,SAMPLE_HOLDER
INFO,Standard,SAMPLE_HOLDER_DETAIL
INFO,66,SAMPLE_OFFSET
DATATYPE,COMMENT,1
DATATYPE,TIME,2
STARTUPAXIS,X,2
STARTUPAXIS,Y1,5
FIELDGROUP, VSM,2,3,4,5,6,8,9,10,11,14,15
FIELDGROUP, DC, 2,3,4,14,34,35,36,37,38,39,40,41,42,43,44,45,46,47
STARTUPGROUP, All
[Data]
Comment,Time Stamp (sec),Temperature (K),Magnetic Field (Oe),Moment (emu),M. Std. Err. (emu),Transport Action,Averaging Time (sec),Frequency (Hz),Peak Amplitude (mm),Center Position (mm),Lockin Signal' (V),Lockin Signal (V),Range,M. Quad. Signal (emu),Min. Temperature (K),Max. Temperature (K),Min. Field (Oe),Max. Field (Oe),Mass (grams),Motor Lag (deg),Pressure (Torr),Measure Count,Measurement Number,SQUID Status (code),Motor Status (code),Measure Status (code),Motor Current (amps),Motor Temp. (C),Temp. Status (code),Field Status (code),Chamber Status (code),Chamber Temp (K),Redirection State,Average Temp (K),Rotation Angle (deg),Rotator state,DC Moment Fixed Ctr (emu),DC Moment Err Fixed Ctr (emu),DC Moment Free Ctr (emu),DC Moment Err Free Ctr (emu),DC Fixed Fit,DC Free Fit,DC Calculated Center (mm),DC Calculated Center Err (mm),DC Scan Length (mm),DC Scan Time (s),DC Number of Points,DC Squid Drift,DC Min V (V),DC Max V (V),DC Scans per Measure,Map 01,Map 02,Map 03,Map 04,Map 05,Map 06,Map 07,Map 08,Map 09,Map 10,Map 11,Map 12,Map 13,Map 14,Map 15,Map 16
,3738628594.03084,299.999053955078,49999.75,-1.64399225391823E-7,3.60006734564612E-8,1,10,13.2042255401611,4.01151838524634,32.3400013148785,-0.000145942306164969,-2.90514292408682E-5,1,-8.16112624981474E-9,299.999053955078,299.999053955078,49999.75,49999.75,50.315381854188,5.51448449338706,8.08004570007324,132,1,0,0,1,0.2386474609375,31.7693061828613,1,1,1,299.999053955078,0,299.999053955078,,,,,,,,,,,,,,,,,,,,,,,,,,,,,,,,,
,3738628649.99104,299.04167175293,49999.75,-1.11443605888713E-7,4.24696428364138E-8,1,10,13.2042255401611,4.01147210058745,32.3400013148785,-9.53339371521275E-5,-4.39988675092977E-5,1,-3.27113051376796E-8,298.808135986328,299.275207519531,49999.75,49999.75,50.4001885485246,5.51578720659825,8.01137447357178,130,1,32,0,0,0.234298706054687,30.7917900085449,2,1,1,298.808135986328,0,299.04167175293,,,,,,,,,,,,,,,,,,,,,,,,,,,,,,,,,
,3738628709.75701,295.914855957031,49999.75,-1.43625802658202E-7,3.80509105015266E-8,1,10,13.2042255401611,4.01142599012927,32.3400013148785,-0.000125509291047555,-3.88099841679555E-5,1,-2.21482415750831E-8,295.651916503906,296.177795410156,49999.75,49999.75,50.4494311452361,5.51562757213698,7.94166707992554,132,1,0,0,1,0.235595703125,30.3030319213867,2,1,1,295.651916503906,0,295.914855957031,,,,,,,,,,,,,,,,,,,,,,,,,,,,,,,,,
,3738628769.71664,292.573181152344,49999.75,-1.22551948356333E-7,3.55510399277455E-8,1,10,13.2042255401611,4.01146453251528,32.3400013148785,-0.000104118085474879,-5.32379566993079E-5,1,-4.13992077278976E-8,292.207305908203,292.939056396484,49999.75,49999.75,50.3990161057457,5.51668715127803,7.88220262527466,132,1,0,0,1,0.234832763671875,30.7917900085449,2,1,1,292.207305908203,0,292.573181152344,,,,,,,,,,,,,,,,,,,,,,,,,,,,,,,,,
,3738628829.70212,289.278854370117,49999.75,-1.28363994650866E-7,3.64036478901003E-8,1,10,13.2042255401611,4.01145602791487,32.3400013148785,-0.000108385094975551,-6.02939039647466E-5,1,-4.84295862616592E-8,289.022674560547,289.535034179687,49999.75,49999.75,50.4193384472457,5.51681092727597,7.82646799087524,130,1,32,0,0,0.23895263671875,31.2805480957031,2,1,1,289.022674560547,0,289.278854370117,,,,,,,,,,,,,,,,,,,,,,,,,,,,,,,,,
,3738628889.75831,286.335830688477,49999.75,-1.06244611958516E-7,3.98599200934997E-8,1,10,13.2042255401611,4.01153265036919,32.3400013148785,-8.90582083015148E-5,-5.43188420027176E-5,1,-4.50190109603897E-8,286.089385986328,286.582275390625,49999.75,49999.75,50.3943263346303,5.51616939326598,7.77836561203003,132,1,0,0,1,0.238265991210938,30.7917900085449,2,1,1,286.089385986328,0,286.335830688477,,,,,,,,,,,,,,,,,,,,,,,,,,,,,,,,,
,3738628949.6847,283.401840209961,49999.75,-9.72128056708765E-8,3.55233520194274E-8,1,10,13.2042255401611,4.01151277229503,32.3400013148785,-7.68370476043022E-5,-8.11270141032629E-5,1,-7.6332597502358E-8,283.147033691406,283.656646728516,49999.75,49999.75,50.4287179894765,5.51677199092925,7.73587417602539,132,1,0,0,1,0.2337646484375,30.7917900085449,2,1,1,283.147033691406,0,283.401840209961,,,,,,,,,,,,,,,,,,,,,,,,,,,,,,,,,
,3738629009.64806,280.445755004883,49999.75,-1.1092139020596E-7,3.4860275179734E-8,1,10,13.2042255401611,4.01141838415855,32.3400013148785,-9.34799217442653E-5,-5.3289550514856E-5,1,-4.31788140532725E-8,280.202819824219,280.688690185547,49999.75,49999.75,50.4439597456015,5.51648652427196,7.69556903839111,132,1,0,0,1,0.239639282226562,31.2805480957031,2,1,1,280.202819824219,0,280.445755004883,,,,,,,,,,,,,,,,,,,,,,,,,,,,,,,,,
,3738629069.61189,277.461395263672,49999.75,-1.03877407141209E-7,6.13093932495925E-8,1,10,13.2042255401611,4.01145983160537,32.3400013148785,-9.34285556649772E-5,-1.01408289047548E-5,1,4.02970178981975E-9,277.2099609375,277.712829589844,49999.75,49999.75,50.4568566161688,5.51556678457292,7.66097354888916,132,1,0,0,1,0.235595703125,31.2805480957031,2,1,1,277.2099609375,0,277.461395263672,,,,,,,,,,,,,,,,,,,,,,,,,,,,,,,,,
,3738629129.67242,274.448013305664,49999.75,-1.19258261695711E-7,3.87579228607526E-8,1,10,13.2042255401611,4.0114387675032,32.3400013148785,-0.000100314522683101,-5.85941623895027E-5,1,-4.78766041304435E-8,274.206970214844,274.689056396484,49999.75,49999.75,50.4048783196399,5.51687964192776,7.62108278274536,132,1,0,0,1,0.24017333984375,30.7917900085449,2,1,1,274.206970214844,0,274.448013305664,,,,,,,,,,,,,,,,,,,,,,,,,,,,,,,,,
,3738629189.57194,271.47444152832,49999.75,-1.03553089772485E-7,4.09185341405194E-8,1,10,13.2042255401611,4.01139184633473,32.3400013148785,-8.77933127176319E-5,-4.62074781484641E-5,1,-3.63501077944689E-8,271.241302490234,271.707580566406,49999.75,49999.75,50.4494311452361,5.51479326966545,7.58839130401611,132,1,0,0,1,0.238189697265625,30.7917900085449,2,1,1,271.241302490234,0,271.47444152832,,,,,,,,,,,,,,,,,,,,,,,,,,,,,,,,,
,3738629249.67131,268.452026367187,49999.75,-1.1194136837303E-7,3.70991460166032E-8,1,10,13.2042255401611,4.01133588339678,32.3400013148785,-9.54706872227614E-5,-4.61116421076527E-5,1,-3.50029823189594E-8,268.204895019531,268.699157714844,49999.75,49999.75,50.4279363609573,5.51466431404469,7.56018447875977,132,1,0,0,1,0.240554809570313,31.7693061828613,2,1,1,268.204895019531,0,268.452026367187,,,,,,,,,,,,,,,,,,,,,,,,,,,,,,,,,
,3738629309.52739,265.472930908203,49999.75,-1.21365799467454E-7,3.9286923936255E-8,1,10,13.2042255401611,4.01132879843943,32.3400013148785,-0.000104485638375358,-4.33870821417615E-5,1,-3.0561903741226E-8,265.226165771484,265.719696044922,49999.75,49999.75,50.3665785221976,5.51542334625661,7.53088855743408,130,1,32,0,0,0.238723754882813,30.7917900085449,2,1,1,265.226165771484,0,265.472930908203,,,,,,,,,,,,,,,,,,,,,,,,,,,,,,,,,
,3738629369.50362,262.453826904297,49999.75,-1.30939012826521E-7,4.53196041779509E-8,1,10,13.2042255401611,4.01127269721725,32.3400013148785,-0.000114381429315454,-3.56119940261729E-5,1,-2.04516614208321E-8,262.200531005859,262.707122802734,49999.75,49999.75,50.4513852165342,5.51591171180736,7.5053243637085,130,1,32,0,0,0.235519409179687,30.7917900085449,2,1,1,262.200531005859,0,262.453826904297,,,,,,,,,,,,,,,,,,,,,,,,,,,,,,,,,
,3738629429.49416,259.475433349609,49999.75,-1.19952798652575E-7,3.84104877236931E-8,1,10,13.2042255401611,4.01119330450079,32.3400013148785,-9.94455605505937E-5,-6.86847670086613E-5,1,-5.90649377895619E-8,259.224700927734,259.726165771484,49999.75,49999.75,50.4408332315246,5.5157184311173,7.47619962692261,132,1,0,0,1,0.23651123046875,31.2805480957031,2,1,1,259.224700927734,0,259.475433349609,,,,,,,,,,,,,,,,,,,,,,,,,,,,,,,,,
,3738629489.60547,256.495513916016,49999.75,-1.2631422081775E-7,3.78698585592621E-8,1,10,13.2042255401611,4.01125064062886,32.3400013148785,-0.000103064998093833,-8.35269191746149E-5,1,-7.47201348226745E-8,256.237579345703,256.753448486328,49999.75,49999.75,50.4693626724765,5.51654643387807,7.45686769485474,130,1,32,0,0,0.240554809570313,31.2805480957031,2,1,1,256.237579345703,0,256.495513916016,,,,,,,,,,,,,,,,,,,,,,,,,,,,,,,,,
,3738629549.6445,253.454208374023,49999.75,-1.05692990581151E-7,3.49279173717948E-8,1,10,13.2042255401611,4.01122579144081,32.3400013148785,-8.67840304760063E-5,-6.62026209039185E-5,1,-5.83979405049341E-8,253.220550537109,253.687866210938,49999.75,49999.75,50.4146486761303,5.51616587178119,7.43006610870361,131,1,68,0,0,0.2398681640625,31.7693061828613,2,1,1,253.220550537109,0,253.454208374023,,,,,,,,,,,,,,,,,,,,,,,,,,,,,,,,,
,3738629609.43175,250.502891540527,49999.75,-1.32914891681336E-7,3.8385223126233E-8,1,10,13.2042255401611,4.01109671215283,32.3400013148785,-0.000114175173766902,-4.91517365797508E-5,1,-3.53046892095866E-8,250.251922607422,250.753860473633,49999.75,49999.75,50.4040966911207,5.51542569326126,7.40903615951538,132,1,0,0,1,0.235214233398438,31.7693061828613,2,1,1,250.251922607422,0,250.502891540527,,,,,,,,,,,,,,,,,,,,,,,,,,,,,,,,,
,3738629669.39984,247.490623474121,49999.75,-1.19423718656947E-7,3.56083567123744E-8,1,10,13.2042255401611,4.01108588604318,32.3400013148785,-0.000101229639596559,-5.33276696479886E-5,1,-4.19713405440288E-8,247.23486328125,247.746383666992,49999.75,49999.75,50.43536183189,5.51534781772765,7.38664627075195,129,1,32,0,0,0.234756469726562,31.7693061828613,2,1,1,247.23486328125,0,247.490623474121,,,,,,,,,,,,,,,,,,,,,,,,,,,,,,,,,
,3738629729.46389,244.491767883301,49999.75,-1.28664013051851E-7,3.39291698403016E-8,1,10,13.2042255401611,4.01108208882775,32.3400013148785,-0.000109844269988299,-5.21667469184099E-5,1,-3.93059044426919E-8,244.242568969727,244.740966796875,49999.75,49999.75,50.381429464063,5.51602623550609,7.3688817024231,132,1,0,0,1,0.2386474609375,31.2805480957031,2,1,1,244.242568969727,0,244.491767883301,,,,,,,,,,,,,,,,,,,,,,,,,,,,,,,,,
,3738629789.46969,241.507911682129,49999.75,-1.21686713414459E-7,3.38125573004906E-8,1,10,13.2042255401611,4.01104546186436,32.3400013148785,-0.000103627459908613,-5.10847004010625E-5,1,-3.91289280841806E-8,241.283889770508,241.73193359375,49999.75,49999.75,50.4494311452361,5.51581672487642,7.34816741943359,132,1,0,0,1,0.236663818359375,30.7917900085449,2,1,1,241.283889770508,0,241.507911682129,,,,,,,,,,,,,,,,,,,,,,,,,,,,,,,,,
,3738629849.32997,238.478141784668,49999.75,-1.49547348125086E-7,3.77623392259358E-8,1,10,13.2042255401611,4.01106289379467,32.3400013148785,-0.000128501236412873,-5.50289492806341E-5,1,-3.94175920569882E-8,238.215286254883,238.740997314453,49999.75,49999.75,50.4244190326207,5.51573793472822,7.334144115448,130,1,32,0,0,0.234298706054687,31.7693061828613,2,1,1,238.215286254883,0,238.478141784668,,,,,,,,,,,,,,,,,,,,,,,,,,,,,,,,,
,3738629909.4048,235.490669250488,49999.75,-1.26723949552119E-7,3.85491310175487E-8,1,10,13.2042255401611,4.01108421357381,32.3400013148785,-0.000113967868645299,-1.23161220907268E-5,1,4.97549372687408E-9,235.255783081055,235.725555419922,49999.75,49999.75,50.3716591075726,5.51626965263241,7.31780385971069,130,1,32,0,0,0.237045288085938,30.7917900085449,2,1,1,235.255783081055,0,235.490669250488,,,,,,,,,,,,,,,,,,,,,,,,,,,,,,,,,
,3738629969.3031,232.50316619873,49999.75,-8.07299033387673E-8,2.91494705432766E-8,1,10,13.2042255401611,4.01122537769116,32.3400013148785,-7.67687232932501E-5,2.02769404077541E-5,1,3.46207236657105E-8,232.252182006836,232.754150390625,49999.75,49999.75,50.4740524435919,5.51578581395731,7.29917049407959,132,1,0,0,1,0.235671997070313,31.2805480957031,2,1,1,232.252182006836,0,232.50316619873,,,,,,,,,,,,,,,,,,,,,,,,,,,,,,,,,
,3738630029.4481,229.520706176758,49999.75,-7.33518596942349E-8,3.79737267367289E-8,1,10,13.2042255401611,4.01119012295592,32.3400013148785,-6.92138499710192E-5,1.47882101251919E-5,1,2.73911464854112E-8,229.282135009766,229.75927734375,49999.75,49999.75,50.4255914753996,5.51531866576807,7.28667688369751,132,1,0,0,1,0.239410400390625,32.7468223571777,2,1,1,229.282135009766,0,229.520706176758,,,,,,,,,,,,,,,,,,,,,,,,,,,,,,,,,
,3738630089.25449,226.530227661133,49999.75,-7.08885623088017E-8,3.91760775354801E-8,1,10,13.2042255401611,4.01121980421081,32.3400013148785,-6.62174280509023E-5,9.74397863852943E-6,1,2.13853940284355E-8,226.289154052734,226.771301269531,49999.75,49999.75,50.3282787247553,5.51549284770333,7.26541709899902,130,1,32,0,0,0.240020751953125,31.2805480957031,2,1,1,226.289154052734,0,226.530227661133,,,,,,,,,,,,,,,,,,,,,,,,,,,,,,,,,
,3738630149.23957,223.526763916016,49999.75,-6.80246831476724E-8,3.44347566588694E-8,1,10,13.2042255401611,4.01122196452737,32.3400013148785,-6.19093825026223E-5,-1.68621974052641E-6,1,8.17897596527252E-9,223.263763427734,223.789764404297,49999.75,49999.75,50.4146486761303,5.51538722661841,7.25342464447021,132,1,0,0,1,0.239105224609375,31.2805480957031,2,1,1,223.263763427734,0,223.526763916016,,,,,,,,,,,,,,,,,,,,,,,,,,,,,,,,,
,3738630209.23914,220.539070129395,49999.75,-7.20842183623073E-8,4.00738159033605E-8,1,10,13.2042255401611,4.01109106430296,32.3400013148785,-6.68013765429406E-5,6.32923034709318E-6,1,1.77438594538397E-8,220.297546386719,220.78059387207,49999.75,49999.75,50.4236374041015,5.51409397083646,7.23611307144165,130,1,32,0,0,0.23406982421875,31.7693061828613,2,1,1,220.297546386719,0,220.539070129395,,,,,,,,,,,,,,,,,,,,,,,,,,,,,,,,,
,3738630269.21671,217.506683349609,49999.75,-6.69694401917835E-8,3.15175509226313E-8,1,10,13.2042255401611,4.01115305072701,32.3400013148785,-6.558471193394E-5,2.96827471786428E-5,1,4.31044586455592E-8,217.268814086914,217.744552612305,49999.75,49999.75,50.3614979368226,5.51440538073856,7.21693325042725,132,1,0,0,1,0.23681640625,31.7693061828613,2,1,1,217.268814086914,0,217.506683349609,,,,,,,,,,,,,,,,,,,,,,,,,,,,,,,,,
,3738630329.17191,214.525123596191,49999.75,-3.54446358631293E-8,3.61683438469435E-8,1,10,13.2042255401611,4.0111074917332,32.3400013148785,-3.78277015907868E-5,3.67739162915039E-5,1,4.63713421123779E-8,214.284301757813,214.76594543457,49999.75,49999.75,50.3845559781399,5.51418550953956,7.20490217208862,130,1,32,0,0,0.239028930664062,31.7693061828613,2,1,1,214.284301757813,0,214.525123596191,,,,,,,,,,,,,,,,,,,,,,,,,,,,,,,,,
,3738630389.26468,211.52367401123,49999.75,-5.01267665955219E-8,3.3872444738341E-8,1,10,13.2042255401611,4.01110557889209,32.3400013148785,-5.23835438193703E-5,4.44816106978943E-5,1,5.71638021861149E-8,211.265426635742,211.781921386719,49999.75,49999.75,50.3329684958707,5.51418600890767,7.18602418899536,132,1,0,0,1,0.234298706054687,31.2805480957031,2,1,1,211.265426635742,0,211.52367401123,,,,,,,,,,,,,,,,,,,,,,,,,,,,,,,,,
,3738630449.34058,208.524230957031,49999.75,-5.14302489805945E-8,3.82471797740171E-8,1,10,13.2042255401611,4.01106249761628,32.3400013148785,-5.26146542214447E-5,3.79992315740401E-5,1,5.01076460180713E-8,208.284118652344,208.764343261719,49999.75,49999.75,50.3486010662553,5.51355299063968,7.17072010040283,132,1,0,0,1,0.23773193359375,31.7693061828613,2,1,1,208.284118652344,0,208.524230957031,,,,,,,,,,,,,,,,,,,,,,,,,,,,,,,,,
,3738630509.13309,205.560211181641,49999.75,-3.80195622216462E-8,3.79609290890347E-8,1,10,13.2042255401611,4.01116814230258,32.3400013148785,-4.12454366437745E-5,4.39659871749838E-5,1,5.47945747295833E-8,205.31217956543,205.808242797852,49999.75,49999.75,50.4232465898419,5.51444102253407,7.1548023223877,132,1,0,0,1,0.235595703125,31.7693061828613,2,1,1,205.31217956543,0,205.560211181641,,,,,,,,,,,,,,,,,,,,,,,,,,,,,,,,,
,3738630569.07917,202.537223815918,49999.75,-6.27422130556368E-8,3.73893528499236E-8,1,10,13.2042255401611,4.01101269981627,32.3400013148785,-6.1968339341616E-5,3.13685703559375E-5,1,4.4366317798332E-8,202.289993286133,202.784454345703,49999.75,49999.75,50.284898341938,5.51252847130751,7.13604688644409,132,1,0,0,1,0.238265991210938,31.2805480957031,2,1,1,202.289993286133,0,202.537223815918,,,,,,,,,,,,,,,,,,,,,,,,,,,,,,,,,
,3738630629.13088,199.537902832031,49999.75,-1.73665356105833E-8,4.88846450485994E-8,1,10,13.2042255401611,4.0110308446188,32.3400013148785,-1.74353139623502E-5,1.0594379428614E-5,1,1.44183584381015E-8,199.288024902344,199.787780761719,49999.75,49999.75,50.3700958505342,5.51251970916131,7.12212896347046,132,1,0,0,1,0.240249633789062,31.2805480957031,2,1,1,199.288024902344,0,199.537902832031,,,,,,,,,,,,,,,,,,,,,,,,,,,,,,,,,
,3738630689.22139,196.527877807617,49999.75,-7.6171659723314E-8,4.80889149540563E-8,1,10,13.2042255401611,4.01106595142845,32.3400013148785,-7.50421502536173E-5,3.67886768389457E-5,1,5.24143712067383E-8,196.285766601562,196.769989013672,49999.75,49999.75,50.3321868673515,5.51261073745618,7.10666656494141,132,1,0,0,1,0.235977172851562,31.7693061828613,2,1,1,196.285766601562,0,196.527877807617,,,,,,,,,,,,,,,,,,,,,,,,,,,,,,,,,
,3738630749.02631,193.553298950195,49999.75,-3.2189182894201E-8,4.43652044536686E-8,1,10,13.2042255401611,4.01105313513575,32.3400013148785,-3.40649207875167E-5,3.14510957758748E-5,1,3.99375204811883E-8,193.304443359375,193.802154541016,49999.75,49999.75,50.3130369686303,5.51312452501539,7.09510564804077,132,1,0,0,1,0.23345947265625,31.2805480957031,2,1,1,193.304443359375,0,193.553298950195,,,,,,,,,,,,,,,,,,,,,,,,,,,,,,,,,
,3738630809.01313,190.562675476074,49999.75,-1.8150176404874E-8,4.67116196500916E-8,1,10,13.2042255401611,4.0110851074994,32.3400013148785,-2.37739259796583E-5,4.85935790619246E-5,1,5.70318188614445E-8,190.302749633789,190.822601318359,49999.75,49999.75,50.3529000231111,5.51282254951466,7.077476978302,132,1,0,0,1,0.23529052734375,30.7917900085449,2,1,1,190.302749633789,0,190.562675476074,,,,,,,,,,,,,,,,,,,,,,,,,,,,,,,,,
,3738630868.96576,187.557952880859,49999.75,-5.30098409688936E-9,4.86711634689992E-8,1,10,13.2042255401611,4.01110997417694,32.3400013148785,-4.04854499141873E-8,-3.24633552405836E-5,1,-3.55218846676172E-8,187.314102172852,187.801803588867,49999.75,49999.75,50.3544632801496,5.51309962017165,7.06274366378784,132,1,0,0,1,0.235977172851562,31.2805480957031,2,1,1,187.314102172852,0,187.557952880859,,,,,,,,,,,,,,,,,,,,,,,,,,,,,,,,,
,3738630929.09616,184.537582397461,49999.75,-4.79370559771283E-8,4.01545216077041E-8,1,10,13.2042255401611,4.01110779375449,32.3400013148785,-4.25572684119896E-5,-8.40891782537946E-6,1,-2.3117149218843E-9,184.287979125977,184.787185668945,49999.75,49999.75,50.3642336366399,5.51291872268591,7.0510082244873,132,1,0,0,1,0.235595703125,31.7693061828613,2,1,1,184.287979125977,0,184.537582397461,,,,,,,,,,,,,,,,,,,,,,,,,,,,,,,,,
,3738630988.93151,181.564308166504,49999.75,-7.06084535280695E-8,3.49038543192176E-8,1,10,13.2042255401611,4.01108094206845,32.3400013148785,-6.07752511039853E-5,-2.52842259597999E-5,1,-1.7830565368789E-8,181.321304321289,181.807312011719,49999.75,49999.75,50.3161634827072,5.51287961449194,7.04550361633301,132,1,0,0,1,0.239181518554687,30.7917900085449,2,1,1,181.321304321289,0,181.564308166504,,,,,,,,,,,,,,,,,,,,,,,,,,,,,,,,,
,3738631048.9361,178.565422058105,49999.75,-5.41166938699693E-8,4.50456033256123E-8,1,10,13.2042255401611,4.01104254889193,32.3400013148785,-4.51165221011673E-5,-2.92661611615923E-5,1,-2.47244812228926E-8,178.325119018555,178.805725097656,49999.75,49999.75,50.3779121357265,5.51233763022253,7.03094482421875,132,1,0,0,1,0.23712158203125,31.7693061828613,2,1,1,178.325119018555,0,178.565422058105,,,,,,,,,,,,,,,,,,,,,,,,,,,,,,,,,
,3738631108.89061,175.578605651855,49999.75,-4.59952857664935E-8,3.94712988872464E-8,1,10,13.2042255401611,4.0110528236944,32.3400013148785,-3.83162918096999E-5,-2.50746490333461E-5,1,-2.12381771776823E-8,175.341033935547,175.816177368164,49999.75,49999.75,50.3685325934957,5.51251122116728,7.02141332626343,132,1,0,0,1,0.23345947265625,30.7917900085449,2,1,1,175.341033935547,0,175.578605651855,,,,,,,,,,,,,,,,,,,,,,,,,,,,,,,,,
,3738631168.88332,172.569030761719,49999.75,-4.61914555407908E-8,3.7181591203803E-8,1,10,13.2042255401611,4.01106375966262,32.3400013148785,-4.07824432462721E-5,-9.61929053719202E-6,1,-3.92382831202295E-9,172.331695556641,172.806365966797,49999.75,49999.75,50.3196808110438,5.5124281427569,7.00787830352783,132,1,0,0,1,0.238037109375,31.2805480957031,2,1,1,172.331695556641,0,172.569030761719,,,,,,,,,,,,,,,,,,,,,,,,,,,,,,,,,
,3738631228.84595,169.592483520508,49999.75,-4.39481619149235E-8,3.94178503659022E-8,1,10,13.2042255401611,4.01101001173116,32.3400013148785,-3.81001296053125E-5,-1.38889948266051E-5,1,-9.03128847147926E-9,169.344314575195,169.84065246582,49999.75,49999.75,50.3349225671688,5.51312324918056,6.99029970169067,132,1,0,0,1,0.239181518554687,32.2580642700195,2,1,1,169.344314575195,0,169.592483520508,,,,,,,,,,,,,,,,,,,,,,,,,,,,,,,,,
,3738631289.04235,166.554069519043,49999.75,-4.23993608099329E-8,4.54272520774998E-8,1,10,13.2042255401611,4.01101305033773,32.3400013148785,-4.62754399998499E-5,5.0929845106636E-5,1,6.3234129684821E-8,166.292816162109,166.815322875977,49999.75,49999.75,50.42520066114,5.5127221605966,6.98170804977417,132,1,0,0,1,0.232772827148438,30.7917900085449,2,1,1,166.292816162109,0,166.554069519043,,,,,,,,,,,,,,,,,,,,,,,,,,,,,,,,,
,3738631348.80057,163.588478088379,49999.75,-3.71228646032561E-8,4.19366851594925E-8,1,10,13.2042255401611,4.01104152232452,32.3400013148785,-3.85744918942919E-5,3.14631458509143E-5,1,4.0681131655032E-8,163.337768554687,163.83918762207,49999.75,49999.75,50.3474286234765,5.51328466770303,6.97083234786987,132,1,0,0,1,0.233230590820313,31.2805480957031,2,1,1,163.326705932617,0,163.588478088379,,,,,,,,,,,,,,,,,,,,,,,,,,,,,,,,,
,3738631408.84645,160.584800720215,49999.75,-3.5226414032447E-8,4.04354916896331E-8,1,10,13.2042255401611,4.01106206593688,32.3400013148785,-3.13833631629328E-5,-5.43002440803298E-6,1,-8.60929302820892E-10,160.338562011719,160.831039428711,49999.75,49999.75,50.3341409386496,5.51356000118217,6.96073198318481,132,1,0,0,1,0.238113403320313,31.7693061828613,2,1,1,160.338562011719,0,160.584800720215,,,,,,,,,,,,,,,,,,,,,,,,,,,,,,,,,
,3738631468.75991,157.571090698242,49999.75,-7.25888744399492E-8,4.38286723696684E-8,1,10,13.2042255401611,4.01104461787256,32.3400013148785,-6.4491675994689E-5,-1.23896855909182E-5,1,-3.11665190559846E-9,157.312973022461,157.829208374023,49999.75,49999.75,50.3439112951399,5.51317561559941,6.94746112823486,130,1,32,0,0,0.2392578125,31.2805480957031,2,1,1,157.312973022461,0,157.571090698242,,,,,,,,,,,,,,,,,,,,,,,,,,,,,,,,,
,3738631528.75444,154.602172851562,49999.75,-3.11458122156281E-8,3.66776028803332E-8,1,10,13.2042255401611,4.01103168417596,32.3400013148785,-2.84501578291512E-5,-5.2577063773738E-8,1,4.54943359023276E-9,154.355941772461,154.848403930664,49999.75,49999.75,50.386510049438,5.51363653632188,6.93732500076294,132,1,0,0,1,0.23834228515625,31.2805480957031,2,1,1,154.355941772461,0,154.602172851562,,,,,,,,,,,,,,,,,,,,,,,,,,,,,,,,,
,3738631588.72412,151.578239440918,49999.75,-2.28473001797651E-8,3.54450245147666E-8,1,10,13.2042255401611,4.01104062039461,32.3400013148785,-2.03716529500807E-5,-3.40643547892707E-6,1,-4.29362325847271E-10,151.320983886719,151.835494995117,49999.75,49999.75,50.2782544995246,5.51315118883822,6.92445087432861,132,1,0,0,1,0.235977172851562,30.3030319213867,2,1,1,151.320983886719,0,151.578239440918,,,,,,,,,,,,,,,,,,,,,,,,,,,,,,,,,
,3738631648.7552,148.591300964355,49999.75,-2.66709840510628E-8,3.40297316729927E-8,1,10,13.2042255401611,4.01105788299815,32.3400013148785,-2.43750749170128E-5,3.74161393342774E-8,1,3.98800094205311E-9,148.347946166992,148.834655761719,49999.75,49999.75,50.3583714227457,5.51265735877834,6.91499042510986,132,1,0,0,1,0.233078002929687,31.2805480957031,2,1,1,148.347946166992,0,148.591300964355,,,,,,,,,,,,,,,,,,,,,,,,,,,,,,,,,
,3738631708.67884,145.58740234375,49999.75,-2.99115034944574E-8,3.53687699976556E-8,1,10,13.2042255401611,4.01099329562672,32.3400013148785,-2.50373747161465E-5,-1.54934169837166E-5,1,-1.29026400679018E-8,145.333908081055,145.840896606445,49999.75,49999.75,50.350945951813,5.5136270263574,6.90342426300049,132,1,0,0,1,0.235137939453125,30.7917900085449,2,1,1,145.333908081055,0,145.58740234375,,,,,,,,,,,,,,,,,,,,,,,,,,,,,,,,,
,3738631768.86412,142.579376220703,49999.75,-3.27095235068892E-9,4.42536963257668E-8,1,10,13.2042255401611,4.01103816874855,32.3400013148785,-3.91871779053723E-7,-1.75511032319553E-5,1,-1.91453134703601E-8,142.305191040039,142.853561401367,49999.75,49999.75,50.3013125408419,5.51332008528961,6.8891396522522,132,1,0,0,1,0.239944458007813,32.2580642700195,2,1,1,142.305191040039,0,142.579376220703,,,,,,,,,,,,,,,,,,,,,,,,,,,,,,,,,
,3738631828.67594,139.59944152832,49999.75,-5.64765048525825E-8,3.68977687488714E-8,1,10,13.2042255401611,4.01101582167885,32.3400013148785,-4.96188121781298E-5,-1.3405666585899E-5,1,-6.63703605459647E-9,139.346694946289,139.852188110352,49999.75,49999.75,50.4025334340823,5.51341590683316,6.87556314468384,128,1,100,0,0,0.236968994140625,30.7917900085449,2,1,1,139.346694946289,0,139.59944152832,,,,,,,,,,,,,,,,,,,,,,,,,,,,,,,,,
,3738631888.65627,136.557403564453,49999.75,-2.00742624070694E-8,4.50614205158773E-8,1,10,13.2042255401611,4.01097850403853,32.3400013148785,-1.10371400246174E-5,-4.93679834577178E-5,1,-5.22446728988254E-8,136.325561523438,136.789245605469,49999.75,49999.75,50.3505551375534,5.51384844008915,6.86078691482544,132,1,0,0,1,0.235137939453125,33.2355842590332,2,1,1,136.325561523438,0,136.557403564453,,,,,,,,,,,,,,,,,,,,,,,,,,,,,,,,,
,3738631948.60428,133.598815917969,49999.75,-3.54305387772724E-8,3.41227295802531E-8,1,10,13.2042255401611,4.01097835023848,32.3400013148785,-3.09401756719596E-5,-9.6787075924892E-6,1,-5.58279877295743E-9,133.354736328125,133.842895507812,49999.75,49999.75,50.3919814490726,5.51418011771507,6.85359191894531,130,1,32,0,0,0.239028930664062,30.3030319213867,2,1,1,133.354736328125,0,133.598815917969,,,,,,,,,,,,,,,,,,,,,,,,,,,,,,,,,
,3738632008.64774,130.597282409668,49999.75,-1.14768037838168E-8,3.87845891851602E-8,1,10,13.2042255401611,4.01098189986779,32.3400013148785,-8.16957592085869E-6,-1.56571009428103E-5,1,-1.58133279872477E-8,130.351470947266,130.84309387207,49999.75,49999.75,50.3532908373707,5.51346481802102,6.84047937393188,130,1,32,0,0,0.236129760742187,33.2355842590332,2,1,1,130.351470947266,0,130.597282409668,,,,,,,,,,,,,,,,,,,,,,,,,,,,,,,,,
,3738632068.75024,127.573986053467,49999.75,-3.07516236181844E-8,3.37595464097346E-8,1,10,13.2042255401611,4.01098870722651,32.3400013148785,-3.00863452038606E-5,1.34435022474814E-5,1,1.95855132542015E-8,127.33715057373,127.810821533203,49999.75,49999.75,50.3368766384669,5.51340881284555,6.82690572738647,130,1,32,0,0,0.237503051757813,31.7693061828613,2,1,1,127.33715057373,0,127.573986053467,,,,,,,,,,,,,,,,,,,,,,,,,,,,,,,,,
,3738632128.52102,124.604808807373,49999.75,-2.8583768896362E-8,3.04428849324026E-8,1,10,13.2042255401611,4.01098023327925,32.3400013148785,-2.7543956259814E-5,9.6480349114352E-6,1,1.5019840711447E-8,124.361862182617,124.847755432129,49999.75,49999.75,50.4076140194573,5.51350175944743,6.81778383255005,130,1,32,0,0,0.236358642578125,33.2355842590332,2,1,1,124.361862182617,0,124.604808807373,,,,,,,,,,,,,,,,,,,,,,,,,,,,,,,,,
,3738632188.55297,121.597835540771,49999.75,-4.18907287782786E-8,3.39582265050583E-8,1,10,13.2042255401611,4.01099727097585,32.3400013148785,-3.6831894961907E-5,-9.75386939874717E-6,1,-4.71095086764679E-9,121.35977935791,121.835891723633,49999.75,49999.75,50.4287179894765,5.51343549743047,6.80188417434692,132,1,0,0,1,0.23223876953125,31.7693061828613,2,1,1,121.35977935791,0,121.597835540771,,,,,,,,,,,,,,,,,,,,,,,,,,,,,,,,,
,3738632248.48248,118.607406616211,49999.75,-2.93376583993469E-8,3.47792590523858E-8,1,10,13.2042255401611,4.01095793253315,32.3400013148785,-3.08497549827909E-5,2.73371197128253E-5,1,3.49157029604805E-8,118.341613769531,118.873199462891,49999.75,49999.75,50.3231981393803,5.5142069914313,6.79219436645508,130,1,32,0,0,0.240554809570313,31.2805480957031,2,1,1,118.341613769531,0,118.607406616211,,,,,,,,,,,,,,,,,,,,,,,,,,,,,,,,,
,3738632308.46037,115.60266494751,49999.75,-2.90126245662113E-8,3.46825171067751E-8,1,10,13.2042255401611,4.01097560828614,32.3400013148785,-2.66279370290942E-5,8.08917008405188E-7,1,5.19733733576646E-9,115.345108032227,115.860221862793,49999.75,49999.75,50.3552449086688,5.51363259663378,6.77766752243042,132,1,0,0,1,0.23712158203125,31.7693061828613,2,1,1,115.345108032227,0,115.60266494751,,,,,,,,,,,,,,,,,,,,,,,,,,,,,,,,,
,3738632368.45056,112.611598968506,49999.75,-1.43312461162054E-8,2.96111535935608E-8,1,10,13.2042255401611,4.0110586903217,32.3400013148785,-1.47924281464043E-5,1.14751308684244E-5,1,1.49541658437708E-8,112.375831604004,112.847366333008,49999.75,49999.75,50.4306720607746,5.51423013945509,6.75983572006226,132,1,0,0,1,0.2349853515625,30.7917900085449,2,1,1,112.375831604004,0,112.611598968506,,,,,,,,,,,,,,,,,,,,,,,,,,,,,,,,,
,3738632428.50393,109.601127624512,49999.75,-3.01379582457109E-8,4.75224640995804E-8,1,10,13.2042255401611,4.0110356044943,32.3400013148785,-2.89046251595004E-5,9.24270648419795E-6,1,1.47962337428678E-8,109.349876403809,109.852378845215,49999.75,49999.75,50.361107122563,5.51421664008732,6.75038814544678,132,1,0,0,1,0.2398681640625,31.2805480957031,2,1,1,109.349876403809,0,109.601127624512,,,,,,,,,,,,,,,,,,,,,,,,,,,,,,,,,
,3738632488.60621,106.59428024292,49999.75,-3.90010955032163E-8,3.78455847086124E-8,1,10,13.2042255401611,4.01100688989523,32.3400013148785,-3.4340607626398E-5,-8.74817706917688E-6,1,-4.0136630910829E-9,106.334426879883,106.854133605957,49999.75,49999.75,50.3740039931303,5.51376011288911,6.73932552337646,132,1,0,0,1,0.236434936523438,31.7693061828613,2,1,1,106.334426879883,0,106.59428024292,,,,,,,,,,,,,,,,,,,,,,,,,,,,,,,,,
,3738632548.37252,103.620796203613,49999.75,-3.83092046340895E-8,3.84974167133202E-8,1,10,13.2042255401611,4.01105881330276,32.3400013148785,-3.28152636578866E-5,-1.47897455904602E-5,1,-1.08727071564524E-8,103.371223449707,103.87036895752,49999.75,49999.75,50.4701443009957,5.51368124506315,6.72454452514648,132,1,0,0,1,0.234909057617187,31.2805480957031,2,1,1,103.371223449707,0,103.620796203613,,,,,,,,,,,,,,,,,,,,,,,,,,,,,,,,,
,3738632608.36509,100.620697021484,49999.75,-5.69312776490292E-9,3.4103324459782E-8,1,10,13.2042255401611,4.01102473331902,32.3400013148785,-8.98941969803398E-6,2.55995020326477E-5,1,2.94731473534589E-8,100.382377624512,100.859016418457,49999.75,49999.75,50.3822110925823,5.51391941613518,6.70153379440308,132,1,0,0,1,0.233383178710938,30.7917900085449,2,1,1,100.382377624512,0,100.620697021484,,,,,,,,,,,,,,,,,,,,,,,,,,,,,,,,,
,3738632668.35392,97.60791015625,49999.75,-4.04480044629169E-8,3.38836427783067E-8,1,10,13.2042255401611,4.01102237272565,32.3400013148785,-3.74121273563684E-5,3.07462323780329E-6,1,9.42326048875871E-9,97.3699417114258,97.8458786010742,49999.75,49999.75,50.3673601507169,5.51403087754554,6.69108963012695,132,1,0,0,1,0.2349853515625,31.2805480957031,2,1,1,97.3699417114258,0,97.60791015625,,,,,,,,,,,,,,,,,,,,,,,,,,,,,,,,,
,3738632728.47104,94.6174926757812,49999.75,-2.03718525569879E-8,3.62832770275722E-8,1,10,13.2042255401611,4.01098569480654,32.3400013148785,-1.85753852267717E-5,-2.57114083630434E-7,1,2.72659101098716E-9,94.378547668457,94.8564376831055,49999.75,49999.75,50.391590634813,5.51409728088607,6.68002939224243,130,1,32,0,0,0.238494873046875,30.3030319213867,2,1,1,94.378547668457,0,94.6174926757812,,,,,,,,,,,,,,,,,,,,,,,,,,,,,,,,,
,3738632788.30171,91.637996673584,49999.75,1.63418092038003E-8,3.78292992361637E-8,1,10,13.2042255401611,4.01101209943729,32.3400013148785,1.26941052404067E-5,1.51212600687613E-5,1,1.44940126992191E-8,91.4028091430664,91.8731842041016,49999.75,49999.75,50.4076140194573,5.51403477958191,6.66432857513428,132,1,0,0,1,0.23651123046875,30.7917900085449,2,1,1,91.4028091430664,0,91.637996673584,,,,,,,,,,,,,,,,,,,,,,,,,,,,,,,,,
,3738632848.28947,88.6131896972656,49999.75,1.30766649731042E-9,4.7954836607966E-8,1,10,13.2042255401611,4.0110358019667,32.3400013148785,-1.07624310566562E-6,1.5349477086325E-5,1,1.69734975436638E-8,88.3584671020508,88.8679122924805,49999.75,49999.75,50.3923722633323,5.51396231907496,6.64460325241089,130,1,32,0,0,0.239334106445313,31.7693061828613,2,1,1,88.3584671020508,0,88.6131896972656,,,,,,,,,,,,,,,,,,,,,,,,,,,,,,,,,
,3738632908.24403,85.6261405944824,49999.75,-2.4728702452087E-8,4.07301182847832E-8,1,10,13.2042255401611,4.01105271392512,32.3400013148785,-2.30918542228619E-5,3.35938060951333E-6,1,7.41591335569821E-9,85.3741607666016,85.8781204223633,49999.75,49999.75,50.2962319554669,5.51444452749532,6.6255373954773,132,1,0,0,1,0.238723754882813,31.7693061828613,2,1,1,85.3741607666016,0,85.6261405944824,,,,,,,,,,,,,,,,,,,,,,,,,,,,,,,,,
,3738632968.23538,82.613094329834,49999.75,-4.09400038925305E-8,4.37579365992418E-8,1,10,13.2042255401611,4.01104120872103,32.3400013148785,-3.89548510279132E-5,1.04612725652926E-5,1,1.7757298330876E-8,82.3657684326172,82.8604202270508,49999.75,49999.75,50.4603739445053,5.51338004733741,6.61847114562988,130,1,32,0,0,0.234832763671875,31.2805480957031,2,1,1,82.3657684326172,0,82.613094329834,,,,,,,,,,,,,,,,,,,,,,,,,,,,,,,,,
,3738633028.20127,79.5869483947754,49999.75,-3.12663622597769E-8,4.69116034188807E-8,1,10,13.2042255401611,4.01106180390844,32.3400013148785,-2.75053923380361E-5,-7.18475091038169E-6,1,-3.40932635474957E-9,79.3442764282227,79.8296203613281,49999.75,49999.75,50.4365342746688,5.51366300766823,6.59658908843994,132,1,0,0,1,0.238876342773438,31.2805480957031,2,1,1,79.3442764282227,0,79.5869483947754,,,,,,,,,,,,,,,,,,,,,,,,,,,,,,,,,
,3738633088.28931,76.5670051574707,49999.75,-1.95456557486611E-8,4.48751298755489E-8,1,10,13.2042255401611,4.01104670019729,32.3400013148785,-1.78786640741197E-5,1.33056563264822E-7,1,3.04072453054065E-9,76.3184661865234,76.815544128418,49999.75,49999.75,50.432235317813,5.51383822994298,6.58300876617432,130,1,100,0,0,0.234375,31.7693061828613,2,1,1,76.3184661865234,0,76.5670051574707,,,,,,,,,,,,,,,,,,,,,,,,,,,,,,,,,
,3738633148.34297,73.5498695373535,49999.75,3.72696622633076E-9,6.10385014827648E-8,1,10,13.2042255401611,4.01104989308548,32.3400013148785,-3.17073752990063E-6,4.44460136567373E-5,1,4.91570623564599E-8,73.2977828979492,73.8019561767578,49999.75,49999.75,50.3951079631496,5.51402714298432,6.56115102767944,132,1,0,0,1,0.236129760742187,30.7917900085449,2,1,1,73.2977828979492,0,73.5498695373535,,,,,,,,,,,,,,,,,,,,,,,,,,,,,,,,,
,3738633208.14911,70.5324096679688,49999.75,-3.82185396679221E-8,5.04562210304348E-8,1,10,13.2042255401611,4.01110147189721,32.3400013148785,-3.53474339093539E-5,2.88040528234323E-6,1,8.87607861082186E-9,70.2994995117187,70.7653198242188,49999.75,49999.75,50.3755672501688,5.51322382323997,6.53708696365356,130,1,68,0,0,0.2398681640625,31.7693061828613,2,1,1,70.2994995117187,0,70.5324096679688,,,,,,,,,,,,,,,,,,,,,,,,,,,,,,,,,
,3738633268.12337,67.5294723510742,49999.75,3.95038967153814E-8,4.88548123342781E-8,1,10,13.2042255401611,4.01106876730796,32.3400013148785,3.79019360734489E-5,-1.2210879271429E-5,1,-1.95014365829252E-8,67.2868957519531,67.7720489501953,49999.75,49999.75,50.48616768564,5.51377187550912,6.52734661102295,128,1,32,0,0,0.235595703125,31.2805480957031,2,1,1,67.2868957519531,0,67.5294723510742,,,,,,,,,,,,,,,,,,,,,,,,,,,,,,,,,
,3738633328.14896,64.4875907897949,49999.75,6.694444217505E-8,5.20003970512431E-8,1,10,13.2042255401611,4.01106183941727,32.3400013148785,5.74509360682239E-5,2.51218617632165E-5,1,1.81913080575126E-8,64.2394943237305,64.7356872558594,49999.75,49999.75,50.3751764359092,5.51288841566404,6.49869251251221,132,1,0,0,1,0.2392578125,30.7917900085449,2,1,1,64.2394943237305,0,64.4875907897949,,,,,,,,,,,,,,,,,,,,,,,,,,,,,,,,,
,3738633388.22542,61.4553203582764,49999.75,6.39891533385752E-9,5.0104487189836E-8,1,10,13.2042255401611,4.01103838181002,32.3400013148785,-8.85658846341405E-7,4.55022192527098E-5,1,4.9943223957767E-8,61.2021789550781,61.7084617614746,49999.75,49999.75,50.3904181920342,5.5131743767442,6.48228406906128,128,1,32,0,0,0.239486694335938,31.2805480957031,2,1,1,61.2021789550781,0,61.4553203582764,,,,,,,,,,,,,,,,,,,,,,,,,,,,,,,,,
,3738633448.06719,58.4336185455322,49999.75,7.52887269888856E-8,5.35955765123107E-8,1,10,13.2042255401611,4.01102757751023,32.3400013148785,7.04651581184707E-5,-1.13137062241396E-5,1,-2.37928622086651E-8,58.188907623291,58.6783294677734,49999.75,49999.75,50.4263731039188,5.51295789217593,6.45807218551636,130,1,68,0,0,0.23101806640625,31.2805480957031,2,1,1,58.188907623291,0,58.4336185455322,,,,,,,,,,,,,,,,,,,,,,,,,,,,,,,,,
,3738633508.04714,55.4068012237549,49999.75,5.06450668002202E-8,5.04349060452758E-8,1,10,13.2042255401611,4.01104479186417,32.3400013148785,3.91280627850459E-5,4.83018480209898E-5,1,4.65276887470163E-8,55.1499214172363,55.6636810302734,49999.75,49999.75,50.4205108900246,5.51313046828147,6.43095970153809,130,1,32,0,0,0.240631103515625,32.2580642700195,2,1,1,55.1499214172363,0,55.4068012237549,,,,,,,,,,,,,,,,,,,,,,,,,,,,,,,,,
,3738633568.02065,52.3825607299805,49999.75,2.71608422363646E-8,5.1496855375477E-8,1,10,13.2042255401611,4.01104253857459,32.3400013148785,1.79629815622009E-5,4.63242780709776E-5,1,4.77906651701689E-8,52.1386985778809,52.6264228820801,49999.75,49999.75,50.4240282183611,5.51279698306352,6.40471029281616,132,1,0,0,1,0.235519409179687,30.7917900085449,2,1,1,52.1386985778809,0,52.3825607299805,,,,,,,,,,,,,,,,,,,,,,,,,,,,,,,,,
,3738633628.09692,49.3563690185547,49999.75,3.06841968210851E-8,4.64083722963038E-8,1,10,13.2042255401611,4.01106652340087,32.3400013148785,2.38898467671076E-5,2.80264155309307E-5,1,2.68046435782059E-8,49.1190071105957,49.5937309265137,49999.75,49999.75,50.4412240457842,5.51262449029133,6.36776828765869,128,1,100,0,0,0.237197875976562,31.2805480957031,2,1,1,49.1190071105957,0,49.3563690185547,,,,,,,,,,,,,,,,,,,,,,,,,,,,,,,,,
,3738633687.97319,46.3370113372803,49999.75,6.22136780142481E-8,4.62858047889742E-8,1,10,13.2042255401611,4.01104906607918,32.3400013148785,5.37742139561396E-5,2.07549220053553E-5,1,1.40074056225011E-8,46.0905914306641,46.5834312438965,49999.75,49999.75,50.4259822896592,5.51308950471347,6.32913684844971,128,1,68,0,0,0.236434936523438,31.2805480957031,2,1,1,46.085506439209,0,46.3370113372803,,,,,,,,,,,,,,,,,,,,,,,,,,,,,,,,,
,3738633747.95053,43.3089199066162,49999.75,3.66152675159529E-8,4.2648949205654E-8,1,10,13.2042255401611,4.01111127561601,32.3400013148785,2.78085237587721E-5,3.81727100364208E-5,1,3.72738989194636E-8,43.0596351623535,43.5582046508789,49999.75,49999.75,50.4400516030053,5.51315043082593,6.29357290267944,128,1,32,0,0,0.238113403320313,31.7693061828613,2,1,1,43.0596351623535,0,43.3089199066162,,,,,,,,,,,,,,,,,,,,,,,,,,,,,,,,,
,3738633807.94473,40.3190135955811,49999.75,3.6792143534105E-8,4.40596577322097E-8,1,10,13.2042255401611,4.01110239913004,32.3400013148785,3.04796754080079E-5,2.12106469515982E-5,1,1.82778768103929E-8,40.0682106018066,40.5698165893555,49999.75,49999.75,50.467799415438,5.51300656460076,6.2508716583252,129,1,68,0,0,0.241012573242187,31.2805480957031,2,1,1,40.0682106018066,0,40.3190135955811,,,,,,,,,,,,,,,,,,,,,,,,,,,,,,,,,
,3738633867.94418,37.2732601165771,49999.75,-9.26230576697837E-10,4.53256013380652E-8,1,10,13.2042255401611,4.01111141838109,32.3400013148785,8.91087822529843E-7,-1.17426922204466E-5,1,-1.29956825102677E-8,37.0284652709961,37.5180549621582,49999.75,49999.75,50.488121756938,5.51281706929,6.20042181015015,132,1,0,0,1,0.23773193359375,32.2580642700195,2,1,1,37.0284652709961,0,37.2732601165771,,,,,,,,,,,,,,,,,,,,,,,,,,,,,,,,,
,3738633927.88189,34.260814666748,49999.75,7.37671028748129E-8,4.66706568812804E-8,1,10,13.2042255401611,4.01116310873416,32.3400013148785,7.10871536185746E-5,-2.48897728161895E-5,1,-3.87498577044676E-8,34.0123252868652,34.5093040466309,49999.75,49999.75,50.5408816819861,5.51256190662695,6.14747285842895,131,1,68,0,0,0.230636596679687,31.2805480957031,2,1,1,34.0123252868652,0,34.260814666748,,,,,,,,,,,,,,,,,,,,,,,,,,,,,,,,,
,3738633988.02779,31.2135200500488,49999.75,5.81066334360707E-8,4.32364237030957E-8,1,10,13.2042255401611,4.0111326517382,32.3400013148785,4.70759912946421E-5,4.06752718837444E-5,1,3.6892518657959E-8,30.9599304199219,31.4671096801758,49999.75,49999.75,50.498282927688,5.51347807236381,6.08202123641968,128,1,100,0,0,0.239181518554687,31.7693061828613,2,1,1,30.9599304199219,0,31.2135200500488,,,,,,,,,,,,,,,,,,,,,,,,,,,,,,,,,
,3738634047.83716,28.2049808502197,49999.75,5.15087670936304E-8,6.10839015102411E-8,1,10,13.2042255401611,4.0111049914525,32.3400013148785,4.69389120840958E-5,8.51822790172621E-7,1,-6.66841585073834E-9,27.9570655822754,28.4528961181641,49999.75,49999.75,50.5111797982553,5.51289393136618,5.99999809265137,132,1,0,0,1,0.233078002929687,31.7693061828613,2,1,1,27.9570655822754,0,28.2049808502197,,,,,,,,,,,,,,,,,,,,,,,,,,,,,,,,,
,3738634107.83488,25.2011432647705,49999.75,1.14456302270793E-7,4.14119952135083E-8,1,10,13.2042255401611,4.0111640115721,32.3400013148785,0.00010298399068203,1.08157330058145E-5,1,-4.83880943037121E-9,24.9576683044434,25.4446182250977,49999.75,49999.75,50.5072716556592,5.51312091866156,5.89717960357666,127,1,100,0,0,0.239486694335938,31.2805480957031,2,1,1,24.9576683044434,0,25.2011432647705,,,,,,,,,,,,,,,,,,,,,,,,,,,,,,,,,
,3738634167.80884,22.2022619247437,49999.75,1.21559595544002E-7,4.16935275274834E-8,1,10,13.2042255401611,4.01121297142757,32.3400013148785,0.000111827168976318,-5.06994886910974E-6,1,-2.36554464498968E-8,21.9535255432129,22.4509983062744,49999.75,49999.75,50.5158695693707,5.51288705415583,5.75860595703125,130,1,32,0,0,0.23834228515625,31.7693061828613,2,1,1,21.94167137146,0,22.2022619247437,,,,,,,,,,,,,,,,,,,,,,,,,,,,,,,,,
,3738634227.8233,19.1961097717285,49999.75,1.67855613906002E-7,3.90644896388355E-8,1,10,13.2042255401611,4.0111771232147,32.3400013148785,0.000149242529129389,2.79544539176209E-5,1,6.42733745894241E-9,18.9405899047852,19.4516296386719,49999.75,49999.75,50.6221710479861,5.51332437769073,5.56984424591064,130,1,68,0,0,0.23956298828125,31.2805480957031,2,1,1,18.9405899047852,0,19.1961097717285,,,,,,,,,,,,,,,,,,,,,,,,,,,,,,,,,
,3738634287.91729,16.2104353904724,49999.75,2.23629261820789E-7,3.98469260625341E-8,1,10,13.2042255401611,4.01124318825276,32.3400013148785,0.000193989306754591,7.00067667802149E-5,1,4.5202185607182E-8,15.9593172073364,16.4615535736084,49999.75,49999.75,50.6721952732169,5.51321148102626,5.31937456130981,130,1,68,0,0,0.237655639648438,31.2805480957031,2,1,1,15.9593172073364,0,16.2104353904724,,,,,,,,,,,,,,,,,,,,,,,,,,,,,,,,,
,3738634347.72326,13.2687249183655,49999.75,2.78546011248436E-7,4.13193805368893E-8,1,10,13.2042255401611,4.01114212507236,32.3400013148785,0.000248087662424808,4.34658527422614E-5,1,7.39770704789364E-9,13.0202531814575,13.5171966552734,49999.75,49999.75,50.7171389130727,5.51410011510945,5.00561857223511,132,1,0,0,1,0.236740112304687,30.7917900085449,2,1,1,13.0202531814575,0,13.2687249183655,,,,,,,,,,,,,,,,,,,,,,,,,,,,,,,,,
,3738634407.73548,10.3488359451294,49999.75,3.57854103270467E-7,4.30755299051037E-8,1,10,13.2042255401611,4.01121873130814,32.3400013148785,0.000313701017005531,8.98550690620774E-5,1,4.75403453796557E-8,10.1038398742676,10.5938320159912,49999.75,49999.75,50.8070261927842,5.51444824051716,4.60634088516235,131,1,68,0,0,0.24139404296875,31.7693061828613,2,1,1,10.1038398742676,0,10.3488359451294,,,,,,,,,,,,,,,,,,,,,,,,,,,,,,,,,
,3738634467.70059,7.20404815673828,49999.75,4.35125502358035E-7,4.23212622354858E-8,1,10,13.2042255401611,4.0112534286955,32.3400013148785,0.000389610523462258,5.4061658693402E-5,1,-3.92204287375575E-9,6.96119403839111,7.44690227508545,49999.75,49999.75,51.0587105759766,5.51472670374454,4.28068065643311,132,1,0,0,1,0.23406982421875,30.7917900085449,6,1,1,6.96119403839111,0,7.20404815673828,,,,,,,,,,,,,,,,,,,,,,,,,,,,,,,,,
,3738634527.84447,4.32116651535034,49999.75,5.82812117592985E-7,4.4282950611729E-8,1,10,13.2042255401611,4.01120191151275,32.3400013148785,0.000517391698448221,0.000102461673357143,1,2.83553323466648E-8,4.10808086395264,4.53425216674805,49999.75,49999.75,51.2834287752554,5.51553891058081,3.54643249511719,132,1,0,0,1,0.233230590820313,31.2805480957031,6,1,1,4.10808086395264,0,4.32116651535034,,,,,,,,,,,,,,,,,,,,,,,,,,,,,,,,,
,3738634587.70635,2.83263087272644,49999.75,5.66934811938722E-7,4.62655979482497E-8,1,10,13.2042255401611,4.01136974427602,32.3400013148785,0.000502759542822686,0.000103533737019917,1,3.18956937293146E-8,2.83154535293579,2.83371639251709,49999.75,49999.75,51.5269060589958,5.51662589605335,2.92628335952759,132,1,0,0,1,0.235366821289062,31.2805480957031,6,1,1,2.83371639251709,0,2.83263087272644,,,,,,,,,,,,,,,,,,,,,,,,,,,,,,,,,
,3738634647.66717,2.83498871326447,49999.75,5.73730007074467E-7,4.22146600051236E-8,1,10,13.2042255401611,4.01131148469944,32.3400013148785,0.000513944833585137,6.98224229854134E-5,1,-6.80589128774905E-9,2.83491635322571,2.83506107330322,49999.75,49999.75,51.4553870494862,5.51729088390137,2.929438829422,132,1,0,0,1,0.2386474609375,31.2805480957031,6,1,1,2.83506107330322,0,2.83498871326447,,,,,,,,,,,,,,,,,,,,,,,,,,,,,,,,,
,3738634707.76083,2.83323740959167,49999.75,5.7327267954055E-7,3.96798239188122E-8,1,10,13.2042255401611,4.0112199296749,32.3400013148785,0.000510413684553965,9.07351949937174E-5,1,1.66519111607055E-8,2.83275938034058,2.83371543884277,49999.75,49999.75,51.4620308918997,5.5163617063836,2.92787146568298,132,1,0,0,1,0.239181518554687,31.7693061828613,6,1,1,2.83275938034058,0,2.83323740959167,,,,,,,,,,,,,,,,,,,,,,,,,,,,,,,,,
,3738634767.62767,2.83192205429077,49999.75,5.78245286322541E-7,4.51938316161662E-8,1,10,13.2042255401611,4.0112847907672,32.3400013148785,0.000515380260819259,8.79698729706725E-5,1,1.28211132155767E-8,2.83139967918396,2.83244442939758,49999.75,49999.75,51.4346738937266,5.51582275484237,2.93608975410461,132,1,0,0,1,0.240402221679687,31.2805480957031,6,1,1,2.83139967918396,0,2.83192205429077,,,,,,,,,,,,,,,,,,,,,,,,,,,,,,,,,
,3738634827.63519,2.85185122489929,49999.75,5.56668976031804E-7,4.28790507275953E-8,1,10,13.2042255401611,4.01132468811429,32.3400013148785,0.000497778893893178,7.37303619673159E-5,1,8.81636041566422E-11,2.85175561904907,2.85194683074951,49999.75,49999.75,51.4577319350439,5.51598454795978,2.94969177246094,132,1,0,0,1,0.23895263671875,31.7693061828613,6,1,1,2.85194683074951,0,2.85185122489929,,,,,,,,,,,,,,,,,,,,,,,,,,,,,,,,,
,3738634887.57938,2.81184208393097,49999.75,6.04219663504599E-7,4.44595666101221E-8,1,10,13.2042255401611,4.01131831550474,32.3400013148785,0.000533553105201934,0.000125613898924453,1,5.10733649405114E-8,2.80099415779114,2.8226900100708,49999.75,49999.75,51.4639849631977,5.51486473747186,2.9320375919342,132,1,0,0,1,0.238494873046875,31.2805480957031,6,1,1,2.80099415779114,0,2.81184208393097,,,,,,,,,,,,,,,,,,,,,,,,,,,,,,,,,
,3738634947.7152,2.77189147472382,49999.75,5.7713127061315E-7,4.29678873764315E-8,1,10,13.2042255401611,4.0113395437399,32.3400013148785,0.000512382583746071,0.000101427648931973,1,2.80332656927459E-8,2.76207566261291,2.78170728683472,49999.75,49999.75,51.4362371507651,5.51495777267906,2.92181515693665,132,1,0,0,1,0.238113403320313,30.7917900085449,6,1,1,2.76207566261291,0,2.77189147472382,,,,,,,,,,,,,,,,,,,,,,,,,,,,,,,,,
,3738635007.50796,2.77118575572968,49999.75,5.71430794729231E-7,4.47015208201625E-8,1,10,13.2042255401611,4.01135643975389,32.3400013148785,0.000505968386404237,0.000109595834391091,1,3.80101279196477E-8,2.76004266738892,2.78232884407043,49999.75,49999.75,51.388557811092,5.51501230515293,2.92915534973145,132,1,0,0,1,0.238418579101562,31.2805480957031,6,1,1,2.78232884407043,0,2.77118575572968,,,,,,,,,,,,,,,,,,,,,,,,,,,,,,,,,
,3738635067.58235,2.72917973995209,49999.75,5.76892917648884E-7,4.80435379159302E-8,1,10,13.2042255401611,4.01137290429587,32.3400013148785,0.000514330690342226,8.6836032971392E-5,1,1.17498359968879E-8,2.72346544265747,2.7348940372467,49999.75,49999.75,51.5265152447362,5.51432972579521,2.90835332870483,132,1,0,0,1,0.236129760742187,30.7917900085449,6,1,1,2.72346544265747,0,2.72917973995209,,,,,,,,,,,,,,,,,,,,,,,,,,,,,,,,,
,3738635127.4755,2.19944620132446,49999.75,5.67162250151834E-7,5.21173321872378E-8,1,10,13.2042255401611,4.01153459500481,32.3400013148785,0.00050181113973864,0.000111577870115416,1,4.08492997716038E-8,2.13153195381165,2.26736044883728,49999.75,49999.75,51.6875307196978,5.51723623885714,2.5871753692627,132,1,0,0,1,0.23956298828125,30.7917900085449,6,1,1,2.13153195381165,0,2.19944620132446,,,,,,,,,,,,,,,,,,,,,,,,,,,,,,,,,
,3738635187.56578,2.00022625923157,49999.75,5.74380755621131E-7,5.25351246260048E-8,1,10,13.2042255401611,4.0114734227382,32.3400013148785,0.000505935990856221,0.000128199346529969,1,5.83706624313338E-8,1.999356508255,2.00109601020813,49999.75,49999.75,51.5820108696016,5.51715171344102,2.48679518699646,132,1,0,0,1,0.236740112304687,30.7917900085449,5,1,1,1.999356508255,0,2.00022625923157,,,,,,,,,,,,,,,,,,,,,,,,,,,,,,,,,
,3738635217.42647,1.99968981742859,49999.75,5.79875387105614E-7,4.9467140422792E-8,1,10,13.2042255401611,4.01141958371671,32.3400013148785,0.000508680253577465,0.000143512801719299,1,7.46848376010227E-8,1.99954724311829,1.99983239173889,49999.75,49999.75,51.6277361379766,5.5177973356182,2.48389005661011,132,1,0,0,1,0.235443115234375,31.7693061828613,1,1,1,1.99983239173889,0,1.99968981742859,,,,,,,,,,,,,,,,,,,,,,,,,,,,,,,,,