File: data/quartz-holder/180619_empty-quartz_4mm_4T.dat
[Header]
; MPMS3 Data File (default extension .dat)
; Copyright (c) 2007, Quantum Design, Inc. All rights reserved.
TITLE,
FILEOPENTIME,3738609271.68124,06/19/2018,10:34 pm
BYAPP,MPMS3,1.0,1.1
INFO,MPMS3 Measurement Release 1.1.16 Build 388, MultiVu Release 2.3.4.15,APPNAME
INFO,0,MOMENT_UNITS
INFO,empty quartz,SAMPLE_MATERIAL
INFO,,SAMPLE_COMMENT
INFO,1,SAMPLE_MASS
INFO,,SAMPLE_VOLUME
INFO,,SAMPLE_MOLECULAR_WEIGHT
INFO,,SAMPLE_SIZE
INFO,,SAMPLE_SHAPE
INFO,Standard,SAMPLE_HOLDER
INFO,Standard,SAMPLE_HOLDER_DETAIL
INFO,66,SAMPLE_OFFSET
DATATYPE,COMMENT,1
DATATYPE,TIME,2
STARTUPAXIS,X,2
STARTUPAXIS,Y1,5
FIELDGROUP, VSM,2,3,4,5,6,8,9,10,11,14,15
FIELDGROUP, DC, 2,3,4,14,34,35,36,37,38,39,40,41,42,43,44,45,46,47
STARTUPGROUP, All
[Data]
Comment,Time Stamp (sec),Temperature (K),Magnetic Field (Oe),Moment (emu),M. Std. Err. (emu),Transport Action,Averaging Time (sec),Frequency (Hz),Peak Amplitude (mm),Center Position (mm),Lockin Signal' (V),Lockin Signal (V),Range,M. Quad. Signal (emu),Min. Temperature (K),Max. Temperature (K),Min. Field (Oe),Max. Field (Oe),Mass (grams),Motor Lag (deg),Pressure (Torr),Measure Count,Measurement Number,SQUID Status (code),Motor Status (code),Measure Status (code),Motor Current (amps),Motor Temp. (C),Temp. Status (code),Field Status (code),Chamber Status (code),Chamber Temp (K),Redirection State,Average Temp (K),Rotation Angle (deg),Rotator state,DC Moment Fixed Ctr (emu),DC Moment Err Fixed Ctr (emu),DC Moment Free Ctr (emu),DC Moment Err Free Ctr (emu),DC Fixed Fit,DC Free Fit,DC Calculated Center (mm),DC Calculated Center Err (mm),DC Scan Length (mm),DC Scan Time (s),DC Number of Points,DC Squid Drift,DC Min V (V),DC Max V (V),DC Scans per Measure,Map 01,Map 02,Map 03,Map 04,Map 05,Map 06,Map 07,Map 08,Map 09,Map 10,Map 11,Map 12,Map 13,Map 14,Map 15,Map 16
,3738609349.67379,2.00064206123352,39999.578125,5.6361531946475E-7,3.38803336082372E-8,1,10,13.2042255401611,3.98074409857696,32.3400013148785,0.000492010087640215,0.000113364816943371,1,4.4940672070148E-8,2.00064206123352,2.00064206123352,39999.578125,39999.578125,51.3299356721497,5.51647179664084,2.45867991447449,130,1,68,0,0,0.236587524414062,31.2805480957031,1,1,1,2.00064206123352,0,2.00064206123352,,,,,,,,,,,,,,,,,,,,,,,,,,,,,,,,,
,3738609406.63536,4.21801280975342,39999.578125,4.92768507807726E-7,3.6276611700115E-8,1,10,13.2042255401611,3.98077194819123,32.3400013148785,0.000432576264231694,8.2845244815389E-5,1,2.08730801345447E-8,4.00601243972778,4.43001317977905,39999.578125,39999.578125,51.0317443920631,5.51537468444794,3.49359560012817,132,1,0,0,1,0.239334106445313,30.7917900085449,6,1,1,4.43001317977905,0,4.21801280975342,,,,,,,,,,,,,,,,,,,,,,,,,,,,,,,,,
,3738609466.59207,6.89292073249817,39999.578125,4.29402769265359E-7,3.50730097967646E-8,1,10,13.2042255401611,3.98073803779479,32.3400013148785,0.000375743895998162,8.03130184442512E-5,1,2.73832102452418E-8,6.66572523117065,7.12011623382568,39999.578125,39999.578125,50.8625218176496,5.51492579304796,4.16885709762573,132,1,0,0,1,0.236663818359375,30.7917900085449,6,1,1,7.12011623382568,0,6.89292073249817,,,,,,,,,,,,,,,,,,,,,,,,,,,,,,,,,
,3738609526.57702,9.68284130096436,39999.578125,3.35807259397442E-7,3.4833964020064E-8,1,10,13.2042255401611,3.98068391878575,32.3400013148785,0.000298127789213574,3.38115549265194E-5,1,-1.14086496805099E-8,9.44435882568359,9.92132377624512,39999.578125,39999.578125,50.7593468531111,5.51424942134158,4.61213827133179,132,1,0,0,1,0.2362060546875,31.2805480957031,6,1,1,9.92132377624512,0,9.68284130096436,,,,,,,,,,,,,,,,,,,,,,,,,,,,,,,,,
,3738609586.58317,12.5105295181274,39999.578125,2.2068960119672E-7,3.72469050643313E-8,1,10,13.2042255401611,3.98064369184715,32.3400013148785,0.000194761963958221,3.00729513682171E-5,1,1.39206418205535E-9,12.2811870574951,12.7398719787598,39999.578125,39999.578125,50.6557810743131,5.51425144941634,4.92702150344849,132,1,0,0,1,0.237655639648438,31.2805480957031,6,1,1,12.7398719787598,0,12.5105295181274,,,,,,,,,,,,,,,,,,,,,,,,,,,,,,,,,
,3738609646.52907,15.4433135986328,39999.578125,2.44249414284474E-7,3.93354795051109E-8,1,10,13.2042255401611,3.9805416323857,32.3499999940395,0.000215013514754835,3.68743895453156E-5,1,5.60762439315592E-9,15.1356649398804,15.7509622573853,39999.578125,39999.578125,50.686264586563,5.51542673310244,5.16788291931152,132,1,0,0,1,0.24200439453125,31.2805480957031,6,1,1,15.7509622573853,0,15.4433135986328,,,,,,,,,,,,,,,,,,,,,,,,,,,,,,,,,
,3738609706.63705,18.5392026901245,39999.578125,2.06805021044206E-7,3.73424357787925E-8,1,10,13.2042255401611,3.98060424112517,32.3400013148785,0.000182757932995186,2.64758247254398E-5,1,-6.25331451567346E-10,18.2849826812744,18.7934226989746,39999.578125,39999.578125,50.6452290893034,5.51383350477808,5.32388496398926,132,1,0,0,1,0.2349853515625,30.7917900085449,2,1,1,18.7934226989746,0,18.5392026901245,,,,,,,,,,,,,,,,,,,,,,,,,,,,,,,,,
,3738609766.48531,21.4326171875,39999.578125,1.46080391708261E-7,3.78480569077993E-8,1,10,13.2042255401611,3.98059196158911,32.3400013148785,0.000132977305576483,-7.54686880802925E-6,1,-3.01573349838117E-8,21.194221496582,21.671012878418,39999.578125,39999.578125,50.5615948377457,5.51393115678583,5.46478462219238,132,1,0,0,1,0.233154296875,31.7693061828613,2,1,1,21.671012878418,0,21.4326171875,,,,,,,,,,,,,,,,,,,,,,,,,,,,,,,,,
,3738609826.49153,24.3382978439331,39999.578125,1.29022519769246E-7,3.31594223310798E-8,1,10,13.2042255401611,3.98056422135282,32.3400013148785,0.00011282016448832,2.46139416104253E-5,1,8.77576001492551E-9,24.0999870300293,24.5766086578369,39999.578125,39999.578125,50.5307205112361,5.51475923101933,5.580322265625,132,1,0,0,1,0.239639282226562,30.7917900085449,2,1,1,24.5766086578369,0,24.3382978439331,,,,,,,,,,,,,,,,,,,,,,,,,,,,,,,,,
,3738609886.44762,27.2399826049805,39999.578125,9.93379070679919E-8,2.98739160273816E-8,1,10,13.2042255401611,3.98064268244627,32.3400013148785,8.95409411265219E-5,8.72434563458875E-7,1,-1.37100689097813E-8,27.0002593994141,27.4797058105469,39999.578125,39999.578125,50.5322837682746,5.51424380194111,5.66889762878418,132,1,0,0,1,0.2349853515625,30.7917900085449,2,1,1,27.4797058105469,0,27.2399826049805,,,,,,,,,,,,,,,,,,,,,,,,,,,,,,,,,
,3738609946.52082,30.1653699874878,39999.578125,7.49620226589715E-8,3.09616219634846E-8,1,10,13.2042255401611,3.98062409921506,32.3400013148785,6.57242782695853E-5,1.31233893303043E-5,1,3.76553100356054E-9,29.9259128570557,30.4048271179199,39999.578125,39999.578125,50.5096165412169,5.51468722401634,5.754225730896,132,1,0,0,1,0.236663818359375,31.2805480957031,2,1,1,30.4048271179199,0,30.1653699874878,,,,,,,,,,,,,,,,,,,,,,,,,,,,,,,,,
,3738610006.58368,33.0778656005859,39999.578125,5.7917794439208E-8,2.89113878819453E-8,1,10,13.2042255401611,3.9806083177412,32.3400013148785,5.04678060039463E-5,1.2250340455466E-5,1,5.29907142248057E-9,32.8343086242676,33.3214225769043,39999.578125,39999.578125,50.4967196706496,5.51483413397831,5.81615209579468,132,1,0,0,1,0.236968994140625,29.8142719268799,2,1,1,33.3214225769043,0,33.0778656005859,,,,,,,,,,,,,,,,,,,,,,,,,,,,,,,,,
,3738610066.41207,36.0127658843994,39999.578125,4.92622540957774E-8,2.75960079280436E-8,1,10,13.2042255401611,3.98056460846553,32.3400013148785,4.36710187749954E-5,5.37643890211905E-6,1,-1.2020044378656E-9,35.7635231018066,36.2620086669922,39999.578125,39999.578125,50.5381459821688,5.51460268342045,5.87402963638306,132,1,0,0,1,0.233154296875,30.7917900085449,2,1,1,36.2620086669922,0,36.0127658843994,,,,,,,,,,,,,,,,,,,,,,,,,,,,,,,,,
,3738610126.39561,38.9240093231201,39999.578125,4.91076810225734E-8,2.91714507348038E-8,1,10,13.2042255401611,3.98054911298077,32.3400013148785,4.3517087810485E-5,5.4719397803938E-6,1,-1.07097890118468E-9,38.6857490539551,39.1622695922852,39999.578125,39999.578125,50.5037543273227,5.51475652422575,5.93232107162476,132,1,0,0,1,0.236663818359375,30.7917900085449,2,1,1,39.1622695922852,0,38.9240093231201,,,,,,,,,,,,,,,,,,,,,,,,,,,,,,,,,
,3738610186.45914,41.8556709289551,39999.578125,4.09708568846568E-8,2.89610313034537E-8,1,10,13.2042255401611,3.9805574664869,32.3400013148785,3.75147266877686E-5,-3.59936191256887E-6,1,-1.01367796794833E-8,41.6146774291992,42.0966644287109,39999.578125,39999.578125,50.5205593404861,5.51514485237843,5.97827434539795,132,1,0,0,1,0.233230590820313,31.2805480957031,2,1,1,42.0966644287109,0,41.8556709289551,,,,,,,,,,,,,,,,,,,,,,,,,,,,,,,,,
,3738610246.31851,44.776819229126,39999.578125,2.35960696891489E-8,3.15247895174791E-8,1,10,13.2042255401611,3.98069028186303,32.3499999940395,2.45934592409569E-5,-2.22593784843895E-5,1,-2.86898415615455E-8,44.5334014892578,45.0202369689941,39999.578125,39999.578125,50.518605269188,5.51512661730673,6.02248859405518,132,1,0,0,1,0.2362060546875,31.2805480957031,2,1,1,45.0202369689941,0,44.776819229126,,,,,,,,,,,,,,,,,,,,,,,,,,,,,,,,,
,3738610306.3026,47.7338066101074,39999.578125,2.18980706820198E-8,3.09234060501521E-8,1,10,13.2042255401611,3.98057112352385,32.3400013148785,1.90327814411961E-5,4.95773536889067E-6,1,2.37268368067142E-9,47.5011901855469,47.966423034668,39999.578125,39999.578125,50.450603588015,5.51307404883424,6.06583738327026,132,1,0,0,1,0.235366821289062,31.2805480957031,2,1,1,47.966423034668,0,47.7338066101074,,,,,,,,,,,,,,,,,,,,,,,,,,,,,,,,,
,3738610366.2906,50.6534843444824,39999.578125,1.59788042624442E-8,3.20750278776943E-8,1,10,13.2042255401611,3.9805442066352,32.3400013148785,1.4103290532101E-5,2.16167755479827E-6,1,8.3088508696467E-11,50.3959045410156,50.9110641479492,39999.578125,39999.578125,50.4384883459669,5.51309636050365,6.09364032745361,132,1,0,0,1,0.237579345703125,31.2805480957031,2,1,1,50.9110641479492,0,50.6534843444824,,,,,,,,,,,,,,,,,,,,,,,,,,,,,,,,,
,3738610426.29725,53.5941925048828,39999.578125,2.6686142750519E-8,3.41022391086004E-8,1,10,13.2042255401611,3.98055838510015,32.3400013148785,3.04724258112634E-5,-4.31496024944272E-5,1,-5.27983215716961E-8,53.3485145568848,53.8398704528809,39999.578125,39999.578125,50.4662361583996,5.51271034201215,6.1253809928894,132,1,0,0,1,0.231704711914062,30.7917900085449,2,1,1,53.8398704528809,0,53.5941925048828,,,,,,,,,,,,,,,,,,,,,,,,,,,,,,,,,
,3738610486.37474,56.5356826782227,39999.578125,6.75490764190937E-10,3.23791225813707E-8,1,10,13.2042255401611,3.98056965632942,32.3400013148785,-4.83435778059469E-6,3.67951177373917E-5,1,4.15558415923284E-8,56.2988967895508,56.7724685668945,39999.578125,39999.578125,50.4549025448707,5.51271235360214,6.15751552581787,132,1,0,0,1,0.2374267578125,31.2805480957031,2,1,1,56.7724685668945,0,56.5356826782227,,,,,,,,,,,,,,,,,,,,,,,,,,,,,,,,,
,3738610546.23431,59.4943771362305,39999.578125,6.13716688739211E-9,3.80066004283379E-8,1,10,13.2042255401611,3.98067440711838,32.3400013148785,5.49027694307832E-6,3.35717983545271E-7,1,-5.27985246496989E-10,59.2568435668945,59.7319107055664,39999.578125,39999.578125,50.4377067174476,5.51258105962952,6.1859769821167,130,1,32,0,0,0.239181518554687,31.2805480957031,2,1,1,59.7319107055664,0,59.4943771362305,,,,,,,,,,,,,,,,,,,,,,,,,,,,,,,,,
,3738610606.20344,62.4258232116699,39999.578125,2.54540335201616E-8,3.40795149558003E-8,1,10,13.2042255401611,3.98059098516711,32.3499999940395,2.80938025814109E-5,-3.45878818664909E-5,1,-4.29227346997659E-8,62.1820487976074,62.6695976257324,39999.578125,39999.578125,50.4142578618707,5.51289260213992,6.2074818611145,132,1,0,0,1,0.242156982421875,31.2805480957031,2,1,1,62.6695976257324,0,62.4258232116699,,,,,,,,,,,,,,,,,,,,,,,,,,,,,,,,,
,3738610666.22329,65.3736839294434,39999.578125,1.08154040124156E-8,3.73653361750138E-8,1,10,13.2042255401611,3.98061573295673,32.3499999940395,1.0205297467295E-5,-2.9913373593752E-6,1,-4.9866461121417E-9,65.1181030273437,65.629264831543,39999.578125,39999.578125,50.4986737419476,5.51329693828019,6.2315034866333,132,1,0,0,1,0.240554809570313,31.2805480957031,2,1,1,65.629264831543,0,65.3736839294434,,,,,,,,,,,,,,,,,,,,,,,,,,,,,,,,,
,3738610726.34595,68.3429489135742,39999.578125,5.88127144131819E-9,3.82645450866882E-8,1,10,13.2042255401611,3.98053391244738,32.3400013148785,7.84206444109578E-7,3.05795165520723E-5,1,3.37494199977937E-8,68.1132202148438,68.5726776123047,39999.578125,39999.578125,50.4783514004476,5.51331149338425,6.25742101669311,132,1,0,0,1,0.238800048828125,30.7917900085449,2,1,1,68.5726776123047,0,68.3429489135742,,,,,,,,,,,,,,,,,,,,,,,,,,,,,,,,,
,3738610786.11358,71.2652206420898,39999.578125,-2.07976053450433E-8,3.78821010427301E-8,1,10,13.2042255401611,3.98050891244911,32.3400013148785,-1.82293290393598E-5,-3.67119453628958E-6,1,-1.07911574199776E-9,71.0254287719727,71.505012512207,39999.578125,39999.578125,50.4529484735726,5.51315530751612,6.27031898498535,132,1,0,0,1,0.2374267578125,30.7917900085449,2,1,1,71.505012512207,0,71.2652206420898,,,,,,,,,,,,,,,,,,,,,,,,,,,,,,,,,
,3738610846.10725,74.2524871826172,39999.578125,4.46326436707178E-8,3.40321148185286E-8,1,10,13.2042255401611,3.98052975900884,32.3400013148785,3.71328071920221E-5,2.13184984340497E-5,1,1.75313720376263E-8,74.0203247070312,74.4846496582031,39999.578125,39999.578125,50.4025334340823,5.51312074236343,6.28530073165894,132,1,0,0,1,0.237045288085938,31.2805480957031,2,1,1,74.4846496582031,0,74.2524871826172,,,,,,,,,,,,,,,,,,,,,,,,,,,,,,,,,
,3738610906.08408,77.1839065551758,39999.578125,-1.35584998629782E-9,3.4266745863837E-8,1,10,13.2042255401611,3.98045456005521,32.3400013148785,-3.49268131396959E-7,-5.91073505580115E-6,1,-6.49125031479742E-9,76.9375915527344,77.4302215576172,39999.578125,39999.578125,50.4924207137938,5.5127653672498,6.30791902542114,132,1,0,0,1,0.233383178710938,31.7693061828613,2,1,1,77.4302215576172,0,77.1839065551758,,,,,,,,,,,,,,,,,,,,,,,,,,,,,,,,,
,3738610966.12249,80.1465339660644,39999.578125,6.80020628434366E-9,3.29013516301502E-8,1,10,13.2042255401611,3.98053160437702,32.3400013148785,1.3897302262917E-6,3.20930352672656E-5,1,3.53269714236552E-8,79.9019165039063,80.3911514282227,39999.578125,39999.578125,50.4076140194573,5.51261006722714,6.32378578186035,132,1,0,0,1,0.23529052734375,30.7917900085449,2,1,1,80.3911514282227,0,80.1465339660644,,,,,,,,,,,,,,,,,,,,,,,,,,,,,,,,,
,3738611026.03355,83.1125297546387,39999.578125,-5.38060599458226E-8,4.21500409839047E-8,1,10,13.2042255401611,3.98057697354123,32.3400013148785,-4.82060384073749E-5,-2.44775424842451E-6,1,5.18987858690394E-9,82.8661575317383,83.3589019775391,39999.578125,39999.578125,50.5307205112361,5.513374922263,6.33750009536743,132,1,0,0,1,0.2374267578125,31.7693061828613,2,1,1,83.3589019775391,0,83.1125297546387,,,,,,,,,,,,,,,,,,,,,,,,,,,,,,,,,
,3738611086.15533,86.1144752502441,39999.578125,-4.93106986676904E-8,4.17613411395489E-8,1,10,13.2042255401611,3.98053296811513,32.3400013148785,-4.7579912918105E-5,2.07509840364057E-5,1,3.07884090006046E-8,85.8666000366211,86.3623504638672,39999.578125,39999.578125,50.41503949039,5.51352785859189,6.35015106201172,132,1,0,0,1,0.234527587890625,30.7917900085449,2,1,1,86.3623504638672,0,86.1144752502441,,,,,,,,,,,,,,,,,,,,,,,,,,,,,,,,,
,3738611146.03908,89.0603675842285,39999.578125,-3.25313999342059E-8,4.02659797551505E-8,1,10,13.2042255401611,3.98048781039942,32.3400013148785,-3.19641093278509E-5,1.75767157378053E-5,1,2.47125127634963E-8,88.8155746459961,89.3051605224609,39999.578125,39999.578125,50.442396488563,5.51308032988134,6.36596441268921,132,1,0,0,1,0.2410888671875,30.7917900085449,2,1,1,89.3051605224609,0,89.0603675842285,,,,,,,,,,,,,,,,,,,,,,,,,,,,,,,,,
,3738611205.98571,92.0688438415527,39999.578125,-6.84061017606291E-8,4.23623099656074E-8,1,10,13.2042255401611,3.980456586159,32.3400013148785,-6.41792967420998E-5,1.64595952694821E-5,1,2.87559196813381E-8,91.8218765258789,92.3158111572266,39999.578125,39999.578125,50.4142578618707,5.51296037055743,6.37800598144531,132,1,0,0,1,0.23956298828125,31.2805480957031,2,1,1,92.3158111572266,0,92.0688438415527,,,,,,,,,,,,,,,,,,,,,,,,,,,,,,,,,
,3738611265.94723,95.0041465759277,39999.578125,-2.33498513096984E-9,4.20566446441105E-8,1,10,13.2042255401611,3.98044424181639,32.3400013148785,-6.80401828363076E-6,3.17420200802968E-5,1,3.62824555582197E-8,94.7726364135742,95.2356567382813,39999.578125,39999.578125,50.427154732438,5.5137627622826,6.39695692062378,132,1,0,0,1,0.233535766601562,30.7917900085449,2,1,1,95.2356567382813,0,95.0041465759277,,,,,,,,,,,,,,,,,,,,,,,,,,,,,,,,,
,3738611325.98249,98.0304794311523,39999.578125,-5.25326932624005E-8,4.02529602021446E-8,1,10,13.2042255401611,3.98045209331228,32.3400013148785,-5.20494242939165E-5,3.13132500372704E-5,1,4.32240032063521E-8,97.7832412719727,98.277717590332,39999.578125,39999.578125,50.4541209163515,5.51346913156087,6.40944337844849,132,1,0,0,1,0.235595703125,31.7693061828613,2,1,1,98.277717590332,0,98.0304794311523,,,,,,,,,,,,,,,,,,,,,,,,,,,,,,,,,
,3738611386.05626,101.006778717041,39999.578125,-7.0228887966954E-9,4.17277350384937E-8,1,10,13.2042255401611,3.98044414942275,32.3400013148785,-1.41251826549132E-5,5.26254053266777E-5,1,6.06193546299929E-8,100.775016784668,101.238540649414,39999.578125,39999.578125,50.4083956479765,5.51242729077679,6.41686677932739,132,1,0,0,1,0.235443115234375,31.2805480957031,2,1,1,101.238540649414,0,101.006778717041,,,,,,,,,,,,,,,,,,,,,,,,,,,,,,,,,
,3738611445.87865,104.005218505859,39999.578125,-3.87460182043558E-8,4.23254358105692E-8,1,10,13.2042255401611,3.98045067332937,32.3400013148785,-4.51280400019941E-5,6.86389632365013E-5,1,8.34426819985473E-8,103.745071411133,104.265365600586,39999.578125,39999.578125,50.4040966911207,5.5135788488512,6.42692470550537,132,1,0,0,1,0.2392578125,31.2805480957031,2,1,1,104.265365600586,0,104.005218505859,,,,,,,,,,,,,,,,,,,,,,,,,,,,,,,,,
,3738611505.86914,106.968296051025,39999.578125,-3.64437885691357E-8,3.69572040746677E-8,1,10,13.2042255401611,3.98046307352878,32.3499999940395,-3.02134528238457E-5,-1.81210742752536E-5,1,-1.51236539120267E-8,106.728446960449,107.208145141602,39999.578125,39999.578125,50.4162119331688,5.5129276540335,6.44596481323242,132,1,0,0,1,0.238189697265625,31.2805480957031,2,1,1,107.208145141602,0,106.968296051025,,,,,,,,,,,,,,,,,,,,,,,,,,,,,,,,,
,3738611565.84522,109.973339080811,39999.578125,-5.4373149363218E-8,3.49255764813657E-8,1,10,13.2042255401611,3.98049110007256,32.3400013148785,-5.16239349607957E-5,1.72046236166154E-5,1,2.75228638317257E-8,109.738388061523,110.208290100098,39999.578125,39999.578125,50.5158695693707,5.5141066468439,6.44962501525879,132,1,0,0,1,0.23681640625,30.3030319213867,2,1,1,110.208290100098,0,109.973339080811,,,,,,,,,,,,,,,,,,,,,,,,,,,,,,,,,
,3738611625.93478,112.950344085693,39999.578125,-4.71812698269586E-8,3.6331862406899E-8,1,10,13.2042255401611,3.9803520137986,32.3400013148785,-4.51815600203513E-5,1.75530439378643E-5,1,2.68543453067487E-8,112.69815826416,113.202529907227,39999.578125,39999.578125,50.4095680907553,5.51379696111648,6.46297645568848,132,1,0,0,1,0.237274169921875,31.2805480957031,2,1,1,113.202529907227,0,112.950344085693,,,,,,,,,,,,,,,,,,,,,,,,,,,,,,,,,
,3738611685.80389,115.931365966797,39999.578125,-6.8107531054998E-8,4.09028136472631E-8,1,10,13.2042255401611,3.98035244766698,32.3499999940395,-6.48070503128396E-5,2.25412126409657E-5,1,3.55981282830913E-8,115.682502746582,116.180229187012,39999.578125,39999.578125,50.4181660044669,5.5140045255431,6.47332143783569,132,1,0,0,1,0.241622924804687,30.7917900085449,2,1,1,116.180229187012,0,115.931365966797,,,,,,,,,,,,,,,,,,,,,,,,,,,,,,,,,
,3738611745.77505,118.924640655518,39999.578125,-4.31390540460384E-8,3.60966084973825E-8,1,10,13.2042255401611,3.98032914060436,32.3400013148785,-4.01244545555225E-5,8.03432760312651E-6,1,1.54792664085354E-8,118.674705505371,119.174575805664,39999.578125,39999.578125,50.4287179894765,5.51360075062218,6.4842963218689,132,1,0,0,1,0.233612060546875,31.2805480957031,2,1,1,119.174575805664,0,118.924640655518,,,,,,,,,,,,,,,,,,,,,,,,,,,,,,,,,
,3738611805.77361,121.908462524414,39999.578125,-2.01165673291126E-8,3.48155797692864E-8,1,10,13.2042255401611,3.98040742606309,32.3400013148785,-1.60326503808589E-5,-1.4358192159583E-5,1,-1.32795969260955E-8,121.665420532227,122.151504516602,39999.578125,39999.578125,50.4736616293323,5.51377340610232,6.48896312713623,132,1,0,0,1,0.239181518554687,31.2805480957031,2,1,1,122.151504516602,0,121.908462524414,,,,,,,,,,,,,,,,,,,,,,,,,,,,,,,,,
,3738611865.77169,124.89835357666,39999.578125,-6.60002018529917E-8,3.46037342130943E-8,1,10,13.2042255401611,3.98023232769789,32.3499999940395,-5.95028476925556E-5,-4.33821595238675E-7,1,9.2739856706656E-9,124.655891418457,125.140815734863,39999.578125,39999.578125,50.4803054717457,5.51377277292652,6.49637603759766,132,1,0,0,1,0.239791870117187,31.7693061828613,2,1,1,125.140815734863,0,124.89835357666,,,,,,,,,,,,,,,,,,,,,,,,,,,,,,,,,
,3738611925.7094,127.894580841064,39999.578125,-6.54493949009227E-8,3.66536335538685E-8,1,10,13.2042255401611,3.98027938633,32.3400013148785,-6.34595993386828E-5,2.9661128766615E-5,1,4.32669904886641E-8,127.644477844238,128.144683837891,39999.578125,39999.578125,50.481087100265,5.51357506615061,6.51179790496826,132,1,0,0,1,0.238113403320313,33.2355842590332,2,1,1,128.144683837891,0,127.894580841064,,,,,,,,,,,,,,,,,,,,,,,,,,,,,,,,,
,3738611985.81748,130.87020111084,39999.578125,-4.37230817048941E-8,3.69380083280401E-8,1,10,13.2042255401611,3.98029295862915,32.3499999940395,-4.25460473246145E-5,2.08424151763495E-5,1,3.00674678357404E-8,130.6240234375,131.11637878418,39999.578125,39999.578125,50.4795238432265,5.51434880654175,6.51221179962158,132,1,0,0,1,0.241165161132813,30.7917900085449,2,1,1,131.11637878418,0,130.87020111084,,,,,,,,,,,,,,,,,,,,,,,,,,,,,,,,,
,3738612045.86661,133.856063842773,39999.578125,-8.55742319699162E-8,3.99186663966466E-8,1,10,13.2042255401611,3.98031477978315,32.3400013148785,-7.53932905183775E-5,-1.24523663500838E-5,1,-1.43748389896691E-9,133.620559692383,134.091567993164,39999.578125,39999.578125,50.4564658019092,5.51553086511995,6.51989221572876,132,1,0,0,1,0.232162475585938,31.7693061828613,2,1,1,134.091567993164,0,133.856063842773,,,,,,,,,,,,,,,,,,,,,,,,,,,,,,,,,
,3738612105.6551,136.851661682129,39999.578125,-7.37462411271059E-8,3.58832501778974E-8,1,10,13.2042255401611,3.98030816979273,32.3400013148785,-6.77670152466999E-5,8.15734901586373E-6,1,2.01471732962518E-8,136.606643676758,137.0966796875,39999.578125,39999.578125,50.3954987774092,5.51625938276324,6.52967405319214,132,1,0,0,1,0.238113403320313,31.2805480957031,2,1,1,137.0966796875,0,136.851661682129,,,,,,,,,,,,,,,,,,,,,,,,,,,,,,,,,
,3738612165.64199,139.838920593262,39999.578125,-8.71930066677162E-8,3.25783728483514E-8,1,10,13.2042255401611,3.98027447682098,32.3400013148785,-7.92341540944378E-5,3.64083420071309E-6,1,1.70230828527078E-8,139.576858520508,140.100982666016,39999.578125,39999.578125,50.4615463872842,5.51562869354031,6.5407567024231,132,1,0,0,1,0.23162841796875,31.2805480957031,2,1,1,140.100982666016,0,139.838920593262,,,,,,,,,,,,,,,,,,,,,,,,,,,,,,,,,
,3738612225.67221,142.832977294922,39999.578125,-3.9163525167604E-8,3.63198091373402E-8,1,10,13.2042255401611,3.9803161226208,32.3400013148785,-3.4217232698926E-5,-7.63829027540107E-6,1,-2.85368368364158E-9,142.583251953125,143.082702636719,39999.578125,39999.578125,50.4310628750342,5.51590956580924,6.55084705352783,132,1,0,0,1,0.238265991210938,31.7693061828613,2,1,1,143.082702636719,0,142.832977294922,,,,,,,,,,,,,,,,,,,,,,,,,,,,,,,,,
,3738612285.73966,145.828567504883,39999.578125,-4.48040801426675E-8,3.55600659988041E-8,1,10,13.2042255401611,3.98051874635029,32.3400013148785,-3.98864967126897E-5,-3.75173058943937E-6,1,2.3816462769303E-9,145.59114074707,146.065994262695,39999.578125,39999.578125,50.4263731039188,5.51383593755381,6.5504150390625,132,1,0,0,1,0.236282348632813,31.7693061828613,2,1,1,146.065994262695,0,145.828567504883,,,,,,,,,,,,,,,,,,,,,,,,,,,,,,,,,
,3738612345.56612,148.798294067383,39999.578125,-1.7810947665461E-8,3.52314815873795E-8,1,10,13.2042255401611,3.98041622211142,32.3400013148785,-1.64627410210081E-5,2.61342236562474E-6,1,5.59409176940142E-9,148.554153442383,149.042434692383,39999.578125,39999.578125,50.4279363609573,5.51297766052543,6.55661010742188,132,1,0,0,1,0.23956298828125,31.2805480957031,2,1,1,149.042434692383,0,148.798294067383,,,,,,,,,,,,,,,,,,,,,,,,,,,,,,,,,
,3738612405.56746,151.787925720215,39999.578125,-2.41701997398929E-8,3.67347043182375E-8,1,10,13.2042255401611,3.98041614377881,32.3400013148785,-2.27502781641302E-5,6.31524824613086E-6,1,1.07260854416573E-8,151.535232543945,152.040618896484,39999.578125,39999.578125,50.457638244688,5.51346607062631,6.57020330429077,132,1,0,0,1,0.234603881835938,31.2805480957031,2,1,1,152.040618896484,0,151.787925720215,,,,,,,,,,,,,,,,,,,,,,,,,,,,,,,,,
,3738612465.52373,154.787605285645,39999.578125,-6.1249123571877E-8,3.46275126638735E-8,1,10,13.2042255401611,3.98046519887183,32.3499999940395,-5.53428006173607E-5,3.95912518842598E-7,1,9.51045914156336E-9,154.533157348633,155.042053222656,39999.578125,39999.578125,50.4209017042842,5.51270878274072,6.57269144058228,132,1,0,0,1,0.24169921875,30.7917900085449,2,1,1,155.042053222656,0,154.787605285645,,,,,,,,,,,,,,,,,,,,,,,,,,,,,,,,,
,3738612525.63344,157.775619506836,39999.578125,-3.2472688270728E-8,3.41177422035724E-8,1,10,13.2042255401611,3.98049617184629,32.3400013148785,-2.7375250909101E-5,-1.30806174478403E-5,1,-1.00044587650784E-8,157.544708251953,158.006530761719,39999.578125,39999.578125,50.4080048337169,5.51318421372827,6.57673025131226,132,1,0,0,1,0.235595703125,31.7693061828613,2,1,1,158.006530761719,0,157.775619506836,,,,,,,,,,,,,,,,,,,,,,,,,,,,,,,,,
,3738612585.52291,160.791656494141,39999.578125,-3.85663245453917E-8,3.09702124644363E-8,1,10,13.2042255401611,3.98044060869853,32.3400013148785,-3.33056175999403E-5,-1.01683976367976E-5,1,-5.80609649654373E-9,160.558395385742,161.024917602539,39999.578125,39999.578125,50.4185568187265,5.51264942218631,6.59104347229004,132,1,0,0,1,0.23162841796875,31.7693061828613,2,1,1,161.024917602539,0,160.791656494141,,,,,,,,,,,,,,,,,,,,,,,,,,,,,,,,,
,3738612645.62765,163.753753662109,39999.578125,-4.61830988664139E-8,3.37713037627936E-8,1,10,13.2042255401611,3.98046230864641,32.3400013148785,-4.13484774212605E-5,-2.27711721048017E-6,1,4.25506834785943E-9,163.495544433594,164.011962890625,39999.578125,39999.578125,50.4263731039188,5.51338512002243,6.5884485244751,132,1,0,0,1,0.236663818359375,31.7693061828613,2,1,1,164.011962890625,0,163.753753662109,,,,,,,,,,,,,,,,,,,,,,,,,,,,,,,,,
,3738612705.42554,166.71671295166,39999.578125,-5.87831818621877E-8,3.20188044712706E-8,1,10,13.2042255401611,3.98051352975896,32.3400013148785,-5.3795664163674E-5,4.97578533592534E-6,1,1.43305923617666E-8,166.468063354492,166.965362548828,39999.578125,39999.578125,50.4267639181784,5.51341523222348,6.59859180450439,132,1,0,0,1,0.2349853515625,31.7693061828613,2,1,1,166.965362548828,0,166.71671295166,,,,,,,,,,,,,,,,,,,,,,,,,,,,,,,,,
,3738612765.51803,169.726776123047,39999.578125,-6.51941394272182E-8,3.32004548103012E-8,1,10,13.2042255401611,3.98056680567596,32.3499999940395,-5.82061765298923E-5,-4.33415227365426E-6,1,4.73921634444938E-9,169.487258911133,169.966293334961,39999.578125,39999.578125,50.4439597456015,5.51271588275374,6.6085033416748,132,1,0,0,1,0.239715576171875,31.7693061828613,2,1,1,169.966293334961,0,169.726776123047,,,,,,,,,,,,,,,,,,,,,,,,,,,,,,,,,
,3738612825.40764,172.725028991699,39999.578125,-3.28059398369485E-8,3.4606991542275E-8,1,10,13.2042255401611,3.98052262516099,32.3400013148785,-3.48024567985734E-5,3.50826852752317E-5,1,4.45717523877452E-8,172.478408813477,172.971649169922,39999.578125,39999.578125,50.3939355203707,5.51280699572189,6.61309003829956,132,1,0,0,1,0.2362060546875,30.7917900085449,2,1,1,172.971649169922,0,172.725028991699,,,,,,,,,,,,,,,,,,,,,,,,,,,,,,,,,
,3738612885.38547,175.733390808105,39999.578125,-4.09990369258802E-8,3.0856244424868E-8,1,10,13.2042255401611,3.98051332467398,32.3400013148785,-4.06978216110785E-5,2.49455466575027E-5,1,3.43076024452068E-8,175.47380065918,175.992980957031,39999.578125,39999.578125,50.4326261320726,5.51288456182086,6.61168670654297,132,1,0,0,1,0.235214233398438,31.2805480957031,2,1,1,175.992980957031,0,175.733390808105,,,,,,,,,,,,,,,,,,,,,,,,,,,,,,,,,
,3738612945.35903,178.691772460938,39999.578125,-4.1665925642498E-8,3.31610880156599E-8,1,10,13.2042255401611,3.9805811163073,32.3400013148785,-3.96553995682707E-5,1.38247401178691E-5,1,2.18156875386286E-8,178.45442199707,178.929122924805,39999.578125,39999.578125,50.4361434604092,5.51238527860592,6.61851167678833,132,1,0,0,1,0.234909057617187,30.7917900085449,2,1,1,178.929122924805,0,178.691772460938,,,,,,,,,,,,,,,,,,,,,,,,,,,,,,,,,
,3738613005.34816,181.690658569336,39999.578125,-3.8511164571476E-8,3.2528055061445E-8,1,10,13.2042255401611,3.98056666916707,32.3400013148785,-3.19344275643591E-5,-1.91112888772266E-5,1,-1.5937942233086E-8,181.452423095703,181.928894042969,39999.578125,39999.578125,50.4236374041015,5.51212392793374,6.6314549446106,132,1,0,0,1,0.23651123046875,31.7693061828613,2,1,1,181.928894042969,0,181.690658569336,,,,,,,,,,,,,,,,,,,,,,,,,,,,,,,,,
,3738613065.32001,184.687423706055,39999.578125,-5.70772243056434E-8,3.81773033365962E-8,1,10,13.2042255401611,3.98047032768056,32.3400013148785,-5.14841362243457E-5,-2.33745365352512E-7,1,8.18033246653293E-9,184.434936523438,184.939910888672,39999.578125,39999.578125,50.4240282183611,5.51325933901963,6.6361141204834,132,1,0,0,1,0.231475830078125,31.2805480957031,2,1,1,184.939910888672,0,184.687423706055,,,,,,,,,,,,,,,,,,,,,,,,,,,,,,,,,
,3738613125.35175,187.678314208984,39999.578125,-1.0997892166942E-7,4.25935772085916E-8,1,10,13.2042255401611,3.98044296126115,32.3400013148785,-9.68119544517387E-5,-1.65960895867307E-5,1,-2.51726855543305E-9,187.426498413086,187.930130004883,39999.578125,39999.578125,50.4533392878323,5.51321461354823,6.6415958404541,132,1,0,0,1,0.23406982421875,31.2805480957031,2,1,1,187.930130004883,0,187.678314208984,,,,,,,,,,,,,,,,,,,,,,,,,,,,,,,,,
,3738613185.46363,190.679039001465,39999.578125,-5.21508149869214E-8,4.10697205047481E-8,1,10,13.2042255401611,3.98050768349372,32.3400013148785,-4.49365729814174E-5,-1.44380332356601E-5,1,-8.62964650082787E-9,190.438430786133,190.919647216797,39999.578125,39999.578125,50.4037058768611,5.51290058733022,6.64195203781128,132,1,0,0,1,0.236663818359375,31.2805480957031,2,1,1,190.919647216797,0,190.679039001465,,,,,,,,,,,,,,,,,,,,,,,,,,,,,,,,,
,3738613245.27308,193.643486022949,39999.578125,1.37875394365889E-8,4.7719086504372E-8,1,10,13.2042255401611,3.98046181950373,32.3499999940395,2.15089707768646E-6,6.95736020223173E-5,1,7.67277856512545E-8,193.393814086914,193.893157958984,39999.578125,39999.578125,50.4537301020919,5.512740628923,6.65221786499023,132,1,0,0,1,0.237960815429687,31.7693061828613,2,1,1,193.893157958984,0,193.643486022949,,,,,,,,,,,,,,,,,,,,,,,,,,,,,,,,,
,3738613305.27033,196.643394470215,39999.578125,-7.77453911996083E-8,4.39084497147753E-8,1,10,13.2042255401611,3.98047656744347,32.3400013148785,-7.12096362594972E-5,6.99769160088572E-6,1,1.94253521661982E-8,196.398361206055,196.888427734375,39999.578125,39999.578125,50.4377067174476,5.51272531226468,6.65223217010498,132,1,0,0,1,0.23162841796875,30.7917900085449,2,1,1,196.888427734375,0,196.643394470215,,,,,,,,,,,,,,,,,,,,,,,,,,,,,,,,,
,3738613365.23603,199.644119262695,39999.578125,-4.69279618110677E-8,3.99672247218289E-8,1,10,13.2042255401611,3.98037494048615,32.3400013148785,-4.53405461169218E-5,2.01701902458768E-5,1,2.97797889867473E-8,199.404403686523,199.883834838867,39999.578125,39999.578125,50.4255914753996,5.51567954509089,6.66464042663574,132,1,0,0,1,0.235366821289062,32.2580642700195,2,1,1,199.883834838867,0,199.644119262695,,,,,,,,,,,,,,,,,,,,,,,,,,,,,,,,,
,3738613425.25638,202.633422851562,39999.578125,-5.08555923413177E-8,4.10757158683814E-8,1,10,13.2042255401611,3.98041610369094,32.3400013148785,-4.99511913194269E-5,2.7367468797059E-5,1,3.85090791338006E-8,202.377151489258,202.889694213867,39999.578125,39999.578125,50.41503949039,5.51578136079743,6.66773557662964,132,1,0,0,1,0.237579345703125,30.7917900085449,2,1,1,202.889694213867,0,202.633422851562,,,,,,,,,,,,,,,,,,,,,,,,,,,,,,,,,
,3738613485.15363,205.604118347168,39999.578125,-6.43639113587485E-8,3.84550492844367E-8,1,10,13.2042255401611,3.98047754497035,32.3400013148785,-5.59590543637815E-5,-1.4442741806633E-5,1,-6.8281638165662E-9,205.356246948242,205.851989746094,39999.578125,39999.578125,50.4248098468803,5.51612089957029,6.67848682403564,132,1,0,0,1,0.239334106445313,31.2805480957031,2,1,1,205.851989746094,0,205.604118347168,,,,,,,,,,,,,,,,,,,,,,,,,,,,,,,,,
,3738613545.31317,208.617492675781,39999.578125,-3.17470526519391E-8,3.84230900270359E-8,1,10,13.2042255401611,3.98062936413631,32.3499999940395,-3.22142899833789E-5,2.40415729739477E-5,1,3.19140272690746E-8,208.359024047852,208.875961303711,39999.578125,39999.578125,50.4412240457842,5.5121148462768,6.68235683441162,132,1,0,0,1,0.239486694335938,30.7917900085449,2,1,1,208.875961303711,0,208.617492675781,,,,,,,,,,,,,,,,,,,,,,,,,,,,,,,,,
,3738613605.10445,211.608116149902,39999.578125,-6.80075437536018E-8,3.55828687185555E-8,1,10,13.2042255401611,3.98060790652377,32.3400013148785,-6.10396631622398E-5,-2.35414191150464E-6,1,7.39709680582721E-9,211.373062133789,211.843170166016,39999.578125,39999.578125,50.4361434604092,5.51409431452108,6.68898725509644,132,1,0,0,1,0.2325439453125,31.2805480957031,2,1,1,211.843170166016,0,211.608116149902,,,,,,,,,,,,,,,,,,,,,,,,,,,,,,,,,
,3738613665.17336,214.597236633301,39999.578125,-4.00443301147856E-8,3.57863479376141E-8,1,10,13.2042255401611,3.98059856177394,32.3499999940395,-3.73445856755352E-5,8.09789057212005E-6,1,1.50923555907438E-8,214.357574462891,214.836898803711,39999.578125,39999.578125,50.4216833328034,5.51284372097532,6.69133520126343,132,1,0,0,1,0.238037109375,32.2580642700195,2,1,1,214.836898803711,0,214.597236633301,,,,,,,,,,,,,,,,,,,,,,,,,,,,,,,,,
,3738613725.12194,217.576148986816,39999.578125,-3.58781004880026E-8,3.37082022477188E-8,1,10,13.2042255401611,3.98057551478822,32.3499999940395,-3.20826151048689E-5,-2.04681493192293E-6,1,2.99121522736253E-9,217.328796386719,217.823501586914,39999.578125,39999.578125,50.3880733064765,5.51269301003094,6.70080709457398,132,1,0,0,1,0.241317749023438,31.2805480957031,2,1,1,217.823501586914,0,217.576148986816,,,,,,,,,,,,,,,,,,,,,,,,,,,,,,,,,
,3738613785.08247,220.598014831543,39999.578125,-4.49209657500136E-8,3.62204332352301E-8,1,10,13.2042255401611,3.98051654311098,32.3400013148785,-4.09642448164064E-5,2.81964002221436E-6,1,9.83854964499061E-9,220.355651855469,220.840377807617,39999.578125,39999.578125,50.4216833328034,5.51307876765166,6.71081876754761,132,1,0,0,1,0.238189697265625,32.2580642700195,2,1,1,220.840377807617,0,220.598014831543,,,,,,,,,,,,,,,,,,,,,,,,,,,,,,,,,
,3738613845.14848,223.564575195313,39999.578125,-6.34954712643771E-8,3.16569454476105E-8,1,10,13.2042255401611,3.9804891979262,32.3400013148785,-5.6443055347409E-5,-5.87536865175611E-6,1,2.74286505848057E-9,223.322158813477,223.806991577148,39999.578125,39999.578125,50.4298904322553,5.51346584684944,6.72195625305176,132,1,0,0,1,0.235061645507813,31.7693061828613,2,1,1,223.806991577148,0,223.564575195313,,,,,,,,,,,,,,,,,,,,,,,,,,,,,,,,,
,3738613905.01265,226.552581787109,39999.578125,-6.45486794188561E-8,2.84953939886772E-8,1,10,13.2042255401611,3.98050579214853,32.3499999940395,-5.83342176784571E-5,4.78687445598059E-7,1,1.00923556975161E-8,226.30061340332,226.804550170898,39999.578125,39999.578125,50.4091772764957,5.51336866364765,6.73288059234619,132,1,0,0,1,0.237350463867187,31.7693061828613,2,1,1,226.804550170898,0,226.552581787109,,,,,,,,,,,,,,,,,,,,,,,,,,,,,,,,,
,3738613965.00621,229.558448791504,39999.578125,-2.43068031795348E-8,3.13284064972714E-8,1,10,13.2042255401611,3.98048746837641,32.3400013148785,-2.33548186912397E-5,9.56359143201972E-6,1,1.44236656170416E-8,229.310287475586,229.806610107422,39999.578125,39999.578125,50.4552933591303,5.51406514820262,6.73894786834717,132,1,0,0,1,0.233383178710938,31.2805480957031,2,1,1,229.806610107422,0,229.558448791504,,,,,,,,,,,,,,,,,,,,,,,,,,,,,,,,,
,3738614024.9647,232.519676208496,39999.578125,-4.626959179752E-8,2.92438008557223E-8,1,10,13.2042255401611,3.98043395306311,32.3400013148785,-4.00064809526167E-5,-1.18717418727923E-5,1,-6.59483868696382E-9,232.275939941406,232.763412475586,39999.578125,39999.578125,50.4052691338996,5.51522859864187,6.75686597824097,132,1,0,0,1,0.234832763671875,31.2805480957031,2,1,1,232.763412475586,0,232.519676208496,,,,,,,,,,,,,,,,,,,,,,,,,,,,,,,,,
,3738614084.97797,235.538764953613,39999.578125,-2.66826544775487E-8,2.77685554457972E-8,1,10,13.2042255401611,3.98041929630084,32.3499999940395,-2.21714881902513E-5,-1.29237984867908E-5,1,-1.06840454820255E-8,235.277267456055,235.800262451172,39999.578125,39999.578125,50.4189476329861,5.51568598572228,6.7685079574585,132,1,0,0,1,0.239791870117187,30.3030319213867,2,1,1,235.800262451172,0,235.538764953613,,,,,,,,,,,,,,,,,,,,,,,,,,,,,,,,,
,3738614144.94669,238.516395568848,39999.578125,-4.05685172241707E-8,2.93573320953045E-8,1,10,13.2042255401611,3.9804144460019,32.3400013148785,-3.4101234001344E-5,-1.70027222037027E-5,1,-1.3247606385333E-8,238.257858276367,238.774932861328,39999.578125,39999.578125,50.4052691338996,5.51560566913287,6.78814792633057,132,1,0,0,1,0.239486694335938,31.2805480957031,2,1,1,238.774932861328,0,238.516395568848,,,,,,,,,,,,,,,,,,,,,,,,,,,,,,,,,
,3738614204.97448,241.515953063965,39999.578125,-3.50681204455717E-8,3.3913231457475E-8,1,10,13.2042255401611,3.9803867978691,32.3400013148785,-3.01249456642801E-5,-1.03204455251321E-5,1,-6.49607470696952E-9,241.262359619141,241.769546508789,39999.578125,39999.578125,50.437315903188,5.5154475703511,6.80486583709717,132,1,0,0,1,0.233917236328125,32.2580642700195,2,1,1,241.769546508789,0,241.515953063965,,,,,,,,,,,,,,,,,,,,,,,,,,,,,,,,,
,3738614264.89364,244.514854431152,39999.578125,-4.04764173170439E-8,2.85064695415495E-8,1,10,13.2042255401611,3.98043379235683,32.3499999940395,-3.49385113885592E-5,-1.07838658688967E-5,1,-6.22032683562513E-9,244.271499633789,244.758209228516,39999.578125,39999.578125,50.4541209163515,5.51541888437759,6.8326940536499,132,1,0,0,1,0.237884521484375,30.7917900085449,2,1,1,244.758209228516,0,244.514854431152,,,,,,,,,,,,,,,,,,,,,,,,,,,,,,,,,
,3738614324.91781,247.530769348145,39999.578125,-2.35576885999999E-8,3.15136060407104E-8,1,10,13.2042255401611,3.98042241831217,32.3400013148785,-1.78908150600331E-5,-2.27923419475906E-5,1,-2.23192345116435E-8,247.290618896484,247.770919799805,39999.578125,39999.578125,50.4666269726592,5.5151873100586,6.86503314971924,132,1,0,0,1,0.233154296875,31.2805480957031,2,1,1,247.770919799805,0,247.530769348145,,,,,,,,,,,,,,,,,,,,,,,,,,,,,,,,,
,3738614384.85458,250.526512145996,39999.578125,-5.50856667159496E-8,2.97554308571557E-8,1,10,13.2042255401611,3.9804736231524,32.3400013148785,-4.4549286495144E-5,-3.495540296912E-5,1,-3.14242666324784E-8,250.285125732422,250.76789855957,39999.578125,39999.578125,50.3904181920342,5.5152863782501,6.9044919013977,132,1,0,0,1,0.233535766601562,31.7693061828613,2,1,1,250.76789855957,0,250.526512145996,,,,,,,,,,,,,,,,,,,,,,,,,,,,,,,,,
,3738614444.92807,253.537811279297,39999.578125,-6.66788997636586E-8,3.08692099628089E-8,1,10,13.2042255401611,3.98043849368645,32.3400013148785,-5.48972313126439E-5,-3.57356189321113E-5,1,-3.0592856334593E-8,253.28987121582,253.785751342773,39999.578125,39999.578125,50.4267639181784,5.51547699687592,6.94734859466553,132,1,0,0,1,0.233612060546875,31.2805480957031,2,1,1,253.785751342773,0,253.537811279297,,,,,,,,,,,,,,,,,,,,,,,,,,,,,,,,,
,3738614504.95498,256.497589111328,39999.578125,-2.82911133960101E-8,3.04187901687023E-8,1,10,13.2042255401611,3.98043632547904,32.3400013148785,-2.09059494288092E-5,-3.1290651258237E-5,1,-3.12402063111669E-8,256.258636474609,256.736541748047,39999.578125,39999.578125,50.4123037905726,5.51586789293562,7.00612735748291,132,1,0,0,1,0.234298706054687,31.2805480957031,2,1,1,256.736541748047,0,256.497589111328,,,,,,,,,,,,,,,,,,,,,,,,,,,,,,,,,
,3738614564.78708,259.468109130859,39999.578125,-5.48046254032767E-8,3.29813488813614E-8,1,10,13.2042255401611,3.98043276093536,32.3400013148785,-4.81327060417833E-5,-9.01606016635092E-6,1,-2.09893094480368E-9,259.221496582031,259.714721679687,39999.578125,39999.578125,50.4584198732073,5.51594352868337,7.05811214447021,132,1,0,0,1,0.234909057617187,31.2805480957031,2,1,1,259.714721679687,0,259.468109130859,,,,,,,,,,,,,,,,,,,,,,,,,,,,,,,,,
,3738614624.75421,262.472045898438,39999.578125,-5.94459926813033E-8,3.39328898544689E-8,1,10,13.2042255401611,3.98038015791017,32.3499999940395,-5.32761432037309E-5,-2.55965667419399E-6,1,5.8974317864654E-9,262.206604003906,262.737487792969,39999.578125,39999.578125,50.4705351152553,5.51585029025274,7.00890588760376,132,1,0,0,1,0.239791870117187,31.2805480957031,2,1,1,262.737487792969,0,262.472045898438,,,,,,,,,,,,,,,,,,,,,,,,,,,,,,,,,
,3738614684.81856,265.477066040039,39999.578125,-7.21923986948688E-8,3.07614231309882E-8,1,10,13.2042255401611,3.98040903077423,32.3400013148785,-6.5550907199332E-5,2.64007817823977E-6,1,1.3670387559351E-8,265.233642578125,265.720489501953,39999.578125,39999.578125,50.3900273777746,5.51629802912115,6.98099279403687,132,1,0,0,1,0.239105224609375,31.7693061828613,2,1,1,265.720489501953,0,265.477066040039,,,,,,,,,,,,,,,,,,,,,,,,,,,,,,,,,
,3738614744.91315,268.453582763672,39999.578125,-5.08907023203743E-8,3.01667322832042E-8,1,10,13.2042255401611,3.9803882053539,32.3400013148785,-4.68603335002914E-5,6.2664971305542E-6,1,1.46244518653502E-8,268.218505859375,268.688659667969,39999.578125,39999.578125,50.4255914753996,5.51662134352222,6.96322584152222,132,1,0,0,1,0.2374267578125,30.7917900085449,2,1,1,268.688659667969,0,268.453582763672,,,,,,,,,,,,,,,,,,,,,,,,,,,,,,,,,
,3738614804.68679,271.441146850586,39999.578125,-4.09857816049534E-8,3.14952752287259E-8,1,10,13.2042255401611,3.98039857336233,32.3400013148785,-3.71797675254053E-5,1.26036560019598E-6,1,7.49108619724408E-9,271.181335449219,271.700958251953,39999.578125,39999.578125,50.4623280158034,5.5170598950442,6.95816850662231,132,1,0,0,1,0.233840942382813,31.7693061828613,2,1,1,271.700958251953,0,271.441146850586,,,,,,,,,,,,,,,,,,,,,,,,,,,,,,,,,
,3738614864.68131,274.437225341797,39999.578125,-5.40130098490984E-8,3.01617024488554E-8,1,10,13.2042255401611,3.98033751990188,32.3400013148785,-4.85433265350137E-5,-1.39898970994402E-6,1,6.40764971485043E-9,274.184448242187,274.690002441406,39999.578125,39999.578125,50.4255914753996,5.51624271649485,6.96609497070312,132,1,0,0,1,0.234222412109375,31.2805480957031,2,1,1,274.690002441406,0,274.437225341797,,,,,,,,,,,,,,,,,,,,,,,,,,,,,,,,,
,3738614924.64878,277.40869140625,39999.578125,-4.51604687265834E-8,3.11453650463516E-8,1,10,13.2042255401611,3.98033647131063,32.3499999940395,-4.35143981055224E-5,1.86142307342208E-5,1,2.77569609786496E-8,277.160339355469,277.657043457031,39999.578125,39999.578125,50.4396607887457,5.51630063412451,6.98245048522949,132,1,0,0,1,0.238189697265625,32.2580642700195,2,1,1,277.657043457031,0,277.40869140625,,,,,,,,,,,,,,,,,,,,,,,,,,,,,,,,,
,3738614984.68202,280.414184570313,39999.578125,-4.60979128955684E-8,3.32535547667225E-8,1,10,13.2042255401611,3.98028637224251,32.3400013148785,-4.16600249427174E-5,3.68092332282636E-7,1,7.23726707397451E-9,280.173004150391,280.655364990234,39999.578125,39999.578125,50.4611555730246,5.51615219750825,7.01452541351318,132,1,0,0,1,0.236968994140625,30.7917900085449,2,1,1,280.655364990234,0,280.414184570313,,,,,,,,,,,,,,,,,,,,,,,,,,,,,,,,,
,3738615044.60526,283.414688110352,39999.578125,-9.86601362100549E-8,2.9979903908888E-8,1,10,13.2042255401611,3.98023825465957,32.3499999940395,-8.78239664245085E-5,-8.24421097512231E-6,1,5.26292243158868E-9,283.162719726562,283.666656494141,39999.578125,39999.578125,50.4615463872842,5.51644191795568,7.07405281066895,132,1,0,0,1,0.236282348632813,31.7693061828613,2,1,1,283.666656494141,0,283.414688110352,,,,,,,,,,,,,,,,,,,,,,,,,,,,,,,,,
,3738615104.76236,286.425415039062,39999.578125,-6.85009851940096E-8,3.19089313693826E-8,1,10,13.2042255401611,3.98023210888753,32.3400013148785,-6.13149886906483E-5,-3.44064906498069E-6,1,6.2395002054846E-9,286.16064453125,286.690185546875,39999.578125,39999.578125,50.4459138168996,5.51677543858919,7.15207672119141,132,1,0,0,1,0.233612060546875,31.2805480957031,2,1,1,286.690185546875,0,286.425415039062,,,,,,,,,,,,,,,,,,,,,,,,,,,,,,,,,
,3738615164.73941,289.389038085937,39999.578125,-6.37692244194167E-8,3.32885273036229E-8,1,10,13.2042255401611,3.98027718281438,32.3400013148785,-5.80212623493231E-5,3.15437109327311E-6,1,1.30065793260954E-8,289.144836425781,289.633239746094,39999.578125,39999.578125,50.4185568187265,5.51638909137354,7.26026487350464,132,1,0,0,1,0.237045288085938,31.7693061828613,2,1,1,289.633239746094,0,289.389038085937,,,,,,,,,,,,,,,,,,,,,,,,,,,,,,,,,
,3738615224.55328,292.391189575195,39999.578125,-5.50786617638072E-8,2.93385007669134E-8,1,10,13.2042255401611,3.98025958336005,32.3400013148785,-4.39718744315262E-5,-3.87863606756187E-5,1,-3.57662753031674E-8,292.149841308594,292.632537841797,39999.578125,39999.578125,50.4345802033707,5.51633640974597,7.39102220535278,132,1,0,0,1,0.236434936523438,31.2805480957031,2,1,1,292.632537841797,0,292.391189575195,,,,,,,,,,,,,,,,,,,,,,,,,,,,,,,,,
,3738615284.53461,295.364181518555,39999.578125,-3.33112600355031E-8,3.1804386184196E-8,1,10,13.2042255401611,3.98025608433277,32.3400013148785,-3.02719402057773E-5,1.40112653711877E-6,1,6.51504545435234E-9,295.121398925781,295.606964111328,39999.578125,39999.578125,50.4134762333515,5.51617189103427,7.5421404838562,132,1,0,0,1,0.235061645507813,31.7693061828613,2,1,1,295.606964111328,0,295.364181518555,,,,,,,,,,,,,,,,,,,,,,,,,,,,,,,,,
,3738615344.49956,298.378021240234,39999.578125,-3.49371899024681E-8,3.03431281235986E-8,1,10,13.2042255401611,3.98028761079694,32.3400013148785,-3.24630430832527E-5,6.28932418326105E-6,1,1.22901524695032E-8,298.126953125,298.629089355469,39999.578125,39999.578125,50.4377067174476,5.5164082118951,7.72779178619385,132,1,0,0,1,0.232696533203125,31.2805480957031,2,1,1,298.629089355469,0,298.378021240234,,,,,,,,,,,,,,,,,,,,,,,,,,,,,,,,,
,3738615404.65563,299.787673950195,39999.578125,-4.6572304717996E-8,3.21154447112879E-8,1,10,13.2042255401611,3.98033216821315,32.3400013148785,-4.14362778940871E-5,-4.04320255920399E-6,1,2.31294183846994E-9,299.760223388672,299.815124511719,39999.578125,39999.578125,50.4021426198226,5.51608767226245,7.91805553436279,132,1,0,0,1,0.239486694335938,32.2580642700195,5,1,1,299.815124511719,0,299.787673950195,,,,,,,,,,,,,,,,,,,,,,,,,,,,,,,,,
,3738615444.46941,299.922912597656,39999.578125,-5.05110982581574E-8,2.80730445792329E-8,1,10,13.2042255401611,3.98034226952334,32.3400013148785,-4.3777458961965E-5,-1.22484198469669E-5,1,-6.39425000406712E-9,299.913879394531,299.931945800781,39999.578125,39999.578125,50.416993561688,5.51627231696271,8.04605007171631,132,1,0,0,1,0.23712158203125,31.2805480957031,1,1,1,299.931945800781,0,299.922912597656,,,,,,,,,,,,,,,,,,,,,,,,,,,,,,,,,