File: data/quartz-holder/180619_empty-quartz_4mm_1T.dat
[Header]
; MPMS3 Data File (default extension .dat)
; Copyright (c) 2007, Quantum Design, Inc. All rights reserved.
TITLE,
FILEOPENTIME,3738587918.3938,06/19/2018,4:38 pm
BYAPP,MPMS3,1.0,1.1
INFO,MPMS3 Measurement Release 1.1.16 Build 388, MultiVu Release 2.3.4.15,APPNAME
INFO,0,MOMENT_UNITS
INFO,empty quartz,SAMPLE_MATERIAL
INFO,,SAMPLE_COMMENT
INFO,1,SAMPLE_MASS
INFO,,SAMPLE_VOLUME
INFO,,SAMPLE_MOLECULAR_WEIGHT
INFO,,SAMPLE_SIZE
INFO,,SAMPLE_SHAPE
INFO,Quartz,SAMPLE_HOLDER
INFO,Standard,SAMPLE_HOLDER_DETAIL
INFO,66.38,SAMPLE_OFFSET
DATATYPE,COMMENT,1
DATATYPE,TIME,2
STARTUPAXIS,X,2
STARTUPAXIS,Y1,5
FIELDGROUP, VSM,2,3,4,5,6,8,9,10,11,14,15
FIELDGROUP, DC, 2,3,4,14,34,35,36,37,38,39,40,41,42,43,44,45,46,47
STARTUPGROUP, All
[Data]
Comment,Time Stamp (sec),Temperature (K),Magnetic Field (Oe),Moment (emu),M. Std. Err. (emu),Transport Action,Averaging Time (sec),Frequency (Hz),Peak Amplitude (mm),Center Position (mm),Lockin Signal' (V),Lockin Signal (V),Range,M. Quad. Signal (emu),Min. Temperature (K),Max. Temperature (K),Min. Field (Oe),Max. Field (Oe),Mass (grams),Motor Lag (deg),Pressure (Torr),Measure Count,Measurement Number,SQUID Status (code),Motor Status (code),Measure Status (code),Motor Current (amps),Motor Temp. (C),Temp. Status (code),Field Status (code),Chamber Status (code),Chamber Temp (K),Redirection State,Average Temp (K),Rotation Angle (deg),Rotator state,DC Moment Fixed Ctr (emu),DC Moment Err Fixed Ctr (emu),DC Moment Free Ctr (emu),DC Moment Err Free Ctr (emu),DC Fixed Fit,DC Free Fit,DC Calculated Center (mm),DC Calculated Center Err (mm),DC Scan Length (mm),DC Scan Time (s),DC Number of Points,DC Squid Drift,DC Min V (V),DC Max V (V),DC Scans per Measure,Map 01,Map 02,Map 03,Map 04,Map 05,Map 06,Map 07,Map 08,Map 09,Map 10,Map 11,Map 12,Map 13,Map 14,Map 15,Map 16
,3738589593.67228,300.000335693359,9999.681640625,-1.01856114898589E-8,1.12002915661121E-8,1,10,13.2042255401611,3.98159612433184,32.3400013148785,-8.06917846028619E-6,-7.6282825567464E-6,1,-7.12539630318038E-9,300.000335693359,300.000335693359,9999.681640625,9999.681640625,50.4853860571207,5.51061937004822,7.11406087875366,132,1,0,0,1,0.236587524414062,31.2805480957031,1,1,1,300.000335693359,0,300.000335693359,,,,,,,,,,,,,,,,,,,,,,,,,,,,,,,,,
,3738589653.62718,298.925552368164,9999.681640625,-1.4317879132318E-8,1.03284775527091E-8,1,10,13.2042255401611,3.98157806914847,32.3400013148785,-1.23904935467423E-5,-3.64145378394943E-6,1,-2.00239609332264E-9,298.679931640625,299.171173095703,9999.681640625,9999.681640625,50.5443990103227,5.51121316275477,7.1149525642395,132,1,0,0,1,0.238876342773438,30.7917900085449,2,1,1,298.679931640625,0,298.925552368164,,,,,,,,,,,,,,,,,,,,,,,,,,,,,,,,,
,3738589713.59932,295.703521728516,9999.681640625,-1.52608666500602E-8,8.94832105887212E-9,1,10,13.2042255401611,3.9815604037001,32.3400013148785,-1.28259427635734E-5,-6.45298785401001E-6,1,-5.04457826756689E-9,295.438171386719,295.968872070313,9999.681640625,9999.681640625,50.5354102823515,5.51186501665697,7.1198558807373,132,1,0,0,1,0.2392578125,30.7917900085449,2,1,1,295.438171386719,0,295.703521728516,,,,,,,,,,,,,,,,,,,,,,,,,,,,,,,,,
,3738589773.58284,292.161331176758,9999.681640625,-7.8121542691478E-9,8.35035306511586E-9,1,10,13.2042255401611,3.98148387165579,32.3400013148785,-6.74637162237352E-6,-2.0807462029676E-6,1,-1.19888843163179E-9,291.879913330078,292.442749023438,9999.681640625,9999.681640625,50.5154787551111,5.51209667526641,7.1185827255249,132,1,0,0,1,0.240097045898438,30.7917900085449,2,1,1,291.879913330078,0,292.161331176758,,,,,,,,,,,,,,,,,,,,,,,,,,,,,,,,,
,3738589833.55774,289.06575012207,9999.681640625,-7.78266818969338E-9,9.26159518417357E-9,1,10,13.2042255401611,3.98155399099518,32.3400013148785,-6.05050488798587E-6,-6.60530281745635E-6,1,-6.32341553198538E-9,288.809600830078,289.321899414063,9999.681640625,9999.681640625,50.6448382750438,5.51194458207291,7.11820411682129,132,1,0,0,1,0.239105224609375,31.2805480957031,2,1,1,288.809600830078,0,289.06575012207,,,,,,,,,,,,,,,,,,,,,,,,,,,,,,,,,
,3738589893.6601,286.13899230957,9999.681640625,-1.18828113379271E-8,9.87965049492318E-9,1,10,13.2042255401611,3.98149931567642,32.3499999940395,-1.07387510799539E-5,5.89596025996917E-8,1,1.82486665285231E-9,285.899658203125,286.378326416016,9999.681640625,9999.681640625,50.6065384776015,5.51257804496644,7.12721347808838,132,1,0,0,1,0.23895263671875,30.7917900085449,2,1,1,285.899658203125,0,286.13899230957,,,,,,,,,,,,,,,,,,,,,,,,,,,,,,,,,
,3738589953.52026,283.223068237305,9999.681640625,-1.75205478672968E-8,9.80020845739766E-9,1,10,13.2042255401611,3.9815878472003,32.3499999940395,-1.45531914277998E-5,-8.57143704737782E-6,1,-7.10748055215547E-9,282.976776123047,283.469360351562,9999.681640625,9999.681640625,50.5342378395727,5.51259985868645,7.12220191955566,132,1,0,0,1,0.238037109375,30.7917900085449,2,1,1,282.976776123047,0,283.223068237305,,,,,,,,,,,,,,,,,,,,,,,,,,,,,,,,,
,3738590013.51252,280.224746704102,9999.681640625,-9.79703618072083E-9,9.90936164970197E-9,1,10,13.2042255401611,3.9815748273491,32.3499999940395,-8.20071841500234E-6,-4.36714405319017E-6,1,-3.49251426676835E-9,279.959320068359,280.490173339844,9999.681640625,9999.681640625,50.5377551679092,5.51240854538289,7.1218090057373,132,1,0,0,1,0.239715576171875,31.7693061828613,2,1,1,279.959320068359,0,280.224746704102,,,,,,,,,,,,,,,,,,,,,,,,,,,,,,,,,
,3738590073.53618,277.230514526367,9999.681640625,-1.576109052463E-8,9.87608359905766E-9,1,10,13.2042255401611,3.98155541832986,32.3499999940395,-1.42294348622142E-5,-1.99386364292149E-8,1,2.30939770101896E-9,276.991241455078,277.469787597656,9999.681640625,9999.681640625,50.5701927514573,5.51362165043997,7.12212562561035,132,1,0,0,1,0.238037109375,30.3030319213867,2,1,1,276.991241455078,0,277.230514526367,,,,,,,,,,,,,,,,,,,,,,,,,,,,,,,,,
,3738590133.56348,274.218200683594,9999.681640625,-5.89710930581458E-9,1.64975242428868E-8,1,10,13.2042255401611,3.98160206035965,32.3400013148785,-5.8188476669488E-6,3.33619767674979E-6,1,4.64786493378101E-9,273.977478027344,274.458923339844,9999.681640625,9999.681640625,50.5373643536496,5.51289765736642,7.11240148544312,132,1,0,0,1,0.23834228515625,31.2805480957031,2,1,1,273.977478027344,0,274.218200683594,,,,,,,,,,,,,,,,,,,,,,,,,,,,,,,,,
,3738590193.42828,271.243423461914,9999.681640625,-9.39119623718208E-9,8.60812282494915E-9,1,10,13.2042255401611,3.98151008220288,32.3499999940395,-7.55128897191472E-6,-6.27803652950369E-6,1,-5.71519593966135E-9,270.990905761719,271.495941162109,9999.681640625,9999.681640625,50.5463530816207,5.51336191062041,7.10775423049927,132,1,0,0,1,0.238571166992187,31.2805480957031,2,1,1,270.990905761719,0,271.243423461914,,,,,,,,,,,,,,,,,,,,,,,,,,,,,,,,,
,3738590253.42134,268.261734008789,9999.681640625,-3.9862792682E-9,8.27412345646576E-9,1,10,13.2042255401611,3.98145214896437,32.3400013148785,-3.10388097939427E-6,-3.34969539974296E-6,1,-3.20105244495878E-9,268.016021728516,268.507446289062,9999.681640625,9999.681640625,50.6464015320823,5.51286674239043,7.10348558425903,132,1,0,0,1,0.24017333984375,32.2580642700195,2,1,1,268.016021728516,0,268.261734008789,,,,,,,,,,,,,,,,,,,,,,,,,,,,,,,,,
,3738590313.39793,265.250793457031,9999.681640625,-1.85110716975067E-8,9.10580938839476E-9,1,10,13.2042255401611,3.98147711928032,32.3400013148785,-1.53342053897906E-5,-9.33318149359957E-6,1,-7.82341432736889E-9,264.999603271484,265.501983642578,9999.681640625,9999.681640625,50.552215295515,5.51351843013361,7.09297275543213,132,1,0,0,1,0.24078369140625,32.2580642700195,2,1,1,264.999603271484,0,265.250793457031,,,,,,,,,,,,,,,,,,,,,,,,,,,,,,,,,
,3738590373.3992,262.197479248047,9999.681640625,-1.1500733547548E-8,7.77910890443147E-9,1,10,13.2042255401611,3.98148003684315,32.3400013148785,-9.36494936596567E-6,-6.89381044413852E-6,1,-6.1000245727471E-9,261.953521728516,262.441436767578,9999.681640625,9999.681640625,50.59794056389,5.51363200379598,7.09218788146973,132,1,0,0,1,0.237350463867187,31.2805480957031,2,1,1,261.953521728516,0,262.197479248047,,,,,,,,,,,,,,,,,,,,,,,,,,,,,,,,,
,3738590433.35503,259.249374389648,9999.681640625,-5.59329733881625E-9,1.16142697078299E-8,1,10,13.2042255401611,3.98145943515221,32.3400013148785,-4.77737592661554E-6,-1.8466169247386E-6,1,-1.26224331978949E-9,259.007019042969,259.491729736328,9999.681640625,9999.681640625,50.5596407664477,5.51356022968111,7.08453702926636,132,1,0,0,1,0.240020751953125,31.2805480957031,2,1,1,259.007019042969,0,259.249374389648,,,,,,,,,,,,,,,,,,,,,,,,,,,,,,,,,
,3738590493.4244,256.232048034668,9999.681640625,-8.13913587574606E-9,8.61134859350802E-9,1,10,13.2042255401611,3.98143719496276,32.3400013148785,-7.31377065976009E-6,-2.40491190323883E-7,1,9.32075434480602E-10,255.991287231445,256.472808837891,9999.681640625,9999.681640625,50.53697353939,5.51317274851448,7.07879686355591,132,1,0,0,1,0.237808227539062,31.2805480957031,2,1,1,255.991287231445,0,256.232048034668,,,,,,,,,,,,,,,,,,,,,,,,,,,,,,,,,
,3738590553.45934,253.263305664062,9999.681640625,-8.33740851674319E-9,8.47553385305267E-9,1,10,13.2042255401611,3.98140622353229,32.3499999940395,-6.52703811856898E-6,-6.76720591239945E-6,1,-6.42501037516184E-9,253.025543212891,253.501068115234,9999.681640625,9999.681640625,50.4603739445053,5.51348334103283,7.07631063461304,132,1,0,0,1,0.238189697265625,31.2805480957031,2,1,1,253.025543212891,0,253.263305664062,,,,,,,,,,,,,,,,,,,,,,,,,,,,,,,,,
,3738590613.28505,250.270317077637,9999.681640625,-4.08179803957277E-9,9.55998917435738E-9,1,10,13.2042255401611,3.98141233495902,32.3400013148785,-3.80920248696177E-6,8.34834118019623E-7,1,1.54872672633362E-9,250.026275634766,250.514358520508,9999.681640625,9999.681640625,50.4904666424957,5.51300175312068,7.0656247138977,132,1,0,0,1,0.24169921875,32.2580642700195,2,1,1,250.026275634766,0,250.270317077637,,,,,,,,,,,,,,,,,,,,,,,,,,,,,,,,,
,3738590673.31113,247.269813537598,9999.681640625,-1.09347087013639E-8,8.68970856128904E-9,1,10,13.2042255401611,3.98145528976353,32.3499999940395,-9.37878347232261E-6,-3.34519830555906E-6,1,-2.16789057506303E-9,247.037155151367,247.502471923828,9999.681640625,9999.681640625,50.5760549653515,5.51301361477066,7.06590890884399,132,1,0,0,1,0.23834228515625,32.2580642700195,2,1,1,247.037155151367,0,247.269813537598,,,,,,,,,,,,,,,,,,,,,,,,,,,,,,,,,
,3738590733.28999,244.269149780273,9999.681640625,-1.01919596744441E-8,7.90641054704199E-9,1,10,13.2042255401611,3.98140888268142,32.3400013148785,-8.14198501865197E-6,-7.17027254373536E-6,1,-6.60676701880655E-9,243.992706298828,244.545593261719,9999.681640625,9999.681640625,50.5850436933227,5.51348697206605,7.05484628677368,132,1,0,0,1,0.237197875976562,31.2805480957031,2,1,1,243.992706298828,0,244.269149780273,,,,,,,,,,,,,,,,,,,,,,,,,,,,,,,,,
,3738590793.40425,241.267547607422,9999.681640625,-1.96424175554315E-8,5.96870241324571E-8,1,10,13.2042255401611,3.98133966607348,32.3499999940395,-1.65243499506721E-5,-8.18729773408886E-6,1,-6.35975172902195E-9,241.03076171875,241.504333496094,9999.681640625,9999.681640625,50.4838228000823,5.51409500940292,7.04951238632202,132,1,0,0,1,0.240402221679687,31.2805480957031,2,1,1,241.03076171875,0,241.267547607422,,,,,,,,,,,,,,,,,,,,,,,,,,,,,,,,,
,3738590853.21127,238.297294616699,9999.681640625,-3.9134431089869E-9,7.82833381290264E-9,1,10,13.2042255401611,3.98122709858377,32.3400013148785,-3.28394613916784E-6,-1.6860125932386E-6,1,-1.32921186125935E-9,238.064086914062,238.530502319336,9999.681640625,9999.681640625,50.6288148903996,5.51502485606865,7.04891490936279,132,1,0,0,1,0.236053466796875,31.2805480957031,2,1,1,238.064086914062,0,238.297294616699,,,,,,,,,,,,,,,,,,,,,,,,,,,,,,,,,
,3738590913.21808,235.253051757813,9999.681640625,-8.47374669927676E-9,8.1800432972405E-9,1,10,13.2042255401611,3.98113363009257,32.3499999940395,-7.20881088019307E-6,-2.98567801086225E-6,1,-2.12557454156408E-9,235.014495849609,235.491607666016,9999.681640625,9999.681640625,50.6034119635246,5.51580238832487,7.04299402236938,132,1,0,0,1,0.240707397460938,32.2580642700195,2,1,1,235.014495849609,0,235.253051757813,,,,,,,,,,,,,,,,,,,,,,,,,,,,,,,,,
,3738590973.1885,232.260208129883,9999.681640625,-1.15826512255629E-8,8.67160863747121E-9,1,10,13.2042255401611,3.98105637610499,32.3499999940395,-1.02886165746886E-5,-1.13891778438736E-6,1,4.24614717714129E-10,232.011581420898,232.508834838867,9999.681640625,9999.681640625,50.5909059072169,5.51649752282802,7.0423059463501,132,1,0,0,1,0.238800048828125,30.7917900085449,2,1,1,232.011581420898,0,232.260208129883,,,,,,,,,,,,,,,,,,,,,,,,,,,,,,,,,
,3738591033.287,229.282051086426,9999.681640625,-1.34110952753576E-8,1.04643019260091E-8,1,10,13.2042255401611,3.98101799955208,32.3400013148785,-1.14423787226967E-5,-4.49678521188754E-6,1,-3.10563473781497E-9,229.040573120117,229.523529052734,9999.681640625,9999.681640625,50.5873885788804,5.51609710959313,7.03599071502686,132,1,0,0,1,0.240020751953125,31.2805480957031,2,1,1,229.040573120117,0,229.282051086426,,,,,,,,,,,,,,,,,,,,,,,,,,,,,,,,,
,3738591093.12053,226.277542114258,9999.681640625,-9.27437232504448E-9,9.29608218893014E-9,1,10,13.2042255401611,3.98093929228919,32.3400013148785,-8.59252406542402E-6,1.48534050057659E-6,1,3.05351265982122E-9,226.040267944336,226.51481628418,9999.681640625,9999.681640625,50.584652879063,5.51629010643147,7.03099203109741,132,1,0,0,1,0.235977172851562,31.7693061828613,2,1,1,226.040267944336,0,226.277542114258,,,,,,,,,,,,,,,,,,,,,,,,,,,,,,,,,
,3738591153.08759,223.304740905762,9999.681640625,-7.525831248182E-9,9.43634182518556E-9,1,10,13.2042255401611,3.98089274974238,32.3499999940395,-6.37830402511321E-6,-2.8100851014568E-6,1,-2.06738884705464E-9,223.060104370117,223.549377441406,9999.681640625,9999.681640625,50.6018487064861,5.5158863777146,7.02511358261108,132,1,0,0,1,0.241241455078125,31.2805480957031,2,1,1,223.060104370117,0,223.304740905762,,,,,,,,,,,,,,,,,,,,,,,,,,,,,,,,,
,3738591213.13089,220.284149169922,9999.681640625,-3.87298265268914E-9,9.13507419252927E-9,1,10,13.2042255401611,3.98089953643496,32.3400013148785,-3.85057881992591E-6,2.39371599779654E-6,1,3.28260338819829E-9,220.024169921875,220.544128417969,9999.681640625,9999.681640625,50.5686294944188,5.51579118984963,7.01778841018677,132,1,0,0,1,0.236053466796875,30.7917900085449,2,1,1,220.024169921875,0,220.284149169922,,,,,,,,,,,,,,,,,,,,,,,,,,,,,,,,,
,3738591273.21437,217.29167175293,9999.681640625,-1.40016639873429E-8,8.55725539078039E-9,1,10,13.2042255401611,3.98087671249459,32.3400013148785,-1.30977152102741E-5,3.09245785169782E-6,1,5.57218475548175E-9,217.050003051758,217.533340454102,9999.681640625,9999.681640625,50.531892954015,5.51613792411644,7.0086669921875,132,1,0,0,1,0.235595703125,31.2805480957031,2,1,1,217.050003051758,0,217.29167175293,,,,,,,,,,,,,,,,,,,,,,,,,,,,,,,,,
,3738591333.05146,214.280776977539,9999.681640625,-1.39502554583847E-8,9.71845494376656E-9,1,10,13.2042255401611,3.98084490226898,32.3499999940395,-1.27171102897896E-5,8.34810235048103E-7,1,3.00902082193951E-9,214.03108215332,214.530471801758,9999.681640625,9999.681640625,50.5510428527361,5.51650189429886,7.00398349761963,132,1,0,0,1,0.238723754882813,31.2805480957031,2,1,1,214.03108215332,0,214.280776977539,,,,,,,,,,,,,,,,,,,,,,,,,,,,,,,,,
,3738591393.0689,211.281867980957,9999.681640625,-3.43519270036836E-9,1.19004019612868E-8,1,10,13.2042255401611,3.98079279964108,32.3400013148785,-2.32530547838918E-6,-5.24308385362214E-6,1,-5.42690774310076E-9,211.041015625,211.522720336914,9999.681640625,9999.681640625,50.552215295515,5.51619767739945,6.99297666549683,132,1,0,0,1,0.237960815429687,31.7693061828613,2,1,1,211.041015625,0,211.281867980957,,,,,,,,,,,,,,,,,,,,,,,,,,,,,,,,,
,3738591453.01375,208.320243835449,9999.681640625,-1.09316250478026E-8,9.01167859165207E-9,1,10,13.2042255401611,3.98074839558581,32.3400013148785,-1.01738359365625E-5,2.06609424316618E-6,1,3.95626805929937E-9,208.085922241211,208.554565429687,9999.681640625,9999.681640625,50.5588591379284,5.51621975262667,6.99120140075684,132,1,0,0,1,0.240478515625,31.7693061828613,2,1,1,208.085922241211,0,208.320243835449,,,,,,,,,,,,,,,,,,,,,,,,,,,,,,,,,
,3738591513.07496,205.308776855469,9999.681640625,-1.33947382730735E-8,1.20375128278546E-8,1,10,13.2042255401611,3.98073736989865,32.3400013148785,-1.13819347961646E-5,-4.79629259454254E-6,1,-3.44767812205698E-9,205.049911499023,205.567642211914,9999.681640625,9999.681640625,50.5076624699188,5.51596875266565,6.97822427749634,132,1,0,0,1,0.240020751953125,31.2805480957031,2,1,1,205.049911499023,0,205.308776855469,,,,,,,,,,,,,,,,,,,,,,,,,,,,,,,,,
,3738591572.9523,202.32494354248,9999.681640625,-4.63918564247182E-9,8.90605765717386E-9,1,10,13.2042255401611,3.98075640018036,32.3400013148785,-3.84137233075966E-6,-2.34192683957519E-6,1,-1.96469934062222E-9,202.075073242187,202.574813842773,9999.681640625,9999.681640625,50.5619856520054,5.51566347945542,6.97130966186523,132,1,0,0,1,0.236587524414062,31.7693061828613,2,1,1,202.075073242187,0,202.32494354248,,,,,,,,,,,,,,,,,,,,,,,,,,,,,,,,,
,3738591632.93654,199.312164306641,9999.681640625,-1.40346529221379E-8,1.05376020129899E-8,1,10,13.2042255401611,3.98077631663726,32.3400013148785,-1.17256127018404E-5,-6.37903970957428E-6,1,-5.1445941827919E-9,199.062683105469,199.561645507813,9999.681640625,9999.681640625,50.5514336669957,5.51602580222121,6.96967315673828,132,1,0,0,1,0.2392578125,31.2805480957031,2,1,1,199.062683105469,0,199.312164306641,,,,,,,,,,,,,,,,,,,,,,,,,,,,,,,,,
,3738591692.89911,196.347312927246,9999.681640625,1.55544958606047E-9,9.30740917298187E-9,1,10,13.2042255401611,3.9807376958754,32.3400013148785,1.80691445532968E-6,-2.72236558821461E-6,1,-3.311923952317E-9,196.101333618164,196.593292236328,9999.681640625,9999.681640625,50.643665832265,5.51662420279466,6.95652198791504,132,1,0,0,1,0.232620239257813,30.7917900085449,2,1,1,196.101333618164,0,196.347312927246,,,,,,,,,,,,,,,,,,,,,,,,,,,,,,,,,
,3738591752.94559,193.33341217041,9999.681640625,5.20749195828681E-9,9.83518362450715E-9,1,10,13.2042255401611,3.98071676828033,32.3400013148785,5.51559179068874E-6,-5.50680682244688E-6,1,-7.00437670376599E-9,193.084823608398,193.582000732422,9999.681640625,9999.681640625,50.6143547627938,5.51636111043591,6.94955635070801,132,1,0,0,1,0.241928100585938,31.2805480957031,2,1,1,193.084823608398,0,193.33341217041,,,,,,,,,,,,,,,,,,,,,,,,,,,,,,,,,
,3738591812.86155,190.301574707031,9999.681640625,5.26153457679968E-9,1.21216905190169E-8,1,10,13.2042255401611,3.98069635929451,32.3400013148785,4.78502726270383E-6,-2.39662566856294E-7,1,-1.04978848493798E-9,190.061538696289,190.541610717773,9999.681640625,9999.681640625,50.5932507927746,5.51617529697677,6.94889736175537,132,1,0,0,1,0.236053466796875,30.7917900085449,2,1,1,190.061538696289,0,190.301574707031,,,,,,,,,,,,,,,,,,,,,,,,,,,,,,,,,
,3738591873.06016,187.302352905273,9999.681640625,-2.58935511979017E-10,1.25520993321327E-8,1,10,13.2042255401611,3.98067842855311,32.3400013148785,-8.50558763928186E-7,4.16892038188096E-6,1,4.75774357900155E-9,187.055435180664,187.549270629883,9999.681640625,9999.681640625,50.5537785525534,5.51700136645382,6.93673992156982,132,1,0,0,1,0.240936279296875,31.7693061828613,2,1,1,187.055435180664,0,187.302352905273,,,,,,,,,,,,,,,,,,,,,,,,,,,,,,,,,
,3738591932.80687,184.326301574707,9999.681640625,-2.34282634302119E-8,1.61964734702979E-8,1,10,13.2042255401611,3.98062062398204,32.3400013148785,-2.10463355707195E-5,-6.8686861679538E-7,1,2.68878342412207E-9,184.077392578125,184.575210571289,9999.681640625,9999.681640625,50.5635489090438,5.51666843818065,6.92909097671509,132,1,0,0,1,0.233993530273438,31.7693061828613,2,1,1,184.077392578125,0,184.326301574707,,,,,,,,,,,,,,,,,,,,,,,,,,,,,,,,,
,3738591992.83297,181.3134765625,9999.681640625,1.70609855660429E-9,1.77309507798738E-8,1,10,13.2042255401611,3.98058796621681,32.3400013148785,3.34133282095934E-6,-1.21745702659568E-5,1,-1.40351693188619E-8,181.075271606445,181.551681518555,9999.681640625,9999.681640625,50.5635489090438,5.51733442830217,6.92529344558716,132,1,0,0,1,0.23651123046875,30.3030319213867,2,1,1,181.075271606445,0,181.3134765625,,,,,,,,,,,,,,,,,,,,,,,,,,,,,,,,,
,3738592052.82943,178.329437255859,9999.681640625,-6.13506726949925E-9,1.8827956296462E-8,1,10,13.2042255401611,3.98059968037456,32.3499999940395,-5.13031087658429E-6,-2.75469756229245E-6,1,-2.21083269901093E-9,178.088897705078,178.569976806641,9999.681640625,9999.681640625,50.544008196063,5.51711688133031,6.91832685470581,132,1,0,0,1,0.238723754882813,30.7917900085449,2,1,1,178.088897705078,0,178.329437255859,,,,,,,,,,,,,,,,,,,,,,,,,,,,,,,,,
,3738592112.77912,175.343589782715,9999.681640625,2.71639886367266E-8,1.80029390746112E-8,1,10,13.2042255401611,3.98055110415375,32.3400013148785,2.68726953085421E-5,-1.5905276910622E-5,1,-2.20256102954907E-8,175.091049194336,175.596130371094,9999.681640625,9999.681640625,50.6280332618804,5.51769511632146,6.90666484832764,132,1,0,0,1,0.2423095703125,32.2580642700195,2,1,1,175.091049194336,0,175.343589782715,,,,,,,,,,,,,,,,,,,,,,,,,,,,,,,,,
,3738592172.74009,172.342819213867,9999.681640625,1.34332211469217E-8,1.72346537459132E-8,1,10,13.2042255401611,3.98056056335382,32.3400013148785,1.30196389640165E-5,-6.04353054761748E-6,1,-8.8294483126209E-9,172.105697631836,172.579940795898,9999.681640625,9999.681640625,50.5733192655342,5.51735572066063,6.89666748046875,132,1,0,0,1,0.243072509765625,31.2805480957031,2,1,1,172.105697631836,0,172.342819213867,,,,,,,,,,,,,,,,,,,,,,,,,,,,,,,,,
,3738592232.70865,169.35270690918,9999.681640625,-4.04376551456125E-9,1.23484450231079E-8,1,10,13.2042255401611,3.9805429104343,32.3400013148785,-3.96509068915694E-6,2.12915870551209E-6,1,3.00875113618551E-9,169.108978271484,169.596435546875,9999.681640625,9999.681640625,50.5170420121496,5.51654547642335,6.88851928710937,132,1,0,0,1,0.238494873046875,30.7917900085449,2,1,1,169.108978271484,0,169.35270690918,,,,,,,,,,,,,,,,,,,,,,,,,,,,,,,,,
,3738592292.69381,166.338218688965,9999.681640625,-7.51853742064878E-9,1.21874866526606E-8,1,10,13.2042255401611,3.98052148504437,32.3499999940395,-6.14886429041241E-6,-4.30946396761654E-6,1,-3.76642318972653E-9,166.09455871582,166.581878662109,9999.681640625,9999.681640625,50.5959864925919,5.51788584849969,6.88966655731201,132,1,0,0,1,0.241622924804687,30.7917900085449,2,1,1,166.09455871582,0,166.338218688965,,,,,,,,,,,,,,,,,,,,,,,,,,,,,,,,,
,3738592352.79688,163.349853515625,9999.681640625,8.16482747000001E-9,1.44382272441314E-8,1,10,13.2042255401611,3.98055759403685,32.3499999940395,8.38103478540796E-6,-6.83365639303084E-6,1,-8.94446802897953E-9,163.087280273438,163.612426757813,9999.681640625,9999.681640625,50.6198261624284,5.51705601640491,6.87931251525879,132,1,0,0,1,0.237274169921875,31.7693061828613,2,1,1,163.087280273438,0,163.349853515625,,,,,,,,,,,,,,,,,,,,,,,,,,,,,,,,,
,3738592412.65685,160.343803405762,9999.681640625,-6.70222562073033E-9,1.33185488835805E-8,1,10,13.2042255401611,3.98050817801184,32.3400013148785,-4.81947830545543E-6,-8.3141707073878E-6,1,-8.4210721177905E-9,160.092529296875,160.595077514648,9999.681640625,9999.681640625,50.5604223949669,5.51825861324871,6.87106895446777,132,1,0,0,1,0.242156982421875,30.7917900085449,2,1,1,160.092529296875,0,160.343803405762,,,,,,,,,,,,,,,,,,,,,,,,,,,,,,,,,
,3738592472.6706,157.355949401855,9999.681640625,-1.40599904284434E-8,1.41418743366577E-8,1,10,13.2042255401611,3.98053179011159,32.3400013148785,-9.78861594699457E-6,-1.96168414032752E-5,1,-2.01283091355607E-8,157.110321044922,157.601577758789,9999.681640625,9999.681640625,50.6917359861977,5.51670875865061,6.86002349853516,132,1,0,0,1,0.234298706054687,31.7693061828613,2,1,1,157.110321044922,0,157.355949401855,,,,,,,,,,,,,,,,,,,,,,,,,,,,,,,,,
,3738592532.62994,154.351219177246,9999.681640625,3.76352163043026E-9,1.1430855157536E-8,1,10,13.2042255401611,3.980592728492,32.3400013148785,3.1754608285055E-6,1.49850906523026E-6,1,1.1396089033308E-9,154.113861083984,154.588577270508,9999.681640625,9999.681640625,50.5463530816207,5.51704466330044,6.85616159439087,132,1,0,0,1,0.23895263671875,31.7693061828613,2,1,1,154.102233886719,0,154.351219177246,,,,,,,,,,,,,,,,,,,,,,,,,,,,,,,,,
,3738592592.67892,151.369766235352,9999.681640625,-1.83050761395675E-8,1.48731633540347E-8,1,10,13.2042255401611,3.98058573429814,32.3400013148785,-1.36301498889372E-5,-1.9553266851181E-5,1,-1.94277662346982E-8,151.109725952148,151.629806518555,9999.681640625,9999.681640625,50.5748825225727,5.51721599923068,6.84786415100098,132,1,0,0,1,0.236358642578125,30.7917900085449,2,1,1,151.109725952148,0,151.369766235352,,,,,,,,,,,,,,,,,,,,,,,,,,,,,,,,,
,3738592652.55963,148.337760925293,9999.681640625,-1.58383934328639E-9,1.07584489274698E-8,1,10,13.2042255401611,3.98054696914478,32.3400013148785,-1.25310021775107E-6,-1.1931847843358E-6,1,-1.11647796571559E-9,148.101959228516,148.57356262207,9999.681640625,9999.681640625,50.6440566465246,5.51665059316775,6.83684968948364,132,1,0,0,1,0.23712158203125,31.2805480957031,2,1,1,148.101959228516,0,148.337760925293,,,,,,,,,,,,,,,,,,,,,,,,,,,,,,,,,
,3738592712.56605,145.342437744141,9999.681640625,-9.13830236578627E-9,9.52986210197122E-9,1,10,13.2042255401611,3.98057252950209,32.3400013148785,-8.1963919305464E-6,-3.53543776847686E-7,1,9.51827680448599E-10,145.102523803711,145.58235168457,9999.681640625,9999.681640625,50.589733464438,5.51696155640593,6.83187818527222,132,1,0,0,1,0.237884521484375,32.7468223571777,2,1,1,145.102523803711,0,145.342437744141,,,,,,,,,,,,,,,,,,,,,,,,,,,,,,,,,
,3738592772.54421,142.377449035645,9999.681640625,-5.23261435281606E-9,8.73904196189501E-9,1,10,13.2042255401611,3.98059301401422,32.3400013148785,-4.76546825606247E-6,2.85237819564627E-7,1,1.09711609773939E-9,142.116897583008,142.638000488281,9999.681640625,9999.681640625,50.6127915057554,5.51701582269019,6.81602573394775,132,1,0,0,1,0.237884521484375,32.2580642700195,2,1,1,142.116897583008,0,142.377449035645,,,,,,,,,,,,,,,,,,,,,,,,,,,,,,,,,
,3738592832.67125,139.37621307373,9999.681640625,-8.80745939945878E-9,8.34978499073565E-9,1,10,13.2042255401611,3.98060288995163,32.3400013148785,-7.4310720190798E-6,-3.50838905853723E-6,1,-2.66867337477113E-9,139.125946044922,139.626480102539,9999.681640625,9999.681640625,50.5424449390246,5.51780928732979,6.81280612945557,132,1,0,0,1,0.236663818359375,31.7693061828613,2,1,1,139.125946044922,0,139.37621307373,,,,,,,,,,,,,,,,,,,,,,,,,,,,,,,,,
,3738592892.48479,136.337432861328,9999.681640625,-1.39475124620704E-8,1.052872271984E-8,1,10,13.2042255401611,3.98057223783818,32.3400013148785,-1.21364800770666E-5,-3.06345860352905E-6,1,-1.4045105594419E-9,136.082916259766,136.591949462891,9999.681640625,9999.681640625,50.582698807765,5.51756057486085,6.80477333068848,132,1,0,0,1,0.233535766601562,31.7693061828613,2,1,1,136.082916259766,0,136.337432861328,,,,,,,,,,,,,,,,,,,,,,,,,,,,,,,,,
,3738592952.53112,133.355125427246,9999.681640625,-1.0589086048582E-8,8.94669327231725E-9,1,10,13.2042255401611,3.98060596872727,32.3400013148785,-9.15490402528823E-6,-2.7269933494104E-6,1,-1.52045872686966E-9,133.107696533203,133.602554321289,9999.681640625,9999.681640625,50.6315505902169,5.51737576678143,6.79016494750977,132,1,0,0,1,0.241241455078125,31.2805480957031,2,1,1,133.107696533203,0,133.355125427246,,,,,,,,,,,,,,,,,,,,,,,,,,,,,,,,,
,3738593012.42735,130.375343322754,9999.681640625,-8.73119740112428E-9,7.58126524115093E-9,1,10,13.2042255401611,3.98059125812457,32.3400013148785,-8.22311065534727E-6,2.31029577305563E-6,1,3.90730565589739E-9,130.127243041992,130.623443603516,9999.681640625,9999.681640625,50.58777939314,5.51739665092288,6.7811131477356,132,1,0,0,1,0.235671997070313,31.2805480957031,2,1,1,130.127243041992,0,130.375343322754,,,,,,,,,,,,,,,,,,,,,,,,,,,,,,,,,
,3738593072.52596,127.364624023437,9999.681640625,-6.53779172707097E-9,7.88694477641252E-9,1,10,13.2042255401611,3.9806194060037,32.3400013148785,-5.77342717872761E-6,-8.65323652338741E-7,1,-1.23030226466719E-11,127.109580993652,127.619667053223,9999.681640625,9999.681640625,50.6096649916784,5.51748637269165,6.77347421646118,132,1,0,0,1,0.236587524414062,32.7468223571777,2,1,1,127.109580993652,0,127.364624023437,,,,,,,,,,,,,,,,,,,,,,,,,,,,,,,,,
,3738593132.56293,124.365013122559,9999.681640625,-4.84044322410881E-9,8.23538626407573E-9,1,10,13.2042255401611,3.98059168461988,32.3400013148785,-3.30965601132013E-6,-7.16161704940739E-6,1,-7.39142449757503E-9,124.133392333984,124.596633911133,9999.681640625,9999.681640625,50.5131338695534,5.51781711074093,6.7643928527832,132,1,0,0,1,0.2362060546875,31.2805480957031,2,1,1,124.133392333984,0,124.365013122559,,,,,,,,,,,,,,,,,,,,,,,,,,,,,,,,,
,3738593192.38034,121.376235961914,9999.681640625,-5.72391085301568E-9,8.97145604045054E-9,1,10,13.2042255401611,3.98056896656976,32.3400013148785,-5.43730403729009E-6,1.82901603911273E-6,1,2.91752305978681E-9,121.13353729248,121.618934631348,9999.681640625,9999.681640625,50.5909059072169,5.51714449924866,6.75390148162842,130,1,32,0,0,0.233535766601562,30.7917900085449,2,1,1,121.13353729248,0,121.376235961914,,,,,,,,,,,,,,,,,,,,,,,,,,,,,,,,,
,3738593252.39297,118.404426574707,9999.681640625,5.87307179703051E-9,1.03764987042748E-8,1,10,13.2042255401611,3.98052661572896,32.3400013148785,5.11973556381596E-6,1.22672932289994E-6,1,5.19844137757659E-10,118.163597106934,118.64525604248,9999.681640625,9999.681640625,50.6780574871111,5.51757961950994,6.737060546875,132,1,0,0,1,0.237884521484375,31.7693061828613,2,1,1,118.163597106934,0,118.404426574707,,,,,,,,,,,,,,,,,,,,,,,,,,,,,,,,,
,3738593312.33715,115.379886627197,9999.681640625,-6.69801103488603E-9,8.68335795759474E-9,1,10,13.2042255401611,3.98053931788236,32.3400013148785,-5.53219125807264E-6,-3.47193761417179E-6,1,-2.9396148838979E-9,115.135383605957,115.624389648438,9999.681640625,9999.681640625,50.6389760611496,5.51747360895968,6.72910737991333,132,1,0,0,1,0.233840942382813,31.2805480957031,2,1,1,115.135383605957,0,115.379886627197,,,,,,,,,,,,,,,,,,,,,,,,,,,,,,,,,
,3738593372.47081,112.373069763184,9999.681640625,-8.9530118370177E-9,8.16316529634682E-9,1,10,13.2042255401611,3.98052342516468,32.3400013148785,-8.49965441557293E-6,2.82761732167728E-6,1,4.52586691222084E-9,112.141746520996,112.604393005371,9999.681640625,9999.681640625,50.6346771042938,5.51817491923534,6.71710920333862,131,1,68,0,0,0.232772827148438,31.7693061828613,2,1,1,112.141746520996,0,112.373069763184,,,,,,,,,,,,,,,,,,,,,,,,,,,,,,,,,
,3738593432.30573,109.404720306396,9999.681640625,-2.7313047831334E-9,8.55222843405183E-9,1,10,13.2042255401611,3.98055385034342,32.3400013148785,-2.92446455592895E-6,3.10270892875921E-6,1,3.91671704821941E-9,109.162857055664,109.646583557129,9999.681640625,9999.681640625,50.6249067478034,5.51678367748943,6.70304441452026,132,1,0,0,1,0.232925415039062,31.2805480957031,2,1,1,109.162857055664,0,109.404720306396,,,,,,,,,,,,,,,,,,,,,,,,,,,,,,,,,
,3738593492.29316,106.396141052246,9999.681640625,4.53640123077857E-10,9.47598742076658E-9,1,10,13.2042255401611,3.98047341653462,32.3400013148785,-7.26834701724895E-9,2.81657069423302E-6,1,3.12164621611713E-9,106.149604797363,106.642677307129,9999.681640625,9999.681640625,50.5936416070342,5.51679077399286,6.69747447967529,132,1,0,0,1,0.240249633789062,31.2805480957031,2,1,1,106.140068054199,0,106.396141052246,,,,,,,,,,,,,,,,,,,,,,,,,,,,,,,,,
,3738593552.24768,103.394565582275,9999.681640625,-8.0245340016944E-9,9.71945502667989E-9,1,10,13.2042255401611,3.98049723724921,32.3400013148785,-6.27596173798149E-6,-6.53687806286443E-6,1,-6.21333581333833E-9,103.134559631348,103.654571533203,9999.681640625,9999.681640625,50.5901242786977,5.5174136008649,6.67956972122192,132,1,0,0,1,0.234527587890625,31.2805480957031,2,1,1,103.134559631348,0,103.394565582275,,,,,,,,,,,,,,,,,,,,,,,,,,,,,,,,,
,3738593612.36503,100.371013641357,9999.681640625,-9.66994624141558E-10,9.00327729782137E-9,1,10,13.2042255401611,3.98049007514343,32.3400013148785,-1.72606297871686E-6,5.76676815496508E-6,1,6.67184539252039E-9,100.117317199707,100.624710083008,9999.681640625,9999.681640625,50.6288148903996,5.5172386705424,6.6687445640564,132,1,0,0,1,0.235214233398438,32.2580642700195,2,1,1,100.117317199707,0,100.371013641357,,,,,,,,,,,,,,,,,,,,,,,,,,,,,,,,,
,3738593672.23252,97.3939208984375,9999.681640625,2.5531191876949E-10,1.09664201356248E-8,1,10,13.2042255401611,3.98041232735799,32.3400013148785,2.14550620501662E-7,1.07411101545637E-7,1,8.38327372052782E-11,97.1372680664062,97.6505737304687,9999.681640625,9999.681640625,50.5565142523707,5.51846689994995,6.65411949157715,132,1,0,0,1,0.240325927734375,31.7693061828613,2,1,1,97.1372680664062,0,97.3939208984375,,,,,,,,,,,,,,,,,,,,,,,,,,,,,,,,,
,3738593732.1951,94.4219589233398,9999.681640625,-1.21854381997775E-8,8.47367669630692E-9,1,10,13.2042255401611,3.98045844858774,32.3400013148785,-1.10108172330551E-5,8.19062265189067E-8,1,1.89564931199345E-9,94.1749649047852,94.6689529418945,9999.681640625,9999.681640625,50.6014578922265,5.51780843836306,6.64431381225586,132,1,0,0,1,0.231475830078125,31.2805480957031,2,1,1,94.1749649047852,0,94.4219589233398,,,,,,,,,,,,,,,,,,,,,,,,,,,,,,,,,
,3738593792.18319,91.4091491699219,9999.681640625,-8.34798888693748E-9,1.09325015288462E-8,1,10,13.2042255401611,3.9804060855555,32.3400013148785,-6.52762148591631E-6,-6.80738006635769E-6,1,-6.47200500136458E-9,91.1518020629883,91.6664962768555,9999.681640625,9999.681640625,50.6096649916784,5.51846480585068,6.62969732284546,132,1,0,0,1,0.232162475585938,31.2805480957031,2,1,1,91.1518020629883,0,91.4091491699219,,,,,,,,,,,,,,,,,,,,,,,,,,,,,,,,,
,3738593852.26621,88.401309967041,9999.681640625,1.02660737512667E-9,9.16076098853446E-9,1,10,13.2042255401611,3.98038164086043,32.3400013148785,8.80029000672759E-7,3.14743965611915E-7,1,2.04455227965062E-10,88.1647796630859,88.6378402709961,9999.681640625,9999.681640625,50.5612040234861,5.5174635683419,6.61690044403076,130,1,68,0,0,0.23223876953125,30.7917900085449,2,1,1,88.1647796630859,0,88.401309967041,,,,,,,,,,,,,,,,,,,,,,,,,,,,,,,,,
,3738593912.14131,85.4282684326172,9999.681640625,3.62748269054569E-9,1.03173293606693E-8,1,10,13.2042255401611,3.98046158918681,32.3400013148785,4.48384832064586E-6,-8.17564008365068E-6,1,-9.792761873165E-9,85.1833038330078,85.6732330322266,9999.681640625,9999.681640625,50.6424933894861,5.51709855870197,6.60592269897461,132,1,0,0,1,0.239639282226562,31.2805480957031,2,1,1,85.1833038330078,0,85.4282684326172,,,,,,,,,,,,,,,,,,,,,,,,,,,,,,,,,
,3738593972.11313,82.4032173156738,9999.681640625,-1.38216554817773E-8,1.03181469267334E-8,1,10,13.2042255401611,3.98051621169491,32.3400013148785,-1.29078334073022E-5,2.91963009804093E-6,1,5.35039534574909E-9,82.1441345214844,82.6623001098633,9999.681640625,9999.681640625,50.5424449390246,5.51763545919944,6.58809804916382,132,1,0,0,1,0.239410400390625,31.2805480957031,2,1,1,82.1441345214844,0,82.4032173156738,,,,,,,,,,,,,,,,,,,,,,,,,,,,,,,,,
,3738594032.07453,79.375301361084,9999.681640625,-4.37623312412451E-9,1.07473847347855E-8,1,10,13.2042255401611,3.98050784945517,32.3400013148785,-4.08168872920423E-6,8.89303156663274E-7,1,1.65429954152259E-9,79.1115493774414,79.6390533447266,9999.681640625,9999.681640625,50.6245159335438,5.51771000882161,6.56744289398193,132,1,0,0,1,0.235748291015625,31.2805480957031,2,1,1,79.1115493774414,0,79.375301361084,,,,,,,,,,,,,,,,,,,,,,,,,,,,,,,,,
,3738594092.22241,76.3351020812988,9999.681640625,-6.63513538033164E-9,1.23080719806971E-8,1,10,13.2042255401611,3.98047236646813,32.3400013148785,-5.56647575317431E-6,-2.85554477146706E-6,1,-2.25117730061887E-9,76.0874710083008,76.5827331542969,9999.681640625,9999.681640625,50.6209986052073,5.51774081571938,6.55201053619385,132,1,0,0,1,0.239181518554687,30.7917900085449,2,1,1,76.0874710083008,0,76.3351020812988,,,,,,,,,,,,,,,,,,,,,,,,,,,,,,,,,
,3738594152.09063,73.3385963439941,9999.681640625,-6.42932756590154E-9,1.16477024427469E-8,1,10,13.2042255401611,3.98050332328499,32.3400013148785,-5.99977330610267E-6,1.32804420189915E-6,1,2.45478311140937E-9,73.0866928100586,73.5904998779297,9999.681640625,9999.681640625,50.6299873331784,5.51732109877362,6.53931331634521,132,1,0,0,1,0.235595703125,30.7917900085449,2,1,1,73.0866928100586,0,73.3385963439941,,,,,,,,,,,,,,,,,,,,,,,,,,,,,,,,,
,3738594212.02924,70.3260879516602,9999.681640625,-1.6133460661312E-8,1.37864772285443E-8,1,10,13.2042255401611,3.98049421338132,32.3400013148785,-1.3072430957773E-5,-1.00705135148692E-5,1,-9.01412653312893E-9,70.0706100463867,70.5815658569336,9999.681640625,9999.681640625,50.55729588089,5.51749839769923,6.51551961898804,132,1,0,0,1,0.234222412109375,31.7693061828613,2,1,1,70.0706100463867,0,70.3260879516602,,,,,,,,,,,,,,,,,,,,,,,,,,,,,,,,,
,3738594271.99994,67.2994422912598,9999.681640625,3.90131211073559E-9,1.10525061615435E-8,1,10,13.2042255401611,3.98047702534363,32.3400013148785,2.63893881835802E-6,5.96424468807535E-6,1,6.17515194357878E-9,67.0433044433594,67.5555801391602,9999.681640625,9999.681640625,50.5772274081304,5.5180067153908,6.49706602096558,132,1,0,0,1,0.235595703125,31.7693061828613,2,1,1,67.0433044433594,0,67.2994422912598,,,,,,,,,,,,,,,,,,,,,,,,,,,,,,,,,
,3738594332.12268,64.2513046264648,9999.681640625,-3.64357450771834E-9,1.0087292674359E-8,1,10,13.2042255401611,3.98046540383187,32.3400013148785,-2.92587292599007E-6,-2.45249290710464E-6,1,-2.23749379354354E-9,64.0104141235352,64.4921951293945,9999.681640625,9999.681640625,50.6213894194669,5.51752423349299,6.48028373718262,132,1,0,0,1,0.237503051757813,31.2805480957031,2,1,1,64.0104141235352,0,64.2513046264648,,,,,,,,,,,,,,,,,,,,,,,,,,,,,,,,,
,3738594391.94395,61.2335815429688,9999.681640625,-9.02489022465182E-10,1.0732524773116E-8,1,10,13.2042255401611,3.98047937160637,32.3400013148785,1.0388635917114E-7,-6.20781555964826E-6,1,-6.89459879613358E-9,60.9955139160156,61.4716491699219,9999.681640625,9999.681640625,50.6155272055727,5.51792803170219,6.45303392410278,132,1,0,0,1,0.236129760742187,31.2805480957031,2,1,1,60.9955139160156,0,61.2335815429688,,,,,,,,,,,,,,,,,,,,,,,,,,,,,,,,,
,3738594451.95861,58.2039279937744,9999.681640625,-8.19235657789536E-9,1.26157413316751E-8,1,10,13.2042255401611,3.98046062739694,32.3400013148785,-7.14289596723809E-6,-1.70058807596409E-6,1,-7.132062626082E-10,57.9435958862305,58.4642601013184,9999.681640625,9999.681640625,50.6256883763227,5.51781187336439,6.43564414978027,132,1,0,0,1,0.2349853515625,30.7917900085449,2,1,1,57.9435958862305,0,58.2039279937744,,,,,,,,,,,,,,,,,,,,,,,,,,,,,,,,,
,3738594511.89824,55.2052707672119,9999.681640625,3.06904427626646E-9,1.18513738789365E-8,1,10,13.2042255401611,3.98049220780832,32.3400013148785,2.57960534041081E-6,1.28809402104485E-6,1,1.00421159640144E-9,54.9549713134766,55.4555702209473,9999.681640625,9999.681640625,50.4842136143419,5.51741369825925,6.41286325454712,132,1,0,0,1,0.240631103515625,31.7693061828613,2,1,1,54.9549713134766,0,55.2052707672119,,,,,,,,,,,,,,,,,,,,,,,,,,,,,,,,,
,3738594571.9627,52.1624011993408,9999.681640625,4.99833851061261E-9,1.08139173498837E-8,1,10,13.2042255401611,3.98048418585153,32.3400013148785,5.98553511695726E-6,-9.96194531821134E-6,1,-1.20178525262555E-8,51.9146041870117,52.4101982116699,9999.681640625,9999.681640625,50.5612040234861,5.51825275857226,6.37983083724976,131,1,68,0,0,0.23590087890625,30.7917900085449,2,1,1,51.9146041870117,0,52.1624011993408,,,,,,,,,,,,,,,,,,,,,,,,,,,,,,,,,
,3738594631.85315,49.1425971984863,9999.681640625,1.13618149841003E-9,1.17810165215393E-8,1,10,13.2042255401611,3.98042814035918,32.3400013148785,4.29039394017397E-7,4.03142490433469E-6,1,4.39613319183932E-9,48.8947563171387,49.390438079834,9999.681640625,9999.681640625,50.6038027777842,5.518182008991,6.35381364822388,132,1,0,0,1,0.238571166992187,31.2805480957031,2,1,1,48.8827857971191,0,49.1425971984863,,,,,,,,,,,,,,,,,,,,,,,,,,,,,,,,,
,3738594691.83841,46.1122264862061,9999.681640625,8.18392937260347E-9,1.01192176997077E-8,1,10,13.2042255401611,3.98047458234504,32.3400013148785,5.95141203773788E-6,9.70237258846502E-6,1,9.77361544376866E-9,45.8585510253906,46.3659019470215,9999.681640625,9999.681640625,50.60810173464,5.51792822674316,6.31253528594971,132,1,0,0,1,0.239334106445313,31.7693061828613,2,1,1,45.8585510253906,0,46.1122264862061,,,,,,,,,,,,,,,,,,,,,,,,,,,,,,,,,
,3738594751.81539,43.0917625427246,9999.681640625,8.05936539505716E-9,1.00052007461777E-8,1,10,13.2042255401611,3.98047528935978,32.3499999940395,9.27441008979993E-6,-1.35167578116927E-5,1,-1.64953515548533E-8,42.8356018066406,43.3479232788086,9999.681640625,9999.681640625,50.5756641510919,5.5185331987513,6.27632904052734,132,1,0,0,1,0.2362060546875,31.7693061828613,2,1,1,42.8356018066406,0,43.0917625427246,,,,,,,,,,,,,,,,,,,,,,,,,,,,,,,,,
,3738594811.8299,40.0683174133301,9999.681640625,2.12101404770126E-8,2.32073440483517E-8,1,10,13.2042255401611,3.98050046821486,32.3400013148785,1.69431116689509E-5,1.48806676871083E-5,1,1.37086993902129E-8,39.8200836181641,40.3165512084961,9999.681640625,9999.681640625,50.6026303350054,5.51760951177982,6.2406530380249,132,1,0,0,1,0.236740112304687,29.8142719268799,2,1,1,39.8200836181641,0,40.0683174133301,,,,,,,,,,,,,,,,,,,,,,,,,,,,,,,,,
,3738594871.76935,37.0438995361328,9999.681640625,1.04200554290999E-8,1.26391518023262E-8,1,10,13.2042255401611,3.9805189578883,32.3400013148785,1.00246341653964E-5,-4.18472800301454E-6,1,-6.27934927469591E-9,36.7980346679687,37.2897644042969,9999.681640625,9999.681640625,50.6421025752265,5.51772343795865,6.18709278106689,132,1,0,0,1,0.234832763671875,31.2805480957031,2,1,1,36.7980346679687,0,37.0438995361328,,,,,,,,,,,,,,,,,,,,,,,,,,,,,,,,,
,3738594931.85202,34.0159969329834,9999.681640625,2.37945475780195E-8,1.15668167609539E-8,1,10,13.2042255401611,3.98049911023897,32.3400013148785,1.93967565793504E-5,1.40635003161324E-5,1,1.24011857370559E-8,33.7537040710449,34.2782897949219,9999.681640625,9999.681640625,50.6272516333611,5.51762131241828,6.13691520690918,132,1,0,0,1,0.23162841796875,30.7917900085449,2,1,1,33.7537040710449,0,34.0159969329834,,,,,,,,,,,,,,,,,,,,,,,,,,,,,,,,,
,3738594991.88214,30.9853458404541,9999.681640625,2.58720280182169E-8,1.11515618243776E-8,1,10,13.2042255401611,3.98047654430481,32.3400013148785,2.12226238557856E-5,1.43953970946382E-5,1,1.24697072289523E-8,30.736515045166,31.2341766357422,9999.681640625,9999.681640625,50.6475739748611,5.51814917600846,6.06655263900757,132,1,0,0,1,0.24078369140625,32.2580642700195,2,1,1,30.736515045166,0,30.9853458404541,,,,,,,,,,,,,,,,,,,,,,,,,,,,,,,,,
,3738595051.71222,27.9833717346191,9999.681640625,1.97275803154523E-8,1.32801497902324E-8,1,10,13.2042255401611,3.98048075662289,32.3400013148785,1.57006247141603E-5,1.42328421514764E-5,1,1.3194757630434E-8,27.7459163665771,28.2208271026611,9999.681640625,9999.681640625,50.6467923463419,5.51781318974267,5.98723888397217,130,1,32,0,0,0.236740112304687,30.7917900085449,2,1,1,27.7459163665771,0,27.9833717346191,,,,,,,,,,,,,,,,,,,,,,,,,,,,,,,,,
,3738595111.69459,24.9707536697388,9999.681640625,2.26657544778265E-8,1.2404143924594E-8,1,10,13.2042255401611,3.98056291134436,32.3400013148785,1.88092686247918E-5,1.1151404585231E-5,1,9.27099545707992E-9,24.7215156555176,25.21999168396,9999.681640625,9999.681640625,50.6163088340919,5.51852641388298,5.89564037322998,132,1,0,0,1,0.233001708984375,30.7917900085449,2,1,1,24.7215156555176,0,24.9707536697388,,,,,,,,,,,,,,,,,,,,,,,,,,,,,,,,,
,3738595171.7297,21.9688005447388,9999.681640625,3.23295653852851E-8,1.0858871861233E-8,1,10,13.2042255401611,3.98052230286394,32.3400013148785,2.87116273917618E-5,3.17734911082876E-6,1,-1.18623256551793E-9,21.7273120880127,22.2102890014648,9999.681640625,9999.681640625,50.6784483013707,5.51807908002915,5.76168489456177,132,1,0,0,1,0.237350463867187,31.7693061828613,2,1,1,21.7273120880127,0,21.9688005447388,,,,,,,,,,,,,,,,,,,,,,,,,,,,,,,,,
,3738595231.71953,18.9577035903931,9999.681640625,4.09772147015213E-8,1.1472928268914E-8,1,10,13.2042255401611,3.98057696405825,32.3400013148785,3.6718274490744E-5,1.82438582023169E-6,1,-3.99747690979075E-9,18.7117366790771,19.203670501709,9999.681640625,9999.681640625,50.6338954757746,5.51755098665675,5.57695198059082,132,1,0,0,1,0.237808227539062,31.2805480957031,2,1,1,18.7117366790771,0,18.9577035903931,,,,,,,,,,,,,,,,,,,,,,,,,,,,,,,,,
,3738595291.63459,15.98397397995,9999.681640625,5.92038690708924E-8,1.33267662854986E-8,1,10,13.2042255401611,3.98051236449399,32.3400013148785,5.14479273693467E-5,1.34582152969342E-5,1,6.47678984008851E-9,15.7406854629517,16.2272624969482,9999.681640625,9999.681640625,50.6620341024669,5.51791878663667,5.3181619644165,132,1,0,0,1,0.234146118164062,31.2805480957031,2,1,1,15.7406854629517,0,15.98397397995,,,,,,,,,,,,,,,,,,,,,,,,,,,,,,,,,
,3738595351.73031,13.0186705589294,9999.681640625,6.89670653799896E-8,1.27807243095854E-8,1,10,13.2042255401611,3.98053016051477,32.3400013148785,6.13262382081869E-5,6.25803252010444E-6,1,-3.11931332919515E-9,12.7710571289062,13.2662839889526,9999.681640625,9999.681640625,50.6194353481688,5.51692995746622,4.99211406707764,132,1,0,0,1,0.236968994140625,30.7917900085449,2,1,1,12.7710571289062,0,13.0186705589294,,,,,,,,,,,,,,,,,,,,,,,,,,,,,,,,,
,3738595411.74811,10.0309824943542,9999.681640625,9.29784513860642E-8,1.35876393707325E-8,1,10,13.2042255401611,3.98052768780488,32.3400013148785,8.08101793950987E-5,2.10563823656079E-5,1,1.00815518247127E-8,9.72386932373047,10.338095664978,9999.681640625,9999.681640625,50.51665119789,5.51795350550088,4.58350372314453,132,1,0,0,1,0.240554809570313,31.2805480957031,2,1,1,9.72386932373047,0,10.0309824943542,,,,,,,,,,,,,,,,,,,,,,,,,,,,,,,,,
,3738595471.59905,6.88276648521423,9999.681640625,1.17885245925397E-7,1.25091085834777E-8,1,10,13.2042255401611,3.98051121076215,32.3400013148785,0.000102909244998123,2.36380661647678E-5,1,9.31937375132503E-9,6.63858938217163,7.12694358825684,9999.681640625,9999.681640625,50.6417117609669,5.51703301625829,4.23503971099854,130,1,32,0,0,0.236282348632813,31.2805480957031,6,1,1,6.63858938217163,0,6.88276648521423,,,,,,,,,,,,,,,,,,,,,,,,,,,,,,,,,
,3738595531.58262,4.04298901557922,9999.681640625,2.10448505641008E-7,1.09982506488606E-8,1,10,13.2042255401611,3.98055449279951,32.3400013148785,0.000185303254355058,3.14754057131228E-5,1,4.49625326273795E-9,3.81770086288452,4.26827716827393,9999.681640625,9999.681640625,50.6999430856496,5.51791450850181,3.44317078590393,132,1,0,0,1,0.236663818359375,31.2805480957031,6,1,1,3.81770086288452,0,4.04298901557922,,,,,,,,,,,,,,,,,,,,,,,,,,,,,,,,,
,3738595591.56371,2.82936227321625,9999.681640625,2.81423036621179E-7,1.02283355977115E-8,1,10,13.2042255401611,3.9805227130766,32.3400013148785,0.000249577772589119,3.00360258291243E-5,1,-7.63401404893738E-9,2.82854104042053,2.83018350601196,9999.681640625,9999.681640625,50.6847013295246,5.5185327551165,2.93773460388184,132,1,0,0,1,0.235519409179687,31.2805480957031,6,1,1,2.83018350601196,0,2.82936227321625,,,,,,,,,,,,,,,,,,,,,,,,,,,,,,,,,
,3738595651.55849,2.83153080940247,9999.681640625,2.79243004763518E-7,1.09266254362001E-8,1,10,13.2042255401611,3.98050918856238,32.3400013148785,0.000247206046705284,3.27570061561869E-5,1,-4.23077972261581E-9,2.8312931060791,2.83176851272583,9999.681640625,9999.681640625,50.6409301324477,5.51833780017406,2.9308352470398,132,1,0,0,1,0.237579345703125,30.7917900085449,6,1,1,2.8312931060791,0,2.83153080940247,,,,,,,,,,,,,,,,,,,,,,,,,,,,,,,,,
,3738595711.65913,2.82875645160675,9999.681640625,2.7609135713601E-7,1.11448929279439E-8,1,10,13.2042255401611,3.98055465941554,32.3400013148785,0.000243793870482801,3.66227258685228E-5,1,6.11262056933812E-10,2.8277895450592,2.8297233581543,9999.681640625,9999.681640625,50.6780574871111,5.51815346479194,2.94113779067993,132,1,0,0,1,0.234603881835938,31.7693061828613,6,1,1,2.8277895450592,0,2.82875645160675,,,,,,,,,,,,,,,,,,,,,,,,,,,,,,,,,
,3738595771.47698,2.8216814994812,9999.681640625,2.8417739760615E-7,9.96375832299057E-9,1,10,13.2042255401611,3.98052044598418,32.3400013148785,0.000250907740821088,3.78489539923615E-5,1,8.03687937550142E-10,2.82075333595276,2.82260966300964,9999.681640625,9999.681640625,50.6890002863804,5.51855185394993,2.94262170791626,132,1,0,0,1,0.236663818359375,30.3030319213867,6,1,1,2.82075333595276,0,2.8216814994812,,,,,,,,,,,,,,,,,,,,,,,,,,,,,,,,,
,3738595831.43741,2.81326568126678,9999.681640625,2.82559344838512E-7,1.07374035381157E-8,1,10,13.2042255401611,3.98047596187722,32.3400013148785,0.000249033115629038,4.06170750049068E-5,1,4.17776546540834E-9,2.81294798851013,2.81358337402344,9999.681640625,9999.681640625,50.6960349430534,5.51820515111284,2.93954610824585,132,1,0,0,1,0.235595703125,30.7917900085449,6,1,1,2.81294798851013,0,2.81326568126678,,,,,,,,,,,,,,,,,,,,,,,,,,,,,,,,,
,3738595891.42139,2.80212473869324,9999.681640625,2.70284312030464E-7,1.04264768695939E-8,1,10,13.2042255401611,3.98048352829701,32.3400013148785,0.000238105343958887,3.95956106219119E-5,1,4.83736023033638E-9,2.79665303230286,2.80759644508362,9999.681640625,9999.681640625,50.6964257573131,5.51897556020577,2.93768000602722,132,1,0,0,1,0.23162841796875,30.7917900085449,6,1,1,2.79665303230286,0,2.80212473869324,,,,,,,,,,,,,,,,,,,,,,,,,,,,,,,,,
,3738595951.41486,2.77535212039948,9999.681640625,2.82034766423202E-7,1.02931927536389E-8,1,10,13.2042255401611,3.9804545291083,32.3400013148785,0.000249638189453656,3.33125278647825E-5,1,-4.01409032861999E-9,2.77081561088562,2.77988862991333,9999.681640625,9999.681640625,50.6557810743131,5.51911588052075,2.92530632019043,132,1,0,0,1,0.238265991210938,31.2805480957031,6,1,1,2.77081561088562,0,2.77535212039948,,,,,,,,,,,,,,,,,,,,,,,,,,,,,,,,,
,3738596011.41821,2.65773165225983,9999.681640625,2.98205826690242E-7,1.03990776470991E-8,1,10,13.2042255401611,3.98042435019019,32.3499999940395,0.000264098217335576,3.42104138782267E-5,1,-5.38969557312085E-9,2.64979529380798,2.66566801071167,9999.681640625,9999.681640625,50.6901727291592,5.51915182167187,2.86425113677979,132,1,0,0,1,0.238418579101562,31.2805480957031,6,1,1,2.64979529380798,0,2.65773165225983,,,,,,,,,,,,,,,,,,,,,,,,,,,,,,,,,
,3738596071.35523,2.72125792503357,9999.681640625,2.79649494209946E-7,1.12601432505945E-8,1,10,13.2042255401611,3.9803624095294,32.3400013148785,0.00024664024067391,3.89604216775614E-5,1,2.73473986078609E-9,2.71538734436035,2.72712850570679,9999.681640625,9999.681640625,50.6342862900342,5.51877379780593,2.90083980560303,132,1,0,0,1,0.239105224609375,33.7243423461914,6,1,1,2.71538734436035,0,2.72125792503357,,,,,,,,,,,,,,,,,,,,,,,,,,,,,,,,,
,3738596131.3453,2.2354542016983,9999.681640625,3.17812946876887E-7,1.08614503466877E-8,1,10,13.2042255401611,3.98041610887528,32.3400013148785,0.000280449297323726,4.33030078583636E-5,1,2.00379316987414E-9,2.17772221565247,2.29318618774414,9999.681640625,9999.681640625,50.613182320015,5.51856637024026,2.61576581001282,132,1,0,0,1,0.23895263671875,31.2805480957031,6,1,1,2.17772221565247,0,2.2354542016983,,,,,,,,,,,,,,,,,,,,,,,,,,,,,,,,,
,3738596191.34982,1.99895465373993,9999.681640625,3.52106893050713E-7,1.7725311889031E-8,1,10,13.2042255401611,3.98045029258527,32.3400013148785,0.000310210837160816,5.13888511663772E-5,1,6.08352499713734E-9,1.99862539768219,1.99928390979767,9999.681640625,9999.681640625,50.7128399562169,5.51752111013128,2.48767566680908,132,1,0,0,1,0.239944458007813,30.3030319213867,5,1,1,1.99862539768219,0,1.99895465373993,,,,,,,,,,,,,,,,,,,,,,,,,,,,,,,,,
,3738596221.30868,1.99966681003571,9999.681640625,3.30257855316081E-7,1.08786854455881E-8,1,10,13.2042255401611,3.98043252424412,32.3400013148785,0.000291623455895616,4.37120085523872E-5,1,6.25216085915221E-10,1.9993109703064,2.00002264976501,9999.681640625,9999.681640625,50.6835288867457,5.51840691937504,2.484041929245,132,1,0,0,1,0.231781005859375,31.2805480957031,1,1,1,2.00002264976501,0,1.99966681003571,,,,,,,,,,,,,,,,,,,,,,,,,,,,,,,,,