File: data/brass-holder/180611_MT_brass-empty-powder-container_0.1T.dat
[Header]
; MPMS3 Data File (default extension .dat)
; Copyright (c) 2007, Quantum Design, Inc. All rights reserved.
TITLE,
FILEOPENTIME,3737893160.926,06/11/2018,4:42 pm
BYAPP,MPMS3,1.0,1.1
INFO,MPMS3 Measurement Release 1.1.16 Build 388, MultiVu Release 2.3.4.15,APPNAME
INFO,0,MOMENT_UNITS
INFO,empty brass,SAMPLE_MATERIAL
INFO,,SAMPLE_COMMENT
INFO,1,SAMPLE_MASS
INFO,,SAMPLE_VOLUME
INFO,,SAMPLE_MOLECULAR_WEIGHT
INFO,,SAMPLE_SIZE
INFO,,SAMPLE_SHAPE
INFO,Brass,SAMPLE_HOLDER
INFO,Standard,SAMPLE_HOLDER_DETAIL
INFO,65.32,SAMPLE_OFFSET
DATATYPE,COMMENT,1
DATATYPE,TIME,2
STARTUPAXIS,X,2
STARTUPAXIS,Y1,5
FIELDGROUP, VSM,2,3,4,5,6,8,9,10,11,14,15
FIELDGROUP, DC, 2,3,4,14,34,35,36,37,38,39,40,41,42,43,44,45,46,47
STARTUPGROUP, All
[Data]
Comment,Time Stamp (sec),Temperature (K),Magnetic Field (Oe),Moment (emu),M. Std. Err. (emu),Transport Action,Averaging Time (sec),Frequency (Hz),Peak Amplitude (mm),Center Position (mm),Lockin Signal' (V),Lockin Signal (V),Range,M. Quad. Signal (emu),Min. Temperature (K),Max. Temperature (K),Min. Field (Oe),Max. Field (Oe),Mass (grams),Motor Lag (deg),Pressure (Torr),Measure Count,Measurement Number,SQUID Status (code),Motor Status (code),Measure Status (code),Motor Current (amps),Motor Temp. (C),Temp. Status (code),Field Status (code),Chamber Status (code),Chamber Temp (K),Redirection State,Average Temp (K),Rotation Angle (deg),Rotator state,DC Moment Fixed Ctr (emu),DC Moment Err Fixed Ctr (emu),DC Moment Free Ctr (emu),DC Moment Err Free Ctr (emu),DC Fixed Fit,DC Free Fit,DC Calculated Center (mm),DC Calculated Center Err (mm),DC Scan Length (mm),DC Scan Time (s),DC Number of Points,DC Squid Drift,DC Min V (V),DC Max V (V),DC Scans per Measure,Map 01,Map 02,Map 03,Map 04,Map 05,Map 06,Map 07,Map 08,Map 09,Map 10,Map 11,Map 12,Map 13,Map 14,Map 15,Map 16
,3737895484.52047,2.07373857498169,999.640686035156,-1.28609819247198E-6,7.24687786084417E-9,1,5,14.0008964538574,3.98006075406015,30.009999871254,-0.00113150437395989,-0.000196675175372896,10,-2.86430007638295E-8,2.00833964347839,2.13913750648499,999.640686035156,999.640686035156,50.1656999927553,5.78719602330293,1.7241622209549,70,1,0,0,1,0.261611938476562,27.8592376708984,6,1,1,2.13913750648499,0,2.07373857498169,,,,,,,,,,,,,,,,,,,,,,,,,,,,,,,,,
,3737895623.82664,8.12171697616577,999.640686035156,1.18536288441729E-7,6.78961356563038E-9,1,5,14.0008964538574,3.98000853409557,30.009999871254,0.000107122607116486,-6.66257328532354E-7,1,-1.86492061830485E-8,8.00869846343994,8.2347354888916,999.640686035156,999.640686035156,50.1911029196303,5.78787981583299,3.01829624176025,70,1,0,0,1,0.26092529296875,27.8592376708984,6,1,1,8.2347354888916,0,8.12171697616577,,,,,,,,,,,,,,,,,,,,,,,,,,,,,,,,,
,3737895753.66936,14.2633514404297,999.640686035156,4.76982990278033E-7,6.81838621851303E-9,1,5,14.0008964538574,3.97989077509643,30.009999871254,0.000425006091666435,3.72533327776511E-5,1,-2.98025516819017E-8,14.1443738937378,14.3823289871216,999.640686035156,999.640686035156,50.3556357229284,5.78871706276835,3.51051497459412,70,1,0,0,1,0.260848999023438,27.8592376708984,6,1,1,14.3823289871216,0,14.2633514404297,,,,,,,,,,,,,,,,,,,,,,,,,,,,,,,,,
,3737895883.68259,20.5332708358765,999.640686035156,6.38797038302105E-7,6.64587628338664E-9,1,5,14.0008964538574,3.97979785227196,30.009999871254,0.000567919003046726,5.81498188248791E-5,1,-3.05545647103073E-8,20.4057922363281,20.6607494354248,999.640686035156,999.640686035156,50.2024365331592,5.78892944619737,3.7360508441925,70,1,0,0,1,0.261459350585938,27.8592376708984,2,1,1,20.66969871521,0,20.5332708358765,,,,,,,,,,,,,,,,,,,,,,,,,,,,,,,,,
,3737896014.03971,26.9203634262085,999.640686035156,7.42938191983485E-7,7.50930887658841E-9,1,5,14.0008964538574,3.97971670476596,30.009999871254,0.000658489180828675,8.08390025742657E-5,1,-2.05677723900381E-8,26.8171977996826,27.0235290527344,999.640686035156,999.640686035156,50.2399547020822,5.79006523522637,3.88194704055786,70,1,0,0,1,0.265655517578125,27.8592376708984,2,1,1,27.0235290527344,0,26.9203634262085,,,,,,,,,,,,,,,,,,,,,,,,,,,,,,,,,
,3737896143.66882,33.21506690979,999.640686035156,7.95192011055723E-7,7.04141480613918E-9,1,5,14.0008964538574,3.97967952812289,30.009999871254,0.000705080917281993,8.46151518651657E-5,1,-2.41764378502938E-8,33.0972061157227,33.3329277038574,999.640686035156,999.640686035156,50.218850732063,5.7902307755259,3.99440693855286,70,1,0,0,1,0.262069702148438,27.8592376708984,2,1,1,33.3329277038574,0,33.21506690979,,,,,,,,,,,,,,,,,,,,,,,,,,,,,,,,,
,3737896273.78201,39.5713214874268,999.640686035156,8.38192689709654E-7,7.29711116966024E-9,1,5,14.0008964538574,3.97972358955499,30.0200004130602,0.000742623828327789,9.31542113962412E-5,1,-2.09951917634135E-8,39.4344635009766,39.708179473877,999.640686035156,999.640686035156,50.1449868369957,5.78971578129399,4.0816125869751,70,1,0,0,1,0.26214599609375,27.8592376708984,2,1,1,39.708179473877,0,39.5713214874268,,,,,,,,,,,,,,,,,,,,,,,,,,,,,,,,,
,3737896403.63957,45.9180870056152,999.640686035156,8.52109479353439E-7,7.50301241245264E-9,1,5,14.0008964538574,3.97975850774661,30.0200004130602,0.000755583961373389,9.05984129356812E-5,1,-2.59931490477432E-8,45.8040466308594,46.0321273803711,999.640686035156,999.640686035156,50.2122068896495,5.79014824933313,4.15320444107056,70,1,0,0,1,0.262298583984375,27.8592376708984,2,1,1,46.0321273803711,0,45.9180870056152,,,,,,,,,,,,,,,,,,,,,,,,,,,,,,,,,
,3737896533.56669,52.2608337402344,999.640686035156,8.61692573272234E-7,7.67002285463429E-9,1,5,14.0008964538574,3.97974364380769,30.0200004130602,0.000764007183649865,9.20788243981153E-5,1,-2.57619856846773E-8,52.1305961608887,52.3910713195801,999.640686035156,999.640686035156,50.3783029499861,5.79035150931389,4.22227048873901,70,1,0,0,1,0.259246826171875,27.8592376708984,2,1,1,52.3910713195801,0,52.2608337402344,,,,,,,,,,,,,,,,,,,,,,,,,,,,,,,,,
,3737896664.044,58.6805667877197,999.640686035156,8.78553892227262E-7,9.10042241183582E-9,1,5,14.0008964538574,3.97971216260741,30.0299990922213,0.000778874979070949,9.43576610262414E-5,1,-2.57242417787967E-8,58.55029296875,58.8108406066895,999.640686035156,999.640686035156,50.1758611635053,5.79105342214407,4.26705455780029,70,1,0,0,1,0.262527465820313,27.8592376708984,2,1,1,58.8209419250488,0,58.6805667877197,,,,,,,,,,,,,,,,,,,,,,,,,,,,,,,,,
,3737896793.53703,65.037052154541,999.640686035156,8.85885908849084E-7,8.07329345186343E-9,1,5,14.0008964538574,3.97961446474878,30.0299990922213,0.00078535904576146,9.50437259958154E-5,1,-2.60495836307602E-8,64.9260559082031,65.1480484008789,999.640686035156,999.640686035156,50.3224165108611,5.79140438189402,4.30606985092163,70,1,0,0,1,0.257720947265625,27.8592376708984,2,1,1,65.1480484008789,0,65.037052154541,,,,,,,,,,,,,,,,,,,,,,,,,,,,,,,,,
,3737896923.581,71.4623146057129,999.640686035156,8.90383161284182E-7,5.88626363886225E-9,1,5,14.0008964538574,3.9795570104532,30.0399996340275,0.000789980922762944,9.11972841789492E-5,1,-3.10841632393117E-8,71.3466796875,71.5779495239258,999.640686035156,999.640686035156,50.2114252611303,5.79144687742597,4.33870506286621,70,1,0,0,1,0.264511108398438,27.8592376708984,2,1,1,71.5779495239258,0,71.4623146057129,,,,,,,,,,,,,,,,,,,,,,,,,,,,,,,,,
,3737897053.90074,77.8692054748535,999.640686035156,8.76391011966983E-7,6.20926437359857E-9,1,5,14.0008964538574,3.97949916934558,30.0399996340275,0.000778064730737672,8.6342471547325E-5,1,-3.44702808250426E-8,77.7696990966797,77.9687118530273,999.640686035156,999.640686035156,50.2634035576592,5.79153651809349,4.37259769439697,70,1,0,0,1,0.261764526367187,27.8592376708984,2,1,1,77.9687118530273,0,77.8692054748535,,,,,,,,,,,,,,,,,,,,,,,,,,,,,,,,,
,3737897183.54321,84.2814788818359,999.640686035156,8.7504184788004E-7,6.79104151683132E-9,1,5,14.0008964538574,3.97947568419953,30.0500001758337,0.000775402508649566,9.58608371822801E-5,1,-2.34806962186748E-8,84.1628646850586,84.4000930786133,999.640686035156,999.640686035156,50.188367219813,5.79265895984906,4.39632940292358,70,1,0,0,1,0.262451171875,27.8592376708984,2,1,1,84.4000930786133,0,84.2814788818359,,,,,,,,,,,,,,,,,,,,,,,,,,,,,,,,,
,3737897313.6004,90.7561264038086,999.640686035156,8.71433640132885E-7,6.87976273152753E-9,1,5,14.0008964538574,3.97944299697572,30.0500001758337,0.000772592210804298,9.28332463188865E-5,1,-2.63650907154505E-8,90.6323852539063,90.8798675537109,999.640686035156,999.640686035156,50.2305751598515,5.79233924092803,4.42201375961304,70,1,0,0,1,0.262832641601562,27.8592376708984,2,1,1,90.8798675537109,0,90.7561264038086,,,,,,,,,,,,,,,,,,,,,,,,,,,,,,,,,
,3737897443.49258,97.2100982666016,999.640686035156,8.56887228533001E-7,7.212599565149E-9,1,5,14.0008964538574,3.97937115620979,30.0600007176399,0.000760567516598155,8.53607572384712E-5,1,-3.26333232063615E-8,97.0885009765625,97.3316955566406,999.640686035156,999.640686035156,50.3681417792361,5.79204047093796,4.43812036514282,70,1,0,0,1,0.259628295898438,27.8592376708984,2,1,1,97.3316955566406,0,97.2100982666016,,,,,,,,,,,,,,,,,,,,,,,,,,,,,,,,,
,3737897573.50613,103.657440185547,999.640686035156,8.66325989056802E-7,5.84680761570439E-9,1,5,14.0008964538574,3.97937487845708,30.0799999386072,0.000767847061915151,9.35836992850869E-5,1,-2.47408009096053E-8,103.541198730469,103.773681640625,999.640686035156,999.640686035156,50.0265701163322,5.79195653779184,4.45941591262817,70,1,0,0,1,0.267257690429687,27.8592376708984,2,1,1,103.791854858398,0,103.657440185547,,,,,,,,,,,,,,,,,,,,,,,,,,,,,,,,,
,3737897704.14708,110.189487457275,999.640686035156,8.57344977688798E-7,6.28442790812453E-9,1,5,14.0008964538574,3.97936328566303,30.0799999386072,0.000760694253620691,8.72419967862668E-5,1,-3.05704447490181E-8,110.064476013184,110.314498901367,999.640686035156,999.640686035156,50.122319609938,5.79197778182074,4.47950410842895,70,1,0,0,1,0.262451171875,27.8592376708984,2,1,1,110.314498901367,0,110.189487457275,,,,,,,,,,,,,,,,,,,,,,,,,,,,,,,,,
,3737897833.50467,116.623584747314,999.640686035156,8.43809340949472E-7,5.60347248858707E-9,1,5,14.0008964538574,3.97936311212539,30.0900004804134,0.000747622814354948,9.28972527319045E-5,1,-2.21189743986613E-8,116.496971130371,116.750198364258,999.640686035156,999.640686035156,50.3454745521784,5.79253139666526,4.48818302154541,70,1,0,0,1,0.262298583984375,27.8592376708984,2,1,1,116.750198364258,0,116.623584747314,,,,,,,,,,,,,,,,,,,,,,,,,,,,,,,,,
,3737897963.65721,123.100288391113,999.640686035156,8.4665613786713E-7,6.08719979880472E-9,1,5,14.0008964538574,3.97929617325513,30.0999991595745,0.000750215193421287,9.26102457236832E-5,1,-2.28711243242968E-8,122.977058410645,123.223518371582,999.640686035156,999.640686035156,50.1856315199957,5.79286035309154,4.50139856338501,70,1,0,0,1,0.262603759765625,27.8592376708984,2,1,1,123.223518371582,0,123.100288391113,,,,,,,,,,,,,,,,,,,,,,,,,,,,,,,,,
,3737898093.51198,129.574096679688,999.640686035156,8.35332316143903E-7,5.82268738502271E-9,1,5,14.0008964538574,3.97932613372523,30.1099997013807,0.000740211216693477,9.12331858400388E-5,1,-2.27233240528591E-8,129.450942993164,129.697250366211,999.640686035156,999.640686035156,50.2110344468707,5.79241892418303,4.52088594436646,70,1,0,0,1,0.262985229492187,27.8592376708984,2,1,1,129.697250366211,0,129.574096679688,,,,,,,,,,,,,,,,,,,,,,,,,,,,,,,,,
,3737898223.41605,136.038619995117,999.640686035156,8.23080529647797E-7,5.64887808338028E-9,1,5,14.0008964538574,3.97948470571605,30.120000243187,0.000730280807722491,8.40729645041159E-5,1,-2.89933710927333E-8,135.916519165039,136.160720825195,999.640686035156,999.640686035156,50.4209017042842,5.79067392920004,4.53224992752075,70,1,0,0,1,0.261383056640625,27.8592376708984,2,1,1,136.160720825195,0,136.038619995117,,,,,,,,,,,,,,,,,,,,,,,,,,,,,,,,,
,3737898353.83514,142.541976928711,999.640686035156,8.26077291879655E-7,5.42702154780872E-9,1,5,14.0008964538574,3.97946382669167,30.1300007849932,0.000732325769365185,8.84043983551926E-5,1,-2.45371208338612E-8,142.434234619141,142.649719238281,999.640686035156,999.640686035156,50.2809901993419,5.79135005739234,4.53713893890381,70,1,0,0,1,0.262374877929687,27.8592376708984,2,1,1,142.649719238281,0,142.541976928711,,,,,,,,,,,,,,,,,,,,,,,,,,,,,,,,,
,3737898483.44222,149.024673461914,999.640686035156,8.09804948906972E-7,6.09796033477324E-9,1,5,14.0008964538574,3.97940984210125,30.1399994641542,0.00071730412889894,9.05062999949784E-5,1,-1.96967785985839E-8,148.910675048828,149.138671875,999.640686035156,999.640686035156,50.2837258991592,5.79127276188786,4.55437326431274,70,1,0,0,1,0.26214599609375,27.8592376708984,2,1,1,149.138671875,0,149.024673461914,,,,,,,,,,,,,,,,,,,,,,,,,,,,,,,,,
,3737898613.86508,155.526893615723,999.640686035156,8.00418517168672E-7,5.72982832535594E-9,1,5,14.0008964538574,3.97936266027035,30.1500000059605,0.000709674710264349,8.48300372438438E-5,1,-2.47097462929903E-8,155.412231445313,155.641555786133,999.640686035156,999.640686035156,50.1754703492457,5.79216113620921,4.55779552459717,70,1,0,0,1,0.261993408203125,27.8592376708984,2,1,1,155.669418334961,0,155.526893615723,,,,,,,,,,,,,,,,,,,,,,,,,,,,,,,,,
,3737898743.4256,161.977890014648,999.640686035156,8.03277346076206E-7,1.53190534569692E-8,1,5,14.0008964538574,3.97941119988872,30.1600005477667,0.000712053513329444,8.62595106072367E-5,1,-2.35234568649431E-8,161.850921630859,162.104858398438,999.640686035156,999.640686035156,50.2075171185342,5.79132943549334,4.56884431838989,70,1,0,0,1,0.262680053710938,27.8592376708984,2,1,1,162.104858398438,0,161.977890014648,,,,,,,,,,,,,,,,,,,,,,,,,,,,,,,,,
,3737898873.4157,168.482231140137,999.640686035156,7.92323160448248E-7,6.97171030842328E-9,1,5,14.0008964538574,3.97935415570312,30.1699992269278,0.000701457321258805,9.08437684635191E-5,1,-1.66730078422109E-8,168.362487792969,168.601974487305,999.640686035156,999.640686035156,50.3665785221976,5.79153220926148,4.57712841033936,70,1,0,0,1,0.262832641601562,27.8592376708984,2,1,1,168.601974487305,0,168.482231140137,,,,,,,,,,,,,,,,,,,,,,,,,,,,,,,,,
,3737899003.7775,174.943237304687,999.640686035156,7.70707434042769E-7,6.14224129011155E-9,1,5,14.0008964538574,3.97938055877067,30.179999768734,0.000683490499324897,8.06643036846414E-5,1,-2.49454536716006E-8,174.841934204102,175.044540405273,999.640686035156,999.640686035156,50.4416148600438,5.79136814285427,4.58753967285156,70,1,0,0,1,0.261306762695313,27.8592376708984,2,1,1,175.044540405273,0,174.943237304687,,,,,,,,,,,,,,,,,,,,,,,,,,,,,,,,,
,3737899133.3527,181.428398132324,999.640686035156,7.79749087715433E-7,5.79617598002378E-9,1,5,14.0008964538574,3.97939657519482,30.2000008523464,0.000691184297584848,8.37912254332675E-5,1,-2.27678472519497E-8,181.305328369141,181.551467895508,999.640686035156,999.640686035156,50.2079079327938,5.79085221126963,4.59730958938599,70,1,0,0,1,0.264739990234375,27.8592376708984,2,1,1,181.551467895508,0,181.428398132324,,,,,,,,,,,,,,,,,,,,,,,,,,,,,,,,,
,3737899263.68825,187.908210754395,999.640686035156,7.72011093992507E-7,5.96138131911606E-9,1,5,14.0008964538574,3.97935526017898,30.2099995315075,0.000684527371117214,8.15438377664237E-5,1,-2.41447043674109E-8,187.789352416992,188.027069091797,999.640686035156,999.640686035156,50.2845075276784,5.79175703044855,4.61620283126831,70,1,0,0,1,0.264663696289062,27.8592376708984,2,1,1,188.027069091797,0,187.908210754395,,,,,,,,,,,,,,,,,,,,,,,,,,,,,,,,,
,3737899393.2946,194.378715515137,999.640686035156,7.72729250961138E-7,5.7487509106142E-9,1,5,14.0008964538574,3.97930588835379,30.2300006151199,0.000685091977392979,8.20061259506072E-5,1,-2.37274447259247E-8,194.243087768555,194.514343261719,999.640686035156,999.640686035156,50.3779121357265,5.79226648247658,4.63106966018677,70,1,0,0,1,0.261154174804687,27.8592376708984,2,1,1,194.514343261719,0,194.378715515137,,,,,,,,,,,,,,,,,,,,,,,,,,,,,,,,,
,3737899523.27729,200.845611572266,999.640686035156,7.67196252886258E-7,8.35254425139595E-9,1,5,14.0008964538574,3.97926797750994,30.239999294281,0.000680326979653777,8.04184551200909E-5,1,-2.46898530073528E-8,200.730255126953,200.960968017578,999.640686035156,999.640686035156,50.2805993850822,5.79120518620694,4.64840698242188,70,1,0,0,1,0.26275634765625,27.8592376708984,2,1,1,200.960968017578,0,200.845611572266,,,,,,,,,,,,,,,,,,,,,,,,,,,,,,,,,
,3737899653.53415,207.34969329834,999.640686035156,7.64733352410183E-7,9.24183179392189E-9,1,5,14.0008964538574,3.97924408969645,30.2600003778934,0.000679348454667121,7.21309341453926E-5,1,-3.37084026879538E-8,207.232131958008,207.467254638672,999.640686035156,999.640686035156,50.2505066870919,5.79233863028023,4.66757011413574,70,1,0,0,1,0.262680053710938,27.8592376708984,2,1,1,207.467254638672,0,207.34969329834,,,,,,,,,,,,,,,,,,,,,,,,,,,,,,,,,
,3737899783.68062,213.84489440918,999.640686035156,7.57011707777064E-7,6.00199886815134E-9,1,5,14.0008964538574,3.97924169436814,30.2700009196997,0.000670798284185212,8.25975968629192E-5,1,-2.06820580181128E-8,213.742599487305,213.947189331055,999.640686035156,999.640686035156,50.0609617711784,5.79264491281963,4.69507694244385,69,1,64,0,0,0.264892578125,27.8592376708984,2,1,1,213.947189331055,0,213.84489440918,,,,,,,,,,,,,,,,,,,,,,,,,,,,,,,,,
,3737899913.55194,220.342552185059,999.640686035156,7.56066193445103E-7,5.4568629779332E-9,1,5,14.0008964538574,3.97928044246682,30.290000140667,0.000670648142727546,7.80093951056313E-5,1,-2.57399470951453E-8,220.236099243164,220.449005126953,999.640686035156,999.640686035156,50.3294511675342,5.79236230677205,4.72078466415405,69,1,64,0,0,0.262985229492187,27.8592376708984,2,1,1,220.449005126953,0,220.342552185059,,,,,,,,,,,,,,,,,,,,,,,,,,,,,,,,,
,3737900043.63116,226.819686889648,999.640686035156,7.59287588896227E-7,5.87606641789875E-9,1,5,14.0008964538574,3.97929817922082,30.3099993616343,0.000672959628597757,8.19907036367258E-5,1,-2.1715455391992E-8,226.69987487793,226.939498901367,999.640686035156,999.640686035156,50.2262762029957,5.79188654444017,4.75572538375854,70,1,0,0,1,0.261993408203125,27.8592376708984,2,1,1,226.939498901367,0,226.819686889648,,,,,,,,,,,,,,,,,,,,,,,,,,,,,,,,,
,3737900173.2536,233.32413482666,999.640686035156,7.3851879085994E-7,5.7447824078793E-9,1,5,14.0008964538574,3.97930436861348,30.3199999034405,0.000655431859511361,7.39316897124791E-5,1,-2.77124593895688E-8,233.209533691406,233.438735961914,999.640686035156,999.640686035156,50.3861192351784,5.79116627718395,4.8090615272522,70,1,0,0,1,0.263290405273438,27.8592376708984,2,1,1,233.438735961914,0,233.32413482666,,,,,,,,,,,,,,,,,,,,,,,,,,,,,,,,,
,3737900303.2569,239.778923034668,999.640686035156,7.46402713981999E-7,5.39732835149403E-9,1,5,14.0008964538574,3.9793967062192,30.3399991244078,0.000661250597203209,8.26911358709281E-5,1,-1.89803436698867E-8,239.647232055664,239.910614013672,999.640686035156,999.640686035156,50.3529000231111,5.79185737651229,4.89501857757568,70,1,0,0,1,0.260543823242187,27.8592376708984,2,1,1,239.910614013672,0,239.778923034668,,,,,,,,,,,,,,,,,,,,,,,,,,,,,,,,,
,3737900434.05107,246.289878845215,999.640686035156,7.42303591891626E-7,6.48328167419192E-9,1,5,14.0008964538574,3.97926462412363,30.3600002080202,0.000657723747007744,8.13084285039162E-5,1,-1.99234005058423E-8,246.201919555664,246.377838134766,999.640686035156,999.640686035156,50.2344833024476,5.79205588787654,4.9865140914917,69,1,64,0,0,0.262985229492187,27.8592376708984,2,1,1,246.421173095703,0,246.289878845215,,,,,,,,,,,,,,,,,,,,,,,,,,,,,,,,,
,3737900563.21042,252.754386901855,999.640686035156,7.48975846317917E-7,5.69306049352823E-9,1,5,14.0008964538574,3.97928000966277,30.3799994289875,0.000663002812814849,8.62596432165208E-5,1,-1.53207038453914E-8,252.629379272461,252.87939453125,999.640686035156,999.640686035156,50.1043421539957,5.79257298782284,7.79372978210449,70,1,0,0,1,0.26153564453125,27.8592376708984,2,1,1,252.87939453125,0,252.754386901855,,,,,,,,,,,,,,,,,,,,,,,,,,,,,,,,,
,3737900693.38786,259.225860595703,999.640686035156,7.37611605105851E-7,6.56417289002354E-9,1,5,14.0008964538574,3.97921928282088,30.4000005125999,0.000653625675015502,8.03213572411259E-5,1,-2.03319491303971E-8,259.104797363281,259.346923828125,999.640686035156,999.640686035156,50.3529000231111,5.79238909736633,7.89985847473145,70,1,0,0,1,0.262374877929687,27.8592376708984,2,1,1,259.346923828125,0,259.225860595703,,,,,,,,,,,,,,,,,,,,,,,,,,,,,,,,,
,3737900823.18468,265.692535400391,999.640686035156,7.25671916492503E-7,6.15015695998929E-9,1,5,14.0008964538574,3.9792837111733,30.409999191761,0.000642726032121598,8.12494669928818E-5,1,-1.74801722065317E-8,265.562438964844,265.822631835938,999.640686035156,999.640686035156,50.289978927313,5.79275822091216,7.77202749252319,70,1,0,0,1,0.263442993164062,27.8592376708984,2,1,1,265.822631835938,0,265.692535400391,,,,,,,,,,,,,,,,,,,,,,,,,,,,,,,,,
,3737900953.14617,272.212814331055,999.640686035156,7.23532508188511E-7,6.07015929840813E-9,1,5,14.0008964538574,3.9793148548701,30.4300002753735,0.000642567995853568,6.95589348013404E-5,1,-3.04054205692821E-8,272.095123291016,272.330505371094,999.640686035156,999.640686035156,50.4001885485246,5.79207654999155,7.83711194992065,70,1,0,0,1,0.259170532226562,27.8592376708984,2,1,1,272.330505371094,0,272.212814331055,,,,,,,,,,,,,,,,,,,,,,,,,,,,,,,,,
,3737901083.55722,278.702819824219,999.640686035156,7.37448502172316E-7,7.0945154701493E-9,1,5,14.0008964538574,3.97925957176475,30.460000038147,0.000653677645421484,7.90732895778068E-5,1,-2.1723072696927E-8,278.578948974609,278.826690673828,999.640686035156,999.640686035156,50.2266670172553,5.79239322220217,7.99896097183228,70,1,0,0,1,0.260696411132813,27.8592376708984,2,1,1,278.826690673828,0,278.702819824219,,,,,,,,,,,,,,,,,,,,,,,,,,,,,,,,,
,3737901213.68615,285.229888916016,999.640686035156,7.35818251967995E-7,6.83794472150044E-9,1,5,14.0008964538574,3.97925657534135,30.4799992591143,0.000651899489729309,8.10996725619101E-5,1,-1.91806203058226E-8,285.125518798828,285.334259033203,999.640686035156,999.640686035156,50.3829927211015,5.79189986228124,8.38616561889648,68,1,64,0,0,0.260391235351562,27.8592376708984,2,1,1,285.334259033203,0,285.229888916016,,,,,,,,,,,,,,,,,,,,,,,,,,,,,,,,,
,3737901343.1302,291.651718139648,999.640686035156,7.20971181569159E-7,5.9938225775395E-9,1,5,14.0008964538574,3.97932774074962,30.4899998009205,0.000638951610350831,7.82225262944954E-5,1,-2.02021135276627E-8,291.529235839844,291.774200439453,999.640686035156,999.640686035156,50.2172874750245,5.79196672426164,9.01359462738037,70,1,0,0,1,0.262680053710938,27.8592376708984,2,1,1,291.774200439453,0,291.651718139648,,,,,,,,,,,,,,,,,,,,,,,,,,,,,,,,,
,3737901473.52345,298.132904052734,999.640686035156,7.20021138093649E-7,5.929092622889E-9,1,5,14.0008964538574,3.97935937075464,30.519999563694,0.000637731089085757,8.0681786796678E-5,1,-1.72731711235428E-8,298.014862060547,298.250946044922,999.640686035156,999.640686035156,50.4107405335342,5.79149008915069,9.04272079467773,70,1,0,0,1,0.259628295898438,27.8592376708984,2,1,1,298.250946044922,0,298.132904052734,,,,,,,,,,,,,,,,,,,,,,,,,,,,,,,,,
,3737901603.16101,304.622589111328,999.640686035156,7.1120551711335E-7,6.50898745215862E-9,1,5,14.0008964538574,3.97929865584982,30.5400006473064,0.000630375526953724,7.65925563828744E-5,1,-2.05738396130391E-8,304.508636474609,304.736541748047,999.640686035156,999.640686035156,50.1621826644188,5.79181813275551,8.85153007507324,69,1,64,0,0,0.262451171875,27.8592376708984,2,1,1,304.736541748047,0,304.622589111328,,,,,,,,,,,,,,,,,,,,,,,,,,,,,,,,,
,3737901733.0733,311.105484008789,999.640686035156,7.05101420388833E-7,5.96529677361889E-9,1,5,14.0008964538574,3.97942843670794,30.5599998682737,0.000625236185728855,7.43597356094754E-5,1,-2.21868725683606E-8,310.97900390625,311.231964111328,999.640686035156,999.640686035156,50.305220683438,5.79064654031158,8.73886013031006,70,1,0,0,1,0.261077880859375,27.8592376708984,2,1,1,311.231964111328,0,311.105484008789,,,,,,,,,,,,,,,,,,,,,,,,,,,,,,,,,
,3737901863.41381,317.587036132812,999.640686035156,7.04679312969516E-7,5.7920380202461E-9,1,5,14.0008964538574,3.9793878650544,30.5899996310473,0.000624407395876114,7.7257204148505E-5,1,-1.88386222610447E-8,317.483673095703,317.690399169922,999.640686035156,999.640686035156,50.3294511675342,5.79172494052735,8.67298603057861,70,1,0,0,1,0.263900756835938,27.8592376708984,2,1,1,317.690399169922,0,317.587036132812,,,,,,,,,,,,,,,,,,,,,,,,,,,,,,,,,
,3737901993.05817,324.05615234375,999.640686035156,6.96133774124086E-7,6.81673461731144E-9,1,5,14.0008964538574,3.97925729850926,30.6100007146597,0.000616838527987162,7.6080642141548E-5,1,-1.88772266995006E-8,323.920318603516,324.191986083984,999.640686035156,999.640686035156,50.4666269726592,5.79261478765794,8.57330703735352,70,1,0,0,1,0.263900756835938,27.8592376708984,2,1,1,324.191986083984,0,324.05615234375,,,,,,,,,,,,,,,,,,,,,,,,,,,,,,,,,
,3737902123.27982,330.552017211914,999.640686035156,6.82503654908927E-7,6.11167019916987E-9,1,5,14.0008964538574,3.97924931612007,30.629999935627,0.000604705172109532,7.49476606151807E-5,1,-1.81031889192583E-8,330.416687011719,330.687347412109,999.640686035156,999.640686035156,50.4240282183611,5.79199198290522,8.53698539733887,70,1,0,0,1,0.261383056640625,27.8592376708984,2,1,1,330.687347412109,0,330.552017211914,,,,,,,,,,,,,,,,,,,,,,,,,,,,,,,,,
,3737902253.02209,337.028259277344,999.640686035156,6.61050894375653E-7,6.78543623897513E-9,1,5,14.0008964538574,3.97937591495702,30.6400004774332,0.000587252509660173,6.2494237575157E-5,1,-2.89801458588334E-8,336.899169921875,337.157348632812,999.640686035156,999.640686035156,50.2551964582072,5.78999433257685,8.52479457855225,70,1,0,0,1,0.265350341796875,27.8592376708984,2,1,1,337.157348632812,0,337.028259277344,,,,,,,,,,,,,,,,,,,,,,,,,,,,,,,,,
,3737902382.98955,343.517776489258,999.640686035156,6.52879926774187E-7,6.28201424280853E-9,1,5,14.0008964538574,3.97929684838807,30.6599996984005,0.000579095281007976,6.75493019087471E-5,1,-2.20162316199376E-8,343.398773193359,343.636779785156,999.640686035156,999.640686035156,50.3571989799669,5.79071101404371,8.4779167175293,70,1,0,0,1,0.259246826171875,27.8592376708984,2,1,1,343.636779785156,0,343.517776489258,,,,,,,,,,,,,,,,,,,,,,,,,,,,,,,,,
,3737902513.39835,349.517349243164,999.640686035156,6.43639971249979E-7,6.37458602593651E-9,1,5,14.0008964538574,3.97928375121162,30.6800007820129,0.00057077288340331,6.74122578153292E-5,1,-2.07762413954325E-8,349.478332519531,349.556365966797,999.640686035156,999.640686035156,50.2614494863611,5.79011034604014,8.40402412414551,70,1,0,0,1,0.263748168945313,27.8592376708984,6,1,1,349.556365966797,0,349.517349243164,,,,,,,,,,,,,,,,,,,,,,,,,,,,,,,,,
,3737902708.32523,347.945816040039,999.640686035156,6.55914281802446E-7,6.01133188738226E-9,1,5,14.0008964538574,3.97926347789442,30.6800007820129,0.000581100265149167,7.23578253776427E-5,1,-1.70244115009044E-8,347.838714599609,348.052917480469,999.640686035156,999.640686035156,50.3267154677169,5.79104268253246,8.33013534545898,70,1,0,0,1,0.263519287109375,27.8592376708984,2,1,1,347.838714599609,0,347.945816040039,,,,,,,,,,,,,,,,,,,,,,,,,,,,,,,,,
,3737902838.06696,341.226974487305,999.640686035156,6.52399504364288E-7,6.6541725842347E-9,1,5,14.0008964538574,3.97939902840216,30.6599996984005,0.000578527610256802,6.85973156502628E-5,1,-2.07593368170746E-8,341.090454101562,341.363494873047,999.640686035156,999.640686035156,50.4205108900246,5.79086027417745,8.29231071472168,70,1,0,0,1,0.260391235351562,27.8592376708984,2,1,1,341.090454101562,0,341.226974487305,,,,,,,,,,,,,,,,,,,,,,,,,,,,,,,,,
,3737902968.67073,334.657287597656,999.640686035156,6.47070993621032E-7,6.32802717979815E-9,1,5,14.0008964538574,3.97936268230156,30.6400004774332,0.000574301365048594,6.46756620409665E-5,1,-2.43975163391748E-8,334.543090820313,334.771484375,999.640686035156,999.640686035156,50.2622311148803,5.79029313512714,8.26566982269287,69,1,64,0,0,0.263900756835938,27.8592376708984,2,1,1,334.543090820313,0,334.657287597656,,,,,,,,,,,,,,,,,,,,,,,,,,,,,,,,,
,3737903097.94638,328.210479736328,999.640686035156,6.62967585326009E-7,5.85227483650802E-9,1,5,14.0008964538574,3.97928168892873,30.629999935627,0.000588000482544942,6.8849795110507E-5,1,-2.20649497906123E-8,328.087188720703,328.333770751953,999.640686035156,999.640686035156,50.2700474000726,5.79134862999841,8.26558971405029,70,1,0,0,1,0.262603759765625,27.8592376708984,2,1,1,328.087188720703,0,328.210479736328,,,,,,,,,,,,,,,,,,,,,,,,,,,,,,,,,
,3737903228.05293,321.706130981445,999.640686035156,6.61533763123097E-7,6.62961317442393E-9,1,5,14.0008964538574,3.97926038897443,30.6000001728535,0.000585894446589107,7.41939272381E-5,1,-1.57920219804169E-8,321.586456298828,321.825805664063,999.640686035156,999.640686035156,50.2770820567457,5.79111447804976,8.25557994842529,70,1,0,0,1,0.262680053710938,27.8592376708984,2,1,1,321.586456298828,0,321.706130981445,,,,,,,,,,,,,,,,,,,,,,,,,,,,,,,,,
,3737903357.90724,315.227615356445,999.640686035156,6.81100667927183E-7,7.0044809062033E-9,1,5,14.0008964538574,3.97928691011049,30.6000001728535,0.000603215597019664,7.64880532343792E-5,1,-1.61471666470301E-8,315.100128173828,315.355102539063,999.640686035156,999.640686035156,50.3423480381015,5.79103520633416,8.23361492156982,70,1,0,0,1,0.262603759765625,27.8592376708984,2,1,1,315.100128173828,0,315.227615356445,,,,,,,,,,,,,,,,,,,,,,,,,,,,,,,,,
,3737903487.95458,308.739212036133,999.640686035156,6.79764639538599E-7,6.56903100035334E-9,1,5,14.0008964538574,3.97923370112519,30.579999089241,0.000600838004655634,8.41626889472477E-5,1,-7.24686790790298E-9,308.598480224609,308.879943847656,999.640686035156,999.640686035156,50.3454745521784,5.79212261827488,8.18492412567139,68,1,64,0,0,0.261154174804687,27.8592376708984,2,1,1,308.598480224609,0,308.739212036133,,,,,,,,,,,,,,,,,,,,,,,,,,,,,,,,,
,3737903618.19923,302.251373291016,999.640686035156,6.85763684733726E-7,6.64452091320639E-9,1,5,14.0008964538574,3.97918222804775,30.5599998682737,0.000607169934869613,7.80015376633703E-5,1,-1.51323707447559E-8,302.138397216797,302.364349365234,999.640686035156,999.640686035156,50.2805993850822,5.79080290453784,8.11845779418945,70,1,0,0,1,0.2642822265625,27.8592376708984,2,1,1,302.138397216797,0,302.251373291016,,,,,,,,,,,,,,,,,,,,,,,,,,,,,,,,,
,3737903747.9151,295.733276367188,999.640686035156,7.00113893745271E-7,6.81072324143373E-9,1,5,14.0008964538574,3.97928575558309,30.5400006473064,0.000620839039385532,7.34252088092937E-5,1,-2.24880838036807E-8,295.614715576172,295.851837158203,999.640686035156,999.640686035156,50.3419572238419,5.79172181323722,8.09586906433105,70,1,0,0,1,0.2606201171875,27.8592376708984,2,1,1,295.614715576172,0,295.733276367188,,,,,,,,,,,,,,,,,,,,,,,,,,,,,,,,,
,3737903878.01322,289.233139038086,999.640686035156,7.00454076090163E-7,7.01848923728303E-9,1,5,14.0008964538574,3.97929873061248,30.519999563694,0.000621575033070058,7.06056248379003E-5,1,-2.57348895394028E-8,289.119201660156,289.347076416016,999.640686035156,999.640686035156,50.1602285931207,5.79036580678692,8.03364944458008,70,1,0,0,1,0.263595581054687,27.8592376708984,2,1,1,289.119201660156,0,289.233139038086,,,,,,,,,,,,,,,,,,,,,,,,,,,,,,,,,
,3737904008.26382,282.713394165039,999.640686035156,7.28290066161961E-7,6.50029871195766E-9,1,5,14.0008964538574,3.97923924686774,30.519999563694,0.000645339102946801,7.9516113916409E-5,1,-1.98379678564891E-8,282.614624023438,282.812164306641,999.640686035156,999.640686035156,50.2751279854476,5.79103881717404,7.95047903060913,70,1,0,0,1,0.263824462890625,27.8592376708984,2,1,1,282.614624023438,0,282.713394165039,,,,,,,,,,,,,,,,,,,,,,,,,,,,,,,,,
,3737904137.87959,276.284408569336,999.640686035156,7.31321416411702E-7,6.03839987146597E-9,1,5,14.0008964538574,3.97926106179532,30.5000003427267,0.000647547141161063,8.30520733624527E-5,1,-1.62895350149122E-8,276.165954589844,276.402862548828,999.640686035156,999.640686035156,50.1445960227361,5.79168627936997,7.89615678787231,70,1,0,0,1,0.261917114257813,27.8592376708984,2,1,1,276.165954589844,0,276.284408569336,,,,,,,,,,,,,,,,,,,,,,,,,,,,,,,,,
,3737904268.43607,269.751037597656,999.640686035156,7.35481676600038E-7,6.78500126406223E-9,1,5,14.0008964538574,3.97928693673784,30.4799992591143,0.000652363765929344,7.60654899799816E-5,1,-2.48354527959455E-8,269.651092529297,269.850982666016,999.640686035156,999.640686035156,50.3536816516303,5.79182144621945,7.83288526535034,70,1,0,0,1,0.2630615234375,27.8592376708984,2,1,1,269.651092529297,0,269.751037597656,,,,,,,,,,,,,,,,,,,,,,,,,,,,,,,,,
,3737904397.81566,263.277572631836,999.640686035156,7.33442744600343E-7,6.32916818709992E-9,1,5,14.0008964538574,3.97925867358995,30.460000038147,0.000651597591180694,6.8900205288875E-5,1,-3.26461614664352E-8,263.140106201172,263.4150390625,999.640686035156,999.640686035156,50.3525092088515,5.79260587807321,7.77245187759399,70,1,0,0,1,0.26214599609375,27.8592376708984,2,1,1,263.140106201172,0,263.277572631836,,,,,,,,,,,,,,,,,,,,,,,,,,,,,,,,,
,3737904528.07382,256.791030883789,999.640686035156,7.51226404503608E-7,6.15850684460527E-9,1,5,14.0008964538574,3.97925649216593,30.4499994963407,0.000666788397056424,7.45968321300181E-5,1,-2.88754919477377E-8,256.673645019531,256.908416748047,999.640686035156,999.640686035156,50.2278394600342,5.79144581028886,7.7137885093689,70,1,0,0,1,0.262451171875,27.8592376708984,2,1,1,256.673645019531,0,256.791030883789,,,,,,,,,,,,,,,,,,,,,,,,,,,,,,,,,
,3737904657.81981,250.269424438477,999.640686035156,7.41319121296034E-7,6.08432293932682E-9,1,5,14.0008964538574,3.97921320461681,30.4300002753735,0.000656798533328656,8.14595661736564E-5,1,-1.96016120019723E-8,250.140808105469,250.398040771484,999.640686035156,999.640686035156,50.1449868369957,5.79179844223665,7.65897417068481,70,1,0,0,1,0.2630615234375,27.8592376708984,2,1,1,250.140808105469,0,250.269424438477,,,,,,,,,,,,,,,,,,,,,,,,,,,,,,,,,
,3737904787.80312,243.777114868164,999.640686035156,7.50965682565977E-7,9.91533465783261E-9,1,5,14.0008964538574,3.97924698481143,30.409999191761,0.000664123340433767,9.06746935862052E-5,1,-1.06167686761268E-8,243.658111572266,243.896118164062,999.640686035156,999.640686035156,50.3196808110438,5.79047025966443,7.59922504425049,70,1,0,0,1,0.262451171875,27.8592376708984,2,1,1,243.658111572266,0,243.777114868164,,,,,,,,,,,,,,,,,,,,,,,,,,,,,,,,,
,3737904917.75285,237.325881958008,999.640686035156,7.40186744488046E-7,7.34909302931586E-9,1,5,14.0008964538574,3.97926105510125,30.3899999707937,0.00065637917971227,7.75522280753326E-5,1,-2.38601161958914E-8,237.184478759766,237.46728515625,999.640686035156,999.640686035156,50.1457684655149,5.79188943777183,7.54343032836914,70,1,0,0,1,0.262451171875,27.8592376708984,2,1,1,237.184478759766,0,237.325881958008,,,,,,,,,,,,,,,,,,,,,,,,,,,,,,,,,
,3737905047.75275,230.791938781738,999.640686035156,7.46741343118261E-7,7.72474740461903E-9,1,5,14.0008964538574,3.97930147708528,30.3700007498264,0.000661613711377936,8.21397527527244E-5,1,-1.96526795982467E-8,230.677215576172,230.906661987305,999.640686035156,999.640686035156,50.2508975013515,5.79116403004987,7.47436666488647,70,1,0,0,1,0.263137817382813,27.8592376708984,2,1,1,230.677215576172,0,230.791938781738,,,,,,,,,,,,,,,,,,,,,,,,,,,,,,,,,
,3737905178.60686,224.253448486328,999.640686035156,7.36963012262962E-7,7.20537676622918E-9,1,5,14.0008964538574,3.97931076772934,30.3600002080202,0.000652450669427627,8.43889207199703E-5,1,-1.56282355199813E-8,224.143768310547,224.363128662109,999.640686035156,999.640686035156,50.4365342746688,5.79149637173771,7.42501544952393,68,1,64,0,0,0.2606201171875,27.8592376708984,2,1,1,224.143768310547,0,224.253448486328,,,,,,,,,,,,,,,,,,,,,,,,,,,,,,,,,
,3737905308.03814,217.770156860352,999.640686035156,7.61154496837488E-7,8.24735334326137E-9,1,5,14.0008964538574,3.97925919798331,30.3399991244078,0.000674833359694759,8.06697860033717E-5,1,-2.34926566483932E-8,217.663925170898,217.876388549805,999.640686035156,999.640686035156,50.2571505295053,5.7922721375955,7.39273548126221,68,1,64,0,0,0.259246826171875,27.8592376708984,2,1,1,217.663925170898,0,217.770156860352,,,,,,,,,,,,,,,,,,,,,,,,,,,,,,,,,
,3737905438.29682,211.304252624512,999.640686035156,7.59071583723831E-7,6.90392532876667E-9,1,5,14.0008964538574,3.97928119214826,30.3300004452467,0.000673595906292832,7.64534053077742E-5,1,-2.79568583652993E-8,211.181411743164,211.427093505859,999.640686035156,999.640686035156,50.2626219291399,5.79001919418444,7.37272262573242,68,1,64,0,0,0.263519287109375,27.8592376708984,2,1,1,211.181411743164,0,211.304252624512,,,,,,,,,,,,,,,,,,,,,,,,,,,,,,,,,
,3737905567.77803,204.797912597656,999.640686035156,7.65012358680582E-7,7.98191473822117E-9,1,5,14.0008964538574,3.97923306484973,30.3099993616343,0.000677371035449898,8.68776338743635E-5,1,-1.70394652280528E-8,204.674194335938,204.921630859375,999.640686035156,999.640686035156,50.2954503269476,5.79162408305626,7.32980728149414,70,1,0,0,1,0.262832641601562,27.8592376708984,2,1,1,204.674194335938,0,204.797912597656,,,,,,,,,,,,,,,,,,,,,,,,,,,,,,,,,
,3737905697.93882,198.302085876465,999.640686035156,7.72539699678455E-7,7.42795363966903E-9,1,5,14.0008964538574,3.9792805184076,30.290000140667,0.000684909509108275,8.20344198025845E-5,1,-2.36658212077445E-8,198.184921264648,198.419250488281,999.640686035156,999.640686035156,50.2704382143322,5.79111441231169,7.26491260528564,70,1,0,0,1,0.261917114257813,27.8592376708984,2,1,1,198.184921264648,0,198.302085876465,,,,,,,,,,,,,,,,,,,,,,,,,,,,,,,,,
,3737905827.66427,191.831130981445,999.640686035156,7.86885536597588E-7,5.92389991015023E-9,1,5,14.0008964538574,3.97924401143885,30.290000140667,0.000697262234529656,8.59122016946737E-5,1,-2.14359178407021E-8,191.713027954102,191.949234008789,999.640686035156,999.640686035156,50.2438628446784,5.79038833836513,7.20923328399658,70,1,0,0,1,0.2630615234375,27.8592376708984,2,1,1,191.713027954102,0,191.831130981445,,,,,,,,,,,,,,,,,,,,,,,,,,,,,,,,,
,3737905957.69441,185.342468261719,999.640686035156,7.85986623741592E-7,7.56347783782224E-9,1,5,14.0008964538574,3.9791934824783,30.2700009196997,0.000694734227204419,9.71883082234898E-5,1,-8.52015600734683E-9,185.211761474609,185.473175048828,999.640686035156,999.640686035156,50.3349225671688,5.7908697150655,7.17417240142822,70,1,0,0,1,0.260696411132813,27.8592376708984,2,1,1,185.211761474609,0,185.342468261719,,,,,,,,,,,,,,,,,,,,,,,,,,,,,,,,,
,3737906087.97147,178.826416015625,999.640686035156,7.68645322956103E-7,7.09677028437534E-9,1,5,14.0008964538574,3.97911658167545,30.2499998360872,0.000681220334784252,8.28851294649092E-5,1,-2.21077429274046E-8,178.710067749023,178.942764282227,999.640686035156,999.640686035156,50.2219772461399,5.79104326128485,7.11436414718628,70,1,0,0,1,0.263214111328125,27.8592376708984,2,1,1,178.710067749023,0,178.826416015625,,,,,,,,,,,,,,,,,,,,,,,,,,,,,,,,,
,3737906217.64114,172.357627868652,999.640686035156,7.84926686619683E-7,7.83371063433958E-9,1,5,14.0008964538574,3.97917018119559,30.239999294281,0.000695947708577186,8.27689130613634E-5,1,-2.46993269331213E-8,172.24040222168,172.474853515625,999.640686035156,999.640686035156,50.2731739141496,5.79014720192221,4.99418258666992,70,1,0,0,1,0.263595581054687,27.8592376708984,2,1,1,172.24040222168,0,172.357627868652,,,,,,,,,,,,,,,,,,,,,,,,,,,,,,,,,
,3737906348.21475,165.816841125488,999.640686035156,7.78295823887069E-7,7.55405893372613E-9,1,5,14.0008964538574,3.97904823855421,30.2200000733137,0.000690246427725291,8.06632417494324E-5,1,-2.60800110091337E-8,165.707748413086,165.925933837891,999.640686035156,999.640686035156,50.2067354900149,5.7922955978583,4.96264505386353,70,1,0,0,1,0.262985229492187,27.8592376708984,2,1,1,165.707748413086,0,165.816841125488,,,,,,,,,,,,,,,,,,,,,,,,,,,,,,,,,
,3737906477.5986,159.374374389648,999.640686035156,7.69181243982266E-7,6.71542870964756E-9,1,5,14.0008964538574,3.97912864979113,30.2000008523464,0.00068243997760597,7.8032330820071E-5,1,-2.768843667042E-8,159.253036499023,159.495712280273,999.640686035156,999.640686035156,50.2993584695438,5.79081730684517,4.93680334091186,70,1,0,0,1,0.263214111328125,27.8592376708984,2,1,1,159.253036499023,0,159.374374389648,,,,,,,,,,,,,,,,,,,,,,,,,,,,,,,,,
,3737906608.04262,152.860107421875,999.640686035156,7.93935025114681E-7,1.51172514700334E-8,1,5,14.0008964538574,3.97895105822779,30.2000008523464,0.000703112094698274,8.87511729656441E-5,1,-1.92712272851251E-8,152.735397338867,152.984817504883,999.640686035156,999.640686035156,50.3274970962361,5.79244790287403,4.91066217422485,70,1,0,0,1,0.261154174804687,27.8592376708984,2,1,1,152.701644897461,0,152.860107421875,,,,,,,,,,,,,,,,,,,,,,,,,,,,,,,,,
,3737906737.60951,146.369171142578,999.640686035156,7.81425636189333E-7,6.4171552799687E-9,1,5,14.0008964538574,3.97891719144466,30.179999768734,0.000691566675902025,9.0383079605277E-5,1,-1.55319370220171E-8,146.25764465332,146.480697631836,999.640686035156,999.640686035156,50.2512883156111,5.79335533257018,4.8805136680603,70,1,0,0,1,0.263671875,27.8592376708984,2,1,1,146.25764465332,0,146.369171142578,,,,,,,,,,,,,,,,,,,,,,,,,,,,,,,,,
,3737906867.63477,139.873031616211,999.640686035156,8.03309338374263E-7,6.07686633219426E-9,1,5,14.0008964538574,3.97879626600063,30.179999768734,0.000711591520694537,8.83246732940527E-5,1,-2.11635214512344E-8,139.760147094727,139.985916137695,999.640686035156,999.640686035156,50.0797208556399,5.79299452877351,4.85759019851685,70,1,0,0,1,0.264816284179687,27.8592376708984,2,1,1,139.760147094727,0,139.873031616211,,,,,,,,,,,,,,,,,,,,,,,,,,,,,,,,,
,3737906997.55143,133.384956359863,999.640686035156,7.99667096666258E-7,5.90753470740831E-9,1,5,14.0008964538574,3.9787748696354,30.1600005477667,0.000708110262164419,8.95714164237282E-5,1,-1.9199774567176E-8,133.267288208008,133.502624511719,999.640686035156,999.640686035156,50.1184114673418,5.79390318924629,4.82941722869873,70,1,0,0,1,0.264739990234375,27.8592376708984,2,1,1,133.267288208008,0,133.384956359863,,,,,,,,,,,,,,,,,,,,,,,,,,,,,,,,,
,3737907127.84989,126.86226272583,999.640686035156,7.87221457023862E-7,6.26263303600206E-9,1,5,14.0008964538574,3.97898939878493,30.1399994641542,0.000698133305811294,8.16690797533869E-5,1,-2.6285370547668E-8,126.763809204102,126.960716247559,999.640686035156,999.640686035156,50.2211956176207,5.79363804962663,4.79831409454346,69,1,64,0,0,0.264434814453125,27.8592376708984,2,1,1,126.763809204102,0,126.86226272583,,,,,,,,,,,,,,,,,,,,,,,,,,,,,,,,,
,3737907257.84419,120.412258148193,999.640686035156,8.06038665416169E-7,2.90388744343195E-8,1,5,14.0008964538574,3.97898457748305,30.1399994641542,0.000715246074816344,8.07962062721122E-5,1,-3.01150940318779E-8,120.300964355469,120.523551940918,999.640686035156,999.640686035156,50.1711713923899,5.79370203127242,4.77129983901978,70,1,0,0,1,0.262985229492187,27.8592376708984,2,1,1,120.300964355469,0,120.412258148193,,,,,,,,,,,,,,,,,,,,,,,,,,,,,,,,,
,3737907387.53048,113.892795562744,999.640686035156,8.05630370896467E-7,6.42894724621794E-9,1,5,14.0008964538574,3.97896627788227,30.1300007849932,0.000715610203007849,7.59078432714872E-5,1,-3.55927826817056E-8,113.75666809082,114.028923034668,999.640686035156,999.640686035156,50.2446444731976,5.79334961441985,4.7409200668335,70,1,0,0,1,0.262680053710938,27.8592376708984,2,1,1,113.75666809082,0,113.892795562744,,,,,,,,,,,,,,,,,,,,,,,,,,,,,,,,,
,3737907517.79538,107.402015686035,999.640686035156,8.0006346299681E-7,1.70639425593283E-8,1,5,14.0008964538574,3.97894545777823,30.120000243187,0.000709966620857555,7.99717271891952E-5,1,-3.01460204612397E-8,107.274291992187,107.529739379883,999.640686035156,999.640686035156,50.2477709872745,5.79311561546448,4.71154022216797,70,1,0,0,1,0.260696411132813,27.8592376708984,2,1,1,107.274291992187,0,107.402015686035,,,,,,,,,,,,,,,,,,,,,,,,,,,,,,,,,
,3737907647.4918,100.922355651855,999.640686035156,7.98886545095919E-7,6.55758846576662E-9,1,5,14.0008964538574,3.97891922324064,30.0999991595745,0.000708469453453853,8.28030816463968E-5,1,-2.67585510708841E-8,100.812606811523,101.032104492187,999.640686035156,999.640686035156,50.1746887207265,5.79350765075294,4.67971420288086,70,1,0,0,1,0.262451171875,27.8592376708984,2,1,1,100.812606811523,0,100.922355651855,,,,,,,,,,,,,,,,,,,,,,,,,,,,,,,,,
,3737907777.55684,94.4473114013672,999.640686035156,8.07092811080956E-7,6.13435079229411E-9,1,5,14.0008964538574,3.97899034166937,30.0999991595745,0.000715600869341961,8.47591296354796E-5,1,-2.57832904464693E-8,94.3259811401367,94.5686416625977,999.640686035156,999.640686035156,50.1352164805053,5.79319368172836,4.65237188339233,70,1,0,0,1,0.260848999023438,27.8592376708984,2,1,1,94.3259811401367,0,94.4473114013672,,,,,,,,,,,,,,,,,,,,,,,,,,,,,,,,,
,3737907907.44813,87.9341850280762,999.640686035156,7.89929557160904E-7,6.61079624860772E-9,1,5,14.0008964538574,3.97910525677707,30.0799999386072,0.000701344126013063,7.68096108285296E-5,1,-3.22054435956137E-8,87.815315246582,88.0530548095703,999.640686035156,999.640686035156,50.259495415063,5.79140874536508,4.61953592300415,70,1,0,0,1,0.262069702148438,27.8592376708984,2,1,1,87.815315246582,0,87.9341850280762,,,,,,,,,,,,,,,,,,,,,,,,,,,,,,,,,
,3737908037.4537,81.4346542358398,999.640686035156,8.02388289795638E-7,6.55427082208543E-9,1,5,14.0008964538574,3.9790801631032,30.0799999386072,0.000711677625322942,8.27955507322436E-5,1,-2.73017826502206E-8,81.3216552734375,81.5476531982422,999.640686035156,999.640686035156,50.2606678578419,5.79186076682206,4.58682727813721,70,1,0,0,1,0.263137817382813,27.8592376708984,2,1,1,81.3216552734375,0,81.4346542358398,,,,,,,,,,,,,,,,,,,,,,,,,,,,,,,,,
,3737908167.9406,74.852222442627,999.640686035156,8.03173318908205E-7,6.48153554803689E-9,1,5,14.0008964538574,3.97893931762728,30.0799999386072,0.000712728034945438,8.0259037530672E-5,1,-3.02896529694561E-8,74.7345504760742,74.9698944091797,999.640686035156,999.640686035156,50.1715622066495,5.79312846791748,4.55206155776978,70,1,0,0,1,0.264739990234375,27.8592376708984,2,1,1,74.7345504760742,0,74.852222442627,,,,,,,,,,,,,,,,,,,,,,,,,,,,,,,,,
,3737908297.40342,68.3388328552246,999.640686035156,7.93435171436577E-7,8.43062844045453E-9,1,5,14.0008964538574,3.97861285155078,30.0600007176399,0.000704269220419588,7.74534187281524E-5,1,-3.19877020548039E-8,68.2236099243164,68.4540557861328,999.640686035156,999.640686035156,50.2481618015342,5.79294802075576,4.52393198013306,70,1,0,0,1,0.265426635742187,27.8592376708984,2,1,1,68.2236099243164,0,68.3388328552246,,,,,,,,,,,,,,,,,,,,,,,,,,,,,,,,,
,3737908427.44357,61.789924621582,999.640686035156,7.77784188881903E-7,7.88928589040563E-9,1,5,14.0008964538574,3.97874478126241,30.0600007176399,0.000690482065446879,7.54766750096418E-5,1,-3.18701051434389E-8,61.6702919006348,61.9095573425293,999.640686035156,999.640686035156,50.1887580340726,5.7939523307671,4.48141241073608,70,1,0,0,1,0.265045166015625,27.8592376708984,2,1,1,61.6702919006348,0,61.789924621582,,,,,,,,,,,,,,,,,,,,,,,,,,,,,,,,,
,3737908557.804,55.2332897186279,999.640686035156,7.73088151292977E-7,6.39394788823981E-9,1,5,14.0008964538574,3.97872003370083,30.0600007176399,0.00068598114352666,7.71741799799652E-5,1,-2.92363536811148E-8,55.1291885375977,55.3373908996582,999.640686035156,999.640686035156,50.1567112647841,5.79394319814322,4.43928623199463,70,1,0,0,1,0.264968872070313,27.8592376708984,2,1,1,55.1291885375977,0,55.2332897186279,,,,,,,,,,,,,,,,,,,,,,,,,,,,,,,,,
,3737908687.40995,48.7196216583252,999.640686035156,7.45030212266186E-7,6.44585406582763E-9,1,5,14.0008964538574,3.97865602514479,30.0399996340275,0.00066069350520772,7.68494723613716E-5,1,-2.53664654420932E-8,48.5911483764648,48.8480949401855,999.640686035156,999.640686035156,50.2888064845342,5.79288537603975,4.38958787918091,70,1,0,0,1,0.26153564453125,27.8592376708984,2,1,1,48.5911483764648,0,48.7196216583252,,,,,,,,,,,,,,,,,,,,,,,,,,,,,,,,,
,3737908817.61985,42.1766128540039,999.640686035156,7.25838757907514E-7,9.00137413443942E-9,1,5,14.0008964538574,3.9786607090182,30.0399996340275,0.000645682297774333,6.1578043886695E-5,1,-3.97787407610441E-8,42.0428504943848,42.310375213623,999.640686035156,999.640686035156,50.3165542969669,5.79263178410869,4.32494926452637,70,1,0,0,1,0.264739990234375,27.8592376708984,2,1,1,42.0428504943848,0,42.1766128540039,,,,,,,,,,,,,,,,,,,,,,,,,,,,,,,,,
,3737908947.397,35.6222496032715,999.640686035156,6.94944855539267E-7,7.17051188940484E-9,1,5,14.0008964538574,3.97862154187702,30.0399996340275,0.000617724797926254,6.20401999017889E-5,1,-3.45900079306257E-8,35.4972076416016,35.7472915649414,999.640686035156,999.640686035156,50.1301358951303,5.79346722045615,4.24024152755737,70,1,0,0,1,0.264358520507813,27.8592376708984,2,1,1,35.4972076416016,0,35.6222496032715,,,,,,,,,,,,,,,,,,,,,,,,,,,,,,,,,
,3737909077.33299,29.1291017532349,999.640686035156,6.42647557165592E-7,1.9233610843126E-8,1,5,14.0008964538574,3.97863906617762,30.0399996340275,0.000570988537108058,5.90550047940167E-5,1,-3.00791859625963E-8,29.0095539093018,29.248649597168,999.640686035156,999.640686035156,50.2794269423034,5.79309737241782,4.11467599868774,70,1,0,0,1,0.264205932617187,27.8592376708984,2,1,1,29.0095539093018,0,29.1291017532349,,,,,,,,,,,,,,,,,,,,,,,,,,,,,,,,,
,3737909207.72004,22.5898818969727,999.640686035156,5.40043443229661E-7,5.6171489283922E-9,1,5,14.0008964538574,3.97863007785545,30.0200004130602,0.000480565401949347,4.47127430757938E-5,1,-3.08459739444872E-8,22.4838562011719,22.6959075927734,999.640686035156,999.640686035156,50.178206049063,5.79365836115087,3.9171097278595,70,1,0,0,1,0.262298583984375,27.8592376708984,2,1,1,22.4838562011719,0,22.5898818969727,,,,,,,,,,,,,,,,,,,,,,,,,,,,,,,,,
,3737909337.29411,16.1568098068237,999.640686035156,3.82957264930768E-7,5.50975022739584E-9,1,5,14.0008964538574,3.97865667789304,30.0200004130602,0.000341407092088477,2.75774151903476E-5,1,-2.65544468593285E-8,16.0361213684082,16.2774982452393,999.640686035156,999.640686035156,50.2051722329765,5.79365831825956,3.58006191253662,70,1,0,0,1,0.263442993164062,27.8592376708984,2,1,1,16.0361213684082,0,16.1568098068237,,,,,,,,,,,,,,,,,,,,,,,,,,,,,,,,,
,3737909467.59828,10.0254888534546,999.640686035156,4.62819562783417E-8,5.19697550153492E-9,1,5,14.0008964538574,3.9785970889074,30.0200004130602,4.46448623979667E-5,-1.90927968020523E-5,1,-2.86279496630865E-8,9.95363521575928,10.0973424911499,999.640686035156,999.640686035156,50.2419087733803,5.79370397595078,3.06834554672241,70,1,0,0,1,0.2655029296875,27.8592376708984,6,1,1,9.95363521575928,0,10.0254888534546,,,,,,,,,,,,,,,,,,,,,,,,,,,,,,,,,
,3737909597.32164,3.75128138065338,999.640686035156,-1.24703404349064E-6,6.83366855722208E-9,1,5,14.0008964538574,3.97861188384521,30.0200004130602,-0.00109692991149011,-0.000187726077000511,1,-2.45264150940316E-8,3.63691306114197,3.86564970016479,999.640686035156,999.640686035156,50.2618403006207,5.79400115143742,2.25576400756836,70,1,0,0,1,0.261306762695313,27.8592376708984,6,1,1,3.63691306114197,0,3.75128138065338,,,,,,,,,,,,,,,,,,,,,,,,,,,,,,,,,
,3737910167.37891,2.3947514295578,999.640686035156,-1.77798756610258E-6,1.5212759561525E-8,1,5,14.0008964538574,3.97856438404472,30.0200004130602,-0.00156619294254514,-0.000252747521286205,1,-1.80777090151843E-8,2.34449529647827,2.44500756263733,999.640686035156,999.640686035156,50.1907121053707,5.79409601442949,1.83237874507904,70,1,0,0,1,0.263137817382813,27.8592376708984,6,1,1,2.34449529647827,0,2.3947514295578,,,,,,,,,,,,,,,,,,,,,,,,,,,,,,,,,
,3737910262.4085,1.9997570514679,999.640686035156,-2.11894610708962E-6,5.36885249221372E-9,1,5,14.0008964538574,3.97858765062639,30.0200004130602,-0.00186610867807287,-0.000304167492404054,1,-2.48866155423754E-8,1.99965190887451,1.99986219406128,999.640686035156,999.640686035156,50.1614010358995,5.79447312794471,1.67630898952484,70,1,0,0,1,0.265121459960938,27.8592376708984,1,1,1,1.99965190887451,0,1.9997570514679,,,,,,,,,,,,,,,,,,,,,,,,,,,,,,,,,