File: data/brass-holder/180611_MT_brass-empty-powder-container_1T.dat
[Header]
; MPMS3 Data File (default extension .dat)
; Copyright (c) 2007, Quantum Design, Inc. All rights reserved.
TITLE,
FILEOPENTIME,3737912175.60329,06/11/2018,9:59 pm
BYAPP,MPMS3,1.0,1.1
INFO,MPMS3 Measurement Release 1.1.16 Build 388, MultiVu Release 2.3.4.15,APPNAME
INFO,0,MOMENT_UNITS
INFO,empty brass,SAMPLE_MATERIAL
INFO,,SAMPLE_COMMENT
INFO,1,SAMPLE_MASS
INFO,,SAMPLE_VOLUME
INFO,,SAMPLE_MOLECULAR_WEIGHT
INFO,,SAMPLE_SIZE
INFO,,SAMPLE_SHAPE
INFO,Brass,SAMPLE_HOLDER
INFO,Standard,SAMPLE_HOLDER_DETAIL
INFO,65.32,SAMPLE_OFFSET
DATATYPE,COMMENT,1
DATATYPE,TIME,2
STARTUPAXIS,X,2
STARTUPAXIS,Y1,5
FIELDGROUP, VSM,2,3,4,5,6,8,9,10,11,14,15
FIELDGROUP, DC, 2,3,4,14,34,35,36,37,38,39,40,41,42,43,44,45,46,47
STARTUPGROUP, All
[Data]
Comment,Time Stamp (sec),Temperature (K),Magnetic Field (Oe),Moment (emu),M. Std. Err. (emu),Transport Action,Averaging Time (sec),Frequency (Hz),Peak Amplitude (mm),Center Position (mm),Lockin Signal' (V),Lockin Signal (V),Range,M. Quad. Signal (emu),Min. Temperature (K),Max. Temperature (K),Min. Field (Oe),Max. Field (Oe),Mass (grams),Motor Lag (deg),Pressure (Torr),Measure Count,Measurement Number,SQUID Status (code),Motor Status (code),Measure Status (code),Motor Current (amps),Motor Temp. (C),Temp. Status (code),Field Status (code),Chamber Status (code),Chamber Temp (K),Redirection State,Average Temp (K),Rotation Angle (deg),Rotator state,DC Moment Fixed Ctr (emu),DC Moment Err Fixed Ctr (emu),DC Moment Free Ctr (emu),DC Moment Err Free Ctr (emu),DC Fixed Fit,DC Free Fit,DC Calculated Center (mm),DC Calculated Center Err (mm),DC Scan Length (mm),DC Scan Time (s),DC Number of Points,DC Squid Drift,DC Min V (V),DC Max V (V),DC Scans per Measure,Map 01,Map 02,Map 03,Map 04,Map 05,Map 06,Map 07,Map 08,Map 09,Map 10,Map 11,Map 12,Map 13,Map 14,Map 15,Map 16
,3737912242.87519,1.99978125095367,9999.71875,-2.33892326908082E-5,1.51715282450215E-8,1,5,14.0008964538574,3.99915739400935,30.0299990922213,-0.0207790435703346,-0.00331682330406958,1,-1.9782334785174E-7,1.99978125095367,1.99978125095367,9999.71875,9999.71875,50.2575413437649,5.79213569041875,1.66332185268402,69,1,68,0,0,0.267105102539062,27.8592376708984,1,1,1,1.99978125095367,0,1.99978125095367,,,,,,,,,,,,,,,,,,,,,,,,,,,,,,,,,
,3737912372.00775,7.47279453277588,9999.71875,-3.62162250523883E-6,5.0578466432858E-8,1,5,14.0008964538574,3.99904831901437,30.0200004130602,-0.00319154940437233,-0.000684249187321618,1,-2.22525567723079E-7,7.36677503585815,7.5788140296936,9999.71875,9999.71875,50.1496766081111,5.79358561582852,2.89756345748901,70,1,0,0,1,0.272064208984375,27.8592376708984,6,1,1,7.59657526016235,0,7.47279453277588,,,,,,,,,,,,,,,,,,,,,,,,,,,,,,,,,
,3737912502.02237,13.6070756912231,9999.71875,2.48693964172364E-6,1.40847293841064E-8,1,5,14.0008964538574,3.99901212746077,30.0200004130602,0.00224418540521282,0.000121394632147949,1,-2.38955632403893E-7,13.4829444885254,13.7312068939209,9999.71875,9999.71875,50.2286210885534,5.79304337841188,3.4342246055603,70,1,0,0,1,0.273895263671875,27.8592376708984,6,1,1,13.7312068939209,0,13.6070756912231,,,,,,,,,,,,,,,,,,,,,,,,,,,,,,,,,
,3737912632.47246,19.8811674118042,9999.71875,5.16483023431647E-6,1.01342486500938E-8,1,5,14.0008964538574,3.99896545269459,30.0200004130602,0.00462616879497227,0.000480157442997711,1,-2.39867670726493E-7,19.7579078674316,20.0044269561768,9999.71875,9999.71875,50.1860223342553,5.79332195642222,3.67044520378113,70,1,0,0,1,0.270843505859375,27.8592376708984,2,1,1,20.0044269561768,0,19.8811674118042,,,,,,,,,,,,,,,,,,,,,,,,,,,,,,,,,
,3737912761.96534,26.1986541748047,9999.71875,6.542352402359E-6,1.00290993934884E-8,1,5,14.0008964538574,3.99890987550019,30.0299990922213,0.00585074940653436,0.000668780300879726,1,-2.3574207694162E-7,26.091968536377,26.3053398132324,9999.71875,9999.71875,50.2106436326111,5.79339244734608,3.8303530216217,70,1,0,0,1,0.267105102539062,27.8592376708984,2,1,1,26.3053398132324,0,26.1986541748047,,,,,,,,,,,,,,,,,,,,,,,,,,,,,,,,,
,3737912891.94449,32.5275554656982,9999.71875,7.26966585334015E-6,1.21357105306654E-8,1,5,14.0008964538574,3.99890980353491,30.0200004130602,0.00649829550297349,0.000762217195066595,1,-2.40488405999695E-7,32.4022483825684,32.6528625488281,9999.71875,9999.71875,50.1954018764861,5.79294232618833,3.95412135124207,70,1,0,0,1,0.264892578125,27.8592376708984,2,1,1,32.6528625488281,0,32.5275554656982,,,,,,,,,,,,,,,,,,,,,,,,,,,,,,,,,
,3737913022.54094,38.8863983154297,9999.71875,7.58619125388467E-6,9.58186808172736E-9,1,5,14.0008964538574,3.99887514767553,30.0200004130602,0.00678001904573348,0.000802827142028792,1,-2.42601798395188E-7,38.7618408203125,39.0109558105469,9999.71875,9999.71875,50.1504582366303,5.79271844396451,4.05257415771484,70,1,0,0,1,0.270919799804687,27.8592376708984,2,1,1,39.0109558105469,0,38.8863983154297,,,,,,,,,,,,,,,,,,,,,,,,,,,,,,,,,
,3737913152.03028,45.2112407684326,9999.71875,7.82274895500699E-6,9.93597445085574E-9,1,5,14.0008964538574,3.9989638708418,30.0200004130602,0.00699103920661169,0.00083217286868881,1,-2.45352521610472E-7,45.0916175842285,45.3308639526367,9999.71875,9999.71875,50.1711713923899,5.7924216710538,4.12717962265015,70,1,0,0,1,0.271148681640625,27.8592376708984,2,1,1,45.3308639526367,0,45.2112407684326,,,,,,,,,,,,,,,,,,,,,,,,,,,,,,,,,
,3737913282.04673,51.5837936401367,9999.71875,7.93686688570757E-6,5.85653936057218E-8,1,5,14.0008964538574,3.9988996885297,30.0200004130602,0.00709134268770694,0.000854226357403573,1,-2.37761387255373E-7,51.4644660949707,51.7031211853027,9999.71875,9999.71875,50.1907121053707,5.79276603701669,4.1892819404602,70,1,0,0,1,0.264434814453125,27.8592376708984,2,1,1,51.7031211853027,0,51.5837936401367,,,,,,,,,,,,,,,,,,,,,,,,,,,,,,,,,
,3737913412.29759,57.9731998443603,9999.71875,8.09922274863666E-6,2.91601118905982E-8,1,5,14.0008964538574,3.99883893927592,30.0299990922213,0.00723549930850195,0.000876500777234776,1,-2.37204018336313E-7,57.872989654541,58.0734100341797,9999.71875,9999.71875,50.2426904018995,5.79271527858064,4.2489013671875,70,1,0,0,1,0.271148681640625,27.8592376708984,2,1,1,58.0734100341797,0,57.9731998443603,,,,,,,,,,,,,,,,,,,,,,,,,,,,,,,,,
,3737913541.89748,64.3723602294922,9999.71875,8.06613251978938E-6,1.03680436519806E-8,1,5,14.0008964538574,3.99879620789042,30.0299990922213,0.00720802041828861,0.000858296089531084,1,-2.52660136651602E-7,64.2556457519531,64.4890747070312,9999.71875,9999.71875,50.1614010358995,5.7930769783151,4.28914070129395,70,1,0,0,1,0.269241333007813,27.8592376708984,2,1,1,64.4890747070312,0,64.3723602294922,,,,,,,,,,,,,,,,,,,,,,,,,,,,,,,,,
,3737913672.09825,70.7569580078125,9999.71875,8.14004202949945E-6,1.05849452961657E-8,1,5,14.0008964538574,3.99874536310541,30.0399996340275,0.00727163891244178,0.000881250244671633,1,-2.37989243905877E-7,70.6181564331055,70.8957595825195,9999.71875,9999.71875,50.2434720304188,5.79317278025464,4.32419586181641,70,1,0,0,1,0.26702880859375,27.8592376708984,2,1,1,70.8957595825195,0,70.7569580078125,,,,,,,,,,,,,,,,,,,,,,,,,,,,,,,,,
,3737913801.90478,77.1648178100586,9999.71875,8.03425482988549E-6,1.00297198974005E-8,1,5,14.0008964538574,3.99875077857989,30.0399996340275,0.00717875125607034,0.000859211692809431,1,-2.46800861456796E-7,77.0491256713867,77.2805099487305,9999.71875,9999.71875,50.2817718278611,5.79353145516581,4.35666370391846,70,1,0,0,1,0.267333984375,27.8592376708984,2,1,1,77.2805099487305,0,77.1648178100586,,,,,,,,,,,,,,,,,,,,,,,,,,,,,,,,,
,3737913931.89395,83.5730972290039,9999.71875,8.12063081940559E-6,1.06016651371001E-8,1,5,14.0008964538574,3.99873866555913,30.0500001758337,0.00725353088655283,0.000884103120266412,1,-2.31848565581292E-7,83.4385986328125,83.7075958251953,9999.71875,9999.71875,50.2059538614957,5.79256530772323,4.38308668136597,70,1,0,0,1,0.271148681640625,27.8592376708984,2,1,1,83.7075958251953,0,83.5730972290039,,,,,,,,,,,,,,,,,,,,,,,,,,,,,,,,,
,3737914062.24164,90.038501739502,9999.71875,8.08300762638946E-6,7.52372071412292E-8,1,5,14.0008964538574,3.99879187394053,30.069999396801,0.00722039284306389,0.000877942039939424,1,-2.33117173938094E-7,89.9158325195313,90.1611709594727,9999.71875,9999.71875,50.2352649309669,5.79226177528517,4.40910339355469,70,1,0,0,1,0.267181396484375,27.8592376708984,2,1,1,90.1611709594727,0,90.038501739502,,,,,,,,,,,,,,,,,,,,,,,,,,,,,,,,,
,3737914191.82369,96.4955749511719,9999.71875,7.91445535355836E-6,1.25513214442318E-8,1,5,14.0008964538574,3.9987152543825,30.069999396801,0.00706958988192996,0.000859756512663001,1,-2.28089440830122E-7,96.3668518066406,96.6242980957031,9999.71875,9999.71875,50.2399547020822,5.79281265755051,4.42559719085693,70,1,0,0,1,0.268478393554687,27.8592376708984,2,1,1,96.6242980957031,0,96.4955749511719,,,,,,,,,,,,,,,,,,,,,,,,,,,,,,,,,
,3737914321.87546,103.00129699707,9999.71875,7.89452054223499E-6,1.05415518517733E-8,1,5,14.0008964538574,3.99886514630252,30.069999396801,0.00705097330342178,0.000865800410143331,1,-2.18342644058996E-7,102.885192871094,103.117401123047,9999.71875,9999.71875,50.1676540640534,5.79225356559605,4.4512186050415,70,1,0,0,1,0.26763916015625,27.8592376708984,2,1,1,103.117401123047,0,103.00129699707,,,,,,,,,,,,,,,,,,,,,,,,,,,,,,,,,
,3737914452.18274,109.481239318848,9999.71875,7.8530082645163E-6,9.82441546492955E-9,1,5,14.0008964538574,3.99877506863068,30.0799999386072,0.00701446597616904,0.000855775946341078,1,-2.23311902267894E-7,109.37816619873,109.584312438965,9999.71875,9999.71875,50.2387822593034,5.79367898611915,4.46226215362549,70,1,0,0,1,0.269088745117187,27.8592376708984,2,1,1,109.584312438965,0,109.481239318848,,,,,,,,,,,,,,,,,,,,,,,,,,,,,,,,,
,3737914582.09747,115.941265106201,9999.71875,7.79176147776104E-6,1.04483513109796E-8,1,5,14.0008964538574,3.99884536734394,30.0999991595745,0.00696080396255943,0.000843497291875463,1,-2.27898093007512E-7,115.831581115723,116.05094909668,9999.71875,9999.71875,50.3005309123226,5.79267546171873,4.47763013839722,69,1,64,0,0,0.267486572265625,27.8592376708984,2,1,1,116.05094909668,0,115.941265106201,,,,,,,,,,,,,,,,,,,,,,,,,,,,,,,,,
,3737914711.83424,122.387054443359,9999.71875,7.57860609117746E-6,1.14587601634624E-8,1,5,14.0008964538574,3.99872551173808,30.0900004804134,0.00676896156278752,0.000827638618478896,1,-2.13505482278316E-7,122.263870239258,122.510238647461,9999.71875,9999.71875,50.2821626421207,5.79375360920648,4.497802734375,70,1,0,0,1,0.26702880859375,27.8592376708984,2,1,1,122.510238647461,0,122.387054443359,,,,,,,,,,,,,,,,,,,,,,,,,,,,,,,,,
,3737914841.78186,128.884826660156,9999.71875,7.50013365809862E-6,1.22069874870798E-8,1,5,14.0008964538574,3.99871040178147,30.1099997013807,0.0067000038213702,0.000811302741474323,1,-2.20021261494141E-7,128.762268066406,129.007385253906,9999.71875,9999.71875,50.1051237825149,5.79432712124176,4.50274419784546,70,1,0,0,1,0.268325805664062,27.8592376708984,2,1,1,129.007385253906,0,128.884826660156,,,,,,,,,,,,,,,,,,,,,,,,,,,,,,,,,
,3737914971.73872,135.35327911377,9999.71875,7.58744875257768E-6,9.58257168932222E-9,1,5,14.0008964538574,3.99864866052841,30.120000243187,0.00677798868209638,0.00081972263152442,1,-2.23712643950682E-7,135.219192504883,135.487365722656,9999.71875,9999.71875,50.2661392574765,5.79420399982762,4.51848030090332,70,1,0,0,1,0.265045166015625,27.8592376708984,2,1,1,135.487365722656,0,135.35327911377,,,,,,,,,,,,,,,,,,,,,,,,,,,,,,,,,
,3737915102.08432,141.855293273926,9999.71875,7.49826713157002E-6,1.10852304172984E-8,1,5,14.0008964538574,3.99871410873195,30.1300007849932,0.00669845908913959,0.000810355081467141,1,-2.20806364721436E-7,141.744659423828,141.965927124023,9999.71875,9999.71875,50.2438628446784,5.79359850097245,4.53191757202148,70,1,0,0,1,0.268402099609375,27.8592376708984,2,1,1,141.965927124023,0,141.855293273926,,,,,,,,,,,,,,,,,,,,,,,,,,,,,,,,,
,3737915231.8029,148.339141845703,9999.71875,7.39808284956989E-6,1.41176756223642E-8,1,5,14.0008964538574,3.99880869109378,30.1399994641542,0.00660848161622957,0.000804386106035635,1,-2.12427883325372E-7,148.225692749023,148.452590942383,9999.71875,9999.71875,50.157883707563,5.79406145806751,4.53980302810669,70,1,0,0,1,0.275192260742187,27.8592376708984,2,1,1,148.452590942383,0,148.339141845703,,,,,,,,,,,,,,,,,,,,,,,,,,,,,,,,,
,3737915361.94938,154.803443908691,9999.71875,7.29606028410502E-6,1.43606550840476E-8,1,5,14.0008964538574,3.99880170505992,30.1500000059605,0.00651820077154096,0.000787521636114559,1,-2.15985230317429E-7,154.675354003906,154.931533813477,9999.71875,9999.71875,50.1660908070149,5.79392096331254,4.5556902885437,70,1,0,0,1,0.268936157226562,27.8592376708984,2,1,1,154.931533813477,0,154.803443908691,,,,,,,,,,,,,,,,,,,,,,,,,,,,,,,,,
,3737915491.72005,161.266540527344,9999.71875,7.17976879271091E-6,1.38320328316295E-8,1,5,14.0008964538574,3.99887233004162,30.1600005477667,0.00641633846004785,0.000762735352107693,1,-2.26322003991216E-7,161.143951416016,161.389129638672,9999.71875,9999.71875,50.2153334037265,5.79397880607439,4.55869722366333,70,1,0,0,1,0.268936157226562,27.8592376708984,2,1,1,161.389129638672,0,161.266540527344,,,,,,,,,,,,,,,,,,,,,,,,,,,,,,,,,
,3737915621.73915,167.761810302734,9999.71875,7.0655373166905E-6,9.82336085384492E-9,1,5,14.0008964538574,3.99876915322178,30.1699992269278,0.00631295840188068,0.00075742498248427,1,-2.15012843364955E-7,167.638946533203,167.884674072266,9999.71875,9999.71875,50.1231012384572,5.79450179936825,4.57744836807251,70,1,0,0,1,0.271987915039062,27.8592376708984,2,1,1,167.884674072266,0,167.761810302734,,,,,,,,,,,,,,,,,,,,,,,,,,,,,,,,,
,3737915752.02659,174.276268005371,9999.71875,6.92424532291999E-6,1.23223218417717E-8,1,5,14.0008964538574,3.99881772421711,30.179999768734,0.00618738088067786,0.000738682756093821,1,-2.14772132085366E-7,174.146881103516,174.405654907227,9999.71875,9999.71875,50.2966227697265,5.79415262179163,4.59010648727417,70,1,0,0,1,0.270767211914062,27.8592376708984,2,1,1,174.405654907227,0,174.276268005371,,,,,,,,,,,,,,,,,,,,,,,,,,,,,,,,,
,3737915881.70123,180.741027832031,9999.71875,6.97830047820844E-6,1.19046971986867E-8,1,5,14.0008964538574,3.99875483996106,30.2000008523464,0.00623466550065558,0.000750138337140914,1,-2.10031361217648E-7,180.630722045898,180.851333618164,9999.71875,9999.71875,50.0719045704476,5.79451102263435,4.59475898742676,70,1,0,0,1,0.273284912109375,27.8592376708984,2,1,1,180.851333618164,0,180.741027832031,,,,,,,,,,,,,,,,,,,,,,,,,,,,,,,,,
,3737916011.65528,187.211456298828,9999.71875,6.85677457365082E-6,1.14896925045694E-8,1,5,14.0008964538574,3.99868596287961,30.2099995315075,0.00612660776584704,0.000732508653942641,1,-2.11485064230095E-7,187.091598510742,187.331314086914,9999.71875,9999.71875,50.0504097861688,5.79385403020805,4.60778093338013,70,1,0,0,1,0.268173217773438,27.8592376708984,2,1,1,187.331314086914,0,187.211456298828,,,,,,,,,,,,,,,,,,,,,,,,,,,,,,,,,
,3737916142.1528,193.721008300781,9999.71875,6.70480929959175E-6,1.26525484342022E-8,1,5,14.0008964538574,3.99875008042183,30.2300006151199,0.00599196274357267,0.000709771392640094,1,-2.14130096492456E-7,193.6025390625,193.839477539062,9999.71875,9999.71875,50.2204139891015,5.7946849072296,4.62668561935425,70,1,0,0,1,0.267410278320313,27.8592376708984,2,1,1,193.839477539062,0,193.721008300781,,,,,,,,,,,,,,,,,,,,,,,,,,,,,,,,,
,3737916271.65321,200.219696044922,9999.71875,6.73649462156716E-6,1.11561754845144E-8,1,5,14.0008964538574,3.99875806316057,30.239999294281,0.00601838564112398,0.000725799016149296,1,-2.00895119185564E-7,200.096878051758,200.342514038086,9999.71875,9999.71875,50.3310144245726,5.79398484301647,4.64002275466919,70,1,0,0,1,0.267791748046875,27.8592376708984,2,1,1,200.342514038086,0,200.219696044922,,,,,,,,,,,,,,,,,,,,,,,,,,,,,,,,,
,3737916402.00322,206.663520812988,9999.71875,6.75419638944484E-6,1.00901662022564E-8,1,5,14.0008964538574,3.99874155326662,30.2700009196997,0.00603498845882448,0.000722217888154442,1,-2.07588531498176E-7,206.540603637695,206.786437988281,9999.71875,9999.71875,50.2184599178034,5.79429298661764,4.65927457809448,70,1,0,0,1,0.269088745117187,27.8592376708984,2,1,1,206.795776367187,0,206.663520812988,,,,,,,,,,,,,,,,,,,,,,,,,,,,,,,,,
,3737916531.62236,213.114326477051,9999.71875,6.62417804338835E-6,1.05404829053961E-8,1,5,14.0008964538574,3.99872545477376,30.2700009196997,0.00591921295085817,0.000705421838389757,1,-2.06840537225921E-7,212.998001098633,213.230651855469,9999.71875,9999.71875,50.2602770435822,5.79418548292311,4.67998743057251,70,1,0,0,1,0.267486572265625,27.8592376708984,2,1,1,213.230651855469,0,213.114326477051,,,,,,,,,,,,,,,,,,,,,,,,,,,,,,,,,
,3737916661.95562,219.64924621582,9999.71875,6.63877074593309E-6,1.20944794173599E-8,1,5,14.0008964538574,3.99864267302311,30.3000006824732,0.00592988513049767,0.0007213374120126,1,-1.91121645932155E-7,219.547332763672,219.751159667969,9999.71875,9999.71875,50.1164573960438,5.7926138460238,4.70444202423096,69,1,64,0,0,0.270843505859375,27.8592376708984,2,1,1,219.751159667969,0,219.64924621582,,,,,,,,,,,,,,,,,,,,,,,,,,,,,,,,,
,3737916791.57184,226.110038757324,9999.71875,6.50206049814505E-6,1.1391982779453E-8,1,5,14.0008964538574,3.99874786887942,30.3000006824732,0.00580814068345661,0.00070569045490788,1,-1.88110524971781E-7,225.993255615234,226.226821899414,9999.71875,9999.71875,50.2262762029957,5.79457566901234,4.73820495605469,70,1,0,0,1,0.265960693359375,27.8592376708984,2,1,1,226.226821899414,0,226.110038757324,,,,,,,,,,,,,,,,,,,,,,,,,,,,,,,,,
,3737916921.55945,232.57495880127,9999.71875,6.47349765676691E-6,1.17905013930513E-8,1,5,14.0008964538574,3.998725054619,30.3199999034405,0.00578471842383459,0.000688375752072645,1,-2.03259591234763E-7,232.440933227539,232.708984375,9999.71875,9999.71875,50.0672147993322,5.79494105585417,4.78393697738647,70,1,0,0,1,0.269317626953125,27.8592376708984,2,1,1,232.708984375,0,232.57495880127,,,,,,,,,,,,,,,,,,,,,,,,,,,,,,,,,
,3737917052.11941,239.098251342773,9999.71875,6.52749755500069E-6,1.15352866690651E-8,1,5,14.0008964538574,3.99856673824851,30.3399991244078,0.00583127648677692,0.000702869594285521,1,-1.9506509935968E-7,238.977630615234,239.218872070313,9999.71875,9999.71875,50.1739070922072,5.79505495990672,4.83876705169678,70,1,0,0,1,0.268478393554687,27.8592376708984,2,1,1,239.218872070313,0,239.098251342773,,,,,,,,,,,,,,,,,,,,,,,,,,,,,,,,,
,3737917181.87632,245.594276428223,9999.71875,6.49216319119469E-6,1.49856032632293E-8,1,5,14.0008964538574,3.99855314764226,30.3600002080202,0.0058024208305937,0.000680901451057502,1,-2.14428759171206E-7,245.488327026367,245.700225830078,9999.71875,9999.71875,50.2337016739284,5.79398189294789,4.93599510192871,68,1,64,0,0,0.269241333007813,27.8592376708984,2,1,1,245.700225830078,0,245.594276428223,,,,,,,,,,,,,,,,,,,,,,,,,,,,,,,,,
,3737917311.95249,252.074119567871,9999.71875,6.32088507590403E-6,8.71385524448424E-9,1,5,14.0008964538574,3.99858311945201,30.3700007498264,0.0056475841650788,0.000675022191256283,1,-1.95192321208157E-7,251.938858032227,252.209381103516,9999.71875,9999.71875,50.2215864318803,5.79459332156149,7.3306999206543,70,1,0,0,1,0.269241333007813,27.8592376708984,2,1,1,252.209381103516,0,252.074119567871,,,,,,,,,,,,,,,,,,,,,,,,,,,,,,,,,
,3737917441.52627,258.550598144531,9999.71875,6.31512494253281E-6,1.01693854959943E-8,1,5,14.0008964538574,3.99876188533599,30.3899999707937,0.00564165627825001,0.000682297039210417,1,-1.86197378119334E-7,258.432312011719,258.668884277344,9999.71875,9999.71875,50.2297935313322,5.79418616601861,7.51284074783325,70,1,0,0,1,0.268783569335938,27.8592376708984,2,1,1,258.668884277344,0,258.550598144531,,,,,,,,,,,,,,,,,,,,,,,,,,,,,,,,,
,3737917571.54865,265.01025390625,9999.71875,6.29845207978726E-6,9.60175590185621E-9,1,5,14.0008964538574,3.99864153650516,30.4199997335672,0.00562828915169908,0.000668553496205428,1,-1.99096958153842E-7,264.891448974609,265.129058837891,9999.71875,9999.71875,50.0711229419284,5.79488995841731,7.35197877883911,70,1,0,0,1,0.268173217773438,27.8592376708984,2,1,1,265.129058837891,0,265.01025390625,,,,,,,,,,,,,,,,,,,,,,,,,,,,,,,,,
,3737917701.51109,271.506500244141,9999.71875,6.26349329746291E-6,1.01174118960324E-8,1,5,14.0008964538574,3.99877282422994,30.4300002753735,0.00559647070398463,0.000670657470567421,1,-1.9149328988886E-7,271.378295898438,271.634704589844,9999.71875,9999.71875,50.2501158728322,5.79400501531937,7.33980417251587,70,1,0,0,1,0.2716064453125,27.8592376708984,2,1,1,271.634704589844,0,271.506500244141,,,,,,,,,,,,,,,,,,,,,,,,,,,,,,,,,
,3737917831.47827,278.040145874023,9999.71875,6.22637419938993E-6,9.1618706344244E-9,1,5,14.0008964538574,3.99863642936812,30.460000038147,0.00556395319296489,0.000660344388229677,1,-1.97444847258567E-7,277.918334960938,278.161956787109,9999.71875,9999.71875,50.1152849532649,5.79471024265856,7.48685503005981,70,1,0,0,1,0.269012451171875,27.8592376708984,2,1,1,278.161956787109,0,278.040145874023,,,,,,,,,,,,,,,,,,,,,,,,,,,,,,,,,
,3737917962.48032,284.550033569336,9999.71875,6.31408959219918E-6,1.24391545954114E-8,1,5,14.0008964538574,3.99871322712522,30.4799992591143,0.00563995573480388,0.000686584247163495,1,-1.81205740935144E-7,284.460601806641,284.639465332031,9999.71875,9999.71875,50.1285726380918,5.79432000864859,7.82726144790649,69,1,64,0,0,0.267868041992187,27.8592376708984,2,1,1,284.664764404297,0,284.550033569336,,,,,,,,,,,,,,,,,,,,,,,,,,,,,,,,,
,3737918091.46263,290.954193115234,9999.71875,6.11683219277628E-6,1.15578076366188E-8,1,5,14.0008964538574,3.99858156685387,30.4899998009205,0.00546295199966108,0.000668543095019364,1,-1.71673001075546E-7,290.833953857422,291.074432373047,9999.71875,9999.71875,50.1348256662457,5.79609960850121,8.44705772399902,70,1,0,0,1,0.268630981445313,27.8592376708984,2,1,1,291.074432373047,0,290.954193115234,,,,,,,,,,,,,,,,,,,,,,,,,,,,,,,,,
,3737918221.80524,297.502532958984,9999.71875,6.10231893781405E-6,9.07211838616018E-9,1,5,14.0008964538574,3.99855626184932,30.5100008845329,0.00545094144710644,0.000660284271179237,1,-1.7876108853855E-7,297.381988525391,297.623077392578,9999.71875,9999.71875,50.0824565554572,5.79560588024052,9.40309715270996,70,1,0,0,1,0.269927978515625,27.8592376708984,2,1,1,297.623077392578,0,297.502532958984,,,,,,,,,,,,,,,,,,,,,,,,,,,,,,,,,
,3737918351.41941,303.933380126953,9999.71875,6.09962079769872E-6,1.0278870363937E-8,1,5,14.0008964538574,3.99863195602672,30.5499993264675,0.00544866840691944,0.000660194295682531,1,-1.78477367560265E-7,303.808227539063,304.058532714844,9999.71875,9999.71875,50.2215864318803,5.79533054131144,9.38084316253662,70,1,0,0,1,0.269317626953125,27.8592376708984,2,1,1,304.058532714844,0,303.933380126953,,,,,,,,,,,,,,,,,,,,,,,,,,,,,,,,,
,3737918481.44449,310.43830871582,9999.71875,5.99078260501269E-6,1.00753303352111E-8,1,5,14.0008964538574,3.99862203160207,30.5599998682737,0.0053501702110395,0.000656718582284446,1,-1.6595217870569E-7,310.321166992188,310.555450439453,9999.71875,9999.71875,50.1703897638707,5.7956548768734,9.17272281646729,70,1,0,0,1,0.270767211914062,27.8592376708984,2,1,1,310.555450439453,0,310.43830871582,,,,,,,,,,,,,,,,,,,,,,,,,,,,,,,,,
,3737918611.80353,316.919982910156,9999.71875,5.86821093429366E-6,1.29114352167398E-8,1,5,14.0008964538574,3.99861673520223,30.5899996310473,0.00524369374251913,0.000623412653019654,1,-1.84896890357118E-7,316.800476074219,317.039489746094,9999.71875,9999.71875,50.2520699441303,5.79450108855051,9.05403900146484,70,1,0,0,1,0.268173217773438,27.8592376708984,2,1,1,317.039489746094,0,316.919982910156,,,,,,,,,,,,,,,,,,,,,,,,,,,,,,,,,
,3737918741.37516,323.40087890625,9999.71875,5.77597044821291E-6,1.0712812299509E-8,1,5,14.0008964538574,3.99863675933813,30.6000001728535,0.00516107638066151,0.000615173014940348,1,-1.80242456525992E-7,323.282257080078,323.519500732422,9999.71875,9999.71875,50.1469409082938,5.79468916000569,8.96765422821045,70,1,0,0,1,0.270004272460938,27.8592376708984,2,1,1,323.519500732422,0,323.40087890625,,,,,,,,,,,,,,,,,,,,,,,,,,,,,,,,,
,3737918871.73452,329.887435913086,9999.71875,5.66375434354908E-6,1.03868509294664E-8,1,5,14.0008964538574,3.99848091784683,30.6199993938208,0.00506185554619099,0.000594150077794014,1,-1.86899024623835E-7,329.785400390625,329.989471435547,9999.71875,9999.71875,50.2532423869092,5.79403583568246,8.90037441253662,70,1,0,0,1,0.26580810546875,27.8592376708984,2,1,1,329.989471435547,0,329.887435913086,,,,,,,,,,,,,,,,,,,,,,,,,,,,,,,,,
,3737919002.13496,336.397323608398,9999.71875,5.55149649607421E-6,1.12004014342706E-8,1,5,14.0008964538574,3.99842276501797,30.6400004774332,0.00496122511663706,0.000583601098762475,1,-1.81799293951715E-7,336.305725097656,336.488922119141,9999.71875,9999.71875,50.2891972987938,5.79435175707307,8.85178565979004,68,1,64,0,0,0.267257690429687,27.8592376708984,2,1,1,336.488922119141,0,336.397323608398,,,,,,,,,,,,,,,,,,,,,,,,,,,,,,,,,
,3737919131.3692,342.841430664063,9999.71875,5.40481180726721E-6,9.28789927437121E-9,1,5,14.0008964538574,3.99859977462596,30.6599996984005,0.00483101608035559,0.000564657265386955,1,-1.81002866665627E-7,342.718475341797,342.964385986328,9999.71875,9999.71875,50.2055630472361,5.79457639989815,8.82761859893799,70,1,0,0,1,0.26885986328125,27.8592376708984,2,1,1,342.964385986328,0,342.841430664063,,,,,,,,,,,,,,,,,,,,,,,,,,,,,,,,,
,3737919261.32596,349.193954467773,9999.71875,4.99263461429769E-6,9.47034371734162E-9,1,5,14.0008964538574,3.99844467670417,30.6800007820129,0.00446397674694962,0.000510595753210048,1,-1.79532676088262E-7,349.122161865234,349.265747070313,9999.71875,9999.71875,50.2813810136015,5.79467101837363,8.82065391540527,70,1,0,0,1,0.269546508789062,27.8592376708984,6,1,1,349.265747070313,0,349.193954467773,,,,,,,,,,,,,,,,,,,,,,,,,,,,,,,,,
,3737919456.42766,348.725860595703,9999.71875,4.89684422843408E-6,1.10589404858584E-8,1,5,14.0008964538574,3.9983963978165,30.6800007820129,0.00437937418125242,0.000493309846167063,1,-1.84499284669721E-7,348.601409912109,348.850311279297,9999.71875,9999.71875,50.345865366438,5.79506144775348,8.79707050323486,69,1,64,0,0,0.264892578125,27.8592376708984,2,1,1,348.601409912109,0,348.725860595703,,,,,,,,,,,,,,,,,,,,,,,,,,,,,,,,,
,3737919586.81122,342.028533935547,9999.71875,5.05135516549983E-6,9.89296753424333E-9,1,5,14.0008964538574,3.99845392853718,30.6700002402067,0.00451710835097013,0.000512547976864176,1,-1.86204090166712E-7,341.918640136719,342.138427734375,9999.71875,9999.71875,50.2266670172553,5.79431931928132,8.75744342803955,70,1,0,0,1,0.26580810546875,27.8592376708984,2,1,1,341.918640136719,0,342.028533935547,,,,,,,,,,,,,,,,,,,,,,,,,,,,,,,,,
,3737919716.35397,335.542434692383,9999.71875,4.88646662045804E-6,1.01409466800249E-8,1,5,14.0008964538574,3.99834490827922,30.6400004774332,0.00436889519642006,0.000499595400257949,1,-1.7585288324049E-7,335.427673339844,335.657196044922,9999.71875,9999.71875,50.2579321580245,5.79557374381857,8.71998882293701,68,1,64,0,0,0.269317626953125,27.8592376708984,2,1,1,335.427673339844,0,335.542434692383,,,,,,,,,,,,,,,,,,,,,,,,,,,,,,,,,
,3737919846.33786,329.006240844727,9999.71875,4.9999926272067E-6,1.05322051823081E-8,1,5,14.0008964538574,3.99825434635395,30.6199993938208,0.00447093710788841,0.000506533254711078,1,-1.85168464909211E-7,328.880950927734,329.131530761719,9999.71875,9999.71875,50.2430812161592,5.79554320216189,8.660080909729,70,1,0,0,1,0.26641845703125,27.8592376708984,2,1,1,328.880950927734,0,329.006240844727,,,,,,,,,,,,,,,,,,,,,,,,,,,,,,,,,
,3737919976.64592,322.495513916016,9999.71875,5.62630030000413E-6,9.70934574196319E-9,1,5,14.0008964538574,3.99832052848597,30.6199993938208,0.00502887202767499,0.000584804116644776,1,-1.91712175272515E-7,322.408874511719,322.582153320313,9999.71875,9999.71875,50.2211956176207,5.79602258123889,8.6100959777832,70,1,0,0,1,0.266189575195313,27.8592376708984,2,1,1,322.408874511719,0,322.495513916016,,,,,,,,,,,,,,,,,,,,,,,,,,,,,,,,,
,3737920106.28746,316.037734985352,9999.71875,5.85353325511647E-6,1.36098558858586E-8,1,5,14.0008964538574,3.99830023073016,30.6000001728535,0.00523007891720739,0.00062070572734266,1,-1.85636691246121E-7,315.905426025391,316.170043945313,9999.71875,9999.71875,50.2383914450438,5.79582974798151,8.55852031707764,70,1,0,0,1,0.265121459960938,27.8592376708984,2,1,1,315.905426025391,0,316.037734985352,,,,,,,,,,,,,,,,,,,,,,,,,,,,,,,,,
,3737920236.67218,309.533889770508,9999.71875,6.02858347229629E-6,9.89641705403715E-9,1,5,14.0008964538574,3.9982500238753,30.579999089241,0.00538502693406831,0.000648196759356042,1,-1.81132561341142E-7,309.425720214844,309.642059326172,9999.71875,9999.71875,50.2118160753899,5.79652306944749,8.52257823944092,68,1,64,0,0,0.266494750976562,27.8592376708984,2,1,1,309.425720214844,0,309.533889770508,,,,,,,,,,,,,,,,,,,,,,,,,,,,,,,,,
,3737920366.30929,303.033050537109,9999.71875,6.28018170266713E-6,1.51014147226748E-8,1,5,14.0008964538574,3.99826732840196,30.5599998682737,0.00561135411335912,0.000664995591570972,1,-2.0022770882188E-7,302.906219482422,303.159881591797,9999.71875,9999.71875,50.1637459214572,5.79527835071852,8.51152229309082,70,1,0,0,1,0.269393920898438,27.8592376708984,2,1,1,302.906219482422,0,303.033050537109,,,,,,,,,,,,,,,,,,,,,,,,,,,,,,,,,
,3737920496.59402,296.55207824707,9999.71875,6.45849418999549E-6,9.56102637106706E-9,1,5,14.0008964538574,3.99826350935021,30.5400006473064,0.00576842485774459,0.000698733770285834,1,-1.89203651909491E-7,296.42431640625,296.679840087891,9999.71875,9999.71875,50.2809901993419,5.79585568805387,8.47573947906494,70,1,0,0,1,0.266265869140625,27.8592376708984,2,1,1,296.42431640625,0,296.55207824707,,,,,,,,,,,,,,,,,,,,,,,,,,,,,,,,,
,3737920626.23885,290.060592651367,9999.71875,6.67473818094035E-6,9.95681494418487E-9,1,5,14.0008964538574,3.99823273903256,30.519999563694,0.00596162301241993,0.000721243297590294,1,-1.96524501982899E-7,289.943115234375,290.178070068359,9999.71875,9999.71875,50.2352649309669,5.79587597722294,8.39621448516846,70,1,0,0,1,0.266494750976562,27.8592376708984,2,1,1,289.943115234375,0,290.060592651367,,,,,,,,,,,,,,,,,,,,,,,,,,,,,,,,,
,3737920756.18525,283.585083007813,9999.71875,7.25284197404588E-6,2.92458459832512E-8,1,5,14.0008964538574,3.99812564496196,30.519999563694,0.00647387319118515,0.000808937494237023,1,-1.85136830190034E-7,283.468475341797,283.701690673828,9999.71875,9999.71875,50.1899304768515,5.79621806592764,8.25313568115234,70,1,0,0,1,0.270462036132813,27.8592376708984,2,1,1,283.468475341797,0,283.585083007813,,,,,,,,,,,,,,,,,,,,,,,,,,,,,,,,,
,3737920886.57382,277.064071655273,9999.71875,7.37986383003942E-6,3.33187814234544E-8,1,5,14.0008964538574,3.99822275608181,30.5000003427267,0.00658722292142963,0.000825024821670829,1,-1.86255750643296E-7,276.967315673828,277.160827636719,9999.71875,9999.71875,50.2567597152457,5.79497400529558,8.17973232269287,69,1,64,0,0,0.267181396484375,27.8592376708984,2,1,1,276.967315673828,0,277.064071655273,,,,,,,,,,,,,,,,,,,,,,,,,,,,,,,,,
,3737921016.1706,270.594863891602,9999.71875,7.52239170847614E-6,3.97187018057473E-8,1,5,14.0008964538574,3.9982039356333,30.4799992591143,0.0067146632174862,0.000839155894010322,1,-1.91873142848322E-7,270.477783203125,270.711944580078,9999.71875,9999.71875,50.2974043982457,5.79515891992808,8.10771465301514,70,1,0,0,1,0.266494750976562,27.8592376708984,2,1,1,270.477783203125,0,270.594863891602,,,,,,,,,,,,,,,,,,,,,,,,,,,,,,,,,
,3737921146.56944,264.084426879883,9999.71875,7.64806053540094E-6,5.12789083504051E-8,1,5,14.0008964538574,3.99825669124941,30.460000038147,0.00682922525219229,0.000838332322643898,1,-2.11790377647514E-7,263.960174560547,264.208679199219,9999.71875,9999.71875,50.3493826947746,5.79414853853044,8.0093879699707,70,1,0,0,1,0.266494750976562,27.8592376708984,2,1,1,263.960174560547,0,264.084426879883,,,,,,,,,,,,,,,,,,,,,,,,,,,,,,,,,
,3737921276.13736,257.606521606445,9999.71875,7.74843199655301E-6,5.11120767795763E-8,1,5,14.0008964538574,3.99816667588559,30.4400008171797,0.006915434813544,0.000870283627208391,1,-1.90975569430103E-7,257.479736328125,257.733306884766,9999.71875,9999.71875,50.2344833024476,5.79453356679649,7.92398691177368,70,1,0,0,1,0.269622802734375,27.8592376708984,2,1,1,257.479736328125,0,257.606521606445,,,,,,,,,,,,,,,,,,,,,,,,,,,,,,,,,
,3737921406.83344,251.109336853027,9999.71875,7.8982127144866E-6,7.84420222654987E-8,1,5,14.0008964538574,3.99822832192964,30.4199997335672,0.00705062488437146,0.000878264327819066,1,-2.04635749633573E-7,250.993103027344,251.225570678711,9999.71875,9999.71875,50.3146002256688,5.79430483561847,7.85142803192139,68,1,64,0,0,0.266342163085938,27.8592376708984,2,1,1,250.993103027344,0,251.109336853027,,,,,,,,,,,,,,,,,,,,,,,,,,,,,,,,,
,3737921536.11897,244.624397277832,9999.71875,8.11956326853368E-6,7.51570091867087E-8,1,5,14.0008964538574,3.99810983758074,30.409999191761,0.00724952275477282,0.000891944925837902,1,-2.22618646337459E-7,244.505310058594,244.74348449707,9999.71875,9999.71875,50.1571020790438,5.79439214034306,7.81144237518311,70,1,0,0,1,0.267715454101562,27.8592376708984,2,1,1,244.505310058594,0,244.624397277832,,,,,,,,,,,,,,,,,,,,,,,,,,,,,,,,,
,3737921666.13656,238.119400024414,9999.71875,8.19567241718268E-6,9.49616400108798E-8,1,5,14.0008964538574,3.99809437993042,30.3899999707937,0.00731627213259991,0.000907979212081962,1,-2.16068972377319E-7,238.000778198242,238.238021850586,9999.71875,9999.71875,50.244253658938,5.79457817673668,7.76952314376831,70,1,0,0,1,0.270767211914062,27.8592376708984,2,1,1,238.000778198242,0,238.119400024414,,,,,,,,,,,,,,,,,,,,,,,,,,,,,,,,,
,3737921796.42758,231.627326965332,9999.71875,8.29312789619246E-6,3.56692099013854E-8,1,5,14.0008964538574,3.99800664648596,30.3700007498264,0.00740542582568952,0.00090275001912385,1,-2.36626519114151E-7,231.524505615234,231.73014831543,9999.71875,9999.71875,50.2270578315149,5.79552228651875,7.73909187316895,70,1,0,0,1,0.26702880859375,27.8592376708984,2,1,1,231.524505615234,0,231.627326965332,,,,,,,,,,,,,,,,,,,,,,,,,,,,,,,,,
,3737921926.08146,225.127731323242,9999.71875,8.66044399596399E-6,4.2478794948155E-8,1,5,14.0008964538574,3.9980266976188,30.3700007498264,0.00772973124724778,0.000967614351595587,1,-2.19133298804749E-7,225.013580322266,225.241882324219,9999.71875,9999.71875,50.2489434300534,5.79473284571649,7.63586378097534,70,1,0,0,1,0.2655029296875,27.8592376708984,2,1,1,225.013580322266,0,225.127731323242,,,,,,,,,,,,,,,,,,,,,,,,,,,,,,,,,
,3737922056.42454,218.605545043945,9999.71875,8.67799261351193E-6,4.17235233468736E-8,1,5,14.0008964538574,3.99820207643452,30.349999666214,0.0077397353040985,0.00101071826188297,1,-1.73383643745248E-7,218.522674560547,218.688415527344,9999.71875,9999.71875,50.3251522106784,5.7943211086396,7.59850883483887,68,1,64,0,0,0.265121459960938,27.8592376708984,2,1,1,218.522674560547,0,218.605545043945,,,,,,,,,,,,,,,,,,,,,,,,,,,,,,,,,
,3737922186.07714,212.183059692383,9999.71875,8.67530483036658E-6,4.5287960352125E-8,1,5,14.0008964538574,3.99809986061672,30.3300004452467,0.00774562862695268,0.000953355300244669,1,-2.37444988755266E-7,212.067337036133,212.298782348633,9999.71875,9999.71875,50.1739070922072,5.79443841627,7.56254434585571,70,1,0,0,1,0.265121459960938,27.8592376708984,2,1,1,212.067337036133,0,212.183059692383,,,,,,,,,,,,,,,,,,,,,,,,,,,,,,,,,
,3737922316.08334,205.645942687988,9999.71875,8.79397725972747E-6,3.81140537744433E-8,1,5,14.0008964538574,3.99821822058466,30.3199999034405,0.00784856740045005,0.000988879646652012,1,-2.15459936613612E-7,205.529556274414,205.762329101562,9999.71875,9999.71875,50.2004824618611,5.79467195586381,7.52270984649658,70,1,0,0,1,0.266571044921875,27.8592376708984,2,1,1,205.529556274414,0,205.645942687988,,,,,,,,,,,,,,,,,,,,,,,,,,,,,,,,,
,3737922446.05352,199.170356750488,9999.71875,8.75332514418015E-6,5.05602739850911E-8,1,5,14.0008964538574,3.99819366106203,30.3000006824732,0.00780826162258137,0.00101044740813672,1,-1.85056765346987E-7,199.050537109375,199.290176391602,9999.71875,9999.71875,50.2884156702746,5.79458790516641,7.46841382980347,70,1,0,0,1,0.266036987304687,27.8592376708984,2,1,1,199.050537109375,0,199.170356750488,,,,,,,,,,,,,,,,,,,,,,,,,,,,,,,,,
,3737922575.99459,192.701309204102,9999.71875,8.70471364240681E-6,5.82895342238433E-8,1,5,14.0008964538574,3.99836057763547,30.2799995988607,0.00776842390752109,0.000984976428504912,1,-2.0643703100373E-7,192.58137512207,192.821243286133,9999.71875,9999.71875,50.1488949795918,5.79389488637526,7.42309951782227,70,1,0,0,1,0.270614624023438,27.8592376708984,2,1,1,192.58137512207,0,192.701309204102,,,,,,,,,,,,,,,,,,,,,,,,,,,,,,,,,
,3737922706.60725,186.178291320801,9999.71875,8.6328764398589E-6,8.50103302317072E-8,1,5,14.0008964538574,3.99829919766857,30.2600003778934,0.00770622150055453,0.000962935441889324,1,-2.20351731519309E-7,186.049011230469,186.307571411133,9999.71875,9999.71875,50.2172874750245,5.79361969310413,7.37483882904053,70,1,0,0,1,0.266494750976562,27.8592376708984,2,1,1,186.049011230469,0,186.178291320801,,,,,,,,,,,,,,,,,,,,,,,,,,,,,,,,,
,3737922835.97528,179.716796875,9999.71875,8.90738934359214E-6,8.08274127708948E-8,1,5,14.0008964538574,3.9983497373928,30.2600003778934,0.00795013708951168,0.00100212995916837,1,-2.17738668212407E-7,179.601104736328,179.832489013672,9999.71875,9999.71875,50.208689561313,5.79361617896025,7.3038272857666,70,1,0,0,1,0.26580810546875,27.8592376708984,2,1,1,179.601104736328,0,179.716796875,,,,,,,,,,,,,,,,,,,,,,,,,,,,,,,,,
,3737922966.21054,173.192817687988,9999.71875,8.84530211040574E-6,7.07273445343985E-8,1,5,14.0008964538574,3.99841470077431,30.239999294281,0.00789553530057539,0.000991140230671259,1,-2.20753169287059E-7,173.069946289062,173.315689086914,9999.71875,9999.71875,50.1074686680726,5.79355134445404,7.26809215545654,70,1,0,0,1,0.2655029296875,27.8592376708984,2,1,1,173.069946289062,0,173.192817687988,,,,,,,,,,,,,,,,,,,,,,,,,,,,,,,,,
,3737923095.98042,166.738090515137,9999.71875,8.93158922942868E-6,6.99865005294392E-8,1,5,14.0008964538574,3.99833262841674,30.2300006151199,0.0079728979356516,0.000996790151125713,1,-2.27389109007605E-7,166.614379882813,166.861801147461,9999.71875,9999.71875,50.1656999927553,5.79424587902226,7.24705982208252,70,1,0,0,1,0.27008056640625,27.8592376708984,2,1,1,166.614379882813,0,166.738090515137,,,,,,,,,,,,,,,,,,,,,,,,,,,,,,,,,
,3737923226.04412,160.212989807129,9999.71875,8.9360650243693E-6,3.26330487963751E-8,1,5,14.0008964538574,3.99830417203173,30.2099995315075,0.00797884888395144,0.000983724185300863,1,-2.42745542126953E-7,160.09944152832,160.326538085938,9999.71875,9999.71875,50.1664816212745,5.79398377099336,4.98625373840332,70,1,0,0,1,0.269851684570313,27.8592376708984,2,1,1,160.09944152832,0,160.212989807129,,,,,,,,,,,,,,,,,,,,,,,,,,,,,,,,,
,3737923355.98434,153.734580993652,9999.71875,8.84958121344328E-6,3.1538575732734E-8,1,5,14.0008964538574,3.99830420394203,30.1900003105402,0.00790061721392477,0.000980907063168511,1,-2.32857833638361E-7,153.6123046875,153.856857299805,9999.71875,9999.71875,50.1516306794092,5.79452974464182,4.95466279983521,70,1,0,0,1,0.26641845703125,27.8592376708984,2,1,1,153.6123046875,0,153.734580993652,,,,,,,,,,,,,,,,,,,,,,,,,,,,,,,,,
,3737923485.9761,147.25220489502,9999.71875,9.06606158155246E-6,3.01512997466612E-8,1,5,14.0008964538574,3.9983180463322,30.1900003105402,0.00809288096091961,0.00101184708445653,1,-2.30750411682646E-7,147.119613647461,147.384796142578,9999.71875,9999.71875,50.2274486457745,5.79435250594903,4.93094778060913,68,1,64,0,0,0.265579223632813,27.8592376708984,2,1,1,147.119613647461,0,147.25220489502,,,,,,,,,,,,,,,,,,,,,,,,,,,,,,,,,
,3737923616.25913,140.740493774414,9999.71875,8.94554104425309E-6,3.73663606220135E-8,1,5,14.0008964538574,3.99831673306805,30.1699992269278,0.00798579869809014,0.000995047664014007,1,-2.31447714365864E-7,140.627105712891,140.853881835938,9999.71875,9999.71875,50.2809901993419,5.79406552389004,4.8938684463501,70,1,0,0,1,0.268936157226562,27.8592376708984,2,1,1,140.627105712891,0,140.740493774414,,,,,,,,,,,,,,,,,,,,,,,,,,,,,,,,,
,3737923745.94987,134.230918884277,9999.71875,9.1880753554667E-6,4.02654364333509E-8,1,5,14.0008964538574,3.99824526994876,30.1699992269278,0.00820268618360769,0.00101796950741106,1,-2.42251575067032E-7,134.109039306641,134.352798461914,9999.71875,9999.71875,50.1434235799572,5.794396951014,4.86480569839478,70,1,0,0,1,0.269775390625,27.8592376708984,2,1,1,134.109039306641,0,134.230918884277,,,,,,,,,,,,,,,,,,,,,,,,,,,,,,,,,
,3737923876.01043,127.760353088379,9999.71875,9.06464991292256E-6,4.22156724074915E-8,1,5,14.0008964538574,3.99828034453744,30.1500000059605,0.00809158819094281,0.00101108402554393,1,-2.31378298358813E-7,127.632354736328,127.88835144043,9999.71875,9999.71875,50.1699989496111,5.79427382984491,4.83554553985596,70,1,0,0,1,0.269622802734375,27.8592376708984,2,1,1,127.632354736328,0,127.760353088379,,,,,,,,,,,,,,,,,,,,,,,,,,,,,,,,,
,3737924025.8529,120.283073425293,9999.71875,8.98628289971411E-6,6.00358611471372E-8,1,5,14.0008964538574,3.99824154194366,30.1300007849932,0.00802210866848963,0.000998357754448136,1,-2.33842104710927E-7,120.156997680664,120.409149169922,9999.71875,9999.71875,50.0488465291303,5.79468268426601,4.8027172088623,70,1,0,0,1,0.266036987304687,27.8592376708984,2,1,1,120.156997680664,0,120.283073425293,,,,,,,,,,,,,,,,,,,,,,,,,,,,,,,,,
,3737924156.52878,113.718818664551,9999.71875,9.20235792742249E-6,7.60013551774788E-8,1,5,14.0008964538574,3.99817282955945,30.1300007849932,0.00821760536976955,0.0010035854449967,1,-2.60551219039407E-7,113.596466064453,113.841171264648,9999.71875,9999.71875,50.101997268438,5.79462420966477,4.76670503616333,70,1,0,0,1,0.266494750976562,27.8592376708984,2,1,1,113.596466064453,0,113.718818664551,,,,,,,,,,,,,,,,,,,,,,,,,,,,,,,,,
,3737924285.84367,107.244121551514,9999.71875,9.23028683074536E-6,3.92209422541273E-8,1,5,14.0008964538574,3.99824752662023,30.120000243187,0.00824120214620264,0.00101718814350894,1,-2.49503638036571E-7,107.13404083252,107.354202270508,9999.71875,9999.71875,50.2860707847169,5.79471561989006,4.74089050292969,70,1,0,0,1,0.265884399414062,27.8592376708984,2,1,1,107.13404083252,0,107.244121551514,,,,,,,,,,,,,,,,,,,,,,,,,,,,,,,,,
,3737924415.94201,100.751831054688,9999.71875,9.29020483768273E-6,1.70676203017441E-8,1,5,14.0008964538574,3.99825097339913,30.1099997013807,0.00829420638602336,0.00102713499679,1,-2.47364450452967E-7,100.637298583984,100.866363525391,9999.71875,9999.71875,50.2243221316976,5.79408559476976,4.70056104660034,70,1,0,0,1,0.26580810546875,27.8592376708984,2,1,1,100.637298583984,0,100.751831054688,,,,,,,,,,,,,,,,,,,,,,,,,,,,,,,,,
,3737924545.84755,94.2866287231445,9999.71875,9.3197099829179E-6,3.30471805399785E-8,1,5,14.0008964538574,3.99836690177254,30.0999991595745,0.00831797614479811,0.00105003322472944,1,-2.26122205954337E-7,94.1755981445313,94.3976593017578,9999.71875,9999.71875,50.0961350545438,5.79394192320347,4.66501379013062,70,1,0,0,1,0.26641845703125,27.8592376708984,2,1,1,94.1755981445313,0,94.2866287231445,,,,,,,,,,,,,,,,,,,,,,,,,,,,,,,,,
,3737924675.84847,87.7474899291992,9999.71875,9.1216841050678E-6,3.20220728911566E-8,1,5,14.0008964538574,3.99824481345609,30.0799999386072,0.0081428913533113,0.00101407367023834,1,-2.36610038649272E-7,87.6212158203125,87.8737640380859,9999.71875,9999.71875,50.0922269119476,5.79375714805588,4.63399744033814,70,1,0,0,1,0.27008056640625,27.8592376708984,2,1,1,87.6212158203125,0,87.7474899291992,,,,,,,,,,,,,,,,,,,,,,,,,,,,,,,,,
,3737924830.78318,80.0307502746582,9999.71875,9.24500386279022E-6,4.13326054031486E-8,1,5,14.0008964538574,3.99827129852408,30.0799999386072,0.00825327598740846,0.00102640086434245,1,-2.41375788011479E-7,79.9106292724609,80.1508712768555,9999.71875,9999.71875,50.1922753624092,5.79391008996134,4.59658622741699,70,1,0,0,1,0.268936157226562,27.8592376708984,2,1,1,79.9106292724609,0,80.0307502746582,,,,,,,,,,,,,,,,,,,,,,,,,,,,,,,,,
,3737924960.9772,73.466423034668,9999.71875,9.04925477677873E-6,5.02378048425936E-8,1,5,14.0008964538574,3.99817489951184,30.0600007176399,0.00807804283774258,0.00100576659921541,1,-2.34986455756504E-7,73.3456497192383,73.5871963500977,9999.71875,9999.71875,50.2251037602168,5.79528872271333,4.56366205215454,70,1,0,0,1,0.269622802734375,27.8592376708984,2,1,1,73.3456497192383,0,73.466423034668,,,,,,,,,,,,,,,,,,,,,,,,,,,,,,,,,
,3737925090.77635,66.9568634033203,9999.71875,9.17060941981661E-6,8.69925676789941E-8,1,5,14.0008964538574,3.99820051731586,30.0600007176399,0.00818829896515437,0.0010070618295941,1,-2.51861307171921E-7,66.8302764892578,67.0834503173828,9999.71875,9999.71875,50.1473317225534,5.79467623778011,4.53433561325073,70,1,0,0,1,0.26611328125,27.8592376708984,2,1,1,66.8302764892578,0,66.9568634033203,,,,,,,,,,,,,,,,,,,,,,,,,,,,,,,,,
,3737925220.73948,60.4003028869629,9999.71875,9.19593729443824E-6,7.74850112468726E-8,1,5,14.0008964538574,3.99821858064511,30.0600007176399,0.00821097855936758,0.00100981386738815,1,-2.5259807001877E-7,60.2958717346191,60.5047340393066,9999.71875,9999.71875,50.1016064541784,5.79465511995608,4.49498796463013,70,1,0,0,1,0.267410278320313,27.8592376708984,2,1,1,60.2958717346191,0,60.4003028869629,,,,,,,,,,,,,,,,,,,,,,,,,,,,,,,,,
,3737925351.12403,53.8476219177246,9999.71875,8.86239887047792E-6,2.0028739499748E-8,1,5,14.0008964538574,3.99812509218431,30.0399996340275,0.00791375759259894,0.000967268777566631,1,-2.50052150914563E-7,53.7560729980469,53.9391708374023,9999.71875,9999.71875,50.234092488188,5.79488809814506,4.44294118881226,70,1,0,0,1,0.264892578125,27.8592376708984,2,1,1,53.7560729980469,0,53.8476219177246,,,,,,,,,,,,,,,,,,,,,,,,,,,,,,,,,
,3737925505.83556,46.0628395080566,9999.71875,8.79178874189325E-6,1.62757353252884E-8,1,5,14.0008964538574,3.99817792362065,30.0399996340275,0.00785397402149022,0.000939028624072742,1,-2.71175059746948E-7,45.9376945495605,46.1879844665527,9999.71875,9999.71875,50.1813325631399,5.79432832884118,4.37226104736328,70,1,0,0,1,0.270538330078125,27.8592376708984,2,1,1,45.9376945495605,0,46.0628395080566,,,,,,,,,,,,,,,,,,,,,,,,,,,,,,,,,
,3737925635.70964,39.5228939056396,9999.71875,8.67454127808169E-6,1.365197544703E-8,1,5,14.0008964538574,3.99822520569695,30.0399996340275,0.00774953890492402,0.000925467278339482,1,-2.68746154567356E-7,39.3905639648438,39.6552238464355,9999.71875,9999.71875,50.2039997901976,5.79454160206459,4.2993311882019,70,1,0,0,1,0.269622802734375,27.8592376708984,2,1,1,39.3905639648438,0,39.5228939056396,,,,,,,,,,,,,,,,,,,,,,,,,,,,,,,,,
,3737925765.7132,32.973840713501,9999.71875,8.40119753998175E-6,1.26518799886027E-8,1,5,14.0008964538574,3.99816478432498,30.0399996340275,0.00750419899297446,0.000902662159936007,1,-2.5310379328534E-7,32.8357086181641,33.1119728088379,9999.71875,9999.71875,50.1653091784957,5.79433412855101,4.20468902587891,70,1,0,0,1,0.264816284179687,27.8592376708984,2,1,1,32.8357086181641,0,32.973840713501,,,,,,,,,,,,,,,,,,,,,,,,,,,,,,,,,
,3737925896.32484,26.4360275268555,9999.71875,7.55673244648595E-6,2.21070106171125E-8,1,5,14.0008964538574,3.99811045288651,30.0200004130602,0.00675624926653536,0.00076886798493957,1,-2.76071296019533E-7,26.3020820617676,26.5699729919434,9999.71875,9999.71875,50.1641367357168,5.7945805589096,4.05838203430176,70,1,0,0,1,0.26580810546875,27.8592376708984,2,1,1,26.3020820617676,0,26.4360275268555,,,,,,,,,,,,,,,,,,,,,,,,,,,,,,,,,
,3737926025.70094,19.9728298187256,9999.71875,6.64022999652333E-6,1.85518957813441E-8,1,5,14.0008964538574,3.99840815677234,30.0200004130602,0.00594181057143162,0.000647389595036251,1,-2.74421485426963E-7,19.8558521270752,20.089807510376,9999.71875,9999.71875,50.1102043678899,5.79276245569362,3.79449558258057,70,1,0,0,1,0.272140502929687,27.8592376708984,2,1,1,19.8558521270752,0,19.9728298187256,,,,,,,,,,,,,,,,,,,,,,,,,,,,,,,,,
,3737926181.06865,12.337254524231,9999.71875,4.09884206898335E-6,2.32025349018974E-8,1,5,14.0008964538574,3.9984214757019,30.0200004130602,0.00367956561970804,0.000321319106261483,1,-2.5744219837932E-7,12.2352542877197,12.4392547607422,9999.71875,9999.71875,50.2434720304188,5.79271433414553,3.29081058502197,70,1,0,0,1,0.264739990234375,27.8592376708984,2,1,1,12.2352542877197,0,12.337254524231,,,,,,,,,,,,,,,,,,,,,,,,,,,,,,,,,
,3737926310.69124,6.19507527351379,9999.71875,-2.18094794861597E-6,1.76173177991399E-8,1,5,14.0008964538574,3.99840804814741,30.0200004130602,-0.00190666474326027,-0.000509998296517724,1,-2.4426112429465E-7,6.08127927780151,6.30887126922607,9999.71875,9999.71875,50.1215379814188,5.79318714078745,2.75499200820923,70,1,0,0,1,0.26947021484375,27.8592376708984,6,1,1,6.06718063354492,0,6.19507527351379,,,,,,,,,,,,,,,,,,,,,,,,,,,,,,,,,
,3737926440.63806,2.87091624736786,9999.71875,-1.36670719647504E-5,1.13615975461911E-8,1,5,14.0008964538574,3.99839111469441,30.0299990922213,-0.0121214530900365,-0.00204809432203471,1,-2.39923480724547E-7,2.87000727653503,2.87182521820068,9999.71875,9999.71875,50.3321868673515,5.79350322072229,1.96664381027222,70,1,0,0,1,0.267410278320313,27.8592376708984,6,1,1,2.87000727653503,0,2.87091624736786,,,,,,,,,,,,,,,,,,,,,,,,,,,,,,,,,
,3737926570.61777,2.85190522670746,9999.71875,-1.38654900272715E-5,1.04429518403287E-8,1,5,14.0008964538574,3.99845292675748,30.0200004130602,-0.0122984535595122,-0.00207312153833381,1,-2.38056110570148E-7,2.85149526596069,2.85231518745422,9999.71875,9999.71875,50.3685325934957,5.79285791047377,1.97338736057282,70,1,0,0,1,0.268020629882813,27.8592376708984,6,1,1,2.85149526596069,0,2.85190522670746,,,,,,,,,,,,,,,,,,,,,,,,,,,,,,,,,
,3737926700.60192,2.79620468616486,9999.71875,-1.40146100396543E-5,1.23923938211203E-8,1,5,14.0008964538574,3.99849628098871,30.0200004130602,-0.0124318999606458,-0.00208906515364231,1,-2.33432564809495E-7,2.79076075553894,2.80164861679077,9999.71875,9999.71875,50.2942778841688,5.79329494976529,1.96867871284485,70,1,0,0,1,0.264739990234375,27.8592376708984,6,1,1,2.79076075553894,0,2.79620468616486,,,,,,,,,,,,,,,,,,,,,,,,,,,,,,,,,
,3737926830.60838,2.78284513950348,9999.71875,-1.40208496027741E-5,1.09377660369777E-8,1,5,14.0008964538574,3.99849620611689,30.0200004130602,-0.0124385007079617,-0.00208293241734928,1,-2.25594585617029E-7,2.78092217445374,2.78476810455322,9999.71875,9999.71875,50.2622311148803,5.79308129728541,1.97197449207306,70,1,0,0,1,0.26641845703125,27.8592376708984,6,1,1,2.78092217445374,0,2.78284513950348,,,,,,,,,,,,,,,,,,,,,,,,,,,,,,,,,
,3737926960.55949,2.04424345493317,9999.71875,-1.78454553730567E-5,1.69574207797893E-8,1,5,14.0008964538574,3.99849391656295,30.0299990922213,-0.0158416694519523,-0.00258347646859164,1,-2.11077588560675E-7,2.02167367935181,2.06681323051453,9999.71875,9999.71875,50.264576000438,5.79363791613333,1.69486021995544,70,1,0,0,1,0.268478393554687,27.8592376708984,2,1,1,2.02167367935181,0,2.04424345493317,,,,,,,,,,,,,,,,,,,,,,,,,,,,,,,,,
,3737927030.85276,1.99942249059677,9999.71875,-1.90604332325611E-5,1.07707277267636E-8,1,5,14.0008964538574,3.99845609797126,30.0200004130602,-0.0169184745277983,-0.00276921662289608,1,-2.36569853710921E-7,1.99871385097504,2.00013113021851,9999.71875,9999.71875,50.2528515726495,5.79357657643188,1.67641854286194,70,1,0,0,1,0.27130126953125,27.8592376708984,1,1,1,1.99871385097504,0,1.99942249059677,,,,,,,,,,,,,,,,,,,,,,,,,,,,,,,,,