File: data/brass-holder/180611_MT_brass-empty-powder-container_5T.dat
[Header]
; MPMS3 Data File (default extension .dat)
; Copyright (c) 2007, Quantum Design, Inc. All rights reserved.
TITLE,
FILEOPENTIME,3737929462.55623,06/12/2018,2:47 am
BYAPP,MPMS3,1.0,1.1
INFO,MPMS3 Measurement Release 1.1.16 Build 388, MultiVu Release 2.3.4.15,APPNAME
INFO,0,MOMENT_UNITS
INFO,empty brass,SAMPLE_MATERIAL
INFO,,SAMPLE_COMMENT
INFO,1,SAMPLE_MASS
INFO,,SAMPLE_VOLUME
INFO,,SAMPLE_MOLECULAR_WEIGHT
INFO,,SAMPLE_SIZE
INFO,,SAMPLE_SHAPE
INFO,Brass,SAMPLE_HOLDER
INFO,Standard,SAMPLE_HOLDER_DETAIL
INFO,65.32,SAMPLE_OFFSET
DATATYPE,COMMENT,1
DATATYPE,TIME,2
STARTUPAXIS,X,2
STARTUPAXIS,Y1,5
FIELDGROUP, VSM,2,3,4,5,6,8,9,10,11,14,15
FIELDGROUP, DC, 2,3,4,14,34,35,36,37,38,39,40,41,42,43,44,45,46,47
STARTUPGROUP, All
[Data]
Comment,Time Stamp (sec),Temperature (K),Magnetic Field (Oe),Moment (emu),M. Std. Err. (emu),Transport Action,Averaging Time (sec),Frequency (Hz),Peak Amplitude (mm),Center Position (mm),Lockin Signal' (V),Lockin Signal (V),Range,M. Quad. Signal (emu),Min. Temperature (K),Max. Temperature (K),Min. Field (Oe),Max. Field (Oe),Mass (grams),Motor Lag (deg),Pressure (Torr),Measure Count,Measurement Number,SQUID Status (code),Motor Status (code),Measure Status (code),Motor Current (amps),Motor Temp. (C),Temp. Status (code),Field Status (code),Chamber Status (code),Chamber Temp (K),Redirection State,Average Temp (K),Rotation Angle (deg),Rotator state,DC Moment Fixed Ctr (emu),DC Moment Err Fixed Ctr (emu),DC Moment Free Ctr (emu),DC Moment Err Free Ctr (emu),DC Fixed Fit,DC Free Fit,DC Calculated Center (mm),DC Calculated Center Err (mm),DC Scan Length (mm),DC Scan Time (s),DC Number of Points,DC Squid Drift,DC Min V (V),DC Max V (V),DC Scans per Measure,Map 01,Map 02,Map 03,Map 04,Map 05,Map 06,Map 07,Map 08,Map 09,Map 10,Map 11,Map 12,Map 13,Map 14,Map 15,Map 16
,3737929668.63925,2.0000364780426,49999.6640625,-3.87032678315472E-5,5.53926965823633E-8,1,5,14.0008964538574,4.00574317859027,30.0299990922213,-0.0343869913576429,-0.00608209296009038,1,-9.76726890645472E-7,2.0000364780426,2.0000364780426,49999.6640625,49999.6640625,51.2705319046881,5.79337760144348,1.6492520570755,70,1,0,0,1,0.268020629882813,27.8592376708984,1,1,1,2.0000364780426,0,2.0000364780426,,,,,,,,,,,,,,,,,,,,,,,,,,,,,,,,,
,3737929785.70407,6.86450171470642,49999.6640625,-1.12871252580013E-5,1.24960710454279E-7,1,5,14.0008964538574,3.99865836876724,30.0200004130602,-0.00989705018828906,-0.00245124594144938,1,-1.05226381158433E-6,6.76752710342407,6.96147632598877,49999.6640625,49999.6640625,50.7050236710246,5.79405210351993,2.81926083564758,70,1,0,0,1,0.268020629882813,27.8592376708984,6,1,1,6.96147632598877,0,6.86450171470642,,,,,,,,,,,,,,,,,,,,,,,,,,,,,,,,,
,3737929905.26989,12.4781174659729,49999.6640625,1.36648386300135E-5,1.63264003070608E-7,1,5,14.0008964538574,3.99853751491044,30.0200004130602,0.0122830810111228,0.000968794129214078,1,-9.73500896630313E-7,12.3594799041748,12.596755027771,49999.6640625,49999.6640625,50.5737100797938,5.79410935624963,3.35961246490479,70,1,0,0,1,0.264739990234375,27.8592376708984,6,1,1,12.596755027771,0,12.4781174659729,,,,,,,,,,,,,,,,,,,,,,,,,,,,,,,,,
,3737930025.31085,18.2244672775269,49999.6640625,2.55576850631284E-5,1.6590558048779E-7,1,5,14.0008964538574,3.99846462106923,30.0299990922213,0.022866097515237,0.00251793927075081,1,-1.02683638669166E-6,18.1059513092041,18.3429832458496,49999.6640625,49999.6640625,50.3646244508996,5.79325727575055,3.6159520149231,70,1,0,0,1,0.268325805664062,27.8592376708984,2,1,1,18.3429832458496,0,18.2244672775269,,,,,,,,,,,,,,,,,,,,,,,,,,,,,,,,,
,3737930170.23517,25.2901296615601,49999.6640625,3.34276995344022E-5,1.51576449561669E-7,1,5,14.0008964538574,3.99848479324569,30.0299990922213,0.0298559325408865,0.00363509890041998,1,-9.58705938796431E-7,25.1590766906738,25.4211826324463,49999.6640625,49999.6640625,50.1852407057361,5.7935339978459,3.81505560874939,70,1,0,0,1,0.268630981445313,27.8592376708984,2,1,1,25.4211826324463,0,25.2901296615601,,,,,,,,,,,,,,,,,,,,,,,,,,,,,,,,,
,3737930290.29433,31.1391506195068,49999.6640625,3.74230320428586E-5,1.5199931235194E-7,1,5,14.0008964538574,3.99840622936094,30.0200004130602,0.0333980683532906,0.00423667502608035,1,-8.85238235278486E-7,31.0214881896973,31.2568130493164,49999.6640625,49999.6640625,50.2321384168899,5.79347180184434,3.93248867988586,68,1,64,0,0,0.265121459960938,27.8592376708984,2,1,1,31.2568130493164,0,31.1391506195068,,,,,,,,,,,,,,,,,,,,,,,,,,,,,,,,,
,3737930410.86578,37.0037326812744,49999.6640625,3.95723727522511E-5,1.45595876816828E-7,1,5,14.0008964538574,3.99845000457993,30.0200004130602,0.0353245200207716,0.00442932432653065,1,-9.93156308076194E-7,36.8844032287598,37.1230621337891,49999.6640625,49999.6640625,50.1793784918418,5.79349443579293,4.02039957046509,68,1,32,0,0,0.266494750976562,27.8592376708984,2,1,1,37.1230621337891,0,37.0037326812744,,,,,,,,,,,,,,,,,,,,,,,,,,,,,,,,,
,3737930530.18632,42.8183708190918,49999.6640625,4.1009797959913E-5,1.68445234343628E-7,1,5,14.0008964538574,3.99845556008492,30.0299990922213,0.0365904499026714,0.00470467563554225,1,-9.00532720509681E-7,42.698917388916,42.9378242492676,49999.6640625,49999.6640625,50.0844106267553,5.79309445886435,4.09678745269775,70,1,0,0,1,0.27130126953125,27.8592376708984,2,1,1,42.9378242492676,0,42.8183708190918,,,,,,,,,,,,,,,,,,,,,,,,,,,,,,,,,
,3737930650.19505,48.7142162322998,49999.6640625,4.20325156535285E-5,1.49398947425238E-7,1,5,14.0008964538574,3.99838907207522,30.0200004130602,0.0374970735202469,0.00485425159345172,1,-8.86581905664548E-7,48.601131439209,48.8273010253906,49999.6640625,49999.6640625,50.0906636549092,5.79321472892301,4.17725086212158,70,1,0,0,1,0.268096923828125,27.8592376708984,2,1,1,48.8273010253906,0,48.7142162322998,,,,,,,,,,,,,,,,,,,,,,,,,,,,,,,,,
,3737930770.24281,54.5987777709961,49999.6640625,4.29767668648908E-5,1.71202807157613E-7,1,5,14.0008964538574,3.99834124977485,30.0299990922213,0.0383380339341364,0.00496765414086926,1,-9.0149727402125E-7,54.4811935424805,54.7163619995117,49999.6640625,49999.6640625,50.1145033247457,5.79366972828371,4.22913074493408,70,1,0,0,1,0.266189575195313,27.8592376708984,2,1,1,54.7163619995117,0,54.5987777709961,,,,,,,,,,,,,,,,,,,,,,,,,,,,,,,,,
,3737930890.58157,60.5067176818848,49999.6640625,4.28546712616065E-5,1.7357327018528E-7,1,5,14.0008964538574,3.99841021595602,30.0299990922213,0.0382294012488504,0.00495876311833433,1,-8.93217331683642E-7,60.4065093994141,60.6069259643555,49999.6640625,49999.6640625,50.1766427920245,5.79271482036611,4.27667760848999,68,1,64,0,0,0.268173217773438,27.8592376708984,2,1,1,60.6069259643555,0,60.5067176818848,,,,,,,,,,,,,,,,,,,,,,,,,,,,,,,,,
,3737931010.2435,66.4142456054687,49999.6640625,4.26091112907497E-5,1.69993631341662E-7,1,5,14.0008964538574,3.99829661022535,30.0299990922213,0.0380068128376396,0.00494210418548565,1,-8.74628406897338E-7,66.2966384887695,66.531852722168,49999.6640625,49999.6640625,50.3048298691784,5.79345733106832,4.31501150131226,70,1,0,0,1,0.268402099609375,27.8592376708984,2,1,1,66.531852722168,0,66.4142456054687,,,,,,,,,,,,,,,,,,,,,,,,,,,,,,,,,
,3737931130.18106,72.3037452697754,49999.6640625,4.28263473920272E-5,1.76846152288848E-7,1,5,14.0008964538574,3.99831651993665,30.0399996340275,0.0382098497671076,0.00490797800334739,1,-9.45843735330664E-7,72.1796340942383,72.4278564453125,49999.6640625,49999.6640625,50.2016549046399,5.79406926787812,4.35151147842407,70,1,0,0,1,0.270462036132813,27.8592376708984,2,1,1,72.4278564453125,0,72.3037452697754,,,,,,,,,,,,,,,,,,,,,,,,,,,,,,,,,
,3737931250.52365,78.2337226867676,49999.6640625,4.21995367937468E-5,1.90748830134297E-7,1,5,14.0008964538574,3.998247499552,30.0399996340275,0.0376543846200556,0.00480411568595647,1,-9.67869513501117E-7,78.1286468505859,78.3387985229492,49999.6640625,49999.6640625,50.2063446757553,5.79430570895914,4.37890481948853,70,1,0,0,1,0.267791748046875,27.8592376708984,2,1,1,78.3387985229492,0,78.2337226867676,,,,,,,,,,,,,,,,,,,,,,,,,,,,,,,,,
,3737931370.14798,84.1718788146973,49999.6640625,4.22651916784503E-5,1.76245748609901E-7,1,5,14.0008964538574,3.99813729304468,30.0500001758337,0.0377073121302811,0.00483785705739262,1,-9.39596474239024E-7,84.0685653686523,84.2751922607422,49999.6640625,49999.6640625,50.0441567580149,5.79535887391378,4.39671421051025,70,1,0,0,1,0.269393920898438,27.8592376708984,2,1,1,84.2943878173828,0,84.1718788146973,,,,,,,,,,,,,,,,,,,,,,,,,,,,,,,,,
,3737931490.39321,90.1076812744141,49999.6640625,4.22402981226057E-5,1.90203138493027E-7,1,5,14.0008964538574,3.99815023987953,30.0600007176399,0.037683471878426,0.00484712798870342,1,-9.25440233797096E-7,89.9985504150391,90.2168121337891,49999.6640625,49999.6640625,50.0949626117649,5.79434454735637,4.41763687133789,69,1,64,0,0,0.26824951171875,27.8592376708984,2,1,1,90.2168121337891,0,90.1076812744141,,,,,,,,,,,,,,,,,,,,,,,,,,,,,,,,,
,3737931610.38622,96.0829277038574,49999.6640625,4.13009538799939E-5,1.81671334718215E-7,1,5,14.0008964538574,3.99808127908238,30.0600007176399,0.0368535538148032,0.00467889298496336,1,-9.72692634870934E-7,95.9519500732422,96.2139053344727,49999.6640625,49999.6640625,50.0574444428418,5.79570607417736,4.442711353302,70,1,0,0,1,0.26641845703125,27.8592376708984,2,1,1,96.2139053344727,0,96.0829277038574,,,,,,,,,,,,,,,,,,,,,,,,,,,,,,,,,
,3737931730.09088,102.053985595703,49999.6640625,4.12436741758405E-5,1.81749565887242E-7,1,5,14.0008964538574,3.99811178186193,30.069999396801,0.0368013148281996,0.00468289617097477,1,-9.5960747170017E-7,101.937210083008,102.170761108398,49999.6640625,49999.6640625,50.1559296362649,5.79585101932205,4.45210647583008,70,1,0,0,1,0.26611328125,27.8592376708984,2,1,1,102.170761108398,0,102.053985595703,,,,,,,,,,,,,,,,,,,,,,,,,,,,,,,,,
,3737931850.42509,108.050224304199,49999.6640625,4.10571652162727E-5,1.90683435228588E-7,1,5,14.0008964538574,3.99804088790523,30.0799999386072,0.0366336783991253,0.00466277881218476,1,-9.53928322636246E-7,107.937889099121,108.162559509277,49999.6640625,49999.6640625,50.1445960227361,5.79605974985783,4.46911096572876,68,1,64,0,0,0.267791748046875,27.8592376708984,2,1,1,108.162559509277,0,108.050224304199,,,,,,,,,,,,,,,,,,,,,,,,,,,,,,,,,
,3737931970.27976,114.022960662842,49999.6640625,4.01195040266427E-5,1.89734289510863E-7,1,5,14.0008964538574,3.99795444055319,30.0799999386072,0.0358152999736213,0.00442699802737665,1,-1.07738349412733E-6,113.883888244629,114.162033081055,49999.6640625,49999.6640625,50.0468924578322,5.79762495168831,4.48514366149902,70,1,0,0,1,0.267105102539062,27.8592376708984,2,1,1,114.162033081055,0,114.022960662842,,,,,,,,,,,,,,,,,,,,,,,,,,,,,,,,,
,3737932090.03901,120.003475189209,49999.6640625,3.98498340954062E-5,1.95111503562749E-7,1,5,14.0008964538574,3.99791439521981,30.0900004804134,0.0355555290729007,0.00451947874506629,1,-9.3257757405243E-7,119.887268066406,120.119682312012,49999.6640625,49999.6640625,50.1742979064668,5.79731702546421,4.49967479705811,70,1,0,0,1,0.268402099609375,27.8592376708984,2,1,1,120.119682312012,0,120.003475189209,,,,,,,,,,,,,,,,,,,,,,,,,,,,,,,,,
,3737932210.06786,125.958511352539,49999.6640625,3.948976190021E-5,1.88189542234152E-7,1,5,14.0008964538574,3.99806717915009,30.0999991595745,0.0352310748908354,0.00451424034083419,1,-8.84421857951158E-7,125.845123291016,126.071899414062,49999.6640625,49999.6640625,50.0805024841591,5.79476412181806,4.50974321365356,70,1,0,0,1,0.265884399414062,27.8592376708984,2,1,1,126.071899414062,0,125.958511352539,,,,,,,,,,,,,,,,,,,,,,,,,,,,,,,,,
,3737932330.48331,131.970611572266,49999.6640625,3.91738746340672E-5,1.84879980151211E-7,1,5,14.0008964538574,3.99808354657303,30.1099997013807,0.0349476116203664,0.00449054959732226,1,-8.63412171047365E-7,131.841583251953,132.099639892578,49999.6640625,49999.6640625,50.1531939364476,5.79555252589579,4.51960706710815,70,1,0,0,1,0.266952514648438,27.8592376708984,2,1,1,132.099639892578,0,131.970611572266,,,,,,,,,,,,,,,,,,,,,,,,,,,,,,,,,
,3737932450.00593,137.9140625,49999.6640625,3.87986012261484E-5,1.90273636500231E-7,1,5,14.0008964538574,3.99810491098696,30.120000243187,0.0346148638523519,0.00443601530832337,1,-8.68135353908842E-7,137.796646118164,138.031478881836,49999.6640625,49999.6640625,50.1656999927553,5.79579447483276,4.53741693496704,70,1,0,0,1,0.2667236328125,27.8592376708984,2,1,1,138.031478881836,0,137.9140625,,,,,,,,,,,,,,,,,,,,,,,,,,,,,,,,,
,3737932570.07345,143.893371582031,49999.6640625,3.83132938564862E-5,1.94547460657774E-7,1,5,14.0008964538574,3.99812288872547,30.1300007849932,0.0341773303123117,0.0044123765378737,1,-8.21493465767705E-7,143.773391723633,144.01335144043,49999.6640625,49999.6640625,49.9628673920149,5.79640409102657,4.5492000579834,68,1,64,0,0,0.266342163085938,27.8592376708984,2,1,1,144.01335144043,0,143.893371582031,,,,,,,,,,,,,,,,,,,,,,,,,,,,,,,,,
,3737932690.43514,149.919097900391,49999.6640625,3.8035136028211E-5,1.80524627824911E-7,1,5,14.0008964538574,3.99807512184549,30.1399994641542,0.0339355141591161,0.00433414752638053,1,-8.67389075230476E-7,149.797119140625,150.041076660156,49999.6640625,49999.6640625,50.0429843152361,5.79520890157444,4.55675458908081,70,1,0,0,1,0.271072387695313,27.8592376708984,2,1,1,150.041076660156,0,149.919097900391,,,,,,,,,,,,,,,,,,,,,,,,,,,,,,,,,
,3737932809.99868,155.862571716309,49999.6640625,3.75590908796031E-5,2.05950827084184E-7,1,5,14.0008964538574,3.99808732402602,30.1500000059605,0.0335192680454034,0.00422477439943541,1,-9.18555693191004E-7,155.745544433594,155.979598999023,49999.6640625,49999.6640625,50.1113768106688,5.79537531732047,4.56587648391724,70,1,0,0,1,0.269241333007813,27.8592376708984,2,1,1,155.979598999023,0,155.862571716309,,,,,,,,,,,,,,,,,,,,,,,,,,,,,,,,,
,3737932930.10277,161.853591918945,49999.6640625,3.73755917960974E-5,1.60865672926612E-7,1,5,14.0008964538574,3.99820202510708,30.1600005477667,0.0333385099992643,0.00432702557871819,1,-7.76079364517737E-7,161.738876342773,161.968307495117,49999.6640625,49999.6640625,50.1352164805053,5.79529520243186,4.56297540664673,68,1,64,0,0,0.266342163085938,27.8592376708984,2,1,1,161.968307495117,0,161.853591918945,,,,,,,,,,,,,,,,,,,,,,,,,,,,,,,,,
,3737933050.02048,167.835838317871,49999.6640625,3.64540487569852E-5,1.55311891053159E-7,1,5,14.0008964538574,3.99803674217887,30.1699992269278,0.0325188406497148,0.00419038816358858,1,-7.90314214917642E-7,167.719757080078,167.951919555664,49999.6640625,49999.6640625,50.0726861989668,5.79537290514355,4.57865953445435,70,1,0,0,1,0.26947021484375,27.8592376708984,2,1,1,167.951919555664,0,167.835838317871,,,,,,,,,,,,,,,,,,,,,,,,,,,,,,,,,
,3737933170.25371,173.86149597168,49999.6640625,3.57875705392218E-5,1.64846907981693E-7,1,5,14.0008964538574,3.99800069272692,30.179999768734,0.0319404789622794,0.00400355942301626,1,-8.99759612673991E-7,173.758926391602,173.964065551758,49999.6640625,49999.6640625,50.0922269119476,5.79535837027095,4.58726501464844,70,1,0,0,1,0.268707275390625,27.8592376708984,2,1,1,173.964065551758,0,173.86149597168,,,,,,,,,,,,,,,,,,,,,,,,,,,,,,,,,
,3737933289.96025,179.812591552734,49999.6640625,3.48708158120919E-5,1.56941106443509E-7,1,5,14.0008964538574,3.99788118306954,30.1900003105402,0.0311151105163359,0.0039384315389625,1,-8.34402600186512E-7,179.693664550781,179.931518554687,49999.6640625,49999.6640625,50.0988707543611,5.79553778662217,4.59961605072022,70,1,0,0,1,0.274200439453125,27.8592376708984,2,1,1,179.931518554687,0,179.812591552734,,,,,,,,,,,,,,,,,,,,,,,,,,,,,,,,,
,3737933409.91759,185.835845947266,49999.6640625,3.48563952331693E-5,1.66132945524651E-7,1,5,14.0008964538574,3.99790258317547,30.2099995315075,0.031115162291543,0.00385301690968151,1,-9.28332923641366E-7,185.708190917969,185.963500976562,49999.6640625,49999.6640625,50.1027788969572,5.7961231403228,4.61719512939453,70,1,0,0,1,0.269241333007813,27.8592376708984,2,1,1,185.963500976562,0,185.835845947266,,,,,,,,,,,,,,,,,,,,,,,,,,,,,,,,,
,3737933530.24457,191.796585083008,49999.6640625,3.38838730330543E-5,1.70913278512267E-7,1,5,14.0008964538574,3.99806075991619,30.2200000733137,0.0302430533910776,0.00378469987010071,1,-8.58627021781898E-7,191.689071655273,191.904098510742,49999.6640625,49999.6640625,50.0687780563707,5.79517741742138,4.62946224212646,70,1,0,0,1,0.271148681640625,27.8592376708984,2,1,1,191.904098510742,0,191.796585083008,,,,,,,,,,,,,,,,,,,,,,,,,,,,,,,,,
,3737933649.92132,197.789489746094,49999.6640625,3.38680214793114E-5,1.51986359016882E-7,1,5,14.0008964538574,3.99800578405713,30.239999294281,0.0302225931892252,0.00382026394986501,1,-8.16141870609215E-7,197.674789428711,197.904190063477,49999.6640625,49999.6640625,49.9538786640438,5.79621255834803,4.64752817153931,70,1,0,0,1,0.2679443359375,27.8592376708984,2,1,1,197.904190063477,0,197.789489746094,,,,,,,,,,,,,,,,,,,,,,,,,,,,,,,,,
,3737933769.87443,203.733909606934,49999.6640625,3.29222853033659E-5,1.8070285890152E-7,1,5,14.0008964538574,3.99792933770869,30.2499998360872,0.0293886331308756,0.00364142194531877,1,-8.74389757370547E-7,203.604537963867,203.86328125,49999.6640625,49999.6640625,50.0472832720918,5.79638172608198,4.66584825515747,70,1,0,0,1,0.269775390625,27.8592376708984,2,1,1,203.86328125,0,203.733909606934,,,,,,,,,,,,,,,,,,,,,,,,,,,,,,,,,
,3737933890.4165,209.759353637695,49999.6640625,3.19210219568849E-5,1.62357377745297E-7,1,5,14.0008964538574,3.99812542042069,30.2600003778934,0.0284856163068035,0.00360681408662954,1,-7.62479215578923E-7,209.635803222656,209.882904052734,49999.6640625,49999.6640625,50.0808932984188,5.79571269891505,4.68256807327271,70,1,0,0,1,0.266494750976562,27.8592376708984,2,1,1,209.882904052734,0,209.759353637695,,,,,,,,,,,,,,,,,,,,,,,,,,,,,,,,,
,3737934009.86626,215.706817626953,49999.6640625,3.1842985982711E-5,1.73175040617178E-7,1,5,14.0008964538574,3.9979427899285,30.2799995988607,0.0284136415675558,0.00359949635985763,1,-7.58633509009789E-7,215.584808349609,215.828826904297,49999.6640625,49999.6640625,50.1059054110341,5.79550655854857,4.7031397819519,70,1,0,0,1,0.267791748046875,27.8592376708984,2,1,1,215.828826904297,0,215.706817626953,,,,,,,,,,,,,,,,,,,,,,,,,,,,,,,,,
,3737934129.98652,221.709373474121,49999.6640625,3.09785689908674E-5,1.70229018411111E-7,1,5,14.0008964538574,3.99790044413216,30.290000140667,0.0276502569189929,0.00344604302101314,1,-8.00666749041035E-7,221.575546264648,221.843200683594,49999.6640625,49999.6640625,50.1203655386399,5.79568578451472,4.73266553878784,69,1,64,0,0,0.266342163085938,27.8592376708984,2,1,1,221.843200683594,0,221.709373474121,,,,,,,,,,,,,,,,,,,,,,,,,,,,,,,,,
,3737934250.5353,227.740776062012,49999.6640625,3.07227813669801E-5,1.61305133436918E-7,1,5,14.0008964538574,3.99803035760542,30.3099993616343,0.02741537407302,0.0034707516973675,1,-7.34464081815479E-7,227.637344360352,227.844207763672,49999.6640625,49999.6640625,50.1445960227361,5.79511431392928,4.75855016708374,69,1,64,0,0,0.267333984375,27.8592376708984,2,1,1,227.844207763672,0,227.740776062012,,,,,,,,,,,,,,,,,,,,,,,,,,,,,,,,,
,3737934370.44109,233.73380279541,49999.6640625,2.97015540250228E-5,1.59666472073378E-7,1,5,14.0008964538574,3.99806549948873,30.3199999034405,0.0265088146366099,0.00332656431670068,1,-7.42515616706542E-7,233.637710571289,233.829895019531,49999.6640625,49999.6640625,50.208689561313,5.7952714064499,4.80660772323608,69,1,64,0,0,0.26519775390625,27.8592376708984,2,1,1,233.829895019531,0,233.73380279541,,,,,,,,,,,,,,,,,,,,,,,,,,,,,,,,,
,3737934489.90858,239.667350769043,49999.6640625,2.97607338179842E-5,1.58430635349096E-7,1,5,14.0008964538574,3.99801749450523,30.3399991244078,0.0265611641731879,0.00333286283638284,1,-7.4429393665897E-7,239.555892944336,239.77880859375,49999.6640625,49999.6640625,50.0449383865341,5.79586968919632,4.85761976242065,68,1,64,0,0,0.2679443359375,27.8592376708984,2,1,1,239.77880859375,0,239.667350769043,,,,,,,,,,,,,,,,,,,,,,,,,,,,,,,,,
,3737934610.55311,245.663131713867,49999.6640625,2.92822549035184E-5,1.62553839318756E-7,1,5,14.0008964538574,3.99796486812032,30.3600002080202,0.02612937103827,0.00330707416860497,1,-7.0098805219052E-7,245.556686401367,245.769577026367,49999.6640625,49999.6640625,50.0976983115822,5.79551093445445,4.95343255996704,68,1,64,0,0,0.26641845703125,27.8592376708984,2,1,1,245.769577026367,0,245.663131713867,,,,,,,,,,,,,,,,,,,,,,,,,,,,,,,,,
,3737934730.40089,251.674629211426,49999.6640625,2.80720201890293E-5,1.58065197760415E-7,1,5,14.0008964538574,3.99796091951523,30.3700007498264,0.0250535934163897,0.00314264594541004,1,-7.03218055092628E-7,251.58056640625,251.768692016602,49999.6640625,49999.6640625,50.1715622066495,5.79640833245815,7.2757453918457,69,1,64,0,0,0.271072387695313,27.8592376708984,2,1,1,251.768692016602,0,251.674629211426,,,,,,,,,,,,,,,,,,,,,,,,,,,,,,,,,
,3737934849.80809,257.615356445313,49999.6640625,2.77775307332164E-5,1.54008750501453E-7,1,5,14.0008964538574,3.99797168372139,30.3899999707937,0.024794459572469,0.003085948249401,1,-7.22545120676645E-7,257.493438720703,257.737274169922,49999.6640625,49999.6640625,49.9835805477745,5.79549200538643,7.47954893112183,70,1,0,0,1,0.268630981445313,27.8592376708984,2,1,1,257.737274169922,0,257.615356445313,,,,,,,,,,,,,,,,,,,,,,,,,,,,,,,,,
,3737934970.41848,263.665817260742,49999.6640625,2.72650546235062E-5,1.64423959494068E-7,1,5,14.0008964538574,3.99807512892553,30.409999191761,0.0243363093717408,0.00304049680759793,1,-6.96441740047435E-7,263.554290771484,263.77734375,49999.6640625,49999.6640625,50.1406878801399,5.7952775770991,7.38437366485596,70,1,0,0,1,0.268478393554687,27.8592376708984,2,1,1,263.77734375,0,263.665817260742,,,,,,,,,,,,,,,,,,,,,,,,,,,,,,,,,
,3737935089.73765,269.61457824707,49999.6640625,2.69513206629338E-5,1.58053095998865E-7,1,5,14.0008964538574,3.99790143028388,30.4300002753735,0.0240531395664664,0.00301503096168971,1,-6.77485352846963E-7,269.493988037109,269.735168457031,49999.6640625,49999.6640625,49.9855346190726,5.79612953986307,7.3377537727356,70,1,0,0,1,0.2685546875,27.8592376708984,2,1,1,269.735168457031,0,269.61457824707,,,,,,,,,,,,,,,,,,,,,,,,,,,,,,,,,
,3737935209.77855,275.561386108398,49999.6640625,2.5549878670386E-5,1.42927103553954E-7,1,5,14.0008964538574,3.99797474817179,30.4400008171797,0.0228097492168395,0.00281407433447008,1,-6.92038293586496E-7,275.437927246094,275.684844970703,49999.6640625,49999.6640625,50.0109375459476,5.79633068855773,7.42092418670654,70,1,0,0,1,0.269699096679687,27.8592376708984,2,1,1,275.684844970703,0,275.561386108398,,,,,,,,,,,,,,,,,,,,,,,,,,,,,,,,,
,3737935330.07983,281.582092285156,49999.6640625,2.58297705393619E-5,1.51325916463446E-7,1,5,14.0008964538574,3.99799816529079,30.4700005799532,0.0230502776911945,0.00290826590842324,1,-6.28383649945901E-7,281.457733154297,281.706451416016,49999.6640625,49999.6640625,50.1090319251111,5.7963210917719,7.6313853263855,70,1,0,0,1,0.269546508789062,27.8592376708984,2,1,1,281.712921142578,0,281.582092285156,,,,,,,,,,,,,,,,,,,,,,,,,,,,,,,,,
,3737935449.7243,287.548217773438,49999.6640625,2.4227046421019E-5,1.45215762895945E-7,1,5,14.0008964538574,3.99801758287066,30.4799992591143,0.0216420120176544,0.00258325911432565,1,-7.5199099341079E-7,287.438812255859,287.657623291016,49999.6640625,49999.6640625,50.1012156399188,5.79699860249229,8.04756927490234,70,1,0,0,1,0.266799926757813,27.8592376708984,2,1,1,287.657623291016,0,287.548217773438,,,,,,,,,,,,,,,,,,,,,,,,,,,,,,,,,
,3737935569.74028,293.522750854492,49999.6640625,2.3778705065278E-5,1.60831396581895E-7,1,5,14.0008964538574,3.99813514730447,30.5000003427267,0.0212235029791838,0.00266144934095879,1,-5.96509208027478E-7,293.400451660156,293.645050048828,49999.6640625,49999.6640625,50.1559296362649,5.79464981971852,8.75701427459717,70,1,0,0,1,0.26519775390625,27.8592376708984,2,1,1,293.645050048828,0,293.522750854492,,,,,,,,,,,,,,,,,,,,,,,,,,,,,,,,,
,3737935690.39142,299.570007324219,49999.6640625,2.38959974297061E-5,1.57820568627087E-7,1,5,14.0008964538574,3.99801407775516,30.5300001055002,0.0213339059973577,0.0026297669411743,1,-6.49704189377262E-7,299.488159179687,299.65185546875,49999.6640625,49999.6640625,50.1524123079284,5.79606397781167,9.7589693069458,68,1,64,0,0,0.26611328125,27.8592376708984,2,1,1,299.65185546875,0,299.570007324219,,,,,,,,,,,,,,,,,,,,,,,,,,,,,,,,,
,3737935809.67347,305.514526367188,49999.6640625,2.15708586579748E-5,1.44649571571878E-7,1,5,14.0008964538574,3.99812453927022,30.5400006473064,0.0192570509227102,0.00238633021967912,1,-5.72606778501103E-7,305.388885498047,305.640167236328,49999.6640625,49999.6640625,50.1231012384572,5.7959943014635,9.58199501037598,70,1,0,0,1,0.266494750976562,27.8592376708984,2,1,1,305.646514892578,0,305.514526367188,,,,,,,,,,,,,,,,,,,,,,,,,,,,,,,,,
,3737935929.71087,311.49333190918,49999.6640625,2.03669183250442E-5,1.52175129998468E-7,1,5,14.0008964538574,3.99802998729049,30.5599998682737,0.0181809898203317,0.00225687079529467,1,-5.36357593036776E-7,311.377990722656,311.608673095703,49999.6640625,49999.6640625,50.0933993547265,5.79580644098422,9.37209320068359,70,1,0,0,1,0.270843505859375,27.8592376708984,2,1,1,311.608673095703,0,311.49333190918,,,,,,,,,,,,,,,,,,,,,,,,,,,,,,,,,
,3737936050.05901,317.489761352539,49999.6640625,1.93607824438258E-5,1.37257899690054E-7,1,5,14.0008964538574,3.99794170379032,30.579999089241,0.0173081291044337,0.00197375017685779,1,-7.02812831336735E-7,317.385681152344,317.593841552734,49999.6640625,49999.6640625,50.0437659437553,5.79714635310984,9.24269485473633,70,1,0,0,1,0.267868041992187,27.8592376708984,2,1,1,317.593841552734,0,317.489761352539,,,,,,,,,,,,,,,,,,,,,,,,,,,,,,,,,
,3737936169.68621,323.450866699219,49999.6640625,1.91291880294799E-5,1.4864540968265E-7,1,5,14.0008964538574,3.99795219314283,30.6100007146597,0.0170959568940763,0.00198461598182942,1,-6.55639229324912E-7,323.330780029297,323.570953369141,49999.6640625,49999.6640625,50.1868039627745,5.79636049631457,9.15471076965332,70,1,0,0,1,0.270767211914062,27.8592376708984,2,1,1,323.570953369141,0,323.450866699219,,,,,,,,,,,,,,,,,,,,,,,,,,,,,,,,,
,3737936289.66242,329.43864440918,49999.6640625,1.72435419316434E-5,1.50588511419715E-7,1,5,14.0008964538574,3.99787583954865,30.6199993938208,0.0154279010117421,0.00167210815719404,1,-7.2240520004059E-7,329.323303222656,329.553985595703,49999.6640625,49999.6640625,50.1023880826976,5.7965089274236,9.07461261749268,70,1,0,0,1,0.2667236328125,27.8592376708984,2,1,1,329.553985595703,0,329.43864440918,,,,,,,,,,,,,,,,,,,,,,,,,,,,,,,,,
,3737936410.08187,335.463394165039,49999.6640625,1.61338097104163E-5,1.54008345585491E-7,1,5,14.0008964538574,3.99795550466816,30.6400004774332,0.0144434413687689,0.00151178218199364,1,-7.35259426093262E-7,335.344390869141,335.582397460937,49999.6640625,49999.6640625,50.0891003978707,5.79598218776925,9.02709674835205,70,1,0,0,1,0.270767211914062,27.8592376708984,2,1,1,335.582397460937,0,335.463394165039,,,,,,,,,,,,,,,,,,,,,,,,,,,,,,,,,
,3737936530.24543,341.442138671875,49999.6640625,1.49600924905027E-5,1.65167152572208E-7,1,5,14.0008964538574,3.99793571387356,30.6599996984005,0.01339640836184,0.00137650252531138,1,-7.10212275693262E-7,341.350189208984,341.534088134766,49999.6640625,49999.6640625,50.1539755649668,5.79575940673801,8.98901462554932,69,1,64,0,0,0.266494750976562,27.8592376708984,2,1,1,341.534088134766,0,341.442138671875,,,,,,,,,,,,,,,,,,,,,,,,,,,,,,,,,
,3737936669.65144,348.401504516602,49999.6640625,1.34096643392204E-5,1.5458813440688E-7,1,5,14.0008964538574,3.99793322261959,30.6800007820129,0.0120202511716729,0.00115285368886546,1,-7.27699546651037E-7,348.285278320313,348.517730712891,49999.6640625,49999.6640625,50.1348256662457,5.79635503844912,8.94091987609863,70,1,0,0,1,0.269241333007813,27.8592376708984,2,1,1,348.517730712891,0,348.401504516602,,,,,,,,,,,,,,,,,,,,,,,,,,,,,,,,,
,3737936849.60401,349.792068481445,49999.6640625,1.20287048783719E-5,1.62832064119519E-7,1,5,14.0008964538574,3.99797260600835,30.6800007820129,0.0108001170020522,0.000917754623312311,1,-7.83666278536112E-7,349.728088378906,349.856048583984,49999.6640625,49999.6640625,50.2708290285919,5.79589291583521,8.91665363311768,70,1,0,0,1,0.269775390625,27.8592376708984,2,1,1,349.728088378906,0,349.792068481445,,,,,,,,,,,,,,,,,,,,,,,,,,,,,,,,,
,3737936970.0307,343.920181274414,49999.6640625,1.15363876858641E-5,1.58097933638031E-7,1,5,14.0008964538574,3.99790056414682,30.6599996984005,0.0103537276837509,0.000907051850986265,1,-7.21353382749298E-7,343.790740966797,344.049621582031,49999.6640625,49999.6640625,50.2079079327938,5.79708986987572,8.89937973022461,70,1,0,0,1,0.266799926757813,27.8592376708984,2,1,1,343.790740966797,0,343.920181274414,,,,,,,,,,,,,,,,,,,,,,,,,,,,,,,,,
,3737937089.53804,337.901809692383,49999.6640625,1.32734756228754E-5,1.56498065804896E-7,1,5,14.0008964538574,3.99800421065353,30.6599996984005,0.0119012875117253,0.00112278194344525,1,-7.40998582306492E-7,337.790740966797,338.012878417969,49999.6640625,49999.6640625,50.1246644954957,5.79724215050046,8.86671352386475,70,1,0,0,1,0.267257690429687,27.8592376708984,2,1,1,337.790740966797,0,337.901809692383,,,,,,,,,,,,,,,,,,,,,,,,,,,,,,,,,
,3737937209.53038,331.911071777344,49999.6640625,1.41599413079E-5,1.64459129265598E-7,1,5,14.0008964538574,3.99807466094724,30.6400004774332,0.0126878903666676,0.0012546265320378,1,-7.26575539868576E-7,331.768768310547,332.053375244141,49999.6640625,49999.6640625,50.2368281880053,5.79622655236499,8.84579849243164,70,1,0,0,1,0.269699096679687,27.8592376708984,2,1,1,331.768768310547,0,331.911071777344,,,,,,,,,,,,,,,,,,,,,,,,,,,,,,,,,
,3737937329.84457,325.882400512695,49999.6640625,1.52110728059508E-5,1.80044096300387E-7,1,5,14.0008964538574,3.99793062889562,30.6199993938208,0.0136215928845182,0.00139651094258571,1,-7.25593511082371E-7,325.748901367188,326.015899658203,49999.6640625,49999.6640625,50.1387338088418,5.79724060035764,8.8266544342041,70,1,0,0,1,0.26580810546875,27.8592376708984,2,1,1,325.748901367188,0,325.882400512695,,,,,,,,,,,,,,,,,,,,,,,,,,,,,,,,,
,3737937474.50324,318.658462524414,49999.6640625,1.68324658897899E-5,1.62078199095872E-7,1,5,14.0008964538574,3.99789283305657,30.6000001728535,0.0150561583690917,0.00165910218221821,1,-6.74989607049947E-7,318.538604736328,318.7783203125,49999.6640625,49999.6640625,50.0539271145053,5.79809582471795,8.79304122924805,70,1,0,0,1,0.267486572265625,27.8592376708984,2,1,1,318.538604736328,0,318.658462524414,,,,,,,,,,,,,,,,,,,,,,,,,,,,,,,,,
,3737937594.74161,312.651748657227,49999.6640625,1.77648744800754E-5,1.67814653468982E-7,1,5,14.0008964538574,3.99804126745451,30.579999089241,0.0158846654281442,0.00179381630829492,1,-6.64347943250702E-7,312.546264648438,312.757232666016,49999.6640625,49999.6640625,50.1168482103034,5.79750032826893,8.78032302856445,70,1,0,0,1,0.269622802734375,27.8592376708984,2,1,1,312.546264648438,0,312.651748657227,,,,,,,,,,,,,,,,,,,,,,,,,,,,,,,,,
,3737937714.48702,306.682495117188,49999.6640625,2.04702570549445E-5,1.51197438440866E-7,1,5,14.0008964538574,3.99802147563393,30.579999089241,0.0182916884955614,0.00214567978012851,1,-6.77004469669373E-7,306.54931640625,306.815673828125,49999.6640625,49999.6640625,50.0844106267553,5.79724364622413,8.75267791748047,70,1,0,0,1,0.26641845703125,27.8592376708984,2,1,1,306.54931640625,0,306.682495117188,,,,,,,,,,,,,,,,,,,,,,,,,,,,,,,,,
,3737937834.48299,300.663681030273,49999.6640625,2.12413468930489E-5,1.78343202295411E-7,1,5,14.0008964538574,3.99792525158152,30.5599998682737,0.0189832428806605,0.00220484091482524,1,-7.26776465128858E-7,300.543853759766,300.783508300781,49999.6640625,49999.6640625,50.0636974709957,5.79725958642075,8.72194290161133,70,1,0,0,1,0.266342163085938,27.8592376708984,2,1,1,300.543853759766,0,300.663681030273,,,,,,,,,,,,,,,,,,,,,,,,,,,,,,,,,
,3737937954.66159,294.6630859375,49999.6640625,2.11741293686024E-5,1.6740298232742E-7,1,5,14.0008964538574,3.99814117940105,30.5300001055002,0.018940366633904,0.00209494946418144,1,-8.40430680173237E-7,294.540802001953,294.785369873047,49999.6640625,49999.6640625,50.1055145967745,5.7952308766878,8.65829372406006,68,1,32,0,0,0.267868041992187,27.8592376708984,2,1,1,294.540802001953,0,294.6630859375,,,,,,,,,,,,,,,,,,,,,,,,,,,,,,,,,
,3737938074.80079,288.66569519043,49999.6640625,2.36055313972008E-5,1.62782682637698E-7,1,5,14.0008964538574,3.9982209323547,30.5300001055002,0.0210900296658862,0.00250722108188222,1,-7.43914076138331E-7,288.558044433594,288.773345947266,49999.6640625,49999.6640625,50.0957442402841,5.79566392017422,8.5718355178833,70,1,0,0,1,0.266494750976562,27.8592376708984,2,1,1,288.558044433594,0,288.66569519043,,,,,,,,,,,,,,,,,,,,,,,,,,,,,,,,,
,3737938194.52175,282.701278686523,49999.6640625,2.46705608270661E-5,1.44687211573151E-7,1,5,14.0008964538574,3.99832970774324,30.5100008845329,0.0220494274593611,0.00257471241549141,1,-8.28917808042248E-7,282.586883544922,282.815673828125,49999.6640625,49999.6640625,50.1113768106688,5.79451025664319,8.43882751464844,70,1,0,0,1,0.265731811523438,27.8592376708984,2,1,1,282.586883544922,0,282.701278686523,,,,,,,,,,,,,,,,,,,,,,,,,,,,,,,,,
,3737938314.41046,276.707336425781,49999.6640625,2.53118418278125E-5,1.33491614926035E-7,1,5,14.0008964538574,3.99827485716626,30.4899998009205,0.0225919804614116,0.00284096700907725,1,-6.26240054000133E-7,276.569396972656,276.845275878906,49999.6640625,49999.6640625,49.995304975563,5.79573229497078,8.31794929504394,70,1,0,0,1,0.270843505859375,27.8592376708984,2,1,1,276.569396972656,0,276.707336425781,,,,,,,,,,,,,,,,,,,,,,,,,,,,,,,,,
,3737938434.8733,270.679763793945,49999.6640625,2.58191192952312E-5,1.71681184047527E-7,1,5,14.0008964538574,3.99838711976587,30.4700005799532,0.0230548521278846,0.00283794625733237,1,-7.06359609761839E-7,270.565490722656,270.794036865234,49999.6640625,49999.6640625,50.1864131485149,5.79361591267521,8.23831748962402,70,1,0,0,1,0.269241333007813,27.8592376708984,2,1,1,270.565490722656,0,270.679763793945,,,,,,,,,,,,,,,,,,,,,,,,,,,,,,,,,
,3737938554.43645,264.708679199219,49999.6640625,2.78792171659622E-5,1.69005084528458E-7,1,5,14.0008964538574,3.99833051444137,30.4700005799532,0.0249000317020731,0.00302321994946228,1,-8.08934019374401E-7,264.571655273438,264.845703125,49999.6640625,49999.6640625,50.1090319251111,5.79381196831816,8.17731285095215,70,1,0,0,1,0.270538330078125,27.8592376708984,2,1,1,264.571655273438,0,264.708679199219,,,,,,,,,,,,,,,,,,,,,,,,,,,,,,,,,
,3737938674.39169,258.721939086914,49999.6640625,2.83076355891929E-5,1.5530769650824E-7,1,5,14.0008964538574,3.99831273616062,30.4499994963407,0.0252831333366682,0.00306539270288116,1,-8.26158997152591E-7,258.591705322266,258.852172851562,49999.6640625,49999.6640625,50.1266185667938,5.79360258403251,8.11889553070068,70,1,0,0,1,0.265045166015625,27.8592376708984,2,1,1,258.591705322266,0,258.721939086914,,,,,,,,,,,,,,,,,,,,,,,,,,,,,,,,,
,3737938794.75671,252.70987701416,49999.6640625,2.85199357620738E-5,1.56239667703075E-7,1,5,14.0008964538574,3.99830945124842,30.4300002753735,0.0254674783223977,0.00312308105517498,1,-7.93329699966577E-7,252.619155883789,252.800598144531,49999.6640625,49999.6640625,50.1543663792265,5.79381555133484,8.06762409210205,70,1,0,0,1,0.26702880859375,27.8592376708984,2,1,1,252.619155883789,0,252.70987701416,,,,,,,,,,,,,,,,,,,,,,,,,,,,,,,,,
,3737938979.66035,243.468826293945,49999.6640625,2.90588384356426E-5,1.59899645488853E-7,1,5,14.0008964538574,3.99831850120507,30.4000005125999,0.0259469667634409,0.0031942260511628,1,-7.94689595362637E-7,243.356414794922,243.581237792969,49999.6640625,49999.6640625,50.0859738837938,5.79424753442325,7.97623157501221,68,1,32,0,0,0.269393920898438,27.8592376708984,2,1,1,243.356414794922,0,243.468826293945,,,,,,,,,,,,,,,,,,,,,,,,,,,,,,,,,
,3737939099.37252,237.497901916504,49999.6640625,3.11039914826183E-5,1.6267735582053E-7,1,5,14.0008964538574,3.99831604140223,30.4000005125999,0.0277643041464247,0.00347716356735089,1,-7.85246763363389E-7,237.390045166016,237.605758666992,49999.6640625,49999.6640625,50.1465500940341,5.79440779113996,7.91948986053467,70,1,0,0,1,0.266265869140625,27.8592376708984,2,1,1,237.37158203125,0,237.497901916504,,,,,,,,,,,,,,,,,,,,,,,,,,,,,,,,,
,3737939219.64946,231.486473083496,49999.6640625,3.09257019772333E-5,1.75936297752549E-7,1,5,14.0008964538574,3.99833921772273,30.3799994289875,0.0276064201557722,0.00345059403997989,1,-7.88246689357146E-7,231.360092163086,231.612854003906,49999.6640625,49999.6640625,50.0910544691688,5.79372118886807,7.88193702697754,70,1,0,0,1,0.266494750976562,27.8592376708984,2,1,1,231.360092163086,0,231.486473083496,,,,,,,,,,,,,,,,,,,,,,,,,,,,,,,,,
,3737939339.32807,225.513275146484,49999.6640625,3.04927695260832E-5,1.53856689787989E-7,1,5,14.0008964538574,3.99828862596395,30.3600002080202,0.0272335823653859,0.00330830748132809,1,-8.82823137116855E-7,225.394622802734,225.631927490234,49999.6640625,49999.6640625,50.0382945441207,5.79469877703465,7.83155345916748,70,1,0,0,1,0.269775390625,27.8592376708984,2,1,1,225.394622802734,0,225.513275146484,,,,,,,,,,,,,,,,,,,,,,,,,,,,,,,,,
,3737939459.40826,219.496940612793,49999.6640625,3.16793946780093E-5,1.38952841997813E-7,1,5,14.0008964538574,3.99827263027745,30.349999666214,0.0282762431558643,0.00354932541690836,1,-7.90891421250866E-7,219.373794555664,219.620086669922,49999.6640625,49999.6640625,50.1582745218226,5.79484266237733,7.7423095703125,68,1,64,0,0,0.267715454101562,27.8592376708984,2,1,1,219.373794555664,0,219.496940612793,,,,,,,,,,,,,,,,,,,,,,,,,,,,,,,,,
,3737939599.65727,212.474945068359,49999.6640625,3.18746426771697E-5,1.50261725741296E-7,1,5,14.0008964538574,3.99816534108899,30.3300004452467,0.0284595093975932,0.00350340909012253,1,-8.718341165828E-7,212.376068115234,212.573822021484,49999.6640625,49999.6640625,49.9925692757457,5.79502187804184,7.66855096817017,68,1,32,0,0,0.269622802734375,27.8592376708984,2,1,1,212.376068115234,0,212.474945068359,,,,,,,,,,,,,,,,,,,,,,,,,,,,,,,,,
,3737939759.33976,204.512138366699,49999.6640625,3.22476882009851E-5,1.71982959191916E-7,1,5,14.0008964538574,3.99823132025557,30.3099993616343,0.0288022061585675,0.00348580003303494,1,-9.48056535385101E-7,204.39128112793,204.632995605469,49999.6640625,49999.6640625,50.0914452834284,5.79462671997965,7.60609579086304,70,1,0,0,1,0.268478393554687,27.8592376708984,2,1,1,204.39128112793,0,204.512138366699,,,,,,,,,,,,,,,,,,,,,,,,,,,,,,,,,
,3737939879.87537,198.498908996582,49999.6640625,3.17788061685774E-5,1.51980416015752E-7,1,5,14.0008964538574,3.99816269746092,30.290000140667,0.0283735275300752,0.00349541284660926,1,-8.66355087961377E-7,198.383499145508,198.614318847656,49999.6640625,49999.6640625,50.0879279550918,5.79569754151775,7.56181287765503,68,1,32,0,0,0.266342163085938,27.8592376708984,2,1,1,198.383499145508,0,198.498908996582,,,,,,,,,,,,,,,,,,,,,,,,,,,,,,,,,
,3737939999.31869,192.543952941895,49999.6640625,3.23289718371639E-5,1.65070170823513E-7,1,5,14.0008964538574,3.9983017433252,30.2799995988607,0.0288444749214418,0.0037009732037923,1,-7.18461622327015E-7,192.416717529297,192.671188354492,49999.6640625,49999.6640625,50.0629158424764,5.79502826164098,7.53542375564575,68,1,68,0,0,0.267257690429687,27.8592376708984,2,1,1,192.381500244141,0,192.543952941895,,,,,,,,,,,,,,,,,,,,,,,,,,,,,,,,,
,3737940119.24575,186.526802062988,49999.6640625,3.260540868978E-5,1.50044925751207E-7,1,5,14.0008964538574,3.99823422787516,30.2700009196997,0.0290990971540477,0.00367446260923656,1,-7.89894522315017E-7,186.420867919922,186.632736206055,49999.6640625,49999.6640625,50.1399062516207,5.7954771664481,7.51207256317139,70,1,0,0,1,0.266189575195313,27.8592376708984,2,1,1,186.420867919922,0,186.526802062988,,,,,,,,,,,,,,,,,,,,,,,,,,,,,,,,,
,3737940239.72713,180.54313659668,49999.6640625,3.22475534687434E-5,1.5634535088301E-7,1,5,14.0008964538574,3.99823987332753,30.2499998360872,0.0287698037915488,0.003700291002285,1,-7.06834992114352E-7,180.418914794922,180.667358398438,49999.6640625,49999.6640625,50.0136732457649,5.79569904346455,7.46934080123901,70,1,0,0,1,0.268020629882813,27.8592376708984,2,1,1,180.418914794922,0,180.54313659668,,,,,,,,,,,,,,,,,,,,,,,,,,,,,,,,,
,3737940359.24618,174.603225708008,49999.6640625,3.34961940965544E-5,1.62381649539421E-7,1,5,14.0008964538574,3.99824371747971,30.2499998360872,0.0299056035434284,0.00369934271890166,1,-8.96404831833778E-7,174.492156982422,174.714294433594,49999.6640625,49999.6640625,50.1594469646015,5.79498988119974,7.42614126205444,70,1,0,0,1,0.266494750976562,27.8592376708984,2,1,1,174.492156982422,0,174.603225708008,,,,,,,,,,,,,,,,,,,,,,,,,,,,,,,,,
,3737940479.20755,168.557182312012,49999.6640625,3.31429776473478E-5,1.79514801201639E-7,1,5,14.0008964538574,3.99818382956124,30.2300006151199,0.0295907824085677,0.0036520327631136,1,-8.96188744685752E-7,168.440582275391,168.673782348633,49999.6640625,49999.6640625,50.0066385890918,5.79431630622442,7.37803220748901,70,1,0,0,1,0.270309448242187,27.8592376708984,2,1,1,168.440582275391,0,168.557182312012,,,,,,,,,,,,,,,,,,,,,,,,,,,,,,,,,
,3737940599.33996,162.563331604004,49999.6640625,3.29398198704237E-5,1.61750629795277E-7,1,5,14.0008964538574,3.99813663177305,30.2099995315075,0.0294162475711935,0.00358054031841367,1,-9.45845381265017E-7,162.442687988281,162.683975219727,49999.6640625,49999.6640625,50.096916683063,5.79492712177162,7.33696794509888,70,1,0,0,1,0.266189575195313,27.8592376708984,2,1,1,162.442687988281,0,162.563331604004,,,,,,,,,,,,,,,,,,,,,,,,,,,,,,,,,
,3737940719.69473,156.578834533691,49999.6640625,3.43652464358789E-5,1.63037540650423E-7,1,5,14.0008964538574,3.99805266489946,30.2099995315075,0.0306754240100084,0.00381977582122251,1,-8.91833219613139E-7,156.474105834961,156.683563232422,49999.6640625,49999.6640625,49.9210502662361,5.79555709191352,7.28978681564331,66,1,96,0,0,0.26885986328125,27.8592376708984,2,1,1,156.474105834961,0,156.578834533691,,,,,,,,,,,,,,,,,,,,,,,,,,,,,,,,,
,3737940839.26562,150.567779541016,49999.6640625,3.40190099603172E-5,1.74677042422884E-7,1,5,14.0008964538574,3.99811250847142,30.1900003105402,0.0303877543915563,0.00364448619438374,1,-1.03680647871915E-6,150.426712036133,150.708847045898,49999.6640625,49999.6640625,50.0449383865341,5.79470163196562,4.98822402954102,68,1,32,0,0,0.27008056640625,27.8592376708984,2,1,1,150.426712036133,0,150.567779541016,,,,,,,,,,,,,,,,,,,,,,,,,,,,,,,,,
,3737940959.29678,144.606643676758,49999.6640625,3.44667504494216E-5,1.51954748364935E-7,1,5,14.0008964538574,3.99804881180493,30.179999768734,0.0307650219839725,0.00383741265011149,1,-8.87314111802141E-7,144.478881835938,144.734405517578,49999.6640625,49999.6640625,50.0128916172457,5.79606196033368,4.96015119552612,70,1,0,0,1,0.267562866210938,27.8592376708984,2,1,1,144.478881835938,0,144.606643676758,,,,,,,,,,,,,,,,,,,,,,,,,,,,,,,,,
,3737941119.16388,136.602447509766,49999.6640625,3.45762649976624E-5,1.65154548952114E-7,1,5,14.0008964538574,3.99824632947842,30.1600005477667,0.0308611260980495,0.00387694602777397,1,-8.59728062775178E-7,136.484039306641,136.720855712891,49999.6640625,49999.6640625,50.0976983115822,5.79535868703541,4.91407012939453,69,1,68,0,0,0.266571044921875,27.8592376708984,2,1,1,136.484039306641,0,136.602447509766,,,,,,,,,,,,,,,,,,,,,,,,,,,,,,,,,
,3737941239.33194,130.570159912109,49999.6640625,3.59268670729605E-5,1.56591529936504E-7,1,5,14.0008964538574,3.99818020253467,30.1600005477667,0.032063059899919,0.00404618434360831,1,-8.73173912493031E-7,130.453384399414,130.686935424805,49999.6640625,49999.6640625,50.1442052084765,5.79512389508031,4.88439178466797,70,1,0,0,1,0.269622802734375,27.8592376708984,2,1,1,130.453384399414,0,130.570159912109,,,,,,,,,,,,,,,,,,,,,,,,,,,,,,,,,
,3737941379.1154,123.615943908691,49999.6640625,3.57763096725033E-5,1.65579185218705E-7,1,5,14.0008964538574,3.9981539860972,30.1399994641542,0.0319445846304116,0.00392171323904754,1,-9.90381752437236E-7,123.500122070312,123.73176574707,49999.6640625,49999.6640625,50.0996523828803,5.79507659831826,4.85296821594238,70,1,0,0,1,0.268325805664062,27.8592376708984,2,1,1,123.500122070312,0,123.615943908691,,,,,,,,,,,,,,,,,,,,,,,,,,,,,,,,,
,3737941539.71965,115.590919494629,49999.6640625,3.64380356811486E-5,1.70757568895416E-7,1,5,14.0008964538574,3.99804582907693,30.1300007849932,0.0325238213090046,0.00406172763006214,1,-9.32615610707742E-7,115.461372375488,115.72046661377,49999.6640625,49999.6640625,50.0660423565534,5.79543781882974,4.80516767501831,70,1,0,0,1,0.26397705078125,27.8592376708984,2,1,1,115.461372375488,0,115.590919494629,,,,,,,,,,,,,,,,,,,,,,,,,,,,,,,,,
,3737941679.07612,108.634159088135,49999.6640625,3.61550051356626E-5,1.70064513399071E-7,1,5,14.0008964538574,3.99802629280617,30.1099997013807,0.0322787045451595,0.00397873030768029,1,-9.83199180829407E-7,108.512786865234,108.755531311035,49999.6640625,49999.6640625,50.0687780563707,5.79535247277541,4.77348136901855,70,1,0,0,1,0.267868041992187,27.8592376708984,2,1,1,108.512786865234,0,108.634159088135,,,,,,,,,,,,,,,,,,,,,,,,,,,,,,,,,
,3737941874.06436,98.8642654418945,49999.6640625,3.7558773731818E-5,1.68965258296787E-7,1,5,14.0008964538574,3.99819056241332,30.1099997013807,0.0335258301733574,0.00418871769720549,1,-9.59253417643671E-7,98.724250793457,99.004280090332,49999.6640625,49999.6640625,50.0074202176111,5.79459026505264,4.71832752227783,70,1,0,0,1,0.270843505859375,27.8592376708984,2,1,1,98.724250793457,0,98.8642654418945,,,,,,,,,,,,,,,,,,,,,,,,,,,,,,,,,
,3737942094.12152,87.8708381652832,49999.6640625,3.78042515903726E-5,1.50832686255912E-7,1,5,14.0008964538574,3.99810615736843,30.0900004804134,0.0337545655597882,0.00414472329715103,1,-1.04563084991293E-6,87.755126953125,87.9865493774414,49999.6640625,49999.6640625,50.2090803755726,5.79505687044889,4.66617155075073,70,1,0,0,1,0.269317626953125,27.8592376708984,2,1,1,87.755126953125,0,87.8708381652832,,,,,,,,,,,,,,,,,,,,,,,,,,,,,,,,,
,3737942214.39753,81.8748970031738,49999.6640625,3.83235753001676E-5,1.73616929482009E-7,1,5,14.0008964538574,3.99805073893533,30.0900004804134,0.0342079236152906,0.00426501085254058,1,-9.88641289748075E-7,81.7703857421875,81.9794082641602,49999.6640625,49999.6640625,50.1328715949476,5.79602953597758,4.63793897628784,70,1,0,0,1,0.26824951171875,27.8592376708984,2,1,1,81.7703857421875,0,81.8748970031738,,,,,,,,,,,,,,,,,,,,,,,,,,,,,,,,,
,3737942512.54461,66.8564224243164,49999.6640625,3.86424161871603E-5,1.53613460813716E-7,1,5,14.0008964538574,3.9980069243393,30.069999396801,0.0344800269717551,0.00437920314636607,1,-9.08258649534179E-7,66.8564224243164,66.8564224243164,49999.6640625,49999.6640625,50.2426904018995,5.7961705458555,4.5543098449707,70,1,0,0,1,0.269012451171875,27.8592376708984,2,1,1,66.8564224243164,0,66.8564224243164,,,,,,,,,,,,,,,,,,,,,,,,,,,,,,,,,
,3737942674.43165,58.7189044952393,49999.6640625,3.74986998962551E-5,1.47472738214314E-7,1,5,14.0008964538574,3.99791975502077,30.0500001758337,0.0334835508049145,0.00408245836439582,1,-1.06918893971768E-6,58.5974845886231,58.8403244018555,49999.6640625,49999.6640625,50.0031212607553,5.79682196611236,4.50024652481079,70,1,0,0,1,0.266342163085938,27.8592376708984,2,1,1,58.5974845886231,0,58.7189044952393,,,,,,,,,,,,,,,,,,,,,,,,,,,,,,,,,
,3737942899.13044,47.4170589447022,49999.6640625,3.78659147986578E-5,1.48672418515499E-7,1,5,14.0008964538574,3.99785553118608,30.0500001758337,0.0338172089091495,0.00407841798998592,1,-1.12905112060225E-6,47.2922286987305,47.5418891906738,49999.6640625,49999.6640625,50.1871947770342,5.79692356553957,4.40787410736084,68,1,68,0,0,0.266571044921875,27.8592376708984,2,1,1,47.2922286987305,0,47.4170589447022,,,,,,,,,,,,,,,,,,,,,,,,,,,,,,,,,
,3737943329.11215,25.8245296478271,49999.6640625,3.0721048280701E-5,1.63260721435491E-5,1,5,14.0008964538574,3.99800254186679,30.0299990922213,0.0250981985761912,0.0188076740052457,10,1.65152373864672E-5,25.6969795227051,25.9520797729492,49999.6640625,49999.6640625,50.2536332011688,5.79660063539954,4.04893064498901,69,1,64,0,0,0.273513793945313,27.8592376708984,2,1,1,25.6969795227051,0,25.8245296478271,,,,,,,,,,,,,,,,,,,,,,,,,,,,,,,,,
,3737943563.93981,14.1680464744568,49999.6640625,2.15490436858955E-5,1.44574811406692E-7,1,5,14.0008964538574,3.99800552596293,30.0299990922213,0.019284472588638,0.00206709839348181,10,-9.28224845672871E-7,14.0517807006836,14.28431224823,49999.6640625,49999.6640625,50.4580290589476,5.79604078669994,3.44066143035889,68,1,68,0,0,0.266571044921875,27.8592376708984,2,1,1,14.0517807006836,0,14.1680464744568,,,,,,,,,,,,,,,,,,,,,,,,,,,,,,,,,
,3737943719.30508,6.75727868080139,49999.6640625,-2.2505473475103E-6,1.74152552944285E-7,1,5,14.0008964538574,3.99799684960279,30.009999871254,-0.00186882768048128,-0.00117774653894979,1,-9.84864808637015E-7,6.6631441116333,6.85141324996948,49999.6640625,49999.6640625,50.6464015320823,5.79698111636154,2.84056258201599,70,1,0,0,1,0.2685546875,27.8592376708984,6,1,1,6.6631441116333,0,6.75727868080139,,,,,,,,,,,,,,,,,,,,,,,,,,,,,,,,,
,3737943911.95768,2.91854465007782,49999.6640625,-3.32447401477236E-5,1.6864397118291E-7,1,5,14.0008964538574,3.99811053756762,30.009999871254,-0.0294184606193491,-0.00540072688284415,1,-1.05523608837138E-6,2.91741967201233,2.91966962814331,49999.6640625,49999.6640625,51.1341377280823,5.79631817230721,1.98391461372375,70,1,0,0,1,0.268096923828125,27.8592376708984,6,1,1,2.91741967201233,0,2.91854465007782,,,,,,,,,,,,,,,,,,,,,,,,,,,,,,,,,
,3737944033.8706,2.90071749687195,49999.6640625,-3.753640500745E-5,1.49939082712671E-7,1,5,14.0008964538574,3.99813758859354,30.009999871254,-0.0332472277342826,-0.0058946942729714,1,-9.6282698893055E-7,2.90027260780334,2.90116238594055,49999.6640625,49999.6640625,51.2060475518516,5.79770102861386,1.98908853530884,70,1,0,0,1,0.268096923828125,27.8592376708984,6,1,1,2.90027260780334,0,2.90071749687195,,,,,,,,,,,,,,,,,,,,,,,,,,,,,,,,,
,3737944198.88066,2.77587616443634,49999.6640625,-4.09707145429184E-5,1.35574331677774E-7,1,5,14.0008964538574,3.99820388327684,30.009999871254,-0.0362982094332625,-0.0063802607253567,1,-9.90273511278042E-7,2.77056264877319,2.78118968009949,49999.6640625,49999.6640625,51.1634487975535,5.79755348316503,1.95769369602203,70,1,0,0,1,0.267791748046875,27.8592376708984,6,1,1,2.76956272125244,0,2.77587616443634,,,,,,,,,,,,,,,,,,,,,,,,,,,,,,,,,
,3737944319.27708,2.77063477039337,49999.6640625,-4.27644566196645E-5,1.39369489368055E-7,1,5,14.0008964538574,3.9980422320618,30.009999871254,-0.0379054899704041,-0.00652303861465489,1,-8.80529298156929E-7,2.76731204986572,2.77395749092102,49999.6640625,49999.6640625,51.1982312666593,5.79770412615314,1.96123290061951,70,1,0,0,1,0.268707275390625,27.8592376708984,6,1,1,2.76731204986572,0,2.77063477039337,,,,,,,,,,,,,,,,,,,,,,,,,,,,,,,,,
,3737944463.81111,1.99978983402252,49999.6640625,-4.85339370934588E-5,1.61384367009729E-7,1,5,14.0008964538574,3.99810927306379,30.009999871254,-0.0430332135794452,-0.0073196173319715,1,-9.05233738276648E-7,1.99936175346374,2.0002179145813,49999.6640625,49999.6640625,51.3229010154766,5.79681626381296,1.65724122524261,70,1,0,0,1,0.267562866210938,27.8592376708984,1,1,1,2.0002179145813,0,1.99978983402252,,,,,,,,,,,,,,,,,,,,,,,,,,,,,,,,,